{"type": "orderbook", "local_time": 1761342392228, "event_time": 1761342390714, "latency_ms": 1514, "data": {"e": "depthUpdate", "E": 1761342390714, "s": "BTCUSDT", "U": 79012699452, "u": 79012699494, "b": [["110998.47000000", "0.39984000"], ["110998.46000000", "0.00613000"], ["110997.41000000", "0.04772000"], ["110996.41000000", "0.00025000"], ["110996.40000000", "0.04556000"], ["110995.01000000", "0.00010000"], ["110995.00000000", "0.02709000"], ["110994.30000000", "0.00000000"], ["110994.29000000", "0.07710000"], ["110989.46000000", "0.01814000"], ["110989.16000000", "0.04536000"], ["110978.78000000", "0.03600000"], ["110898.37000000", "0.03600000"], ["99898.00000000", "0.03587000"]], "a": [["110998.48000000", "5.29526000"], ["110999.14000000", "0.20750000"], ["110999.77000000", "0.48331000"], ["111000.88000000", "0.00000000"], ["111001.15000000", "0.29730000"], ["111003.85000000", "0.00000000"], ["111004.44000000", "0.00518000"], ["111005.03000000", "0.00083000"], ["111096.35000000", "0.00100000"], ["111096.36000000", "0.00100000"], ["111103.35000000", "0.00000000"], ["111103.36000000", "0.00000000"]]}}
{"type": "orderbook", "local_time": 1761342392228, "event_time": 1761342390814, "latency_ms": 1414, "data": {"e": "depthUpdate", "E": 1761342390814, "s": "BTCUSDT", "U": 79012699495, "u": 79012699546, "b": [["110998.47000000", "0.39984000"], ["110998.46000000", "0.00613000"], ["110997.42000000", "0.00010000"], ["110997.41000000", "0.04797000"], ["110997.40000000", "0.03226000"], ["110996.42000000", "0.00000000"], ["110996.41000000", "0.00010000"], ["110995.02000000", "0.00000000"], ["110995.00000000", "0.00005000"], ["110994.99000000", "0.02704000"], ["110994.88000000", "0.00005000"], ["110994.72000000", "0.20745000"], ["110990.96000000", "0.04536000"], ["110990.28000000", "0.00005000"], ["110989.16000000", "0.00000000"], ["42000.00000000", "1.36734000"]], "a": [["110998.48000000", "5.29546000"], ["110999.13000000", "0.00015000"], ["110999.14000000", "0.00005000"], ["110999.76000000", "0.00005000"], ["111003.94000000", "0.21105000"], ["111057.78000000", "0.00000000"]]}}
{"type": "orderbook", "local_time": 1761342392229, "event_time": 1761342390914, "latency_ms": 1315, "data": {"e": "depthUpdate", "E": 1761342390914, "s": "BTCUSDT", "U": 79012699547, "u": 79012699595, "b": [["110998.47000000", "0.39984000"], ["110998.46000000", "0.00613000"], ["110997.41000000", "0.10378000"], ["110996.40000000", "0.04556000"], ["110995.02000000", "0.00000000"], ["110995.01000000", "0.00000000"], ["110995.00000000", "0.00010000"], ["110994.99000000", "0.02709000"], ["110994.87000000", "0.05428000"], ["110994.29000000", "0.03479000"], ["110993.93000000", "0.00012000"], ["110991.20000000", "0.00000000"], ["110990.28000000", "0.00000000"], ["110977.59000000", "0.03600000"], ["110881.95000000", "0.03600000"]], "a": [["110998.48000000", "5.29551000"], ["110999.12000000", "0.00000000"], ["110999.13000000", "0.00000000"], ["110999.14000000", "0.00000000"], ["110999.76000000", "0.00010000"], ["111000.88000000", "0.00010000"], ["111001.14000000", "0.00005000"], ["111003.87000000", "0.65349000"], ["111003.94000000", "0.21110000"], ["111005.05000000", "0.26996000"], ["111014.95000000", "0.00044000"]]}}
{"type": "orderbook", "local_time": 1761342392229, "event_time": 1761342391018, "latency_ms": 1211, "data": {"e": "depthUpdate", "E": 1761342391018, "s": "BTCUSDT", "U": 79012699596, "u": 79012699685, "b": [["110998.47000000", "1.19515000"], ["110996.02000000", "0.00000000"], ["110995.00000000", "1.44352000"], ["110992.77000000", "0.00000000"], ["110990.96000000", "0.00000000"], ["110989.08000000", "1.44342000"], ["110987.66000000", "0.20282000"], ["110983.50000000", "0.06100000"], ["110982.80000000", "0.20282000"], ["110980.01000000", "0.00450000"], ["110978.56000000", "0.00000000"], ["110973.47000000", "0.00000000"], ["110972.00000000", "0.06220000"], ["110948.49000000", "0.04348000"], ["110900.34000000", "0.00000000"], ["110895.01000000", "0.00224000"], ["110858.37000000", "0.00000000"], ["110852.01000000", "0.00224000"], ["110790.01000000", "0.00000000"], ["110784.01000000", "0.00090000"], ["110766.01000000", "0.00000000"], ["110760.45000000", "0.00076000"], ["110746.01000000", "0.00000000"], ["110740.01000000", "0.00090000"]], "a": [["110998.48000000", "2.56380000"], ["110999.77000000", "0.00020000"], ["110999.78000000", "0.00010000"], ["110999.86000000", "0.04581000"], ["111000.89000000", "0.04010000"], ["111001.15000000", "0.00005000"], ["111003.87000000", "0.13529000"], ["111003.94000000", "0.00005000"], ["111005.05000000", "0.00005000"], ["111007.28000000", "0.00000000"], ["111007.29000000", "0.00000000"], ["111007.30000000", "0.00000000"], ["111007.31000000", "0.00390000"], ["111008.18000000", "0.00000000"], ["111009.57000000", "0.00450000"], ["111012.52000000", "0.04548000"], ["111012.86000000", "0.00000000"], ["111013.97000000", "0.00000000"], ["111015.53000000", "0.00644000"], ["111016.68000000", "0.00000000"], ["111016.69000000", "0.00000000"], ["111018.59000000", "0.00000000"], ["111018.60000000", "0.27246000"], ["111022.42000000", "0.00000000"], ["111022.43000000", "0.00000000"], ["111026.87000000", "0.22544000"], ["111027.99000000", "0.00000000"], ["111028.01000000", "0.00000000"], ["111030.40000000", "0.00000000"], ["111030.62000000", "0.00900000"], ["111033.39000000", "0.00000000"], ["111036.15000000", "0.00000000"], ["111036.53000000", "0.00000000"], ["111040.12000000", "0.00000000"], ["111040.26000000", "0.00000000"], ["111045.56000000", "0.00000000"], ["111049.95000000", "0.00000000"], ["111053.99000000", "0.00224000"], ["111060.34000000", "0.00000000"], ["111066.93000000", "0.00000000"], ["111066.99000000", "0.00048000"], ["111075.99000000", "0.00000000"], ["111080.82000000", "0.00225000"], ["111087.99000000", "0.00000000"], ["111096.35000000", "0.00000000"], ["111096.36000000", "0.00000000"], ["111148.72000000", "0.00007000"], ["111165.78000000", "0.00090000"], ["111171.36000000", "0.00000000"], ["111179.99000000", "0.00019000"], ["111192.15000000", "0.00090000"], ["111199.79000000", "0.00000000"], ["111208.79000000", "0.00000000"]]}}
{"type": "orderbook", "local_time": 1761342392230, "event_time": 1761342391114, "latency_ms": 1116, "data": {"e": "depthUpdate", "E": 1761342391114, "s": "BTCUSDT", "U": 79012699686, "u": 79012699855, "b": [["110998.47000000", "1.66419000"], ["110998.46000000", "0.00598000"], ["110997.87000000", "0.00012000"], ["110997.41000000", "0.52753000"], ["110996.93000000", "0.04536000"], ["110996.40000000", "0.04551000"], ["110995.01000000", "0.00010000"], ["110995.00000000", "1.44342000"], ["110994.88000000", "0.00000000"], ["110994.73000000", "0.00005000"], ["110994.72000000", "0.00000000"], ["110994.29000000", "0.44765000"], ["110993.93000000", "0.00000000"], ["110993.83000000", "0.00000000"], ["110992.92000000", "0.11267000"], ["110987.67000000", "0.13041000"], ["110987.37000000", "0.00300000"], ["110986.78000000", "0.00000000"], ["110986.77000000", "0.00000000"], ["110984.05000000", "0.30397000"], ["110983.64000000", "0.06748000"], ["110981.32000000", "0.00000000"], ["110977.27000000", "0.00000000"], ["110972.18000000", "0.00576000"], ["110936.60000000", "0.00000000"], ["110911.85000000", "0.03218000"], ["110907.68000000", "0.02536000"], ["110898.37000000", "0.00000000"], ["110894.25000000", "0.00000000"], ["110887.69000000", "0.00000000"], ["110881.95000000", "0.00000000"], ["110782.24000000", "0.00000000"]], "a": [["110998.48000000", "1.88090000"], ["110998.49000000", "0.00005000"], ["110999.55000000", "0.00000000"], ["110999.76000000", "0.00000000"], ["110999.77000000", "0.00000000"], ["110999.78000000", "0.00000000"], ["111000.89000000", "0.00005000"], ["111001.14000000", "0.00000000"], ["111001.15000000", "0.00000000"], ["111003.13000000", "0.00010000"], ["111003.14000000", "0.00000000"], ["111003.73000000", "0.00000000"], ["111003.87000000", "0.00005000"], ["111003.94000000", "0.00000000"], ["111004.44000000", "0.00518000"], ["111004.66000000", "0.00000000"], ["111005.05000000", "0.00000000"], ["111006.02000000", "0.04548000"], ["111007.31000000", "0.00390000"], ["111007.51000000", "0.29723000"], ["111007.61000000", "0.00000000"], ["111008.72000000", "0.00000000"], ["111009.57000000", "0.00010000"], ["111009.58000000", "0.00039000"], ["111011.27000000", "0.00455000"], ["111011.28000000", "0.06005000"], ["111011.72000000", "0.00069000"], ["111012.20000000", "0.00072000"], ["111012.36000000", "0.11267000"], ["111012.52000000", "0.00005000"], ["111012.80000000", "0.04000000"], ["111012.91000000", "0.11046000"], ["111015.53000000", "0.00649000"], ["111016.00000000", "0.00000000"], ["111017.72000000", "0.27041000"], ["111018.33000000", "0.13524000"], ["111020.00000000", "0.00000000"], ["111023.59000000", "0.00000000"], ["111027.06000000", "0.00007000"], ["111031.42000000", "0.18027000"], ["111031.78000000", "0.00309000"], ["111038.12000000", "0.00007000"], ["111042.31000000", "0.00000000"], ["111042.72000000", "0.00000000"], ["111043.90000000", "0.00000000"], ["111044.59000000", "0.13511000"], ["111045.10000000", "0.71195000"], ["111051.12000000", "0.22985000"], ["111057.75000000", "0.04008000"], ["111058.05000000", "0.32411000"], ["111082.48000000", "0.03326000"], ["111097.38000000", "0.00000000"], ["111098.18000000", "0.00000000"], ["111098.46000000", "0.00000000"], ["111098.47000000", "0.00013000"], ["111099.09000000", "0.00007000"], ["111099.10000000", "0.00000000"], ["111100.13000000", "0.00000000"], ["111101.08000000", "0.00000000"], ["111102.03000000", "0.00000000"], ["111104.93000000", "0.00000000"], ["111105.50000000", "0.00000000"], ["111105.51000000", "0.19452000"], ["111105.93000000", "0.03400000"], ["111269.98000000", "0.00000000"]]}}
{"type": "orderbook", "local_time": 1761342392230, "event_time": 1761342391214, "latency_ms": 1016, "data": {"e": "depthUpdate", "E": 1761342391214, "s": "BTCUSDT", "U": 79012699856, "u": 79012699964, "b": [["110998.47000000", "1.80725000"], ["110998.46000000", "0.00593000"], ["110997.42000000", "0.70180000"], ["110997.41000000", "0.52753000"], ["110997.40000000", "0.03226000"], ["110996.94000000", "0.00010000"], ["110996.93000000", "0.00010000"], ["110996.40000000", "0.04551000"], ["110995.00000000", "0.00000000"], ["110994.87000000", "0.05423000"], ["110994.73000000", "0.00000000"], ["110994.29000000", "0.44760000"], ["110989.62000000", "0.04536000"], ["110987.67000000", "0.22551000"], ["110971.15000000", "0.00000000"], ["110967.50000000", "0.83925000"], ["110663.23000000", "0.03998000"], ["110621.84000000", "0.00000000"], ["99898.00000000", "0.03587000"], ["60000.00000000", "56.85876000"]], "a": [["110998.48000000", "1.70968000"], ["110999.28000000", "0.04548000"], ["110999.85000000", "0.01718000"], ["110999.86000000", "0.04576000"], ["111000.88000000", "0.00000000"], ["111000.89000000", "0.00000000"], ["111001.38000000", "0.00000000"], ["111003.13000000", "0.00000000"], ["111003.87000000", "0.00000000"], ["111004.44000000", "0.00518000"], ["111006.01000000", "0.00010000"], ["111006.02000000", "0.00005000"], ["111007.50000000", "0.00010000"], ["111007.51000000", "0.29728000"], ["111009.57000000", "0.00000000"], ["111009.58000000", "0.00034000"], ["111010.71000000", "0.00069000"], ["111010.72000000", "0.00068000"], ["111011.27000000", "0.00460000"], ["111011.28000000", "0.06005000"], ["111012.35000000", "0.09082000"], ["111012.36000000", "0.11272000"], ["111012.52000000", "0.00000000"], ["111012.80000000", "0.04005000"], ["111013.80000000", "0.20282000"], ["111016.00000000", "0.00007000"], ["111017.18000000", "0.20282000"], ["111017.71000000", "1.82799000"], ["111020.53000000", "0.20282000"], ["111022.70000000", "0.37990000"], ["111023.44000000", "1.44342000"], ["111023.89000000", "0.20282000"], ["111028.94000000", "0.37000000"], ["111029.03000000", "1.44342000"], ["111034.58000000", "0.55501000"], ["111045.10000000", "0.56839000"]]}}
{"type": "orderbook", "local_time": 1761342392230, "event_time": 1761342391314, "latency_ms": 916, "data": {"e": "depthUpdate", "E": 1761342391314, "s": "BTCUSDT", "U": 79012699965, "u": 79012700082, "b": [["110998.47000000", "1.14644000"], ["110998.46000000", "0.00598000"], ["110997.43000000", "0.38382000"], ["110997.42000000", "0.00035000"], ["110997.41000000", "0.00015000"], ["110997.40000000", "0.03221000"], ["110996.94000000", "0.00000000"], ["110996.93000000", "0.00000000"], ["110996.41000000", "0.00000000"], ["110996.40000000", "0.04551000"], ["110995.01000000", "0.00000000"], ["110994.87000000", "0.05428000"], ["110994.30000000", "0.00010000"], ["110994.29000000", "0.44765000"], ["110992.93000000", "0.00010000"], ["110992.92000000", "0.11272000"], ["110991.52000000", "0.04536000"], ["110989.62000000", "0.00000000"], ["110989.09000000", "0.00005000"], ["110989.08000000", "0.00000000"], ["110987.66000000", "0.00000000"], ["110972.18000000", "0.00000000"], ["110907.68000000", "0.00000000"], ["110895.55000000", "0.02536000"], ["110762.72000000", "0.84080000"]], "a": [["110998.48000000", "1.71003000"], ["110998.49000000", "0.00015000"], ["110999.27000000", "0.03068000"], ["110999.28000000", "0.00005000"], ["110999.84000000", "0.00010000"], ["110999.85000000", "0.00015000"], ["111003.73000000", "0.04931000"], ["111004.39000000", "0.29724000"], ["111004.44000000", "0.00518000"], ["111006.01000000", "0.00000000"], ["111006.02000000", "0.00000000"], ["111007.21000000", "0.20745000"], ["111007.50000000", "0.09011000"], ["111007.51000000", "0.00005000"], ["111007.61000000", "0.01791000"], ["111010.36000000", "0.20282000"], ["111010.71000000", "0.00000000"], ["111011.04000000", "0.00000000"], ["111011.28000000", "0.06005000"], ["111012.35000000", "0.15140000"], ["111012.91000000", "0.11041000"], ["111015.53000000", "0.00644000"], ["111017.70000000", "0.99077000"], ["111017.71000000", "1.44342000"], ["111022.70000000", "0.82273000"], ["111040.78000000", "0.06912000"], ["111064.36000000", "0.32409000"], ["111245.54000000", "4.65070000"], ["111357.99000000", "0.48717000"]]}}
{"type": "orderbook", "local_time": 1761342392231, "event_time": 1761342391414, "latency_ms": 817, "data": {"e": "depthUpdate", "E": 1761342391414, "s": "BTCUSDT", "U": 79012700083, "u": 79012700219, "b": [["110998.47000000", "0.93904000"], ["110998.46000000", "0.00588000"], ["110997.44000000", "0.16229000"], ["110997.43000000", "0.00025000"], ["110997.42000000", "0.00010000"], ["110997.41000000", "0.00010000"], ["110996.41000000", "0.00010000"], ["110996.34000000", "0.00000000"], ["110995.00000000", "0.00010000"], ["110994.88000000", "0.00005000"], ["110994.30000000", "0.00005000"], ["110994.29000000", "0.04887000"], ["110993.82000000", "0.00000000"], ["110992.93000000", "0.00000000"], ["110992.92000000", "0.11272000"], ["110991.52000000", "0.04541000"], ["110989.09000000", "0.00000000"], ["110983.50000000", "0.00000000"], ["110982.80000000", "0.00000000"], ["110971.15000000", "0.71394000"], ["110962.47000000", "0.00000000"], ["110940.13000000", "0.32445000"], ["110911.85000000", "0.00000000"], ["110899.47000000", "0.03218000"]], "a": [["110998.48000000", "1.83321000"], ["110998.49000000", "0.00010000"], ["110999.26000000", "0.00010000"], ["110999.27000000", "0.11661000"], ["110999.28000000", "0.00000000"], ["110999.84000000", "0.00000000"], ["110999.85000000", "0.00010000"], ["110999.86000000", "0.04576000"], ["111000.87000000", "0.04548000"], ["111003.72000000", "0.00010000"], ["111003.73000000", "0.04936000"], ["111004.38000000", "0.00010000"], ["111004.39000000", "0.29729000"], ["111004.44000000", "0.00518000"], ["111007.03000000", "0.20282000"], ["111007.20000000", "0.13014000"], ["111007.21000000", "0.20750000"], ["111007.31000000", "0.04898000"], ["111007.50000000", "0.00005000"], ["111007.51000000", "0.00000000"], ["111007.61000000", "0.01796000"], ["111010.36000000", "0.20287000"], ["111010.72000000", "0.00000000"], ["111011.27000000", "0.00450000"], ["111011.28000000", "0.06000000"], ["111012.34000000", "0.19651000"], ["111012.35000000", "0.00000000"], ["111012.36000000", "0.00000000"], ["111012.80000000", "0.04000000"], ["111038.23000000", "0.97008000"], ["111084.60000000", "0.00005000"], ["111099.98000000", "0.00000000"]]}}
{"type": "orderbook", "local_time": 1761342392231, "event_time": 1761342391514, "latency_ms": 717, "data": {"e": "depthUpdate", "E": 1761342391514, "s": "BTCUSDT", "U": 79012700220, "u": 79012700299, "b": [["110998.47000000", "0.77406000"], ["110998.46000000", "0.00588000"], ["110997.45000000", "0.09624000"], ["110997.44000000", "0.00025000"], ["110997.43000000", "0.00000000"], ["110997.42000000", "0.00000000"], ["110997.40000000", "0.03226000"], ["110996.42000000", "0.70230000"], ["110996.40000000", "0.04556000"], ["110995.70000000", "0.00198000"], ["110993.83000000", "0.20745000"], ["110991.82000000", "0.00541000"], ["110989.04000000", "0.00396000"], ["110987.67000000", "0.13041000"], ["110987.38000000", "0.00721000"], ["110933.32000000", "0.00000000"], ["99898.00000000", "0.03607000"]], "a": [["110998.48000000", "1.83306000"], ["110999.59000000", "0.00099000"], ["110999.86000000", "0.04576000"], ["111000.86000000", "0.00005000"], ["111000.87000000", "0.04553000"], ["111001.25000000", "0.00198000"], ["111002.91000000", "0.00360000"], ["111004.44000000", "0.00518000"], ["111005.13000000", "0.00541000"], ["111007.02000000", "0.24273000"], ["111007.03000000", "0.20287000"], ["111007.20000000", "0.00005000"], ["111007.21000000", "0.20750000"], ["111007.50000000", "0.00000000"], ["111007.61000000", "0.01791000"], ["111010.36000000", "0.20282000"], ["111012.34000000", "0.11766000"], ["111016.07000000", "0.00000000"], ["111019.96000000", "0.00000000"], ["111020.68000000", "0.11267000"], ["111029.14000000", "0.00059000"], ["111032.47000000", "0.00005000"]]}}
{"type": "orderbook", "local_time": 1761342392232, "event_time": 1761342391614, "latency_ms": 618, "data": {"e": "depthUpdate", "E": 1761342391614, "s": "BTCUSDT", "U": 79012700300, "u": 79012700393, "b": [["110998.47000000", "0.47716000"], ["110998.46000000", "0.00608000"], ["110997.87000000", "0.00000000"], ["110997.46000000", "0.00010000"], ["110997.45000000", "0.24588000"], ["110997.44000000", "0.00000000"], ["110997.40000000", "0.03226000"], ["110996.43000000", "0.00010000"], ["110996.42000000", "0.00010000"], ["110996.40000000", "0.04551000"], ["110996.05000000", "0.00012000"], ["110995.56000000", "0.29727000"], ["110995.00000000", "0.00000000"], ["110994.29000000", "0.11176000"], ["110993.83000000", "0.20750000"], ["110992.92000000", "0.00000000"], ["110991.52000000", "0.00000000"], ["110984.59000000", "0.11267000"], ["110984.05000000", "0.00000000"], ["110983.64000000", "0.00000000"], ["110980.02000000", "0.30398000"], ["110948.52000000", "0.00000000"], ["110931.30000000", "0.00450000"], ["99898.00000000", "0.03587000"]], "a": [["110998.48000000", "1.87206000"], ["110998.49000000", "0.00000000"], ["111002.49000000", "0.00000000"], ["111004.44000000", "0.00518000"], ["111005.05000000", "0.00902000"], ["111005.13000000", "0.00546000"], ["111006.39000000", "0.06748000"], ["111007.02000000", "0.24278000"], ["111007.03000000", "0.20287000"], ["111007.20000000", "0.00000000"], ["111007.21000000", "0.20745000"], ["111012.80000000", "0.00000000"], ["111066.96000000", "0.00044000"]]}}
{"type": "orderbook", "local_time": 1761342392232, "event_time": 1761342391714, "latency_ms": 518, "data": {"e": "depthUpdate", "E": 1761342391714, "s": "BTCUSDT", "U": 79012700394, "u": 79012700460, "b": [["110998.47000000", "0.70697000"], ["110998.46000000", "0.00606000"], ["110997.46000000", "0.21052000"], ["110997.45000000", "0.00025000"], ["110997.40000000", "0.03226000"], ["110996.43000000", "0.00000000"], ["110996.42000000", "0.00000000"], ["110996.40000000", "0.04556000"], ["110996.34000000", "0.00000000"], ["110995.78000000", "0.00000000"], ["110995.57000000", "0.00010000"], ["110995.56000000", "0.00005000"], ["110995.00000000", "0.00005000"], ["110994.30000000", "0.00000000"], ["110994.29000000", "0.04887000"], ["110993.83000000", "0.20750000"], ["110989.47000000", "0.04536000"], ["110987.67000000", "0.08834000"], ["110983.33000000", "0.00000000"], ["110979.28000000", "0.00000000"], ["60000.00000000", "56.85866000"]], "a": [["110998.48000000", "1.96518000"], ["110998.88000000", "0.00000000"], ["110998.93000000", "0.04548000"], ["111000.87000000", "0.00005000"], ["111003.73000000", "0.00005000"], ["111004.44000000", "0.00518000"], ["111005.05000000", "0.00907000"], ["111005.13000000", "0.00546000"], ["111006.39000000", "0.06753000"], ["111007.02000000", "0.24273000"], ["111007.03000000", "0.20282000"], ["111010.88000000", "0.00000000"], ["111011.72000000", "0.00000000"], ["111012.20000000", "0.00000000"], ["111020.68000000", "0.00000000"], ["111070.48000000", "0.00000000"], ["111244.62000000", "0.00000000"]]}}
{"type": "orderbook", "local_time": 1761342392232, "event_time": 1761342391814, "latency_ms": 418, "data": {"e": "depthUpdate", "E": 1761342391814, "s": "BTCUSDT", "U": 79012700461, "u": 79012700561, "b": [["110998.47000000", "0.62636000"], ["110998.46000000", "0.00611000"], ["110997.47000000", "0.00010000"], ["110997.46000000", "0.04863000"], ["110997.45000000", "0.00000000"], ["110996.40000000", "0.04556000"], ["110995.78000000", "0.00000000"], ["110995.57000000", "0.00000000"], ["110995.56000000", "0.00000000"], ["110995.00000000", "0.00010000"], ["110994.29000000", "0.07812000"], ["110993.83000000", "0.00005000"], ["110991.82000000", "0.00546000"], ["110991.07000000", "0.20745000"], ["110983.34000000", "0.27303000"], ["110947.42000000", "0.00260000"], ["110938.28000000", "0.58221000"], ["99898.00000000", "0.03587000"]], "a": [["110998.48000000", "2.05648000"], ["110998.92000000", "0.05077000"], ["110998.93000000", "0.00005000"], ["110999.28000000", "0.06748000"], ["110999.86000000", "0.04576000"], ["111000.86000000", "0.00000000"], ["111000.87000000", "0.00000000"], ["111001.89000000", "0.00000000"], ["111003.10000000", "0.20745000"], ["111003.12000000", "0.20282000"], ["111003.72000000", "0.00000000"], ["111003.73000000", "0.00000000"], ["111006.38000000", "0.00000000"], ["111006.50000000", "0.00005000"], ["111007.02000000", "0.24278000"], ["111007.21000000", "0.00000000"], ["111007.31000000", "0.00390000"], ["111017.76000000", "0.00250000"], ["111018.60000000", "0.26996000"], ["111025.13000000", "0.22535000"], ["111026.55000000", "0.00000000"], ["111033.28000000", "0.34584000"], ["111039.97000000", "0.57111000"], ["111073.58000000", "0.00000000"], ["111089.44000000", "0.00000000"], ["111089.46000000", "0.22535000"], ["111089.49000000", "0.27956000"], ["111089.70000000", "0.00000000"], ["111094.82000000", "0.00402000"], ["111095.11000000", "0.00000000"], ["111204.64000000", "0.01410000"], ["111268.96000000", "0.00089000"]]}}
{"type": "orderbook", "local_time": 1761342392233, "event_time": 1761342391914, "latency_ms": 319, "data": {"e": "depthUpdate", "E": 1761342391914, "s": "BTCUSDT", "U": 79012700562, "u": 79012700611, "b": [["110998.47000000", "0.51600000"], ["110998.46000000", "0.00616000"], ["110997.46000000", "0.04863000"], ["110996.06000000", "0.00000000"], ["110994.29000000", "0.07812000"], ["110993.83000000", "0.00000000"], ["110991.82000000", "0.00546000"], ["110991.07000000", "0.20750000"]], "a": [["110998.48000000", "2.05878000"], ["110998.91000000", "0.00010000"], ["110998.92000000", "0.05072000"], ["110998.93000000", "0.00000000"], ["110999.27000000", "0.23993000"], ["110999.28000000", "0.06753000"], ["110999.86000000", "0.04576000"], ["111003.09000000", "0.00005000"], ["111003.10000000", "0.20750000"], ["111003.12000000", "0.20287000"], ["111004.38000000", "0.00000000"], ["111005.13000000", "0.00541000"], ["111006.39000000", "0.06748000"], ["111007.02000000", "0.12846000"], ["111011.36000000", "0.00000000"], ["111012.36000000", "0.11267000"]]}}
{"type": "orderbook", "local_time": 1761342392233, "event_time": 1761342392014, "latency_ms": 219, "data": {"e": "depthUpdate", "E": 1761342392014, "s": "BTCUSDT", "U": 79012700612, "u": 79012700623, "b": [["88804.00000000", "0.00000000"]], "a": [["110998.48000000", "2.01037000"], ["110999.26000000", "0.20292000"], ["111003.10000000", "0.00005000"], ["111006.38000000", "0.00450000"], ["111011.09000000", "0.00000000"], ["111011.27000000", "0.00000000"], ["111012.09000000", "1.44342000"], ["111013.24000000", "0.00044000"], ["111090.23000000", "0.00000000"]]}}
{"type": "orderbook", "local_time": 1761342392234, "event_time": 1761342392114, "latency_ms": 120, "data": {"e": "depthUpdate", "E": 1761342392114, "s": "BTCUSDT", "U": 79012700624, "u": 79012700641, "b": [["110982.80000000", "1.44342000"]], "a": [["110998.48000000", "2.05874000"], ["110998.92000000", "0.05072000"], ["110999.25000000", "0.00010000"], ["110999.26000000", "0.20297000"], ["110999.86000000", "0.04576000"], ["111001.90000000", "0.20745000"], ["111003.09000000", "0.00000000"], ["111003.10000000", "0.00000000"], ["111012.08000000", "0.56975000"], ["111012.34000000", "0.00000000"], ["111014.95000000", "0.00000000"], ["111089.49000000", "0.00000000"]]}}
{"type": "orderbook", "local_time": 1761342392234, "event_time": 1761342392214, "latency_ms": 20, "data": {"e": "depthUpdate", "E": 1761342392214, "s": "BTCUSDT", "U": 79012700642, "u": 79012700655, "b": [["110983.34000000", "0.66898000"]], "a": [["110998.48000000", "1.97037000"], ["110999.86000000", "0.04576000"], ["111001.69000000", "0.04000000"], ["111001.90000000", "0.00005000"], ["111005.05000000", "0.00902000"], ["111006.38000000", "0.00000000"], ["111007.30000000", "0.00450000"], ["111007.31000000", "0.04898000"], ["111011.14000000", "0.00331000"], ["112600.00000000", "1.58615000"]]}}
{"type": "orderbook", "local_time": 1761342392235, "event_time": 1761342392314, "latency_ms": -79, "data": {"e": "depthUpdate", "E": 1761342392314, "s": "BTCUSDT", "U": 79012700656, "u": 79012700667, "b": [["110998.47000000", "0.55991000"], ["110991.24000000", "0.00360000"], ["110947.41000000", "0.06669000"], ["110681.52000000", "0.02598000"], ["110677.11000000", "0.02598000"]], "a": [["110998.48000000", "1.96572000"], ["110999.86000000", "0.04576000"], ["111001.69000000", "0.04005000"], ["111001.90000000", "0.00000000"], ["111002.00000000", "0.21105000"]]}}
{"type": "orderbook", "local_time": 1761342392334, "event_time": 1761342392414, "latency_ms": -80, "data": {"e": "depthUpdate", "E": 1761342392414, "s": "BTCUSDT", "U": 79012700668, "u": 79012700674, "b": [["110998.47000000", "0.55996000"], ["110998.46000000", "0.00621000"], ["110996.06000000", "0.70230000"]], "a": [["111001.69000000", "0.04005000"], ["111002.00000000", "0.21110000"], ["111004.44000000", "0.00513000"]]}}
{"type": "orderbook", "local_time": 1761342392434, "event_time": 1761342392514, "latency_ms": -80, "data": {"e": "depthUpdate", "E": 1761342392514, "s": "BTCUSDT", "U": 79012700675, "u": 79012700692, "b": [["110998.47000000", "0.56001000"], ["110998.46000000", "0.00621000"], ["110997.46000000", "0.25198000"], ["110996.40000000", "0.04556000"], ["110996.06000000", "0.70235000"], ["110995.00000000", "0.00000000"], ["110991.07000000", "0.20745000"], ["99898.00000000", "0.03587000"]], "a": []}}
{"type": "orderbook", "local_time": 1761342392545, "event_time": 1761342392614, "latency_ms": -69, "data": {"e": "depthUpdate", "E": 1761342392614, "s": "BTCUSDT", "U": 79012700693, "u": 79012700698, "b": [["109599.87000000", "0.02501000"], ["99898.00000000", "0.03587000"]], "a": [["111343.41000000", "0.48717000"], ["111357.99000000", "0.00000000"]]}}
{"type": "orderbook", "local_time": 1761342392858, "event_time": 1761342392714, "latency_ms": 144, "data": {"e": "depthUpdate", "E": 1761342392714, "s": "BTCUSDT", "U": 79012700699, "u": 79012700707, "b": [["110992.47000000", "0.20756000"], ["110991.07000000", "0.00000000"], ["99898.00000000", "0.03597000"]], "a": [["110998.48000000", "1.96592000"], ["111002.00000000", "0.00365000"], ["111002.69000000", "0.20756000"]]}}
{"type": "orderbook", "local_time": 1761342392859, "event_time": 1761342392814, "latency_ms": 45, "data": {"e": "depthUpdate", "E": 1761342392814, "s": "BTCUSDT", "U": 79012700708, "u": 79012700725, "b": [["110998.47000000", "0.56001000"], ["110998.46000000", "0.00621000"], ["110994.29000000", "0.07812000"], ["110992.47000000", "0.20761000"], ["110991.82000000", "0.00541000"], ["110888.69000000", "0.09915000"], ["99898.00000000", "0.03587000"]], "a": [["111001.69000000", "0.04005000"], ["111002.00000000", "0.00360000"], ["111002.69000000", "0.20761000"], ["111005.40000000", "0.00005000"], ["111028.94000000", "0.85542000"], ["111078.00000000", "0.00171000"], ["111089.36000000", "0.28631000"]]}}
{"type": "orderbook", "local_time": 1761342392859, "event_time": 1761342392914, "latency_ms": -55, "data": {"e": "depthUpdate", "E": 1761342392914, "s": "BTCUSDT", "U": 79012700726, "u": 79012700752, "b": [["110947.41000000", "0.00000000"], ["110946.81000000", "0.06634000"], ["110911.68000000", "0.13709000"], ["110884.00000000", "0.00160000"], ["110779.00000000", "0.00000000"], ["110743.00000000", "0.00000000"], ["110699.00000000", "0.00000000"], ["110551.00000000", "0.68581000"], ["110524.00000000", "0.11380000"], ["110453.00000000", "1.36132000"], ["110412.00000000", "2.02305000"]], "a": [["110998.48000000", "1.92044000"], ["111000.54000000", "0.04548000"], ["111005.05000000", "0.00000000"], ["111040.78000000", "0.00000000"], ["111041.93000000", "0.00000000"], ["111043.04000000", "0.06724000"], ["111080.59000000", "0.00000000"], ["111111.00000000", "0.17232000"], ["111222.00000000", "0.01016000"], ["111273.00000000", "0.00000000"], ["111344.00000000", "0.16920000"], ["111372.00000000", "0.00179000"], ["111492.00000000", "0.68695000"], ["111534.00000000", "2.00770000"], ["111576.00000000", "2.79619000"]]}}
{"type": "orderbook", "local_time": 1761342392934, "event_time": 1761342393014, "latency_ms": -80, "data": {"e": "depthUpdate", "E": 1761342393014, "s": "BTCUSDT", "U": 79012700753, "u": 79012700759, "b": [["110911.68000000", "0.00000000"]], "a": [["110999.86000000", "0.04576000"], ["111000.54000000", "0.04553000"], ["111004.39000000", "0.29724000"], ["111013.24000000", "0.00000000"], ["111066.96000000", "0.00000000"]]}}
{"type": "orderbook", "local_time": 1761342393041, "event_time": 1761342393114, "latency_ms": -73, "data": {"e": "depthUpdate", "E": 1761342393114, "s": "BTCUSDT", "U": 79012700760, "u": 79012700760, "b": [], "a": [["110998.92000000", "0.05077000"]]}}
{"type": "orderbook", "local_time": 1761342393145, "event_time": 1761342393214, "latency_ms": -69, "data": {"e": "depthUpdate", "E": 1761342393214, "s": "BTCUSDT", "U": 79012700761, "u": 79012700779, "b": [["110998.47000000", "0.61891000"], ["110998.46000000", "0.00621000"], ["110997.46000000", "0.25198000"], ["110983.50000000", "0.06100000"], ["110695.11000000", "0.00401000"], ["99898.00000000", "0.03587000"]], "a": [["110998.48000000", "1.92029000"], ["110999.26000000", "0.20302000"], ["110999.27000000", "0.23998000"], ["110999.28000000", "0.06758000"], ["111005.03000000", "0.00007000"], ["111015.53000000", "0.00000000"]]}}
{"type": "orderbook", "local_time": 1761342393237, "event_time": 1761342393314, "latency_ms": -77, "data": {"e": "depthUpdate", "E": 1761342393314, "s": "BTCUSDT", "U": 79012700780, "u": 79012700788, "b": [["110998.47000000", "0.60945000"], ["110909.64000000", "0.13845000"], ["110698.47000000", "0.00010000"]], "a": [["111000.19000000", "0.00076000"], ["111080.59000000", "0.13209000"], ["111095.44000000", "0.00100000"], ["111095.45000000", "0.00100000"]]}}
{"type": "orderbook", "local_time": 1761342393395, "event_time": 1761342393414, "latency_ms": -19, "data": {"e": "depthUpdate", "E": 1761342393414, "s": "BTCUSDT", "U": 79012700789, "u": 79012700795, "b": [["110698.47000000", "0.00000000"], ["102145.79000000", "0.00010000"]], "a": [["111039.24000000", "0.00016000"], ["111039.98000000", "0.00000000"], ["111094.82000000", "0.00000000"], ["111105.82000000", "0.00402000"], ["111268.96000000", "0.00000000"], ["111279.96000000", "0.00089000"]]}}
{"type": "orderbook", "local_time": 1761342393434, "event_time": 1761342393514, "latency_ms": -80, "data": {"e": "depthUpdate", "E": 1761342393514, "s": "BTCUSDT", "U": 79012700796, "u": 79012700801, "b": [["110998.47000000", "0.55997000"], ["110994.17000000", "0.00360000"], ["110991.24000000", "0.00000000"]], "a": [["110998.48000000", "1.92034000"], ["110998.49000000", "0.00005000"], ["111002.00000000", "0.00000000"], ["111002.69000000", "0.00005000"]]}}
{"type": "orderbook", "local_time": 1761342393540, "event_time": 1761342393614, "latency_ms": -74, "data": {"e": "depthUpdate", "E": 1761342393614, "s": "BTCUSDT", "U": 79012700802, "u": 79012700811, "b": [["110998.47000000", "0.55997000"], ["110998.46000000", "0.00621000"], ["110998.18000000", "0.00000000"]], "a": [["111001.69000000", "0.04005000"], ["111002.69000000", "0.00000000"], ["111004.39000000", "0.29729000"]]}}
{"type": "orderbook", "local_time": 1761342393641, "event_time": 1761342393714, "latency_ms": -73, "data": {"e": "depthUpdate", "E": 1761342393714, "s": "BTCUSDT", "U": 79012700812, "u": 79012700813, "b": [["99898.00000000", "0.03587000"]], "a": []}}
{"type": "orderbook", "local_time": 1761342393746, "event_time": 1761342393814, "latency_ms": -68, "data": {"e": "depthUpdate", "E": 1761342393814, "s": "BTCUSDT", "U": 79012700814, "u": 79012700816, "b": [["110996.06000000", "0.00005000"]], "a": [["111003.86000000", "0.21116000"]]}}
{"type": "orderbook", "local_time": 1761342393837, "event_time": 1761342393914, "latency_ms": -77, "data": {"e": "depthUpdate", "E": 1761342393914, "s": "BTCUSDT", "U": 79012700817, "u": 79012700843, "b": [["110998.47000000", "0.55997000"], ["110998.46000000", "0.00616000"], ["110997.46000000", "0.04863000"], ["110996.40000000", "0.04556000"], ["110996.06000000", "0.00000000"], ["110991.82000000", "0.00546000"], ["110971.15000000", "0.90020000"], ["110762.72000000", "0.00000000"], ["102145.79000000", "0.00000000"]], "a": [["110998.48000000", "1.96597000"], ["110998.49000000", "0.00010000"], ["111000.54000000", "0.00005000"], ["111003.12000000", "0.20287000"], ["111003.86000000", "0.21121000"], ["111004.39000000", "0.29724000"], ["111034.58000000", "0.77362000"], ["111245.54000000", "0.00000000"], ["111339.76000000", "0.48717000"], ["111343.41000000", "0.00000000"]]}}
{"type": "orderbook", "local_time": 1761342393936, "event_time": 1761342394014, "latency_ms": -78, "data": {"e": "depthUpdate", "E": 1761342394014, "s": "BTCUSDT", "U": 79012700844, "u": 79012700860, "b": [["110998.47000000", "0.56002000"], ["110997.46000000", "0.04868000"], ["110996.06000000", "0.00000000"], ["110995.00000000", "0.00010000"], ["110989.47000000", "0.00000000"], ["110988.55000000", "0.04536000"], ["110982.80000000", "0.00000000"]], "a": [["110999.86000000", "0.04576000"], ["111000.54000000", "0.00000000"], ["111004.39000000", "0.29729000"]]}}
{"type": "orderbook", "local_time": 1761342394305, "event_time": 1761342394115, "latency_ms": 190, "data": {"e": "depthUpdate", "E": 1761342394115, "s": "BTCUSDT", "U": 79012700861, "u": 79012700876, "b": [["110998.47000000", "0.56002000"], ["110998.46000000", "0.00616000"], ["110991.82000000", "0.00546000"], ["110983.51000000", "1.44342000"], ["110983.50000000", "0.00000000"], ["110983.34000000", "0.27303000"], ["110982.46000000", "0.01802000"], ["110758.75000000", "0.84083000"]], "a": [["111015.75000000", "0.01802000"], ["111078.00000000", "0.00176000"], ["111095.44000000", "0.00000000"], ["111095.45000000", "0.00000000"], ["111241.60000000", "4.62575000"]]}}
{"type": "orderbook", "local_time": 1761342394404, "event_time": 1761342394214, "latency_ms": 190, "data": {"e": "depthUpdate", "E": 1761342394214, "s": "BTCUSDT", "U": 79012700877, "u": 79012700881, "b": [["110990.42000000", "0.04536000"], ["110988.55000000", "0.00000000"], ["110987.67000000", "0.50790000"], ["110698.47000000", "0.00000000"]], "a": []}}
{"type": "orderbook", "local_time": 1761342394404, "event_time": 1761342394314, "latency_ms": 90, "data": {"e": "depthUpdate", "E": 1761342394314, "s": "BTCUSDT", "U": 79012700882, "u": 79012700892, "b": [["110998.47000000", "0.56002000"], ["110998.46000000", "0.00616000"], ["110992.63000000", "0.04536000"], ["110991.82000000", "0.00546000"], ["110990.42000000", "0.00000000"], ["99898.62000000", "0.00020000"]], "a": [["110998.48000000", "1.92049000"], ["111001.71000000", "0.04548000"]]}}
{"type": "orderbook", "local_time": 1761342394407, "event_time": 1761342394414, "latency_ms": -7, "data": {"e": "depthUpdate", "E": 1761342394414, "s": "BTCUSDT", "U": 79012700893, "u": 79012700908, "b": [["110998.47000000", "0.55128000"], ["110998.46000000", "0.00616000"], ["110994.29000000", "0.07812000"], ["110992.63000000", "0.04541000"], ["110991.82000000", "0.00541000"], ["110909.64000000", "0.00000000"], ["99898.00000000", "0.03587000"]], "a": [["111001.69000000", "0.04005000"], ["111001.71000000", "0.04553000"], ["111004.39000000", "0.29724000"]]}}
{"type": "orderbook", "local_time": 1761342394635, "event_time": 1761342394714, "latency_ms": -79, "data": {"e": "depthUpdate", "E": 1761342394714, "s": "BTCUSDT", "U": 79012700909, "u": 79012700910, "b": [["110998.47000000", "0.55127000"]], "a": []}}
{"type": "orderbook", "local_time": 1761342394737, "event_time": 1761342394814, "latency_ms": -77, "data": {"e": "depthUpdate", "E": 1761342394814, "s": "BTCUSDT", "U": 79012700911, "u": 79012700913, "b": [["110998.18000000", "0.05031000"], ["99898.00000000", "0.03587000"]], "a": []}}
{"type": "orderbook", "local_time": 1761342394844, "event_time": 1761342394914, "latency_ms": -70, "data": {"e": "depthUpdate", "E": 1761342394914, "s": "BTCUSDT", "U": 79012700914, "u": 79012700938, "b": [["110998.47000000", "0.55132000"], ["110998.46000000", "0.00621000"], ["110998.19000000", "0.00005000"], ["110998.18000000", "0.05056000"], ["110997.46000000", "0.04858000"], ["110997.40000000", "0.03221000"], ["110996.41000000", "0.70210000"], ["110996.40000000", "0.04551000"], ["110994.88000000", "0.00000000"], ["110992.47000000", "0.20756000"], ["109333.49000000", "0.00100000"], ["99898.00000000", "0.03587000"]], "a": [["112663.46000000", "0.00100000"]]}}
{"type": "orderbook", "local_time": 1761342394935, "event_time": 1761342395014, "latency_ms": -79, "data": {"e": "depthUpdate", "E": 1761342395014, "s": "BTCUSDT", "U": 79012700939, "u": 79012700957, "b": [["110998.47000000", "0.55142000"], ["110998.46000000", "0.00616000"], ["110998.19000000", "0.00010000"], ["110997.46000000", "0.25180000"], ["110997.40000000", "0.03221000"], ["110996.41000000", "0.00010000"], ["110995.00000000", "0.00000000"], ["110992.63000000", "0.04536000"], ["88799.00000000", "0.00000000"]], "a": []}}
{"type": "orderbook", "local_time": 1761342395034, "event_time": 1761342395114, "latency_ms": -80, "data": {"e": "depthUpdate", "E": 1761342395114, "s": "BTCUSDT", "U": 79012700958, "u": 79012700979, "b": [["110998.47000000", "0.55120000"], ["110997.46000000", "0.04858000"], ["110997.40000000", "0.03221000"], ["110996.42000000", "0.70200000"], ["110996.41000000", "0.00010000"], ["110995.00000000", "0.00005000"], ["110992.63000000", "0.04541000"], ["110987.68000000", "0.18014000"], ["110905.62000000", "0.00000000"], ["110869.59000000", "0.19455000"], ["99898.00000000", "0.03587000"]], "a": [["110998.81000000", "0.00902000"], ["111095.86000000", "0.00100000"], ["111095.87000000", "0.00100000"]]}}
{"type": "orderbook", "local_time": 1761342395346, "event_time": 1761342395214, "latency_ms": 132, "data": {"e": "depthUpdate", "E": 1761342395214, "s": "BTCUSDT", "U": 79012700980, "u": 79012701008, "b": [["110998.47000000", "0.55125000"], ["110998.46000000", "0.00616000"], ["110997.46000000", "0.25178000"], ["110997.40000000", "0.03221000"], ["110996.43000000", "0.00010000"], ["110996.42000000", "0.00005000"], ["110995.98000000", "0.21116000"], ["110995.00000000", "0.00000000"], ["110992.63000000", "0.04536000"], ["110992.47000000", "0.00000000"]], "a": [["110998.48000000", "1.92054000"], ["110998.49000000", "0.00015000"], ["110998.80000000", "0.00005000"], ["110998.81000000", "0.00907000"], ["110999.85000000", "0.00000000"], ["111003.86000000", "0.21116000"], ["111005.15000000", "0.00360000"]]}}
{"type": "orderbook", "local_time": 1761342395346, "event_time": 1761342395314, "latency_ms": 32, "data": {"e": "depthUpdate", "E": 1761342395314, "s": "BTCUSDT", "U": 79012701009, "u": 79012701031, "b": [["110998.47000000", "0.55125000"], ["110998.46000000", "0.00616000"], ["110997.46000000", "0.10530000"], ["110997.40000000", "0.03221000"], ["110996.43000000", "0.00000000"], ["110996.42000000", "0.00000000"], ["110996.40000000", "0.04551000"], ["110995.99000000", "0.00000000"], ["110995.98000000", "0.21121000"], ["110994.29000000", "0.02930000"]], "a": [["110998.80000000", "0.00010000"]]}}
{"type": "orderbook", "local_time": 1761342395347, "event_time": 1761342395414, "latency_ms": -67, "data": {"e": "depthUpdate", "E": 1761342395414, "s": "BTCUSDT", "U": 79012701032, "u": 79012701032, "b": [["99898.62000000", "0.00000000"]], "a": []}}
{"type": "orderbook", "local_time": 1761342395488, "event_time": 1761342395514, "latency_ms": -26, "data": {"e": "depthUpdate", "E": 1761342395514, "s": "BTCUSDT", "U": 79012701033, "u": 79012701034, "b": [["110996.42000000", "0.70200000"]], "a": [["111023.58000000", "0.00000000"]]}}
{"type": "orderbook", "local_time": 1761342395551, "event_time": 1761342395614, "latency_ms": -63, "data": {"e": "depthUpdate", "E": 1761342395614, "s": "BTCUSDT", "U": 79012701035, "u": 79012701060, "b": [["110998.47000000", "0.55135000"], ["110997.46000000", "0.30756000"], ["110997.40000000", "0.03221000"], ["110996.42000000", "0.00005000"], ["110996.41000000", "0.00005000"], ["110994.29000000", "0.02925000"], ["110980.01000000", "0.00000000"], ["110979.06000000", "0.00450000"]], "a": [["110998.48000000", "2.50657000"], ["110999.28000000", "0.00010000"], ["111007.31000000", "0.00390000"], ["111018.33000000", "0.00000000"], ["111025.13000000", "0.00000000"], ["111026.87000000", "0.00000000"], ["111062.73000000", "0.13524000"], ["111065.24000000", "0.00000000"], ["111089.37000000", "0.00000000"], ["111089.46000000", "0.00000000"]]}}
{"type": "orderbook", "local_time": 1761342395644, "event_time": 1761342395714, "latency_ms": -70, "data": {"e": "depthUpdate", "E": 1761342395714, "s": "BTCUSDT", "U": 79012701061, "u": 79012701086, "b": [["110998.47000000", "0.55130000"], ["110997.46000000", "0.10530000"], ["110997.40000000", "0.03221000"], ["110996.42000000", "0.00000000"], ["110994.29000000", "0.02930000"]], "a": [["110998.48000000", "2.50647000"], ["110999.27000000", "0.23983000"], ["110999.28000000", "0.00000000"], ["110999.85000000", "0.00005000"], ["111003.86000000", "0.21121000"], ["111007.31000000", "0.04898000"], ["111089.36000000", "0.15175000"], ["111090.13000000", "0.22535000"], ["111090.83000000", "0.22544000"], ["111339.76000000", "0.00000000"], ["111347.06000000", "0.48717000"]]}}
{"type": "orderbook", "local_time": 1761342395818, "event_time": 1761342395814, "latency_ms": 4, "data": {"e": "depthUpdate", "E": 1761342395814, "s": "BTCUSDT", "U": 79012701087, "u": 79012701094, "b": [["110996.42000000", "0.00000000"], ["110960.01000000", "0.03698000"], ["110934.79000000", "0.22481000"]], "a": [["110998.48000000", "2.14579000"], ["111011.90000000", "0.13524000"], ["111025.31000000", "0.22544000"]]}}
{"type": "orderbook", "local_time": 1761342395906, "event_time": 1761342395914, "latency_ms": -8, "data": {"e": "depthUpdate", "E": 1761342395914, "s": "BTCUSDT", "U": 79012701095, "u": 79012701114, "b": [["110998.47000000", "0.55140000"], ["110998.18000000", "0.05061000"], ["110997.40000000", "0.03226000"], ["110996.42000000", "0.70200000"], ["110996.40000000", "0.04556000"], ["110994.87000000", "0.05437000"], ["109333.49000000", "0.00100000"], ["99898.00000000", "0.03587000"]], "a": [["110998.48000000", "2.14584000"], ["110999.27000000", "0.23988000"], ["110999.86000000", "0.04581000"], ["111013.24000000", "0.00044000"], ["111066.96000000", "0.00044000"], ["111068.10000000", "0.00049000"], ["111068.35000000", "0.00044000"], ["112663.46000000", "0.00100000"]]}}
{"type": "orderbook", "local_time": 1761342395937, "event_time": 1761342396014, "latency_ms": -77, "data": {"e": "depthUpdate", "E": 1761342396014, "s": "BTCUSDT", "U": 79012701115, "u": 79012701134, "b": [["110998.47000000", "0.55150000"], ["110997.46000000", "0.30760000"], ["110997.40000000", "0.03226000"], ["110996.43000000", "0.00005000"], ["110996.42000000", "0.00005000"], ["110996.40000000", "0.04551000"], ["110994.29000000", "0.02925000"], ["110984.79000000", "0.01802000"], ["110984.00000000", "0.06100000"], ["110982.46000000", "0.00000000"]], "a": [["111007.22000000", "0.00044000"], ["111015.75000000", "0.00000000"], ["111016.41000000", "0.01802000"]]}}
{"type": "orderbook", "local_time": 1761342396037, "event_time": 1761342396114, "latency_ms": -77, "data": {"e": "depthUpdate", "E": 1761342396114, "s": "BTCUSDT", "U": 79012701135, "u": 79012701175, "b": [["110998.47000000", "0.55145000"], ["110998.27000000", "0.00012000"], ["110997.46000000", "0.10530000"], ["110997.40000000", "0.03226000"], ["110996.57000000", "0.00720000"], ["110996.43000000", "0.00000000"], ["110996.42000000", "0.00000000"], ["110996.05000000", "0.00000000"], ["110995.98000000", "0.20761000"], ["110994.45000000", "0.04536000"], ["110994.29000000", "0.02930000"], ["110994.17000000", "0.00000000"], ["110992.63000000", "0.00000000"], ["110991.12000000", "0.00250000"], ["110989.05000000", "0.18014000"], ["110987.68000000", "0.00000000"], ["110980.03000000", "0.20282000"], ["110980.02000000", "0.00000000"], ["110977.25000000", "0.30399000"], ["110972.03000000", "0.00576000"], ["110969.65000000", "0.00000000"], ["110923.87000000", "0.03218000"], ["110899.47000000", "0.00000000"], ["110654.28000000", "0.00000000"], ["110653.74000000", "0.03698000"], ["33000.00000000", "3.79445000"]], "a": [["110998.48000000", "1.92049000"], ["110998.92000000", "0.00010000"], ["111000.80000000", "0.00000000"], ["111001.69000000", "0.00005000"], ["111001.71000000", "0.00005000"], ["111003.86000000", "0.00005000"], ["111004.08000000", "0.04548000"], ["111005.15000000", "0.00000000"], ["111006.09000000", "0.04000000"], ["111025.73000000", "0.22535000"], ["111026.64000000", "0.00250000"]]}}
{"type": "orderbook", "local_time": 1761342396188, "event_time": 1761342396214, "latency_ms": -26, "data": {"e": "depthUpdate", "E": 1761342396214, "s": "BTCUSDT", "U": 79012701176, "u": 79012701237, "b": [["110998.47000000", "0.55150000"], ["110998.46000000", "0.00621000"], ["110997.40000000", "0.03226000"], ["110996.57000000", "0.00725000"], ["110994.87000000", "0.05437000"], ["110994.29000000", "0.05961000"], ["110958.01000000", "0.02498000"], ["110933.01000000", "0.01712000"], ["110705.98000000", "0.02498000"], ["110705.92000000", "0.02498000"], ["110684.64000000", "0.00000000"]], "a": [["110998.48000000", "1.91970000"], ["110998.49000000", "0.00010000"], ["110998.81000000", "0.00907000"], ["110998.91000000", "0.00000000"], ["110998.92000000", "0.00000000"], ["110999.85000000", "0.00010000"], ["110999.86000000", "0.04581000"], ["111001.69000000", "0.00000000"], ["111001.71000000", "0.00000000"], ["111003.11000000", "0.00005000"], ["111003.12000000", "0.20292000"], ["111003.86000000", "0.00000000"], ["111004.08000000", "0.04553000"], ["111004.39000000", "0.29729000"], ["111004.44000000", "0.00518000"], ["111004.62000000", "0.21476000"], ["111005.13000000", "0.00546000"], ["111010.91000000", "0.00074000"]]}}
{"type": "orderbook", "local_time": 1761342396233, "event_time": 1761342396314, "latency_ms": -81, "data": {"e": "depthUpdate", "E": 1761342396314, "s": "BTCUSDT", "U": 79012701238, "u": 79012701268, "b": [["110998.47000000", "0.55205000"], ["110998.46000000", "0.00621000"], ["110998.18000000", "0.05061000"], ["110997.47000000", "0.00010000"], ["110996.40000000", "0.04556000"], ["110972.03000000", "0.00000000"], ["99898.00000000", "0.03587000"]], "a": [["110998.48000000", "1.91341000"], ["110998.81000000", "0.00917000"], ["110999.26000000", "0.20312000"], ["110999.27000000", "0.23993000"], ["111004.44000000", "0.00518000"], ["111004.62000000", "0.21481000"], ["111005.13000000", "0.00541000"], ["111022.20000000", "0.00250000"], ["111026.64000000", "0.00000000"], ["111029.87000000", "0.00044000"]]}}
{"type": "orderbook", "local_time": 1761342396338, "event_time": 1761342396414, "latency_ms": -76, "data": {"e": "depthUpdate", "E": 1761342396414, "s": "BTCUSDT", "U": 79012701269, "u": 79012701283, "b": [["110998.47000000", "0.55279000"], ["110994.45000000", "0.00000000"], ["110695.11000000", "0.00000000"], ["110681.77000000", "0.00401000"]], "a": [["111001.90000000", "0.04548000"], ["111004.08000000", "0.00005000"], ["111005.03000000", "0.00000000"], ["111006.09000000", "0.00000000"], ["111008.59000000", "0.04000000"], ["111016.41000000", "0.00000000"], ["111016.68000000", "0.01802000"], ["111092.28000000", "0.00402000"], ["111105.82000000", "0.00000000"], ["111266.41000000", "0.00089000"], ["111279.96000000", "0.00000000"]]}}
{"type": "orderbook", "local_time": 1761342396435, "event_time": 1761342396514, "latency_ms": -79, "data": {"e": "depthUpdate", "E": 1761342396514, "s": "BTCUSDT", "U": 79012701284, "u": 79012701306, "b": [["110998.47000000", "0.55344000"], ["110998.46000000", "0.00616000"], ["110994.87000000", "0.05437000"], ["110992.25000000", "0.04536000"], ["110989.05000000", "0.00000000"], ["110987.68000000", "0.18014000"], ["110923.87000000", "0.00000000"], ["110899.67000000", "0.03218000"]], "a": [["110998.48000000", "1.91346000"], ["110999.86000000", "0.04581000"], ["111001.89000000", "0.00005000"], ["111001.90000000", "0.04558000"], ["111003.12000000", "0.20287000"], ["111004.08000000", "0.00000000"], ["111007.30000000", "0.00000000"], ["111008.58000000", "0.00450000"], ["115000.00000000", "198.91802000"]]}}
{"type": "orderbook", "local_time": 1761342396534, "event_time": 1761342396614, "latency_ms": -80, "data": {"e": "depthUpdate", "E": 1761342396614, "s": "BTCUSDT", "U": 79012701307, "u": 79012701312, "b": [["110998.47000000", "0.55349000"], ["110998.46000000", "0.00616000"], ["110994.29000000", "0.02925000"]], "a": []}}
{"type": "orderbook", "local_time": 1761342396635, "event_time": 1761342396714, "latency_ms": -79, "data": {"e": "depthUpdate", "E": 1761342396714, "s": "BTCUSDT", "U": 79012701313, "u": 79012701335, "b": [["110998.47000000", "0.55351000"], ["110992.25000000", "0.00000000"], ["110991.12000000", "0.00000000"], ["110989.84000000", "0.00000000"], ["110987.45000000", "0.00000000"], ["110986.35000000", "0.04536000"], ["110977.25000000", "0.00000000"], ["110974.73000000", "0.30399000"], ["110968.92000000", "0.00250000"], ["110964.48000000", "0.00250000"], ["99898.00000000", "0.03587000"]], "a": [["110998.48000000", "1.95889000"], ["110999.32000000", "0.05046000"], ["111000.00000000", "0.00255000"], ["111000.04000000", "0.00000000"], ["111001.90000000", "0.00010000"], ["111010.91000000", "0.00000000"], ["111022.20000000", "0.00000000"]]}}
{"type": "orderbook", "local_time": 1761342396746, "event_time": 1761342396814, "latency_ms": -68, "data": {"e": "depthUpdate", "E": 1761342396814, "s": "BTCUSDT", "U": 79012701336, "u": 79012701367, "b": [["110998.47000000", "0.55324000"], ["110998.46000000", "0.00601000"], ["110994.29000000", "0.00000000"]], "a": [["110998.48000000", "1.95962000"], ["110999.27000000", "0.23993000"], ["110999.31000000", "0.00010000"], ["110999.32000000", "0.05056000"], ["110999.86000000", "0.04581000"], ["111001.89000000", "0.00000000"], ["111001.90000000", "0.00000000"], ["111003.11000000", "0.00000000"], ["111016.68000000", "0.00000000"], ["111016.74000000", "0.01802000"]]}}
{"type": "orderbook", "local_time": 1761342396846, "event_time": 1761342396914, "latency_ms": -68, "data": {"e": "depthUpdate", "E": 1761342396914, "s": "BTCUSDT", "U": 79012701368, "u": 79012701389, "b": [["110998.47000000", "0.55314000"], ["110998.46000000", "0.00596000"], ["110997.41000000", "0.70180000"], ["110996.41000000", "0.00010000"], ["110995.99000000", "0.00005000"], ["110994.87000000", "0.05437000"], ["110970.70000000", "0.00576000"], ["109333.49000000", "0.00100000"], ["99898.00000000", "0.03607000"]], "a": [["110998.48000000", "1.95887000"], ["110998.49000000", "0.00015000"], ["111016.74000000", "0.00000000"], ["111016.75000000", "0.01802000"], ["112663.46000000", "0.00100000"]]}}
{"type": "orderbook", "local_time": 1761342396937, "event_time": 1761342397014, "latency_ms": -77, "data": {"e": "depthUpdate", "E": 1761342397014, "s": "BTCUSDT", "U": 79012701390, "u": 79012701455, "b": [["110998.47000000", "0.55324000"], ["110997.47000000", "0.00010000"], ["110997.46000000", "0.30860000"], ["110997.42000000", "0.00010000"], ["110997.41000000", "0.00015000"], ["110997.40000000", "0.03221000"], ["110996.40000000", "0.04551000"], ["110994.87000000", "0.05432000"], ["110970.70000000", "0.00000000"], ["110918.03000000", "0.00000000"], ["110904.64000000", "0.03218000"], ["110899.67000000", "0.00000000"], ["110852.01000000", "0.00000000"], ["110740.01000000", "0.00000000"], ["99898.00000000", "0.03587000"]], "a": [["110998.48000000", "2.90516000"], ["110998.49000000", "0.00000000"], ["111004.62000000", "0.00005000"], ["111005.24000000", "0.00450000"], ["111007.31000000", "0.00390000"], ["111008.58000000", "0.00000000"], ["111010.83000000", "0.00072000"], ["111011.90000000", "0.00000000"], ["111016.75000000", "0.00000000"], ["111016.77000000", "0.01802000"], ["111025.31000000", "0.00000000"], ["111025.73000000", "0.00000000"], ["111031.42000000", "0.00000000"], ["111044.59000000", "0.00000000"], ["111062.73000000", "0.00000000"], ["111089.36000000", "0.26811000"], ["111089.50000000", "0.00000000"], ["111090.08000000", "0.13511000"], ["111090.13000000", "0.00000000"], ["111090.25000000", "0.00000000"], ["111090.83000000", "0.00000000"], ["111090.87000000", "0.18027000"]]}}
{"type": "orderbook", "local_time": 1761342397035, "event_time": 1761342397114, "latency_ms": -79, "data": {"e": "depthUpdate", "E": 1761342397114, "s": "BTCUSDT", "U": 79012701456, "u": 79012701503, "b": [["110998.47000000", "0.55319000"], ["110998.27000000", "0.00000000"], ["110998.18000000", "0.00030000"], ["110997.46000000", "0.10530000"], ["110997.42000000", "0.00000000"], ["110997.41000000", "0.00010000"], ["110997.40000000", "0.03226000"], ["110997.12000000", "0.00012000"], ["110996.40000000", "0.04556000"], ["110994.87000000", "0.05437000"], ["110987.68000000", "0.00000000"], ["110986.74000000", "0.18014000"], ["110984.00000000", "0.00000000"], ["110954.08000000", "0.00010000"], ["110852.01000000", "0.00224000"], ["110740.01000000", "0.00090000"]], "a": [["110998.48000000", "2.45528000"], ["111004.44000000", "0.00518000"], ["111004.62000000", "0.00000000"], ["111005.13000000", "0.00546000"], ["111010.83000000", "0.00000000"], ["111011.86000000", "0.13524000"], ["111014.95000000", "0.00044000"], ["111016.77000000", "0.00000000"], ["111016.78000000", "0.01802000"], ["111026.05000000", "0.18027000"], ["111038.44000000", "0.00000000"], ["111039.14000000", "0.13641000"], ["111063.46000000", "0.13524000"], ["111089.36000000", "0.15175000"], ["111089.51000000", "0.00000000"], ["111090.22000000", "0.22544000"], ["111090.67000000", "0.22535000"]]}}
{"type": "orderbook", "local_time": 1761342397146, "event_time": 1761342397214, "latency_ms": -68, "data": {"e": "depthUpdate", "E": 1761342397214, "s": "BTCUSDT", "U": 79012701504, "u": 79012701531, "b": [["110998.47000000", "0.55103000"], ["110998.46000000", "0.00601000"], ["110998.19000000", "0.00000000"], ["110998.18000000", "0.00020000"], ["110997.13000000", "0.70170000"], ["110995.99000000", "0.00010000"], ["110995.98000000", "0.20766000"], ["110995.00000000", "0.00005000"], ["110991.82000000", "0.00546000"], ["110988.26000000", "0.04536000"], ["110986.35000000", "0.00000000"], ["99898.00000000", "0.03587000"]], "a": [["110999.83000000", "0.06748000"], ["111004.55000000", "0.21476000"]]}}
{"type": "orderbook", "local_time": 1761342397234, "event_time": 1761342397314, "latency_ms": -80, "data": {"e": "depthUpdate", "E": 1761342397314, "s": "BTCUSDT", "U": 79012701532, "u": 79012701585, "b": [["110998.47000000", "0.55113000"], ["110998.46000000", "0.00606000"], ["110998.18000000", "0.00000000"], ["110997.46000000", "0.30878000"], ["110997.40000000", "0.03231000"], ["110997.14000000", "0.00000000"], ["110997.13000000", "0.00010000"], ["110996.96000000", "0.04977000"], ["110995.98000000", "0.20761000"], ["110995.00000000", "0.00005000"], ["110991.82000000", "0.00541000"], ["110929.96000000", "0.01410000"], ["110918.09000000", "0.00000000"]], "a": [["110998.48000000", "2.45528000"], ["110999.32000000", "0.05056000"], ["110999.82000000", "0.00005000"], ["110999.83000000", "0.06758000"], ["110999.85000000", "0.00005000"], ["110999.86000000", "0.04576000"], ["111004.44000000", "0.00518000"], ["111005.13000000", "0.00541000"], ["111005.24000000", "0.00000000"], ["111007.01000000", "0.00450000"]]}}
{"type": "orderbook", "local_time": 1761342397335, "event_time": 1761342397414, "latency_ms": -79, "data": {"e": "depthUpdate", "E": 1761342397414, "s": "BTCUSDT", "U": 79012701586, "u": 79012701609, "b": [["110998.47000000", "0.55118000"], ["110998.46000000", "0.00606000"], ["110997.47000000", "0.18824000"], ["110997.46000000", "0.00030000"], ["110997.40000000", "0.03226000"], ["110997.13000000", "0.00000000"], ["110996.97000000", "0.70175000"], ["110996.96000000", "0.04987000"], ["110995.00000000", "0.00000000"], ["110970.31000000", "0.00576000"], ["110929.96000000", "0.00000000"], ["110758.75000000", "0.00000000"]], "a": [["111241.60000000", "0.00000000"]]}}
{"type": "orderbook", "local_time": 1761342397438, "event_time": 1761342397514, "latency_ms": -76, "data": {"e": "depthUpdate", "E": 1761342397514, "s": "BTCUSDT", "U": 79012701610, "u": 79012701718, "b": [["110998.47000000", "0.55134000"], ["110998.46000000", "0.00611000"], ["110997.48000000", "0.00010000"], ["110997.47000000", "0.31298000"], ["110997.46000000", "0.00010000"], ["110997.40000000", "0.03221000"], ["110996.98000000", "0.00010000"], ["110996.97000000", "0.00010000"], ["110996.96000000", "0.00005000"], ["110996.40000000", "0.04551000"], ["110996.28000000", "0.00000000"], ["110995.99000000", "0.00000000"], ["110994.87000000", "0.05432000"], ["110988.26000000", "0.00000000"], ["110986.52000000", "0.04536000"], ["110984.79000000", "0.00000000"], ["110984.59000000", "0.00000000"], ["110984.22000000", "0.00000000"], ["110983.51000000", "0.00000000"], ["110981.82000000", "0.11417000"], ["110980.97000000", "0.01802000"], ["110980.03000000", "0.00000000"], ["110976.42000000", "0.02000000"], ["110973.96000000", "0.04000000"], ["110973.26000000", "0.08000000"], ["110970.31000000", "0.00000000"], ["110909.40000000", "0.00000000"], ["110894.03000000", "0.01410000"], ["110852.02000000", "0.00225000"], ["110852.01000000", "0.00000000"], ["110740.02000000", "0.00090000"], ["110740.01000000", "0.00000000"]], "a": [["110998.48000000", "2.91887000"], ["111001.28000000", "0.20756000"], ["111004.55000000", "0.00720000"], ["111005.12000000", "0.00450000"], ["111007.01000000", "0.00000000"], ["111009.69000000", "0.00000000"], ["111011.14000000", "0.00000000"], ["111011.86000000", "0.00000000"], ["111012.59000000", "0.00000000"], ["111014.03000000", "0.01802000"], ["111016.78000000", "0.00000000"], ["111024.14000000", "0.00044000"], ["111026.05000000", "0.00000000"], ["111038.44000000", "0.45079000"], ["111039.14000000", "0.00130000"], ["111043.65000000", "0.24764000"], ["111063.01000000", "0.13624000"], ["111063.08000000", "0.00000000"], ["111063.46000000", "0.00000000"], ["111089.36000000", "0.15175000"], ["111089.64000000", "0.00000000"], ["111090.08000000", "0.00000000"], ["111090.22000000", "0.00000000"], ["111090.34000000", "0.00000000"], ["111090.67000000", "0.00000000"], ["111090.87000000", "0.00000000"], ["111090.92000000", "0.18027000"]]}}
{"type": "orderbook", "local_time": 1761342397538, "event_time": 1761342397614, "latency_ms": -76, "data": {"e": "depthUpdate", "E": 1761342397614, "s": "BTCUSDT", "U": 79012701719, "u": 79012701774, "b": [["110998.47000000", "0.54721000"], ["110998.46000000", "0.00601000"], ["110997.47000000", "0.12484000"], ["110997.46000000", "0.00000000"], ["110997.40000000", "0.03226000"], ["110996.98000000", "0.00000000"], ["110996.97000000", "0.00000000"], ["110996.96000000", "0.00000000"], ["110996.57000000", "0.00730000"], ["110995.99000000", "0.00010000"], ["110995.00000000", "0.00005000"], ["110994.87000000", "0.05437000"], ["110991.82000000", "0.00546000"], ["110987.67000000", "0.08834000"], ["110986.25000000", "0.00068000"], ["110985.65000000", "0.00332000"], ["110976.74000000", "0.00000000"], ["110974.08000000", "0.00900000"], ["110972.00000000", "0.00120000"], ["110964.77000000", "0.39784000"]], "a": [["110999.86000000", "0.04576000"], ["111001.28000000", "0.20761000"], ["111004.44000000", "0.00513000"], ["111025.48000000", "0.00441000"], ["111027.39000000", "0.00275000"], ["111038.44000000", "0.45079000"], ["111043.19000000", "0.00000000"], ["111045.10000000", "0.56563000"], ["111089.36000000", "0.00000000"], ["111089.41000000", "0.18027000"], ["111089.44000000", "0.13511000"], ["111090.92000000", "0.00000000"]]}}
{"type": "orderbook", "local_time": 1761342397636, "event_time": 1761342397714, "latency_ms": -78, "data": {"e": "depthUpdate", "E": 1761342397714, "s": "BTCUSDT", "U": 79012701775, "u": 79012701779, "b": [["110982.80000000", "1.44342000"], ["110758.91000000", "0.84083000"]], "a": [["111244.33000000", "4.78900000"], ["111343.41000000", "0.48717000"], ["111347.06000000", "0.00000000"]]}}
{"type": "orderbook", "local_time": 1761342397736, "event_time": 1761342397814, "latency_ms": -78, "data": {"e": "depthUpdate", "E": 1761342397814, "s": "BTCUSDT", "U": 79012701780, "u": 79012701783, "b": [["110998.47000000", "0.59772000"], ["110986.25000000", "0.00000000"], ["110983.34000000", "0.61726000"]], "a": []}}
{"type": "orderbook", "local_time": 1761342397835, "event_time": 1761342397914, "latency_ms": -79, "data": {"e": "depthUpdate", "E": 1761342397914, "s": "BTCUSDT", "U": 79012701784, "u": 79012701809, "b": [["110998.47000000", "0.60070000"], ["110998.46000000", "0.00601000"], ["110997.47000000", "0.12489000"], ["110997.40000000", "0.03231000"], ["110996.40000000", "0.04556000"], ["110995.98000000", "0.20766000"], ["110985.65000000", "0.00000000"], ["109333.49000000", "0.00100000"], ["99898.00000000", "0.03587000"]], "a": [["110998.48000000", "2.91878000"], ["111038.44000000", "0.22535000"], ["112663.46000000", "0.00100000"]]}}
{"type": "orderbook", "local_time": 1761342397935, "event_time": 1761342398014, "latency_ms": -79, "data": {"e": "depthUpdate", "E": 1761342398014, "s": "BTCUSDT", "U": 79012701810, "u": 79012701822, "b": [["110957.51000000", "1.47040000"], ["110931.57000000", "0.00000000"], ["110565.69000000", "0.02698000"], ["110528.47000000", "0.00000000"], ["88799.00000000", "0.00000000"]], "a": [["110998.48000000", "2.60340000"], ["111025.32000000", "0.18027000"], ["111038.32000000", "0.13511000"], ["111038.44000000", "0.00000000"], ["111089.40000000", "0.15295000"], ["111090.00000000", "0.22827000"]]}}
{"type": "orderbook", "local_time": 1761342398034, "event_time": 1761342398114, "latency_ms": -80, "data": {"e": "depthUpdate", "E": 1761342398114, "s": "BTCUSDT", "U": 79012701823, "u": 79012701835, "b": [["110983.47000000", "0.01802000"], ["110983.25000000", "0.00000000"], ["110980.97000000", "0.00000000"], ["110976.48000000", "0.04571000"], ["110967.50000000", "0.00000000"], ["99898.00000000", "0.03587000"]], "a": [["110998.48000000", "2.60347000"], ["111014.03000000", "0.00000000"], ["111015.10000000", "0.00000000"], ["111015.12000000", "0.01892000"], ["111038.23000000", "0.00000000"]]}}
{"type": "orderbook", "local_time": 1761342398136, "event_time": 1761342398214, "latency_ms": -78, "data": {"e": "depthUpdate", "E": 1761342398214, "s": "BTCUSDT", "U": 79012701836, "u": 79012701851, "b": [["110998.47000000", "0.60070000"], ["110998.46000000", "0.00601000"], ["110997.47000000", "0.12489000"], ["110800.89000000", "0.01410000"], ["110792.37000000", "0.00000000"]], "a": [["110998.48000000", "2.24251000"], ["111005.12000000", "0.00000000"], ["111007.01000000", "0.00450000"], ["111012.40000000", "0.13524000"], ["111015.12000000", "0.00090000"], ["111015.14000000", "0.01802000"], ["111025.20000000", "0.22549000"]]}}
{"type": "orderbook", "local_time": 1761342398235, "event_time": 1761342398314, "latency_ms": -79, "data": {"e": "depthUpdate", "E": 1761342398314, "s": "BTCUSDT", "U": 79012701852, "u": 79012701858, "b": [["110971.33000000", "0.83922000"]], "a": [["110998.48000000", "2.19743000"], ["111007.31000000", "0.04898000"], ["111033.01000000", "0.98523000"], ["111038.44000000", "0.22535000"], ["111090.00000000", "0.00292000"], ["111091.89000000", "0.22544000"]]}}
{"type": "orderbook", "local_time": 1761342398337, "event_time": 1761342398414, "latency_ms": -77, "data": {"e": "depthUpdate", "E": 1761342398414, "s": "BTCUSDT", "U": 79012701859, "u": 79012701860, "b": [], "a": [["111015.14000000", "0.00000000"], ["111015.15000000", "0.01802000"]]}}
{"type": "orderbook", "local_time": 1761342398435, "event_time": 1761342398514, "latency_ms": -79, "data": {"e": "depthUpdate", "E": 1761342398514, "s": "BTCUSDT", "U": 79012701861, "u": 79012701861, "b": [["39959.45000000", "0.00016000"]], "a": []}}
{"type": "orderbook", "local_time": 1761342398536, "event_time": 1761342398614, "latency_ms": -78, "data": {"e": "depthUpdate", "E": 1761342398614, "s": "BTCUSDT", "U": 79012701862, "u": 79012701863, "b": [], "a": [["111038.44000000", "0.00000000"], ["111089.62000000", "0.22535000"]]}}
{"type": "orderbook", "local_time": 1761342398636, "event_time": 1761342398714, "latency_ms": -78, "data": {"e": "depthUpdate", "E": 1761342398714, "s": "BTCUSDT", "U": 79012701864, "u": 79012701878, "b": [["110998.47000000", "0.60070000"], ["110998.46000000", "0.00601000"], ["110997.47000000", "0.12489000"], ["110694.98000000", "0.00401000"], ["110681.77000000", "0.00000000"], ["99898.00000000", "0.03587000"]], "a": [["110998.48000000", "2.19725000"], ["111092.28000000", "0.00000000"], ["111105.53000000", "0.02708000"], ["111266.41000000", "0.00000000"], ["111279.67000000", "0.00106000"]]}}
{"type": "orderbook", "local_time": 1761342398735, "event_time": 1761342398814, "latency_ms": -79, "data": {"e": "depthUpdate", "E": 1761342398814, "s": "BTCUSDT", "U": 79012701879, "u": 79012701883, "b": [["110988.53000000", "0.04536000"], ["110986.52000000", "0.00000000"], ["42000.00000000", "1.36834000"]], "a": [["111015.15000000", "0.00000000"], ["111015.17000000", "0.01802000"]]}}
{"type": "orderbook", "local_time": 1761342398835, "event_time": 1761342398914, "latency_ms": -79, "data": {"e": "depthUpdate", "E": 1761342398914, "s": "BTCUSDT", "U": 79012701884, "u": 79012701892, "b": [["110998.47000000", "0.60070000"], ["110998.46000000", "0.00601000"], ["109333.49000000", "0.00100000"], ["102145.79000000", "0.00010000"]], "a": [["112663.46000000", "0.00100000"]]}}
{"type": "orderbook", "local_time": 1761342398936, "event_time": 1761342399014, "latency_ms": -78, "data": {"e": "depthUpdate", "E": 1761342399014, "s": "BTCUSDT", "U": 79012701893, "u": 79012701897, "b": [["110931.30000000", "0.00000000"], ["109599.87000000", "0.02501000"]], "a": [["111015.17000000", "0.00000000"], ["111015.18000000", "0.01802000"]]}}
{"type": "orderbook", "local_time": 1761342399037, "event_time": 1761342399114, "latency_ms": -77, "data": {"e": "depthUpdate", "E": 1761342399114, "s": "BTCUSDT", "U": 79012701898, "u": 79012702005, "b": [["110998.47000000", "0.36957000"], ["110997.36000000", "0.00000000"], ["110995.50000000", "0.00005000"], ["110994.99000000", "0.00005000"], ["110993.66000000", "0.02704000"], ["110988.53000000", "0.00000000"], ["110986.74000000", "0.00000000"], ["110986.20000000", "0.00072000"], ["110986.15000000", "0.00000000"], ["110985.83000000", "0.00070000"], ["110985.26000000", "0.00331000"], ["110984.05000000", "0.18014000"], ["110983.93000000", "0.04536000"], ["110981.82000000", "0.00150000"], ["110979.06000000", "0.00000000"], ["110976.49000000", "0.00450000"], ["110976.42000000", "0.00000000"], ["110976.27000000", "0.11267000"], ["110974.08000000", "0.00000000"], ["110973.96000000", "0.00000000"], ["110973.26000000", "0.00000000"], ["110972.67000000", "0.14000000"], ["110971.92000000", "0.00000000"], ["110971.87000000", "0.16000000"], ["110970.88000000", "0.00900000"], ["110969.99000000", "0.00000000"], ["110969.94000000", "0.00000000"], ["110968.67000000", "0.00000000"], ["110967.80000000", "0.00000000"], ["110966.76000000", "0.00000000"], ["110965.32000000", "0.04000000"], ["110961.66000000", "0.00000000"], ["110955.28000000", "0.00000000"], ["110946.81000000", "0.00000000"], ["110914.09000000", "0.00000000"], ["110892.19000000", "0.00000000"], ["110886.31000000", "0.07396000"], ["110880.00000000", "0.01984000"], ["110866.01000000", "0.06310000"], ["110852.03000000", "0.00225000"], ["110852.02000000", "0.00000000"], ["110740.03000000", "0.00090000"], ["110740.02000000", "0.00000000"], ["110703.48000000", "0.00000000"], ["110700.67000000", "0.00000000"], ["110689.01000000", "0.00000000"], ["110686.95000000", "0.00000000"], ["110686.82000000", "0.00000000"], ["110679.20000000", "0.00000000"], ["110658.83000000", "0.02198000"], ["110654.76000000", "0.03698000"], ["110653.97000000", "0.03698000"], ["110653.19000000", "0.03698000"], ["110590.32000000", "0.00000000"], ["110556.30000000", "0.00000000"], ["110553.34000000", "0.00000000"], ["110553.20000000", "0.00000000"], ["110552.62000000", "0.00000000"], ["110552.02000000", "0.00000000"], ["110550.09000000", "0.00000000"], ["110522.14000000", "0.03698000"], ["110521.29000000", "0.03698000"], ["110520.50000000", "0.03698000"], ["110519.73000000", "0.03698000"], ["110518.91000000", "0.03698000"], ["110518.08000000", "0.03698000"], ["99898.00000000", "0.03597000"]], "a": [["110998.48000000", "3.12572000"], ["111001.04000000", "0.29725000"], ["111004.39000000", "0.00005000"], ["111007.31000000", "0.00390000"], ["111008.59000000", "0.00000000"], ["111012.36000000", "0.00000000"], ["111014.34000000", "0.01802000"], ["111015.18000000", "0.00000000"], ["111019.45000000", "0.07664000"], ["111038.44000000", "0.22535000"], ["111040.98000000", "0.32416000"], ["111044.51000000", "0.00000000"], ["111045.11000000", "0.00000000"], ["111049.45000000", "0.30044000"], ["111054.78000000", "0.04493000"], ["111063.01000000", "0.00100000"], ["111063.63000000", "0.00000000"], ["111064.36000000", "0.00000000"], ["111068.92000000", "0.04711000"], ["111089.40000000", "0.26675000"], ["111089.41000000", "0.00000000"], ["111089.44000000", "0.00000000"], ["111089.62000000", "0.00000000"], ["111091.89000000", "0.00000000"], ["111121.94000000", "0.00000000"]]}}
{"type": "orderbook", "local_time": 1761342409464, "event_time": 1761342399214, "latency_ms": 10250, "data": {"e": "depthUpdate", "E": 1761342399214, "s": "BTCUSDT", "U": 79012702006, "u": 79012702059, "b": [["110998.47000000", "0.16714000"], ["110998.46000000", "0.00596000"], ["110995.98000000", "0.20766000"], ["110995.34000000", "0.29727000"], ["110995.00000000", "0.00000000"], ["110994.99000000", "0.00000000"], ["110994.88000000", "0.00005000"], ["110994.87000000", "0.05437000"], ["110993.67000000", "0.01692000"], ["110993.66000000", "0.00005000"], ["110993.56000000", "0.02704000"], ["110986.27000000", "0.00070000"], ["110986.20000000", "0.00000000"], ["110985.83000000", "0.00000000"], ["110965.74000000", "0.00009000"], ["110963.60000000", "0.00009000"], ["110962.56000000", "0.00009000"], ["110957.46000000", "0.00009000"], ["110951.08000000", "0.00009000"], ["110929.65000000", "0.00350000"], ["110909.89000000", "0.00090000"], ["99898.00000000", "0.03587000"]], "a": [["110999.86000000", "0.04576000"], ["111001.04000000", "0.29730000"], ["111003.12000000", "0.20287000"], ["111004.39000000", "0.00000000"], ["111014.34000000", "0.00000000"], ["111014.35000000", "0.01802000"], ["111067.19000000", "0.00000000"], ["111089.40000000", "0.00000000"]]}}
{"type": "orderbook", "local_time": 1761342409465, "event_time": 1761342399314, "latency_ms": 10151, "data": {"e": "depthUpdate", "E": 1761342399314, "s": "BTCUSDT", "U": 79012702060, "u": 79012702091, "b": [["110998.47000000", "0.16793000"], ["110998.46000000", "0.00606000"], ["110995.98000000", "0.20766000"], ["110995.34000000", "0.29732000"], ["110994.87000000", "0.05437000"], ["110993.67000000", "0.01697000"], ["110993.66000000", "0.00000000"], ["110991.82000000", "0.00541000"], ["110986.27000000", "0.00000000"], ["110985.86000000", "0.00000000"], ["110985.26000000", "0.00000000"], ["110954.15000000", "0.36563000"], ["110877.02000000", "0.36588000"]], "a": [["111025.32000000", "0.00000000"], ["111030.15000000", "0.36538000"], ["111038.32000000", "0.00000000"], ["111089.13000000", "0.13511000"], ["111107.40000000", "0.36512000"]]}}
{"type": "orderbook", "local_time": 1761342409465, "event_time": 1761342399414, "latency_ms": 10051, "data": {"e": "depthUpdate", "E": 1761342399414, "s": "BTCUSDT", "U": 79012702092, "u": 79012702106, "b": [["110998.47000000", "0.12678000"], ["110998.46000000", "0.02535000"], ["99898.00000000", "0.03587000"]], "a": [["110998.48000000", "3.57649000"], ["111089.29000000", "0.18027000"], ["111089.31000000", "0.00000000"]]}}
{"type": "orderbook", "local_time": 1761342409466, "event_time": 1761342399514, "latency_ms": 9952, "data": {"e": "depthUpdate", "E": 1761342399514, "s": "BTCUSDT", "U": 79012702107, "u": 79012702123, "b": [["110998.47000000", "0.12286000"], ["110998.46000000", "0.02540000"], ["110995.98000000", "0.20761000"], ["110994.88000000", "0.00000000"], ["110986.12000000", "0.04536000"], ["110985.97000000", "0.00327000"], ["110983.93000000", "0.00000000"], ["110635.81000000", "0.00000000"], ["110634.15000000", "0.00025000"], ["110631.92000000", "0.00000000"], ["110629.85000000", "0.00000000"], ["102145.79000000", "0.00000000"]], "a": [["111038.44000000", "0.40562000"], ["111089.29000000", "0.00000000"]]}}
{"type": "orderbook", "local_time": 1761342409466, "event_time": 1761342399614, "latency_ms": 9852, "data": {"e": "depthUpdate", "E": 1761342399614, "s": "BTCUSDT", "U": 79012702124, "u": 79012702140, "b": [["110998.47000000", "0.12209000"], ["110997.47000000", "0.17748000"], ["110986.22000000", "0.00070000"], ["110971.87000000", "0.00000000"], ["110970.67000000", "0.16000000"], ["110944.47000000", "0.06704000"], ["110661.74000000", "0.02198000"], ["110659.86000000", "0.02198000"], ["110657.22000000", "0.02198000"], ["110656.73000000", "0.02198000"]], "a": [["110998.48000000", "3.57725000"], ["111038.44000000", "0.54073000"], ["111049.13000000", "0.00000000"], ["111089.13000000", "0.00000000"], ["111245.47000000", "0.00000000"]]}}
{"type": "orderbook", "local_time": 1761342409866, "event_time": 1761342399714, "latency_ms": 10152, "data": {"e": "depthUpdate", "E": 1761342399714, "s": "BTCUSDT", "U": 79012702141, "u": 79012702178, "b": [["110998.47000000", "0.10195000"], ["110986.21000000", "0.00000000"], ["110983.47000000", "0.00000000"], ["110972.67000000", "0.00000000"], ["110970.77000000", "0.02000000"], ["110970.67000000", "0.04000000"], ["110970.47000000", "0.08000000"], ["110969.37000000", "0.16000000"], ["110944.47000000", "0.00000000"], ["110896.13000000", "0.00000000"], ["110852.03000000", "0.00000000"], ["110740.03000000", "0.00000000"], ["110678.12000000", "0.00000000"], ["110549.44000000", "0.00000000"]], "a": [["110998.48000000", "3.59977000"], ["111000.92000000", "0.00720000"], ["111004.03000000", "0.11267000"], ["111004.55000000", "0.00000000"], ["111012.40000000", "0.00000000"], ["111017.73000000", "0.00000000"], ["111038.44000000", "0.22535000"], ["111062.75000000", "0.13524000"], ["111065.95000000", "0.00007000"], ["111070.16000000", "0.00000000"], ["111089.01000000", "0.00000000"], ["111089.94000000", "0.00000000"]]}}
{"type": "orderbook", "local_time": 1761342409867, "event_time": 1761342399814, "latency_ms": 10053, "data": {"e": "depthUpdate", "E": 1761342399814, "s": "BTCUSDT", "U": 79012702179, "u": 79012702257, "b": [["110998.47000000", "0.00654000"], ["110997.94000000", "0.00000000"], ["110997.47000000", "0.00030000"], ["110997.06000000", "0.00000000"], ["110996.57000000", "0.00010000"], ["110995.98000000", "0.00010000"], ["110995.34000000", "0.00005000"], ["110994.27000000", "0.00000000"], ["110993.67000000", "0.00005000"], ["110993.56000000", "0.00000000"], ["110993.15000000", "0.02704000"], ["110992.20000000", "0.29732000"], ["110991.16000000", "0.00000000"], ["110990.00000000", "0.00005000"], ["110989.46000000", "0.00000000"], ["110989.05000000", "0.00000000"], ["110986.12000000", "0.00000000"], ["110985.28000000", "0.00072000"], ["110984.06000000", "0.18015000"], ["110984.05000000", "0.00000000"], ["110982.80000000", "0.00000000"], ["110982.61000000", "0.00000000"], ["110982.54000000", "0.04536000"], ["110981.30000000", "0.01802000"], ["110975.77000000", "0.00000000"], ["110969.37000000", "0.00000000"], ["110968.02000000", "0.00000000"], ["110967.26000000", "0.16000000"], ["110948.49000000", "0.00000000"], ["110943.67000000", "0.06682000"], ["110929.65000000", "0.00000000"], ["110900.31000000", "0.00000000"], ["110877.31000000", "0.01483000"], ["110852.01000000", "0.00224000"], ["110740.01000000", "0.00090000"], ["110711.34000000", "0.00000000"], ["110703.88000000", "0.00000000"], ["110658.13000000", "0.02198000"], ["110514.97000000", "0.03698000"]], "a": [["110998.48000000", "3.82899000"], ["110999.82000000", "0.00000000"], ["110999.85000000", "0.00000000"], ["110999.86000000", "0.04576000"], ["111000.92000000", "0.21481000"], ["111001.28000000", "0.00005000"], ["111003.12000000", "0.20282000"], ["111038.44000000", "0.54073000"], ["111056.92000000", "0.04097000"], ["111059.99000000", "0.04097000"], ["111062.93000000", "0.13519000"], ["111073.52000000", "0.00000000"], ["111091.95000000", "0.01410000"], ["111099.81000000", "0.89997000"], ["111225.06000000", "0.00000000"], ["111282.60000000", "0.00016000"], ["111284.69000000", "0.03698000"], ["111359.30000000", "0.00000000"], ["111421.58000000", "0.00000000"], ["111462.37000000", "0.03698000"], ["111580.43000000", "0.00000000"]]}}
{"type": "orderbook", "local_time": 1761342409867, "event_time": 1761342399914, "latency_ms": 9953, "data": {"e": "depthUpdate", "E": 1761342399914, "s": "BTCUSDT", "U": 79012702258, "u": 79012702389, "b": [["110998.47000000", "0.00558000"], ["110998.46000000", "0.02525000"], ["110997.48000000", "0.00000000"], ["110997.47000000", "0.00020000"], ["110997.40000000", "0.03231000"], ["110997.12000000", "0.00000000"], ["110996.57000000", "0.00000000"], ["110996.40000000", "0.04561000"], ["110995.99000000", "0.00000000"], ["110995.98000000", "0.00000000"], ["110995.74000000", "0.00010000"], ["110995.34000000", "0.00000000"], ["110994.88000000", "0.00010000"], ["110994.87000000", "0.05437000"], ["110993.67000000", "0.00000000"], ["110993.16000000", "0.00005000"], ["110993.15000000", "0.00005000"], ["110993.01000000", "0.00000000"], ["110992.67000000", "0.02540000"], ["110992.20000000", "0.29737000"], ["110991.82000000", "0.00546000"], ["110990.67000000", "0.04904000"], ["110987.90000000", "0.01776000"], ["110987.67000000", "0.08839000"], ["110987.38000000", "0.00726000"], ["110983.34000000", "0.18622000"], ["110983.00000000", "0.00000000"], ["110981.30000000", "0.00000000"], ["110979.05000000", "0.00000000"], ["110977.61000000", "0.01802000"], ["110974.72000000", "0.00000000"], ["110972.27000000", "0.00000000"], ["110965.74000000", "0.00000000"], ["110963.60000000", "0.00000000"], ["110962.56000000", "0.00000000"], ["110960.04000000", "0.00250000"], ["110958.09000000", "0.13519000"], ["110957.52000000", "0.21140000"], ["110957.46000000", "0.00000000"], ["110951.08000000", "0.00000000"], ["110943.67000000", "0.00000000"], ["110941.12000000", "0.13511000"], ["110939.27000000", "0.00000000"], ["110934.95000000", "0.01916000"], ["110909.89000000", "0.00000000"], ["110904.81000000", "0.13519000"], ["110904.64000000", "0.00000000"], ["110895.55000000", "0.00000000"], ["110894.03000000", "0.00000000"], ["110885.11000000", "0.00000000"], ["110880.26000000", "0.13914000"], ["110827.83000000", "0.00000000"], ["110788.52000000", "0.02161000"], ["109333.49000000", "0.00000000"]], "a": [["110998.80000000", "0.00000000"], ["110999.25000000", "0.00000000"], ["110999.26000000", "0.20302000"], ["110999.31000000", "0.00000000"], ["111001.04000000", "0.29730000"], ["111001.28000000", "0.00000000"], ["111003.12000000", "0.20287000"], ["111009.24000000", "0.01802000"], ["111014.35000000", "0.00000000"], ["111039.18000000", "0.04008000"], ["111057.75000000", "0.00000000"], ["111059.49000000", "0.00620000"], ["111063.99000000", "0.03326000"], ["111073.67000000", "0.00000000"], ["111082.48000000", "0.00000000"], ["111090.82000000", "0.06446000"], ["111091.95000000", "0.00000000"], ["111208.80000000", "0.00000000"], ["111343.41000000", "0.00000000"]]}}
{"type": "orderbook", "local_time": 1761342410572, "event_time": 1761342400014, "latency_ms": 10558, "data": {"e": "depthUpdate", "E": 1761342400014, "s": "BTCUSDT", "U": 79012702390, "u": 79012702452, "b": [["110998.47000000", "0.00548000"], ["110998.46000000", "0.02535000"], ["110997.47000000", "0.00000000"], ["110997.40000000", "0.03241000"], ["110996.40000000", "0.04566000"], ["110995.70000000", "0.00203000"], ["110994.87000000", "0.05437000"], ["110993.16000000", "0.00000000"], ["110993.15000000", "0.00000000"], ["110992.68000000", "0.00005000"], ["110992.67000000", "0.02545000"], ["110991.82000000", "0.00546000"], ["110990.67000000", "0.04909000"], ["110989.77000000", "0.21476000"], ["110987.90000000", "0.01781000"], ["110987.67000000", "0.08834000"], ["110987.38000000", "0.00721000"], ["110964.04000000", "0.00009000"], ["110961.90000000", "0.00009000"], ["110960.86000000", "0.00009000"], ["110955.76000000", "0.00009000"], ["110949.38000000", "0.00009000"], ["110908.19000000", "0.00095000"], ["110887.48000000", "0.03218000"], ["110854.19000000", "0.01410000"], ["110559.76000000", "0.02698000"], ["109333.49000000", "0.00100000"], ["99898.00000000", "0.03587000"]], "a": [["110998.48000000", "3.82792000"], ["111020.24000000", "0.00000000"], ["111062.37000000", "0.13511000"], ["112663.46000000", "0.00100000"]]}}
{"type": "orderbook", "local_time": 1761342410573, "event_time": 1761342400114, "latency_ms": 10459, "data": {"e": "depthUpdate", "E": 1761342400114, "s": "BTCUSDT", "U": 79012702453, "u": 79012702505, "b": [["110998.47000000", "0.00604000"], ["110998.46000000", "0.00606000"], ["110994.97000000", "0.29727000"], ["110994.87000000", "0.05442000"], ["110992.67000000", "0.02550000"], ["110992.20000000", "0.00010000"], ["110990.67000000", "0.04909000"], ["110989.77000000", "0.21481000"], ["110987.90000000", "0.01776000"], ["110970.47000000", "0.00000000"], ["110966.96000000", "0.08000000"], ["110945.15000000", "0.02432000"], ["110926.81000000", "0.00470000"], ["110919.72000000", "0.00000000"], ["110886.31000000", "0.03698000"], ["110862.01000000", "0.03698000"], ["110854.19000000", "0.00000000"], ["110661.04000000", "0.00000000"], ["110660.16000000", "0.00000000"], ["110658.67000000", "0.00000000"], ["110657.20000000", "0.00000000"], ["110656.92000000", "0.03698000"], ["110656.81000000", "0.03698000"], ["110656.63000000", "0.03698000"], ["110656.25000000", "0.02432000"], ["110656.22000000", "0.03698000"], ["110655.79000000", "0.03698000"], ["110655.72000000", "0.00000000"], ["110654.95000000", "0.02432000"], ["110654.60000000", "0.00000000"], ["110654.49000000", "0.03698000"], ["110654.45000000", "0.00000000"], ["110654.02000000", "0.00000000"], ["110653.63000000", "0.00000000"], ["110653.48000000", "0.03698000"], ["110653.42000000", "0.02432000"], ["110652.20000000", "0.03698000"], ["110650.67000000", "0.03698000"], ["110634.06000000", "0.00000000"], ["110629.02000000", "0.00000000"], ["110628.56000000", "0.00000000"]], "a": [["110998.48000000", "3.73381000"], ["111016.62000000", "0.00000000"], ["111024.76000000", "0.00900000"], ["111030.62000000", "0.00000000"], ["111068.91000000", "0.10960000"], ["111206.19000000", "0.00000000"], ["111335.05000000", "0.04097000"]]}}
{"type": "orderbook", "local_time": 1761342410573, "event_time": 1761342400214, "latency_ms": 10359, "data": {"e": "depthUpdate", "E": 1761342400214, "s": "BTCUSDT", "U": 79012702506, "u": 79012702806, "b": [["110998.47000000", "0.00000000"], ["110998.46000000", "0.00000000"], ["110997.51000000", "0.00000000"], ["110997.41000000", "0.00000000"], ["110997.40000000", "0.00777000"], ["110997.39000000", "0.00090000"], ["110996.40000000", "0.04576000"], ["110995.74000000", "0.00000000"], ["110995.70000000", "0.00218000"], ["110994.98000000", "0.00010000"], ["110994.97000000", "0.00020000"], ["110994.87000000", "0.05447000"], ["110993.62000000", "0.00000000"], ["110992.68000000", "0.00010000"], ["110992.67000000", "0.00010000"], ["110992.60000000", "0.00606000"], ["110992.20000000", "0.00005000"], ["110991.91000000", "0.29728000"], ["110991.56000000", "0.00010000"], ["110990.68000000", "0.08056000"], ["110990.67000000", "0.00010000"], ["110990.55000000", "0.02946000"], ["110990.42000000", "0.05054000"], ["110987.90000000", "0.00005000"], ["110987.67000000", "0.08839000"], ["110987.38000000", "0.00721000"], ["110970.67000000", "0.00000000"], ["110969.27000000", "0.04000000"], ["110964.04000000", "0.00000000"], ["110961.90000000", "0.00000000"], ["110960.86000000", "0.00000000"], ["110955.76000000", "0.00000000"], ["110949.38000000", "0.00000000"], ["110943.25000000", "0.00000000"], ["110943.10000000", "0.00000000"], ["110942.60000000", "0.05105000"], ["110942.36000000", "0.06624000"], ["110941.32000000", "0.00000000"], ["110914.64000000", "0.00000000"], ["110911.87000000", "0.00000000"], ["110908.19000000", "0.00005000"], ["110906.01000000", "0.01892000"], ["110905.43000000", "0.00000000"], ["110897.17000000", "0.00000000"], ["110890.56000000", "0.00000000"], ["110885.00000000", "0.11380000"], ["110881.02000000", "0.00000000"], ["110868.01000000", "0.02612000"], ["110860.01000000", "0.06219000"], ["110836.01000000", "0.00000000"], ["110832.83000000", "0.00000000"], ["110828.51000000", "0.00000000"], ["110797.00000000", "0.68581000"], ["110746.00000000", "1.36292000"], ["110702.25000000", "0.02498000"], ["110701.32000000", "0.02498000"], ["110700.87000000", "0.02498000"], ["110700.69000000", "0.02498000"], ["110700.58000000", "0.02498000"], ["110700.27000000", "0.02498000"], ["110699.59000000", "0.02498000"], ["110692.97000000", "0.00000000"], ["110692.68000000", "0.00000000"], ["110692.65000000", "0.00000000"], ["110692.64000000", "0.00000000"], ["110663.00000000", "2.02305000"], ["110644.96000000", "0.00000000"], ["110551.00000000", "0.00000000"], ["110524.00000000", "0.00000000"], ["110453.00000000", "0.00000000"], ["110412.00000000", "0.00000000"], ["109333.49000000", "0.00000000"]], "a": [["110997.41000000", "6.23280000"], ["110997.66000000", "0.00000000"], ["110997.91000000", "0.29726000"], ["110998.19000000", "0.00027000"], ["110998.47000000", "1.48087000"], ["110998.48000000", "1.25322000"], ["110998.81000000", "0.00912000"], ["110999.26000000", "0.20292000"], ["110999.27000000", "0.00010000"], ["110999.83000000", "0.06753000"], ["111000.92000000", "0.00005000"], ["111001.04000000", "0.00005000"], ["111003.12000000", "0.20282000"], ["111004.64000000", "0.02535000"], ["111005.27000000", "0.00005000"], ["111012.08000000", "0.42619000"], ["111025.20000000", "0.00005000"], ["111037.88000000", "0.44166000"], ["111038.13000000", "0.00016000"], ["111038.44000000", "0.00000000"], ["111038.96000000", "0.00000000"], ["111039.24000000", "0.00000000"], ["111049.44000000", "0.00016000"], ["111050.88000000", "0.00000000"], ["111061.35000000", "0.13519000"], ["111062.75000000", "0.00000000"], ["111062.93000000", "0.00000000"], ["111099.00000000", "0.19002000"], ["111192.00000000", "0.68490000"], ["111275.00000000", "2.00835000"], ["111344.00000000", "0.00000000"], ["111359.00000000", "2.79625000"], ["111492.00000000", "0.00210000"], ["111534.00000000", "0.00000000"], ["111576.00000000", "0.00000000"], ["112663.46000000", "0.00000000"]]}}
{"type": "orderbook", "local_time": 1761342410574, "event_time": 1761342400314, "latency_ms": 10260, "data": {"e": "depthUpdate", "E": 1761342400314, "s": "BTCUSDT", "U": 79012702807, "u": 79012702954, "b": [["110997.40000000", "0.00854000"], ["110997.39000000", "0.00115000"], ["110996.40000000", "0.04576000"], ["110995.70000000", "0.00208000"], ["110994.98000000", "0.00000000"], ["110994.97000000", "0.00000000"], ["110994.87000000", "0.05447000"], ["110994.67000000", "0.00010000"], ["110992.68000000", "0.00000000"], ["110992.67000000", "0.00000000"], ["110992.60000000", "0.00005000"], ["110992.14000000", "0.00777000"], ["110991.92000000", "0.00015000"], ["110991.91000000", "0.29738000"], ["110991.82000000", "0.00546000"], ["110991.56000000", "0.00000000"], ["110990.69000000", "0.00010000"], ["110990.68000000", "0.08061000"], ["110990.67000000", "0.00000000"], ["110990.56000000", "0.00005000"], ["110990.55000000", "0.02956000"], ["110990.42000000", "0.00005000"], ["110990.00000000", "0.00000000"], ["110989.77000000", "0.21481000"], ["110987.90000000", "0.00000000"], ["110987.67000000", "0.08834000"], ["110962.84000000", "0.00009000"], ["110960.70000000", "0.00009000"], ["110959.66000000", "0.00009000"], ["110954.56000000", "0.00009000"], ["110948.18000000", "0.00009000"], ["110942.36000000", "0.00000000"], ["110907.00000000", "0.00090000"], ["110898.70000000", "0.04097000"], ["110887.48000000", "0.07315000"], ["110886.40000000", "0.02536000"], ["110880.26000000", "0.18011000"], ["110874.52000000", "0.00005000"], ["110824.73000000", "0.02598000"], ["110714.35000000", "0.02598000"], ["110704.67000000", "0.02598000"], ["110694.78000000", "0.02598000"], ["110684.93000000", "0.02598000"], ["110676.33000000", "0.02598000"], ["110672.09000000", "0.02598000"], ["110650.74000000", "0.04097000"]], "a": [["110997.41000000", "6.47810000"], ["110997.91000000", "0.29746000"], ["110998.19000000", "0.00037000"], ["110998.46000000", "1.03699000"], ["110998.47000000", "0.00015000"], ["110998.48000000", "1.21999000"], ["110998.81000000", "0.00907000"], ["110999.26000000", "0.20292000"], ["110999.27000000", "0.00000000"], ["110999.32000000", "0.05051000"], ["110999.86000000", "0.04576000"], ["111000.92000000", "0.00000000"], ["111001.04000000", "0.00000000"], ["111012.00000000", "0.00016000"], ["111039.18000000", "0.00000000"], ["111051.74000000", "0.04008000"], ["111057.57000000", "0.02572000"], ["111075.84000000", "0.00000000"], ["111076.36000000", "0.00000000"], ["111114.51000000", "0.07853000"], ["111153.00000000", "0.00000000"]]}}
{"type": "orderbook", "local_time": 1761342410574, "event_time": 1761342400414, "latency_ms": 10160, "data": {"e": "depthUpdate", "E": 1761342400414, "s": "BTCUSDT", "U": 79012702955, "u": 79012703013, "b": [["110997.40000000", "0.00849000"], ["110997.39000000", "0.00110000"], ["110994.87000000", "0.05447000"], ["110992.60000000", "0.00000000"], ["110992.14000000", "0.00005000"], ["110991.74000000", "0.00854000"], ["110990.55000000", "0.02956000"], ["110990.42000000", "0.05018000"], ["110987.67000000", "0.08839000"], ["110970.88000000", "0.00000000"], ["110967.98000000", "0.00900000"], ["110841.33000000", "0.00000000"], ["110803.27000000", "0.15910000"], ["110672.09000000", "0.00000000"], ["110546.95000000", "0.02698000"], ["110546.04000000", "0.02698000"], ["110545.02000000", "0.02698000"], ["110544.56000000", "0.02698000"], ["110544.05000000", "0.02698000"], ["110543.51000000", "0.02698000"], ["110542.36000000", "0.02698000"], ["110541.75000000", "0.02705000"], ["110532.97000000", "0.00000000"], ["110532.30000000", "0.00000000"], ["110531.64000000", "0.00000000"], ["110531.27000000", "0.00000000"], ["110530.91000000", "0.00000000"], ["110530.54000000", "0.00000000"], ["110530.24000000", "0.00000000"], ["110530.17000000", "0.00000000"], ["50000.00000000", "39.95292000"]], "a": [["110997.41000000", "6.38404000"], ["110997.91000000", "0.29746000"], ["110998.19000000", "0.00037000"], ["110998.46000000", "0.58511000"], ["110998.47000000", "0.00000000"], ["111042.32000000", "0.02186000"]]}}
{"type": "orderbook", "local_time": 1761342410575, "event_time": 1761342400514, "latency_ms": 10061, "data": {"e": "depthUpdate", "E": 1761342400514, "s": "BTCUSDT", "U": 79012703014, "u": 79012703036, "b": [["110997.40000000", "0.00854000"], ["110997.39000000", "0.00110000"], ["110994.87000000", "0.05447000"], ["110992.14000000", "0.00000000"], ["110991.82000000", "0.00546000"], ["110991.74000000", "0.00859000"], ["110990.55000000", "0.02951000"], ["110987.67000000", "0.08834000"], ["50000.00000000", "39.95322000"]], "a": [["110998.46000000", "0.58516000"], ["110998.48000000", "1.21923000"], ["111003.12000000", "0.20287000"], ["111009.24000000", "0.00000000"], ["111010.00000000", "0.01802000"]]}}
{"type": "orderbook", "local_time": 1761342410576, "event_time": 1761342400614, "latency_ms": 9962, "data": {"e": "depthUpdate", "E": 1761342400614, "s": "BTCUSDT", "U": 79012703037, "u": 79012703042, "b": [["110987.90000000", "0.01826000"], ["99897.00000000", "0.00000000"], ["50000.00000000", "39.95352000"]], "a": [["110997.41000000", "6.38480000"], ["111350.70000000", "0.48717000"]]}}
{"type": "orderbook", "local_time": 1761342410576, "event_time": 1761342400715, "latency_ms": 9861, "data": {"e": "depthUpdate", "E": 1761342400715, "s": "BTCUSDT", "U": 79012703043, "u": 79012703063, "b": [["110997.40000000", "0.00859000"], ["110990.42000000", "0.05023000"], ["110989.77000000", "0.21476000"], ["110692.94000000", "0.01711000"], ["110686.51000000", "0.01716000"], ["110666.12000000", "0.00000000"], ["110664.91000000", "0.00000000"], ["50000.00000000", "39.95382000"]], "a": [["110997.90000000", "0.00010000"], ["110998.45000000", "0.00010000"], ["110998.47000000", "0.00010000"], ["110998.48000000", "0.94901000"], ["110999.25000000", "0.00010000"], ["111012.30000000", "0.13511000"], ["111062.37000000", "0.00000000"], ["111065.58000000", "0.13511000"]]}}
{"type": "orderbook", "local_time": 1761342410577, "event_time": 1761342400814, "latency_ms": 9763, "data": {"e": "depthUpdate", "E": 1761342400814, "s": "BTCUSDT", "U": 79012703064, "u": 79012703073, "b": [["110946.01000000", "0.01711000"], ["110942.16000000", "0.06879000"], ["110920.95000000", "0.00000000"], ["110710.72000000", "0.00000000"], ["110527.89000000", "0.00000000"], ["110515.81000000", "0.03698000"], ["50000.00000000", "39.95412000"], ["42000.00000000", "1.36734000"]], "a": [["110997.41000000", "6.38485000"], ["111087.93000000", "0.13511000"]]}}
{"type": "orderbook", "local_time": 1761342410579, "event_time": 1761342400914, "latency_ms": 9665, "data": {"e": "depthUpdate", "E": 1761342400914, "s": "BTCUSDT", "U": 79012703074, "u": 79012703090, "b": [["110991.74000000", "0.00005000"], ["110991.73000000", "0.00859000"], ["110972.88000000", "0.00000000"], ["110964.11000000", "0.04506000"], ["110946.21000000", "0.04088000"], ["110942.16000000", "0.00000000"], ["110926.81000000", "0.00000000"], ["110715.33000000", "0.01711000"]], "a": [["110997.41000000", "6.47896000"], ["111003.11000000", "0.00000000"], ["111030.70000000", "0.04507000"], ["111034.54000000", "0.32418000"], ["111037.37000000", "0.13511000"], ["111058.05000000", "0.00000000"], ["111087.93000000", "0.00000000"], ["111147.98000000", "0.06000000"]]}}
{"type": "orderbook", "local_time": 1761342410579, "event_time": 1761342401014, "latency_ms": 9565, "data": {"e": "depthUpdate", "E": 1761342401014, "s": "BTCUSDT", "U": 79012703091, "u": 79012703104, "b": [["110997.40000000", "0.00859000"], ["110997.39000000", "0.00110000"], ["110991.82000000", "0.00546000"], ["110991.74000000", "0.00000000"], ["110991.73000000", "0.00864000"], ["110926.01000000", "0.02321000"], ["109332.43000000", "0.00100000"], ["88798.00000000", "0.00000000"]], "a": [["110998.47000000", "0.00102000"], ["112662.38000000", "0.00100000"]]}}
{"type": "orderbook", "local_time": 1761342410580, "event_time": 1761342401115, "latency_ms": 9465, "data": {"e": "depthUpdate", "E": 1761342401115, "s": "BTCUSDT", "U": 79012703105, "u": 79012703112, "b": [["110941.96000000", "0.00000000"], ["110941.84000000", "0.06813000"], ["110904.10000000", "0.13473000"], ["33000.00000000", "3.79445000"]], "a": [["111037.37000000", "0.00000000"], ["111088.02000000", "0.13511000"]]}}
{"type": "orderbook", "local_time": 1761342410580, "event_time": 1761342401214, "latency_ms": 9366, "data": {"e": "depthUpdate", "E": 1761342401214, "s": "BTCUSDT", "U": 79012703113, "u": 79012703115, "b": [["110997.39000000", "0.00118000"], ["60000.00000000", "56.85876000"]], "a": [["111095.12000000", "0.73941000"]]}}
{"type": "orderbook", "local_time": 1761342410581, "event_time": 1761342401314, "latency_ms": 9267, "data": {"e": "depthUpdate", "E": 1761342401314, "s": "BTCUSDT", "U": 79012703116, "u": 79012703120, "b": [["110821.58000000", "0.02598000"], ["110809.72000000", "0.02598000"], ["110733.48000000", "0.00000000"], ["99897.00000000", "0.00000000"]], "a": []}}
{"type": "orderbook", "local_time": 1761342410581, "event_time": 1761342401414, "latency_ms": 9167, "data": {"e": "depthUpdate", "E": 1761342401414, "s": "BTCUSDT", "U": 79012703121, "u": 79012703122, "b": [], "a": [["110997.41000000", "6.47890000"]]}}
{"type": "orderbook", "local_time": 1761342410581, "event_time": 1761342401514, "latency_ms": 9067, "data": {"e": "depthUpdate", "E": 1761342401514, "s": "BTCUSDT", "U": 79012703123, "u": 79012703128, "b": [["110969.27000000", "0.00000000"], ["110966.98000000", "0.04000000"]], "a": [["111037.37000000", "0.13511000"], ["111087.93000000", "0.00000000"], ["111088.02000000", "0.00000000"]]}}
{"type": "orderbook", "local_time": 1761342410582, "event_time": 1761342401614, "latency_ms": 8968, "data": {"e": "depthUpdate", "E": 1761342401614, "s": "BTCUSDT", "U": 79012703129, "u": 79012703234, "b": [["110994.63000000", "0.00198000"], ["110991.73000000", "0.00005000"], ["110990.42000000", "0.00005000"], ["110990.19000000", "0.00000000"], ["110987.90000000", "0.00000000"], ["110986.10000000", "0.00000000"], ["110984.06000000", "0.00000000"], ["110983.90000000", "0.00000000"], ["110983.81000000", "0.00000000"], ["110982.87000000", "0.00000000"], ["110982.79000000", "0.00000000"], ["110982.70000000", "0.00000000"], ["110982.54000000", "0.00000000"], ["110980.01000000", "0.18015000"], ["110979.46000000", "0.04536000"], ["110979.00000000", "0.00016000"], ["110978.91000000", "0.00000000"], ["110978.78000000", "0.00000000"], ["110978.35000000", "0.00000000"], ["110977.61000000", "0.00000000"], ["110977.59000000", "0.00000000"], ["110977.56000000", "0.00000000"], ["110977.24000000", "0.00000000"], ["110977.15000000", "0.00000000"], ["110976.49000000", "0.00000000"], ["110976.48000000", "0.00000000"], ["110976.27000000", "0.00000000"], ["110974.66000000", "0.01802000"], ["110974.18000000", "0.00000000"], ["110972.69000000", "0.00450000"], ["110971.33000000", "0.00000000"], ["110970.77000000", "0.00000000"], ["110969.65000000", "0.11267000"], ["110969.46000000", "0.36028000"], ["110967.98000000", "0.00000000"], ["110967.26000000", "0.00000000"], ["110966.96000000", "0.00000000"], ["110966.78000000", "0.02000000"], ["110965.88000000", "0.08000000"], ["110965.38000000", "0.16000000"], ["110964.37000000", "0.00900000"], ["110963.68000000", "0.03900000"], ["110962.84000000", "0.00000000"], ["110960.70000000", "0.00000000"], ["110960.01000000", "0.00000000"], ["110959.66000000", "0.00000000"], ["110958.01000000", "0.00000000"], ["110954.56000000", "0.00000000"], ["110950.51000000", "0.03697000"], ["110948.93000000", "0.07003000"], ["110948.18000000", "0.00000000"], ["110947.49000000", "0.00000000"], ["110941.84000000", "0.00000000"], ["110939.64000000", "0.06723000"], ["110925.72000000", "0.00000000"], ["110907.00000000", "0.00000000"], ["110904.10000000", "0.00000000"], ["110886.26000000", "0.13511000"], ["110881.55000000", "0.03900000"], ["110878.01000000", "0.00000000"], ["110860.01000000", "0.09917000"]], "a": [["110997.41000000", "6.61401000"], ["110997.90000000", "0.00000000"], ["110998.45000000", "0.00000000"], ["110998.47000000", "0.00092000"], ["110998.51000000", "0.00099000"], ["110999.25000000", "0.00000000"], ["110999.26000000", "0.50292000"], ["111000.18000000", "0.00450000"], ["111001.25000000", "0.00000000"], ["111004.02000000", "0.27041000"], ["111006.01000000", "1.44342000"], ["111006.28000000", "0.00000000"], ["111007.01000000", "0.00000000"], ["111007.84000000", "0.01802000"], ["111010.00000000", "0.00000000"], ["111011.28000000", "0.00000000"], ["111012.30000000", "0.00000000"], ["111017.72000000", "0.00000000"], ["111022.71000000", "0.00000000"], ["111048.88000000", "0.04413000"], ["111054.78000000", "0.00000000"], ["111061.43000000", "0.13511000"], ["111061.55000000", "0.00000000"], ["111065.58000000", "0.00000000"], ["111090.82000000", "0.10543000"], ["111177.60000000", "0.02704000"], ["111199.80000000", "0.00000000"], ["111300.30000000", "0.03697000"], ["111359.10000000", "0.00000000"], ["111421.56000000", "0.00000000"]]}}
{"type": "orderbook", "local_time": 1761342410583, "event_time": 1761342401714, "latency_ms": 8869, "data": {"e": "depthUpdate", "E": 1761342401714, "s": "BTCUSDT", "U": 79012703235, "u": 79012703372, "b": [["110997.40000000", "0.00712000"], ["110997.39000000", "0.00118000"], ["110994.87000000", "0.05447000"], ["110991.82000000", "0.00546000"], ["110991.73000000", "0.00000000"], ["110990.68000000", "0.00010000"], ["110990.55000000", "0.02951000"], ["110990.42000000", "0.00000000"], ["110990.05000000", "0.00859000"], ["110989.77000000", "0.00005000"], ["110989.67000000", "0.00000000"], ["110987.67000000", "0.00005000"], ["110986.30000000", "0.00000000"], ["110985.25000000", "0.00000000"], ["110983.34000000", "0.07802000"], ["110982.65000000", "0.21476000"], ["110979.46000000", "0.00000000"], ["110978.55000000", "0.00000000"], ["110977.18000000", "0.61010000"], ["110977.17000000", "0.00000000"], ["110976.71000000", "0.00000000"], ["110974.73000000", "0.00000000"], ["110974.69000000", "0.04536000"], ["110974.66000000", "0.00000000"], ["110974.17000000", "0.00000000"], ["110971.89000000", "0.00000000"], ["110971.88000000", "0.00000000"], ["110971.21000000", "0.00000000"], ["110970.37000000", "0.03900000"], ["110968.15000000", "0.11264000"], ["110967.01000000", "0.01802000"], ["110966.99000000", "0.00000000"], ["110965.38000000", "0.00000000"], ["110964.38000000", "0.30402000"], ["110964.07000000", "0.16000000"], ["110960.52000000", "0.07661000"], ["110959.24000000", "0.00009000"], ["110957.52000000", "0.59538000"], ["110957.10000000", "0.00009000"], ["110956.57000000", "0.13511000"], ["110956.16000000", "0.00000000"], ["110956.06000000", "0.00009000"], ["110955.60000000", "0.00250000"], ["110950.96000000", "0.00009000"], ["110949.19000000", "0.83939000"], ["110944.75000000", "0.18027000"], ["110944.58000000", "0.00009000"], ["110939.64000000", "0.00000000"], ["110938.81000000", "0.00000000"], ["110938.41000000", "0.00000000"], ["110936.49000000", "0.00000000"], ["110935.76000000", "0.34588000"], ["110932.43000000", "0.00000000"], ["110932.35000000", "0.00000000"], ["110926.01000000", "0.01891000"], ["110923.66000000", "0.02663000"], ["110922.18000000", "0.20282000"], ["110903.40000000", "0.00090000"], ["110900.96000000", "0.00000000"], ["110900.13000000", "0.00000000"], ["110899.83000000", "0.00000000"], ["110898.69000000", "0.00000000"], ["110898.37000000", "0.03600000"], ["110891.44000000", "0.00000000"], ["110888.14000000", "0.03900000"], ["110878.15000000", "0.18027000"], ["110869.97000000", "0.00000000"], ["110835.14000000", "0.00000000"], ["110758.91000000", "0.00000000"], ["110695.03000000", "0.00000000"], ["110677.55000000", "0.01711000"], ["60000.00000000", "56.85866000"]], "a": [["110997.41000000", "6.80530000"], ["110998.48000000", "0.90901000"], ["110998.63000000", "0.01802000"], ["111000.18000000", "0.00000000"], ["111000.19000000", "0.00000000"], ["111002.90000000", "0.00450000"], ["111003.12000000", "0.20287000"], ["111003.51000000", "0.00000000"], ["111004.45000000", "0.07661000"], ["111006.00000000", "0.58499000"], ["111007.02000000", "0.00000000"], ["111007.84000000", "0.00000000"], ["111017.70000000", "0.69547000"], ["111018.61000000", "0.00000000"], ["111028.89000000", "0.04008000"], ["111051.74000000", "0.00000000"], ["111065.22000000", "0.00000000"], ["111071.10000000", "0.00000000"], ["111113.50000000", "0.09817000"], ["111151.08000000", "1.50342000"], ["111244.33000000", "0.00000000"], ["111350.70000000", "0.00000000"]]}}
{"type": "orderbook", "local_time": 1761342411258, "event_time": 1761342401814, "latency_ms": 9444, "data": {"e": "depthUpdate", "E": 1761342401814, "s": "BTCUSDT", "U": 79012703373, "u": 79012703830, "b": [["110997.40000000", "0.00000000"], ["110997.39000000", "0.00000000"], ["110996.41000000", "0.00000000"], ["110996.40000000", "0.00000000"], ["110995.70000000", "0.00000000"], ["110995.50000000", "0.00000000"], ["110994.88000000", "0.00000000"], ["110994.87000000", "0.00000000"], ["110994.67000000", "0.00000000"], ["110994.63000000", "0.00000000"], ["110992.20000000", "0.00000000"], ["110991.92000000", "0.00000000"], ["110991.91000000", "0.12664000"], ["110991.90000000", "0.00090000"], ["110991.83000000", "0.00000000"], ["110991.82000000", "0.00566000"], ["110990.69000000", "0.00000000"], ["110990.68000000", "0.00000000"], ["110990.56000000", "0.00010000"], ["110990.55000000", "0.00030000"], ["110990.06000000", "0.00010000"], ["110990.05000000", "0.00005000"], ["110989.98000000", "0.00000000"], ["110989.78000000", "0.00000000"], ["110989.77000000", "0.00000000"], ["110989.62000000", "0.00000000"], ["110989.57000000", "0.00712000"], ["110989.18000000", "0.00000000"], ["110988.54000000", "0.29728000"], ["110987.88000000", "0.00000000"], ["110987.67000000", "0.00000000"], ["110987.39000000", "0.00010000"], ["110987.38000000", "0.00726000"], ["110986.74000000", "0.00010000"], ["110986.73000000", "0.00005000"], ["110986.03000000", "0.00015000"], ["110985.16000000", "0.01821000"], ["110984.50000000", "0.02861000"], ["110984.05000000", "0.00005000"], ["110984.04000000", "0.00010000"], ["110983.48000000", "0.00000000"], ["110983.34000000", "0.11797000"], ["110983.24000000", "0.00000000"], ["110982.65000000", "0.00010000"], ["110980.01000000", "0.00005000"], ["110978.56000000", "0.04536000"], ["110977.81000000", "0.18016000"], ["110977.72000000", "0.20756000"], ["110977.70000000", "0.00720000"], ["110977.48000000", "0.07914000"], ["110977.18000000", "0.07379000"], ["110976.19000000", "0.00000000"], ["110975.26000000", "0.00151000"], ["110974.69000000", "0.00000000"], ["110974.10000000", "0.00000000"], ["110973.36000000", "0.00250000"], ["110972.69000000", "0.00000000"], ["110971.27000000", "0.00990000"], ["110969.45000000", "0.00000000"], ["110969.04000000", "0.00450000"], ["110967.98000000", "0.04571000"], ["110966.98000000", "0.00000000"], ["110965.88000000", "0.00000000"], ["110964.77000000", "0.60845000"], ["110964.38000000", "0.00000000"], ["110964.07000000", "0.04000000"], ["110962.37000000", "0.08000000"], ["110962.07000000", "0.16000000"], ["110960.53000000", "0.30403000"], ["110956.31000000", "0.00000000"], ["110955.21000000", "0.00000000"], ["110951.16000000", "0.00000000"], ["110950.75000000", "0.00000000"], ["110948.53000000", "0.00000000"], ["110947.80000000", "0.22082000"], ["110945.90000000", "0.00037000"], ["110944.57000000", "0.00034000"], ["110941.97000000", "0.00090000"], ["110940.00000000", "0.04394000"], ["110937.40000000", "0.04419000"], ["110937.12000000", "0.00005000"], ["110937.05000000", "0.00000000"], ["110936.98000000", "0.06875000"], ["110936.10000000", "0.00005000"], ["110935.49000000", "0.32447000"], ["110923.73000000", "0.00000000"], ["110916.69000000", "0.00621000"], ["110916.50000000", "0.00620000"], ["110907.73000000", "0.00663000"], ["110895.01000000", "0.00000000"], ["110888.15000000", "0.00224000"], ["110878.46000000", "0.02439000"], ["110878.00000000", "0.00271000"], ["110877.14000000", "0.00005000"], ["110877.02000000", "0.40527000"], ["110870.88000000", "0.00000000"], ["110865.00000000", "0.00191000"], ["110839.29000000", "0.08885000"], ["110797.99000000", "0.08578000"], ["110784.01000000", "0.00000000"], ["110776.01000000", "0.00090000"], ["110760.45000000", "0.00000000"], ["110754.01000000", "0.00076000"], ["110714.27000000", "0.00005000"], ["110713.56000000", "0.00000000"], ["110693.56000000", "0.02498000"], ["110692.88000000", "0.02498000"], ["110672.15000000", "0.00000000"], ["110647.03000000", "0.02198000"], ["109332.43000000", "0.00000000"], ["99898.00000000", "0.03577000"], ["99897.00000000", "0.00030000"]], "a": [["110991.92000000", "6.94812000"], ["110992.21000000", "0.04168000"], ["110994.61000000", "0.29727000"], ["110994.64000000", "0.00000000"], ["110994.88000000", "0.00000000"], ["110995.25000000", "0.20282000"], ["110995.56000000", "0.00250000"], ["110995.71000000", "0.00000000"], ["110996.41000000", "0.00000000"], ["110997.40000000", "3.75302000"], ["110997.41000000", "1.36820000"], ["110997.91000000", "0.00020000"], ["110998.19000000", "0.00005000"], ["110998.46000000", "0.00010000"], ["110998.48000000", "0.00386000"], ["110998.63000000", "0.00000000"], ["110998.64000000", "0.01802000"], ["110998.81000000", "0.00005000"], ["110999.26000000", "0.50287000"], ["110999.32000000", "0.00005000"], ["110999.86000000", "0.00000000"], ["111000.66000000", "0.00044000"], ["111001.38000000", "0.00005000"], ["111003.02000000", "0.00020000"], ["111003.11000000", "0.20926000"], ["111003.12000000", "0.20282000"], ["111004.03000000", "0.00000000"], ["111004.44000000", "0.00000000"], ["111004.94000000", "0.00007000"], ["111006.35000000", "0.12340000"], ["111006.68000000", "0.00044000"], ["111007.22000000", "0.00000000"], ["111007.31000000", "0.00010000"], ["111007.61000000", "0.00000000"], ["111008.56000000", "0.00090000"], ["111012.91000000", "0.00000000"], ["111013.24000000", "0.00000000"], ["111013.32000000", "0.00250000"], ["111014.15000000", "0.00000000"], ["111017.76000000", "0.00000000"], ["111018.41000000", "0.00000000"], ["111023.29000000", "0.00000000"], ["111028.30000000", "0.32419000"], ["111032.39000000", "0.44164000"], ["111033.00000000", "0.00016000"], ["111037.37000000", "0.00000000"], ["111037.88000000", "0.00000000"], ["111038.13000000", "0.00000000"], ["111043.64000000", "0.00016000"], ["111047.99000000", "0.00224000"], ["111049.44000000", "0.00000000"], ["111051.90000000", "0.00626000"], ["111052.20000000", "0.00000000"], ["111053.99000000", "0.00000000"], ["111054.14000000", "0.00000000"], ["111056.25000000", "0.00666000"], ["111061.35000000", "0.00000000"], ["111061.43000000", "0.00000000"], ["111074.20000000", "0.00225000"], ["111080.82000000", "0.00000000"], ["111083.57000000", "0.00000000"], ["111114.10000000", "0.00000000"], ["111115.91000000", "0.00000000"], ["111137.40000000", "0.00000000"], ["111880.00000000", "0.36432000"], ["112662.38000000", "0.00000000"]]}}
{"type": "orderbook", "local_time": 1761342411260, "event_time": 1761342401914, "latency_ms": 9346, "data": {"e": "depthUpdate", "E": 1761342401914, "s": "BTCUSDT", "U": 79012703831, "u": 79012704006, "b": [["110991.91000000", "0.03273000"], ["110991.90000000", "0.00120000"], ["110991.82000000", "0.00566000"], ["110990.56000000", "0.00000000"], ["110990.55000000", "0.00010000"], ["110990.06000000", "0.00000000"], ["110990.05000000", "0.00000000"], ["110989.68000000", "0.00000000"], ["110989.58000000", "0.00010000"], ["110989.57000000", "0.00010000"], ["110988.55000000", "0.00010000"], ["110988.54000000", "0.29738000"], ["110987.39000000", "0.00000000"], ["110987.38000000", "0.00726000"], ["110986.92000000", "0.02704000"], ["110986.74000000", "0.00000000"], ["110986.73000000", "0.00000000"], ["110985.56000000", "0.04979000"], ["110985.17000000", "0.00010000"], ["110985.16000000", "0.00010000"], ["110984.51000000", "0.00010000"], ["110984.50000000", "0.02871000"], ["110984.05000000", "0.00000000"], ["110984.04000000", "0.00000000"], ["110983.35000000", "0.00010000"], ["110983.34000000", "0.07812000"], ["110982.66000000", "0.00000000"], ["110982.65000000", "0.00000000"], ["110980.01000000", "0.00000000"], ["110980.00000000", "0.01949000"], ["110978.56000000", "0.04541000"], ["110977.73000000", "0.14709000"], ["110977.18000000", "0.00000000"], ["110965.81000000", "0.03600000"], ["110964.11000000", "0.00000000"], ["110962.50000000", "0.03610000"], ["110943.63000000", "0.00000000"], ["110920.94000000", "0.00380000"], ["110888.08000000", "0.03600000"], ["110881.96000000", "0.03600000"], ["99897.00000000", "0.00010000"]], "a": [["110991.92000000", "6.98155000"], ["110992.21000000", "0.04188000"], ["110994.61000000", "0.29742000"], ["110995.25000000", "0.20292000"], ["110997.39000000", "1.41636000"], ["110997.40000000", "1.44352000"], ["110997.41000000", "1.33492000"], ["110997.91000000", "0.00000000"], ["110998.19000000", "0.00000000"], ["110998.46000000", "0.00000000"], ["110998.48000000", "0.00376000"], ["110998.64000000", "0.01807000"], ["110998.81000000", "0.00000000"], ["110999.26000000", "0.50287000"], ["110999.32000000", "0.00000000"], ["110999.83000000", "0.06748000"], ["111007.31000000", "0.00000000"], ["111014.00000000", "0.03000000"], ["111028.94000000", "1.28548000"], ["111030.70000000", "0.00000000"], ["111034.58000000", "0.55501000"], ["111051.12000000", "0.00000000"], ["111056.44000000", "0.13511000"], ["111087.34000000", "0.00100000"], ["111087.35000000", "0.00100000"], ["111095.86000000", "0.00000000"], ["111095.87000000", "0.00000000"]]}}
{"type": "orderbook", "local_time": 1761342411260, "event_time": 1761342402014, "latency_ms": 9246, "data": {"e": "depthUpdate", "E": 1761342402014, "s": "BTCUSDT", "U": 79012704007, "u": 79012704377, "b": [["110991.91000000", "0.00000000"], ["110991.90000000", "0.00000000"], ["110991.82000000", "0.00000000"], ["110990.55000000", "0.00000000"], ["110990.50000000", "0.00000000"], ["110989.74000000", "0.00000000"], ["110989.58000000", "0.00000000"], ["110989.57000000", "0.00000000"], ["110989.04000000", "0.00000000"], ["110988.90000000", "0.00000000"], ["110988.55000000", "0.00000000"], ["110988.54000000", "0.43287000"], ["110988.53000000", "0.00090000"], ["110987.39000000", "0.00010000"], ["110987.38000000", "0.00746000"], ["110987.37000000", "0.00320000"], ["110987.21000000", "0.00010000"], ["110986.93000000", "0.00010000"], ["110986.92000000", "0.00015000"], ["110986.53000000", "0.00000000"], ["110986.22000000", "0.00000000"], ["110986.03000000", "0.00000000"], ["110985.97000000", "0.00000000"], ["110985.85000000", "0.00000000"], ["110985.57000000", "0.00010000"], ["110985.56000000", "0.00010000"], ["110985.17000000", "0.00000000"], ["110985.16000000", "0.00000000"], ["110983.34000000", "0.07812000"], ["110982.66000000", "0.00000000"], ["110982.36000000", "0.00000000"], ["110980.85000000", "0.00015000"], ["110978.06000000", "0.00000000"], ["110977.81000000", "0.00005000"], ["110977.80000000", "0.00995000"], ["110977.79000000", "0.00720000"], ["110977.70000000", "0.00000000"], ["110974.00000000", "0.18136000"], ["110971.89000000", "0.00150000"], ["110969.46000000", "0.00000000"], ["110969.04000000", "0.00000000"], ["110967.01000000", "0.00000000"], ["110966.78000000", "0.00000000"], ["110966.01000000", "0.00450000"], ["110965.66000000", "0.01802000"], ["110964.12000000", "0.00022000"], ["110964.07000000", "0.02000000"], ["110963.69000000", "0.36029000"], ["110962.87000000", "0.00000000"], ["110962.37000000", "0.00000000"], ["110962.07000000", "0.00000000"], ["110961.37000000", "0.04000000"], ["110959.67000000", "0.24000000"], ["110959.24000000", "0.03900000"], ["110957.51000000", "1.44342000"], ["110957.10000000", "0.00000000"], ["110956.06000000", "0.00000000"], ["110954.16000000", "0.52335000"], ["110950.96000000", "0.00000000"], ["110949.70000000", "0.00090000"], ["110944.76000000", "0.02698000"], ["110944.58000000", "0.00000000"], ["110940.62000000", "0.00000000"], ["110936.98000000", "0.00000000"], ["110936.13000000", "0.00000000"], ["110935.30000000", "0.00000000"], ["110935.13000000", "0.06608000"], ["110924.71000000", "0.07046000"], ["110920.94000000", "0.00000000"], ["110903.40000000", "0.00000000"], ["110897.39000000", "0.13627000"], ["110891.04000000", "0.00062000"], ["110881.51000000", "0.04260000"], ["110873.26000000", "0.00000000"], ["110852.01000000", "0.00000000"], ["110842.01000000", "0.00224000"], ["110740.48000000", "0.84097000"], ["109323.71000000", "0.00100000"]], "a": [["110988.55000000", "5.99075000"], ["110989.05000000", "0.00000000"], ["110989.33000000", "0.00021000"], ["110989.58000000", "0.00000000"], ["110990.06000000", "0.00000000"], ["110990.56000000", "0.00000000"], ["110991.83000000", "0.00000000"], ["110991.88000000", "0.20282000"], ["110991.89000000", "0.29728000"], ["110991.91000000", "1.94602000"], ["110991.92000000", "1.46943000"], ["110994.61000000", "0.00015000"], ["110995.25000000", "0.20292000"], ["110995.35000000", "0.01802000"], ["110997.39000000", "0.71696000"], ["110997.41000000", "0.29832000"], ["111004.95000000", "0.00044000"], ["111005.02000000", "0.00044000"], ["111005.20000000", "0.00150000"], ["111009.58000000", "0.00000000"], ["111014.87000000", "0.00000000"], ["111014.95000000", "0.00000000"], ["111020.26000000", "0.00000000"], ["111027.39000000", "0.00365000"], ["111028.51000000", "0.13524000"], ["111028.52000000", "0.44164000"], ["111028.89000000", "0.00000000"], ["111032.39000000", "0.00000000"], ["111044.68000000", "0.00000000"], ["111044.69000000", "0.04008000"], ["111046.72000000", "0.00000000"], ["111050.88000000", "0.16862000"], ["111051.00000000", "0.00015000"], ["111053.87000000", "0.00616000"], ["111054.31000000", "0.13519000"], ["111067.45000000", "0.00005000"], ["111069.57000000", "0.00510000"], ["111076.91000000", "0.00000000"], ["111079.64000000", "0.00000000"], ["111090.81000000", "0.06816000"], ["111111.11000000", "0.10802000"], ["111237.31000000", "4.63350000"], ["111463.01000000", "0.03698000"], ["111544.56000000", "0.00000000"], ["111579.83000000", "0.00000000"], ["112653.38000000", "0.00100000"]]}}
{"type": "orderbook", "local_time": 1761342411261, "event_time": 1761342402114, "latency_ms": 9147, "data": {"e": "depthUpdate", "E": 1761342402114, "s": "BTCUSDT", "U": 79012704378, "u": 79012704524, "b": [["110988.54000000", "0.43297000"], ["110988.53000000", "0.00110000"], ["110987.38000000", "0.00746000"], ["110987.37000000", "0.00310000"], ["110987.21000000", "0.00000000"], ["110986.93000000", "0.00000000"], ["110986.92000000", "0.00000000"], ["110985.90000000", "0.00000000"], ["110985.57000000", "0.00000000"], ["110985.56000000", "0.00000000"], ["110985.28000000", "0.00077000"], ["110984.60000000", "0.02704000"], ["110984.50000000", "0.02866000"], ["110983.34000000", "0.02344000"], ["110980.01000000", "0.00010000"], ["110980.00000000", "0.01954000"], ["110978.57000000", "0.00005000"], ["110978.56000000", "0.04546000"], ["110977.81000000", "0.00000000"], ["110977.80000000", "0.00995000"], ["110977.79000000", "0.00725000"], ["110977.73000000", "0.14714000"], ["110977.72000000", "0.20761000"], ["110973.99000000", "0.00000000"], ["110973.93000000", "0.00069000"], ["110973.38000000", "0.00332000"], ["110968.17000000", "0.30401000"], ["110964.83000000", "0.05100000"], ["110960.53000000", "0.00000000"], ["110955.24000000", "0.00300000"], ["110949.20000000", "0.05468000"], ["110940.20000000", "0.00036000"], ["110939.87000000", "0.00035000"], ["110937.06000000", "0.00000000"], ["110888.14000000", "0.00000000"], ["110887.05000000", "0.05100000"], ["110881.96000000", "0.00000000"], ["110881.55000000", "0.00000000"], ["110881.51000000", "0.00360000"], ["110869.45000000", "0.00000000"], ["110858.36000000", "0.00000000"]], "a": [["110988.55000000", "5.79227000"], ["110991.12000000", "0.00250000"], ["110991.87000000", "0.29902000"], ["110991.88000000", "0.20312000"], ["110991.89000000", "0.29743000"], ["110991.90000000", "0.00010000"], ["110991.91000000", "0.00020000"], ["110991.92000000", "1.30109000"], ["110992.21000000", "0.04173000"], ["110994.61000000", "0.00000000"], ["110995.25000000", "0.20287000"], ["110997.41000000", "0.29827000"], ["110998.64000000", "0.00000000"], ["110998.83000000", "0.01802000"], ["110999.26000000", "0.50282000"], ["110999.65000000", "0.00300000"], ["111008.88000000", "0.00250000"], ["111009.70000000", "0.00000000"], ["111013.32000000", "0.00000000"], ["111017.74000000", "0.01260000"], ["111024.76000000", "0.00000000"], ["111029.52000000", "0.00000000"], ["111064.99000000", "0.00010000"], ["111080.04000000", "0.13511000"], ["111083.08000000", "0.00000000"]]}}
{"type": "orderbook", "local_time": 1761342411261, "event_time": 1761342402214, "latency_ms": 9047, "data": {"e": "depthUpdate", "E": 1761342402214, "s": "BTCUSDT", "U": 79012704525, "u": 79012704585, "b": [["110988.54000000", "0.43297000"], ["110988.53000000", "0.00115000"], ["110987.38000000", "0.00741000"], ["110985.28000000", "0.00077000"], ["110984.61000000", "0.01679000"], ["110984.60000000", "0.00000000"], ["110984.49000000", "0.02704000"], ["110981.30000000", "0.01840000"], ["110978.57000000", "0.00000000"], ["110978.56000000", "0.04541000"], ["110977.72000000", "0.20756000"], ["110957.04000000", "0.00009000"], ["110954.90000000", "0.00009000"], ["110953.86000000", "0.00009000"], ["110948.76000000", "0.00009000"], ["110942.38000000", "0.00009000"], ["110906.80000000", "0.00000000"], ["110901.20000000", "0.00090000"], ["110887.48000000", "0.04097000"], ["110887.01000000", "0.03218000"], ["110851.99000000", "0.00114000"], ["110840.90000000", "0.00229000"]], "a": [["110988.55000000", "6.00718000"], ["110991.12000000", "0.00260000"], ["110991.86000000", "0.00010000"], ["110991.87000000", "0.29922000"], ["110991.88000000", "0.20307000"], ["110991.89000000", "0.29733000"], ["110991.90000000", "0.00000000"], ["110991.91000000", "0.00010000"], ["110995.35000000", "0.01807000"], ["110997.39000000", "0.26834000"], ["110998.83000000", "0.00000000"], ["110998.90000000", "0.01802000"], ["111001.00000000", "0.00005000"], ["111064.99000000", "0.00124000"]]}}
{"type": "orderbook", "local_time": 1761342411262, "event_time": 1761342402314, "latency_ms": 8948, "data": {"e": "depthUpdate", "E": 1761342402314, "s": "BTCUSDT", "U": 79012704586, "u": 79012704642, "b": [["110988.54000000", "0.43307000"], ["110988.53000000", "0.00120000"], ["110987.38000000", "0.00746000"], ["110985.28000000", "0.00077000"], ["110984.62000000", "0.00010000"], ["110984.61000000", "0.01679000"], ["110984.50000000", "0.02871000"], ["110984.49000000", "0.00005000"], ["110984.47000000", "0.02704000"], ["110983.34000000", "0.02334000"], ["110980.01000000", "0.00000000"], ["110980.00000000", "0.01949000"], ["110977.79000000", "0.00720000"], ["110977.73000000", "0.14709000"], ["110968.55000000", "0.01802000"], ["110965.66000000", "0.00000000"], ["110961.50000000", "0.05100000"], ["110959.19000000", "0.05400000"], ["110939.31000000", "0.00000000"], ["110887.05000000", "0.00000000"], ["110883.75000000", "0.05100000"], ["110881.46000000", "0.05400000"], ["110877.99000000", "0.09919000"]], "a": [["110991.86000000", "0.60751000"], ["110991.87000000", "0.00030000"], ["110991.89000000", "0.29738000"], ["110997.39000000", "0.66493000"], ["110998.90000000", "0.00000000"], ["111000.17000000", "0.01802000"], ["111083.08000000", "0.00229000"], ["111343.41000000", "0.48717000"]]}}
{"type": "orderbook", "local_time": 1761342411262, "event_time": 1761342402414, "latency_ms": 8848, "data": {"e": "depthUpdate", "E": 1761342402414, "s": "BTCUSDT", "U": 79012704643, "u": 79012704679, "b": [["110988.54000000", "0.43307000"], ["110988.53000000", "0.00120000"], ["110984.50000000", "0.02861000"], ["110984.49000000", "0.00000000"], ["110984.48000000", "0.00010000"], ["110964.89000000", "0.05700000"], ["110961.00000000", "0.05100000"], ["110937.01000000", "0.00000000"], ["110887.08000000", "0.05700000"], ["110883.20000000", "0.05100000"], ["110881.51000000", "0.00000000"], ["110857.71000000", "0.00360000"]], "a": [["110988.55000000", "6.00798000"], ["110991.12000000", "0.00260000"], ["110991.85000000", "0.00010000"], ["110991.86000000", "0.60761000"], ["110991.87000000", "0.00015000"], ["110991.88000000", "0.20302000"], ["110997.41000000", "0.29757000"]]}}
{"type": "orderbook", "local_time": 1761342411262, "event_time": 1761342402514, "latency_ms": 8748, "data": {"e": "depthUpdate", "E": 1761342402514, "s": "BTCUSDT", "U": 79012704680, "u": 79012704691, "b": [["110978.56000000", "0.00005000"], ["110964.82000000", "0.09000000"], ["110960.43000000", "0.05100000"], ["110938.22000000", "0.00000000"], ["110887.01000000", "0.12218000"], ["110882.66000000", "0.05100000"]], "a": [["110991.86000000", "0.60761000"], ["110991.87000000", "0.00010000"], ["110991.88000000", "0.20307000"]]}}
{"type": "orderbook", "local_time": 1761342411263, "event_time": 1761342402614, "latency_ms": 8649, "data": {"e": "depthUpdate", "E": 1761342402614, "s": "BTCUSDT", "U": 79012704692, "u": 79012704702, "b": [["110988.54000000", "0.43302000"], ["110988.53000000", "0.00115000"], ["110984.47000000", "0.02709000"], ["110983.34000000", "0.01532000"], ["110980.00000000", "0.01944000"], ["110978.56000000", "0.00000000"], ["110976.52000000", "0.04536000"], ["110887.08000000", "0.00000000"]], "a": [["110989.33000000", "0.00229000"]]}}
{"type": "orderbook", "local_time": 1761342411263, "event_time": 1761342402714, "latency_ms": 8549, "data": {"e": "depthUpdate", "E": 1761342402714, "s": "BTCUSDT", "U": 79012704703, "u": 79012704826, "b": [["110988.54000000", "0.04178000"], ["110988.53000000", "0.00120000"], ["110985.56000000", "0.00000000"], ["110984.61000000", "0.00010000"], ["110984.56000000", "0.29730000"], ["110984.47000000", "0.00005000"], ["110983.34000000", "0.00005000"], ["110983.02000000", "0.02704000"], ["110981.30000000", "0.00000000"], ["110977.79000000", "0.00000000"], ["110977.72000000", "0.00000000"], ["110977.46000000", "0.00000000"], ["110976.52000000", "0.00000000"], ["110972.79000000", "0.04536000"], ["110971.14000000", "0.00000000"], ["110969.65000000", "0.00000000"], ["110969.03000000", "0.00000000"], ["110968.16000000", "0.00000000"], ["110967.98000000", "0.00000000"], ["110966.34000000", "0.11267000"], ["110965.32000000", "0.00000000"], ["110965.01000000", "0.00000000"], ["110964.07000000", "0.00000000"], ["110961.37000000", "0.00000000"], ["110961.33000000", "0.00000000"], ["110961.07000000", "0.02000000"], ["110960.17000000", "0.00000000"], ["110959.67000000", "0.00000000"], ["110958.33000000", "0.04000000"], ["110957.04000000", "0.00000000"], ["110956.07000000", "0.28000000"], ["110954.90000000", "0.00000000"], ["110954.86000000", "0.13524000"], ["110953.86000000", "0.00000000"], ["110950.50000000", "0.00000000"], ["110948.76000000", "0.00000000"], ["110942.38000000", "0.00000000"], ["110940.53000000", "0.07661000"], ["110937.40000000", "0.00000000"], ["110935.76000000", "0.00000000"], ["110935.13000000", "0.00000000"], ["110933.53000000", "0.00000000"], ["110933.20000000", "0.00000000"], ["110931.01000000", "0.32448000"], ["110916.22000000", "0.20282000"], ["110915.74000000", "0.00000000"], ["110907.77000000", "0.00000000"], ["110904.92000000", "0.03218000"], ["110901.58000000", "0.13524000"], ["110901.20000000", "0.00000000"], ["110897.39000000", "0.00000000"], ["110887.01000000", "0.09000000"], ["110842.02000000", "0.00224000"], ["110842.01000000", "0.00000000"], ["110740.01000000", "0.00000000"], ["110730.29000000", "0.90297000"], ["110730.01000000", "0.00090000"], ["110715.14000000", "0.00000000"], ["110690.58000000", "0.02498000"], ["110684.72000000", "0.00000000"], ["110676.33000000", "0.00000000"], ["110675.85000000", "0.00000000"], ["110675.79000000", "0.00000000"], ["110662.02000000", "0.00000000"], ["110644.07000000", "0.03698000"], ["110642.25000000", "0.03698000"], ["110635.56000000", "0.04097000"], ["110633.93000000", "0.04097000"], ["110557.19000000", "0.00000000"], ["110532.76000000", "0.06396000"], ["110518.91000000", "0.00000000"], ["110518.87000000", "0.00000000"], ["110499.61000000", "0.03698000"], ["110497.66000000", "0.03698000"]], "a": [["110988.55000000", "6.31743000"], ["110989.14000000", "0.29728000"], ["110989.33000000", "0.00239000"], ["110991.85000000", "0.00000000"], ["110991.86000000", "0.60756000"], ["110991.87000000", "0.00000000"], ["110991.88000000", "0.20292000"], ["110991.89000000", "0.00010000"], ["110991.91000000", "0.00000000"], ["110997.41000000", "0.17757000"], ["111012.74000000", "0.03000000"], ["111028.51000000", "0.27035000"], ["111042.81000000", "0.04416000"], ["111048.88000000", "0.00000000"], ["111054.31000000", "0.00000000"], ["111079.99000000", "1.23416000"], ["111080.04000000", "0.00000000"], ["111087.29000000", "0.04097000"], ["111119.28000000", "0.01483000"], ["111132.26000000", "0.00000000"], ["111205.16000000", "0.00000000"], ["111458.12000000", "0.03698000"], ["111574.51000000", "0.00000000"]]}}
{"type": "orderbook", "local_time": 1761342411264, "event_time": 1761342402814, "latency_ms": 8450, "data": {"e": "depthUpdate", "E": 1761342402814, "s": "BTCUSDT", "U": 79012704827, "u": 79012705317, "b": [["110988.54000000", "0.00000000"], ["110988.53000000", "0.00000000"], ["110987.39000000", "0.00000000"], ["110987.38000000", "0.00000000"], ["110987.37000000", "0.00000000"], ["110986.44000000", "0.00000000"], ["110985.60000000", "0.00000000"], ["110985.28000000", "0.00000000"], ["110984.62000000", "0.00000000"], ["110984.61000000", "0.00000000"], ["110984.56000000", "0.30242000"], ["110984.55000000", "0.00090000"], ["110984.50000000", "0.00030000"], ["110984.48000000", "0.00000000"], ["110984.47000000", "0.00000000"], ["110983.35000000", "0.00000000"], ["110983.34000000", "0.00000000"], ["110983.03000000", "0.00010000"], ["110983.02000000", "0.00010000"], ["110982.60000000", "0.02704000"], ["110980.85000000", "0.00000000"], ["110980.01000000", "0.00010000"], ["110980.00000000", "0.01954000"], ["110979.21000000", "0.21476000"], ["110977.81000000", "0.00010000"], ["110977.80000000", "0.00005000"], ["110977.74000000", "0.00005000"], ["110977.73000000", "0.14719000"], ["110977.66000000", "0.00015000"], ["110977.48000000", "0.00005000"], ["110977.15000000", "0.02939000"], ["110976.60000000", "0.09011000"], ["110975.26000000", "0.00000000"], ["110974.00000000", "0.18141000"], ["110973.93000000", "0.00000000"], ["110973.36000000", "0.00000000"], ["110972.79000000", "0.04541000"], ["110972.25000000", "0.00069000"], ["110972.10000000", "0.00073000"], ["110971.15000000", "0.18626000"], ["110970.13000000", "0.08543000"], ["110968.55000000", "0.00000000"], ["110968.17000000", "0.00000000"], ["110967.91000000", "0.00150000"], ["110967.42000000", "0.00000000"], ["110964.90000000", "0.30402000"], ["110964.58000000", "0.01802000"], ["110963.92000000", "0.00990000"], ["110953.44000000", "0.00009000"], ["110951.29000000", "0.00009000"], ["110951.16000000", "0.00250000"], ["110950.26000000", "0.00009000"], ["110949.20000000", "0.80911000"], ["110946.01000000", "0.00000000"], ["110945.16000000", "0.00009000"], ["110945.15000000", "0.00000000"], ["110941.97000000", "0.00000000"], ["110941.13000000", "0.05481000"], ["110938.78000000", "0.00009000"], ["110936.01000000", "0.01711000"], ["110935.75000000", "0.00037000"], ["110934.95000000", "0.04348000"], ["110934.80000000", "0.00035000"], ["110934.62000000", "0.00090000"], ["110932.47000000", "0.00000000"], ["110932.07000000", "0.06768000"], ["110931.64000000", "0.00005000"], ["110931.61000000", "0.04503000"], ["110929.11000000", "0.34588000"], ["110924.71000000", "0.00000000"], ["110904.92000000", "0.00000000"], ["110897.60000000", "0.00090000"], ["110895.22000000", "0.07213000"], ["110888.15000000", "0.00000000"], ["110886.40000000", "0.00000000"], ["110883.20000000", "0.00000000"], ["110881.40000000", "0.03218000"], ["110881.00000000", "0.00224000"], ["110869.38000000", "0.00005000"], ["110865.00000000", "0.00000000"], ["110864.87000000", "0.00005000"], ["110857.72000000", "0.00191000"], ["110821.58000000", "0.00000000"], ["110729.09000000", "0.00000000"], ["110719.10000000", "0.00000000"], ["110714.82000000", "0.00000000"], ["110714.54000000", "0.00000000"], ["110714.41000000", "0.00000000"], ["110690.00000000", "0.02598000"], ["110689.60000000", "0.02498000"], ["110689.45000000", "0.02498000"], ["110673.91000000", "0.00000000"], ["110636.20000000", "0.03698000"], ["110614.82000000", "0.00000000"], ["110586.22000000", "0.02432000"], ["110575.44000000", "0.00000000"], ["110556.47000000", "0.00000000"], ["110555.74000000", "0.00000000"], ["110538.93000000", "0.00000000"], ["110531.87000000", "0.02698000"], ["110531.76000000", "0.02698000"], ["110500.30000000", "0.03698000"], ["109323.71000000", "0.00000000"], ["99897.00000000", "0.00000000"], ["99889.00000000", "0.00963000"]], "a": [["110984.57000000", "5.75748000"], ["110984.58000000", "0.00024000"], ["110984.59000000", "0.00000000"], ["110984.62000000", "0.00000000"], ["110984.63000000", "0.00000000"], ["110985.29000000", "0.00000000"], ["110985.35000000", "0.00019000"], ["110985.57000000", "0.00000000"], ["110985.98000000", "0.00000000"], ["110986.44000000", "0.00005000"], ["110986.45000000", "0.00000000"], ["110986.68000000", "0.00250000"], ["110986.93000000", "0.00000000"], ["110987.38000000", "0.00000000"], ["110987.39000000", "0.00000000"], ["110987.40000000", "0.00000000"], ["110988.52000000", "0.29728000"], ["110988.54000000", "1.79008000"], ["110988.55000000", "1.40717000"], ["110989.14000000", "0.00020000"], ["110989.33000000", "0.00213000"], ["110991.11000000", "0.00450000"], ["110991.12000000", "0.00250000"], ["110991.86000000", "0.60751000"], ["110991.88000000", "0.20292000"], ["110991.89000000", "0.00000000"], ["110991.92000000", "0.44268000"], ["110992.21000000", "0.00005000"], ["110993.31000000", "0.00044000"], ["110995.67000000", "0.00024000"], ["110996.20000000", "0.01802000"], ["110997.40000000", "1.44347000"], ["110998.48000000", "0.00260000"], ["110998.80000000", "0.00005000"], ["110999.00000000", "0.10685000"], ["110999.33000000", "0.00045000"], ["111000.17000000", "0.00000000"], ["111000.66000000", "0.00000000"], ["111001.21000000", "0.00090000"], ["111002.90000000", "0.00000000"], ["111004.44000000", "0.00250000"], ["111005.20000000", "0.00000000"], ["111005.25000000", "0.00000000"], ["111006.35000000", "0.00000000"], ["111006.68000000", "0.00000000"], ["111007.15000000", "0.07656000"], ["111008.88000000", "0.00000000"], ["111010.23000000", "0.00044000"], ["111015.12000000", "0.00000000"], ["111015.95000000", "0.00044000"], ["111019.03000000", "0.00000000"], ["111021.74000000", "0.32421000"], ["111024.14000000", "0.00000000"], ["111024.54000000", "0.44164000"], ["111025.47000000", "0.00016000"], ["111026.21000000", "0.06913000"], ["111027.06000000", "0.04015000"], ["111028.51000000", "0.00000000"], ["111028.52000000", "0.00000000"], ["111029.87000000", "0.00000000"], ["111033.00000000", "0.00000000"], ["111034.26000000", "0.00000000"], ["111041.24000000", "0.00000000"], ["111042.31000000", "0.00007000"], ["111043.04000000", "0.00000000"], ["111044.69000000", "0.00000000"], ["111044.88000000", "0.00624000"], ["111048.67000000", "0.00000000"], ["111048.90000000", "0.13524000"], ["111049.02000000", "0.03715000"], ["111049.27000000", "0.00000000"], ["111049.36000000", "0.00000000"], ["111049.64000000", "0.03000000"], ["111050.11000000", "0.00000000"], ["111050.46000000", "0.13519000"], ["111059.49000000", "0.00000000"], ["111070.25000000", "0.00000000"], ["111076.67000000", "0.13511000"], ["111078.24000000", "0.47962000"], ["111078.34000000", "0.00000000"], ["111081.37000000", "0.03400000"], ["111084.34000000", "0.00100000"], ["111084.35000000", "0.00100000"], ["111087.34000000", "0.00000000"], ["111087.35000000", "0.00000000"], ["111088.28000000", "0.04097000"], ["111105.93000000", "0.00000000"], ["111109.14000000", "0.01350000"], ["111110.21000000", "0.00000000"], ["111117.75000000", "0.00000000"], ["111130.80000000", "0.00000000"], ["111198.03000000", "0.01711000"], ["111201.36000000", "0.04298000"], ["111314.48000000", "0.01711000"], ["111343.41000000", "0.00000000"], ["112653.38000000", "0.00000000"]]}}
{"type": "orderbook", "local_time": 1761342411264, "event_time": 1761342402914, "latency_ms": 8350, "data": {"e": "depthUpdate", "E": 1761342402914, "s": "BTCUSDT", "U": 79012705318, "u": 79012705474, "b": [["110984.56000000", "0.30247000"], ["110984.55000000", "0.00110000"], ["110984.51000000", "0.00000000"], ["110984.50000000", "0.00020000"], ["110983.03000000", "0.00000000"], ["110983.02000000", "0.00000000"], ["110982.61000000", "0.00010000"], ["110982.60000000", "0.00020000"], ["110981.82000000", "0.00155000"], ["110981.06000000", "0.00000000"], ["110981.05000000", "0.00000000"], ["110980.00000000", "0.01954000"], ["110979.22000000", "0.06469000"], ["110979.21000000", "0.21486000"], ["110978.87000000", "0.04888000"], ["110977.81000000", "0.00000000"], ["110977.80000000", "0.00000000"], ["110977.74000000", "0.00010000"], ["110977.73000000", "0.14719000"], ["110977.49000000", "0.00000000"], ["110977.48000000", "0.00000000"], ["110977.16000000", "0.00005000"], ["110977.15000000", "0.02944000"], ["110972.68000000", "0.09913000"], ["110964.37000000", "0.00000000"], ["110960.85000000", "0.04571000"], ["110939.36000000", "0.20266000"], ["110938.52000000", "0.00000000"], ["110932.07000000", "0.00000000"], ["110920.38000000", "0.00000000"], ["110917.13000000", "0.30938000"], ["110896.67000000", "0.00000000"], ["110887.01000000", "0.00000000"], ["110876.03000000", "0.02536000"], ["110573.62000000", "0.00000000"], ["110554.85000000", "0.00000000"], ["108806.67000000", "0.00000000"]], "a": [["110984.57000000", "5.84168000"], ["110986.68000000", "0.00260000"], ["110988.51000000", "0.00010000"], ["110988.52000000", "0.29748000"], ["110988.53000000", "0.65599000"], ["110988.54000000", "0.20307000"], ["110988.55000000", "1.37394000"], ["110989.14000000", "0.00000000"], ["110989.33000000", "0.00208000"], ["110991.86000000", "0.25124000"], ["110991.88000000", "0.20287000"], ["110991.92000000", "0.39237000"], ["110992.21000000", "0.00000000"], ["110995.35000000", "0.01807000"], ["110996.20000000", "0.00000000"], ["110997.39000000", "0.66488000"], ["111027.06000000", "0.00007000"], ["111041.16000000", "0.04008000"], ["111068.91000000", "0.04860000"], ["111103.39000000", "0.01410000"], ["111140.37000000", "0.06000000"], ["111151.08000000", "1.44342000"], ["112500.00000000", "21.28275000"]]}}
{"type": "orderbook", "local_time": 1761342411265, "event_time": 1761342403014, "latency_ms": 8251, "data": {"e": "depthUpdate", "E": 1761342403014, "s": "BTCUSDT", "U": 79012705475, "u": 79012705606, "b": [["110984.56000000", "0.39663000"], ["110984.55000000", "0.00115000"], ["110984.50000000", "0.00000000"], ["110982.61000000", "0.00000000"], ["110982.60000000", "0.00000000"], ["110981.82000000", "0.00170000"], ["110981.00000000", "0.00000000"], ["110980.62000000", "0.02704000"], ["110980.00000000", "0.01964000"], ["110979.23000000", "0.09858000"], ["110979.22000000", "0.00025000"], ["110979.21000000", "0.21486000"], ["110978.88000000", "0.00010000"], ["110977.73000000", "0.14714000"], ["110977.16000000", "0.00000000"], ["110976.18000000", "0.01833000"], ["110972.68000000", "0.09908000"], ["110904.53000000", "0.00634000"], ["110881.51000000", "0.03900000"], ["110861.95000000", "0.02191000"], ["110550.40000000", "0.02698000"], ["110548.83000000", "0.02698000"], ["110531.67000000", "0.02698000"], ["109319.79000000", "0.00100000"]], "a": [["110984.57000000", "5.66146000"], ["110988.51000000", "0.00010000"], ["110988.52000000", "0.66564000"], ["110988.53000000", "0.00025000"], ["110988.54000000", "0.20302000"], ["110988.55000000", "0.74288000"], ["110991.11000000", "0.00000000"], ["110991.86000000", "0.17786000"], ["110995.24000000", "0.00450000"], ["110995.35000000", "0.01807000"], ["110998.48000000", "0.00253000"], ["111011.70000000", "0.18027000"], ["111024.53000000", "0.00000000"], ["111075.99000000", "0.18027000"], ["111076.32000000", "0.22535000"], ["111077.02000000", "0.22544000"], ["112649.34000000", "0.00100000"]]}}
{"type": "orderbook", "local_time": 1761342411265, "event_time": 1761342403114, "latency_ms": 8151, "data": {"e": "depthUpdate", "E": 1761342403114, "s": "BTCUSDT", "U": 79012705607, "u": 79012705690, "b": [["110984.56000000", "0.30327000"], ["110984.55000000", "0.00120000"], ["110981.82000000", "0.00170000"], ["110980.63000000", "0.00010000"], ["110980.62000000", "0.02724000"], ["110980.00000000", "0.01959000"], ["110979.24000000", "0.00010000"], ["110979.23000000", "0.09853000"], ["110979.22000000", "0.00010000"], ["110978.87000000", "0.04893000"], ["110977.74000000", "0.00000000"], ["110976.60000000", "0.09011000"], ["110974.00000000", "0.18136000"], ["110972.79000000", "0.04536000"], ["110972.25000000", "0.00000000"], ["110958.46000000", "0.00900000"], ["110951.26000000", "0.00300000"], ["110928.05000000", "0.00000000"], ["110927.06000000", "0.00015000"], ["110889.27000000", "0.01410000"], ["110873.40000000", "0.00005000"], ["110870.00000000", "0.00249000"], ["108764.91000000", "0.00459000"], ["99886.00000000", "0.00765000"]], "a": [["110988.51000000", "0.38746000"], ["110988.52000000", "0.29748000"], ["110988.53000000", "0.00010000"], ["110988.54000000", "0.20307000"], ["110991.86000000", "0.17791000"], ["110997.39000000", "0.66493000"], ["111006.77000000", "0.00300000"], ["111031.78000000", "0.00009000"]]}}
{"type": "orderbook", "local_time": 1761342411265, "event_time": 1761342403214, "latency_ms": 8051, "data": {"e": "depthUpdate", "E": 1761342403214, "s": "BTCUSDT", "U": 79012705691, "u": 79012705712, "b": [["110984.56000000", "0.30257000"], ["110982.31000000", "0.00010000"], ["110885.00000000", "0.00000000"], ["110862.00000000", "0.11540000"], ["110645.62000000", "0.00000000"], ["110645.01000000", "0.00000000"], ["110644.68000000", "0.00000000"]], "a": [["110984.57000000", "5.66156000"], ["110986.68000000", "0.00260000"], ["110988.50000000", "0.00010000"], ["110988.51000000", "0.38756000"], ["110988.52000000", "0.29743000"], ["110988.54000000", "0.20302000"], ["110988.55000000", "0.74218000"], ["110991.86000000", "0.17786000"], ["110997.39000000", "0.66488000"], ["111023.94000000", "0.01351000"], ["111028.95000000", "0.00000000"]]}}
{"type": "orderbook", "local_time": 1761342411266, "event_time": 1761342403314, "latency_ms": 7952, "data": {"e": "depthUpdate", "E": 1761342403314, "s": "BTCUSDT", "U": 79012705713, "u": 79012705736, "b": [["110984.56000000", "0.00527000"], ["110981.74000000", "0.29730000"], ["110980.62000000", "0.00020000"], ["110980.54000000", "0.02704000"], ["110972.11000000", "0.00069000"], ["110684.01000000", "0.02598000"], ["110674.28000000", "0.02598000"], ["110665.85000000", "0.02598000"], ["110661.40000000", "0.02598000"], ["110641.09000000", "0.04097000"], ["110640.30000000", "0.04097000"], ["110638.08000000", "0.04097000"]], "a": [["110984.57000000", "5.66226000"], ["110988.50000000", "0.39786000"], ["110988.51000000", "0.00010000"], ["110988.53000000", "0.00000000"], ["110988.54000000", "0.20292000"]]}}
{"type": "orderbook", "local_time": 1761342411266, "event_time": 1761342403414, "latency_ms": 7852, "data": {"e": "depthUpdate", "E": 1761342403414, "s": "BTCUSDT", "U": 79012705737, "u": 79012706024, "b": [["110984.56000000", "0.00000000"], ["110984.55000000", "0.00000000"], ["110982.31000000", "0.00000000"], ["110982.30000000", "0.00000000"], ["110981.97000000", "0.00000000"], ["110981.82000000", "0.00000000"], ["110981.74000000", "0.39900000"], ["110981.73000000", "0.00090000"], ["110980.63000000", "0.00000000"], ["110980.62000000", "0.00000000"], ["110980.55000000", "0.00010000"], ["110980.54000000", "0.00030000"], ["110980.19000000", "0.00527000"], ["110980.00000000", "0.01974000"], ["110979.23000000", "0.09868000"], ["110979.21000000", "0.21491000"], ["110979.00000000", "0.00010000"], ["110978.88000000", "0.00005000"], ["110978.08000000", "0.00000000"], ["110977.66000000", "0.00000000"], ["110976.18000000", "0.01838000"], ["110974.42000000", "0.00000000"], ["110974.00000000", "0.00120000"], ["110973.38000000", "0.00000000"], ["110972.79000000", "0.00000000"], ["110972.11000000", "0.00000000"], ["110972.10000000", "0.00000000"], ["110971.74000000", "0.18016000"], ["110971.33000000", "0.00015000"], ["110966.01000000", "0.00000000"], ["110965.09000000", "0.00150000"], ["110962.51000000", "0.00450000"], ["110961.07000000", "0.00000000"], ["110958.17000000", "0.00000000"], ["110956.77000000", "0.02000000"], ["110954.15000000", "0.00000000"], ["110953.44000000", "0.00000000"], ["110951.29000000", "0.00000000"], ["110950.26000000", "0.00000000"], ["110949.70000000", "0.00000000"], ["110945.16000000", "0.00000000"], ["110942.90000000", "0.00090000"], ["110939.96000000", "0.36568000"], ["110938.78000000", "0.00000000"], ["110931.71000000", "0.00000000"], ["110931.53000000", "0.00000000"], ["110930.26000000", "0.06763000"], ["110927.06000000", "0.00000000"], ["110922.51000000", "0.00000000"], ["110922.06000000", "0.00018000"], ["110916.51000000", "0.00018000"], ["110910.01000000", "0.28296000"], ["110897.60000000", "0.00000000"], ["110893.80000000", "0.00000000"], ["110877.02000000", "0.03939000"], ["110754.01000000", "0.00000000"], ["110743.19000000", "0.00077000"], ["110709.05000000", "0.00000000"], ["110699.06000000", "0.00000000"], ["110689.73000000", "0.00000000"], ["109319.79000000", "0.00000000"], ["99889.00000000", "0.00953000"], ["99886.00000000", "0.00775000"], ["99885.00000000", "0.00053000"]], "a": [["110981.75000000", "3.11900000"], ["110981.78000000", "0.00021000"], ["110981.81000000", "0.00000000"], ["110981.83000000", "0.00000000"], ["110982.53000000", "0.00017000"], ["110983.42000000", "0.00000000"], ["110984.51000000", "0.00000000"], ["110984.56000000", "2.05298000"], ["110984.57000000", "0.76228000"], ["110984.58000000", "0.00000000"], ["110985.35000000", "0.00000000"], ["110986.68000000", "0.00260000"], ["110988.49000000", "0.00000000"], ["110988.50000000", "0.00015000"], ["110988.51000000", "0.00000000"], ["110988.52000000", "0.29738000"], ["110988.55000000", "0.56526000"], ["110991.85000000", "1.44342000"], ["110993.88000000", "0.00007000"], ["110995.35000000", "0.00000000"], ["110996.00000000", "0.06000000"], ["110998.15000000", "0.00044000"], ["110998.22000000", "0.00044000"], ["110998.40000000", "0.00150000"], ["111002.27000000", "0.13519000"], ["111002.38000000", "0.01036000"], ["111003.02000000", "0.00000000"], ["111004.95000000", "0.00000000"], ["111005.02000000", "0.00000000"], ["111011.60000000", "0.22544000"], ["111017.74000000", "0.00360000"], ["111020.59000000", "0.00090000"], ["111021.33000000", "0.44164000"], ["111024.54000000", "0.00000000"], ["111025.62000000", "0.00000000"], ["111030.15000000", "0.00000000"], ["111033.99000000", "0.00016000"], ["111035.25000000", "0.00000000"], ["111040.00000000", "0.01966000"], ["111043.64000000", "0.00000000"], ["111063.59000000", "0.00000000"], ["111093.18000000", "0.36609000"], ["111107.40000000", "0.00000000"]]}}
{"type": "orderbook", "local_time": 1761342412146, "event_time": 1761342403514, "latency_ms": 8632, "data": {"e": "depthUpdate", "E": 1761342403514, "s": "BTCUSDT", "U": 79012706025, "u": 79012706153, "b": [["110981.74000000", "0.39915000"], ["110981.73000000", "0.00110000"], ["110980.55000000", "0.00000000"], ["110980.54000000", "0.00020000"], ["110980.19000000", "0.00015000"], ["110980.00000000", "0.01959000"], ["110979.23000000", "0.09858000"], ["110979.21000000", "0.00010000"], ["110979.00000000", "0.00005000"], ["110978.88000000", "0.00010000"], ["110978.87000000", "0.04898000"], ["110978.52000000", "0.02704000"], ["110977.74000000", "0.00005000"], ["110977.73000000", "0.07160000"], ["110976.18000000", "0.01838000"], ["110971.74000000", "0.00000000"], ["110970.83000000", "0.04536000"], ["110968.93000000", "0.18016000"], ["110968.15000000", "0.07664000"], ["110964.58000000", "0.00000000"], ["110963.69000000", "0.00000000"], ["110958.34000000", "0.36030000"], ["110951.44000000", "0.00009000"], ["110949.29000000", "0.00009000"], ["110948.26000000", "0.00009000"], ["110943.16000000", "0.00009000"], ["110936.78000000", "0.00009000"], ["110934.79000000", "0.20282000"], ["110922.06000000", "0.00000000"], ["110916.51000000", "0.00000000"], ["110895.60000000", "0.00090000"], ["110870.00000000", "0.00160000"], ["110646.75000000", "0.00000000"], ["110645.09000000", "0.00000000"], ["110644.80000000", "0.00000000"], ["99886.00000000", "0.00765000"]], "a": [["110981.75000000", "3.45875000"], ["110982.24000000", "0.00250000"], ["110984.29000000", "0.20756000"], ["110984.55000000", "0.93182000"], ["110984.56000000", "0.20312000"], ["110984.57000000", "0.50380000"], ["110986.44000000", "0.00725000"], ["110986.68000000", "0.00255000"], ["110988.50000000", "0.00000000"], ["110988.55000000", "0.27050000"], ["110991.84000000", "0.60871000"], ["110991.86000000", "0.00005000"], ["110995.25000000", "0.20282000"], ["110998.85000000", "0.06000000"], ["111003.78000000", "0.03000000"], ["111004.44000000", "0.00000000"], ["111022.34000000", "0.00000000"], ["111041.79000000", "0.20247000"], ["111045.73000000", "0.07200000"], ["111055.68000000", "0.00000000"], ["111072.60000000", "0.22535000"], ["111076.32000000", "0.00000000"], ["111090.81000000", "0.16845000"], ["111100.98000000", "0.00000000"], ["111291.40000000", "0.02432000"], ["111393.08000000", "0.00000000"]]}}
{"type": "orderbook", "local_time": 1761342412146, "event_time": 1761342403614, "latency_ms": 8532, "data": {"e": "depthUpdate", "E": 1761342403614, "s": "BTCUSDT", "U": 79012706154, "u": 79012706250, "b": [["110981.74000000", "0.39920000"], ["110981.73000000", "0.00115000"], ["110980.54000000", "0.00000000"], ["110980.19000000", "0.00000000"], ["110980.00000000", "0.01974000"], ["110979.23000000", "0.00020000"], ["110979.22000000", "0.00000000"], ["110979.21000000", "0.00000000"], ["110978.87000000", "0.04903000"], ["110978.53000000", "0.00010000"], ["110975.75000000", "0.21476000"], ["110958.46000000", "0.00000000"], ["110949.19000000", "0.00000000"], ["110941.13000000", "0.13882000"], ["110938.76000000", "0.02198000"], ["110645.21000000", "0.02198000"], ["110643.22000000", "0.02198000"], ["110642.30000000", "0.02198000"]], "a": [["110981.75000000", "3.45895000"], ["110982.24000000", "0.00260000"], ["110984.29000000", "0.20776000"], ["110984.54000000", "0.57179000"], ["110984.55000000", "0.00025000"], ["110984.56000000", "0.20302000"], ["110984.57000000", "0.50370000"], ["110986.44000000", "0.00730000"], ["110986.68000000", "0.00250000"], ["110988.52000000", "0.29733000"], ["110988.54000000", "0.20287000"], ["110988.55000000", "0.27050000"], ["110991.84000000", "0.60876000"], ["110991.86000000", "0.00000000"], ["110991.88000000", "0.20282000"], ["110991.92000000", "0.39232000"], ["110995.50000000", "0.00005000"], ["110998.75000000", "0.03000000"], ["111004.27000000", "0.03000000"], ["111018.01000000", "0.00000000"], ["111033.01000000", "0.00000000"]]}}
{"type": "orderbook", "local_time": 1761342412147, "event_time": 1761342403714, "latency_ms": 8433, "data": {"e": "depthUpdate", "E": 1761342403714, "s": "BTCUSDT", "U": 79012706251, "u": 79012706342, "b": [["110981.74000000", "0.39939000"], ["110981.73000000", "0.00115000"], ["110980.01000000", "0.02918000"], ["110980.00000000", "0.01974000"], ["110979.24000000", "0.00000000"], ["110979.23000000", "0.00000000"], ["110978.87000000", "0.04908000"], ["110978.52000000", "0.00010000"], ["110978.49000000", "0.02704000"], ["110977.74000000", "0.00010000"], ["110977.73000000", "0.12656000"], ["110977.16000000", "0.00005000"], ["110976.18000000", "0.01838000"], ["110973.38000000", "0.04536000"], ["110970.83000000", "0.00000000"], ["110964.90000000", "0.00000000"], ["110962.52000000", "0.30402000"], ["110959.18000000", "0.03600000"], ["110956.07000000", "0.12000000"], ["110954.97000000", "0.16000000"], ["110930.26000000", "0.00000000"], ["110930.20000000", "0.00000000"], ["110875.15000000", "0.00000000"], ["110875.05000000", "0.00000000"], ["110870.60000000", "0.03600000"], ["110870.15000000", "0.00000000"], ["110862.57000000", "0.36593000"]], "a": [["110981.75000000", "3.10047000"], ["110982.24000000", "0.00010000"], ["110983.42000000", "0.01788000"], ["110984.05000000", "0.04548000"], ["110984.28000000", "0.00010000"], ["110984.29000000", "0.20776000"], ["110984.53000000", "0.00010000"], ["110984.54000000", "0.29381000"], ["110984.55000000", "0.00010000"], ["110984.57000000", "0.50037000"], ["110988.51000000", "0.00000000"], ["110997.66000000", "0.03000000"], ["110998.48000000", "0.00246000"], ["110999.88000000", "0.03000000"], ["111004.44000000", "0.00250000"], ["111011.60000000", "0.00000000"], ["111015.69000000", "0.36543000"], ["111017.91000000", "0.00000000"], ["111021.71000000", "0.45079000"], ["111028.94000000", "0.84041000"], ["111072.60000000", "0.00000000"], ["111072.65000000", "0.00000000"], ["111077.02000000", "0.00000000"]]}}
{"type": "orderbook", "local_time": 1761342412147, "event_time": 1761342403814, "latency_ms": 8333, "data": {"e": "depthUpdate", "E": 1761342403814, "s": "BTCUSDT", "U": 79012706343, "u": 79012706437, "b": [["110981.74000000", "0.40052000"], ["110981.73000000", "0.00115000"], ["110980.02000000", "0.00010000"], ["110980.01000000", "0.02943000"], ["110980.00000000", "0.01964000"], ["110978.87000000", "0.04893000"], ["110978.53000000", "0.00000000"], ["110978.52000000", "0.00000000"], ["110978.50000000", "0.00010000"], ["110978.49000000", "0.00000000"], ["110978.34000000", "0.02704000"], ["110977.16000000", "0.00000000"], ["110975.75000000", "0.00000000"], ["110974.23000000", "0.00015000"], ["110971.33000000", "0.00000000"], ["110969.23000000", "0.00034000"], ["110960.34000000", "0.11696000"], ["110956.77000000", "0.00000000"], ["110955.37000000", "0.02000000"], ["110953.03000000", "0.83639000"], ["110930.06000000", "0.06859000"], ["110865.50000000", "0.00005000"], ["109317.01000000", "0.00100000"]], "a": [["110981.75000000", "3.09735000"], ["110982.24000000", "0.00000000"], ["110983.41000000", "0.00010000"], ["110983.42000000", "0.01808000"], ["110984.04000000", "0.00010000"], ["110984.05000000", "0.04568000"], ["110984.29000000", "0.20771000"], ["110984.54000000", "0.40553000"], ["110984.56000000", "0.20287000"], ["110984.57000000", "0.50032000"], ["110988.55000000", "0.27045000"], ["110991.84000000", "0.60871000"], ["110994.37000000", "0.00326000"], ["110997.50000000", "0.00005000"], ["111012.74000000", "0.00000000"], ["111016.81000000", "0.00000000"], ["111021.13000000", "0.95325000"], ["111021.71000000", "0.22535000"], ["111023.45000000", "0.00005000"], ["111072.67000000", "0.00000000"], ["112649.34000000", "0.00000000"]]}}
{"type": "orderbook", "local_time": 1761342412148, "event_time": 1761342403914, "latency_ms": 8234, "data": {"e": "depthUpdate", "E": 1761342403914, "s": "BTCUSDT", "U": 79012706438, "u": 79012706695, "b": [["110981.74000000", "0.01022000"], ["110981.73000000", "0.00110000"], ["110980.01000000", "0.00040000"], ["110978.87000000", "0.00015000"], ["110978.71000000", "0.29731000"], ["110978.50000000", "0.00000000"], ["110978.35000000", "0.00010000"], ["110978.34000000", "0.00010000"], ["110977.73000000", "0.00005000"], ["110977.71000000", "0.02704000"], ["110976.45000000", "0.00000000"], ["110976.18000000", "0.00005000"], ["110976.09000000", "0.00000000"], ["110973.38000000", "0.00005000"], ["110970.37000000", "0.00000000"], ["110968.92000000", "0.00000000"], ["110968.15000000", "0.00000000"], ["110968.08000000", "0.00000000"], ["110966.92000000", "0.00000000"], ["110966.40000000", "0.00000000"], ["110966.34000000", "0.00000000"], ["110964.76000000", "0.00000000"], ["110964.28000000", "0.00000000"], ["110963.68000000", "0.00000000"], ["110963.43000000", "0.04536000"], ["110962.52000000", "0.00000000"], ["110962.51000000", "0.00000000"], ["110960.85000000", "0.00000000"], ["110960.52000000", "0.00000000"], ["110960.49000000", "0.00000000"], ["110959.54000000", "0.11267000"], ["110958.35000000", "0.00450000"], ["110958.09000000", "0.00000000"], ["110956.79000000", "0.00000000"], ["110956.57000000", "0.00000000"], ["110956.07000000", "0.00000000"], ["110955.40000000", "0.30416000"], ["110955.37000000", "0.00000000"], ["110955.20000000", "0.00000000"], ["110954.97000000", "0.00000000"], ["110954.17000000", "0.20282000"], ["110953.88000000", "0.00000000"], ["110952.08000000", "0.14000000"], ["110951.98000000", "0.16000000"], ["110951.44000000", "0.00000000"], ["110950.51000000", "0.00000000"], ["110949.29000000", "0.00000000"], ["110948.93000000", "0.04505000"], ["110948.45000000", "0.04506000"], ["110948.26000000", "0.00000000"], ["110948.20000000", "0.00000000"], ["110946.94000000", "0.00000000"], ["110946.90000000", "0.07661000"], ["110946.54000000", "0.00000000"], ["110943.76000000", "0.00000000"], ["110943.34000000", "0.13511000"], ["110943.16000000", "0.00000000"], ["110942.28000000", "0.00250000"], ["110940.79000000", "0.13519000"], ["110938.70000000", "0.00000000"], ["110937.51000000", "0.07298000"], ["110936.78000000", "0.00000000"], ["110936.01000000", "0.06907000"], ["110935.79000000", "0.22535000"], ["110933.01000000", "0.00000000"], ["110931.61000000", "0.00000000"], ["110930.06000000", "0.00000000"], ["110928.93000000", "0.00000000"], ["110926.75000000", "0.00000000"], ["110926.01000000", "0.00000000"], ["110925.82000000", "0.00000000"], ["110925.65000000", "0.06759000"], ["110925.58000000", "0.04436000"], ["110925.17000000", "0.32450000"], ["110920.76000000", "0.07664000"], ["110919.32000000", "0.11192000"], ["110910.22000000", "0.20282000"], ["110904.81000000", "0.00000000"], ["110904.33000000", "0.20282000"], ["110896.34000000", "0.00000000"], ["110895.60000000", "0.00000000"], ["110893.22000000", "1.44342000"], ["110892.12000000", "0.00000000"], ["110889.02000000", "0.00000000"], ["110887.51000000", "0.13519000"], ["110885.97000000", "0.00000000"], ["110877.31000000", "0.00000000"], ["110869.19000000", "0.22535000"], ["110866.01000000", "0.02612000"], ["110860.42000000", "0.01483000"], ["110847.62000000", "1.54781000"], ["110842.10000000", "1.41564000"], ["110838.26000000", "0.00000000"], ["110824.73000000", "0.00000000"], ["110809.72000000", "0.00000000"], ["110801.27000000", "0.00000000"], ["110775.76000000", "0.03698000"], ["110773.74000000", "0.03698000"], ["110762.43000000", "0.00000000"], ["110744.43000000", "0.24292000"], ["110727.81000000", "0.24292000"], ["110714.73000000", "0.00000000"], ["110704.97000000", "0.00000000"], ["110694.90000000", "0.00005000"], ["110692.94000000", "0.00000000"], ["110684.62000000", "0.00000000"], ["110668.19000000", "0.00000000"], ["110662.44000000", "0.00000000"], ["110657.87000000", "0.00000000"], ["110653.89000000", "0.00000000"], ["110653.79000000", "0.00000000"], ["110653.74000000", "0.00000000"], ["110653.48000000", "0.00000000"], ["110653.19000000", "0.00000000"], ["110650.67000000", "0.00000000"], ["110642.30000000", "0.04396000"], ["110635.36000000", "0.03698000"], ["110633.30000000", "0.03698000"], ["110632.86000000", "0.03698000"], ["110632.10000000", "0.03698000"], ["110631.22000000", "0.03698000"], ["110630.25000000", "0.03698000"], ["110630.18000000", "0.04097000"], ["110628.90000000", "0.03698000"], ["110551.33000000", "0.00000000"], ["110529.86000000", "0.02698000"], ["110520.64000000", "0.00000000"], ["110520.50000000", "0.00000000"], ["110520.34000000", "0.00000000"], ["110519.73000000", "0.00000000"], ["110519.34000000", "0.00000000"], ["110497.82000000", "0.03698000"], ["110496.85000000", "0.03698000"], ["110495.52000000", "0.03698000"], ["110493.70000000", "0.03698000"], ["110491.87000000", "0.03698000"], ["99885.00000000", "0.00043000"], ["99882.00000000", "0.00010000"]], "a": [["110981.75000000", "3.96484000"], ["110981.78000000", "0.00000000"], ["110982.24000000", "0.00250000"], ["110983.41000000", "0.00000000"], ["110984.04000000", "0.00000000"], ["110984.05000000", "0.00020000"], ["110984.28000000", "0.00000000"], ["110984.53000000", "0.00000000"], ["110984.55000000", "0.00000000"], ["110985.67000000", "0.00000000"], ["110986.44000000", "0.00010000"], ["110987.46000000", "0.06000000"], ["110988.52000000", "0.00005000"], ["110997.76000000", "0.03000000"], ["110997.85000000", "0.11491000"], ["110999.26000000", "0.44282000"], ["111001.10000000", "0.03000000"], ["111002.14000000", "0.07661000"], ["111002.27000000", "0.00000000"], ["111004.44000000", "0.00000000"], ["111011.95000000", "0.01916000"], ["111015.04000000", "0.04507000"], ["111017.70000000", "1.11859000"], ["111021.71000000", "0.36054000"], ["111022.60000000", "0.04008000"], ["111023.33000000", "0.24694000"], ["111027.42000000", "0.29975000"], ["111036.57000000", "0.04400000"], ["111041.16000000", "0.00000000"], ["111042.81000000", "0.00000000"], ["111043.65000000", "0.00000000"], ["111048.90000000", "0.00000000"], ["111049.45000000", "0.00000000"], ["111050.46000000", "0.00000000"], ["111050.89000000", "0.00000000"], ["111055.18000000", "0.00000000"], ["111056.44000000", "0.00000000"], ["111061.19000000", "0.00000000"], ["111075.99000000", "0.00000000"], ["111076.67000000", "0.00000000"], ["111190.73000000", "0.03698000"], ["111238.33000000", "0.04097000"], ["111297.53000000", "0.03698000"], ["111358.56000000", "0.00000000"], ["111421.01000000", "0.00000000"], ["111421.26000000", "0.00000000"], ["111452.90000000", "0.03698000"], ["111456.47000000", "0.03698000"], ["111459.59000000", "0.03708000"], ["111462.83000000", "0.03698000"], ["111570.80000000", "0.00000000"], ["111571.62000000", "0.00000000"], ["111572.24000000", "0.00000000"], ["111573.52000000", "0.00000000"]]}}
{"type": "orderbook", "local_time": 1761342412148, "event_time": 1761342404014, "latency_ms": 8134, "data": {"e": "depthUpdate", "E": 1761342404014, "s": "BTCUSDT", "U": 79012706696, "u": 79012707272, "b": [["110981.74000000", "0.00000000"], ["110981.73000000", "0.00000000"], ["110980.96000000", "0.00000000"], ["110980.02000000", "0.00000000"], ["110980.01000000", "0.00000000"], ["110980.00000000", "0.00000000"], ["110979.00000000", "0.00000000"], ["110978.88000000", "0.00000000"], ["110978.87000000", "0.00000000"], ["110978.72000000", "0.00000000"], ["110978.71000000", "0.00406000"], ["110978.70000000", "0.00090000"], ["110978.61000000", "0.00000000"], ["110978.35000000", "0.00000000"], ["110978.34000000", "0.00000000"], ["110978.00000000", "0.00140000"], ["110977.74000000", "0.00000000"], ["110977.73000000", "0.00000000"], ["110977.72000000", "0.00010000"], ["110977.71000000", "0.00030000"], ["110977.16000000", "0.00010000"], ["110977.15000000", "0.00020000"], ["110976.89000000", "0.00000000"], ["110976.61000000", "0.00010000"], ["110976.60000000", "0.09016000"], ["110976.18000000", "0.00000000"], ["110975.50000000", "0.29732000"], ["110974.23000000", "0.00000000"], ["110973.51000000", "0.00000000"], ["110973.50000000", "0.00000000"], ["110973.38000000", "0.00000000"], ["110972.69000000", "0.00010000"], ["110972.68000000", "0.09918000"], ["110972.40000000", "0.00005000"], ["110971.88000000", "0.00000000"], ["110971.30000000", "0.02715000"], ["110971.27000000", "0.00005000"], ["110971.16000000", "0.00005000"], ["110971.15000000", "0.00010000"], ["110971.13000000", "0.11729000"], ["110971.12000000", "0.12157000"], ["110970.13000000", "0.00005000"], ["110969.79000000", "0.20756000"], ["110969.11000000", "0.00000000"], ["110968.93000000", "0.00005000"], ["110968.73000000", "0.00720000"], ["110968.61000000", "0.00015000"], ["110967.78000000", "0.00000000"], ["110966.51000000", "0.00000000"], ["110966.50000000", "0.00000000"], ["110966.07000000", "0.00069000"], ["110965.93000000", "0.00000000"], ["110965.82000000", "0.11460000"], ["110964.89000000", "0.05773000"], ["110964.77000000", "0.00000000"], ["110964.28000000", "0.08680000"], ["110963.93000000", "0.18017000"], ["110963.43000000", "0.00000000"], ["110962.50000000", "0.00010000"], ["110960.34000000", "0.00000000"], ["110959.67000000", "0.04536000"], ["110959.54000000", "0.00000000"], ["110958.35000000", "0.00000000"], ["110958.34000000", "0.00000000"], ["110958.08000000", "0.00990000"], ["110957.52000000", "0.40616000"], ["110956.18000000", "0.00000000"], ["110955.40000000", "0.00000000"], ["110955.39000000", "0.00000000"], ["110954.87000000", "0.00450000"], ["110954.42000000", "0.00000000"], ["110954.17000000", "0.00000000"], ["110954.16000000", "0.76754000"], ["110953.75000000", "0.00005000"], ["110953.04000000", "0.30405000"], ["110953.03000000", "0.00000000"], ["110952.09000000", "0.36034000"], ["110950.97000000", "0.00090000"], ["110944.83000000", "0.00009000"], ["110944.76000000", "0.00000000"], ["110942.69000000", "0.00009000"], ["110941.66000000", "0.00009000"], ["110941.13000000", "0.79683000"], ["110938.12000000", "0.00271000"], ["110936.56000000", "0.00009000"], ["110935.94000000", "0.22544000"], ["110935.17000000", "0.00012000"], ["110934.95000000", "0.07046000"], ["110934.62000000", "0.00000000"], ["110934.12000000", "0.00000000"], ["110933.96000000", "0.00446000"], ["110930.18000000", "0.00009000"], ["110928.98000000", "0.07656000"], ["110928.78000000", "0.00090000"], ["110926.16000000", "0.00005000"], ["110925.65000000", "0.01711000"], ["110925.25000000", "0.01711000"], ["110923.66000000", "0.00000000"], ["110923.21000000", "0.00000000"], ["110919.23000000", "0.00260000"], ["110916.69000000", "0.00000000"], ["110916.50000000", "0.00000000"], ["110914.65000000", "0.00000000"], ["110910.60000000", "0.02663000"], ["110909.76000000", "0.00000000"], ["110908.00000000", "0.02052000"], ["110903.03000000", "0.02213000"], ["110902.35000000", "0.00626000"], ["110889.00000000", "0.00090000"], ["110887.51000000", "0.17217000"], ["110882.97000000", "0.00000000"], ["110881.00000000", "0.00000000"], ["110880.88000000", "0.00055000"], ["110877.03000000", "0.03698000"], ["110874.01000000", "0.00223000"], ["110864.01000000", "0.04097000"], ["110862.01000000", "0.00000000"], ["110862.00000000", "0.00160000"], ["110861.62000000", "0.00000000"], ["110860.01000000", "0.06220000"], ["110857.72000000", "0.00000000"], ["110851.61000000", "0.09817000"], ["110850.77000000", "0.00191000"], ["110840.00000000", "0.00165000"], ["110824.84000000", "0.01711000"], ["110824.83000000", "0.00000000"], ["110797.00000000", "0.00000000"], ["110776.01000000", "0.00000000"], ["110766.72000000", "0.04097000"], ["110764.01000000", "0.00090000"], ["110763.00000000", "0.11380000"], ["110730.00000000", "0.68841000"], ["110709.91000000", "0.00000000"], ["110705.98000000", "0.00000000"], ["110705.92000000", "0.00000000"], ["110700.69000000", "0.00000000"], ["110700.58000000", "0.00000000"], ["110700.27000000", "0.00000000"], ["110699.59000000", "0.00000000"], ["110693.28000000", "0.01711000"], ["110685.90000000", "0.00000000"], ["110681.73000000", "0.00000000"], ["110677.32000000", "0.02498000"], ["110677.27000000", "0.02498000"], ["110676.95000000", "0.02498000"], ["110676.15000000", "0.02498000"], ["110676.05000000", "0.02498000"], ["110675.70000000", "0.02498000"], ["110669.64000000", "0.01711000"], ["110664.80000000", "0.00000000"], ["110661.74000000", "0.00000000"], ["110661.02000000", "0.01711000"], ["110659.86000000", "0.00000000"], ["110658.83000000", "0.00000000"], ["110658.13000000", "0.00000000"], ["110654.65000000", "0.00000000"], ["110654.49000000", "0.00000000"], ["110653.97000000", "0.00000000"], ["110650.53000000", "0.00000000"], ["110637.83000000", "0.02198000"], ["110636.07000000", "0.02198000"], ["110634.29000000", "0.02198000"], ["110633.36000000", "0.02198000"], ["110629.71000000", "0.04097000"], ["110629.55000000", "0.04097000"], ["110626.96000000", "0.03698000"], ["110626.09000000", "0.03698000"], ["110625.81000000", "0.03698000"], ["110624.13000000", "0.03698000"], ["110565.69000000", "0.00000000"], ["110555.05000000", "0.00000000"], ["110554.51000000", "0.00000000"], ["110553.98000000", "0.00000000"], ["110553.45000000", "0.00000000"], ["110552.36000000", "0.00000000"], ["110542.52000000", "0.02698000"], ["110541.75000000", "0.00007000"], ["110541.69000000", "0.02698000"], ["110540.24000000", "0.02698000"], ["110538.69000000", "0.02698000"], ["110538.67000000", "0.00000000"], ["110537.95000000", "0.00000000"], ["110537.37000000", "0.02698000"], ["110536.70000000", "0.02698000"], ["110520.87000000", "0.00000000"], ["110520.65000000", "0.00000000"], ["110519.07000000", "0.02698000"], ["110518.61000000", "0.02698000"], ["110518.57000000", "0.02698000"], ["110491.59000000", "0.03698000"], ["110490.42000000", "0.03698000"], ["110487.18000000", "0.03697000"], ["109317.01000000", "0.00000000"], ["88798.00000000", "0.00000000"]], "a": [["110978.72000000", "5.71882000"], ["110978.73000000", "0.00000000"], ["110978.78000000", "0.00000000"], ["110978.88000000", "0.00000000"], ["110979.01000000", "1.03364000"], ["110979.50000000", "0.00015000"], ["110980.00000000", "0.00005000"], ["110980.01000000", "0.00000000"], ["110980.02000000", "0.00000000"], ["110980.05000000", "0.00000000"], ["110980.55000000", "0.00000000"], ["110980.96000000", "0.00005000"], ["110981.74000000", "0.00000000"], ["110981.75000000", "1.29331000"], ["110982.23000000", "0.00450000"], ["110982.24000000", "0.00260000"], ["110982.53000000", "0.00000000"], ["110982.78000000", "0.29730000"], ["110983.42000000", "0.01803000"], ["110984.05000000", "0.00000000"], ["110984.29000000", "0.00010000"], ["110984.57000000", "0.36653000"], ["110986.44000000", "0.00005000"], ["110987.46000000", "0.06049000"], ["110988.52000000", "0.00000000"], ["110988.55000000", "0.00015000"], ["110989.82000000", "0.00065000"], ["110990.03000000", "0.07661000"], ["110991.92000000", "0.00081000"], ["110992.33000000", "0.00000000"], ["110993.15000000", "0.10420000"], ["110993.31000000", "0.00000000"], ["110994.37000000", "0.00000000"], ["110995.24000000", "0.00000000"], ["110995.36000000", "0.00090000"], ["110997.41000000", "0.04246000"], ["110998.40000000", "0.00000000"], ["110999.00000000", "0.00000000"], ["111004.31000000", "0.03000000"], ["111004.45000000", "0.00000000"], ["111006.91000000", "0.00448000"], ["111007.71000000", "0.00012000"], ["111008.56000000", "0.00000000"], ["111008.82000000", "0.00269000"], ["111011.70000000", "0.00000000"], ["111014.00000000", "0.00000000"], ["111015.68000000", "0.32423000"], ["111016.93000000", "0.00000000"], ["111021.71000000", "0.00000000"], ["111025.48000000", "0.00000000"], ["111027.39000000", "0.00090000"], ["111027.75000000", "0.00000000"], ["111033.99000000", "0.00241000"], ["111035.76000000", "0.00000000"], ["111037.81000000", "0.00632000"], ["111040.98000000", "0.00000000"], ["111042.63000000", "0.00000000"], ["111044.36000000", "0.00000000"], ["111044.70000000", "0.00000000"], ["111044.90000000", "0.13511000"], ["111047.99000000", "0.00000000"], ["111050.88000000", "0.11330000"], ["111051.90000000", "0.00005000"], ["111056.25000000", "0.00000000"], ["111056.93000000", "0.00000000"], ["111067.38000000", "0.04053000"], ["111068.37000000", "0.00110000"], ["111068.83000000", "0.02422000"], ["111087.30000000", "0.00000000"], ["111088.51000000", "0.00000000"], ["111088.75000000", "0.00000000"], ["111101.55000000", "0.08576000"], ["111102.44000000", "0.00000000"], ["111115.12000000", "0.16342000"], ["111124.20000000", "0.00000000"], ["111138.76000000", "0.00000000"], ["111141.98000000", "0.00000000"], ["111155.40000000", "0.02705000"], ["111177.60000000", "0.00000000"], ["111193.26000000", "0.01411000"], ["111204.64000000", "0.00000000"], ["111223.13000000", "0.01711000"], ["111340.40000000", "0.00000000"], ["111350.70000000", "0.48717000"], ["111463.01000000", "0.00000000"], ["111529.68000000", "0.03698000"], ["112646.48000000", "0.00100000"]]}}
{"type": "orderbook", "local_time": 1761342412149, "event_time": 1761342404114, "latency_ms": 8035, "data": {"e": "depthUpdate", "E": 1761342404114, "s": "BTCUSDT", "U": 79012707273, "u": 79012707772, "b": [["110978.71000000", "0.00000000"], ["110978.70000000", "0.00000000"], ["110978.00000000", "0.00000000"], ["110977.72000000", "0.00000000"], ["110977.71000000", "0.00000000"], ["110977.16000000", "0.00000000"], ["110977.15000000", "0.00000000"], ["110976.61000000", "0.00000000"], ["110976.60000000", "0.00000000"], ["110976.00000000", "0.00000000"], ["110975.70000000", "0.00000000"], ["110975.51000000", "0.00000000"], ["110975.50000000", "0.30176000"], ["110975.49000000", "0.00090000"], ["110975.48000000", "0.00000000"], ["110974.00000000", "0.00140000"], ["110973.57000000", "0.00000000"], ["110973.55000000", "0.04918000"], ["110972.68000000", "0.09938000"], ["110972.00000000", "0.00130000"], ["110971.31000000", "0.00010000"], ["110971.30000000", "0.02725000"], ["110971.27000000", "0.00000000"], ["110971.16000000", "0.00000000"], ["110971.15000000", "0.00000000"], ["110971.14000000", "0.00010000"], ["110971.13000000", "0.00020000"], ["110971.12000000", "0.12162000"], ["110970.13000000", "0.00000000"], ["110970.09000000", "0.00011000"], ["110969.80000000", "0.00005000"], ["110969.79000000", "0.00005000"], ["110968.93000000", "0.00000000"], ["110968.73000000", "0.00005000"], ["110968.61000000", "0.00000000"], ["110967.91000000", "0.00000000"], ["110966.07000000", "0.00000000"], ["110965.94000000", "0.00000000"], ["110965.82000000", "0.11465000"], ["110965.81000000", "0.00005000"], ["110965.47000000", "0.00000000"], ["110965.40000000", "0.00000000"], ["110964.89000000", "0.00073000"], ["110964.83000000", "0.00000000"], ["110964.82000000", "0.00000000"], ["110964.48000000", "0.00000000"], ["110963.96000000", "0.00000000"], ["110961.50000000", "0.00000000"], ["110961.00000000", "0.00000000"], ["110960.43000000", "0.00000000"], ["110959.24000000", "0.00000000"], ["110959.19000000", "0.00000000"], ["110958.85000000", "0.00151000"], ["110957.51000000", "0.00000000"], ["110955.77000000", "0.00000000"], ["110955.14000000", "0.00000000"], ["110950.74000000", "0.00000000"], ["110946.72000000", "0.00250000"], ["110942.90000000", "0.00000000"], ["110922.61000000", "0.06716000"], ["110920.68000000", "0.00005000"], ["110900.22000000", "0.00625000"], ["110897.67000000", "0.20282000"], ["110893.23000000", "0.20282000"], ["110882.12000000", "1.44342000"], ["110880.26000000", "0.08194000"], ["110870.60000000", "0.00000000"], ["110848.87000000", "0.09817000"], ["110842.02000000", "0.00000000"], ["110828.51000000", "0.00224000"], ["110770.21000000", "0.00000000"], ["110768.61000000", "0.00000000"], ["110751.12000000", "0.01892000"], ["110746.73000000", "0.01892000"], ["110720.62000000", "0.00000000"], ["110711.74000000", "0.00000000"], ["110711.25000000", "0.00000000"], ["110710.30000000", "0.00000000"], ["110706.69000000", "0.00470000"], ["110690.79000000", "0.02592000"], ["110686.40000000", "0.03424000"], ["110679.00000000", "0.00000000"], ["110657.87000000", "0.01712000"], ["110655.73000000", "0.00000000"], ["110650.04000000", "0.00000000"], ["110642.47000000", "0.00000000"], ["110640.55000000", "0.00000000"], ["110637.28000000", "0.00000000"], ["110632.24000000", "0.00000000"], ["110630.41000000", "0.02432000"], ["110621.74000000", "0.03698000"], ["110619.03000000", "0.04097000"], ["110618.39000000", "0.01712000"], ["110616.01000000", "0.03424000"], ["110596.61000000", "0.00000000"], ["110572.11000000", "0.02432000"], ["110539.18000000", "0.00000000"], ["110518.43000000", "0.02698000"]], "a": [["110975.51000000", "5.03018000"], ["110975.57000000", "0.00000000"], ["110976.01000000", "0.00000000"], ["110976.26000000", "0.00720000"], ["110976.29000000", "0.20769000"], ["110976.61000000", "0.00000000"], ["110977.16000000", "0.00000000"], ["110977.72000000", "0.00000000"], ["110977.80000000", "0.00250000"], ["110978.01000000", "0.00000000"], ["110978.71000000", "2.09600000"], ["110978.72000000", "1.25442000"], ["110979.00000000", "0.00010000"], ["110979.01000000", "0.00020000"], ["110979.50000000", "0.00000000"], ["110981.74000000", "0.00010000"], ["110981.75000000", "0.44177000"], ["110982.23000000", "0.00450000"], ["110982.24000000", "0.00250000"], ["110982.78000000", "0.00010000"], ["110983.42000000", "0.01793000"], ["110984.29000000", "0.00000000"], ["110984.54000000", "0.29371000"], ["110984.57000000", "0.27073000"], ["110988.54000000", "0.20282000"], ["110988.55000000", "0.00010000"], ["110989.05000000", "0.01802000"], ["110990.26000000", "0.00044000"], ["110992.16000000", "0.00150000"], ["110992.20000000", "0.00005000"], ["110995.67000000", "0.00000000"], ["110996.14000000", "0.01036000"], ["110999.33000000", "0.00000000"], ["111000.00000000", "0.00005000"], ["111012.08000000", "0.65672000"], ["111014.35000000", "0.00090000"], ["111014.61000000", "0.44174000"], ["111017.17000000", "0.00016000"], ["111019.15000000", "0.00000000"], ["111021.33000000", "0.00000000"], ["111025.47000000", "0.00000000"], ["111027.39000000", "0.00000000"], ["111039.69000000", "0.13524000"], ["111040.02000000", "0.02572000"], ["111040.77000000", "0.00000000"], ["111040.78000000", "0.00000000"], ["111041.81000000", "0.13519000"], ["111042.54000000", "0.00667000"], ["111046.47000000", "0.03326000"], ["111057.57000000", "0.00000000"], ["111063.99000000", "0.00000000"], ["111066.42000000", "0.00000000"], ["111068.09000000", "0.13511000"], ["111068.53000000", "0.07646000"], ["111068.91000000", "0.00000000"], ["111094.50000000", "0.00000000"], ["111096.66000000", "0.00000000"], ["111111.11000000", "0.15236000"]]}}
{"type": "orderbook", "local_time": 1761342412149, "event_time": 1761342404214, "latency_ms": 7935, "data": {"e": "depthUpdate", "E": 1761342404214, "s": "BTCUSDT", "U": 79012707773, "u": 79012707978, "b": [["110975.50000000", "0.30176000"], ["110975.49000000", "0.00105000"], ["110974.00000000", "0.00140000"], ["110973.56000000", "0.00010000"], ["110973.55000000", "0.00020000"], ["110972.68000000", "0.09923000"], ["110972.00000000", "0.00120000"], ["110971.30000000", "0.02725000"], ["110971.14000000", "0.00000000"], ["110971.13000000", "0.00010000"], ["110971.12000000", "0.12162000"], ["110969.80000000", "0.00000000"], ["110969.79000000", "0.00000000"], ["110968.73000000", "0.00000000"], ["110965.83000000", "0.00005000"], ["110965.82000000", "0.08447000"], ["110965.81000000", "0.00000000"], ["110964.28000000", "0.08685000"], ["110963.93000000", "0.00005000"], ["110963.92000000", "0.00995000"], ["110961.46000000", "0.00329000"], ["110961.03000000", "0.00070000"], ["110960.05000000", "0.18018000"], ["110960.00000000", "0.01952000"], ["110959.68000000", "0.04172000"], ["110957.52000000", "0.00000000"], ["110953.04000000", "0.00000000"], ["110952.08000000", "0.06000000"], ["110951.98000000", "0.00000000"], ["110951.33000000", "0.04571000"], ["110948.28000000", "0.24000000"], ["110947.81000000", "0.30406000"], ["110940.00000000", "0.01962000"], ["110939.36000000", "0.00000000"], ["110936.01000000", "0.05196000"], ["110934.95000000", "0.04614000"], ["110924.37000000", "0.83660000"], ["110922.62000000", "0.02432000"], ["110919.32000000", "0.12904000"], ["110919.06000000", "0.01056000"], ["110917.13000000", "0.33370000"], ["110913.51000000", "0.01056000"], ["110881.40000000", "0.00000000"], ["110876.03000000", "0.00000000"], ["110868.87000000", "0.03218000"], ["110866.87000000", "0.02536000"], ["110860.00000000", "0.01964000"], ["110858.01000000", "0.00000000"], ["110839.29000000", "0.11498000"], ["110828.52000000", "0.00224000"], ["110828.51000000", "0.00000000"], ["110730.01000000", "0.00000000"], ["110718.01000000", "0.00090000"], ["110680.92000000", "0.00000000"], ["110657.87000000", "0.03424000"], ["110646.03000000", "0.00000000"], ["110643.05000000", "0.00000000"], ["110625.41000000", "0.02432000"], ["110616.01000000", "0.05136000"], ["110585.97000000", "0.00000000"], ["110567.08000000", "0.02432000"]], "a": [["110975.51000000", "5.21524000"], ["110976.25000000", "0.00010000"], ["110976.26000000", "0.00735000"], ["110976.28000000", "0.00010000"], ["110976.29000000", "0.20789000"], ["110977.80000000", "0.00255000"], ["110978.70000000", "0.00000000"], ["110978.71000000", "0.20292000"], ["110978.72000000", "1.02092000"], ["110979.00000000", "0.00000000"], ["110979.01000000", "0.00000000"], ["110981.74000000", "0.00000000"], ["110981.75000000", "0.44167000"], ["110982.78000000", "0.00000000"], ["110986.22000000", "1.44342000"], ["110987.46000000", "0.06044000"], ["110988.55000000", "0.00000000"], ["111001.00000000", "0.00011000"], ["111003.69000000", "0.00005000"], ["111004.64000000", "0.00000000"], ["111015.47000000", "0.18027000"], ["111023.45000000", "0.00000000"], ["111023.48000000", "0.00000000"], ["111030.38000000", "0.20249000"], ["111034.49000000", "0.00000000"], ["111040.66000000", "0.13519000"], ["111041.79000000", "0.00000000"], ["111041.81000000", "0.00000000"], ["111044.88000000", "0.00000000"], ["111066.07000000", "0.13511000"], ["111066.28000000", "0.00000000"], ["111068.08000000", "0.11755000"], ["111068.09000000", "0.00000000"], ["111068.53000000", "0.00000000"], ["111151.08000000", "0.00000000"], ["111160.00000000", "0.00428000"]]}}
{"type": "orderbook", "local_time": 1761342412150, "event_time": 1761342404314, "latency_ms": 7836, "data": {"e": "depthUpdate", "E": 1761342404314, "s": "BTCUSDT", "U": 79012707979, "u": 79012708115, "b": [["110975.50000000", "0.00356000"], ["110975.49000000", "0.00110000"], ["110974.00000000", "0.00140000"], ["110973.56000000", "0.00000000"], ["110973.55000000", "0.00000000"], ["110972.68000000", "0.09928000"], ["110972.33000000", "0.00000000"], ["110972.00000000", "0.00125000"], ["110971.48000000", "0.00000000"], ["110971.44000000", "0.00000000"], ["110969.39000000", "0.29734000"], ["110969.26000000", "0.01782000"], ["110965.83000000", "0.00010000"], ["110965.82000000", "0.03175000"], ["110965.70000000", "0.21476000"], ["110964.29000000", "0.00005000"], ["110964.28000000", "0.08685000"], ["110963.93000000", "0.00000000"], ["110963.92000000", "0.00995000"], ["110960.06000000", "0.10245000"], ["110960.05000000", "0.18023000"], ["110960.00000000", "0.01952000"], ["110959.68000000", "0.00000000"], ["110958.33000000", "0.00000000"], ["110955.90000000", "0.00005000"], ["110954.16000000", "0.52335000"], ["110953.30000000", "0.11267000"], ["110952.88000000", "0.01802000"], ["110952.08000000", "0.00000000"], ["110950.84000000", "0.04000000"], ["110949.21000000", "0.20282000"], ["110948.68000000", "0.02000000"], ["110948.48000000", "0.04000000"], ["110948.44000000", "0.05100000"], ["110946.13000000", "0.05400000"], ["110940.13000000", "0.00000000"], ["110938.28000000", "0.80439000"], ["110936.59000000", "0.01712000"], ["110935.49000000", "0.00000000"], ["110931.07000000", "0.00000000"], ["110919.59000000", "0.32451000"], ["110907.73000000", "0.00000000"], ["110906.82000000", "0.01916000"], ["110904.93000000", "0.00000000"], ["110890.26000000", "0.00666000"], ["110869.02000000", "0.00450000"], ["110862.58000000", "0.04097000"], ["110855.98000000", "0.05100000"], ["110853.69000000", "0.05400000"], ["110794.12000000", "0.92843000"], ["110784.34000000", "0.02598000"], ["110719.92000000", "0.02598000"], ["110709.19000000", "0.02598000"], ["110699.64000000", "0.02598000"], ["110689.49000000", "0.02598000"], ["110679.81000000", "0.02598000"], ["110670.33000000", "0.02598000"], ["110660.90000000", "0.02598000"], ["110652.61000000", "0.02598000"], ["110648.05000000", "0.02598000"], ["110645.26000000", "0.00000000"], ["110624.21000000", "0.04097000"], ["110542.36000000", "0.00000000"], ["110517.37000000", "0.02698000"]], "a": [["110975.51000000", "5.44451000"], ["110976.08000000", "0.29732000"], ["110976.28000000", "0.00000000"], ["110978.97000000", "0.00000000"], ["110981.75000000", "0.44172000"], ["110983.53000000", "0.00000000"], ["110984.50000000", "0.01802000"], ["110984.54000000", "0.61408000"], ["110984.57000000", "0.27003000"], ["110989.05000000", "0.00000000"], ["110997.39000000", "0.69488000"], ["110999.70000000", "0.03000000"], ["111025.49000000", "0.01351000"], ["111035.74000000", "0.02212000"], ["111039.63000000", "0.13519000"], ["111040.19000000", "0.00625000"], ["111040.66000000", "0.00000000"], ["111053.87000000", "0.00000000"], ["111066.07000000", "0.00000000"], ["111066.46000000", "0.00000000"], ["111066.48000000", "0.00000000"], ["111068.08000000", "0.07722000"], ["111077.58000000", "0.90015000"], ["111258.91000000", "0.00000000"]]}}
{"type": "orderbook", "local_time": 1761342412150, "event_time": 1761342404414, "latency_ms": 7736, "data": {"e": "depthUpdate", "E": 1761342404414, "s": "BTCUSDT", "U": 79012708116, "u": 79012708282, "b": [["110975.50000000", "0.00366000"], ["110975.49000000", "0.00120000"], ["110971.12000000", "0.12162000"], ["110969.40000000", "0.00010000"], ["110969.39000000", "0.29739000"], ["110969.26000000", "0.00005000"], ["110965.82000000", "0.09176000"], ["110965.70000000", "0.21481000"], ["110965.17000000", "0.00000000"], ["110964.29000000", "0.00000000"], ["110963.92000000", "0.00990000"], ["110960.05000000", "0.18018000"], ["110960.00000000", "0.01947000"], ["110950.84000000", "0.00000000"], ["110948.28000000", "0.00000000"], ["110946.34000000", "0.04000000"], ["110945.68000000", "0.08000000"], ["110944.98000000", "0.16000000"], ["110944.83000000", "0.00000000"], ["110942.69000000", "0.00000000"], ["110942.21000000", "0.00009000"], ["110941.66000000", "0.00000000"], ["110936.66000000", "0.00090000"], ["110936.56000000", "0.00000000"], ["110931.87000000", "0.00000000"], ["110930.18000000", "0.00000000"], ["110922.61000000", "0.00000000"], ["110921.01000000", "0.00000000"], ["110913.43000000", "0.00000000"], ["110909.06000000", "0.00000000"], ["110908.91000000", "0.00009000"], ["110907.50000000", "0.00005000"], ["110906.25000000", "0.00000000"], ["110902.65000000", "0.00000000"], ["110902.01000000", "0.00000000"], ["110898.57000000", "0.00000000"], ["110892.23000000", "0.08294000"], ["110890.01000000", "0.00000000"], ["110889.28000000", "0.00404000"], ["110889.00000000", "0.00000000"], ["110888.95000000", "0.00000000"], ["110888.76000000", "0.00055000"], ["110888.09000000", "0.04097000"], ["110887.09000000", "0.05700000"], ["110886.31000000", "0.00000000"], ["110885.68000000", "0.00000000"], ["110884.01000000", "0.04097000"], ["110883.20000000", "0.05100000"], ["110882.68000000", "0.13230000"], ["110882.01000000", "0.00000000"], ["110878.87000000", "0.08294000"], ["110875.62000000", "0.00009000"], ["110874.01000000", "0.03921000"], ["110871.88000000", "0.00000000"], ["110868.01000000", "0.06709000"], ["110866.87000000", "0.06633000"], ["110866.80000000", "0.00005000"], ["110865.27000000", "0.00000000"], ["110862.93000000", "0.00399000"], ["110862.59000000", "0.08194000"], ["110862.01000000", "0.04097000"], ["110860.01000000", "0.02522000"], ["110842.33000000", "0.00009000"], ["110840.66000000", "0.07853000"], ["110831.97000000", "0.00000000"], ["110809.04000000", "0.00009000"], ["110763.00000000", "0.00000000"], ["110746.00000000", "0.00160000"], ["110730.00000000", "0.00260000"], ["110702.25000000", "0.00000000"], ["110681.52000000", "0.00000000"], ["110677.11000000", "0.00000000"], ["110663.00000000", "0.00000000"], ["110661.34000000", "0.00000000"], ["110657.22000000", "0.00000000"], ["110656.73000000", "0.00000000"], ["110631.00000000", "0.68581000"], ["110630.04000000", "0.02198000"], ["110629.35000000", "0.02198000"], ["110623.99000000", "0.03698000"], ["110603.00000000", "0.11380000"], ["110536.21000000", "0.00000000"], ["110534.22000000", "0.00000000"], ["110533.00000000", "1.36132000"], ["110532.76000000", "0.02698000"], ["110531.73000000", "0.00062000"], ["110531.45000000", "0.00000000"], ["110529.04000000", "0.00000000"], ["110528.16000000", "0.00000000"], ["110526.61000000", "0.00000000"], ["110491.00000000", "2.02305000"], ["110490.62000000", "0.03698000"], ["110489.16000000", "0.03698000"], ["110487.47000000", "0.03698000"], ["110487.31000000", "0.03698000"], ["109599.87000000", "0.02503000"], ["99877.00000000", "0.12321000"]], "a": [["110975.51000000", "5.57985000"], ["110976.08000000", "0.29752000"], ["110976.25000000", "0.00000000"], ["110976.29000000", "0.20784000"], ["110977.80000000", "0.00250000"], ["110978.72000000", "0.88573000"], ["110981.75000000", "0.44167000"], ["110983.42000000", "0.01793000"], ["110984.50000000", "0.01807000"], ["110984.56000000", "0.20282000"], ["110984.57000000", "0.26998000"], ["110990.00000000", "0.00005000"], ["110994.04000000", "0.03000000"], ["110997.93000000", "0.03000000"], ["111008.80000000", "0.00009000"], ["111031.78000000", "0.00000000"], ["111039.63000000", "0.00000000"], ["111039.72000000", "0.13519000"], ["111042.10000000", "0.00009000"], ["111065.08000000", "0.00000000"], ["111075.39000000", "0.00009000"], ["111080.59000000", "0.00000000"], ["111098.38000000", "0.00000000"], ["111099.00000000", "0.02082000"], ["111108.68000000", "0.00009000"], ["111131.68000000", "0.00000000"], ["111141.97000000", "0.00008000"], ["111164.98000000", "0.00000000"], ["111192.00000000", "0.00005000"], ["111214.00000000", "0.16920000"], ["111275.00000000", "0.00065000"], ["111362.00000000", "0.68485000"], ["111409.00000000", "2.00808000"]]}}
{"type": "orderbook", "local_time": 1761342412152, "event_time": 1761342404514, "latency_ms": 7638, "data": {"e": "depthUpdate", "E": 1761342404514, "s": "BTCUSDT", "U": 79012708283, "u": 79012708304, "b": [["110975.50000000", "0.00361000"], ["110975.49000000", "0.00115000"], ["110969.39000000", "0.29739000"], ["110969.26000000", "0.00000000"], ["110963.92000000", "0.00995000"], ["110947.24000000", "0.05100000"], ["110925.58000000", "0.00000000"], ["110887.01000000", "0.09000000"], ["110854.89000000", "0.05100000"], ["110675.47000000", "0.02498000"], ["110491.63000000", "0.03698000"], ["110490.75000000", "0.03698000"], ["110489.87000000", "0.03698000"], ["110488.98000000", "0.03698000"]], "a": [["110975.51000000", "5.58065000"], ["111029.63000000", "0.04357000"], ["111036.57000000", "0.00000000"]]}}
{"type": "orderbook", "local_time": 1761342412152, "event_time": 1761342404614, "latency_ms": 7538, "data": {"e": "depthUpdate", "E": 1761342404614, "s": "BTCUSDT", "U": 79012708305, "u": 79012708352, "b": [["110971.11000000", "0.00000000"], ["110968.00000000", "0.00125000"], ["110967.47000000", "0.00000000"], ["110960.04000000", "0.00000000"], ["110959.67000000", "0.00000000"], ["110954.97000000", "0.04536000"], ["110954.86000000", "0.00000000"], ["110948.48000000", "0.00000000"], ["110946.34000000", "0.00000000"], ["110945.68000000", "0.12000000"], ["110941.53000000", "0.00009000"], ["110940.23000000", "0.13524000"], ["110939.39000000", "0.00009000"], ["110938.74000000", "0.04000000"], ["110938.35000000", "0.00009000"], ["110933.40000000", "0.00250000"], ["110933.26000000", "0.00009000"], ["110926.88000000", "0.00009000"], ["110920.21000000", "0.06667000"], ["110915.44000000", "0.32452000"], ["110901.58000000", "0.00000000"], ["110887.05000000", "0.05100000"], ["110886.95000000", "0.13524000"], ["110885.71000000", "0.00090000"], ["110882.68000000", "0.00000000"], ["110881.56000000", "0.03900000"], ["110855.98000000", "0.00000000"], ["110854.89000000", "0.00000000"], ["110701.32000000", "0.00000000"], ["110675.55000000", "0.02498000"], ["110546.95000000", "0.00000000"], ["110546.04000000", "0.00000000"], ["110519.05000000", "0.02698000"], ["110518.45000000", "0.02698000"], ["102097.47000000", "0.00010000"]], "a": [["110975.51000000", "5.70065000"], ["110981.75000000", "0.36167000"], ["110981.92000000", "0.00361000"], ["111006.89000000", "0.00075000"], ["111008.83000000", "0.32425000"], ["111034.54000000", "0.00000000"], ["111048.94000000", "0.13628000"], ["111078.74000000", "0.00000000"], ["111092.92000000", "0.00000000"], ["111193.26000000", "0.00000000"], ["111213.63000000", "0.01411000"]]}}
{"type": "orderbook", "local_time": 1761342412153, "event_time": 1761342404714, "latency_ms": 7439, "data": {"e": "depthUpdate", "E": 1761342404714, "s": "BTCUSDT", "U": 79012708353, "u": 79012708377, "b": [["110975.50000000", "0.00356000"], ["110975.49000000", "0.00110000"], ["110971.30000000", "0.00010000"], ["110970.97000000", "0.00000000"], ["110970.91000000", "0.00361000"], ["110966.98000000", "0.00856000"], ["110960.06000000", "0.07621000"], ["110936.59000000", "0.00000000"], ["110925.26000000", "0.01712000"], ["110888.14000000", "0.03900000"], ["110706.69000000", "0.00000000"], ["110694.71000000", "0.00470000"], ["110675.36000000", "0.00000000"], ["110673.44000000", "0.00000000"], ["110663.45000000", "0.01712000"], ["110658.09000000", "0.01712000"]], "a": [["110981.92000000", "0.00000000"], ["110984.62000000", "0.00361000"], ["110995.15000000", "0.03000000"]]}}
{"type": "orderbook", "local_time": 1761342412153, "event_time": 1761342404814, "latency_ms": 7339, "data": {"e": "depthUpdate", "E": 1761342404814, "s": "BTCUSDT", "U": 79012708378, "u": 79012708426, "b": [["110975.50000000", "0.00490000"], ["110975.49000000", "0.00115000"], ["110972.68000000", "0.09928000"], ["110971.31000000", "0.00000000"], ["110971.30000000", "0.00000000"], ["110969.39000000", "0.29744000"], ["110966.98000000", "0.00861000"], ["110965.71000000", "0.00005000"], ["110855.23000000", "0.00005000"], ["110853.69000000", "0.00000000"], ["110800.89000000", "0.00000000"], ["110669.47000000", "0.00000000"], ["110647.21000000", "0.00572000"], ["109310.86000000", "0.00100000"], ["99882.00000000", "0.00000000"], ["99877.00000000", "0.12331000"]], "a": [["110975.51000000", "5.69522000"], ["110978.72000000", "0.75069000"], ["110984.62000000", "0.00000000"], ["110984.63000000", "0.00360000"], ["110989.73000000", "0.00005000"], ["110999.88000000", "0.00000000"], ["111015.47000000", "0.31538000"], ["111015.94000000", "0.00251000"], ["111021.49000000", "0.01351000"], ["111023.94000000", "0.00000000"], ["111025.49000000", "0.00000000"], ["111066.16000000", "0.00000000"], ["111094.96000000", "0.00000000"], ["111105.28000000", "0.00000000"], ["111213.63000000", "0.00000000"], ["111247.52000000", "0.01411000"], ["112646.48000000", "0.00000000"]]}}
{"type": "orderbook", "local_time": 1761342412154, "event_time": 1761342404914, "latency_ms": 7240, "data": {"e": "depthUpdate", "E": 1761342404914, "s": "BTCUSDT", "U": 79012708427, "u": 79012708452, "b": [["110965.70000000", "0.20761000"], ["110964.45000000", "0.00720000"], ["110952.46000000", "0.03600000"], ["110949.14000000", "0.03600000"], ["110881.96000000", "0.03600000"], ["110860.31000000", "0.03600000"], ["110825.21000000", "0.06000000"], ["110785.58000000", "0.01411000"], ["110716.11000000", "0.00000000"], ["110686.52000000", "0.01712000"], ["110651.10000000", "0.00000000"], ["110631.50000000", "0.00000000"], ["110618.56000000", "0.01712000"], ["110616.08000000", "0.01712000"]], "a": [["110975.51000000", "5.65514000"], ["110976.26000000", "0.00015000"], ["110976.29000000", "0.00028000"], ["110984.50000000", "0.00005000"], ["110991.92000000", "0.00005000"], ["110996.35000000", "0.03000000"], ["111123.85000000", "0.06000000"], ["111148.39000000", "0.00000000"]]}}
{"type": "orderbook", "local_time": 1761342412154, "event_time": 1761342405014, "latency_ms": 7140, "data": {"e": "depthUpdate", "E": 1761342405014, "s": "BTCUSDT", "U": 79012708453, "u": 79012708502, "b": [["110975.50000000", "0.00495000"], ["110975.49000000", "0.00120000"], ["110965.70000000", "0.20761000"], ["110956.79000000", "0.04536000"], ["110954.97000000", "0.00000000"], ["110948.45000000", "0.00000000"], ["110945.86000000", "0.03900000"], ["110937.51000000", "0.03698000"], ["110853.74000000", "0.03900000"]], "a": [["110975.51000000", "5.72763000"], ["110976.08000000", "0.29752000"], ["110976.26000000", "0.00000000"], ["110976.29000000", "0.00010000"], ["110977.80000000", "0.00255000"], ["110978.48000000", "0.00076000"], ["110978.72000000", "0.63802000"], ["110981.75000000", "0.36172000"], ["110983.42000000", "0.01793000"], ["110983.84000000", "0.11267000"], ["110984.50000000", "0.00000000"], ["110984.56000000", "0.20287000"], ["110984.57000000", "0.27003000"], ["110985.23000000", "0.01802000"], ["110986.22000000", "1.44347000"], ["110989.71000000", "0.13519000"], ["110998.48000000", "0.00628000"], ["111001.10000000", "0.00000000"], ["111015.04000000", "0.00000000"], ["111015.47000000", "0.00000000"], ["111066.41000000", "0.03400000"], ["111066.90000000", "0.18027000"], ["111068.19000000", "0.13539000"], ["111077.49000000", "0.03000000"], ["111081.37000000", "0.00000000"], ["111247.52000000", "0.00000000"], ["112640.15000000", "0.00100000"]]}}
{"type": "orderbook", "local_time": 1761342412155, "event_time": 1761342405114, "latency_ms": 7041, "data": {"e": "depthUpdate", "E": 1761342405114, "s": "BTCUSDT", "U": 79012708503, "u": 79012708552, "b": [["110975.50000000", "0.00495000"], ["110975.49000000", "0.00120000"], ["110969.39000000", "0.00010000"], ["110967.83000000", "0.00000000"], ["110966.49000000", "0.29734000"], ["110945.23000000", "0.00900000"], ["110937.84000000", "0.00250000"], ["110933.40000000", "0.00000000"], ["110882.48000000", "0.13435000"], ["110860.31000000", "0.00000000"], ["110853.74000000", "0.00000000"], ["110785.58000000", "0.00000000"], ["110769.01000000", "0.01411000"], ["110647.81000000", "0.00000000"], ["110647.02000000", "0.00000000"], ["110631.82000000", "0.00000000"], ["110629.13000000", "0.02432000"], ["110626.46000000", "0.02432000"], ["110625.48000000", "0.02432000"], ["102097.47000000", "0.00000000"]], "a": [["110975.51000000", "5.73483000"], ["110976.08000000", "0.29752000"], ["110976.29000000", "0.00000000"], ["110977.80000000", "0.00260000"], ["110978.48000000", "0.00081000"], ["110978.70000000", "0.36111000"], ["110983.42000000", "0.01793000"], ["110983.84000000", "0.11272000"], ["110984.57000000", "0.27003000"], ["110986.22000000", "1.44342000"], ["110986.61000000", "0.00300000"], ["110999.65000000", "0.00000000"], ["111015.47000000", "0.00000000"], ["111021.13000000", "0.00000000"], ["111039.72000000", "0.00000000"], ["111066.90000000", "0.00000000"], ["111068.19000000", "0.00028000"]]}}
{"type": "orderbook", "local_time": 1761342412156, "event_time": 1761342405214, "latency_ms": 6942, "data": {"e": "depthUpdate", "E": 1761342405214, "s": "BTCUSDT", "U": 79012708553, "u": 79012708606, "b": [["110975.50000000", "0.00490000"], ["110975.49000000", "0.00120000"], ["110971.12000000", "0.12162000"], ["110969.40000000", "0.00000000"], ["110969.39000000", "0.00000000"], ["110966.98000000", "0.00861000"], ["110966.50000000", "0.18502000"], ["110966.49000000", "0.29739000"], ["110965.82000000", "0.00005000"], ["110918.01000000", "0.00000000"], ["110915.34000000", "0.00000000"], ["110912.01000000", "0.00000000"], ["110906.01000000", "0.00000000"], ["110898.01000000", "0.02522000"], ["110895.42000000", "0.01892000"], ["110862.93000000", "0.03012000"], ["110858.01000000", "0.02613000"], ["110850.78000000", "0.02613000"], ["110839.29000000", "0.14111000"]], "a": [["110975.51000000", "5.73488000"], ["110976.08000000", "0.29752000"], ["110978.70000000", "0.36121000"], ["110981.75000000", "0.36167000"], ["110984.57000000", "0.26998000"], ["111015.47000000", "0.18027000"], ["111017.70000000", "0.69547000"], ["111042.35000000", "0.13519000"], ["111066.27000000", "0.00000000"], ["111067.79000000", "0.13511000"], ["111093.87000000", "0.02613000"], ["111101.07000000", "0.02613000"], ["111113.52000000", "0.02613000"], ["111113.58000000", "0.00000000"], ["111125.72000000", "0.00000000"], ["111125.85000000", "0.00000000"]]}}
