{"type": "orderbook", "local_time": 1761342412157, "event_time": 1761342405314, "latency_ms": 6843, "data": {"e": "depthUpdate", "E": 1761342405314, "s": "BTCUSDT", "U": 79012708607, "u": 79012708629, "b": [["110975.50000000", "0.00495000"], ["110975.49000000", "0.00120000"], ["110971.12000000", "0.12162000"], ["110967.47000000", "0.00000000"], ["110966.98000000", "0.00861000"], ["110966.51000000", "0.00010000"], ["110966.50000000", "0.18507000"], ["110966.49000000", "0.29739000"], ["110965.83000000", "0.00000000"], ["110965.82000000", "0.00000000"]], "a": [["110975.51000000", "5.73514000"], ["111004.27000000", "1.00169000"]]}}
{"type": "orderbook", "local_time": 1761342412159, "event_time": 1761342405414, "latency_ms": 6745, "data": {"e": "depthUpdate", "E": 1761342405414, "s": "BTCUSDT", "U": 79012708630, "u": 79012708639, "b": [["110962.40000000", "0.01800000"], ["110959.34000000", "0.04536000"], ["110956.79000000", "0.00000000"], ["110867.82000000", "0.04508000"], ["110007.31000000", "0.00251000"]], "a": [["110975.52000000", "0.04505000"], ["110982.30000000", "0.00005000"], ["111003.11000000", "0.43310000"], ["111074.70000000", "0.00000000"], ["112053.31000000", "0.00247000"]]}}
{"type": "orderbook", "local_time": 1761342412159, "event_time": 1761342405514, "latency_ms": 6645, "data": {"e": "depthUpdate", "E": 1761342405514, "s": "BTCUSDT", "U": 79012708640, "u": 79012708666, "b": [["110975.50000000", "0.00495000"], ["110975.49000000", "0.00120000"], ["110963.92000000", "0.00990000"], ["99877.00000000", "0.12331000"]], "a": [["110975.51000000", "5.76412000"], ["110975.52000000", "0.04520000"], ["110977.80000000", "0.00255000"], ["110978.48000000", "0.00076000"], ["110978.72000000", "0.63797000"], ["110984.56000000", "0.20282000"], ["111066.40000000", "0.00000000"], ["111066.41000000", "0.00000000"], ["111067.35000000", "0.03400000"], ["111077.51000000", "0.00000000"]]}}
{"type": "orderbook", "local_time": 1761342412160, "event_time": 1761342405614, "latency_ms": 6546, "data": {"e": "depthUpdate", "E": 1761342405614, "s": "BTCUSDT", "U": 79012708667, "u": 79012708670, "b": [["110952.89000000", "0.30405000"], ["110947.81000000", "0.00000000"], ["99877.00000000", "0.12331000"]], "a": [["111078.80000000", "0.03000000"]]}}
{"type": "orderbook", "local_time": 1761342412160, "event_time": 1761342405714, "latency_ms": 6446, "data": {"e": "depthUpdate", "E": 1761342405714, "s": "BTCUSDT", "U": 79012708671, "u": 79012708671, "b": [["39951.18000000", "0.00016000"]], "a": []}}
{"type": "orderbook", "local_time": 1761342412160, "event_time": 1761342405814, "latency_ms": 6346, "data": {"e": "depthUpdate", "E": 1761342405814, "s": "BTCUSDT", "U": 79012708672, "u": 79012708685, "b": [["110966.56000000", "0.04939000"], ["110952.89000000", "0.00000000"], ["110950.74000000", "0.30405000"], ["110929.50000000", "0.00010000"], ["110920.21000000", "0.00000000"], ["110919.76000000", "0.06908000"], ["110882.48000000", "0.00000000"], ["109310.86000000", "0.00100000"]], "a": [["110975.51000000", "5.89931000"], ["111015.47000000", "0.31538000"], ["111042.35000000", "0.00000000"], ["111067.79000000", "0.00000000"], ["111317.89000000", "0.48717000"], ["111350.70000000", "0.00000000"]]}}
{"type": "orderbook", "local_time": 1761342412161, "event_time": 1761342405914, "latency_ms": 6247, "data": {"e": "depthUpdate", "E": 1761342405914, "s": "BTCUSDT", "U": 79012708686, "u": 79012708710, "b": [["110975.50000000", "0.00495000"], ["110975.49000000", "0.00120000"], ["110971.12000000", "0.12157000"], ["110966.98000000", "0.00861000"], ["110966.57000000", "0.00010000"], ["110966.56000000", "0.00000000"], ["110965.71000000", "0.00000000"], ["110962.40000000", "0.00000000"], ["110959.18000000", "0.00000000"], ["39951.18000000", "0.00032000"]], "a": [["110975.52000000", "0.04525000"], ["110981.96000000", "0.00005000"], ["110985.84000000", "0.00005000"], ["110989.71000000", "0.00000000"], ["111015.47000000", "0.18027000"], ["111040.00000000", "0.15485000"], ["111066.01000000", "0.13511000"]]}}
{"type": "orderbook", "local_time": 1761342412161, "event_time": 1761342406014, "latency_ms": 6147, "data": {"e": "depthUpdate", "E": 1761342406014, "s": "BTCUSDT", "U": 79012708711, "u": 79012708735, "b": [["110975.50000000", "0.00485000"], ["110975.49000000", "0.00105000"], ["110966.98000000", "0.00861000"], ["110966.57000000", "0.00000000"], ["110965.71000000", "0.00005000"], ["110904.53000000", "0.00000000"], ["110888.88000000", "0.00618000"], ["110740.48000000", "0.00000000"], ["99877.00000000", "0.12331000"]], "a": [["110975.51000000", "5.89951000"], ["111028.03000000", "0.00000000"], ["111237.31000000", "0.00000000"], ["112640.15000000", "0.00100000"]]}}
{"type": "orderbook", "local_time": 1761342412162, "event_time": 1761342406114, "latency_ms": 6048, "data": {"e": "depthUpdate", "E": 1761342406114, "s": "BTCUSDT", "U": 79012708736, "u": 79012708740, "b": [], "a": [["110975.51000000", "5.76432000"], ["110978.48000000", "0.00000000"], ["110985.23000000", "0.00000000"], ["110985.32000000", "0.01802000"], ["111003.02000000", "0.00900000"]]}}
{"type": "orderbook", "local_time": 1761342412162, "event_time": 1761342406214, "latency_ms": 5948, "data": {"e": "depthUpdate", "E": 1761342406214, "s": "BTCUSDT", "U": 79012708741, "u": 79012708745, "b": [["110975.50000000", "0.00505000"]], "a": [["110975.51000000", "5.76406000"], ["110978.49000000", "0.00076000"], ["110989.03000000", "0.13519000"], ["111078.80000000", "0.00000000"]]}}
{"type": "orderbook", "local_time": 1761342412163, "event_time": 1761342406314, "latency_ms": 5849, "data": {"e": "depthUpdate", "E": 1761342406314, "s": "BTCUSDT", "U": 79012708746, "u": 79012708973, "b": [["110975.50000000", "0.00000000"], ["110975.49000000", "0.00000000"], ["110974.20000000", "0.00000000"], ["110974.00000000", "0.00175000"], ["110973.99000000", "0.00090000"], ["110972.68000000", "0.09938000"], ["110972.00000000", "0.00140000"], ["110971.89000000", "0.00010000"], ["110971.73000000", "0.00305000"], ["110971.12000000", "0.12162000"], ["110970.32000000", "0.00000000"], ["110970.09000000", "0.00000000"], ["110967.48000000", "0.00011000"], ["110966.50000000", "0.18512000"], ["110966.49000000", "0.29744000"], ["110965.70000000", "0.20766000"], ["110964.45000000", "0.00725000"], ["110963.92000000", "0.00005000"], ["110962.40000000", "0.01838000"], ["110960.06000000", "0.07626000"], ["110957.35000000", "0.00151000"], ["110953.27000000", "0.00990000"], ["110932.01000000", "0.02598000"], ["110919.76000000", "0.00000000"], ["110919.06000000", "0.00000000"], ["110913.51000000", "0.00000000"], ["110725.53000000", "0.83811000"], ["110661.96000000", "0.02598000"], ["110652.89000000", "0.02598000"], ["110648.85000000", "0.02598000"], ["109310.86000000", "0.00000000"]], "a": [["110974.01000000", "5.18792000"], ["110974.07000000", "0.00000000"], ["110974.21000000", "0.00000000"], ["110974.76000000", "0.00000000"], ["110975.48000000", "0.00005000"], ["110975.50000000", "1.52757000"], ["110975.51000000", "1.13004000"], ["110976.08000000", "0.00015000"], ["110977.80000000", "0.00250000"], ["110978.71000000", "0.20287000"], ["110978.72000000", "0.36691000"], ["110981.75000000", "0.13623000"], ["110984.54000000", "0.61403000"], ["110985.11000000", "0.00099000"], ["110987.46000000", "0.06000000"], ["110990.41000000", "0.00044000"], ["110990.48000000", "0.00044000"], ["110992.16000000", "0.00000000"], ["110997.41000000", "0.04418000"], ["110998.15000000", "0.00000000"], ["110998.22000000", "0.00000000"], ["111010.23000000", "0.00000000"], ["111015.47000000", "0.00000000"], ["111015.87000000", "0.13511000"], ["111024.00000000", "0.00120000"], ["111026.00000000", "0.00120000"], ["111028.00000000", "0.00120000"], ["111030.28000000", "0.00094000"], ["111052.58000000", "0.00000000"], ["111055.09000000", "0.03000000"], ["111056.16000000", "0.00225000"], ["111065.91000000", "0.18027000"], ["111066.60000000", "0.00000000"], ["111074.20000000", "0.00000000"], ["111214.17000000", "4.82016000"], ["111318.02000000", "1.19998000"], ["111353.43000000", "0.00000000"], ["112640.15000000", "0.00000000"]]}}
{"type": "orderbook", "local_time": 1761342412264, "event_time": 1761342406414, "latency_ms": 5850, "data": {"e": "depthUpdate", "E": 1761342406414, "s": "BTCUSDT", "U": 79012708974, "u": 79012709029, "b": [["110974.00000000", "0.00185000"], ["110973.99000000", "0.00110000"], ["110972.00000000", "0.00130000"], ["110971.89000000", "0.00000000"], ["110968.00000000", "0.00120000"], ["110964.28000000", "0.08685000"], ["110963.92000000", "0.00000000"], ["110962.40000000", "0.00005000"], ["110922.69000000", "0.20269000"]], "a": [["110974.01000000", "5.29206000"], ["110975.50000000", "0.04320000"], ["110975.51000000", "1.03143000"], ["110975.52000000", "0.00015000"], ["110976.08000000", "0.00000000"], ["110978.70000000", "0.21299000"], ["111050.88000000", "0.05803000"]]}}
{"type": "orderbook", "local_time": 1761342412265, "event_time": 1761342406514, "latency_ms": 5751, "data": {"e": "depthUpdate", "E": 1761342406514, "s": "BTCUSDT", "U": 79012709030, "u": 79012709193, "b": [["110974.00000000", "0.00000000"], ["110973.99000000", "0.00210000"], ["110973.98000000", "0.00085000"], ["110972.00000000", "0.00140000"], ["110971.73000000", "0.00310000"], ["110971.12000000", "0.12167000"], ["110965.87000000", "0.04984000"], ["110964.28000000", "0.08685000"], ["110962.40000000", "0.00000000"], ["110960.05000000", "0.18023000"], ["110919.50000000", "0.06666000"], ["99877.00000000", "0.12321000"], ["99876.00000000", "0.00060000"]], "a": [["110974.00000000", "4.97419000"], ["110974.01000000", "1.48554000"], ["110975.50000000", "0.00020000"], ["110975.51000000", "0.58059000"], ["110975.52000000", "0.00000000"], ["110977.80000000", "0.00250000"], ["110979.55000000", "0.00011000"], ["111013.10000000", "0.44230000"], ["111014.61000000", "0.00000000"], ["111039.06000000", "0.00000000"], ["111073.64000000", "0.06000000"]]}}
{"type": "orderbook", "local_time": 1761342412266, "event_time": 1761342406614, "latency_ms": 5652, "data": {"e": "depthUpdate", "E": 1761342406614, "s": "BTCUSDT", "U": 79012709194, "u": 79012709262, "b": [["110973.99000000", "0.00211000"], ["110973.98000000", "0.00105000"], ["110972.00000000", "0.00130000"], ["110971.73000000", "0.00305000"], ["110971.22000000", "0.00198000"], ["110971.12000000", "0.12162000"], ["110970.26000000", "0.00011000"], ["110967.48000000", "0.00000000"], ["110967.34000000", "0.00541000"], ["110966.49000000", "0.29744000"], ["110965.88000000", "0.00005000"], ["110965.87000000", "0.04994000"], ["110965.70000000", "0.20761000"], ["110964.56000000", "0.00396000"], ["110962.90000000", "0.00721000"], ["110960.05000000", "0.18018000"], ["110851.99000000", "0.00000000"], ["110840.90000000", "0.00000000"], ["99876.00000000", "0.00060000"]], "a": [["110974.00000000", "5.06253000"], ["110974.01000000", "0.79403000"], ["110975.10000000", "0.00099000"], ["110975.50000000", "0.17405000"], ["110975.51000000", "0.57994000"], ["110976.77000000", "0.00198000"], ["110977.80000000", "0.00255000"], ["110978.43000000", "0.00360000"], ["110978.71000000", "0.20292000"], ["110980.65000000", "0.00541000"], ["110982.74000000", "0.00044000"], ["110984.54000000", "0.61408000"], ["110999.59000000", "0.00000000"], ["111005.13000000", "0.00000000"], ["111014.41000000", "0.00000000"], ["111017.74000000", "0.00000000"], ["111064.99000000", "0.00010000"], ["111083.08000000", "0.00000000"], ["111317.89000000", "0.00000000"]]}}
{"type": "orderbook", "local_time": 1761342412270, "event_time": 1761342406714, "latency_ms": 5556, "data": {"e": "depthUpdate", "E": 1761342406714, "s": "BTCUSDT", "U": 79012709263, "u": 79012709323, "b": [["110973.99000000", "0.00221000"], ["110973.98000000", "0.00110000"], ["110971.73000000", "0.00305000"], ["110971.12000000", "0.12162000"], ["110967.34000000", "0.00546000"], ["110964.28000000", "0.08685000"], ["110960.06000000", "0.07621000"], ["110948.26000000", "0.03600000"], ["110870.60000000", "0.03600000"], ["110829.81000000", "0.00114000"], ["110818.72000000", "0.00229000"], ["110694.98000000", "0.00000000"], ["110007.31000000", "0.00000000"], ["33000.00000000", "3.79445000"]], "a": [["110974.00000000", "5.06258000"], ["110974.01000000", "0.56859000"], ["110975.10000000", "0.00109000"], ["110975.50000000", "0.17420000"], ["110975.51000000", "0.57984000"], ["110977.80000000", "0.00250000"], ["110978.71000000", "0.20287000"], ["110978.72000000", "0.36691000"], ["110980.65000000", "0.00546000"], ["110983.84000000", "0.11267000"], ["110984.54000000", "0.61403000"], ["110990.00000000", "0.00011000"], ["111013.96000000", "0.00000000"], ["111064.99000000", "0.00124000"], ["111065.14000000", "0.22544000"], ["111069.85000000", "0.00100000"], ["111069.86000000", "0.00100000"], ["111084.34000000", "0.00000000"], ["111084.35000000", "0.00000000"], ["111105.53000000", "0.02306000"], ["111279.67000000", "0.00017000"], ["112053.31000000", "0.00000000"]]}}
{"type": "orderbook", "local_time": 1761342412271, "event_time": 1761342406814, "latency_ms": 5457, "data": {"e": "depthUpdate", "E": 1761342406814, "s": "BTCUSDT", "U": 79012709324, "u": 79012709332, "b": [["110926.15000000", "0.00000000"], ["110668.18000000", "0.00401000"]], "a": [["110985.60000000", "0.00005000"], ["111065.14000000", "0.00000000"], ["111065.91000000", "0.00000000"], ["111071.40000000", "0.00000000"], ["111078.64000000", "0.00402000"], ["111082.58000000", "0.00229000"], ["111252.76000000", "0.00089000"]]}}
{"type": "orderbook", "local_time": 1761342412272, "event_time": 1761342406914, "latency_ms": 5358, "data": {"e": "depthUpdate", "E": 1761342406914, "s": "BTCUSDT", "U": 79012709333, "u": 79012709350, "b": [["110973.99000000", "0.00252000"], ["110964.45000000", "0.00005000"], ["110964.04000000", "0.00720000"], ["110857.74000000", "0.00005000"], ["109309.38000000", "0.00100000"], ["50000.00000000", "39.95352000"]], "a": [["110974.00000000", "5.24285000"], ["110974.02000000", "0.00000000"], ["110975.51000000", "0.36508000"], ["111009.15000000", "0.00005000"], ["111013.96000000", "0.22544000"], ["111039.97000000", "0.76568000"], ["111105.51000000", "0.00000000"]]}}
{"type": "orderbook", "local_time": 1761342412272, "event_time": 1761342407014, "latency_ms": 5258, "data": {"e": "depthUpdate", "E": 1761342407014, "s": "BTCUSDT", "U": 79012709351, "u": 79012709394, "b": [["110973.99000000", "0.00252000"], ["110973.98000000", "0.00110000"], ["110966.50000000", "0.00020000"], ["110965.87000000", "0.00010000"], ["110965.70000000", "0.00005000"], ["110964.45000000", "0.00000000"], ["110964.28000000", "0.08685000"], ["110964.04000000", "0.00005000"], ["110960.06000000", "0.00038000"], ["110959.34000000", "0.00000000"], ["110956.51000000", "0.04536000"], ["110952.88000000", "0.00000000"], ["110945.68000000", "0.04000000"], ["110944.29000000", "0.08000000"], ["110931.01000000", "0.00000000"], ["110924.37000000", "0.00000000"], ["110919.50000000", "0.00000000"], ["110909.65000000", "0.32454000"], ["88779.00000000", "0.00000000"], ["50000.00000000", "39.95292000"]], "a": [["110974.00000000", "5.59272000"], ["110975.50000000", "0.11046000"], ["110984.50000000", "0.00005000"], ["111015.87000000", "0.00000000"], ["111038.23000000", "0.00000000"], ["111039.46000000", "0.13524000"], ["111039.69000000", "0.00000000"], ["111065.41000000", "0.13528000"], ["111066.01000000", "0.00000000"], ["112638.61000000", "0.00100000"]]}}
{"type": "orderbook", "local_time": 1761342412273, "event_time": 1761342407114, "latency_ms": 5159, "data": {"e": "depthUpdate", "E": 1761342407114, "s": "BTCUSDT", "U": 79012709395, "u": 79012709464, "b": [["110973.99000000", "0.00247000"], ["110973.98000000", "0.00090000"], ["110971.12000000", "0.12162000"], ["110970.91000000", "0.00000000"], ["110967.54000000", "0.00000000"], ["110966.98000000", "0.00861000"], ["110966.51000000", "0.00000000"], ["110966.50000000", "0.00010000"], ["110966.49000000", "0.29744000"], ["110965.88000000", "0.00000000"], ["110965.87000000", "0.00000000"], ["110965.71000000", "0.00000000"], ["110965.70000000", "0.00000000"], ["110965.03000000", "0.00000000"], ["110964.29000000", "0.00010000"], ["110964.28000000", "0.08690000"], ["110964.06000000", "0.21476000"], ["110964.04000000", "0.00000000"], ["110962.90000000", "0.00726000"], ["110961.68000000", "0.01770000"], ["110960.06000000", "0.00043000"], ["110960.05000000", "0.18028000"], ["110953.96000000", "0.00000000"], ["110952.86000000", "0.01802000"], ["110950.74000000", "0.00000000"], ["110948.94000000", "0.30406000"], ["110930.80000000", "0.13939000"], ["110922.90000000", "0.00005000"], ["50000.00000000", "39.95262000"]], "a": [["110974.00000000", "5.49933000"], ["110978.72000000", "0.32535000"], ["110984.63000000", "0.00000000"], ["111007.30000000", "0.00300000"], ["111013.87000000", "0.13511000"], ["111018.42000000", "0.00000000"]]}}
{"type": "orderbook", "local_time": 1761342412274, "event_time": 1761342407214, "latency_ms": 5060, "data": {"e": "depthUpdate", "E": 1761342407214, "s": "BTCUSDT", "U": 79012709465, "u": 79012709492, "b": [["110973.99000000", "0.00242000"], ["110973.98000000", "0.00095000"], ["110966.98000000", "0.00005000"], ["110964.28000000", "0.08690000"], ["110964.07000000", "0.00005000"], ["110964.06000000", "0.21486000"], ["110962.90000000", "0.00726000"], ["110961.68000000", "0.01775000"], ["110960.06000000", "0.07954000"], ["110960.05000000", "0.18023000"], ["110958.77000000", "0.04536000"], ["110956.51000000", "0.00000000"], ["110952.86000000", "0.00000000"], ["110949.74000000", "0.01802000"], ["110935.36000000", "0.83652000"]], "a": [["110974.00000000", "5.54438000"], ["110981.36000000", "0.01802000"], ["110985.32000000", "0.00000000"], ["111028.04000000", "0.00000000"]]}}
{"type": "orderbook", "local_time": 1761342412274, "event_time": 1761342407314, "latency_ms": 4960, "data": {"e": "depthUpdate", "E": 1761342407314, "s": "BTCUSDT", "U": 79012709493, "u": 79012710977, "b": [["110973.99000000", "0.00000000"], ["110973.98000000", "0.00000000"], ["110972.69000000", "0.00000000"], ["110972.68000000", "0.00000000"], ["110972.40000000", "0.00000000"], ["110972.00000000", "0.00000000"], ["110971.73000000", "0.00000000"], ["110971.22000000", "0.00000000"], ["110971.13000000", "0.00000000"], ["110971.12000000", "0.00000000"], ["110971.11000000", "0.00000000"], ["110970.26000000", "0.00000000"], ["110970.06000000", "0.00000000"], ["110970.00000000", "0.00000000"], ["110969.23000000", "0.00000000"], ["110969.10000000", "0.00000000"], ["110968.00000000", "0.00000000"], ["110967.34000000", "0.00000000"], ["110966.98000000", "0.00000000"], ["110966.50000000", "0.00000000"], ["110966.49000000", "0.00000000"], ["110966.43000000", "0.00000000"], ["110966.00000000", "0.00000000"], ["110965.80000000", "0.00000000"], ["110965.75000000", "0.00000000"], ["110965.09000000", "0.00000000"], ["110964.89000000", "0.00000000"], ["110964.56000000", "0.00000000"], ["110964.52000000", "0.00000000"], ["110964.29000000", "0.00000000"], ["110964.28000000", "0.00000000"], ["110964.19000000", "0.00000000"], ["110964.12000000", "0.00000000"], ["110964.07000000", "0.00000000"], ["110964.06000000", "0.00000000"], ["110964.00000000", "0.00000000"], ["110962.90000000", "0.00000000"], ["110962.55000000", "0.00000000"], ["110962.50000000", "0.00000000"], ["110962.00000000", "0.00000000"], ["110961.69000000", "0.00000000"], ["110961.68000000", "0.00000000"], ["110961.46000000", "0.00000000"], ["110961.03000000", "0.00000000"], ["110960.07000000", "0.00000000"], ["110960.06000000", "0.00000000"], ["110960.05000000", "0.00000000"], ["110960.00000000", "0.00000000"], ["110959.20000000", "0.00000000"], ["110959.13000000", "0.00000000"], ["110959.04000000", "0.00000000"], ["110958.85000000", "0.00000000"], ["110958.77000000", "0.00000000"], ["110958.66000000", "0.00000000"], ["110958.08000000", "0.00808000"], ["110958.07000000", "0.00180000"], ["110958.00000000", "0.00000000"], ["110957.35000000", "0.00000000"], ["110957.00000000", "0.00000000"], ["110956.99000000", "0.00000000"], ["110956.85000000", "0.00000000"], ["110956.68000000", "0.00000000"], ["110956.47000000", "0.00000000"], ["110956.00000000", "0.00000000"], ["110955.90000000", "0.00000000"], ["110955.66000000", "0.00010000"], ["110955.65000000", "0.00000000"], ["110955.64000000", "0.00000000"], ["110955.60000000", "0.00000000"], ["110954.87000000", "0.00000000"], ["110954.78000000", "0.00000000"], ["110954.17000000", "0.68980000"], ["110954.16000000", "0.00000000"], ["110953.75000000", "0.00000000"], ["110953.31000000", "0.00010000"], ["110953.30000000", "0.00000000"], ["110953.27000000", "0.00000000"], ["110952.47000000", "0.00000000"], ["110952.46000000", "0.00000000"], ["110952.10000000", "0.00010000"], ["110952.09000000", "0.00000000"], ["110951.41000000", "0.00000000"], ["110951.33000000", "0.00000000"], ["110950.97000000", "0.00000000"], ["110950.74000000", "0.00005000"], ["110950.73000000", "0.00000000"], ["110950.46000000", "0.00000000"], ["110949.74000000", "0.00000000"], ["110949.21000000", "0.00000000"], ["110949.14000000", "0.00000000"], ["110948.94000000", "0.00000000"], ["110948.68000000", "0.00000000"], ["110948.44000000", "0.00000000"], ["110948.26000000", "0.00000000"], ["110948.25000000", "0.00150000"], ["110947.80000000", "0.00000000"], ["110947.29000000", "0.04536000"], ["110947.24000000", "0.00000000"], ["110946.98000000", "0.00150000"], ["110946.90000000", "0.00000000"], ["110946.21000000", "0.00000000"], ["110946.13000000", "0.00000000"], ["110946.09000000", "0.00000000"], ["110946.00000000", "0.00156000"], ["110945.86000000", "0.00000000"], ["110945.68000000", "0.00000000"], ["110945.66000000", "0.00000000"], ["110945.48000000", "0.00000000"], ["110945.14000000", "0.00000000"], ["110944.98000000", "0.00000000"], ["110944.75000000", "0.00000000"], ["110944.39000000", "0.00000000"], ["110944.29000000", "0.00000000"], ["110943.66000000", "0.09211000"], ["110943.38000000", "0.00090000"], ["110943.34000000", "0.00000000"], ["110942.65000000", "0.00000000"], ["110942.29000000", "0.00000000"], ["110942.12000000", "0.00000000"], ["110941.53000000", "0.00000000"], ["110941.44000000", "0.00150000"], ["110940.79000000", "0.00000000"], ["110940.70000000", "0.04506000"], ["110940.53000000", "0.00000000"], ["110940.00000000", "0.01967000"], ["110939.97000000", "0.30409000"], ["110939.96000000", "0.00000000"], ["110939.39000000", "0.00000000"], ["110938.76000000", "0.00000000"], ["110938.74000000", "0.00000000"], ["110938.35000000", "0.00000000"], ["110938.29000000", "0.20282000"], ["110938.27000000", "0.00000000"], ["110937.51000000", "0.00000000"], ["110937.35000000", "0.00258000"], ["110937.15000000", "0.00000000"], ["110936.69000000", "0.14000000"], ["110936.66000000", "0.00000000"], ["110936.47000000", "0.05100000"], ["110936.01000000", "0.00000000"], ["110935.88000000", "0.11267000"], ["110935.36000000", "0.00000000"], ["110935.00000000", "0.00011000"], ["110934.95000000", "0.01916000"], ["110934.94000000", "0.00000000"], ["110934.24000000", "0.00000000"], ["110934.16000000", "0.05400000"], ["110933.67000000", "0.00022000"], ["110933.26000000", "0.00000000"], ["110933.19000000", "0.16000000"], ["110933.11000000", "0.00005000"], ["110932.01000000", "0.00000000"], ["110930.80000000", "0.54039000"], ["110929.11000000", "0.00000000"], ["110928.96000000", "0.00250000"], ["110928.78000000", "0.00000000"], ["110928.14000000", "0.04000000"], ["110927.18000000", "0.20282000"], ["110926.88000000", "0.00000000"], ["110926.67000000", "0.07661000"], ["110926.01000000", "0.12228000"], ["110925.91000000", "0.13519000"], ["110925.83000000", "0.00258000"], ["110925.17000000", "0.00000000"], ["110921.19000000", "0.00090000"], ["110920.91000000", "0.22117000"], ["110920.88000000", "0.00000000"], ["110919.59000000", "0.00000000"], ["110919.02000000", "0.00000000"], ["110918.60000000", "0.00000000"], ["110918.01000000", "0.03697000"], ["110917.75000000", "0.00000000"], ["110917.33000000", "0.07661000"], ["110917.13000000", "0.02432000"], ["110916.23000000", "0.05196000"], ["110916.11000000", "0.02198000"], ["110915.60000000", "0.18027000"], ["110915.20000000", "0.00005000"], ["110914.96000000", "0.00000000"], ["110914.55000000", "0.00000000"], ["110910.94000000", "0.00000000"], ["110910.01000000", "0.00000000"], ["110909.75000000", "0.00000000"], ["110909.72000000", "0.00005000"], ["110909.50000000", "0.00000000"], ["110909.36000000", "0.04088000"], ["110904.24000000", "0.00005000"], ["110902.65000000", "0.32456000"], ["110898.70000000", "0.00000000"], ["110895.41000000", "0.00000000"], ["110894.12000000", "0.00000000"], ["110893.50000000", "0.00000000"], ["110892.23000000", "0.04097000"], ["110888.94000000", "0.00000000"], ["110887.52000000", "0.20282000"], ["110887.51000000", "0.00000000"], ["110887.48000000", "0.00000000"], ["110887.30000000", "0.30864000"], ["110886.86000000", "0.00000000"], ["110886.30000000", "0.00000000"], ["110885.71000000", "0.00000000"], ["110885.39000000", "0.00000000"], ["110882.13000000", "0.20282000"], ["110882.05000000", "0.07661000"], ["110880.26000000", "0.00000000"], ["110880.25000000", "0.28221000"], ["110879.96000000", "0.00000000"], ["110878.87000000", "0.04097000"], ["110878.46000000", "0.00000000"], ["110878.15000000", "0.00000000"], ["110878.00000000", "0.00160000"], ["110877.25000000", "0.07661000"], ["110877.04000000", "0.00540000"], ["110877.03000000", "0.00000000"], ["110877.02000000", "0.00000000"], ["110876.16000000", "0.00000000"], ["110876.01000000", "0.00000000"], ["110875.47000000", "0.20282000"], ["110875.21000000", "0.13511000"], ["110874.01000000", "0.07795000"], ["110873.84000000", "0.01900000"], ["110872.65000000", "0.13519000"], ["110871.04000000", "0.00000000"], ["110871.02000000", "1.44342000"], ["110869.59000000", "0.23552000"], ["110869.02000000", "0.00000000"], ["110866.87000000", "0.07794000"], ["110862.57000000", "0.00000000"], ["110860.43000000", "0.08417000"], ["110860.42000000", "0.00000000"], ["110859.92000000", "1.44342000"], ["110858.01000000", "0.06310000"], ["110857.66000000", "0.02453000"], ["110857.29000000", "0.00109000"], ["110856.30000000", "0.04042000"], ["110856.01000000", "0.04097000"], ["110855.98000000", "0.05100000"], ["110853.86000000", "0.00000000"], ["110853.69000000", "0.05400000"], ["110853.44000000", "0.02536000"], ["110853.42000000", "0.00450000"], ["110850.77000000", "0.00000000"], ["110849.02000000", "0.18027000"], ["110848.01000000", "0.04097000"], ["110847.52000000", "0.00084000"], ["110846.01000000", "0.00000000"], ["110842.00000000", "0.01651000"], ["110840.50000000", "0.36600000"], ["110839.29000000", "0.16724000"], ["110838.01000000", "0.00191000"], ["110836.01000000", "0.04097000"], ["110832.43000000", "0.04612000"], ["110830.01000000", "0.03697000"], ["110828.52000000", "0.00000000"], ["110827.69000000", "0.00084000"], ["110827.39000000", "0.09922000"], ["110824.84000000", "0.00000000"], ["110824.21000000", "0.00000000"], ["110814.01000000", "0.04097000"], ["110809.14000000", "0.00000000"], ["110803.65000000", "0.04097000"], ["110788.59000000", "0.00000000"], ["110786.56000000", "0.01712000"], ["110782.59000000", "0.00000000"], ["110777.82000000", "0.00000000"], ["110777.69000000", "0.00000000"], ["110777.40000000", "0.04097000"], ["110776.22000000", "0.01892000"], ["110775.76000000", "0.00000000"], ["110773.85000000", "0.00000000"], ["110773.74000000", "0.00000000"], ["110767.44000000", "0.00000000"], ["110765.86000000", "0.04097000"], ["110764.01000000", "0.00000000"], ["110763.04000000", "0.01892000"], ["110756.65000000", "0.04097000"], ["110756.39000000", "0.03697000"], ["110751.78000000", "0.00000000"], ["110751.58000000", "0.01892000"], ["110746.77000000", "0.01892000"], ["110745.00000000", "0.04097000"], ["110743.20000000", "0.00090000"], ["110743.19000000", "0.00000000"], ["110743.18000000", "0.00000000"], ["110726.01000000", "0.00076000"], ["110719.12000000", "0.00000000"], ["110718.01000000", "0.00000000"], ["110717.45000000", "1.01150000"], ["110717.31000000", "0.00000000"], ["110715.33000000", "0.00000000"], ["110714.35000000", "0.00000000"], ["110707.11000000", "0.90316000"], ["110704.67000000", "0.00000000"], ["110702.13000000", "0.00000000"], ["110700.87000000", "0.00000000"], ["110696.46000000", "0.00000000"], ["110696.28000000", "0.00000000"], ["110695.41000000", "0.00000000"], ["110694.78000000", "0.00000000"], ["110693.56000000", "0.00000000"], ["110692.88000000", "0.00000000"], ["110691.78000000", "0.00000000"], ["110691.26000000", "0.01712000"], ["110690.58000000", "0.00000000"], ["110690.17000000", "0.01712000"], ["110690.00000000", "0.00100000"], ["110689.60000000", "0.00000000"], ["110689.45000000", "0.00000000"], ["110688.83000000", "0.00000000"], ["110688.27000000", "0.01712000"], ["110686.51000000", "0.00005000"], ["110686.45000000", "0.01712000"], ["110684.93000000", "0.00000000"], ["110684.01000000", "0.00000000"], ["110681.21000000", "0.00000000"], ["110680.95000000", "0.00000000"], ["110680.32000000", "0.00000000"], ["110678.82000000", "0.01712000"], ["110677.55000000", "0.00000000"], ["110674.44000000", "0.02498000"], ["110674.28000000", "0.00000000"], ["110672.06000000", "0.02498000"], ["110671.75000000", "0.02498000"], ["110671.37000000", "0.02498000"], ["110671.35000000", "0.00000000"], ["110670.85000000", "0.02498000"], ["110670.64000000", "0.00000000"], ["110670.37000000", "0.01712000"], ["110670.04000000", "0.02498000"], ["110669.46000000", "0.00000000"], ["110669.14000000", "0.02498000"], ["110668.25000000", "0.02498000"], ["110667.63000000", "0.02498000"], ["110667.54000000", "0.02498000"], ["110665.85000000", "0.00000000"], ["110663.60000000", "0.00000000"], ["110663.23000000", "0.00000000"], ["110661.40000000", "0.00000000"], ["110661.10000000", "0.01712000"], ["110660.29000000", "0.02598000"], ["110659.81000000", "0.01712000"], ["110659.77000000", "0.01712000"], ["110657.87000000", "0.05136000"], ["110657.66000000", "0.00000000"], ["110657.10000000", "0.00000000"], ["110656.92000000", "0.00000000"], ["110656.81000000", "0.00000000"], ["110656.63000000", "0.00000000"], ["110656.22000000", "0.00000000"], ["110655.91000000", "0.00000000"], ["110655.79000000", "0.00000000"], ["110654.95000000", "0.00000000"], ["110654.76000000", "0.00000000"], ["110653.42000000", "0.00000000"], ["110652.22000000", "0.00000000"], ["110652.20000000", "0.00000000"], ["110651.82000000", "0.00000000"], ["110651.73000000", "0.02598000"], ["110649.24000000", "0.01719000"], ["110647.20000000", "0.00000000"], ["110647.07000000", "0.00000000"], ["110647.03000000", "0.00000000"], ["110646.33000000", "0.02598000"], ["110645.21000000", "0.00000000"], ["110644.45000000", "0.01712000"], ["110643.22000000", "0.00000000"], ["110642.30000000", "0.00000000"], ["110638.75000000", "0.00000000"], ["110633.93000000", "0.00000000"], ["110629.79000000", "0.02198000"], ["110629.71000000", "0.00000000"], ["110629.55000000", "0.00000000"], ["110629.00000000", "0.02198000"], ["110628.65000000", "0.02198000"], ["110628.42000000", "0.02198000"], ["110625.69000000", "0.02198000"], ["110624.79000000", "0.03697000"], ["110624.25000000", "0.04097000"], ["110624.04000000", "0.03697000"], ["110623.96000000", "0.02198000"], ["110623.64000000", "0.02198000"], ["110622.70000000", "0.03697000"], ["110622.01000000", "0.03697000"], ["110621.82000000", "0.03697000"], ["110621.26000000", "0.03697000"], ["110620.73000000", "0.02433000"], ["110620.53000000", "0.03697000"], ["110619.32000000", "0.02433000"], ["110618.51000000", "0.01712000"], ["110617.89000000", "0.03697000"], ["110616.11000000", "0.01712000"], ["110615.61000000", "0.03697000"], ["110613.20000000", "0.04097000"], ["110613.14000000", "0.03697000"], ["110613.07000000", "0.04097000"], ["110612.55000000", "0.04097000"], ["110610.57000000", "0.00000000"], ["110610.46000000", "0.04097000"], ["110609.44000000", "0.04097000"], ["110607.97000000", "0.00000000"], ["110607.13000000", "0.04097000"], ["110604.85000000", "0.00000000"], ["110603.73000000", "0.00000000"], ["110602.05000000", "0.00000000"], ["110600.61000000", "0.00000000"], ["110600.31000000", "0.02433000"], ["110590.68000000", "0.02433000"], ["110586.39000000", "0.02433000"], ["110578.78000000", "0.02433000"], ["110572.96000000", "0.02433000"], ["110570.50000000", "0.02433000"], ["110569.03000000", "0.02433000"], ["110567.62000000", "0.02433000"], ["110560.58000000", "0.00000000"], ["110559.76000000", "0.00000000"], ["110558.80000000", "0.00000000"], ["110558.18000000", "0.00000000"], ["110557.58000000", "0.00000000"], ["110557.05000000", "0.00000000"], ["110556.86000000", "0.00000000"], ["110555.59000000", "0.00000000"], ["110555.43000000", "0.00000000"], ["110554.31000000", "0.00000000"], ["110550.40000000", "0.00000000"], ["110548.83000000", "0.00000000"], ["110545.02000000", "0.00000000"], ["110544.56000000", "0.00000000"], ["110544.05000000", "0.00000000"], ["110543.51000000", "0.00000000"], ["110539.79000000", "0.00000000"], ["110539.22000000", "0.00000000"], ["110532.76000000", "0.00000000"], ["110531.87000000", "0.00000000"], ["110531.76000000", "0.00000000"], ["110531.67000000", "0.00000000"], ["110529.89000000", "0.00000000"], ["110529.86000000", "0.00000000"], ["110528.34000000", "0.00000000"], ["110527.03000000", "0.00000000"], ["110525.78000000", "0.00005000"], ["110523.52000000", "0.00000000"], ["110522.41000000", "0.00000000"], ["110522.14000000", "0.00000000"], ["110521.60000000", "0.00000000"], ["110521.55000000", "0.00000000"], ["110521.29000000", "0.00000000"], ["110521.07000000", "0.00000000"], ["110518.08000000", "0.00000000"], ["110517.79000000", "0.02698000"], ["110517.76000000", "0.02698000"], ["110517.33000000", "0.02698000"], ["110517.30000000", "0.02698000"], ["110516.35000000", "0.02698000"], ["110515.81000000", "0.00000000"], ["110514.97000000", "0.00000000"], ["110514.81000000", "0.02698000"], ["110513.51000000", "0.02698000"], ["110512.26000000", "0.02698000"], ["110511.32000000", "0.02698000"], ["110510.96000000", "0.02698000"], ["110510.49000000", "0.02698000"], ["110490.10000000", "0.03697000"], ["110488.65000000", "0.03697000"], ["110487.17000000", "0.03697000"], ["110485.83000000", "0.03697000"], ["110469.85000000", "0.03697000"], ["110468.33000000", "0.03697000"], ["110467.48000000", "0.03697000"], ["110466.63000000", "0.03697000"], ["109309.38000000", "0.00000000"], ["109291.26000000", "0.00100000"], ["99876.00000000", "0.00050000"], ["99875.00000000", "0.06697000"], ["55497.44000000", "0.00000000"], ["55479.57000000", "0.00020000"], ["55479.04000000", "0.00100000"], ["55467.02000000", "0.00000000"], ["55461.47000000", "0.00000000"]], "a": [["110958.09000000", "2.26152000"], ["110958.20000000", "0.04913000"], ["110958.22000000", "0.01795000"], ["110958.78000000", "0.00010000"], ["110958.86000000", "0.14595000"], ["110959.04000000", "0.00005000"], ["110959.05000000", "0.00000000"], ["110959.14000000", "0.00000000"], ["110959.20000000", "0.00000000"], ["110959.21000000", "0.00000000"], ["110959.28000000", "0.00000000"], ["110959.30000000", "0.00000000"], ["110959.35000000", "0.00000000"], ["110960.00000000", "0.00015000"], ["110960.01000000", "0.00010000"], ["110960.06000000", "0.00015000"], ["110960.07000000", "0.00000000"], ["110960.09000000", "0.00000000"], ["110961.18000000", "0.04000000"], ["110961.69000000", "0.00000000"], ["110962.16000000", "0.04548000"], ["110962.91000000", "0.00000000"], ["110964.07000000", "0.00000000"], ["110964.29000000", "0.00000000"], ["110964.48000000", "0.00250000"], ["110964.52000000", "0.00005000"], ["110964.89000000", "1.51799000"], ["110964.90000000", "0.20292000"], ["110964.95000000", "0.00000000"], ["110965.10000000", "0.00010000"], ["110965.38000000", "0.00000000"], ["110965.58000000", "0.00000000"], ["110965.70000000", "0.00759000"], ["110966.40000000", "0.00000000"], ["110966.49000000", "0.26991000"], ["110966.50000000", "0.00010000"], ["110966.70000000", "0.00000000"], ["110966.99000000", "0.00000000"], ["110967.35000000", "0.00000000"], ["110968.01000000", "0.00000000"], ["110968.92000000", "0.00250000"], ["110969.11000000", "0.00000000"], ["110969.24000000", "0.00000000"], ["110970.00000000", "0.00005000"], ["110970.01000000", "0.00000000"], ["110970.06000000", "0.00000000"], ["110970.07000000", "0.00000000"], ["110970.27000000", "1.44342000"], ["110971.12000000", "0.96609000"], ["110971.13000000", "0.30010000"], ["110971.14000000", "0.00000000"], ["110971.19000000", "0.00000000"], ["110971.23000000", "0.00000000"], ["110971.74000000", "0.00000000"], ["110971.76000000", "0.00007000"], ["110972.01000000", "0.00000000"], ["110972.41000000", "0.00000000"], ["110972.51000000", "0.09516000"], ["110972.68000000", "2.55869000"], ["110972.69000000", "0.45023000"], ["110972.75000000", "0.00000000"], ["110972.84000000", "0.00044000"], ["110973.34000000", "0.00000000"], ["110973.36000000", "0.00250000"], ["110973.55000000", "0.00072000"], ["110973.99000000", "0.00000000"], ["110974.00000000", "1.20449000"], ["110974.01000000", "0.00005000"], ["110974.69000000", "0.00090000"], ["110974.73000000", "0.00150000"], ["110975.10000000", "0.00099000"], ["110975.14000000", "0.07661000"], ["110975.50000000", "0.00005000"], ["110975.51000000", "0.00042000"], ["110978.69000000", "1.44342000"], ["110978.70000000", "0.21289000"], ["110978.71000000", "0.20282000"], ["110978.72000000", "0.00007000"], ["110978.81000000", "0.01036000"], ["110979.18000000", "0.01802000"], ["110979.55000000", "0.00000000"], ["110979.57000000", "0.07664000"], ["110980.13000000", "0.00000000"], ["110980.65000000", "0.00541000"], ["110981.30000000", "0.00045000"], ["110981.36000000", "0.00000000"], ["110981.37000000", "0.00044000"], ["110981.54000000", "0.00090000"], ["110981.75000000", "0.13511000"], ["110982.74000000", "0.00000000"], ["110982.82000000", "0.00007000"], ["110983.42000000", "0.00000000"], ["110983.84000000", "0.00000000"], ["110984.57000000", "0.00007000"], ["110985.11000000", "0.00000000"], ["110986.68000000", "0.00000000"], ["110987.46000000", "0.00000000"], ["110987.77000000", "0.00000000"], ["110989.03000000", "0.00000000"], ["110989.46000000", "0.00119000"], ["110989.82000000", "0.00000000"], ["110990.03000000", "0.00000000"], ["110990.26000000", "0.00000000"], ["110990.41000000", "0.00000000"], ["110990.48000000", "0.00000000"], ["110991.12000000", "0.00000000"], ["110993.15000000", "0.00000000"], ["110993.59000000", "0.36550000"], ["110995.36000000", "0.00000000"], ["110995.56000000", "0.00000000"], ["110997.46000000", "0.24618000"], ["110998.48000000", "0.00382000"], ["110998.74000000", "0.00016000"], ["110999.26000000", "0.20282000"], ["110999.76000000", "0.01916000"], ["110999.97000000", "0.01749000"], ["111001.21000000", "0.00000000"], ["111001.64000000", "0.32427000"], ["111002.38000000", "0.00000000"], ["111003.73000000", "0.00090000"], ["111004.00000000", "0.00000000"], ["111004.52000000", "0.29900000"], ["111006.89000000", "0.07661000"], ["111007.29000000", "0.04507000"], ["111008.76000000", "0.06647000"], ["111009.78000000", "0.07661000"], ["111010.35000000", "0.00016000"], ["111013.10000000", "0.00000000"], ["111013.84000000", "0.00000000"], ["111013.87000000", "0.00000000"], ["111013.96000000", "0.00000000"], ["111014.35000000", "0.00000000"], ["111015.69000000", "0.00000000"], ["111015.95000000", "0.00000000"], ["111017.17000000", "0.00000000"], ["111019.32000000", "0.00000000"], ["111019.45000000", "0.00000000"], ["111020.59000000", "0.00000000"], ["111023.33000000", "0.00000000"], ["111024.80000000", "0.00000000"], ["111026.21000000", "0.00000000"], ["111027.23000000", "0.00048000"], ["111027.42000000", "0.00000000"], ["111028.30000000", "0.00000000"], ["111030.47000000", "0.13524000"], ["111030.53000000", "0.13519000"], ["111033.05000000", "0.13511000"], ["111033.36000000", "0.00045000"], ["111033.99000000", "0.00225000"], ["111034.49000000", "0.00045000"], ["111034.75000000", "0.00045000"], ["111037.81000000", "0.00000000"], ["111038.80000000", "0.00000000"], ["111039.46000000", "0.00000000"], ["111039.63000000", "0.00000000"], ["111039.99000000", "0.00000000"], ["111040.00000000", "0.01966000"], ["111041.48000000", "0.00000000"], ["111044.90000000", "0.00000000"], ["111045.92000000", "0.00000000"], ["111048.03000000", "0.00000000"], ["111049.63000000", "0.00085000"], ["111051.78000000", "0.00000000"], ["111052.47000000", "0.22535000"], ["111053.17000000", "0.22544000"], ["111054.73000000", "0.18038000"], ["111057.70000000", "1.49431000"], ["111057.79000000", "0.13511000"], ["111065.41000000", "0.00017000"], ["111065.97000000", "0.00085000"], ["111066.96000000", "0.00000000"], ["111066.99000000", "0.00000000"], ["111068.10000000", "0.00005000"], ["111068.35000000", "0.00000000"], ["111083.00000000", "0.00000000"], ["111083.40000000", "0.09817000"], ["111086.88000000", "0.00000000"], ["111091.14000000", "0.04097000"], ["111093.18000000", "0.00092000"], ["111094.66000000", "0.00000000"], ["111101.03000000", "0.08971000"], ["111104.24000000", "0.00000000"], ["111109.14000000", "0.00000000"], ["111117.60000000", "0.00000000"], ["111122.47000000", "0.00000000"], ["111128.86000000", "0.00000000"], ["111132.00000000", "0.00022000"], ["111139.97000000", "0.00000000"], ["111238.52000000", "0.00000000"], ["111358.85000000", "0.00000000"], ["111457.28000000", "0.03697000"], ["111462.00000000", "0.03697000"], ["111566.02000000", "0.00000000"], ["111568.30000000", "0.00000000"], ["112638.61000000", "0.00000000"]]}}
{"type": "orderbook", "local_time": 1761342412637, "event_time": 1761342407414, "latency_ms": 5223, "data": {"e": "depthUpdate", "E": 1761342407414, "s": "BTCUSDT", "U": 79012710978, "u": 79012711996, "b": [["110958.08000000", "0.00000000"], ["110958.07000000", "0.00000000"], ["110955.66000000", "0.00000000"], ["110955.34000000", "0.00000000"], ["110955.24000000", "0.00000000"], ["110954.79000000", "0.00000000"], ["110954.40000000", "0.00000000"], ["110954.18000000", "0.00000000"], ["110954.17000000", "0.00225000"], ["110954.16000000", "0.00085000"], ["110954.00000000", "0.00160000"], ["110953.31000000", "0.00000000"], ["110952.10000000", "0.00000000"], ["110952.00000000", "0.00160000"], ["110951.26000000", "0.00310000"], ["110951.16000000", "0.00005000"], ["110950.74000000", "0.00000000"], ["110950.40000000", "0.00010000"], ["110950.39000000", "0.00000000"], ["110950.19000000", "0.00000000"], ["110950.16000000", "0.01765000"], ["110950.01000000", "0.00010000"], ["110950.00000000", "0.02150000"], ["110949.22000000", "0.00000000"], ["110949.21000000", "0.00010000"], ["110949.20000000", "0.03344000"], ["110948.95000000", "0.00000000"], ["110948.94000000", "0.00010000"], ["110948.93000000", "0.04515000"], ["110948.77000000", "0.29739000"], ["110947.82000000", "0.20756000"], ["110947.81000000", "0.00720000"], ["110947.30000000", "0.00005000"], ["110947.29000000", "0.00010000"], ["110946.98000000", "0.00000000"], ["110945.23000000", "0.00005000"], ["110944.00000000", "0.00140000"], ["110943.70000000", "0.00000000"], ["110943.69000000", "0.03910000"], ["110943.67000000", "0.00005000"], ["110943.66000000", "0.09216000"], ["110943.38000000", "0.00000000"], ["110942.71000000", "0.04536000"], ["110942.64000000", "0.05705000"], ["110942.60000000", "0.05110000"], ["110941.14000000", "0.00000000"], ["110941.12000000", "0.00000000"], ["110940.24000000", "0.18021000"], ["110940.23000000", "0.00000000"], ["110939.97000000", "0.00000000"], ["110938.29000000", "0.00000000"], ["110938.12000000", "0.00000000"], ["110937.54000000", "0.00150000"], ["110937.11000000", "0.03900000"], ["110936.70000000", "0.00000000"], ["110936.69000000", "0.00000000"], ["110936.42000000", "0.01802000"], ["110935.17000000", "0.00000000"], ["110934.17000000", "0.00450000"], ["110934.09000000", "0.04572000"], ["110933.96000000", "0.00000000"], ["110933.29000000", "0.02000000"], ["110933.19000000", "0.00000000"], ["110931.99000000", "0.00000000"], ["110931.50000000", "0.06100000"], ["110931.35000000", "0.30410000"], ["110931.09000000", "0.00000000"], ["110929.99000000", "0.04000000"], ["110929.89000000", "0.00901000"], ["110929.47000000", "0.00039000"], ["110929.43000000", "0.00000000"], ["110928.98000000", "0.07696000"], ["110928.69000000", "0.24000000"], ["110927.28000000", "0.00000000"], ["110927.19000000", "0.27181000"], ["110926.25000000", "0.00000000"], ["110926.01000000", "0.00000000"], ["110925.65000000", "0.00000000"], ["110925.25000000", "0.00000000"], ["110925.11000000", "0.00038000"], ["110924.78000000", "0.00036000"], ["110924.52000000", "0.00250000"], ["110922.69000000", "0.00000000"], ["110922.18000000", "0.85500000"], ["110921.15000000", "0.00000000"], ["110919.66000000", "0.00272000"], ["110919.32000000", "0.01712000"], ["110919.19000000", "0.00073000"], ["110916.11000000", "0.72192000"], ["110915.44000000", "0.00000000"], ["110914.78000000", "0.09000000"], ["110914.29000000", "0.00444000"], ["110910.60000000", "0.00000000"], ["110909.29000000", "0.01712000"], ["110908.59000000", "0.01712000"], ["110907.97000000", "0.00000000"], ["110906.85000000", "0.00000000"], ["110905.22000000", "0.34591000"], ["110904.53000000", "0.00000000"], ["110902.35000000", "0.00000000"], ["110900.22000000", "0.00000000"], ["110898.76000000", "0.00005000"], ["110898.01000000", "0.00000000"], ["110897.68000000", "0.07583000"], ["110896.87000000", "0.02663000"], ["110896.50000000", "0.00005000"], ["110896.31000000", "0.00000000"], ["110896.04000000", "0.00000000"], ["110892.41000000", "0.11192000"], ["110892.01000000", "0.00000000"], ["110890.26000000", "0.00000000"], ["110888.70000000", "0.00000000"], ["110886.95000000", "0.00000000"], ["110885.50000000", "0.00005000"], ["110882.76000000", "0.06748000"], ["110878.42000000", "0.00000000"], ["110873.61000000", "0.00000000"], ["110872.18000000", "0.00000000"], ["110871.64000000", "0.00064000"], ["110870.87000000", "0.00000000"], ["110869.40000000", "0.02613000"], ["110868.87000000", "0.00000000"], ["110868.01000000", "0.04097000"], ["110866.01000000", "0.00000000"], ["110865.00000000", "0.02613000"], ["110862.93000000", "0.05625000"], ["110861.29000000", "0.00057000"], ["110860.43000000", "0.12291000"], ["110860.01000000", "0.00000000"], ["110858.01000000", "0.08923000"], ["110856.32000000", "0.03218000"], ["110852.01000000", "0.05226000"], ["110850.79000000", "0.00225000"], ["110847.01000000", "0.02613000"], ["110844.01000000", "0.02613000"], ["110839.29000000", "0.07839000"], ["110838.01000000", "0.00000000"], ["110836.01000000", "0.06710000"], ["110832.43000000", "0.07225000"], ["110828.51000000", "0.02613000"], ["110827.40000000", "0.00252000"], ["110824.01000000", "0.02613000"], ["110810.01000000", "0.00000000"], ["110769.01000000", "0.00000000"], ["110700.65000000", "0.00000000"], ["110675.47000000", "0.00000000"], ["110670.85000000", "0.00000000"], ["110669.14000000", "0.00000000"], ["110656.70000000", "0.00000000"], ["110656.25000000", "0.00000000"], ["110655.99000000", "0.00000000"], ["110653.27000000", "0.02498000"], ["110652.48000000", "0.02498000"], ["110652.08000000", "0.02498000"], ["110649.98000000", "0.00000000"], ["110649.05000000", "0.00000000"], ["110647.84000000", "0.00000000"], ["110646.94000000", "0.00000000"], ["110630.18000000", "0.00000000"], ["110623.99000000", "0.00000000"], ["110622.20000000", "0.02433000"], ["110621.82000000", "0.00000000"], ["110621.74000000", "0.00000000"], ["110621.48000000", "0.02433000"], ["110621.26000000", "0.00000000"], ["110620.86000000", "0.02433000"], ["110620.53000000", "0.00000000"], ["110620.23000000", "0.02433000"], ["110620.11000000", "0.02433000"], ["110618.97000000", "0.02433000"], ["110617.04000000", "0.02433000"], ["110607.74000000", "0.04098000"], ["110602.35000000", "0.03698000"], ["110601.59000000", "0.03698000"], ["110601.47000000", "0.03698000"], ["110601.22000000", "0.03698000"], ["110600.68000000", "0.03698000"], ["110597.61000000", "0.00000000"], ["110591.96000000", "0.00000000"], ["110587.96000000", "0.00000000"], ["110561.62000000", "0.02433000"], ["110558.56000000", "0.02433000"], ["110556.86000000", "0.02433000"], ["110517.30000000", "0.00000000"], ["110514.81000000", "0.00000000"], ["110510.49000000", "0.00000000"], ["110496.05000000", "0.02698000"], ["110495.52000000", "0.06396000"], ["110495.09000000", "0.02698000"], ["110481.09000000", "0.03697000"], ["110478.98000000", "0.03697000"], ["110477.70000000", "0.03697000"], ["110476.29000000", "0.03697000"], ["110473.80000000", "0.03697000"], ["110471.72000000", "0.03697000"], ["110407.98000000", "0.00000000"], ["110343.94000000", "1.17963000"], ["109291.26000000", "0.00000000"]], "a": [["110954.18000000", "3.80789000"], ["110954.19000000", "1.60094000"], ["110954.70000000", "0.00000000"], ["110954.79000000", "0.00000000"], ["110954.80000000", "0.00000000"], ["110955.24000000", "0.00010000"], ["110955.25000000", "0.00020000"], ["110955.28000000", "0.00000000"], ["110955.29000000", "0.00000000"], ["110955.30000000", "0.00000000"], ["110955.35000000", "0.00000000"], ["110955.76000000", "0.00000000"], ["110956.11000000", "0.04572000"], ["110957.96000000", "0.04548000"], ["110958.08000000", "0.00005000"], ["110958.09000000", "0.50574000"], ["110958.19000000", "0.29737000"], ["110958.20000000", "0.04923000"], ["110958.21000000", "0.00000000"], ["110958.22000000", "0.01800000"], ["110958.29000000", "0.00720000"], ["110958.30000000", "0.20756000"], ["110958.78000000", "0.00000000"], ["110958.85000000", "0.00000000"], ["110958.86000000", "0.00005000"], ["110959.25000000", "0.00000000"], ["110959.27000000", "0.00000000"], ["110959.29000000", "0.00000000"], ["110959.31000000", "0.00000000"], ["110960.00000000", "0.00005000"], ["110960.01000000", "0.00000000"], ["110960.04000000", "0.00250000"], ["110960.06000000", "0.00000000"], ["110960.59000000", "0.00000000"], ["110961.17000000", "0.00000000"], ["110961.18000000", "0.04005000"], ["110962.15000000", "0.00000000"], ["110962.16000000", "0.00005000"], ["110964.89000000", "0.08294000"], ["110964.90000000", "0.20282000"], ["110965.10000000", "0.00000000"], ["110965.20000000", "0.00000000"], ["110965.29000000", "0.00091000"], ["110965.62000000", "0.00000000"], ["110965.64000000", "0.00000000"], ["110965.70000000", "0.00246000"], ["110966.49000000", "0.26991000"], ["110966.50000000", "0.00000000"], ["110966.64000000", "0.00000000"], ["110967.67000000", "0.00000000"], ["110968.03000000", "0.01802000"], ["110968.72000000", "0.00000000"], ["110968.91000000", "0.00450000"], ["110970.26000000", "0.63370000"], ["110971.12000000", "0.00000000"], ["110971.13000000", "0.30000000"], ["110972.29000000", "0.00000000"], ["110972.68000000", "0.19954000"], ["110972.69000000", "0.26991000"], ["110974.00000000", "0.47328000"], ["110974.01000000", "0.00000000"], ["110974.02000000", "0.00000000"], ["110974.73000000", "0.00000000"], ["110975.50000000", "0.00000000"], ["110975.51000000", "0.00027000"], ["110977.93000000", "0.07656000"], ["110978.68000000", "0.56742000"], ["110978.70000000", "0.00000000"], ["110979.18000000", "0.00000000"], ["110981.30000000", "0.00000000"], ["110981.37000000", "0.00000000"], ["110982.23000000", "0.00000000"], ["110982.24000000", "0.00000000"], ["110986.37000000", "0.00012000"], ["110989.02000000", "0.00270000"], ["110994.36000000", "0.44234000"], ["110997.08000000", "0.07664000"], ["110997.19000000", "0.00000000"], ["110998.04000000", "0.00000000"], ["111001.82000000", "0.04008000"], ["111003.02000000", "0.00000000"], ["111006.91000000", "0.00000000"], ["111007.15000000", "0.00000000"], ["111007.71000000", "0.00000000"], ["111008.82000000", "0.00000000"], ["111009.77000000", "0.00224000"], ["111017.61000000", "0.17650000"], ["111019.12000000", "0.13519000"], ["111019.48000000", "0.03706000"], ["111021.52000000", "0.00615000"], ["111022.32000000", "0.02572000"], ["111022.45000000", "0.00620000"], ["111022.60000000", "0.00000000"], ["111024.07000000", "0.13511000"], ["111027.44000000", "0.00648000"], ["111027.85000000", "0.03326000"], ["111029.69000000", "0.00000000"], ["111030.38000000", "0.00000000"], ["111030.47000000", "0.00000000"], ["111030.51000000", "0.00000000"], ["111030.53000000", "0.00000000"], ["111033.05000000", "0.00000000"], ["111033.99000000", "0.00000000"], ["111034.65000000", "0.00000000"], ["111035.51000000", "0.00000000"], ["111040.02000000", "0.00000000"], ["111040.19000000", "0.00000000"], ["111042.32000000", "0.00000000"], ["111042.54000000", "0.00000000"], ["111044.42000000", "0.00000000"], ["111045.47000000", "0.03998000"], ["111046.47000000", "0.00000000"], ["111049.02000000", "0.00000000"], ["111049.91000000", "0.01900000"], ["111050.88000000", "0.21611000"], ["111052.47000000", "0.00000000"], ["111053.17000000", "0.00000000"], ["111054.73000000", "0.00011000"], ["111057.79000000", "0.00000000"], ["111058.88000000", "0.00900000"], ["111067.38000000", "0.00000000"], ["111068.37000000", "0.00000000"], ["111068.83000000", "0.00000000"], ["111074.21000000", "1.39206000"], ["111080.00000000", "0.00349000"], ["111087.42000000", "0.04097000"], ["111090.81000000", "0.06816000"], ["111100.00000000", "13.26672000"], ["111120.00000000", "0.00440000"], ["111124.62000000", "0.00000000"], ["111133.58000000", "0.00000000"], ["111140.00000000", "0.00156000"], ["111201.36000000", "0.00000000"], ["111253.89000000", "0.02433000"], ["111291.10000000", "0.02433000"], ["111374.16000000", "0.00000000"], ["111388.72000000", "0.00000000"], ["111462.92000000", "0.03698000"], ["111561.35000000", "0.00000000"]]}}
{"type": "orderbook", "local_time": 1761342412639, "event_time": 1761342407514, "latency_ms": 5125, "data": {"e": "depthUpdate", "E": 1761342407514, "s": "BTCUSDT", "U": 79012711997, "u": 79012712195, "b": [["110954.17000000", "0.09651000"], ["110954.16000000", "0.00110000"], ["110952.00000000", "0.00150000"], ["110951.26000000", "0.00305000"], ["110951.16000000", "0.00000000"], ["110950.40000000", "0.00000000"], ["110950.32000000", "0.00000000"], ["110950.17000000", "0.00010000"], ["110950.16000000", "0.01770000"], ["110949.20000000", "0.16550000"], ["110948.93000000", "0.04510000"], ["110948.78000000", "0.00005000"], ["110948.77000000", "0.29744000"], ["110947.82000000", "0.20761000"], ["110947.81000000", "0.00725000"], ["110947.30000000", "0.00000000"], ["110947.29000000", "0.00000000"], ["110945.23000000", "0.00000000"], ["110943.69000000", "0.03905000"], ["110943.66000000", "0.09216000"], ["110942.71000000", "0.04536000"], ["110942.64000000", "0.05700000"], ["110942.60000000", "0.05105000"], ["110941.13000000", "0.50453000"], ["110936.42000000", "0.00000000"], ["110935.70000000", "0.01802000"], ["110931.87000000", "0.05100000"], ["110927.19000000", "0.20206000"], ["110925.92000000", "0.00009000"], ["110925.31000000", "0.13524000"], ["110925.26000000", "0.00000000"], ["110923.78000000", "0.00009000"], ["110922.75000000", "0.00009000"], ["110922.62000000", "0.00000000"], ["110919.32000000", "0.00000000"], ["110917.65000000", "0.00009000"], ["110917.13000000", "0.00000000"], ["110915.60000000", "0.18064000"], ["110915.06000000", "0.00038000"], ["110914.59000000", "0.36576000"], ["110913.49000000", "0.00012000"], ["110912.01000000", "0.02433000"], ["110911.53000000", "0.01712000"], ["110911.28000000", "0.00009000"], ["110908.00000000", "0.00160000"], ["110907.26000000", "0.01712000"], ["110906.01000000", "0.02433000"], ["110904.45000000", "0.00000000"], ["110899.49000000", "0.32457000"], ["110894.07000000", "0.01352000"], ["110888.88000000", "0.00000000"], ["110888.52000000", "0.01352000"], ["110884.01000000", "0.05989000"], ["110873.28000000", "0.00627000"], ["110873.27000000", "0.00661000"], ["110871.68000000", "0.13524000"], ["110870.12000000", "0.00090000"], ["110854.90000000", "0.05100000"], ["110807.54000000", "0.08912000"], ["110806.01000000", "0.00222000"], ["110696.91000000", "0.00090000"]], "a": [["110954.18000000", "3.77332000"], ["110954.19000000", "0.35217000"], ["110955.24000000", "0.00000000"], ["110955.25000000", "0.00000000"], ["110955.31000000", "0.00000000"], ["110955.32000000", "0.00000000"], ["110955.33000000", "0.00000000"], ["110955.34000000", "0.00000000"], ["110955.37000000", "0.00000000"], ["110955.39000000", "0.00000000"], ["110955.43000000", "0.00000000"], ["110956.11000000", "0.04587000"], ["110957.89000000", "0.06748000"], ["110957.96000000", "0.04558000"], ["110958.08000000", "0.00010000"], ["110958.09000000", "0.45256000"], ["110958.18000000", "0.00010000"], ["110958.19000000", "0.29742000"], ["110958.20000000", "0.04918000"], ["110958.22000000", "0.01800000"], ["110958.29000000", "0.00735000"], ["110958.30000000", "0.20761000"], ["110958.86000000", "0.00000000"], ["110961.18000000", "0.04000000"], ["110962.16000000", "0.00000000"], ["110964.88000000", "0.27041000"], ["110964.89000000", "0.08289000"], ["110970.65000000", "0.00044000"], ["110972.50000000", "0.05436000"], ["110972.68000000", "0.00000000"], ["110974.00000000", "0.46998000"], ["110978.39000000", "0.03000000"], ["110985.24000000", "0.00445000"], ["110988.38000000", "0.03000000"], ["110989.33000000", "0.00000000"], ["110994.13000000", "0.00000000"], ["110994.66000000", "0.32429000"], ["111001.82000000", "0.00000000"], ["111004.02000000", "0.00000000"], ["111006.67000000", "0.02172000"], ["111014.91000000", "0.04008000"], ["111021.74000000", "0.00000000"], ["111045.27000000", "0.22544000"], ["111046.45000000", "0.00111000"], ["111047.02000000", "0.02420000"], ["111050.88000000", "0.03516000"], ["111054.59000000", "0.90034000"], ["111067.78000000", "0.36525000"], ["111075.64000000", "0.07853000"], ["111114.51000000", "0.00000000"], ["111237.32000000", "0.00000000"]]}}
{"type": "orderbook", "local_time": 1761342412640, "event_time": 1761342407614, "latency_ms": 5026, "data": {"e": "depthUpdate", "E": 1761342407614, "s": "BTCUSDT", "U": 79012712196, "u": 79012712264, "b": [["110954.17000000", "0.27859000"], ["110943.67000000", "0.00000000"], ["110938.29000000", "0.20282000"], ["110935.70000000", "0.00000000"], ["110935.41000000", "0.01802000"], ["110925.91000000", "0.14095000"], ["110916.33000000", "0.00000000"], ["110910.48000000", "0.83076000"], ["110910.44000000", "0.00000000"], ["110904.43000000", "0.13511000"], ["110855.98000000", "0.00000000"], ["110850.00000000", "0.02249000"], ["110803.27000000", "0.00000000"], ["110797.13000000", "0.02350000"], ["110764.86000000", "0.15998000"]], "a": [["110956.10000000", "0.00020000"], ["110956.11000000", "0.04587000"], ["110957.88000000", "0.00010000"], ["110957.89000000", "0.06758000"], ["110957.95000000", "0.00010000"], ["110957.96000000", "0.04553000"], ["110958.09000000", "0.18226000"], ["110958.18000000", "0.00000000"], ["110958.20000000", "0.00005000"], ["110958.22000000", "0.00005000"], ["110958.29000000", "0.00725000"], ["110958.30000000", "0.20756000"], ["110962.40000000", "0.01840000"], ["110964.87000000", "0.16229000"], ["110964.89000000", "0.00000000"], ["110970.58000000", "0.00044000"], ["110972.07000000", "0.13519000"], ["110972.84000000", "0.00000000"], ["110978.30000000", "0.03000000"], ["110978.39000000", "0.06000000"], ["110979.00000000", "0.00005000"], ["110980.21000000", "0.00005000"], ["110980.48000000", "0.03000000"], ["110982.71000000", "0.18027000"], ["110994.93000000", "0.01351000"], ["110996.85000000", "0.13511000"], ["110998.85000000", "0.00000000"], ["111000.48000000", "0.01351000"], ["111003.69000000", "0.00000000"], ["111003.78000000", "0.00000000"], ["111015.94000000", "0.00000000"], ["111017.78000000", "0.04414000"], ["111021.49000000", "0.00000000"], ["111029.63000000", "0.00000000"], ["111045.70000000", "0.22535000"], ["111049.11000000", "0.18027000"], ["111050.88000000", "0.29941000"], ["111067.77000000", "0.17949000"], ["111068.08000000", "0.00000000"], ["111248.53000000", "0.02198000"]]}}
{"type": "orderbook", "local_time": 1761342412641, "event_time": 1761342407714, "latency_ms": 4927, "data": {"e": "depthUpdate", "E": 1761342407714, "s": "BTCUSDT", "U": 79012712265, "u": 79012712287, "b": [["110935.24000000", "0.03600000"], ["110903.91000000", "0.06921000"], ["110866.18000000", "0.13298000"], ["110852.11000000", "0.22544000"], ["110842.84000000", "0.03600000"]], "a": [["110954.18000000", "3.82412000"], ["110954.19000000", "0.25587000"], ["110958.19000000", "0.29742000"], ["110958.20000000", "0.00000000"], ["110958.22000000", "0.00000000"], ["110958.30000000", "0.20761000"], ["110960.35000000", "0.11267000"], ["110961.18000000", "0.04005000"], ["110970.25000000", "0.75021000"], ["110970.26000000", "0.20282000"], ["110970.58000000", "0.00000000"], ["110972.50000000", "0.26814000"], ["110973.81000000", "0.03000000"], ["110976.03000000", "0.03000000"], ["111023.96000000", "0.13524000"], ["111051.27000000", "0.13511000"]]}}
{"type": "orderbook", "local_time": 1761342412641, "event_time": 1761342407814, "latency_ms": 4827, "data": {"e": "depthUpdate", "E": 1761342407814, "s": "BTCUSDT", "U": 79012712288, "u": 79012712313, "b": [["110954.17000000", "0.27859000"], ["110950.91000000", "0.68730000"], ["110938.55000000", "0.01802000"], ["110935.41000000", "0.00000000"], ["110853.69000000", "0.00000000"], ["99875.00000000", "0.06687000"], ["99858.00000000", "0.02245000"]], "a": [["110954.18000000", "3.54597000"], ["110958.30000000", "0.20761000"], ["110960.35000000", "0.11272000"], ["110961.18000000", "0.04000000"], ["110968.03000000", "0.00000000"], ["110970.16000000", "0.01802000"], ["110981.20000000", "0.22535000"], ["110995.15000000", "0.00000000"], ["110998.75000000", "0.00000000"], ["111026.19000000", "0.00000000"], ["111299.72000000", "0.03698000"], ["111314.24000000", "0.48717000"], ["111420.48000000", "0.00000000"]]}}
{"type": "orderbook", "local_time": 1761342412642, "event_time": 1761342407914, "latency_ms": 4728, "data": {"e": "depthUpdate", "E": 1761342407914, "s": "BTCUSDT", "U": 79012712314, "u": 79012712345, "b": [["110954.17000000", "0.27864000"], ["110954.16000000", "0.00115000"], ["110951.26000000", "0.00305000"], ["110950.92000000", "0.21185000"], ["110950.91000000", "0.68735000"], ["110950.17000000", "0.00000000"], ["110950.01000000", "0.00000000"], ["110948.78000000", "0.00010000"], ["110947.83000000", "0.00005000"], ["110943.66000000", "0.09211000"], ["110940.24000000", "0.00000000"], ["110937.36000000", "0.03600000"], ["110934.03000000", "0.03600000"], ["110860.32000000", "0.03600000"], ["110854.20000000", "0.03600000"], ["110846.10000000", "0.00005000"], ["110838.34000000", "0.00005000"], ["103318.00000000", "0.00026000"], ["99858.00000000", "0.02245000"]], "a": [["110971.12000000", "0.04505000"], ["110973.89000000", "0.03000000"], ["110977.22000000", "0.03000000"], ["111068.70000000", "0.00000000"], ["111068.92000000", "0.01711000"]]}}
{"type": "orderbook", "local_time": 1761342412642, "event_time": 1761342408015, "latency_ms": 4627, "data": {"e": "depthUpdate", "E": 1761342408015, "s": "BTCUSDT", "U": 79012712346, "u": 79012712375, "b": [["110954.17000000", "0.27859000"], ["110954.16000000", "0.00120000"], ["110951.26000000", "0.00305000"], ["110950.93000000", "0.00010000"], ["110950.92000000", "0.21190000"], ["110949.80000000", "0.00720000"], ["110949.20000000", "0.16545000"], ["110948.94000000", "0.00000000"], ["110947.81000000", "0.00005000"], ["110943.69000000", "0.03900000"], ["110938.76000000", "0.30409000"], ["110931.35000000", "0.00000000"], ["110930.76000000", "0.03900000"], ["110915.86000000", "0.00000000"], ["110909.28000000", "0.00000000"], ["110853.75000000", "0.03900000"], ["109289.85000000", "0.00100000"]], "a": [["110958.29000000", "0.00005000"], ["110958.30000000", "0.00005000"], ["110980.47000000", "0.03000000"], ["110996.35000000", "0.00000000"], ["111072.50000000", "0.00000000"]]}}
{"type": "orderbook", "local_time": 1761342412643, "event_time": 1761342408115, "latency_ms": 4528, "data": {"e": "depthUpdate", "E": 1761342408115, "s": "BTCUSDT", "U": 79012712376, "u": 79012712436, "b": [["110954.17000000", "0.27859000"], ["110954.16000000", "0.00120000"], ["110950.91000000", "0.00005000"], ["110950.00000000", "0.02150000"], ["110949.80000000", "0.00725000"], ["110947.82000000", "0.20761000"], ["110947.81000000", "0.00000000"], ["110945.66000000", "0.02705000"], ["110942.21000000", "0.00000000"], ["110931.97000000", "0.00300000"], ["110920.88000000", "0.00309000"], ["110908.91000000", "0.00000000"], ["110901.13000000", "0.17668000"], ["110887.60000000", "0.00009000"], ["110875.62000000", "0.00000000"], ["110854.31000000", "0.00009000"], ["110854.20000000", "0.00000000"], ["110842.84000000", "0.00000000"], ["110842.33000000", "0.00000000"], ["110821.02000000", "0.00009000"], ["110809.04000000", "0.00000000"], ["110787.74000000", "0.00009000"], ["108180.33000000", "0.00092000"], ["105739.33000000", "0.00094000"], ["99858.00000000", "0.02255000"]], "a": [["110957.91000000", "0.05041000"], ["110958.19000000", "0.29742000"], ["110958.29000000", "0.00000000"], ["110958.30000000", "0.00000000"], ["110960.46000000", "0.00720000"], ["110960.47000000", "0.20756000"], ["110961.18000000", "0.04005000"], ["110962.40000000", "0.01845000"], ["110965.28000000", "0.00300000"], ["110972.40000000", "0.00005000"], ["110976.92000000", "0.02705000"], ["110987.47000000", "0.00309000"], ["111006.77000000", "0.00000000"], ["111007.30000000", "0.00000000"], ["111008.80000000", "0.00000000"], ["111020.75000000", "0.00009000"], ["111042.10000000", "0.00000000"], ["111054.04000000", "0.00009000"], ["111075.39000000", "0.00000000"], ["111077.49000000", "0.00000000"], ["111083.50000000", "0.00000000"], ["111085.13000000", "0.00000000"], ["111087.33000000", "0.00009000"], ["111108.68000000", "0.00000000"], ["111111.00000000", "0.17227000"], ["111120.61000000", "0.00008000"], ["111141.97000000", "0.00000000"], ["112618.50000000", "0.00100000"]]}}
{"type": "orderbook", "local_time": 1761342412643, "event_time": 1761342408214, "latency_ms": 4429, "data": {"e": "depthUpdate", "E": 1761342408214, "s": "BTCUSDT", "U": 79012712437, "u": 79012712474, "b": [["110954.17000000", "0.27859000"], ["110954.16000000", "0.00120000"], ["110950.93000000", "0.00010000"], ["110950.92000000", "0.00005000"], ["110950.91000000", "0.00000000"], ["110950.17000000", "0.00010000"], ["110950.01000000", "0.00010000"], ["110948.94000000", "0.00005000"], ["110948.78000000", "0.00005000"], ["110947.83000000", "0.00000000"], ["110947.82000000", "0.20761000"], ["110945.66000000", "0.02710000"], ["110903.91000000", "0.00000000"], ["110903.90000000", "0.06773000"], ["99858.00000000", "0.02245000"]], "a": [["110957.89000000", "0.06758000"], ["110957.90000000", "0.00005000"], ["110957.91000000", "0.05046000"], ["110958.08000000", "0.00000000"], ["110960.35000000", "0.11272000"], ["110960.46000000", "0.00725000"], ["110961.18000000", "0.04000000"], ["110962.40000000", "0.01840000"], ["110980.00000000", "0.00000000"], ["110987.68000000", "0.00901000"]]}}
{"type": "orderbook", "local_time": 1761342412644, "event_time": 1761342408314, "latency_ms": 4330, "data": {"e": "depthUpdate", "E": 1761342408314, "s": "BTCUSDT", "U": 79012712475, "u": 79012712509, "b": [["110954.17000000", "0.28029000"], ["110954.16000000", "0.00115000"], ["110951.26000000", "0.00305000"], ["110950.93000000", "0.68730000"], ["110950.92000000", "0.00000000"], ["110949.81000000", "0.00010000"], ["110943.69000000", "0.03905000"], ["110940.70000000", "0.00000000"], ["110937.53000000", "0.00090000"], ["110916.23000000", "0.07794000"], ["110915.34000000", "0.00090000"], ["110904.25000000", "0.00090000"], ["110661.47000000", "0.02598000"], ["110651.87000000", "0.02598000"], ["110642.19000000", "0.02598000"], ["110633.01000000", "0.02598000"], ["110628.86000000", "0.02598000"]], "a": [["110954.18000000", "3.54704000"], ["110958.09000000", "0.04702000"], ["110960.35000000", "0.00005000"], ["110962.39000000", "0.00700000"], ["110965.90000000", "0.11267000"], ["110974.00000000", "0.60522000"], ["110978.23000000", "0.03000000"], ["110980.54000000", "0.03000000"], ["110993.01000000", "0.00090000"], ["111007.29000000", "0.00000000"]]}}
{"type": "orderbook", "local_time": 1761342412644, "event_time": 1761342408414, "latency_ms": 4230, "data": {"e": "depthUpdate", "E": 1761342408414, "s": "BTCUSDT", "U": 79012712510, "u": 79012712553, "b": [["110954.17000000", "0.28041000"], ["110954.16000000", "0.00120000"], ["110951.26000000", "0.00305000"], ["110950.94000000", "0.21185000"], ["110950.93000000", "0.68735000"], ["110950.17000000", "0.00000000"], ["110950.01000000", "0.00000000"], ["110949.81000000", "0.00000000"], ["110948.94000000", "0.00010000"], ["110948.78000000", "0.00010000"], ["110947.83000000", "0.00005000"], ["110943.69000000", "0.03900000"], ["110929.65000000", "0.13511000"], ["110910.48000000", "0.00000000"], ["110875.21000000", "0.00000000"], ["110860.20000000", "0.00005000"], ["110654.17000000", "0.00000000"]], "a": [["110955.25000000", "0.00901000"], ["110957.90000000", "0.00010000"], ["110958.19000000", "0.29742000"], ["110960.35000000", "0.00000000"], ["110960.46000000", "0.00005000"], ["110960.47000000", "0.00005000"], ["110964.87000000", "0.23661000"], ["110970.16000000", "0.00000000"], ["110974.00000000", "0.56350000"], ["110974.88000000", "0.03000000"], ["110978.77000000", "0.03000000"], ["110997.39000000", "0.66488000"], ["110999.70000000", "0.00000000"], ["111004.27000000", "0.03000000"]]}}
{"type": "orderbook", "local_time": 1761342412645, "event_time": 1761342408514, "latency_ms": 4131, "data": {"e": "depthUpdate", "E": 1761342408514, "s": "BTCUSDT", "U": 79012712554, "u": 79012712594, "b": [["110954.17000000", "0.28041000"], ["110954.16000000", "0.00120000"], ["110951.79000000", "0.29738000"], ["110951.26000000", "0.00305000"], ["110950.95000000", "0.00010000"], ["110950.94000000", "0.21190000"], ["110948.94000000", "0.00000000"], ["110948.77000000", "0.00005000"], ["110945.66000000", "0.02705000"], ["110945.59000000", "0.04536000"], ["110942.71000000", "0.00000000"], ["110892.00000000", "0.32619000"]], "a": [["110954.19000000", "0.16913000"], ["110955.25000000", "0.00015000"], ["110956.11000000", "0.04582000"], ["110957.89000000", "0.06753000"], ["110957.96000000", "0.00005000"], ["110958.19000000", "0.29742000"], ["110960.46000000", "0.00000000"], ["110960.47000000", "0.00000000"], ["110961.18000000", "0.04005000"], ["110961.89000000", "0.04548000"], ["110964.90000000", "0.00000000"], ["110970.27000000", "0.00000000"], ["111003.11000000", "0.20926000"]]}}
{"type": "orderbook", "local_time": 1761342412645, "event_time": 1761342408614, "latency_ms": 4031, "data": {"e": "depthUpdate", "E": 1761342408614, "s": "BTCUSDT", "U": 79012712595, "u": 79012712652, "b": [["110954.17000000", "0.28036000"], ["110954.16000000", "0.00115000"], ["110952.00000000", "0.00150000"], ["110951.80000000", "0.36481000"], ["110951.79000000", "0.29748000"], ["110951.26000000", "0.00300000"], ["110950.94000000", "0.00015000"], ["110950.93000000", "0.00005000"], ["110950.00000000", "0.02145000"], ["110949.20000000", "0.09612000"], ["110948.93000000", "0.04510000"], ["110948.78000000", "0.00000000"], ["110948.77000000", "0.00000000"], ["99858.00000000", "0.02245000"]], "a": [["110954.18000000", "3.54604000"], ["110954.19000000", "0.16913000"], ["110955.25000000", "0.00000000"], ["110956.11000000", "0.04587000"], ["110957.89000000", "0.06758000"], ["110957.91000000", "0.05046000"], ["110957.95000000", "0.00000000"], ["110957.96000000", "0.00000000"], ["110958.08000000", "0.00005000"], ["110958.91000000", "0.04548000"], ["110961.18000000", "0.04005000"], ["110961.89000000", "0.00005000"], ["110962.39000000", "0.00705000"], ["110970.25000000", "0.20405000"], ["110976.92000000", "0.00000000"], ["110994.04000000", "0.00000000"], ["110997.93000000", "0.00000000"]]}}
{"type": "orderbook", "local_time": 1761342412646, "event_time": 1761342408714, "latency_ms": 3932, "data": {"e": "depthUpdate", "E": 1761342408714, "s": "BTCUSDT", "U": 79012712653, "u": 79012712694, "b": [["110954.17000000", "0.28051000"], ["110954.16000000", "0.00110000"], ["110952.00000000", "0.00150000"], ["110951.81000000", "0.20535000"], ["110951.80000000", "0.00020000"], ["110951.79000000", "0.29743000"], ["110950.95000000", "0.00000000"], ["110950.94000000", "0.00000000"], ["110950.93000000", "0.00000000"], ["110948.94000000", "0.00010000"], ["110945.66000000", "0.02710000"], ["110921.99000000", "0.83068000"], ["110916.21000000", "0.00000000"], ["110876.16000000", "0.13511000"]], "a": [["110958.19000000", "0.29742000"], ["110958.91000000", "0.04553000"], ["110960.44000000", "0.20756000"], ["110961.18000000", "0.04005000"], ["110961.89000000", "0.00000000"], ["110966.85000000", "0.20282000"], ["110972.49000000", "1.44342000"], ["110990.60000000", "0.98622000"]]}}
{"type": "orderbook", "local_time": 1761342412647, "event_time": 1761342408814, "latency_ms": 3833, "data": {"e": "depthUpdate", "E": 1761342408814, "s": "BTCUSDT", "U": 79012712695, "u": 79012712737, "b": [["110954.17000000", "0.28051000"], ["110954.16000000", "0.00110000"], ["110952.00000000", "0.00150000"], ["110951.82000000", "0.15771000"], ["110951.81000000", "0.00010000"], ["110951.80000000", "0.00010000"], ["110903.21000000", "0.04450000"], ["42000.00000000", "1.36834000"]], "a": [["110954.18000000", "3.54532000"], ["110958.91000000", "0.04553000"], ["110960.33000000", "0.00720000"], ["110960.44000000", "0.20761000"], ["110962.39000000", "0.00700000"], ["110972.48000000", "0.77864000"], ["110972.50000000", "0.00000000"], ["110977.61000000", "0.02705000"], ["110990.56000000", "0.34592000"], ["110990.59000000", "1.02725000"], ["110991.84000000", "0.00000000"], ["111033.28000000", "0.00000000"]]}}
{"type": "orderbook", "local_time": 1761342412647, "event_time": 1761342408915, "latency_ms": 3732, "data": {"e": "depthUpdate", "E": 1761342408915, "s": "BTCUSDT", "U": 79012712738, "u": 79012712786, "b": [["110954.17000000", "0.28009000"], ["110954.16000000", "0.00110000"], ["110952.00000000", "0.00150000"], ["110951.83000000", "0.00010000"], ["110951.82000000", "0.09641000"], ["110951.81000000", "0.00000000"], ["110950.01000000", "0.00010000"], ["110947.83000000", "0.00000000"], ["110849.98000000", "0.00005000"], ["110835.94000000", "0.00005000"]], "a": [["110954.18000000", "3.54512000"], ["110958.91000000", "0.04553000"], ["110960.33000000", "0.00725000"], ["110961.18000000", "0.04000000"], ["110979.00000000", "0.00011000"], ["111049.39000000", "0.00000000"], ["111050.34000000", "0.03400000"], ["111052.82000000", "0.00000000"], ["111052.83000000", "0.00000000"], ["111053.30000000", "0.00100000"], ["111053.31000000", "0.00100000"], ["111067.35000000", "0.00000000"], ["111069.85000000", "0.00000000"], ["111069.86000000", "0.00000000"], ["111105.93000000", "0.06000000"]]}}
{"type": "orderbook", "local_time": 1761342412961, "event_time": 1761342409014, "latency_ms": 3947, "data": {"e": "depthUpdate", "E": 1761342409014, "s": "BTCUSDT", "U": 79012712787, "u": 79012712797, "b": [["110951.83000000", "0.68680000"], ["110950.17000000", "0.00010000"], ["110948.94000000", "0.00000000"], ["109289.85000000", "0.00100000"], ["99858.00000000", "0.02245000"]], "a": [["111033.36000000", "0.00000000"], ["111147.98000000", "0.00000000"]]}}
{"type": "orderbook", "local_time": 1761342412962, "event_time": 1761342409114, "latency_ms": 3848, "data": {"e": "depthUpdate", "E": 1761342409114, "s": "BTCUSDT", "U": 79012712798, "u": 79012712818, "b": [["110954.17000000", "0.28019000"], ["110954.16000000", "0.00115000"], ["110952.00000000", "0.00150000"], ["110951.84000000", "0.33020000"], ["110951.83000000", "0.68685000"], ["110951.82000000", "0.00005000"], ["110950.17000000", "0.00000000"], ["110950.01000000", "0.00000000"], ["110947.83000000", "0.00005000"], ["110945.66000000", "0.02705000"], ["110921.99000000", "0.00000000"]], "a": [["110990.60000000", "0.00000000"], ["112618.50000000", "0.00100000"]]}}
{"type": "orderbook", "local_time": 1761342412963, "event_time": 1761342409214, "latency_ms": 3749, "data": {"e": "depthUpdate", "E": 1761342409214, "s": "BTCUSDT", "U": 79012712819, "u": 79012712842, "b": [["110954.17000000", "0.28024000"], ["110954.16000000", "0.00115000"], ["110952.00000000", "0.00150000"], ["110951.85000000", "0.00010000"], ["110951.84000000", "0.33025000"], ["110951.83000000", "0.68670000"], ["110951.82000000", "0.00000000"], ["110668.18000000", "0.00000000"], ["110654.17000000", "0.00000000"], ["99858.75000000", "0.00020000"]], "a": [["110990.59000000", "0.73286000"], ["111069.51000000", "0.00402000"], ["111078.64000000", "0.00000000"], ["111243.62000000", "0.00089000"], ["111252.76000000", "0.00000000"]]}}
{"type": "orderbook", "local_time": 1761342412963, "event_time": 1761342409314, "latency_ms": 3649, "data": {"e": "depthUpdate", "E": 1761342409314, "s": "BTCUSDT", "U": 79012712843, "u": 79012712857, "b": [["110954.17000000", "0.28014000"], ["110951.84000000", "0.33030000"], ["110951.83000000", "0.00005000"], ["110922.00000000", "0.83228000"], ["110659.09000000", "0.00401000"], ["99858.00000000", "0.02245000"]], "a": [["110954.18000000", "3.54507000"], ["110978.49000000", "0.00000000"], ["110990.62000000", "0.95604000"], ["111024.00000000", "0.00140000"], ["111026.00000000", "0.00140000"], ["111028.00000000", "0.00140000"]]}}
{"type": "orderbook", "local_time": 1761342412964, "event_time": 1761342409414, "latency_ms": 3550, "data": {"e": "depthUpdate", "E": 1761342409414, "s": "BTCUSDT", "U": 79012712858, "u": 79012712885, "b": [["110954.17000000", "0.27913000"], ["110954.16000000", "0.00110000"], ["110951.85000000", "0.09646000"], ["110951.84000000", "0.00010000"], ["110951.83000000", "0.00000000"], ["110948.94000000", "0.00010000"], ["110945.66000000", "0.02710000"], ["109750.00000000", "0.21225000"]], "a": [["110954.18000000", "3.99578000"], ["110954.19000000", "0.17814000"], ["110961.28000000", "0.00076000"], ["110963.51000000", "0.20282000"], ["111038.14000000", "0.00000000"], ["111111.00000000", "0.17232000"], ["111398.47000000", "0.00041000"]]}}
{"type": "orderbook", "local_time": 1761342412964, "event_time": 1761342409514, "latency_ms": 3450, "data": {"e": "depthUpdate", "E": 1761342409514, "s": "BTCUSDT", "U": 79012712886, "u": 79012712911, "b": [["110954.17000000", "0.27894000"], ["110954.16000000", "0.00110000"], ["110952.00000000", "0.00150000"], ["110951.86000000", "0.68680000"], ["110951.85000000", "0.09641000"], ["110951.84000000", "0.00000000"], ["110950.17000000", "0.00010000"], ["110950.01000000", "0.00010000"], ["110948.94000000", "0.00000000"], ["110947.83000000", "0.00000000"]], "a": [["110954.19000000", "0.17819000"], ["110957.91000000", "0.05051000"]]}}
{"type": "orderbook", "local_time": 1761342412965, "event_time": 1761342409614, "latency_ms": 3351, "data": {"e": "depthUpdate", "E": 1761342409614, "s": "BTCUSDT", "U": 79012712912, "u": 79012712945, "b": [["110954.17000000", "0.27894000"], ["110954.16000000", "0.00115000"], ["110952.00000000", "0.00150000"], ["110951.87000000", "0.30144000"], ["110951.86000000", "0.68690000"], ["110951.85000000", "0.00005000"], ["110950.17000000", "0.00000000"], ["110950.01000000", "0.00000000"], ["110947.83000000", "0.00005000"], ["110945.66000000", "0.02705000"], ["110750.05000000", "0.01411000"]], "a": [["110954.18000000", "3.99571000"], ["110955.68000000", "0.04921000"], ["110956.10000000", "0.00087000"], ["110957.91000000", "0.00010000"], ["110960.44000000", "0.20882000"], ["110962.40000000", "0.01767000"], ["110977.61000000", "0.00000000"], ["110984.57000000", "0.00000000"], ["111162.16000000", "0.01411000"]]}}
{"type": "orderbook", "local_time": 1761342412965, "event_time": 1761342409714, "latency_ms": 3251, "data": {"e": "depthUpdate", "E": 1761342409714, "s": "BTCUSDT", "U": 79012712946, "u": 79012712989, "b": [["110954.17000000", "0.27894000"], ["110954.16000000", "0.00123000"], ["110952.00000000", "0.00150000"], ["110951.88000000", "0.00010000"], ["110951.87000000", "0.30154000"], ["110951.86000000", "0.68675000"], ["110951.85000000", "0.00000000"], ["110647.21000000", "0.00000000"], ["110630.26000000", "0.00572000"]], "a": [["110954.19000000", "0.17814000"], ["110955.67000000", "0.00010000"], ["110955.68000000", "0.04936000"], ["110956.10000000", "0.00092000"], ["110956.11000000", "0.04577000"], ["110957.89000000", "0.06753000"], ["110957.90000000", "0.00000000"], ["110957.91000000", "0.00000000"], ["111050.34000000", "0.00000000"], ["111050.35000000", "0.03400000"], ["111053.30000000", "0.00000000"], ["111053.32000000", "0.00100000"]]}}
{"type": "orderbook", "local_time": 1761342413608, "event_time": 1761342409814, "latency_ms": 3794, "data": {"e": "depthUpdate", "E": 1761342409814, "s": "BTCUSDT", "U": 79012712990, "u": 79012712994, "b": [["110951.86000000", "0.00005000"], ["110938.55000000", "0.00000000"], ["110853.60000000", "0.00005000"]], "a": [["110955.68000000", "0.00015000"], ["110973.50000000", "0.00005000"]]}}
{"type": "orderbook", "local_time": 1761342413609, "event_time": 1761342409914, "latency_ms": 3695, "data": {"e": "depthUpdate", "E": 1761342409914, "s": "BTCUSDT", "U": 79012712995, "u": 79012713032, "b": [["110954.17000000", "0.27889000"], ["110954.16000000", "0.00118000"], ["110951.88000000", "0.18641000"], ["110951.87000000", "0.00010000"], ["110951.86000000", "0.00000000"], ["110948.94000000", "0.00010000"], ["110945.66000000", "0.02710000"]], "a": [["110954.19000000", "0.17814000"], ["110955.67000000", "0.00000000"], ["110955.68000000", "0.00000000"], ["110956.10000000", "0.00097000"], ["110956.11000000", "0.04582000"], ["110958.08000000", "0.00010000"], ["110958.18000000", "0.00005000"], ["110961.18000000", "0.04005000"], ["111004.00000000", "0.00120000"], ["111006.00000000", "0.58619000"], ["111008.00000000", "0.00120000"], ["111010.00000000", "0.00120000"], ["111012.00000000", "0.00136000"], ["111014.00000000", "0.00120000"], ["111016.00000000", "0.00127000"], ["111018.00000000", "0.00120000"], ["111020.00000000", "0.00120000"], ["111022.00000000", "0.00120000"]]}}
{"type": "orderbook", "local_time": 1761342413609, "event_time": 1761342410014, "latency_ms": 3595, "data": {"e": "depthUpdate", "E": 1761342410014, "s": "BTCUSDT", "U": 79012713033, "u": 79012713065, "b": [["110954.17000000", "0.28002000"], ["110954.16000000", "0.00118000"], ["110952.00000000", "0.00150000"], ["110951.89000000", "0.00010000"], ["110951.88000000", "0.09638000"], ["110951.87000000", "0.00000000"], ["110951.81000000", "0.68670000"], ["110950.01000000", "0.00010000"], ["110947.83000000", "0.00000000"], ["109289.85000000", "0.00100000"], ["88779.00000000", "0.00000000"]], "a": [["110954.18000000", "4.08528000"], ["110962.40000000", "0.00000000"], ["110970.31000000", "0.00005000"], ["110974.19000000", "0.00005000"], ["110977.47000000", "0.02705000"]]}}
{"type": "orderbook", "local_time": 1761342413610, "event_time": 1761342410114, "latency_ms": 3496, "data": {"e": "depthUpdate", "E": 1761342410114, "s": "BTCUSDT", "U": 79012713066, "u": 79012713112, "b": [["110954.17000000", "0.49837000"], ["110951.88000000", "0.28905000"], ["110951.82000000", "0.00010000"], ["110951.81000000", "0.00005000"], ["110950.01000000", "0.00000000"], ["110949.80000000", "0.00005000"], ["110948.94000000", "0.00000000"], ["110947.83000000", "0.00005000"], ["110947.82000000", "0.00005000"], ["110945.66000000", "0.02705000"], ["110933.40000000", "0.00250000"], ["110924.52000000", "0.00000000"], ["110878.74000000", "0.00623000"], ["110878.49000000", "0.00623000"], ["99858.00000000", "0.02245000"]], "a": [["110954.18000000", "4.07709000"], ["110958.09000000", "0.04702000"], ["110958.19000000", "0.00005000"], ["110960.33000000", "0.00005000"], ["110961.16000000", "0.00000000"], ["110961.52000000", "0.29736000"], ["110962.18000000", "0.00720000"], ["110965.90000000", "0.00000000"], ["110970.83000000", "0.11267000"], ["110977.47000000", "0.00000000"], ["110994.66000000", "0.00000000"], ["111013.77000000", "0.00623000"], ["111017.43000000", "0.32423000"], ["112618.50000000", "0.00100000"]]}}
{"type": "orderbook", "local_time": 1761342413610, "event_time": 1761342410214, "latency_ms": 3396, "data": {"e": "depthUpdate", "E": 1761342410214, "s": "BTCUSDT", "U": 79012713113, "u": 79012713180, "b": [["110954.17000000", "0.35406000"], ["110954.16000000", "0.00108000"], ["110951.88000000", "0.09638000"], ["110951.82000000", "0.00000000"], ["110951.81000000", "0.00000000"], ["110950.00000000", "0.02145000"], ["110949.80000000", "0.00000000"], ["110949.20000000", "0.03838000"], ["110948.94000000", "0.00010000"], ["110948.93000000", "0.04510000"], ["110947.83000000", "0.00000000"], ["110947.82000000", "0.00000000"], ["110945.66000000", "0.02710000"], ["110945.60000000", "0.00005000"], ["110945.59000000", "0.04541000"], ["110943.69000000", "0.03905000"], ["110938.76000000", "0.00000000"], ["110935.25000000", "0.30410000"], ["110903.90000000", "0.00000000"], ["110902.96000000", "0.06742000"], ["110866.18000000", "0.00000000"], ["110850.00000000", "0.02160000"], ["99858.75000000", "0.00000000"]], "a": [["110954.18000000", "4.08666000"], ["110954.19000000", "0.13412000"], ["110958.09000000", "0.04702000"], ["110958.18000000", "0.00000000"], ["110958.19000000", "0.00000000"], ["110958.90000000", "0.00005000"], ["110958.91000000", "0.00005000"], ["110959.28000000", "0.04548000"], ["110960.33000000", "0.00000000"], ["110960.44000000", "0.00126000"], ["110961.18000000", "0.04005000"], ["110961.51000000", "0.31749000"], ["110961.52000000", "0.29741000"], ["110962.18000000", "0.00005000"], ["110962.36000000", "0.00000000"], ["110962.39000000", "0.00000000"], ["110964.83000000", "0.01787000"], ["110964.87000000", "0.00000000"], ["110970.65000000", "0.00000000"], ["110977.51000000", "0.02705000"]]}}
{"type": "orderbook", "local_time": 1761342413611, "event_time": 1761342410314, "latency_ms": 3297, "data": {"e": "depthUpdate", "E": 1761342410314, "s": "BTCUSDT", "U": 79012713181, "u": 79012713222, "b": [["110951.32000000", "0.00720000"], ["110951.16000000", "0.20756000"], ["110950.17000000", "0.00010000"], ["110950.01000000", "0.00010000"], ["110948.94000000", "0.00000000"], ["110945.60000000", "0.00000000"], ["110945.59000000", "0.00005000"], ["110942.73000000", "0.04536000"], ["110725.53000000", "0.00000000"], ["99858.00000000", "0.02255000"]], "a": [["110954.19000000", "0.07214000"], ["110958.09000000", "0.04702000"], ["110958.55000000", "0.29736000"], ["110958.90000000", "0.00000000"], ["110958.91000000", "0.00000000"], ["110959.27000000", "0.00005000"], ["110959.28000000", "0.04553000"], ["110959.73000000", "0.11267000"], ["110960.44000000", "0.00121000"], ["110961.18000000", "0.04005000"], ["110961.51000000", "0.31754000"], ["110961.52000000", "0.00005000"], ["110962.15000000", "0.00720000"], ["110962.18000000", "0.00000000"], ["110962.33000000", "0.20756000"], ["110963.51000000", "0.20287000"], ["110970.83000000", "0.00000000"], ["110977.51000000", "0.00000000"], ["110977.74000000", "0.00000000"], ["110978.72000000", "0.00000000"], ["111214.17000000", "0.00000000"]]}}
{"type": "orderbook", "local_time": 1761342413611, "event_time": 1761342410414, "latency_ms": 3197, "data": {"e": "depthUpdate", "E": 1761342410414, "s": "BTCUSDT", "U": 79012713223, "u": 79012713415, "b": [["110954.17000000", "2.37291000"], ["110954.16000000", "0.00588000"], ["110954.00000000", "0.00660000"], ["110952.00000000", "0.00650000"], ["110951.89000000", "0.00000000"], ["110951.88000000", "0.14821000"], ["110951.80000000", "0.00000000"], ["110951.79000000", "0.29743000"], ["110951.32000000", "0.00725000"], ["110951.17000000", "0.00000000"], ["110951.16000000", "0.21011000"], ["110950.41000000", "0.04536000"], ["110950.17000000", "0.00000000"], ["110950.01000000", "0.00000000"], ["110949.21000000", "0.00000000"], ["110949.20000000", "0.02484000"], ["110948.94000000", "0.00000000"], ["110946.97000000", "0.06748000"], ["110945.66000000", "0.02710000"], ["110945.59000000", "0.00000000"], ["110943.69000000", "0.03900000"], ["110943.00000000", "0.06100000"], ["110942.74000000", "0.20282000"], ["110942.73000000", "0.00000000"], ["110940.01000000", "0.00000000"], ["110935.88000000", "0.00000000"], ["110935.80000000", "0.06748000"], ["110935.25000000", "0.00000000"], ["110928.96000000", "0.00000000"], ["110926.67000000", "0.00000000"], ["110925.91000000", "0.13519000"], ["110916.39000000", "0.32452000"], ["110899.49000000", "0.00000000"], ["110892.00000000", "0.00160000"], ["110886.26000000", "0.00000000"], ["110872.65000000", "0.00000000"], ["110871.68000000", "0.00000000"], ["110869.19000000", "0.00000000"], ["110866.18000000", "0.13484000"], ["110852.11000000", "0.00000000"], ["109599.87000000", "0.02506000"], ["99858.00000000", "0.02245000"]], "a": [["110954.18000000", "0.84370000"], ["110954.19000000", "0.00996000"], ["110956.10000000", "0.00107000"], ["110956.11000000", "0.04587000"], ["110957.89000000", "0.00010000"], ["110958.08000000", "0.00010000"], ["110958.09000000", "0.00194000"], ["110958.54000000", "0.00005000"], ["110958.55000000", "0.00005000"], ["110959.28000000", "0.00005000"], ["110959.73000000", "0.00005000"], ["110960.04000000", "0.00000000"], ["110961.16000000", "0.00000000"], ["110961.18000000", "0.00005000"], ["110961.51000000", "0.00005000"], ["110961.52000000", "0.00000000"], ["110962.15000000", "0.00000000"], ["110962.33000000", "0.00000000"], ["110963.15000000", "0.00000000"], ["110963.51000000", "0.00000000"], ["110963.55000000", "0.00000000"], ["110964.78000000", "0.04000000"], ["110964.83000000", "0.00000000"], ["110964.87000000", "0.00000000"], ["110964.88000000", "0.00000000"], ["110966.49000000", "0.00000000"], ["110966.85000000", "0.00000000"], ["110967.15000000", "0.04548000"], ["110968.67000000", "0.04508000"], ["110968.91000000", "0.00000000"], ["110971.12000000", "0.00000000"], ["110971.13000000", "0.00000000"], ["110972.07000000", "0.00000000"], ["110972.35000000", "0.00000000"], ["110972.49000000", "0.00000000"], ["110972.69000000", "0.00000000"], ["110973.65000000", "0.28000000"], ["110977.74000000", "0.00000000"], ["110977.92000000", "0.27041000"], ["110981.19000000", "0.04505000"], ["110986.68000000", "0.00250000"], ["111001.64000000", "0.00000000"], ["111008.83000000", "0.00000000"], ["111023.32000000", "0.32421000"], ["111027.23000000", "0.00000000"], ["111179.99000000", "0.00000000"]]}}
{"type": "orderbook", "local_time": 1761342413612, "event_time": 1761342410514, "latency_ms": 3098, "data": {"e": "depthUpdate", "E": 1761342410514, "s": "BTCUSDT", "U": 79012713416, "u": 79012714367, "b": [["110961.27000000", "5.49355000"], ["110961.17000000", "0.00000000"], ["110960.44000000", "0.00000000"], ["110960.43000000", "0.00530000"], ["110960.04000000", "0.00250000"], ["110960.00000000", "0.00005000"], ["110959.04000000", "0.00005000"], ["110958.09000000", "0.41017000"], ["110958.08000000", "0.00530000"], ["110958.07000000", "0.00000000"], ["110957.88000000", "0.00000000"], ["110957.87000000", "0.00000000"], ["110956.10000000", "0.03515000"], ["110956.09000000", "0.00010000"], ["110955.72000000", "0.00019000"], ["110955.60000000", "0.00250000"], ["110954.20000000", "0.00000000"], ["110954.19000000", "0.00605000"], ["110954.18000000", "0.65975000"], ["110954.17000000", "1.12750000"], ["110954.16000000", "0.00013000"], ["110954.00000000", "0.00145000"], ["110953.43000000", "0.00000000"], ["110953.25000000", "0.06748000"], ["110952.00000000", "0.00145000"], ["110951.89000000", "1.44342000"], ["110951.88000000", "0.00000000"], ["110951.80000000", "0.00000000"], ["110951.79000000", "0.00000000"], ["110951.57000000", "0.00088000"], ["110951.45000000", "0.04000000"], ["110951.32000000", "0.00000000"], ["110951.16000000", "0.00250000"], ["110950.42000000", "0.00000000"], ["110950.41000000", "0.00000000"], ["110950.16000000", "0.01765000"], ["110950.00000000", "0.02140000"], ["110949.20000000", "0.04175000"], ["110948.93000000", "0.04505000"], ["110948.31000000", "0.00044000"], ["110946.70000000", "0.02000000"], ["110946.16000000", "0.20282000"], ["110946.09000000", "0.00089000"], ["110945.66000000", "0.02705000"], ["110945.00000000", "1.44342000"], ["110944.88000000", "0.00044000"], ["110944.63000000", "0.00090000"], ["110942.83000000", "0.00000000"], ["110942.30000000", "0.04000000"], ["110941.45000000", "0.00000000"], ["110941.38000000", "0.00576000"], ["110939.90000000", "0.07661000"], ["110939.42000000", "0.13519000"], ["110938.95000000", "0.00000000"], ["110938.66000000", "0.00015000"], ["110937.84000000", "0.00000000"], ["110937.77000000", "0.00044000"], ["110937.54000000", "0.00000000"], ["110935.94000000", "0.00000000"], ["110935.79000000", "0.00000000"], ["110934.17000000", "0.00000000"], ["110933.40000000", "0.00000000"], ["110933.29000000", "0.00000000"], ["110929.99000000", "0.00000000"], ["110929.65000000", "0.00000000"], ["110928.14000000", "0.00000000"], ["110925.92000000", "0.00000000"], ["110925.91000000", "0.00000000"], ["110925.31000000", "0.00000000"], ["110923.78000000", "0.00000000"], ["110923.14000000", "0.32450000"], ["110922.75000000", "0.00000000"], ["110920.91000000", "0.00000000"], ["110917.65000000", "0.00000000"], ["110915.60000000", "0.00037000"], ["110915.35000000", "0.00000000"], ["110915.34000000", "0.00000000"], ["110914.59000000", "0.00000000"], ["110914.22000000", "0.00000000"], ["110911.28000000", "0.00000000"], ["110910.54000000", "0.00044000"], ["110909.86000000", "0.30772000"], ["110904.43000000", "0.00000000"], ["110904.25000000", "0.00000000"], ["110904.24000000", "0.00000000"], ["110902.82000000", "0.03218000"], ["110902.70000000", "0.28129000"], ["110902.65000000", "0.00000000"], ["110898.76000000", "0.00000000"], ["110896.01000000", "0.13524000"], ["110894.66000000", "0.13511000"], ["110891.58000000", "0.13519000"], ["110887.30000000", "0.00000000"], ["110886.12000000", "0.00000000"], ["110880.25000000", "0.00000000"], ["110879.26000000", "0.02536000"], ["110876.16000000", "0.00000000"], ["110870.12000000", "0.00000000"], ["110868.01000000", "0.22124000"], ["110856.33000000", "0.04098000"], ["110856.32000000", "0.00000000"], ["110853.44000000", "0.00000000"], ["110849.02000000", "0.00000000"], ["110838.34000000", "0.00000000"], ["110835.94000000", "0.00000000"], ["110791.00000000", "0.11380000"], ["110733.31000000", "0.03698000"], ["110731.00000000", "0.68581000"], ["110709.00000000", "1.36132000"], ["110642.19000000", "0.00000000"], ["110633.01000000", "0.00000000"], ["110631.00000000", "0.00000000"], ["110628.86000000", "0.00000000"], ["110626.00000000", "2.02305000"], ["110607.13000000", "0.00000000"], ["110603.00000000", "0.00000000"], ["110600.68000000", "0.00000000"], ["110533.00000000", "0.00000000"], ["110491.00000000", "0.00000000"], ["109289.85000000", "0.00000000"]], "a": [["110954.18000000", "0.00000000"], ["110954.19000000", "0.00000000"], ["110954.20000000", "0.00000000"], ["110954.21000000", "0.00000000"], ["110956.10000000", "0.00000000"], ["110956.11000000", "0.00000000"], ["110957.88000000", "0.00000000"], ["110957.89000000", "0.00000000"], ["110958.08000000", "0.00000000"], ["110958.09000000", "0.00000000"], ["110958.54000000", "0.00000000"], ["110958.55000000", "0.00000000"], ["110959.04000000", "0.00000000"], ["110959.27000000", "0.00000000"], ["110959.28000000", "0.00000000"], ["110959.73000000", "0.00000000"], ["110960.00000000", "0.00000000"], ["110960.44000000", "0.00000000"], ["110961.18000000", "0.00000000"], ["110961.28000000", "0.00326000"], ["110961.29000000", "0.00090000"], ["110961.51000000", "0.00000000"], ["110964.48000000", "0.00000000"], ["110964.77000000", "0.00010000"], ["110964.78000000", "0.00010000"], ["110964.82000000", "0.00000000"], ["110964.87000000", "0.00000000"], ["110965.45000000", "0.00000000"], ["110966.48000000", "0.00000000"], ["110967.14000000", "0.00010000"], ["110967.15000000", "0.00010000"], ["110967.59000000", "0.00074000"], ["110968.62000000", "0.00010000"], ["110968.63000000", "0.00000000"], ["110968.66000000", "0.00010000"], ["110968.67000000", "0.00010000"], ["110968.84000000", "0.00069000"], ["110968.92000000", "0.00000000"], ["110969.70000000", "0.00000000"], ["110970.24000000", "0.00005000"], ["110970.25000000", "0.00010000"], ["110970.26000000", "0.00010000"], ["110970.55000000", "0.00328000"], ["110970.98000000", "0.00000000"], ["110971.49000000", "0.00000000"], ["110972.02000000", "0.00000000"], ["110972.45000000", "0.00000000"], ["110972.48000000", "0.00005000"], ["110972.51000000", "0.09521000"], ["110972.65000000", "0.00000000"], ["110973.36000000", "0.00000000"], ["110973.65000000", "0.00005000"], ["110973.72000000", "0.00000000"], ["110973.81000000", "0.00005000"], ["110973.89000000", "0.00005000"], ["110974.00000000", "0.00000000"], ["110974.44000000", "0.00000000"], ["110974.45000000", "0.00000000"], ["110974.88000000", "0.00000000"], ["110975.05000000", "0.00000000"], ["110975.14000000", "0.00000000"], ["110975.33000000", "0.00151000"], ["110975.35000000", "0.00000000"], ["110976.02000000", "0.00000000"], ["110976.03000000", "0.00000000"], ["110976.25000000", "0.00000000"], ["110976.38000000", "0.00000000"], ["110977.00000000", "0.04508000"], ["110977.22000000", "0.00000000"], ["110977.29000000", "0.04000000"], ["110977.92000000", "0.00000000"], ["110977.93000000", "0.00000000"], ["110978.23000000", "0.00000000"], ["110978.30000000", "0.00000000"], ["110978.39000000", "0.00000000"], ["110978.65000000", "0.00000000"], ["110978.69000000", "0.00000000"], ["110978.77000000", "0.00000000"], ["110979.00000000", "0.00005000"], ["110979.15000000", "0.00000000"], ["110979.35000000", "0.00000000"], ["110980.00000000", "0.00005000"], ["110980.21000000", "0.04553000"], ["110980.46000000", "0.00000000"], ["110980.47000000", "0.00000000"], ["110980.48000000", "0.00000000"], ["110980.54000000", "0.00000000"], ["110980.65000000", "0.30541000"], ["110981.19000000", "0.00000000"], ["110981.54000000", "0.00000000"], ["110981.75000000", "0.00000000"], ["110982.24000000", "0.00250000"], ["110986.21000000", "0.00000000"], ["110987.75000000", "0.13519000"], ["110989.22000000", "0.07661000"], ["110990.00000000", "0.00005000"], ["110990.27000000", "0.06000000"], ["110990.55000000", "0.00450000"], ["110990.56000000", "0.00000000"], ["110991.12000000", "0.00250000"], ["110991.65000000", "0.13524000"], ["110995.56000000", "0.00250000"], ["110995.99000000", "0.27041000"], ["110996.43000000", "0.13511000"], ["110997.46000000", "0.00000000"], ["111000.11000000", "0.00090000"], ["111000.47000000", "0.04504000"], ["111001.65000000", "0.22835000"], ["111003.02000000", "0.22544000"], ["111003.73000000", "0.00000000"], ["111004.52000000", "0.00000000"], ["111008.37000000", "0.07656000"], ["111008.77000000", "0.00000000"], ["111011.21000000", "0.00090000"], ["111013.84000000", "0.00005000"], ["111014.91000000", "0.00000000"], ["111017.43000000", "0.00000000"], ["111017.57000000", "0.24526000"], ["111018.03000000", "0.06000000"], ["111024.07000000", "0.00000000"], ["111024.74000000", "0.29808000"], ["111027.85000000", "0.00000000"], ["111034.27000000", "0.04008000"], ["111034.49000000", "0.00000000"], ["111047.75000000", "0.00000000"], ["111049.70000000", "0.13511000"], ["111050.35000000", "0.00000000"], ["111050.39000000", "0.00000000"], ["111050.44000000", "0.03400000"], ["111053.31000000", "0.00000000"], ["111053.32000000", "0.00000000"], ["111053.82000000", "0.00000000"], ["111053.83000000", "0.00000000"], ["111054.40000000", "0.00000000"], ["111054.41000000", "0.00100000"], ["111054.59000000", "0.00000000"], ["111060.60000000", "0.03343000"], ["111067.78000000", "0.00000000"], ["111101.40000000", "0.06000000"], ["111104.00000000", "0.16928000"], ["111201.10000000", "0.00000000"], ["111214.00000000", "0.00000000"], ["111224.00000000", "0.68485000"], ["111233.13000000", "0.89889000"], ["111256.00000000", "2.00770000"], ["111300.30000000", "0.00000000"], ["111313.99000000", "0.04098000"], ["111314.24000000", "0.00000000"], ["111362.00000000", "0.00000000"], ["111372.79000000", "0.03698000"], ["111409.00000000", "0.00038000"], ["112618.50000000", "0.00000000"]]}}
{"type": "orderbook", "local_time": 1761342413613, "event_time": 1761342410614, "latency_ms": 2999, "data": {"e": "depthUpdate", "E": 1761342410614, "s": "BTCUSDT", "U": 79012714368, "u": 79012715067, "b": [["110965.69000000", "3.69069000"], ["110965.28000000", "0.00000000"], ["110965.27000000", "0.00520000"], ["110964.77000000", "0.00000000"], ["110964.76000000", "0.00000000"], ["110964.52000000", "0.00005000"], ["110964.51000000", "0.00000000"], ["110961.29000000", "2.28478000"], ["110961.28000000", "0.68355000"], ["110961.27000000", "1.56685000"], ["110960.43000000", "0.00510000"], ["110960.04000000", "0.00250000"], ["110958.09000000", "0.00005000"], ["110958.08000000", "0.00005000"], ["110957.72000000", "0.00088000"], ["110956.11000000", "0.00000000"], ["110956.10000000", "0.00005000"], ["110956.09000000", "0.00000000"], ["110954.46000000", "0.00044000"], ["110954.45000000", "0.00044000"], ["110954.19000000", "0.00005000"], ["110954.18000000", "0.80898000"], ["110954.17000000", "0.22520000"], ["110954.16000000", "0.00000000"], ["110954.00000000", "0.00140000"], ["110953.25000000", "0.06748000"], ["110952.00000000", "0.00140000"], ["110951.90000000", "0.20282000"], ["110951.89000000", "1.44342000"], ["110951.57000000", "0.00000000"], ["110949.21000000", "0.00015000"], ["110949.20000000", "0.53772000"], ["110948.73000000", "0.04572000"], ["110948.31000000", "0.00000000"], ["110944.87000000", "0.00044000"], ["110944.67000000", "0.00089000"], ["110943.66000000", "0.00000000"], ["110943.33000000", "0.00009000"], ["110941.44000000", "0.00000000"], ["110941.18000000", "0.00009000"], ["110940.15000000", "0.00009000"], ["110939.90000000", "0.00000000"], ["110938.66000000", "0.00000000"], ["110937.77000000", "0.00000000"], ["110935.05000000", "0.00009000"], ["110934.09000000", "0.00000000"], ["110930.64000000", "0.36571000"], ["110930.37000000", "0.32448000"], ["110928.68000000", "0.00009000"], ["110927.19000000", "0.00000000"], ["110922.18000000", "0.20282000"], ["110921.09000000", "0.00000000"], ["110920.51000000", "0.03218000"], ["110916.11000000", "0.02198000"], ["110909.72000000", "0.00000000"], ["110909.65000000", "0.00000000"], ["110902.82000000", "0.00000000"], ["110896.01000000", "0.00000000"], ["110895.40000000", "0.00000000"], ["110894.66000000", "0.00000000"], ["110893.18000000", "0.00617000"], ["110891.58000000", "0.00000000"], ["110887.51000000", "0.00090000"], ["110878.74000000", "0.00000000"], ["110878.49000000", "0.00000000"], ["110873.28000000", "0.00000000"], ["110868.01000000", "0.04097000"], ["110840.50000000", "0.00000000"], ["110786.56000000", "0.03424000"], ["110752.05000000", "0.00024000"], ["110715.19000000", "0.83223000"], ["110644.45000000", "0.00000000"], ["33000.00000000", "3.79445000"]], "a": [["110961.28000000", "0.00000000"], ["110961.29000000", "0.00000000"], ["110961.30000000", "0.00000000"], ["110964.52000000", "0.00000000"], ["110964.77000000", "0.00000000"], ["110964.78000000", "0.00000000"], ["110965.28000000", "0.00000000"], ["110965.29000000", "0.00000000"], ["110965.70000000", "0.00225000"], ["110965.71000000", "0.00090000"], ["110967.14000000", "0.00000000"], ["110967.15000000", "0.00000000"], ["110967.59000000", "0.00020000"], ["110968.62000000", "0.00000000"], ["110968.66000000", "0.00000000"], ["110968.67000000", "0.00000000"], ["110968.84000000", "0.00000000"], ["110970.24000000", "0.00000000"], ["110970.25000000", "0.00000000"], ["110970.26000000", "0.00000000"], ["110970.55000000", "0.00000000"], ["110970.76000000", "0.00000000"], ["110972.47000000", "0.00000000"], ["110972.48000000", "0.00000000"], ["110972.50000000", "0.00010000"], ["110972.51000000", "0.00005000"], ["110973.50000000", "0.00000000"], ["110973.55000000", "0.00000000"], ["110973.64000000", "0.00000000"], ["110973.65000000", "0.00000000"], ["110973.81000000", "0.00000000"], ["110973.89000000", "0.00000000"], ["110973.99000000", "0.00000000"], ["110974.51000000", "0.00070000"], ["110974.69000000", "0.00000000"], ["110976.13000000", "0.00074000"], ["110976.98000000", "0.00038000"], ["110976.99000000", "0.00010000"], ["110977.00000000", "0.00005000"], ["110977.28000000", "0.00010000"], ["110977.29000000", "0.00005000"], ["110977.80000000", "0.00000000"], ["110977.91000000", "0.00000000"], ["110978.67000000", "0.00010000"], ["110978.68000000", "0.00005000"], ["110978.70000000", "0.00005000"], ["110978.71000000", "0.00005000"], ["110978.81000000", "0.01041000"], ["110979.36000000", "0.00331000"], ["110979.57000000", "0.00005000"], ["110980.13000000", "0.08329000"], ["110980.21000000", "0.00010000"], ["110980.64000000", "0.20282000"], ["110980.65000000", "0.00541000"], ["110981.20000000", "0.00000000"], ["110981.80000000", "0.29730000"], ["110982.24000000", "0.00000000"], ["110982.34000000", "0.00090000"], ["110982.71000000", "0.00000000"], ["110984.35000000", "0.06000000"], ["110984.54000000", "0.00000000"], ["110984.86000000", "0.00000000"], ["110985.09000000", "0.00000000"], ["110986.21000000", "0.00000000"], ["110986.22000000", "0.00000000"], ["110987.75000000", "0.00000000"], ["110988.16000000", "0.24000000"], ["110988.17000000", "0.00000000"], ["110988.38000000", "0.00000000"], ["110988.99000000", "0.04000000"], ["110989.46000000", "0.00000000"], ["110990.00000000", "0.00011000"], ["110990.27000000", "0.09000000"], ["110991.78000000", "0.04548000"], ["110993.59000000", "0.00000000"], ["110997.41000000", "0.00172000"], ["110998.34000000", "0.13519000"], ["110999.83000000", "0.00000000"], ["111000.00000000", "0.00255000"], ["111001.64000000", "0.23827000"], ["111003.11000000", "0.00000000"], ["111003.75000000", "0.34593000"], ["111004.44000000", "0.00250000"], ["111006.96000000", "0.22535000"], ["111008.76000000", "0.00000000"], ["111008.94000000", "0.18027000"], ["111009.59000000", "0.00037000"], ["111009.77000000", "0.00000000"], ["111009.93000000", "0.00000000"], ["111010.28000000", "0.00034000"], ["111010.98000000", "0.00000000"], ["111011.76000000", "0.00000000"], ["111012.13000000", "0.00000000"], ["111013.77000000", "0.00000000"], ["111015.68000000", "0.00000000"], ["111019.32000000", "0.00005000"], ["111019.48000000", "0.00000000"], ["111021.20000000", "0.00224000"], ["111021.52000000", "0.00000000"], ["111022.32000000", "0.00000000"], ["111028.58000000", "0.00617000"], ["111029.69000000", "0.00048000"], ["111031.22000000", "0.32419000"], ["111034.27000000", "0.00000000"], ["111034.75000000", "0.00000000"], ["111036.49000000", "0.00617000"], ["111037.50000000", "0.02572000"], ["111047.01000000", "0.04008000"], ["111048.94000000", "0.00000000"], ["111049.49000000", "0.00000000"], ["111050.44000000", "0.00000000"], ["111050.88000000", "0.07132000"], ["111051.44000000", "0.00000000"], ["111051.79000000", "0.03694000"], ["111053.39000000", "0.00000000"], ["111054.41000000", "0.00000000"], ["111055.45000000", "0.00000000"], ["111056.45000000", "0.00000000"], ["111058.40000000", "0.00000000"], ["111059.40000000", "0.03400000"], ["111059.41000000", "0.00000000"], ["111059.42000000", "0.00000000"], ["111067.77000000", "0.00000000"], ["111068.10000000", "0.00000000"], ["111080.00000000", "0.02150000"], ["111083.86000000", "0.36520000"], ["111118.88000000", "0.03000000"], ["111140.36000000", "0.00019000"], ["111189.02000000", "0.00000000"], ["111198.68000000", "4.87537000"], ["111224.48000000", "0.04098000"], ["111248.53000000", "0.00000000"], ["111291.69000000", "0.00000000"], ["111313.49000000", "0.02199000"], ["111328.82000000", "0.48717000"], ["111363.55000000", "0.02433000"], ["111462.37000000", "0.00000000"], ["111462.83000000", "0.00000000"], ["111462.92000000", "0.00000000"], ["111532.81000000", "0.03698000"], ["111534.54000000", "0.03698000"], ["111535.48000000", "0.03698000"]]}}
{"type": "orderbook", "local_time": 1761342413614, "event_time": 1761342410714, "latency_ms": 2900, "data": {"e": "depthUpdate", "E": 1761342410714, "s": "BTCUSDT", "U": 79012715068, "u": 79012715317, "b": [["110965.69000000", "5.26896000"], ["110965.27000000", "0.00525000"], ["110964.72000000", "0.00000000"], ["110964.48000000", "0.00250000"], ["110962.13000000", "0.00088000"], ["110961.30000000", "2.89715000"], ["110961.29000000", "0.00550000"], ["110961.28000000", "0.68345000"], ["110961.27000000", "1.17642000"], ["110960.43000000", "0.00005000"], ["110958.09000000", "0.00000000"], ["110958.08000000", "0.00000000"], ["110957.72000000", "0.00000000"], ["110957.00000000", "0.00005000"], ["110956.10000000", "0.00000000"], ["110955.24000000", "0.20282000"], ["110954.88000000", "0.03900000"], ["110954.46000000", "0.00000000"], ["110954.45000000", "0.00000000"], ["110954.19000000", "0.00000000"], ["110954.18000000", "0.59986000"], ["110954.17000000", "0.17516000"], ["110953.61000000", "0.13519000"], ["110953.25000000", "0.06753000"], ["110952.67000000", "0.03600000"], ["110951.90000000", "0.20287000"], ["110951.26000000", "0.11459000"], ["110950.94000000", "0.00044000"], ["110950.16000000", "0.00000000"], ["110947.30000000", "0.00900000"], ["110942.28000000", "0.00000000"], ["110939.42000000", "0.00000000"], ["110938.28000000", "0.22218000"], ["110936.06000000", "0.04088000"], ["110933.89000000", "0.00012000"], ["110932.88000000", "0.00446000"], ["110930.80000000", "0.00000000"], ["110929.89000000", "0.00000000"], ["110925.88000000", "0.22076000"], ["110914.29000000", "0.00000000"], ["110913.49000000", "0.00000000"], ["110909.36000000", "0.00000000"], ["110902.86000000", "0.00626000"], ["110900.29000000", "0.13519000"], ["110892.23000000", "0.04753000"], ["110891.96000000", "0.00622000"], ["110873.27000000", "0.00000000"], ["110854.26000000", "0.36596000"]], "a": [["110965.70000000", "0.00195000"], ["110965.71000000", "0.00075000"], ["110967.59000000", "0.00000000"], ["110971.74000000", "0.03268000"], ["110971.76000000", "0.00000000"], ["110972.50000000", "0.00000000"], ["110972.51000000", "0.00000000"], ["110974.51000000", "0.00090000"], ["110975.10000000", "0.00109000"], ["110975.33000000", "0.00156000"], ["110976.55000000", "0.00000000"], ["110976.80000000", "0.00151000"], ["110976.99000000", "0.00000000"], ["110977.00000000", "0.00000000"], ["110977.28000000", "0.00000000"], ["110977.29000000", "0.00000000"], ["110978.67000000", "0.30972000"], ["110978.68000000", "0.00000000"], ["110978.70000000", "0.00000000"], ["110978.71000000", "0.00000000"], ["110978.80000000", "0.00010000"], ["110978.81000000", "0.01041000"], ["110979.56000000", "0.00000000"], ["110979.57000000", "0.00000000"], ["110980.12000000", "0.00010000"], ["110980.13000000", "0.08334000"], ["110980.21000000", "0.00005000"], ["110980.24000000", "0.00000000"], ["110980.63000000", "0.14366000"], ["110980.64000000", "0.20287000"], ["110980.65000000", "0.00546000"], ["110980.74000000", "0.00000000"], ["110981.12000000", "0.00070000"], ["110981.79000000", "0.00010000"], ["110981.80000000", "0.29735000"], ["110982.34000000", "0.00240000"], ["110984.34000000", "0.00005000"], ["110984.35000000", "0.06005000"], ["110984.55000000", "0.19225000"], ["110985.24000000", "0.00000000"], ["110986.37000000", "0.00000000"], ["110987.68000000", "0.00000000"], ["110988.15000000", "0.20756000"], ["110988.38000000", "0.00720000"], ["110989.02000000", "0.00000000"], ["110993.45000000", "0.11267000"], ["110998.74000000", "0.00000000"], ["111001.66000000", "0.03000000"], ["111005.10000000", "0.00900000"], ["111005.85000000", "0.00446000"], ["111006.38000000", "0.00016000"], ["111006.96000000", "0.22547000"], ["111007.37000000", "0.36545000"], ["111007.42000000", "0.07664000"], ["111008.00000000", "0.00393000"], ["111010.35000000", "0.00000000"], ["111014.34000000", "0.00038000"], ["111014.87000000", "0.00033000"], ["111017.56000000", "0.00016000"], ["111022.45000000", "0.00000000"], ["111027.44000000", "0.00000000"], ["111038.32000000", "0.00626000"], ["111042.30000000", "0.00653000"], ["111045.47000000", "0.00000000"], ["111046.45000000", "0.00000000"], ["111047.02000000", "0.00000000"], ["111059.40000000", "0.00000000"], ["111061.35000000", "0.00000000"], ["111062.35000000", "0.00000000"], ["111063.35000000", "0.00000000"], ["111063.40000000", "0.00000000"], ["111066.23000000", "0.04015000"], ["111066.81000000", "0.03000000"], ["111067.03000000", "0.00112000"], ["111067.92000000", "0.02415000"], ["111073.48000000", "0.03000000"], ["111119.92000000", "0.03000000"], ["111162.16000000", "0.00000000"], ["111177.43000000", "0.01411000"], ["111299.72000000", "0.00000000"], ["111377.58000000", "0.03698000"]]}}
{"type": "orderbook", "local_time": 1761342413614, "event_time": 1761342410814, "latency_ms": 2800, "data": {"e": "depthUpdate", "E": 1761342410814, "s": "BTCUSDT", "U": 79012715318, "u": 79012715576, "b": [["110969.99000000", "4.62571000"], ["110968.92000000", "0.00250000"], ["110968.78000000", "0.03000000"], ["110967.58000000", "0.00000000"], ["110965.70000000", "0.00000000"], ["110965.69000000", "2.09768000"], ["110965.27000000", "0.00525000"], ["110964.48000000", "0.00760000"], ["110962.13000000", "0.00093000"], ["110961.31000000", "0.00000000"], ["110961.30000000", "1.74749000"], ["110961.29000000", "0.00530000"], ["110961.28000000", "0.00005000"], ["110961.27000000", "0.26996000"], ["110960.43000000", "0.00000000"], ["110958.87000000", "0.00044000"], ["110955.24000000", "0.20287000"], ["110954.88000000", "0.03905000"], ["110954.17000000", "0.17511000"], ["110953.35000000", "0.00090000"], ["110953.34000000", "0.00151000"], ["110953.25000000", "0.06748000"], ["110951.90000000", "0.20282000"], ["110949.19000000", "0.00259000"], ["110948.25000000", "0.00000000"], ["110946.72000000", "0.00000000"], ["110946.09000000", "0.00000000"], ["110944.88000000", "0.00000000"], ["110944.87000000", "0.00000000"], ["110944.67000000", "0.00000000"], ["110937.53000000", "0.00000000"], ["110937.23000000", "0.32446000"], ["110935.24000000", "0.00000000"], ["110930.18000000", "0.22076000"], ["110925.88000000", "0.00000000"], ["110925.83000000", "0.00000000"], ["110877.06000000", "0.18027000"], ["110846.10000000", "0.00000000"], ["110727.81000000", "0.00000000"], ["42000.00000000", "1.36734000"]], "a": [["110965.70000000", "0.00000000"], ["110965.71000000", "0.00000000"], ["110970.00000000", "0.00418000"], ["110970.01000000", "0.00075000"], ["110970.31000000", "0.00000000"], ["110971.73000000", "0.00010000"], ["110971.74000000", "0.03293000"], ["110974.19000000", "0.00000000"], ["110974.51000000", "0.00090000"], ["110975.10000000", "0.00109000"], ["110975.33000000", "0.00156000"], ["110976.56000000", "0.00000000"], ["110976.80000000", "0.00000000"], ["110978.42000000", "0.00000000"], ["110978.66000000", "0.31648000"], ["110978.67000000", "0.30977000"], ["110978.80000000", "0.00000000"], ["110978.81000000", "0.00005000"], ["110980.13000000", "0.00005000"], ["110980.62000000", "0.00010000"], ["110980.63000000", "0.00015000"], ["110981.12000000", "0.00000000"], ["110981.79000000", "0.00000000"], ["110981.80000000", "0.00005000"], ["110982.34000000", "0.00309000"], ["110984.34000000", "0.00000000"], ["110984.35000000", "0.06005000"], ["110984.43000000", "0.08308000"], ["110984.55000000", "0.19230000"], ["110984.87000000", "0.29729000"], ["110986.65000000", "0.04658000"], ["110987.58000000", "0.04548000"], ["110988.16000000", "0.08000000"], ["110989.66000000", "0.16000000"], ["110990.27000000", "0.03000000"], ["110990.55000000", "0.00000000"], ["110990.81000000", "0.01036000"], ["110991.78000000", "0.00000000"], ["110994.36000000", "0.00000000"], ["110995.98000000", "0.00450000"], ["111000.11000000", "0.00000000"], ["111013.22000000", "0.06618000"], ["111013.75000000", "0.44152000"], ["111019.77000000", "0.00036000"], ["111020.95000000", "0.00035000"], ["111024.80000000", "0.00005000"], ["111032.17000000", "0.32418000"], ["111071.40000000", "0.00005000"], ["111118.88000000", "0.00000000"]]}}
{"type": "orderbook", "local_time": 1761342413615, "event_time": 1761342410914, "latency_ms": 2701, "data": {"e": "depthUpdate", "E": 1761342410914, "s": "BTCUSDT", "U": 79012715577, "u": 79012716035, "b": [["110978.66000000", "0.00000000"], ["110978.65000000", "2.43370000"], ["110978.42000000", "0.00000000"], ["110977.48000000", "0.29731000"], ["110977.22000000", "0.20756000"], ["110977.21000000", "0.00720000"], ["110976.76000000", "0.00000000"], ["110975.50000000", "0.00000000"], ["110975.48000000", "0.00005000"], ["110975.32000000", "0.00000000"], ["110975.26000000", "0.00044000"], ["110975.09000000", "0.00000000"], ["110975.03000000", "0.00000000"], ["110974.50000000", "0.00000000"], ["110971.73000000", "0.00000000"], ["110970.00000000", "1.15512000"], ["110969.99000000", "0.86928000"], ["110968.92000000", "0.00770000"], ["110968.78000000", "0.00515000"], ["110968.50000000", "0.06100000"], ["110967.54000000", "0.00007000"], ["110965.70000000", "1.15354000"], ["110965.69000000", "0.39224000"], ["110965.27000000", "0.00005000"], ["110964.48000000", "0.00255000"], ["110964.22000000", "0.11112000"], ["110964.07000000", "0.00044000"], ["110964.00000000", "0.06000000"], ["110962.18000000", "0.00090000"], ["110962.13000000", "0.00000000"], ["110962.00000000", "0.00103000"], ["110961.29000000", "0.00030000"], ["110961.28000000", "0.00000000"], ["110958.87000000", "0.00000000"], ["110956.47000000", "0.00007000"], ["110956.45000000", "0.11267000"], ["110956.37000000", "0.07661000"], ["110955.72000000", "0.00000000"], ["110955.24000000", "0.20287000"], ["110954.88000000", "0.03900000"], ["110954.79000000", "0.03600000"], ["110954.18000000", "0.59981000"], ["110953.59000000", "0.00044000"], ["110953.34000000", "0.00000000"], ["110951.47000000", "0.03600000"], ["110951.26000000", "0.00300000"], ["110950.94000000", "0.00000000"], ["110949.21000000", "0.00000000"], ["110945.36000000", "0.04506000"], ["110943.69000000", "0.00000000"], ["110941.13000000", "0.00000000"], ["110938.39000000", "0.22076000"], ["110937.23000000", "0.32719000"], ["110934.05000000", "0.00044000"], ["110931.50000000", "0.00000000"], ["110930.18000000", "0.00000000"], ["110925.24000000", "0.00000000"], ["110921.19000000", "0.00000000"], ["110920.68000000", "0.00000000"], ["110919.73000000", "0.17665000"], ["110919.66000000", "0.00000000"], ["110915.20000000", "0.00000000"], ["110910.54000000", "0.00000000"], ["110904.77000000", "0.13524000"], ["110902.96000000", "0.00000000"], ["110901.13000000", "0.00000000"], ["110882.21000000", "0.22544000"], ["110881.85000000", "0.22535000"], ["110881.75000000", "0.13511000"], ["110855.23000000", "0.00000000"], ["110832.80000000", "0.06000000"], ["99873.00000000", "0.00010000"], ["99858.00000000", "0.02235000"]], "a": [["110970.00000000", "0.00000000"], ["110970.01000000", "0.00000000"], ["110971.73000000", "0.00000000"], ["110971.74000000", "0.00000000"], ["110972.40000000", "0.00000000"], ["110974.51000000", "0.00000000"], ["110975.10000000", "0.00000000"], ["110975.33000000", "0.00000000"], ["110975.48000000", "0.00000000"], ["110975.51000000", "0.00000000"], ["110976.13000000", "0.00000000"], ["110976.77000000", "0.00000000"], ["110976.98000000", "0.00000000"], ["110978.43000000", "0.00000000"], ["110978.65000000", "0.00000000"], ["110978.66000000", "1.74887000"], ["110978.67000000", "0.00101000"], ["110978.68000000", "0.00045000"], ["110978.81000000", "0.00000000"], ["110979.00000000", "0.00005000"], ["110979.01000000", "0.00000000"], ["110979.36000000", "0.00000000"], ["110979.79000000", "0.00000000"], ["110980.12000000", "0.00000000"], ["110980.13000000", "0.00000000"], ["110980.21000000", "0.00000000"], ["110980.62000000", "0.00000000"], ["110980.63000000", "0.06329000"], ["110980.65000000", "0.00546000"], ["110981.80000000", "0.00000000"], ["110982.34000000", "0.00150000"], ["110984.34000000", "0.00010000"], ["110984.35000000", "0.06005000"], ["110984.42000000", "0.00010000"], ["110984.43000000", "0.00005000"], ["110984.54000000", "0.00010000"], ["110984.55000000", "0.30342000"], ["110984.56000000", "0.20287000"], ["110984.87000000", "0.29734000"], ["110986.65000000", "0.00155000"], ["110987.58000000", "0.04553000"], ["110988.15000000", "0.20756000"], ["110990.62000000", "0.00000000"], ["110992.54000000", "0.04508000"], ["110993.09000000", "0.08949000"], ["110995.31000000", "0.00151000"], ["110995.99000000", "0.00000000"], ["111001.65000000", "0.00000000"], ["111003.62000000", "0.00005000"], ["111003.63000000", "0.03000000"], ["111005.99000000", "0.27041000"], ["111006.38000000", "0.00000000"], ["111011.95000000", "0.06423000"], ["111013.22000000", "0.00000000"], ["111014.69000000", "0.06847000"], ["111017.56000000", "0.00000000"], ["111017.61000000", "0.00000000"], ["111019.22000000", "0.22835000"], ["111019.76000000", "0.00016000"], ["111021.20000000", "0.00000000"], ["111024.08000000", "0.00036000"], ["111024.89000000", "0.00034000"], ["111029.69000000", "0.00000000"], ["111030.27000000", "0.00016000"], ["111030.28000000", "0.00099000"], ["111033.99000000", "0.00224000"], ["111037.65000000", "0.32417000"], ["111046.88000000", "0.00048000"], ["111070.92000000", "0.03000000"], ["111083.40000000", "0.00000000"], ["111101.40000000", "0.00000000"], ["111108.74000000", "0.03000000"], ["111114.78000000", "0.09817000"]]}}
{"type": "orderbook", "local_time": 1761342413616, "event_time": 1761342411014, "latency_ms": 2602, "data": {"e": "depthUpdate", "E": 1761342411014, "s": "BTCUSDT", "U": 79012716036, "u": 79012716159, "b": [["110978.65000000", "2.43385000"], ["110977.49000000", "0.15310000"], ["110977.48000000", "0.29756000"], ["110977.23000000", "0.00010000"], ["110977.22000000", "0.20781000"], ["110977.21000000", "0.00735000"], ["110975.26000000", "0.00005000"], ["110970.01000000", "0.39094000"], ["110970.00000000", "0.00020000"], ["110969.99000000", "0.63641000"], ["110968.92000000", "0.00755000"], ["110968.78000000", "0.00505000"], ["110968.50000000", "0.06105000"], ["110965.71000000", "0.99912000"], ["110965.70000000", "0.00035000"], ["110965.69000000", "0.39179000"], ["110965.27000000", "0.00000000"], ["110964.48000000", "0.00250000"], ["110964.07000000", "0.00000000"], ["110962.25000000", "0.00044000"], ["110961.31000000", "0.20282000"], ["110961.30000000", "1.74744000"], ["110961.29000000", "0.00025000"], ["110961.27000000", "0.26991000"], ["110956.46000000", "0.05725000"], ["110955.24000000", "0.20282000"], ["110953.59000000", "0.00000000"], ["110948.20000000", "0.03900000"], ["110937.36000000", "0.00000000"], ["110934.05000000", "0.00000000"], ["110934.03000000", "0.00000000"], ["110930.76000000", "0.00000000"], ["110926.98000000", "0.04400000"], ["110903.21000000", "0.00000000"]], "a": [["110978.66000000", "1.79460000"], ["110978.67000000", "0.00106000"], ["110978.68000000", "0.00050000"], ["110980.62000000", "0.00010000"], ["110980.63000000", "0.06344000"], ["110980.64000000", "0.00010000"], ["110980.86000000", "0.01786000"], ["110984.35000000", "0.06005000"], ["110984.42000000", "0.00000000"], ["110984.43000000", "0.00000000"], ["110984.87000000", "0.29734000"], ["110986.65000000", "0.00150000"], ["110988.15000000", "0.20761000"], ["110997.13000000", "0.00000000"], ["111077.49000000", "0.03000000"], ["111083.00000000", "0.00005000"], ["111086.88000000", "0.00005000"], ["111098.29000000", "0.00450000"], ["111114.54000000", "0.01874000"], ["111170.09000000", "0.01874000"], ["111225.65000000", "0.01874000"]]}}
{"type": "orderbook", "local_time": 1761342413618, "event_time": 1761342411114, "latency_ms": 2504, "data": {"e": "depthUpdate", "E": 1761342411114, "s": "BTCUSDT", "U": 79012716160, "u": 79012716249, "b": [["110978.65000000", "2.43400000"], ["110977.50000000", "0.00010000"], ["110977.49000000", "0.15335000"], ["110977.22000000", "0.20771000"], ["110977.21000000", "0.00730000"], ["110975.26000000", "0.00000000"], ["110970.02000000", "0.13886000"], ["110970.01000000", "0.00005000"], ["110970.00000000", "0.00015000"], ["110968.50000000", "0.06105000"], ["110967.55000000", "0.00300000"], ["110965.71000000", "0.37226000"], ["110965.70000000", "0.00000000"], ["110965.69000000", "0.34304000"], ["110959.20000000", "0.00005000"], ["110953.79000000", "0.05100000"], ["110945.35000000", "0.00300000"], ["110931.97000000", "0.00000000"], ["110930.65000000", "0.62888000"], ["110926.98000000", "0.00000000"], ["110920.88000000", "0.00009000"], ["110646.33000000", "0.00000000"], ["109313.97000000", "0.00100000"]], "a": [["110978.66000000", "1.84423000"], ["110978.67000000", "0.00086000"], ["110978.68000000", "0.00025000"], ["110980.62000000", "0.02654000"], ["110980.63000000", "0.00015000"], ["110980.64000000", "0.00000000"], ["110980.65000000", "0.00546000"], ["110980.85000000", "0.00010000"], ["110987.47000000", "0.00009000"], ["110997.13000000", "0.00000000"], ["111000.86000000", "0.00300000"], ["111011.96000000", "0.00300000"], ["111017.78000000", "0.00000000"], ["111027.74000000", "0.04485000"], ["111070.41000000", "0.03400000"], ["111108.74000000", "0.00000000"], ["111119.92000000", "0.00000000"], ["111346.25000000", "0.00000000"], ["111459.59000000", "0.00010000"], ["111535.41000000", "0.03697000"], ["112643.34000000", "0.00100000"]]}}
{"type": "orderbook", "local_time": 1761342413618, "event_time": 1761342411214, "latency_ms": 2404, "data": {"e": "depthUpdate", "E": 1761342411214, "s": "BTCUSDT", "U": 79012716250, "u": 79012716306, "b": [["110978.65000000", "2.50299000"], ["110977.21000000", "0.00725000"], ["110975.48000000", "0.05035000"], ["110970.03000000", "0.06451000"], ["110970.02000000", "0.00000000"], ["110970.01000000", "0.00000000"], ["110965.71000000", "0.66810000"], ["110953.68000000", "0.00005000"], ["110942.60000000", "0.00005000"], ["110940.00000000", "0.01962000"], ["110933.11000000", "0.00000000"], ["110922.00000000", "0.00160000"], ["60000.00000000", "56.85876000"]], "a": [["110978.66000000", "1.84423000"], ["110978.67000000", "0.00086000"], ["110978.68000000", "0.00005000"], ["110980.61000000", "0.00010000"], ["110980.62000000", "0.00025000"], ["110980.63000000", "0.00000000"], ["110980.65000000", "0.00556000"], ["110980.86000000", "0.01796000"], ["110984.64000000", "0.04548000"], ["110987.58000000", "0.00005000"], ["110997.14000000", "0.02704000"], ["111022.03000000", "0.93602000"], ["111070.41000000", "0.00000000"], ["111338.62000000", "0.02432000"]]}}
{"type": "orderbook", "local_time": 1761342413619, "event_time": 1761342411314, "latency_ms": 2305, "data": {"e": "depthUpdate", "E": 1761342411314, "s": "BTCUSDT", "U": 79012716307, "u": 79012716360, "b": [["110977.21000000", "0.00730000"], ["110975.49000000", "0.00010000"], ["110970.04000000", "0.00005000"], ["110970.03000000", "0.20463000"], ["110970.00000000", "0.00010000"], ["110968.50000000", "0.06100000"], ["110950.46000000", "0.05100000"], ["110948.14000000", "0.05400000"], ["110914.52000000", "0.02663000"], ["110896.87000000", "0.00000000"], ["110800.01000000", "0.02598000"], ["110782.17000000", "0.02598000"], ["110768.74000000", "0.02598000"], ["110657.76000000", "0.02598000"]], "a": [["110978.66000000", "1.84474000"], ["110978.67000000", "0.00081000"], ["110980.61000000", "0.00000000"], ["110980.62000000", "0.00000000"], ["110980.65000000", "0.00566000"], ["110980.86000000", "0.01801000"], ["110982.34000000", "0.00155000"], ["110984.55000000", "0.30347000"], ["110984.56000000", "0.20287000"], ["110984.63000000", "0.00005000"], ["110984.64000000", "0.04553000"], ["110984.87000000", "0.29734000"], ["110987.58000000", "0.00000000"], ["110988.16000000", "0.08005000"], ["110997.14000000", "0.00000000"], ["111004.63000000", "0.03000000"], ["111006.94000000", "0.03000000"], ["111071.20000000", "0.03000000"], ["111082.86000000", "0.03000000"], ["113000.00000000", "40.24509000"]]}}
{"type": "orderbook", "local_time": 1761342413620, "event_time": 1761342411414, "latency_ms": 2206, "data": {"e": "depthUpdate", "E": 1761342411414, "s": "BTCUSDT", "U": 79012716361, "u": 79012716377, "b": [["110953.81000000", "0.05700000"], ["110949.92000000", "0.05100000"], ["110945.01000000", "0.83348000"], ["110936.47000000", "0.00000000"], ["110934.16000000", "0.00000000"], ["110920.39000000", "0.06633000"], ["99880.00000000", "1.67435000"]], "a": [["110998.43000000", "0.02704000"], ["111001.27000000", "0.03000000"], ["111005.17000000", "0.03000000"], ["111021.21000000", "0.00000000"], ["111023.52000000", "0.00000000"], ["111073.53000000", "0.03000000"], ["111077.41000000", "0.03000000"], ["112244.93000000", "0.00000000"]]}}
{"type": "orderbook", "local_time": 1761342413621, "event_time": 1761342411514, "latency_ms": 2107, "data": {"e": "depthUpdate", "E": 1761342411514, "s": "BTCUSDT", "U": 79012716378, "u": 79012716392, "b": [["110975.48000000", "0.00005000"], ["110953.74000000", "0.09000000"], ["110949.37000000", "0.05100000"], ["110942.60000000", "0.04385000"], ["110928.72000000", "0.00090000"], ["99880.00000000", "1.67415000"]], "a": [["111001.36000000", "0.06000000"], ["111005.72000000", "0.03000000"], ["111017.50000000", "0.00095000"], ["111070.46000000", "0.03400000"], ["111074.42000000", "0.00100000"], ["111074.43000000", "0.00100000"], ["111123.29000000", "0.03000000"]]}}
{"type": "orderbook", "local_time": 1761342413621, "event_time": 1761342411614, "latency_ms": 2007, "data": {"e": "depthUpdate", "E": 1761342411614, "s": "BTCUSDT", "U": 79012716393, "u": 79012716412, "b": [["110977.21000000", "0.00730000"], ["110975.49000000", "0.00000000"], ["110970.04000000", "0.00010000"], ["110957.00000000", "0.00011000"], ["110942.64000000", "0.00000000"], ["110942.56000000", "0.00000000"], ["110938.75000000", "0.00000000"], ["110931.87000000", "0.00000000"]], "a": [["110978.66000000", "1.84481000"], ["111017.90000000", "0.00000000"], ["111018.03000000", "0.00000000"], ["111021.78000000", "0.00000000"], ["111028.60000000", "0.00090000"], ["111123.29000000", "0.00000000"]]}}
{"type": "orderbook", "local_time": 1761342413622, "event_time": 1761342411714, "latency_ms": 1908, "data": {"e": "depthUpdate", "E": 1761342411714, "s": "BTCUSDT", "U": 79012716413, "u": 79012716436, "b": [["110977.55000000", "0.00099000"], ["110975.88000000", "0.00198000"], ["110974.22000000", "0.00360000"], ["110972.00000000", "0.00541000"], ["110969.22000000", "0.00396000"], ["110967.56000000", "0.00721000"], ["110948.27000000", "0.03900000"], ["110920.39000000", "0.00000000"], ["110899.63000000", "0.13511000"], ["110866.18000000", "0.00000000"], ["102097.47000000", "0.00010000"], ["60000.00000000", "56.85866000"]], "a": [["110978.66000000", "1.79488000"], ["110979.76000000", "0.00099000"], ["110980.65000000", "0.00025000"], ["110980.86000000", "0.00015000"], ["110981.43000000", "0.00198000"], ["110983.09000000", "0.00360000"], ["110985.31000000", "0.00541000"], ["110988.09000000", "0.00396000"], ["110989.75000000", "0.00721000"], ["110998.43000000", "0.00000000"], ["110998.51000000", "0.00000000"], ["111002.91000000", "0.00000000"], ["111014.69000000", "0.00000000"]]}}
{"type": "orderbook", "local_time": 1761342413622, "event_time": 1761342411814, "latency_ms": 1808, "data": {"e": "depthUpdate", "E": 1761342411814, "s": "BTCUSDT", "U": 79012716437, "u": 79012716508, "b": [["110978.65000000", "2.50334000"], ["110977.55000000", "0.00119000"], ["110977.49000000", "0.15340000"], ["110977.48000000", "0.29751000"], ["110977.22000000", "0.20771000"], ["110977.21000000", "0.00725000"], ["110972.77000000", "0.05080000"], ["110970.03000000", "0.20468000"], ["110965.69000000", "0.34312000"], ["110961.29000000", "0.00000000"]], "a": [["110978.66000000", "1.79508000"], ["110978.67000000", "0.00076000"], ["110978.68000000", "0.00000000"], ["110979.76000000", "0.00119000"], ["110980.65000000", "0.00000000"], ["110980.85000000", "0.00000000"], ["110980.86000000", "0.00000000"], ["110981.43000000", "0.00208000"], ["110981.65000000", "0.04955000"], ["110982.34000000", "0.00155000"], ["110984.35000000", "0.06010000"], ["110984.55000000", "0.30352000"], ["110984.56000000", "0.20292000"], ["110984.63000000", "0.00010000"], ["110984.64000000", "0.04558000"], ["110984.86000000", "0.00005000"], ["110984.87000000", "0.29734000"], ["110985.31000000", "0.00546000"], ["110988.38000000", "0.00725000"], ["110998.43000000", "0.02704000"]]}}
{"type": "orderbook", "local_time": 1761342413623, "event_time": 1761342411914, "latency_ms": 1709, "data": {"e": "depthUpdate", "E": 1761342411914, "s": "BTCUSDT", "U": 79012716509, "u": 79012716540, "b": [["110978.65000000", "2.50339000"], ["110977.22000000", "0.20771000"], ["110977.21000000", "0.00725000"], ["110972.78000000", "0.00010000"], ["110972.77000000", "0.05090000"], ["110970.03000000", "0.20463000"], ["110970.00000000", "0.00005000"], ["110968.78000000", "0.00500000"], ["110954.17000000", "0.13511000"], ["110937.11000000", "0.00000000"]], "a": [["110978.66000000", "1.79513000"], ["110978.67000000", "0.00081000"], ["110981.43000000", "0.00208000"], ["110981.64000000", "0.01648000"], ["110981.65000000", "0.04970000"], ["110982.34000000", "0.00150000"], ["110984.64000000", "0.04553000"], ["110984.86000000", "0.00000000"], ["110988.38000000", "0.00720000"]]}}
{"type": "orderbook", "local_time": 1761342413623, "event_time": 1761342412014, "latency_ms": 1609, "data": {"e": "depthUpdate", "E": 1761342412014, "s": "BTCUSDT", "U": 79012716541, "u": 79012716568, "b": [["110977.55000000", "0.00619000"], ["110977.49000000", "0.15840000"], ["110968.78000000", "0.00000000"], ["110965.69000000", "0.33812000"], ["110945.36000000", "0.00000000"]], "a": [["110978.66000000", "1.79614000"], ["110978.67000000", "0.00086000"], ["110981.43000000", "0.00208000"], ["110981.63000000", "0.00010000"], ["110981.64000000", "0.01663000"], ["110981.65000000", "0.00010000"], ["110984.56000000", "0.20287000"], ["110984.63000000", "0.00000000"], ["110988.16000000", "0.08000000"], ["111011.95000000", "0.01916000"], ["111028.58000000", "0.00622000"], ["111094.66000000", "0.00005000"]]}}
{"type": "orderbook", "local_time": 1761342413624, "event_time": 1761342412114, "latency_ms": 1510, "data": {"e": "depthUpdate", "E": 1761342412114, "s": "BTCUSDT", "U": 79012716569, "u": 79012716624, "b": [["110978.65000000", "2.50344000"], ["110977.56000000", "0.00010000"], ["110977.48000000", "0.30251000"], ["110972.77000000", "0.00010000"], ["110970.32000000", "0.11267000"], ["110970.04000000", "0.00000000"], ["110968.92000000", "0.00250000"], ["110956.45000000", "0.00000000"], ["110945.36000000", "0.00009000"], ["110920.88000000", "0.00000000"], ["110912.06000000", "0.00009000"], ["110887.60000000", "0.00000000"], ["110878.77000000", "0.00009000"], ["110854.31000000", "0.00000000"], ["110845.48000000", "0.00009000"], ["110821.02000000", "0.00000000"], ["110812.18000000", "0.00009000"], ["110787.74000000", "0.00000000"], ["109313.97000000", "0.00100000"]], "a": [["110978.66000000", "1.79609000"], ["110978.67000000", "0.00081000"], ["110981.64000000", "0.00015000"], ["110981.65000000", "0.00000000"], ["110984.56000000", "0.20292000"], ["110984.63000000", "0.00005000"], ["110985.89000000", "0.01797000"], ["110987.47000000", "0.00000000"], ["110988.16000000", "0.08005000"], ["110988.90000000", "0.00005000"], ["111011.95000000", "0.01925000"], ["111020.75000000", "0.00000000"], ["111045.25000000", "0.00009000"], ["111054.04000000", "0.00000000"], ["111064.80000000", "0.00000000"], ["111078.54000000", "0.00009000"], ["111087.33000000", "0.00000000"], ["111111.83000000", "0.00008000"], ["111120.61000000", "0.00000000"], ["111145.13000000", "0.00008000"], ["112643.34000000", "0.00100000"]]}}
{"type": "orderbook", "local_time": 1761342413624, "event_time": 1761342412214, "latency_ms": 1410, "data": {"e": "depthUpdate", "E": 1761342412214, "s": "BTCUSDT", "U": 79012716625, "u": 79012716663, "b": [["110978.65000000", "2.50349000"], ["110977.55000000", "0.00624000"], ["110977.22000000", "0.20771000"], ["110977.21000000", "0.00725000"], ["110972.78000000", "0.00000000"], ["110972.77000000", "0.00000000"], ["110972.00000000", "0.00546000"], ["110970.33000000", "0.00005000"], ["110970.32000000", "0.11272000"], ["110969.99000000", "0.63636000"], ["110956.46000000", "0.02361000"], ["110918.66000000", "0.06720000"]], "a": [["110978.66000000", "1.79604000"], ["110978.67000000", "0.00076000"], ["110981.43000000", "0.00208000"], ["110981.63000000", "0.00000000"], ["110981.64000000", "0.00000000"], ["110982.34000000", "0.00155000"], ["110984.63000000", "0.00010000"], ["110984.64000000", "0.04558000"], ["110984.86000000", "0.00005000"], ["110985.31000000", "0.00546000"], ["110985.89000000", "0.01802000"], ["111019.66000000", "0.06753000"], ["111715.71000000", "0.00022000"]]}}
{"type": "orderbook", "local_time": 1761342413625, "event_time": 1761342412314, "latency_ms": 1311, "data": {"e": "depthUpdate", "E": 1761342412314, "s": "BTCUSDT", "U": 79012716664, "u": 79012716667, "b": [["102097.47000000", "0.00000000"]], "a": [["110978.66000000", "1.79987000"], ["111325.18000000", "0.48717000"], ["111328.82000000", "0.00000000"]]}}
{"type": "orderbook", "local_time": 1761342413625, "event_time": 1761342412414, "latency_ms": 1211, "data": {"e": "depthUpdate", "E": 1761342412414, "s": "BTCUSDT", "U": 79012716668, "u": 79012716742, "b": [["110978.65000000", "2.50230000"], ["110977.89000000", "0.05077000"], ["110973.36000000", "0.00250000"], ["110972.93000000", "0.04536000"], ["110970.33000000", "0.00000000"], ["110969.99000000", "0.59100000"], ["110969.10000000", "0.00005000"], ["110951.16000000", "0.00000000"], ["110950.91000000", "0.24000000"], ["110941.38000000", "0.00000000"], ["110928.69000000", "0.00000000"], ["110913.86000000", "0.07661000"], ["110886.24000000", "0.22544000"], ["110885.88000000", "0.22535000"], ["110882.21000000", "0.00000000"], ["110881.85000000", "0.00000000"], ["110877.25000000", "0.00000000"], ["110866.87000000", "0.11891000"], ["110648.05000000", "0.00000000"], ["110607.74000000", "0.00000000"]], "a": [["110978.66000000", "0.59848000"], ["110978.67000000", "0.00126000"], ["110981.67000000", "0.05099000"], ["110984.35000000", "0.00010000"], ["110984.56000000", "0.00010000"], ["110984.64000000", "0.00010000"], ["110987.24000000", "0.02000000"], ["110987.54000000", "0.00000000"], ["110987.80000000", "0.04548000"], ["110989.22000000", "0.00000000"], ["110989.25000000", "0.04000000"], ["110993.45000000", "0.00000000"], ["111000.86000000", "0.11567000"], ["111004.00000000", "0.07781000"], ["111005.10000000", "0.00000000"], ["111007.93000000", "0.00900000"], ["111009.78000000", "0.00000000"], ["111019.12000000", "0.00000000"], ["111019.66000000", "0.00000000"], ["111046.67000000", "0.07661000"], ["111046.88000000", "0.00000000"], ["111047.01000000", "0.00000000"], ["111057.97000000", "0.13519000"], ["111059.50000000", "0.04008000"], ["111140.36000000", "0.00000000"], ["111253.89000000", "0.00000000"], ["111339.46000000", "0.02432000"]]}}
{"type": "orderbook", "local_time": 1761342413626, "event_time": 1761342412514, "latency_ms": 1112, "data": {"e": "depthUpdate", "E": 1761342412514, "s": "BTCUSDT", "U": 79012716743, "u": 79012716836, "b": [["110978.65000000", "2.50255000"], ["110977.89000000", "0.00520000"], ["110977.56000000", "0.00000000"], ["110977.49000000", "0.15830000"], ["110977.48000000", "0.30246000"], ["110977.22000000", "0.20761000"], ["110977.21000000", "0.00720000"], ["110970.32000000", "0.11267000"], ["110969.99000000", "0.58600000"], ["110962.04000000", "0.00044000"], ["110950.60000000", "0.00576000"], ["110943.70000000", "0.32444000"], ["110940.01000000", "0.43715000"], ["110916.39000000", "0.00000000"], ["99880.00000000", "1.67415000"]], "a": [["110978.66000000", "0.59838000"], ["110978.67000000", "0.00116000"], ["110981.43000000", "0.00208000"], ["110981.66000000", "0.01691000"], ["110981.67000000", "0.05114000"], ["110982.34000000", "0.00150000"], ["110984.34000000", "0.00000000"], ["110984.35000000", "0.00000000"], ["110984.55000000", "0.30342000"], ["110984.56000000", "0.00000000"], ["110984.63000000", "0.00000000"], ["110984.64000000", "0.00000000"], ["110984.86000000", "0.20282000"], ["110984.87000000", "0.00010000"], ["110985.88000000", "0.00010000"], ["110985.89000000", "0.01807000"], ["110987.23000000", "0.00010000"], ["110987.24000000", "0.02005000"], ["110987.79000000", "0.00005000"], ["110987.80000000", "0.04553000"], ["110987.96000000", "0.29729000"], ["110992.75000000", "0.00332000"], ["110998.43000000", "0.00000000"], ["110998.49000000", "0.02704000"], ["111006.00000000", "0.81721000"], ["111046.88000000", "0.00048000"], ["111068.53000000", "0.08058000"], ["111158.28000000", "0.00019000"]]}}
{"type": "orderbook", "local_time": 1761342413626, "event_time": 1761342412614, "latency_ms": 1012, "data": {"e": "depthUpdate", "E": 1761342412614, "s": "BTCUSDT", "U": 79012716837, "u": 79012716900, "b": [["110978.65000000", "2.51105000"], ["110970.33000000", "0.00450000"], ["110965.69000000", "0.33362000"], ["110964.23000000", "0.36035000"], ["110874.02000000", "0.00223000"], ["110851.62000000", "0.00191000"], ["110850.79000000", "0.00000000"], ["110832.01000000", "0.00224000"], ["110827.40000000", "0.00060000"], ["110806.01000000", "0.00000000"], ["110764.01000000", "0.00090000"], ["110743.20000000", "0.00000000"], ["110740.01000000", "0.00076000"], ["110726.01000000", "0.00000000"], ["110720.21000000", "0.00090000"], ["110696.91000000", "0.00000000"], ["99880.00000000", "1.67445000"], ["99873.00000000", "0.00000000"]], "a": [["110978.66000000", "0.59843000"], ["110978.67000000", "0.00121000"], ["110981.43000000", "0.00208000"], ["110981.65000000", "0.00010000"], ["110981.66000000", "0.01706000"], ["110981.67000000", "0.05109000"], ["110984.55000000", "0.30342000"], ["110984.85000000", "0.00010000"], ["110984.86000000", "0.20292000"], ["110984.87000000", "0.00000000"], ["110985.88000000", "0.00000000"], ["110985.89000000", "0.01802000"], ["110987.23000000", "0.00000000"], ["110987.80000000", "0.04553000"], ["110987.96000000", "0.29734000"], ["110988.15000000", "0.20756000"], ["110988.16000000", "0.08000000"], ["110995.98000000", "0.00000000"], ["110997.65000000", "0.00450000"], ["111000.47000000", "0.00000000"], ["111010.35000000", "0.04504000"], ["111056.16000000", "0.00000000"], ["111061.48000000", "0.00224000"], ["111075.64000000", "0.00000000"], ["111106.99000000", "0.07853000"], ["111145.27000000", "0.00090000"], ["111165.78000000", "0.00000000"], ["111171.99000000", "0.00090000"], ["111192.15000000", "0.00000000"]]}}
{"type": "orderbook", "local_time": 1761342413627, "event_time": 1761342412715, "latency_ms": 912, "data": {"e": "depthUpdate", "E": 1761342412715, "s": "BTCUSDT", "U": 79012716901, "u": 79012716906, "b": [["110978.65000000", "3.19625000"], ["110962.50000000", "0.00005000"], ["99880.00000000", "1.67425000"]], "a": [["110978.66000000", "0.64348000"], ["111060.60000000", "0.00017000"], ["111073.11000000", "0.03326000"]]}}
{"type": "orderbook", "local_time": 1761342413627, "event_time": 1761342412914, "latency_ms": 713, "data": {"e": "depthUpdate", "E": 1761342412914, "s": "BTCUSDT", "U": 79012716907, "u": 79012716913, "b": [["110812.74000000", "0.13509000"]], "a": [["110978.66000000", "0.59843000"], ["110997.65000000", "0.00000000"], ["110998.33000000", "0.00450000"], ["111019.72000000", "0.06798000"], ["111033.32000000", "0.01411000"], ["111103.39000000", "0.00000000"], ["111125.70000000", "0.13239000"]]}}
{"type": "orderbook", "local_time": 1761342413628, "event_time": 1761342413014, "latency_ms": 614, "data": {"e": "depthUpdate", "E": 1761342413014, "s": "BTCUSDT", "U": 79012716914, "u": 79012716928, "b": [["110558.15000000", "0.02698000"], ["110556.37000000", "0.02698000"], ["110555.61000000", "0.02698000"], ["110554.39000000", "0.02698000"], ["110553.09000000", "0.02698000"], ["110552.65000000", "0.02698000"], ["110552.03000000", "0.02698000"], ["110551.39000000", "0.02698000"], ["110549.34000000", "0.02698000"], ["110547.29000000", "0.02698000"], ["110545.54000000", "0.02698000"], ["88783.00000000", "0.00000000"]], "a": [["110993.61000000", "0.00005000"], ["111096.58000000", "0.00005000"]]}}
{"type": "orderbook", "local_time": 1761342413628, "event_time": 1761342413114, "latency_ms": 514, "data": {"e": "depthUpdate", "E": 1761342413114, "s": "BTCUSDT", "U": 79012716929, "u": 79012716946, "b": [["110964.23000000", "0.00000000"], ["110962.04000000", "0.00000000"], ["110961.32000000", "0.36035000"], ["110925.85000000", "0.09912000"], ["110923.34000000", "0.07661000"], ["110889.27000000", "0.00000000"], ["110882.05000000", "0.00000000"], ["109313.97000000", "0.00100000"]], "a": [["110978.66000000", "0.59823000"], ["110978.67000000", "0.00101000"], ["112643.34000000", "0.00100000"]]}}
{"type": "orderbook", "local_time": 1761342413629, "event_time": 1761342413214, "latency_ms": 415, "data": {"e": "depthUpdate", "E": 1761342413214, "s": "BTCUSDT", "U": 79012716947, "u": 79012716951, "b": [["110964.23000000", "0.00000000"], ["110961.33000000", "0.36035000"], ["110961.32000000", "0.00000000"], ["110906.36000000", "0.01411000"]], "a": [["110983.70000000", "0.29730000"], ["110987.96000000", "0.00005000"]]}}
{"type": "orderbook", "local_time": 1761342413629, "event_time": 1761342413315, "latency_ms": 314, "data": {"e": "depthUpdate", "E": 1761342413315, "s": "BTCUSDT", "U": 79012716952, "u": 79012716981, "b": [["110978.65000000", "3.19692000"], ["110977.93000000", "0.01184000"], ["110950.60000000", "0.00000000"], ["99880.00000000", "1.67425000"]], "a": [["110978.66000000", "0.59650000"], ["110978.67000000", "0.00050000"], ["110981.67000000", "0.05109000"], ["110983.69000000", "0.00010000"], ["110983.70000000", "0.29740000"], ["110984.86000000", "0.20287000"], ["110987.79000000", "0.00000000"], ["110987.80000000", "0.04553000"], ["110987.96000000", "0.00000000"], ["110992.75000000", "0.00000000"], ["110996.84000000", "0.00000000"], ["110998.32000000", "0.00450000"], ["110998.33000000", "0.00000000"]]}}
{"type": "orderbook", "local_time": 1761342413630, "event_time": 1761342413414, "latency_ms": 216, "data": {"e": "depthUpdate", "E": 1761342413414, "s": "BTCUSDT", "U": 79012716982, "u": 79012717009, "b": [["110978.65000000", "3.19702000"], ["110977.93000000", "0.01204000"], ["110977.89000000", "0.00520000"], ["110977.55000000", "0.00614000"], ["110977.49000000", "0.15825000"], ["110977.48000000", "0.30241000"], ["110950.43000000", "0.00576000"], ["110943.70000000", "0.00000000"], ["110921.49000000", "0.32451000"]], "a": [["110978.66000000", "0.59650000"], ["110993.43000000", "0.00331000"], ["111010.35000000", "0.00000000"], ["111011.94000000", "0.04504000"], ["111028.58000000", "0.00005000"], ["111041.72000000", "0.00629000"], ["111064.80000000", "0.00005000"], ["111070.46000000", "0.00000000"], ["111070.51000000", "0.03400000"], ["111074.42000000", "0.00000000"], ["111074.43000000", "0.00000000"], ["111075.06000000", "0.00166000"], ["111075.07000000", "0.00100000"]]}}
{"type": "orderbook", "local_time": 1761342413630, "event_time": 1761342413514, "latency_ms": 116, "data": {"e": "depthUpdate", "E": 1761342413514, "s": "BTCUSDT", "U": 79012717010, "u": 79012717049, "b": [["110978.65000000", "3.19792000"], ["110978.64000000", "0.00090000"], ["110949.20000000", "0.77881000"], ["110906.36000000", "0.00000000"], ["110897.68000000", "0.00000000"], ["110873.68000000", "0.01411000"]], "a": []}}
{"type": "orderbook", "local_time": 1761342413805, "event_time": 1761342413615, "latency_ms": 190, "data": {"e": "depthUpdate", "E": 1761342413615, "s": "BTCUSDT", "U": 79012717050, "u": 79012717073, "b": [["110978.65000000", "3.19817000"], ["110978.64000000", "0.00110000"], ["110977.94000000", "0.00010000"], ["110977.89000000", "0.00510000"], ["110977.55000000", "0.00609000"], ["110977.49000000", "0.15820000"], ["110972.94000000", "0.00005000"], ["110950.43000000", "0.00000000"], ["110832.02000000", "0.00224000"], ["110832.01000000", "0.00000000"], ["110720.22000000", "0.00090000"], ["110720.21000000", "0.00000000"]], "a": [["110978.66000000", "1.70089000"], ["111008.36000000", "0.04509000"], ["111011.94000000", "0.00000000"]]}}
{"type": "orderbook", "local_time": 1761342413805, "event_time": 1761342413714, "latency_ms": 91, "data": {"e": "depthUpdate", "E": 1761342413714, "s": "BTCUSDT", "U": 79012717074, "u": 79012717075, "b": [["110950.62000000", "0.00576000"], ["99880.00000000", "1.67445000"]], "a": []}}
{"type": "orderbook", "local_time": 1761342413806, "event_time": 1761342413814, "latency_ms": -8, "data": {"e": "depthUpdate", "E": 1761342413814, "s": "BTCUSDT", "U": 79012717076, "u": 79012717080, "b": [["110978.65000000", "3.19774000"], ["110965.80000000", "0.00005000"], ["99880.00000000", "1.67425000"]], "a": []}}
{"type": "orderbook", "local_time": 1761342413898, "event_time": 1761342413914, "latency_ms": -16, "data": {"e": "depthUpdate", "E": 1761342413914, "s": "BTCUSDT", "U": 79012717081, "u": 79012717086, "b": [["110976.28000000", "0.05020000"], ["110965.80000000", "0.00064000"], ["110965.71000000", "0.66775000"], ["110965.69000000", "0.33354000"], ["110945.01000000", "0.00000000"]], "a": [["111022.03000000", "0.00000000"]]}}
{"type": "orderbook", "local_time": 1761342413945, "event_time": 1761342414014, "latency_ms": -69, "data": {"e": "depthUpdate", "E": 1761342414014, "s": "BTCUSDT", "U": 79012717087, "u": 79012717097, "b": [["110978.65000000", "3.19784000"], ["110978.64000000", "0.00115000"], ["110972.00000000", "0.00541000"], ["110971.12000000", "0.11436000"], ["110962.55000000", "0.00005000"], ["110932.89000000", "0.02698000"], ["110545.52000000", "0.02698000"]], "a": [["111290.05000000", "0.00005000"], ["111325.18000000", "0.48717000"]]}}
{"type": "orderbook", "local_time": 1761342414055, "event_time": 1761342414114, "latency_ms": -59, "data": {"e": "depthUpdate", "E": 1761342414114, "s": "BTCUSDT", "U": 79012717098, "u": 79012717111, "b": [["110978.65000000", "3.19859000"], ["110978.64000000", "0.00120000"], ["110964.54000000", "0.01802000"], ["110962.25000000", "0.00000000"], ["109313.97000000", "0.00100000"]], "a": [["110978.66000000", "1.65516000"], ["110997.82000000", "0.01802000"], ["111003.75000000", "0.00000000"], ["111340.90000000", "0.02432000"], ["111346.02000000", "0.00000000"], ["112643.34000000", "0.00100000"]]}}
{"type": "orderbook", "local_time": 1761342414158, "event_time": 1761342414214, "latency_ms": -56, "data": {"e": "depthUpdate", "E": 1761342414214, "s": "BTCUSDT", "U": 79012717112, "u": 79012717120, "b": [["110976.28000000", "0.00000000"], ["110950.62000000", "0.00000000"], ["110945.55000000", "0.83347000"]], "a": [["110978.66000000", "1.70089000"], ["111007.37000000", "0.00000000"], ["111013.40000000", "0.34595000"], ["111013.41000000", "0.97391000"], ["111075.06000000", "0.00066000"], ["111075.08000000", "0.00100000"]]}}
{"type": "orderbook", "local_time": 1761342414271, "event_time": 1761342414314, "latency_ms": -43, "data": {"e": "depthUpdate", "E": 1761342414314, "s": "BTCUSDT", "U": 79012717121, "u": 79012717140, "b": [["110978.65000000", "3.19372000"], ["110978.64000000", "0.00115000"], ["110977.93000000", "0.00020000"], ["110950.38000000", "0.00576000"], ["110840.00000000", "0.00254000"], ["110761.28000000", "0.02498000"], ["110659.12000000", "0.02498000"], ["110657.77000000", "0.00572000"], ["110630.26000000", "0.00000000"]], "a": [["110978.66000000", "1.65723000"], ["111012.08000000", "0.93421000"], ["111013.40000000", "0.00000000"], ["111551.07000000", "0.00000000"]]}}
{"type": "orderbook", "local_time": 1761342414395, "event_time": 1761342414414, "latency_ms": -19, "data": {"e": "depthUpdate", "E": 1761342414414, "s": "BTCUSDT", "U": 79012717141, "u": 79012717158, "b": [["110978.65000000", "3.19367000"], ["110978.64000000", "0.00110000"], ["110977.94000000", "0.00000000"], ["110977.93000000", "0.00000000"], ["110977.89000000", "0.00520000"], ["110977.55000000", "0.00614000"], ["110977.49000000", "0.15825000"], ["110970.33000000", "0.00000000"], ["110969.23000000", "0.00450000"]], "a": [["110996.13000000", "0.00450000"], ["110998.32000000", "0.00000000"]]}}
{"type": "orderbook", "local_time": 1761342414480, "event_time": 1761342414514, "latency_ms": -34, "data": {"e": "depthUpdate", "E": 1761342414514, "s": "BTCUSDT", "U": 79012717159, "u": 79012717171, "b": [["110978.65000000", "3.19367000"], ["110978.64000000", "0.00110000"], ["110956.47000000", "0.04511000"], ["110659.09000000", "0.00000000"], ["110652.09000000", "0.00401000"]], "a": [["110978.66000000", "1.70296000"], ["111013.02000000", "0.34595000"], ["111062.48000000", "0.00402000"], ["111069.51000000", "0.00000000"], ["111236.61000000", "0.00089000"], ["111243.62000000", "0.00000000"]]}}
{"type": "orderbook", "local_time": 1761342414548, "event_time": 1761342414614, "latency_ms": -66, "data": {"e": "depthUpdate", "E": 1761342414614, "s": "BTCUSDT", "U": 79012717172, "u": 79012717176, "b": [["110956.48000000", "0.03708000"], ["110956.46000000", "0.00000000"], ["99880.00000000", "1.67435000"], ["39952.32000000", "0.00016000"]], "a": [["111481.21000000", "0.36390000"]]}}
{"type": "orderbook", "local_time": 1761342414676, "event_time": 1761342414714, "latency_ms": -38, "data": {"e": "depthUpdate", "E": 1761342414714, "s": "BTCUSDT", "U": 79012717177, "u": 79012717181, "b": [["110965.71000000", "0.66783000"], ["110942.60000000", "0.00005000"], ["110938.49000000", "0.04335000"], ["99880.00000000", "1.67425000"]], "a": [["111481.21000000", "0.00000000"]]}}
{"type": "orderbook", "local_time": 1761342414821, "event_time": 1761342414814, "latency_ms": 7, "data": {"e": "depthUpdate", "E": 1761342414814, "s": "BTCUSDT", "U": 79012717182, "u": 79012717411, "b": [["110978.65000000", "3.79648000"], ["110978.64000000", "0.00520000"], ["110977.50000000", "0.00000000"], ["110977.49000000", "0.15815000"], ["110977.48000000", "0.29741000"], ["110977.23000000", "0.00000000"], ["110977.21000000", "0.00000000"], ["110976.28000000", "0.05097000"], ["110976.14000000", "0.04536000"], ["110975.73000000", "0.00720000"], ["110973.40000000", "0.06748000"], ["110973.37000000", "0.00450000"], ["110972.94000000", "0.00000000"], ["110972.93000000", "0.00000000"], ["110969.23000000", "0.00000000"], ["110968.51000000", "0.66436000"], ["110968.43000000", "0.01802000"], ["110967.86000000", "0.13511000"], ["110966.88000000", "1.44342000"], ["110965.72000000", "0.20282000"], ["110965.69000000", "0.31551000"], ["110964.54000000", "0.00000000"], ["110962.25000000", "0.00044000"], ["110961.34000000", "0.00000000"], ["110961.33000000", "0.00000000"], ["110961.30000000", "1.44342000"], ["110959.11000000", "0.04573000"], ["110956.49000000", "0.04504000"], ["110956.47000000", "0.00007000"], ["110954.17000000", "0.00000000"], ["110953.73000000", "0.04000000"], ["110950.61000000", "0.00576000"], ["110950.38000000", "0.00000000"], ["110948.73000000", "0.00000000"], ["110945.42000000", "0.32444000"], ["110945.36000000", "0.04515000"], ["110943.33000000", "0.00000000"], ["110942.30000000", "0.00000000"], ["110941.18000000", "0.00000000"], ["110940.15000000", "0.00000000"], ["110935.05000000", "0.00000000"], ["110928.68000000", "0.00000000"], ["110921.49000000", "0.00000000"], ["110912.96000000", "0.13524000"], ["110911.87000000", "0.13511000"], ["110904.77000000", "0.00000000"], ["110899.63000000", "0.00000000"], ["110899.27000000", "0.02536000"], ["110887.51000000", "0.00000000"], ["110886.24000000", "0.00000000"], ["110885.88000000", "0.00000000"], ["110885.71000000", "0.18027000"], ["110885.44000000", "0.90171000"], ["110881.75000000", "0.00000000"], ["110879.26000000", "0.00000000"], ["110877.06000000", "0.00000000"], ["110707.11000000", "0.00000000"], ["110648.85000000", "0.00000000"], ["110592.50000000", "0.03798000"], ["110591.32000000", "0.03798000"], ["110467.48000000", "0.00000000"], ["110466.63000000", "0.00000000"]], "a": [["110978.66000000", "0.06077000"], ["110978.67000000", "0.00090000"], ["110979.00000000", "0.00000000"], ["110981.66000000", "0.00025000"], ["110981.67000000", "0.00010000"], ["110983.70000000", "0.00010000"], ["110984.78000000", "0.00000000"], ["110984.86000000", "0.00005000"], ["110985.89000000", "0.00005000"], ["110986.68000000", "0.00000000"], ["110986.98000000", "0.00000000"], ["110987.24000000", "0.00005000"], ["110987.80000000", "0.00005000"], ["110988.15000000", "0.00000000"], ["110988.16000000", "0.00000000"], ["110988.38000000", "0.00000000"], ["110988.45000000", "0.00000000"], ["110988.99000000", "0.00000000"], ["110989.66000000", "0.00000000"], ["110989.75000000", "0.02721000"], ["110990.35000000", "0.00000000"], ["110990.66000000", "0.04548000"], ["110991.62000000", "0.00000000"], ["110991.65000000", "0.00000000"], ["110991.81000000", "0.00070000"], ["110991.85000000", "0.00000000"], ["110992.54000000", "0.04508000"], ["110994.59000000", "0.00000000"], ["110994.75000000", "0.24000000"], ["110995.50000000", "0.00010000"], ["110995.59000000", "0.04000000"], ["110996.13000000", "0.00000000"], ["110996.43000000", "0.00000000"], ["110997.82000000", "0.00000000"], ["110998.46000000", "0.00000000"], ["110998.49000000", "0.00000000"], ["111000.05000000", "0.00000000"], ["111000.84000000", "0.01802000"], ["111000.85000000", "0.00000000"], ["111001.77000000", "0.02704000"], ["111003.62000000", "0.00455000"], ["111004.51000000", "0.13524000"], ["111005.99000000", "0.00000000"], ["111008.36000000", "0.00005000"], ["111008.88000000", "0.00250000"], ["111008.93000000", "0.00000000"], ["111011.09000000", "0.13511000"], ["111011.94000000", "0.00000000"], ["111011.95000000", "0.06432000"], ["111012.07000000", "0.27041000"], ["111013.02000000", "0.00000000"], ["111017.17000000", "0.04504000"], ["111017.57000000", "0.00000000"], ["111019.72000000", "0.00000000"], ["111020.46000000", "0.00000000"], ["111021.86000000", "0.00000000"], ["111022.39000000", "0.00000000"], ["111023.06000000", "0.00000000"], ["111023.32000000", "0.00000000"], ["111024.21000000", "0.06906000"], ["111024.74000000", "0.00000000"], ["111037.50000000", "0.00000000"], ["111038.17000000", "0.24524000"], ["111045.27000000", "0.00000000"], ["111045.33000000", "0.29805000"], ["111045.70000000", "0.00000000"], ["111046.87000000", "0.00048000"], ["111046.88000000", "0.00000000"], ["111047.03000000", "0.32414000"], ["111049.70000000", "0.00000000"], ["111051.02000000", "0.02572000"], ["111057.70000000", "0.00000000"], ["111058.20000000", "0.00000000"], ["111061.50000000", "0.00005000"], ["111064.37000000", "0.13533000"], ["111083.77000000", "0.22535000"], ["111084.48000000", "0.22544000"], ["111099.05000000", "1.48954000"], ["111114.54000000", "0.00000000"], ["111125.70000000", "0.00000000"], ["111128.64000000", "0.00000000"], ["111155.40000000", "0.00000000"], ["111158.27000000", "0.00019000"], ["111158.28000000", "0.00000000"], ["111170.09000000", "0.00000000"], ["111177.60000000", "0.02705000"], ["111225.65000000", "0.00000000"], ["111458.12000000", "0.00000000"], ["111540.83000000", "0.03798000"]]}}
{"type": "orderbook", "local_time": 1761342415044, "event_time": 1761342414914, "latency_ms": 130, "data": {"e": "depthUpdate", "E": 1761342414914, "s": "BTCUSDT", "U": 79012717412, "u": 79012717885, "b": [["110985.30000000", "3.62762000"], ["110984.85000000", "0.00000000"], ["110984.84000000", "0.00000000"], ["110984.55000000", "1.79118000"], ["110984.54000000", "0.08467000"], ["110984.53000000", "0.00000000"], ["110984.03000000", "0.29730000"], ["110983.69000000", "0.00000000"], ["110983.08000000", "0.00000000"], ["110982.33000000", "0.00000000"], ["110982.09000000", "0.21476000"], ["110981.74000000", "0.00044000"], ["110981.66000000", "0.00000000"], ["110981.65000000", "0.00000000"], ["110981.42000000", "0.00000000"], ["110980.96000000", "0.00005000"], ["110980.00000000", "0.00010000"], ["110979.75000000", "0.00000000"], ["110979.59000000", "0.04536000"], ["110979.35000000", "0.00000000"], ["110978.66000000", "0.00000000"], ["110978.65000000", "1.29130000"], ["110978.64000000", "0.00515000"], ["110978.47000000", "0.00044000"], ["110977.89000000", "0.00510000"], ["110977.80000000", "0.00250000"], ["110977.55000000", "0.00104000"], ["110977.49000000", "0.15310000"], ["110977.48000000", "0.00010000"], ["110977.22000000", "0.00005000"], ["110976.28000000", "0.05096000"], ["110976.14000000", "0.00000000"], ["110975.73000000", "0.00000000"], ["110974.20000000", "0.00029000"], ["110971.16000000", "0.01802000"], ["110970.87000000", "0.08067000"], ["110970.54000000", "0.00044000"], ["110970.04000000", "0.04503000"], ["110970.03000000", "0.84688000"], ["110969.99000000", "0.00010000"], ["110968.65000000", "0.00150000"], ["110968.43000000", "0.00000000"], ["110967.90000000", "0.00090000"], ["110965.72000000", "0.20290000"], ["110965.71000000", "0.00000000"], ["110964.49000000", "0.00258000"], ["110964.22000000", "0.00000000"], ["110962.66000000", "0.00044000"], ["110962.25000000", "0.00088000"], ["110962.00000000", "0.00000000"], ["110960.12000000", "0.00022000"], ["110959.12000000", "0.05078000"], ["110956.49000000", "0.00000000"], ["110956.48000000", "0.00000000"], ["110955.60000000", "0.00000000"], ["110954.18000000", "0.00000000"], ["110953.35000000", "0.00000000"], ["110950.13000000", "0.00009000"], ["110949.20000000", "0.00000000"], ["110947.99000000", "0.00009000"], ["110946.95000000", "0.00009000"], ["110945.04000000", "0.22010000"], ["110941.86000000", "0.00009000"], ["110940.69000000", "0.00044000"], ["110940.01000000", "0.00000000"], ["110938.39000000", "0.00000000"], ["110938.28000000", "0.00000000"], ["110937.35000000", "0.00000000"], ["110935.48000000", "0.00009000"], ["110934.60000000", "0.00090000"], ["110933.67000000", "0.00000000"], ["110930.65000000", "0.00000000"], ["110928.72000000", "0.00000000"], ["110926.16000000", "0.00000000"], ["110919.19000000", "0.00000000"], ["110916.08000000", "0.00044000"], ["110915.60000000", "0.00000000"], ["110915.06000000", "0.00000000"], ["110908.63000000", "0.00624000"], ["110894.31000000", "0.00090000"], ["110893.18000000", "0.00000000"], ["110892.41000000", "0.00000000"], ["110891.58000000", "0.22544000"], ["110891.23000000", "0.22535000"], ["110889.89000000", "0.13511000"], ["110881.00000000", "0.00224000"], ["110874.02000000", "0.00000000"], ["110864.87000000", "0.00000000"], ["110857.67000000", "0.00191000"], ["110851.62000000", "0.00000000"], ["110838.70000000", "0.06000000"], ["109313.97000000", "0.00000000"], ["99880.00000000", "1.67445000"]], "a": [["110978.66000000", "0.00000000"], ["110978.67000000", "0.00000000"], ["110979.76000000", "0.00000000"], ["110980.00000000", "0.00000000"], ["110980.96000000", "0.00000000"], ["110981.43000000", "0.00000000"], ["110981.65000000", "0.00000000"], ["110981.66000000", "0.00000000"], ["110981.67000000", "0.00000000"], ["110981.96000000", "0.00000000"], ["110982.30000000", "0.00000000"], ["110982.34000000", "0.00000000"], ["110982.82000000", "0.00000000"], ["110983.09000000", "0.00000000"], ["110983.69000000", "0.00000000"], ["110983.70000000", "0.00000000"], ["110984.50000000", "0.00000000"], ["110984.54000000", "0.00000000"], ["110984.55000000", "0.00000000"], ["110984.85000000", "0.00000000"], ["110984.86000000", "0.00000000"], ["110985.31000000", "0.01226000"], ["110985.32000000", "0.00065000"], ["110985.84000000", "0.00000000"], ["110985.89000000", "0.00000000"], ["110987.24000000", "0.00000000"], ["110987.79000000", "0.00000000"], ["110987.80000000", "0.00000000"], ["110988.14000000", "0.00000000"], ["110988.15000000", "0.00000000"], ["110988.53000000", "0.06066000"], ["110988.54000000", "0.00010000"], ["110989.24000000", "0.00010000"], ["110989.25000000", "0.04010000"], ["110989.74000000", "0.00010000"], ["110989.75000000", "0.02731000"], ["110990.00000000", "0.00005000"], ["110990.13000000", "0.29728000"], ["110990.26000000", "0.00010000"], ["110990.27000000", "0.00010000"], ["110990.58000000", "0.00005000"], ["110990.59000000", "0.11971000"], ["110990.66000000", "0.00005000"], ["110990.81000000", "0.00005000"], ["110991.62000000", "0.04998000"], ["110991.81000000", "0.00000000"], ["110991.88000000", "0.20287000"], ["110992.54000000", "0.00005000"], ["110993.01000000", "0.00000000"], ["110993.09000000", "0.00000000"], ["110993.43000000", "0.00000000"], ["110993.52000000", "0.00720000"], ["110993.53000000", "0.20756000"], ["110994.87000000", "0.01842000"], ["110996.41000000", "0.04508000"], ["110996.62000000", "0.04548000"], ["110999.39000000", "0.00325000"], ["110999.74000000", "0.10306000"], ["111000.84000000", "0.00000000"], ["111001.19000000", "0.00090000"], ["111001.20000000", "0.00150000"], ["111002.79000000", "0.01802000"], ["111003.62000000", "0.00005000"], ["111006.00000000", "0.69046000"], ["111006.13000000", "0.01036000"], ["111009.99000000", "0.00450000"], ["111012.07000000", "0.00000000"], ["111017.16000000", "0.27041000"], ["111017.17000000", "0.00000000"], ["111017.50000000", "0.00005000"], ["111018.00000000", "0.34715000"], ["111019.76000000", "0.00000000"], ["111022.69000000", "0.04503000"], ["111024.21000000", "0.00000000"], ["111025.32000000", "0.06653000"], ["111025.99000000", "0.00016000"], ["111028.84000000", "0.00039000"], ["111030.27000000", "0.00033000"], ["111033.99000000", "0.00000000"], ["111034.07000000", "0.17647000"], ["111034.49000000", "0.00090000"], ["111035.76000000", "0.00005000"], ["111036.49000000", "0.00000000"], ["111037.64000000", "0.00016000"], ["111039.96000000", "0.00224000"], ["111046.87000000", "0.00000000"], ["111052.62000000", "0.00048000"], ["111052.94000000", "0.00623000"], ["111061.48000000", "0.00000000"], ["111066.58000000", "0.00225000"], ["111070.51000000", "0.00000000"], ["111074.51000000", "0.00000000"], ["111075.07000000", "0.00000000"], ["111075.08000000", "0.00000000"], ["111075.51000000", "0.03406000"], ["111078.07000000", "0.00000000"], ["111078.08000000", "0.00000000"], ["111095.12000000", "1.09595000"], ["111098.55000000", "0.00017000"], ["111145.27000000", "0.00000000"], ["111152.07000000", "0.00090000"], ["111432.37000000", "0.36406000"], ["112643.34000000", "0.00000000"]]}}
{"type": "orderbook", "local_time": 1761342415057, "event_time": 1761342415014, "latency_ms": 43, "data": {"e": "depthUpdate", "E": 1761342415014, "s": "BTCUSDT", "U": 79012717886, "u": 79012718041, "b": [["110985.30000000", "3.62797000"], ["110984.56000000", "1.09062000"], ["110984.55000000", "0.00030000"], ["110984.54000000", "0.08482000"], ["110984.03000000", "0.29745000"], ["110982.09000000", "0.21486000"], ["110979.59000000", "0.04541000"], ["110978.65000000", "1.29105000"], ["110978.64000000", "0.00505000"], ["110977.89000000", "0.00500000"], ["110977.55000000", "0.00099000"], ["110977.49000000", "0.03926000"], ["110977.48000000", "0.00000000"], ["110977.22000000", "0.00000000"], ["110976.28000000", "0.05091000"], ["110969.31000000", "0.00044000"], ["110968.90000000", "0.00044000"], ["110968.69000000", "0.00089000"], ["110962.66000000", "0.00000000"], ["110962.25000000", "0.00000000"], ["110959.12000000", "0.00000000"], ["110958.64000000", "0.03600000"], ["110954.22000000", "0.00900000"], ["110951.47000000", "0.00000000"], ["110947.30000000", "0.00000000"], ["110942.01000000", "0.11192000"], ["110938.49000000", "0.00000000"], ["110935.67000000", "0.17663000"], ["110919.73000000", "0.00000000"], ["110916.08000000", "0.00000000"], ["99880.00000000", "1.67425000"]], "a": [["110985.31000000", "0.01226000"], ["110985.32000000", "0.00070000"], ["110986.61000000", "0.00320000"], ["110986.65000000", "0.00160000"], ["110988.09000000", "0.00401000"], ["110988.52000000", "0.01825000"], ["110988.53000000", "0.00010000"], ["110988.54000000", "0.00000000"], ["110989.75000000", "0.02731000"], ["110990.12000000", "0.22935000"], ["110990.13000000", "0.29738000"], ["110990.26000000", "0.00000000"], ["110990.27000000", "0.00000000"], ["110990.59000000", "0.00005000"], ["110990.66000000", "0.00000000"], ["110990.81000000", "0.00000000"], ["110991.62000000", "0.05003000"], ["110991.88000000", "0.20287000"], ["110992.54000000", "0.00000000"], ["110993.52000000", "0.00725000"], ["110993.53000000", "0.20761000"], ["110993.73000000", "0.04548000"], ["110996.62000000", "0.00000000"], ["111001.77000000", "0.00000000"], ["111003.95000000", "0.01226000"], ["111007.93000000", "0.00000000"], ["111012.02000000", "0.00900000"], ["111025.32000000", "0.00000000"], ["111025.75000000", "0.00000000"], ["111025.89000000", "0.06809000"], ["111033.32000000", "0.00000000"], ["111076.74000000", "0.01411000"], ["111100.00000000", "13.28472000"], ["111105.34000000", "0.00900000"], ["111122.65000000", "0.01874000"], ["111178.21000000", "0.01874000"], ["111233.77000000", "0.01874000"], ["111432.37000000", "0.00000000"]]}}
{"type": "orderbook", "local_time": 1761342415057, "event_time": 1761342415114, "latency_ms": -57, "data": {"e": "depthUpdate", "E": 1761342415114, "s": "BTCUSDT", "U": 79012718042, "u": 79012718125, "b": [["110985.30000000", "3.62807000"], ["110984.56000000", "0.55620000"], ["110984.03000000", "0.29740000"], ["110982.09000000", "0.21481000"], ["110981.74000000", "0.00000000"], ["110978.65000000", "1.27261000"], ["110978.47000000", "0.00000000"], ["110975.70000000", "0.00005000"], ["110970.54000000", "0.00000000"], ["110970.05000000", "0.20282000"], ["110969.31000000", "0.00000000"], ["110965.70000000", "0.49176000"], ["110963.10000000", "0.00300000"], ["110956.46000000", "0.04505000"], ["110951.26000000", "0.00000000"], ["110950.61000000", "0.00000000"], ["110940.69000000", "0.00000000"], ["110827.39000000", "0.00000000"], ["109599.87000000", "0.02504000"], ["109320.52000000", "0.00100000"]], "a": [["110985.31000000", "0.10414000"], ["110985.32000000", "0.00070000"], ["110986.61000000", "0.00020000"], ["110988.09000000", "0.00401000"], ["110988.51000000", "0.00010000"], ["110988.52000000", "0.00010000"], ["110988.53000000", "0.00000000"], ["110989.74000000", "0.00010000"], ["110989.75000000", "0.02731000"], ["110990.11000000", "0.00010000"], ["110990.12000000", "0.22945000"], ["110990.13000000", "0.29733000"], ["110990.58000000", "0.00000000"], ["110990.59000000", "0.00000000"], ["110993.53000000", "0.20761000"], ["111006.92000000", "0.03000000"], ["111018.61000000", "0.00300000"], ["111027.74000000", "0.00000000"], ["111076.74000000", "0.00000000"], ["111091.95000000", "0.01411000"], ["111102.44000000", "0.00005000"], ["111106.25000000", "0.00005000"], ["111118.88000000", "0.03000000"], ["111131.35000000", "0.13508000"], ["112650.09000000", "0.00100000"]]}}
{"type": "orderbook", "local_time": 1761342415180, "event_time": 1761342415214, "latency_ms": -34, "data": {"e": "depthUpdate", "E": 1761342415214, "s": "BTCUSDT", "U": 79012718126, "u": 79012718156, "b": [["110957.41000000", "0.00576000"], ["110948.85000000", "0.04383000"]], "a": [["110985.31000000", "0.10404000"], ["110985.32000000", "0.00060000"], ["110986.61000000", "0.00000000"], ["110986.65000000", "0.00170000"], ["110988.09000000", "0.00406000"], ["110988.51000000", "0.00000000"], ["110988.52000000", "0.00000000"], ["110989.25000000", "0.04015000"], ["110990.13000000", "0.29738000"], ["110991.61000000", "0.00005000"], ["110993.73000000", "0.04553000"]]}}
{"type": "orderbook", "local_time": 1761342415416, "event_time": 1761342415314, "latency_ms": 102, "data": {"e": "depthUpdate", "E": 1761342415314, "s": "BTCUSDT", "U": 79012718157, "u": 79012718167, "b": [["110977.81000000", "0.01843000"]], "a": [["110985.31000000", "0.10409000"], ["110985.32000000", "0.00065000"], ["111002.79000000", "0.00000000"], ["111002.85000000", "0.00000000"], ["111003.02000000", "0.24346000"], ["111091.95000000", "0.00000000"], ["111118.88000000", "0.00000000"], ["111375.12000000", "0.00000000"]]}}
{"type": "orderbook", "local_time": 1761342415417, "event_time": 1761342415414, "latency_ms": 3, "data": {"e": "depthUpdate", "E": 1761342415414, "s": "BTCUSDT", "U": 79012718168, "u": 79012718191, "b": [["110985.30000000", "3.03963000"], ["110984.57000000", "0.00010000"], ["110984.55000000", "0.00040000"], ["110984.04000000", "0.00010000"], ["110982.10000000", "0.00010000"], ["110979.59000000", "0.00005000"], ["110978.66000000", "0.00005000"], ["110977.81000000", "0.00000000"], ["110975.05000000", "0.04536000"], ["110970.04000000", "0.00000000"], ["110961.32000000", "0.04504000"], ["110889.99000000", "0.07429000"]], "a": [["110985.31000000", "1.16331000"], ["110989.92000000", "0.04548000"], ["110993.73000000", "0.00005000"], ["111003.02000000", "0.22544000"], ["111003.19000000", "0.01802000"], ["111036.00000000", "0.04554000"], ["111080.58000000", "0.00100000"], ["111080.59000000", "0.00100000"]]}}
{"type": "orderbook", "local_time": 1761342415437, "event_time": 1761342415515, "latency_ms": -78, "data": {"e": "depthUpdate", "E": 1761342415515, "s": "BTCUSDT", "U": 79012718192, "u": 79012718215, "b": [["110985.30000000", "3.03989000"], ["110984.56000000", "0.55625000"], ["110982.09000000", "0.21476000"], ["110979.59000000", "0.00000000"], ["110978.65000000", "1.27246000"]], "a": [["110985.31000000", "1.16336000"], ["110985.32000000", "0.00070000"], ["110989.75000000", "0.02731000"], ["110989.91000000", "0.00010000"], ["110989.92000000", "0.04558000"], ["110990.13000000", "0.29733000"], ["110991.61000000", "0.00000000"], ["110993.53000000", "0.20761000"], ["110993.73000000", "0.00000000"]]}}
{"type": "orderbook", "local_time": 1761342415572, "event_time": 1761342415614, "latency_ms": -42, "data": {"e": "depthUpdate", "E": 1761342415614, "s": "BTCUSDT", "U": 79012718216, "u": 79012718225, "b": [["110985.30000000", "3.04003000"], ["110972.00000000", "0.00612000"], ["110968.69000000", "0.00044000"], ["110965.80000000", "0.00005000"], ["110965.72000000", "0.20282000"]], "a": [["111075.51000000", "0.00006000"], ["111075.56000000", "0.03400000"], ["111080.58000000", "0.00000000"], ["111080.59000000", "0.00000000"], ["111312.59000000", "0.36445000"]]}}
{"type": "orderbook", "local_time": 1761342415774, "event_time": 1761342415714, "latency_ms": 60, "data": {"e": "depthUpdate", "E": 1761342415714, "s": "BTCUSDT", "U": 79012718226, "u": 79012718255, "b": [["110985.30000000", "3.03973000"], ["110984.56000000", "0.55630000"], ["110984.55000000", "0.00030000"], ["110984.54000000", "0.08457000"], ["110984.03000000", "0.29745000"], ["110982.09000000", "0.21486000"], ["110978.65000000", "0.58726000"], ["110977.89000000", "0.00505000"], ["110977.49000000", "0.03931000"], ["110976.28000000", "0.05096000"], ["110959.91000000", "0.03600000"], ["99886.00000000", "0.00775000"], ["99880.00000000", "1.67415000"]], "a": [["110985.31000000", "1.16272000"], ["111312.59000000", "0.00000000"]]}}
{"type": "orderbook", "local_time": 1761342415774, "event_time": 1761342415814, "latency_ms": -40, "data": {"e": "depthUpdate", "E": 1761342415814, "s": "BTCUSDT", "U": 79012718256, "u": 79012718262, "b": [["110984.56000000", "0.35774000"], ["110977.90000000", "0.04536000"], ["110975.05000000", "0.00000000"], ["110959.12000000", "0.06250000"]], "a": [["110989.92000000", "0.00010000"], ["110993.47000000", "0.04548000"]]}}
{"type": "orderbook", "local_time": 1761342415859, "event_time": 1761342415914, "latency_ms": -55, "data": {"e": "depthUpdate", "E": 1761342415914, "s": "BTCUSDT", "U": 79012718263, "u": 79012718286, "b": [["110978.64000000", "0.00505000"], ["110977.90000000", "0.04541000"], ["110976.28000000", "0.05091000"], ["110952.67000000", "0.00000000"], ["110945.36000000", "0.00009000"], ["88783.00000000", "0.00200000"]], "a": [["110985.31000000", "1.16272000"], ["110985.32000000", "0.00065000"], ["110989.75000000", "0.02731000"], ["110989.91000000", "0.00000000"], ["110989.92000000", "0.00000000"], ["110990.13000000", "0.29738000"], ["110991.61000000", "0.00005000"], ["110991.88000000", "0.20287000"], ["110993.47000000", "0.04553000"], ["111011.95000000", "0.01925000"]]}}
{"type": "orderbook", "local_time": 1761342415957, "event_time": 1761342416014, "latency_ms": -57, "data": {"e": "depthUpdate", "E": 1761342416014, "s": "BTCUSDT", "U": 79012718287, "u": 79012718292, "b": [["110953.62000000", "0.13606000"], ["99886.00000000", "0.00795000"], ["88783.00000000", "0.00000000"]], "a": [["111003.01000000", "0.00450000"], ["111009.99000000", "0.00000000"], ["111325.18000000", "0.00000000"], ["111332.47000000", "0.48717000"]]}}
{"type": "orderbook", "local_time": 1761342426735, "event_time": 1761342416114, "latency_ms": 10621, "data": {"e": "depthUpdate", "E": 1761342416114, "s": "BTCUSDT", "U": 79012718293, "u": 79012718303, "b": [["110970.32000000", "0.11272000"], ["110968.69000000", "0.00000000"], ["110966.43000000", "0.00005000"], ["109320.52000000", "0.00100000"], ["99886.00000000", "0.00775000"]], "a": [["111058.20000000", "0.00005000"], ["111228.00000000", "0.00000000"], ["112650.09000000", "0.00100000"]]}}
{"type": "orderbook", "local_time": 1761342426736, "event_time": 1761342416215, "latency_ms": 10521, "data": {"e": "depthUpdate", "E": 1761342416215, "s": "BTCUSDT", "U": 79012718304, "u": 79012718305, "b": [["110971.16000000", "0.01810000"]], "a": [["111080.80000000", "0.00100000"]]}}
{"type": "orderbook", "local_time": 1761342426736, "event_time": 1761342416314, "latency_ms": 10422, "data": {"e": "depthUpdate", "E": 1761342416314, "s": "BTCUSDT", "U": 79012718306, "u": 79012718307, "b": [["110985.30000000", "3.03957000"]], "a": [["111080.79000000", "0.00100000"]]}}
{"type": "orderbook", "local_time": 1761342426737, "event_time": 1761342416414, "latency_ms": 10323, "data": {"e": "depthUpdate", "E": 1761342416414, "s": "BTCUSDT", "U": 79012718308, "u": 79012718311, "b": [["110985.30000000", "3.03971000"], ["110972.40000000", "0.00005000"], ["110762.58000000", "0.02498000"]], "a": [["111169.51000000", "0.36492000"]]}}
{"type": "orderbook", "local_time": 1761342426738, "event_time": 1761342416516, "latency_ms": 10222, "data": {"e": "depthUpdate", "E": 1761342416516, "s": "BTCUSDT", "U": 79012718312, "u": 79012718316, "b": [["110977.81000000", "0.00000000"], ["110972.00000000", "0.00541000"], ["110971.16000000", "0.01802000"]], "a": [["111111.78000000", "0.00000000"]]}}
{"type": "orderbook", "local_time": 1761342426739, "event_time": 1761342416614, "latency_ms": 10125, "data": {"e": "depthUpdate", "E": 1761342416614, "s": "BTCUSDT", "U": 79012718317, "u": 79012718317, "b": [["110972.40000000", "0.00084000"]], "a": []}}
{"type": "orderbook", "local_time": 1761342426739, "event_time": 1761342416714, "latency_ms": 10025, "data": {"e": "depthUpdate", "E": 1761342416714, "s": "BTCUSDT", "U": 79012718318, "u": 79012718318, "b": [["33000.00000000", "3.79505000"]], "a": []}}
{"type": "orderbook", "local_time": 1761342426739, "event_time": 1761342416814, "latency_ms": 9925, "data": {"e": "depthUpdate", "E": 1761342416814, "s": "BTCUSDT", "U": 79012718319, "u": 79012718346, "b": [["110985.30000000", "3.03731000"], ["110984.20000000", "0.00099000"], ["110982.53000000", "0.00198000"], ["110982.09000000", "0.20766000"], ["110980.93000000", "0.04536000"], ["110980.87000000", "0.00360000"], ["110980.47000000", "0.00720000"], ["110978.65000000", "0.59267000"], ["110977.90000000", "0.00005000"], ["110977.55000000", "0.00000000"], ["110972.00000000", "0.00000000"], ["110969.22000000", "0.00000000"], ["110967.56000000", "0.00000000"], ["110957.41000000", "0.00000000"], ["99886.00000000", "0.00775000"], ["33000.00000000", "3.79445000"]], "a": [["110985.31000000", "1.16267000"], ["110991.96000000", "0.00541000"], ["110993.52000000", "0.00005000"], ["110993.53000000", "0.00005000"], ["110994.74000000", "0.00396000"], ["111003.19000000", "0.00000000"], ["111169.51000000", "0.00000000"]]}}
{"type": "orderbook", "local_time": 1761342427132, "event_time": 1761342416914, "latency_ms": 10218, "data": {"e": "depthUpdate", "E": 1761342416914, "s": "BTCUSDT", "U": 79012718347, "u": 79012718375, "b": [["110985.30000000", "3.03736000"], ["110984.54000000", "0.08457000"], ["110984.20000000", "0.00104000"], ["110984.03000000", "0.29740000"], ["110982.09000000", "0.20766000"], ["110980.93000000", "0.04541000"], ["110980.47000000", "0.00725000"], ["110978.64000000", "0.00505000"], ["110977.90000000", "0.00000000"], ["110977.49000000", "0.03926000"], ["110966.08000000", "0.04000000"], ["110957.10000000", "0.00576000"], ["110951.45000000", "0.00000000"]], "a": [["110985.31000000", "1.15790000"], ["110991.88000000", "0.20287000"], ["110991.96000000", "0.00546000"], ["110993.47000000", "0.04553000"], ["110993.52000000", "0.00000000"], ["110993.53000000", "0.00000000"], ["110994.75000000", "0.24005000"], ["110994.87000000", "0.00000000"], ["110996.40000000", "0.00721000"]]}}
{"type": "orderbook", "local_time": 1761342427133, "event_time": 1761342417014, "latency_ms": 10119, "data": {"e": "depthUpdate", "E": 1761342417014, "s": "BTCUSDT", "U": 79012718376, "u": 79012718388, "b": [["110985.30000000", "3.03729000"], ["110980.93000000", "0.00005000"], ["110966.08000000", "0.00000000"], ["110963.57000000", "0.04000000"]], "a": [["110992.56000000", "0.21476000"], ["110994.75000000", "0.24005000"], ["111001.44000000", "0.00000000"], ["111002.85000000", "0.01802000"], ["111003.95000000", "0.00000000"]]}}
{"type": "orderbook", "local_time": 1761342427133, "event_time": 1761342417114, "latency_ms": 10019, "data": {"e": "depthUpdate", "E": 1761342417114, "s": "BTCUSDT", "U": 79012718389, "u": 79012718418, "b": [["110985.30000000", "3.03932000"], ["110982.09000000", "0.20766000"], ["110980.93000000", "0.00000000"], ["110977.95000000", "0.04536000"], ["110977.81000000", "0.01796000"], ["110977.49000000", "0.03931000"], ["110974.20000000", "0.00034000"], ["110958.66000000", "0.00005000"], ["110957.10000000", "0.00000000"], ["110945.66000000", "0.00000000"], ["109320.52000000", "0.00100000"], ["99886.00000000", "0.00775000"]], "a": [["110991.96000000", "0.00546000"], ["110992.56000000", "0.21481000"], ["110994.75000000", "0.24000000"], ["110994.97000000", "0.01802000"], ["111075.56000000", "0.00000000"], ["111075.61000000", "0.03400000"], ["111080.79000000", "0.00000000"], ["111080.80000000", "0.00000000"], ["111081.58000000", "0.00100000"], ["111081.59000000", "0.00100000"], ["112650.09000000", "0.00100000"]]}}
{"type": "orderbook", "local_time": 1761342427134, "event_time": 1761342417215, "latency_ms": 9919, "data": {"e": "depthUpdate", "E": 1761342417215, "s": "BTCUSDT", "U": 79012718419, "u": 79012718427, "b": [["110978.64000000", "0.00505000"], ["110977.95000000", "0.04541000"], ["110977.89000000", "0.00505000"], ["110977.49000000", "0.03926000"], ["110957.84000000", "0.02000000"], ["110957.23000000", "0.00576000"], ["110946.70000000", "0.00000000"]], "a": []}}
{"type": "orderbook", "local_time": 1761342427134, "event_time": 1761342417314, "latency_ms": 9820, "data": {"e": "depthUpdate", "E": 1761342417314, "s": "BTCUSDT", "U": 79012718428, "u": 79012718430, "b": [["110973.70000000", "0.02704000"], ["110971.16000000", "0.01809000"]], "a": [["111004.96000000", "0.02704000"]]}}
{"type": "orderbook", "local_time": 1761342427135, "event_time": 1761342417414, "latency_ms": 9721, "data": {"e": "depthUpdate", "E": 1761342417414, "s": "BTCUSDT", "U": 79012718431, "u": 79012718433, "b": [["102097.47000000", "0.00010000"]], "a": [["111002.10000000", "0.00005000"], ["111014.04000000", "0.36543000"]]}}
{"type": "orderbook", "local_time": 1761342427135, "event_time": 1761342417514, "latency_ms": 9621, "data": {"e": "depthUpdate", "E": 1761342417514, "s": "BTCUSDT", "U": 79012718434, "u": 79012718434, "b": [["110971.38000000", "0.00324000"]], "a": []}}
{"type": "orderbook", "local_time": 1761342427136, "event_time": 1761342417614, "latency_ms": 9522, "data": {"e": "depthUpdate", "E": 1761342417614, "s": "BTCUSDT", "U": 79012718435, "u": 79012718436, "b": [["110971.38000000", "0.00331000"], ["110971.16000000", "0.01802000"]], "a": []}}
{"type": "orderbook", "local_time": 1761342427136, "event_time": 1761342417714, "latency_ms": 9422, "data": {"e": "depthUpdate", "E": 1761342417714, "s": "BTCUSDT", "U": 79012718437, "u": 79012718441, "b": [["110985.30000000", "3.72422000"], ["110972.14000000", "0.00072000"], ["110957.23000000", "0.00000000"], ["110948.85000000", "0.00000000"], ["110944.64000000", "0.04379000"]], "a": []}}
{"type": "orderbook", "local_time": 1761342427137, "event_time": 1761342417814, "latency_ms": 9323, "data": {"e": "depthUpdate", "E": 1761342417814, "s": "BTCUSDT", "U": 79012718442, "u": 79012718478, "b": [["110985.30000000", "3.03997000"], ["110985.29000000", "0.00070000"], ["110972.14000000", "0.00083000"], ["110971.38000000", "0.00324000"], ["110962.50000000", "0.00010000"], ["110957.58000000", "0.00576000"], ["99886.00000000", "0.00775000"]], "a": [["110985.31000000", "1.15784000"]]}}
{"type": "orderbook", "local_time": 1761342427138, "event_time": 1761342417914, "latency_ms": 9224, "data": {"e": "depthUpdate", "E": 1761342417914, "s": "BTCUSDT", "U": 79012718479, "u": 79012718496, "b": [["110985.30000000", "3.04002000"], ["110985.29000000", "0.00090000"], ["110984.55000000", "0.00020000"], ["110984.54000000", "0.08452000"], ["110984.20000000", "0.00099000"], ["110971.16000000", "0.00000000"], ["110971.12000000", "0.13238000"], ["102701.69000000", "0.01708000"], ["102688.64000000", "0.00000000"], ["102097.47000000", "0.00000000"]], "a": [["110985.31000000", "1.15765000"], ["111328.82000000", "0.48717000"], ["111332.47000000", "0.00000000"]]}}
{"type": "orderbook", "local_time": 1761342427138, "event_time": 1761342418014, "latency_ms": 9124, "data": {"e": "depthUpdate", "E": 1761342418014, "s": "BTCUSDT", "U": 79012718497, "u": 79012718508, "b": [["110984.56000000", "0.35774000"], ["110984.55000000", "0.00010000"], ["110984.54000000", "0.08457000"], ["110984.20000000", "0.00104000"], ["110971.12000000", "0.11436000"], ["110971.09000000", "0.01802000"]], "a": [["110985.31000000", "1.15765000"]]}}
{"type": "orderbook", "local_time": 1761342427840, "event_time": 1761342418114, "latency_ms": 9726, "data": {"e": "depthUpdate", "E": 1761342418114, "s": "BTCUSDT", "U": 79012718509, "u": 79012718700, "b": [["110985.30000000", "3.77764000"], ["110985.29000000", "0.00020000"], ["110984.82000000", "0.00720000"], ["110984.57000000", "0.00000000"], ["110984.56000000", "0.36274000"], ["110984.55000000", "0.00000000"], ["110984.24000000", "0.04704000"], ["110984.20000000", "0.00604000"], ["110984.19000000", "0.06748000"], ["110984.04000000", "0.00000000"], ["110982.24000000", "0.00250000"], ["110982.10000000", "0.00000000"], ["110981.34000000", "0.00000000"], ["110980.88000000", "0.00450000"], ["110980.47000000", "0.00005000"], ["110979.75000000", "0.00036000"], ["110978.66000000", "0.00000000"], ["110978.64000000", "0.00005000"], ["110977.95000000", "0.00005000"], ["110977.89000000", "0.00005000"], ["110976.29000000", "0.30399000"], ["110976.28000000", "0.00000000"], ["110974.12000000", "0.01802000"], ["110973.37000000", "0.00000000"], ["110972.14000000", "0.00011000"], ["110971.72000000", "0.00000000"], ["110971.38000000", "0.00000000"], ["110971.09000000", "0.00000000"], ["110971.05000000", "0.00000000"], ["110968.51000000", "0.36035000"], ["110968.00000000", "0.00005000"], ["110960.04000000", "0.00000000"], ["110955.68000000", "0.07656000"], ["110950.13000000", "0.00000000"], ["110947.99000000", "0.00000000"], ["110946.95000000", "0.00000000"], ["110941.86000000", "0.00000000"], ["110935.48000000", "0.00000000"], ["110928.98000000", "0.00040000"], ["110894.31000000", "0.00000000"], ["110878.84000000", "0.02429000"], ["110877.39000000", "0.04002000"], ["110871.70000000", "0.04598000"], ["110857.66000000", "0.00000000"], ["110857.29000000", "0.00000000"], ["110856.30000000", "0.00000000"], ["110853.42000000", "0.00000000"], ["110832.43000000", "0.02613000"], ["110807.54000000", "0.00000000"], ["110715.19000000", "0.00000000"], ["110589.47000000", "0.03798000"], ["110468.33000000", "0.00000000"], ["109320.52000000", "0.00100000"], ["106834.50000000", "0.04680000"]], "a": [["110985.31000000", "0.05130000"], ["110985.32000000", "0.00110000"], ["110989.25000000", "0.00015000"], ["110989.75000000", "0.00731000"], ["110990.13000000", "0.00010000"], ["110991.12000000", "0.00000000"], ["110991.62000000", "0.00005000"], ["110992.56000000", "0.00005000"], ["110992.92000000", "0.29727000"], ["110993.47000000", "0.00005000"], ["110993.52000000", "0.00000000"], ["110993.75000000", "0.02000000"], ["110994.25000000", "0.00000000"], ["110994.75000000", "0.00000000"], ["110994.97000000", "0.00000000"], ["110995.95000000", "0.04000000"], ["110996.35000000", "0.24000000"], ["110996.70000000", "0.21476000"], ["110997.85000000", "0.00000000"], ["110998.34000000", "0.00000000"], ["110999.57000000", "0.04975000"], ["111000.86000000", "0.00300000"], ["111002.14000000", "0.00000000"], ["111002.85000000", "0.00000000"], ["111003.01000000", "0.00000000"], ["111003.83000000", "0.00000000"], ["111004.96000000", "0.00000000"], ["111005.74000000", "0.00000000"], ["111006.39000000", "0.00000000"], ["111006.89000000", "0.00000000"], ["111007.12000000", "0.01802000"], ["111007.51000000", "0.11267000"], ["111008.87000000", "0.00450000"], ["111011.94000000", "0.13519000"], ["111011.95000000", "0.00009000"], ["111013.32000000", "0.00250000"], ["111018.00000000", "0.00120000"], ["111025.24000000", "0.11491000"], ["111025.89000000", "0.00000000"], ["111026.95000000", "0.00000000"], ["111028.44000000", "0.00000000"], ["111029.53000000", "0.07661000"], ["111036.39000000", "0.01916000"], ["111048.17000000", "0.07661000"], ["111049.11000000", "0.00000000"], ["111052.62000000", "0.00000000"], ["111053.99000000", "0.00048000"], ["111089.14000000", "0.18027000"], ["111131.35000000", "0.00000000"], ["111134.42000000", "0.00000000"], ["111158.27000000", "0.00000000"], ["111165.78000000", "0.00019000"], ["111198.68000000", "0.00000000"], ["111223.13000000", "0.00000000"], ["111291.10000000", "0.00000000"], ["111322.91000000", "0.01711000"], ["111375.11000000", "0.02432000"], ["111457.28000000", "0.00000000"], ["111544.77000000", "0.03798000"], ["112650.09000000", "0.00100000"]]}}
{"type": "orderbook", "local_time": 1761342427842, "event_time": 1761342418214, "latency_ms": 9628, "data": {"e": "depthUpdate", "E": 1761342418214, "s": "BTCUSDT", "U": 79012718701, "u": 79012719204, "b": [["110990.11000000", "5.47860000"], ["110990.10000000", "0.00035000"], ["110989.74000000", "0.00000000"], ["110989.24000000", "0.00000000"], ["110988.51000000", "0.29728000"], ["110988.44000000", "0.04704000"], ["110988.08000000", "0.00000000"], ["110986.64000000", "0.00000000"], ["110986.55000000", "0.00044000"], ["110986.44000000", "0.00005000"], ["110985.98000000", "0.20756000"], ["110985.31000000", "1.75953000"], ["110985.30000000", "0.06966000"], ["110985.29000000", "0.00000000"], ["110984.82000000", "0.01245000"], ["110984.56000000", "0.11787000"], ["110984.54000000", "0.00515000"], ["110984.24000000", "0.00010000"], ["110984.20000000", "0.00104000"], ["110984.19000000", "0.06753000"], ["110984.03000000", "0.00005000"], ["110982.10000000", "0.24764000"], ["110982.09000000", "0.00000000"], ["110980.47000000", "0.00000000"], ["110978.65000000", "0.59131000"], ["110978.64000000", "0.00000000"], ["110978.61000000", "0.00007000"], ["110978.08000000", "0.00005000"], ["110977.95000000", "0.00000000"], ["110977.89000000", "0.00000000"], ["110977.49000000", "0.12211000"], ["110976.90000000", "0.01802000"], ["110974.12000000", "0.00000000"], ["110973.71000000", "0.04503000"], ["110973.47000000", "0.00090000"], ["110973.41000000", "0.20282000"], ["110972.14000000", "0.00000000"], ["110971.12000000", "0.11447000"], ["110970.32000000", "0.00005000"], ["110970.03000000", "0.59955000"], ["110968.65000000", "0.00000000"], ["110962.18000000", "0.00000000"], ["110961.32000000", "0.00000000"], ["110954.78000000", "0.00005000"], ["110954.33000000", "0.00009000"], ["110953.62000000", "0.00000000"], ["110952.19000000", "0.00009000"], ["110952.04000000", "0.32442000"], ["110951.27000000", "0.00090000"], ["110951.16000000", "0.00009000"], ["110950.23000000", "0.21967000"], ["110946.06000000", "0.00009000"], ["110945.04000000", "0.00000000"], ["110939.68000000", "0.00009000"], ["110934.60000000", "0.00000000"], ["110931.64000000", "0.00000000"], ["110930.64000000", "0.00000000"], ["110923.14000000", "0.00000000"], ["110917.53000000", "0.00631000"], ["110909.94000000", "0.00651000"], ["110909.64000000", "0.00616000"], ["110902.86000000", "0.00000000"], ["110898.50000000", "0.00090000"], ["110892.23000000", "0.04097000"], ["110891.96000000", "0.00000000"], ["110878.38000000", "0.00112000"], ["110875.47000000", "0.00000000"], ["110865.50000000", "0.00000000"], ["110838.81000000", "0.08835000"], ["110651.73000000", "0.00000000"], ["109320.52000000", "0.00000000"], ["99886.00000000", "0.00775000"]], "a": [["110985.31000000", "0.00000000"], ["110985.32000000", "0.00000000"], ["110985.60000000", "0.00000000"], ["110986.44000000", "0.00000000"], ["110986.65000000", "0.00000000"], ["110988.09000000", "0.00000000"], ["110988.90000000", "0.00000000"], ["110989.24000000", "0.00000000"], ["110989.25000000", "0.00000000"], ["110989.73000000", "0.00000000"], ["110989.74000000", "0.00000000"], ["110989.75000000", "0.00000000"], ["110990.00000000", "0.00000000"], ["110990.11000000", "0.00000000"], ["110990.12000000", "0.00703000"], ["110990.13000000", "0.00090000"], ["110991.61000000", "0.00000000"], ["110991.62000000", "0.00000000"], ["110991.87000000", "0.15709000"], ["110991.88000000", "0.00010000"], ["110991.96000000", "0.00546000"], ["110992.55000000", "0.00000000"], ["110992.56000000", "0.00000000"], ["110992.91000000", "0.00010000"], ["110992.92000000", "0.00010000"], ["110993.46000000", "0.00000000"], ["110993.47000000", "0.00000000"], ["110993.61000000", "0.00000000"], ["110993.75000000", "0.00010000"], ["110994.93000000", "0.01361000"], ["110995.24000000", "0.00010000"], ["110995.25000000", "0.20292000"], ["110995.56000000", "0.00000000"], ["110995.58000000", "0.00010000"], ["110995.59000000", "0.00005000"], ["110995.65000000", "0.00000000"], ["110995.92000000", "0.29727000"], ["110995.94000000", "0.00010000"], ["110995.95000000", "0.00005000"], ["110995.99000000", "0.00000000"], ["110996.00000000", "0.00005000"], ["110996.14000000", "0.00000000"], ["110996.35000000", "0.00000000"], ["110996.41000000", "0.00000000"], ["110997.05000000", "0.02000000"], ["110997.40000000", "0.00005000"], ["110998.85000000", "0.28000000"], ["110998.91000000", "0.00000000"], ["110998.99000000", "0.04000000"], ["110999.39000000", "0.00000000"], ["110999.49000000", "0.00000000"], ["110999.57000000", "0.00000000"], ["111001.19000000", "0.00000000"], ["111003.88000000", "0.00331000"], ["111004.00000000", "0.12289000"], ["111005.94000000", "0.00000000"], ["111006.67000000", "0.00000000"], ["111006.77000000", "0.00150000"], ["111007.02000000", "0.02704000"], ["111007.12000000", "0.00000000"], ["111008.52000000", "0.01802000"], ["111008.87000000", "0.00000000"], ["111011.12000000", "0.01036000"], ["111011.93000000", "0.00450000"], ["111012.02000000", "0.00000000"], ["111013.75000000", "0.00000000"], ["111016.30000000", "0.00900000"], ["111017.16000000", "0.00000000"], ["111017.76000000", "0.00250000"], ["111017.86000000", "0.00090000"], ["111022.68000000", "0.27041000"], ["111022.69000000", "0.00000000"], ["111023.94000000", "0.34595000"], ["111025.99000000", "0.00000000"], ["111027.23000000", "0.04503000"], ["111029.34000000", "0.00000000"], ["111030.81000000", "0.06720000"], ["111030.85000000", "0.43934000"], ["111030.97000000", "0.00016000"], ["111031.22000000", "0.00000000"], ["111032.17000000", "0.00000000"], ["111034.49000000", "0.00000000"], ["111036.36000000", "0.02816000"], ["111037.64000000", "0.00000000"], ["111038.32000000", "0.00000000"], ["111039.96000000", "0.00000000"], ["111040.06000000", "0.00090000"], ["111041.24000000", "0.00005000"], ["111041.71000000", "0.00016000"], ["111042.30000000", "0.00000000"], ["111042.45000000", "0.02146000"], ["111045.32000000", "0.00225000"], ["111050.36000000", "0.32413000"], ["111052.34000000", "0.00625000"], ["111058.02000000", "0.00657000"], ["111065.97000000", "0.00000000"], ["111066.58000000", "0.00000000"], ["111072.78000000", "0.00224000"], ["111075.61000000", "0.00000000"], ["111077.56000000", "0.00000000"], ["111081.58000000", "0.00000000"], ["111081.59000000", "0.00000000"], ["111082.79000000", "0.00000000"], ["111082.80000000", "0.00000000"], ["111083.86000000", "0.00000000"], ["111089.13000000", "0.12883000"], ["111090.81000000", "0.00000000"], ["111098.29000000", "0.00000000"], ["111106.33000000", "0.00000000"], ["111110.00000000", "0.00550000"], ["111122.65000000", "0.00000000"], ["111171.99000000", "0.00000000"], ["111177.43000000", "0.00000000"], ["111178.21000000", "0.00000000"], ["111183.83000000", "0.00098000"], ["111193.46000000", "0.01411000"], ["111233.77000000", "0.00000000"], ["111297.53000000", "0.00000000"], ["111298.06000000", "0.00000000"], ["111387.94000000", "0.03698000"], ["111390.21000000", "0.03698000"], ["111462.00000000", "0.00000000"], ["111544.56000000", "0.00005000"], ["111544.79000000", "0.03798000"], ["112650.09000000", "0.00000000"]]}}
