{"type": "orderbook", "local_time": 1761342363135, "event_time": 1761342363214, "latency_ms": -79, "data": {"e": "depthUpdate", "E": 1761342363214, "s": "BTCUSDT", "U": 79012689566, "u": 79012689571, "b": [["111028.02000000", "2.18334000"], ["111018.00000000", "0.01801000"], ["110353.81000000", "0.00000000"]], "a": [["111034.13000000", "0.00005000"]]}}
{"type": "orderbook", "local_time": 1761342363236, "event_time": 1761342363314, "latency_ms": -78, "data": {"e": "depthUpdate", "E": 1761342363314, "s": "BTCUSDT", "U": 79012689572, "u": 79012689583, "b": [["111028.02000000", "2.21936000"], ["111018.00000000", "0.00000000"], ["111017.99000000", "0.01801000"], ["110998.27000000", "0.00000000"]], "a": [["111028.03000000", "0.73709000"], ["111028.04000000", "0.00128000"], ["111033.16000000", "0.04577000"], ["111034.13000000", "0.00000000"], ["111034.69000000", "0.00545000"], ["111036.33000000", "0.04773000"], ["111061.70000000", "0.00000000"]]}}
{"type": "orderbook", "local_time": 1761342363334, "event_time": 1761342363414, "latency_ms": -80, "data": {"e": "depthUpdate", "E": 1761342363414, "s": "BTCUSDT", "U": 79012689584, "u": 79012689589, "b": [["110728.02000000", "0.00000000"], ["110133.10000000", "0.00000000"]], "a": [["111028.03000000", "0.73707000"], ["111028.04000000", "0.00133000"]]}}
{"type": "orderbook", "local_time": 1761342363434, "event_time": 1761342363514, "latency_ms": -80, "data": {"e": "depthUpdate", "E": 1761342363514, "s": "BTCUSDT", "U": 79012689590, "u": 79012689599, "b": [["111028.02000000", "2.21271000"], ["111027.22000000", "0.03064000"], ["111018.59000000", "0.02420000"], ["111017.99000000", "0.00000000"], ["111017.98000000", "0.01801000"], ["110998.27000000", "0.84681000"], ["99925.00000000", "0.00530000"]], "a": [["111061.12000000", "0.97783000"], ["111368.93000000", "0.48717000"], ["111376.22000000", "0.00000000"]]}}
{"type": "orderbook", "local_time": 1761342363535, "event_time": 1761342363614, "latency_ms": -79, "data": {"e": "depthUpdate", "E": 1761342363614, "s": "BTCUSDT", "U": 79012689600, "u": 79012689603, "b": [["111028.02000000", "2.21935000"], ["111028.01000000", "0.85662000"], ["99925.00000000", "0.00510000"]], "a": [["111028.04000000", "0.00688000"]]}}
{"type": "orderbook", "local_time": 1761342363640, "event_time": 1761342363714, "latency_ms": -74, "data": {"e": "depthUpdate", "E": 1761342363714, "s": "BTCUSDT", "U": 79012689604, "u": 79012689615, "b": [["109912.84000000", "0.00000000"]], "a": [["111028.03000000", "0.73717000"], ["111028.04000000", "0.00698000"], ["111031.25000000", "0.34775000"], ["111034.69000000", "0.00540000"]]}}
{"type": "orderbook", "local_time": 1761342363733, "event_time": 1761342363814, "latency_ms": -81, "data": {"e": "depthUpdate", "E": 1761342363814, "s": "BTCUSDT", "U": 79012689616, "u": 79012689627, "b": [["111025.67000000", "0.00000000"], ["111017.98000000", "0.00000000"], ["111017.97000000", "0.00000000"], ["111014.03000000", "0.01801000"], ["110892.83000000", "0.00114000"], ["110892.67000000", "0.00005000"], ["110881.57000000", "0.00000000"]], "a": [["111032.52000000", "0.20745000"], ["111035.83000000", "0.00000000"], ["111045.66000000", "0.01801000"], ["111049.14000000", "0.00000000"], ["111064.39000000", "0.00000000"], ["111075.49000000", "0.00000000"]]}}
{"type": "orderbook", "local_time": 1761342363839, "event_time": 1761342363914, "latency_ms": -75, "data": {"e": "depthUpdate", "E": 1761342363914, "s": "BTCUSDT", "U": 79012689628, "u": 79012689638, "b": [["110881.74000000", "0.00229000"]], "a": [["111028.03000000", "0.73717000"], ["111028.04000000", "0.00698000"], ["111031.26000000", "0.81635000"], ["111032.52000000", "0.20750000"], ["111034.67000000", "0.00720000"], ["111042.74000000", "0.00044000"], ["111064.39000000", "0.00114000"]]}}
{"type": "orderbook", "local_time": 1761342363934, "event_time": 1761342364014, "latency_ms": -80, "data": {"e": "depthUpdate", "E": 1761342364014, "s": "BTCUSDT", "U": 79012689639, "u": 79012689646, "b": [["111028.02000000", "2.21932000"], ["99925.00000000", "0.00510000"]], "a": [["111028.03000000", "0.73633000"], ["111076.89000000", "0.00229000"]]}}
{"type": "orderbook", "local_time": 1761342364040, "event_time": 1761342364114, "latency_ms": -74, "data": {"e": "depthUpdate", "E": 1761342364114, "s": "BTCUSDT", "U": 79012689647, "u": 79012689653, "b": [["111028.02000000", "2.21947000"], ["111028.01000000", "0.85667000"]], "a": [["111028.03000000", "0.73529000"], ["111045.66000000", "0.00000000"], ["111045.67000000", "0.01801000"]]}}
{"type": "orderbook", "local_time": 1761342364146, "event_time": 1761342364214, "latency_ms": -68, "data": {"e": "depthUpdate", "E": 1761342364214, "s": "BTCUSDT", "U": 79012689654, "u": 79012689658, "b": [["111028.02000000", "2.21893000"], ["110728.02000000", "0.00000000"]], "a": []}}
{"type": "orderbook", "local_time": 1761342364238, "event_time": 1761342364314, "latency_ms": -76, "data": {"e": "depthUpdate", "E": 1761342364314, "s": "BTCUSDT", "U": 79012689659, "u": 79012689664, "b": [["111028.02000000", "2.93053000"], ["111015.31000000", "0.00000000"], ["110999.81000000", "0.00000000"]], "a": [["111028.03000000", "0.72628000"], ["111028.04000000", "0.30439000"]]}}
{"type": "orderbook", "local_time": 1761342364339, "event_time": 1761342364414, "latency_ms": -75, "data": {"e": "depthUpdate", "E": 1761342364414, "s": "BTCUSDT", "U": 79012689665, "u": 79012689676, "b": [["111028.02000000", "2.21893000"], ["111015.31000000", "0.00010000"], ["110999.80000000", "0.00576000"], ["110568.65000000", "0.00000000"], ["110563.66000000", "0.00250000"]], "a": [["111028.03000000", "0.72633000"], ["111028.04000000", "0.30444000"], ["111028.94000000", "0.00000000"], ["111031.25000000", "0.34775000"], ["111243.45000000", "0.00000000"], ["111248.46000000", "0.00250000"]]}}
{"type": "orderbook", "local_time": 1761342364533, "event_time": 1761342364614, "latency_ms": -81, "data": {"e": "depthUpdate", "E": 1761342364614, "s": "BTCUSDT", "U": 79012689677, "u": 79012689686, "b": [["111028.02000000", "2.24861000"], ["111027.84000000", "0.00020000"], ["99925.00000000", "0.00510000"]], "a": [["111028.03000000", "0.72635000"], ["111029.14000000", "0.00158000"]]}}
{"type": "orderbook", "local_time": 1761342364634, "event_time": 1761342364714, "latency_ms": -80, "data": {"e": "depthUpdate", "E": 1761342364714, "s": "BTCUSDT", "U": 79012689687, "u": 79012689708, "b": [["111028.02000000", "2.24861000"], ["111028.01000000", "0.85662000"], ["111028.00000000", "2.47747000"], ["111027.84000000", "0.00000000"], ["111027.75000000", "0.29738000"], ["111027.22000000", "0.03074000"], ["111023.32000000", "0.04577000"], ["99925.00000000", "0.00510000"]], "a": [["111028.03000000", "0.67581000"]]}}
{"type": "orderbook", "local_time": 1761342364751, "event_time": 1761342364814, "latency_ms": -63, "data": {"e": "depthUpdate", "E": 1761342364814, "s": "BTCUSDT", "U": 79012689709, "u": 79012689715, "b": [["111028.02000000", "2.24846000"], ["111015.31000000", "0.00000000"]], "a": [["111045.67000000", "0.00000000"], ["111046.47000000", "0.01801000"]]}}
{"type": "orderbook", "local_time": 1761342364935, "event_time": 1761342365014, "latency_ms": -79, "data": {"e": "depthUpdate", "E": 1761342365014, "s": "BTCUSDT", "U": 79012689716, "u": 79012689721, "b": [["111015.31000000", "0.00010000"], ["88822.00000000", "0.00337000"]], "a": [["111046.47000000", "0.00000000"], ["111046.48000000", "0.01801000"]]}}
{"type": "orderbook", "local_time": 1761342365040, "event_time": 1761342365114, "latency_ms": -74, "data": {"e": "depthUpdate", "E": 1761342365114, "s": "BTCUSDT", "U": 79012689722, "u": 79012689736, "b": [["111016.08000000", "0.01801000"], ["111014.03000000", "0.00000000"], ["110930.27000000", "0.90135000"], ["110749.06000000", "0.00000000"]], "a": [["111031.24000000", "0.00020000"], ["111031.78000000", "0.04993000"], ["111042.74000000", "0.00000000"], ["111046.48000000", "0.00000000"], ["111047.72000000", "0.01801000"], ["111125.22000000", "0.00000000"], ["111125.23000000", "0.00000000"], ["111125.70000000", "0.00100000"], ["111125.71000000", "0.00100000"], ["111368.93000000", "0.48717000"]]}}
{"type": "orderbook", "local_time": 1761342365140, "event_time": 1761342365215, "latency_ms": -75, "data": {"e": "depthUpdate", "E": 1761342365215, "s": "BTCUSDT", "U": 79012689737, "u": 79012689758, "b": [["111028.02000000", "2.21244000"]], "a": [["111028.03000000", "0.67581000"], ["111028.04000000", "0.30449000"], ["111029.70000000", "0.04082000"], ["111031.23000000", "0.00000000"], ["111031.24000000", "0.00010000"], ["111031.25000000", "0.34785000"], ["111031.26000000", "0.81635000"], ["111031.78000000", "0.04998000"], ["111032.51000000", "0.00005000"], ["111125.70000000", "0.00000000"], ["111125.71000000", "0.00000000"]]}}
{"type": "orderbook", "local_time": 1761342365234, "event_time": 1761342365314, "latency_ms": -80, "data": {"e": "depthUpdate", "E": 1761342365314, "s": "BTCUSDT", "U": 79012689759, "u": 79012689763, "b": [["111028.02000000", "2.92404000"], ["111015.31000000", "0.00000000"], ["99925.00000000", "0.00520000"]], "a": [["111028.03000000", "0.60720000"]]}}
{"type": "orderbook", "local_time": 1761342365337, "event_time": 1761342365414, "latency_ms": -77, "data": {"e": "depthUpdate", "E": 1761342365414, "s": "BTCUSDT", "U": 79012689764, "u": 79012689769, "b": [["110805.97000000", "0.00010000"], ["102145.04000000", "0.00010000"], ["99925.00000000", "0.00520000"]], "a": []}}
{"type": "orderbook", "local_time": 1761342365434, "event_time": 1761342365514, "latency_ms": -80, "data": {"e": "depthUpdate", "E": 1761342365514, "s": "BTCUSDT", "U": 79012689770, "u": 79012689773, "b": [["111028.02000000", "3.10413000"], ["111024.25000000", "0.00005000"], ["110707.74000000", "0.00572000"], ["110706.75000000", "0.00000000"], ["99925.00000000", "0.00510000"]], "a": []}}
{"type": "orderbook", "local_time": 1761342365535, "event_time": 1761342365614, "latency_ms": -79, "data": {"e": "depthUpdate", "E": 1761342365614, "s": "BTCUSDT", "U": 79012689774, "u": 79012689783, "b": [["111028.02000000", "3.10408000"], ["111028.01000000", "0.85657000"], ["111025.24000000", "0.03449000"], ["111024.25000000", "0.00000000"], ["111022.13000000", "0.11202000"], ["111021.36000000", "0.00540000"], ["111020.82000000", "0.00005000"], ["110584.36000000", "0.00010000"]], "a": []}}
{"type": "orderbook", "local_time": 1761342365635, "event_time": 1761342365714, "latency_ms": -79, "data": {"e": "depthUpdate", "E": 1761342365714, "s": "BTCUSDT", "U": 79012689784, "u": 79012689788, "b": [["111022.13000000", "0.08480000"], ["109599.87000000", "0.02498000"], ["99925.00000000", "0.00530000"]], "a": []}}
{"type": "orderbook", "local_time": 1761342365738, "event_time": 1761342365814, "latency_ms": -76, "data": {"e": "depthUpdate", "E": 1761342365814, "s": "BTCUSDT", "U": 79012689789, "u": 79012689801, "b": [["111028.02000000", "3.15078000"], ["111025.57000000", "0.00005000"], ["110955.10000000", "0.03218000"], ["110930.25000000", "0.00000000"], ["99925.00000000", "0.00510000"]], "a": [["111032.52000000", "0.00005000"], ["111034.67000000", "0.00000000"], ["111047.72000000", "0.00000000"], ["111047.73000000", "0.01801000"]]}}
{"type": "orderbook", "local_time": 1761342365840, "event_time": 1761342365914, "latency_ms": -74, "data": {"e": "depthUpdate", "E": 1761342365914, "s": "BTCUSDT", "U": 79012689802, "u": 79012689830, "b": [["111028.02000000", "3.15075000"], ["111028.01000000", "0.85652000"], ["111027.50000000", "0.00250000"], ["111027.22000000", "0.03074000"], ["111025.57000000", "0.00000000"], ["111021.36000000", "0.00545000"], ["111005.25000000", "0.00000000"], ["110363.19000000", "0.00010000"]], "a": [["111028.03000000", "0.60710000"], ["111028.04000000", "0.30444000"], ["111031.78000000", "0.04998000"], ["111032.51000000", "0.00000000"], ["111032.52000000", "0.00000000"], ["111032.55000000", "0.00005000"], ["111033.16000000", "0.04577000"], ["111034.58000000", "0.20745000"], ["111034.69000000", "0.00545000"], ["111036.33000000", "0.00000000"], ["111036.40000000", "0.00000000"], ["111063.10000000", "0.00250000"]]}}
{"type": "orderbook", "local_time": 1761342365939, "event_time": 1761342366014, "latency_ms": -75, "data": {"e": "depthUpdate", "E": 1761342366014, "s": "BTCUSDT", "U": 79012689831, "u": 79012689853, "b": [["111028.02000000", "3.18682000"], ["111027.75000000", "0.29738000"], ["111027.50000000", "0.00255000"], ["111027.22000000", "0.03069000"], ["102145.04000000", "0.00000000"]], "a": [["111028.03000000", "0.60710000"], ["111028.04000000", "0.29884000"], ["111033.16000000", "0.04577000"], ["111034.57000000", "0.20824000"], ["111034.58000000", "0.21470000"], ["111034.69000000", "0.00540000"], ["111034.79000000", "0.00000000"], ["111045.00000000", "0.04789000"]]}}
{"type": "orderbook", "local_time": 1761342366052, "event_time": 1761342366115, "latency_ms": -63, "data": {"e": "depthUpdate", "E": 1761342366115, "s": "BTCUSDT", "U": 79012689854, "u": 79012689867, "b": [["111028.01000000", "0.86207000"], ["111021.36000000", "0.00553000"], ["39970.09000000", "0.00016000"]], "a": [["111028.03000000", "0.60705000"], ["111033.16000000", "0.04577000"], ["111034.57000000", "0.20829000"], ["111034.58000000", "0.21465000"], ["111040.67000000", "0.04773000"], ["111045.00000000", "0.00016000"], ["111047.73000000", "0.00000000"], ["111048.97000000", "0.01801000"], ["111058.65000000", "0.00250000"], ["111063.10000000", "0.00000000"]]}}
{"type": "orderbook", "local_time": 1761342366138, "event_time": 1761342366214, "latency_ms": -76, "data": {"e": "depthUpdate", "E": 1761342366214, "s": "BTCUSDT", "U": 79012689868, "u": 79012689889, "b": [["111028.02000000", "3.19797000"], ["111019.70000000", "0.30388000"], ["111013.90000000", "0.00000000"], ["33000.00000000", "3.79445000"]], "a": [["111028.03000000", "0.60710000"], ["111028.04000000", "0.29889000"], ["111032.56000000", "0.00005000"], ["111034.58000000", "0.00000000"], ["111035.26000000", "0.00000000"], ["111035.82000000", "0.29716000"], ["111035.87000000", "0.21465000"], ["111041.91000000", "0.04508000"], ["111045.10000000", "0.00276000"], ["111047.99000000", "0.00450000"], ["111096.98000000", "0.00048000"], ["111097.72000000", "0.00000000"], ["111208.76000000", "0.00019000"], ["111208.77000000", "0.00000000"]]}}
{"type": "orderbook", "local_time": 1761342366239, "event_time": 1761342366314, "latency_ms": -75, "data": {"e": "depthUpdate", "E": 1761342366314, "s": "BTCUSDT", "U": 79012689890, "u": 79012689914, "b": [["111027.50000000", "0.00005000"], ["111022.13000000", "0.16673000"], ["111021.36000000", "0.00553000"], ["111019.70000000", "0.00000000"], ["111017.10000000", "0.30389000"], ["111005.25000000", "0.00250000"], ["109400.00000000", "4.05097000"]], "a": [["111028.03000000", "0.60710000"], ["111028.04000000", "0.29889000"], ["111031.78000000", "0.04998000"], ["111032.55000000", "0.00000000"], ["111032.56000000", "0.00000000"], ["111034.56000000", "0.00005000"], ["111034.57000000", "0.20829000"], ["111034.69000000", "0.00545000"], ["111038.26000000", "0.04773000"], ["111040.67000000", "0.00000000"]]}}
{"type": "orderbook", "local_time": 1761342366338, "event_time": 1761342366414, "latency_ms": -76, "data": {"e": "depthUpdate", "E": 1761342366414, "s": "BTCUSDT", "U": 79012689915, "u": 79012689922, "b": [["111028.02000000", "3.19757000"], ["111027.75000000", "0.29738000"], ["111027.50000000", "0.00000000"], ["111027.22000000", "0.03074000"], ["111021.36000000", "0.00553000"]], "a": []}}
{"type": "orderbook", "local_time": 1761342366436, "event_time": 1761342366514, "latency_ms": -78, "data": {"e": "depthUpdate", "E": 1761342366514, "s": "BTCUSDT", "U": 79012689923, "u": 79012689927, "b": [["111015.31000000", "0.00010000"], ["110142.47000000", "0.00010000"]], "a": [["111036.40000000", "0.00250000"], ["111058.65000000", "0.00000000"]]}}
{"type": "orderbook", "local_time": 1761342366537, "event_time": 1761342366614, "latency_ms": -77, "data": {"e": "depthUpdate", "E": 1761342366614, "s": "BTCUSDT", "U": 79012689928, "u": 79012689936, "b": [["111028.02000000", "3.19149000"], ["111015.31000000", "0.00000000"], ["110787.37000000", "0.00000000"]], "a": [["111028.03000000", "0.60715000"], ["111125.70000000", "0.00100000"], ["111125.71000000", "0.00100000"], ["111270.46000000", "0.00000000"]]}}
{"type": "orderbook", "local_time": 1761342366635, "event_time": 1761342366714, "latency_ms": -79, "data": {"e": "depthUpdate", "E": 1761342366714, "s": "BTCUSDT", "U": 79012689937, "u": 79012689950, "b": [["111028.02000000", "2.48529000"], ["99925.00000000", "0.00510000"]], "a": [["111028.03000000", "0.60595000"], ["111028.04000000", "0.29889000"], ["111075.88000000", "0.00010000"], ["111250.04000000", "0.00000000"]]}}
{"type": "orderbook", "local_time": 1761342366734, "event_time": 1761342366814, "latency_ms": -80, "data": {"e": "depthUpdate", "E": 1761342366814, "s": "BTCUSDT", "U": 79012689951, "u": 79012689957, "b": [["110955.10000000", "0.00000000"], ["110937.28000000", "0.03218000"], ["109922.18000000", "0.00010000"], ["99925.00000000", "0.00510000"]], "a": [["111082.49000000", "0.00402000"], ["111256.64000000", "0.00089000"]]}}
{"type": "orderbook", "local_time": 1761342366837, "event_time": 1761342366914, "latency_ms": -77, "data": {"e": "depthUpdate", "E": 1761342366914, "s": "BTCUSDT", "U": 79012689958, "u": 79012689967, "b": [["110787.44000000", "0.84842000"], ["99925.00000000", "0.00510000"]], "a": [["111270.21000000", "4.77430000"], ["111368.93000000", "0.48717000"]]}}
{"type": "orderbook", "local_time": 1761342366943, "event_time": 1761342367014, "latency_ms": -71, "data": {"e": "depthUpdate", "E": 1761342367014, "s": "BTCUSDT", "U": 79012689968, "u": 79012689969, "b": [], "a": [["111121.53000000", "0.03400000"], ["111122.48000000", "0.00000000"]]}}
{"type": "orderbook", "local_time": 1761342367035, "event_time": 1761342367114, "latency_ms": -79, "data": {"e": "depthUpdate", "E": 1761342367114, "s": "BTCUSDT", "U": 79012689970, "u": 79012689971, "b": [], "a": [["111121.53000000", "0.00000000"], ["111122.48000000", "0.03400000"]]}}
{"type": "orderbook", "local_time": 1761342367269, "event_time": 1761342367314, "latency_ms": -45, "data": {"e": "depthUpdate", "E": 1761342367314, "s": "BTCUSDT", "U": 79012689972, "u": 79012689976, "b": [["111028.02000000", "2.48476000"], ["110956.23000000", "0.03218000"], ["110937.28000000", "0.00000000"], ["110827.83000000", "0.02161000"], ["110825.28000000", "0.00000000"]], "a": []}}
{"type": "orderbook", "local_time": 1761342367335, "event_time": 1761342367414, "latency_ms": -79, "data": {"e": "depthUpdate", "E": 1761342367414, "s": "BTCUSDT", "U": 79012689977, "u": 79012689979, "b": [["111028.02000000", "2.48526000"], ["110998.27000000", "0.00000000"]], "a": [["111061.12000000", "0.00000000"]]}}
{"type": "orderbook", "local_time": 1761342367434, "event_time": 1761342367514, "latency_ms": -80, "data": {"e": "depthUpdate", "E": 1761342367514, "s": "BTCUSDT", "U": 79012689980, "u": 79012689982, "b": [["111028.02000000", "2.44924000"], ["108000.00000000", "28.73587000"]], "a": [["111249.90000000", "0.00000000"]]}}
{"type": "orderbook", "local_time": 1761342367535, "event_time": 1761342367614, "latency_ms": -79, "data": {"e": "depthUpdate", "E": 1761342367614, "s": "BTCUSDT", "U": 79012689983, "u": 79012689985, "b": [["110998.27000000", "0.84681000"]], "a": [["111061.07000000", "0.93888000"], ["112027.22000000", "0.00404000"]]}}
{"type": "orderbook", "local_time": 1761342367848, "event_time": 1761342367914, "latency_ms": -66, "data": {"e": "depthUpdate", "E": 1761342367914, "s": "BTCUSDT", "U": 79012689986, "u": 79012689988, "b": [["99925.00000000", "0.00510000"]], "a": []}}
{"type": "orderbook", "local_time": 1761342367935, "event_time": 1761342368014, "latency_ms": -79, "data": {"e": "depthUpdate", "E": 1761342368014, "s": "BTCUSDT", "U": 79012689989, "u": 79012689991, "b": [["99925.00000000", "0.00530000"], ["88822.00000000", "0.00337000"]], "a": []}}
{"type": "orderbook", "local_time": 1761342368034, "event_time": 1761342368114, "latency_ms": -80, "data": {"e": "depthUpdate", "E": 1761342368114, "s": "BTCUSDT", "U": 79012689992, "u": 79012689998, "b": [["111028.02000000", "2.44011000"], ["110999.80000000", "0.00000000"], ["99925.00000000", "0.00510000"]], "a": [["111049.59000000", "0.04367000"]]}}
{"type": "orderbook", "local_time": 1761342368135, "event_time": 1761342368214, "latency_ms": -79, "data": {"e": "depthUpdate", "E": 1761342368214, "s": "BTCUSDT", "U": 79012689999, "u": 79012690002, "b": [["111028.02000000", "2.44615000"], ["111000.34000000", "0.00576000"]], "a": []}}
{"type": "orderbook", "local_time": 1761342368339, "event_time": 1761342368415, "latency_ms": -76, "data": {"e": "depthUpdate", "E": 1761342368415, "s": "BTCUSDT", "U": 79012690003, "u": 79012690005, "b": [["111028.01000000", "0.85652000"]], "a": [["111031.78000000", "0.00005000"], ["111049.59000000", "0.00000000"]]}}
{"type": "orderbook", "local_time": 1761342368437, "event_time": 1761342368514, "latency_ms": -77, "data": {"e": "depthUpdate", "E": 1761342368514, "s": "BTCUSDT", "U": 79012690006, "u": 79012690015, "b": [], "a": [["111028.03000000", "0.60590000"], ["111028.04000000", "0.29884000"], ["111031.25000000", "0.24350000"], ["111031.26000000", "0.81635000"], ["111031.78000000", "0.00000000"], ["111034.80000000", "0.20287000"]]}}
{"type": "orderbook", "local_time": 1761342368538, "event_time": 1761342368614, "latency_ms": -76, "data": {"e": "depthUpdate", "E": 1761342368614, "s": "BTCUSDT", "U": 79012690016, "u": 79012690018, "b": [], "a": [["111028.04000000", "0.30439000"], ["111036.76000000", "0.00044000"], ["111053.27000000", "0.00044000"]]}}
{"type": "orderbook", "local_time": 1761342368634, "event_time": 1761342368714, "latency_ms": -80, "data": {"e": "depthUpdate", "E": 1761342368714, "s": "BTCUSDT", "U": 79012690019, "u": 79012690022, "b": [], "a": [["111076.20000000", "0.00402000"], ["111082.49000000", "0.00000000"], ["111250.36000000", "0.00089000"], ["111256.64000000", "0.00000000"]]}}
{"type": "orderbook", "local_time": 1761342368737, "event_time": 1761342368814, "latency_ms": -77, "data": {"e": "depthUpdate", "E": 1761342368814, "s": "BTCUSDT", "U": 79012690023, "u": 79012690024, "b": [["42000.00000000", "1.36834000"]], "a": [["111096.29000000", "0.00044000"]]}}
{"type": "orderbook", "local_time": 1761342368841, "event_time": 1761342368915, "latency_ms": -74, "data": {"e": "depthUpdate", "E": 1761342368915, "s": "BTCUSDT", "U": 79012690025, "u": 79012690028, "b": [["110956.23000000", "0.00000000"], ["110933.26000000", "0.03218000"], ["99925.00000000", "0.00510000"]], "a": []}}
{"type": "orderbook", "local_time": 1761342369040, "event_time": 1761342369115, "latency_ms": -75, "data": {"e": "depthUpdate", "E": 1761342369115, "s": "BTCUSDT", "U": 79012690029, "u": 79012690029, "b": [], "a": [["111096.29000000", "0.00000000"]]}}
{"type": "orderbook", "local_time": 1761342369135, "event_time": 1761342369214, "latency_ms": -79, "data": {"e": "depthUpdate", "E": 1761342369214, "s": "BTCUSDT", "U": 79012690030, "u": 79012690034, "b": [["111028.02000000", "3.19347000"], ["99925.00000000", "0.00510000"]], "a": [["111122.48000000", "0.00000000"]]}}
{"type": "orderbook", "local_time": 1761342369249, "event_time": 1761342369314, "latency_ms": -65, "data": {"e": "depthUpdate", "E": 1761342369314, "s": "BTCUSDT", "U": 79012690035, "u": 79012690036, "b": [["111028.02000000", "3.19427000"]], "a": [["111120.52000000", "0.03400000"]]}}
{"type": "orderbook", "local_time": 1761342369334, "event_time": 1761342369414, "latency_ms": -80, "data": {"e": "depthUpdate", "E": 1761342369414, "s": "BTCUSDT", "U": 79012690037, "u": 79012690050, "b": [["111028.02000000", "2.29351000"], ["111025.26000000", "0.00000000"], ["111024.25000000", "0.18009000"], ["111016.12000000", "0.00450000"], ["111015.32000000", "0.00000000"], ["111015.31000000", "0.00010000"], ["39970.09000000", "0.00032000"]], "a": [["111028.03000000", "1.58018000"], ["111031.79000000", "0.04948000"], ["111043.42000000", "0.00450000"], ["111045.91000000", "0.27041000"], ["111047.99000000", "0.00000000"], ["111049.94000000", "0.00000000"], ["111080.32000000", "0.00016000"], ["111080.82000000", "0.00000000"]]}}
{"type": "orderbook", "local_time": 1761342369441, "event_time": 1761342369514, "latency_ms": -73, "data": {"e": "depthUpdate", "E": 1761342369514, "s": "BTCUSDT", "U": 79012690051, "u": 79012690067, "b": [["111028.02000000", "2.25566000"], ["111025.24000000", "0.03449000"], ["111024.25000000", "0.18014000"], ["111021.36000000", "0.00548000"]], "a": [["111028.03000000", "1.58023000"], ["111028.04000000", "0.30444000"], ["111031.26000000", "0.81635000"], ["111031.79000000", "0.04953000"], ["111034.80000000", "0.20282000"], ["111035.26000000", "0.04508000"], ["111041.91000000", "0.00000000"], ["111368.93000000", "0.48717000"]]}}
{"type": "orderbook", "local_time": 1761342369544, "event_time": 1761342369614, "latency_ms": -70, "data": {"e": "depthUpdate", "E": 1761342369614, "s": "BTCUSDT", "U": 79012690068, "u": 79012690079, "b": [["111017.10000000", "0.00000000"], ["111013.90000000", "0.30390000"], ["50000.00000000", "39.95292000"]], "a": [["111028.03000000", "1.58021000"], ["111029.67000000", "0.04915000"], ["111033.07000000", "0.29717000"], ["111034.57000000", "0.28765000"], ["111035.62000000", "0.04773000"], ["111035.82000000", "0.00000000"], ["111038.26000000", "0.00000000"], ["111124.00000000", "0.03016000"], ["111127.86000000", "0.00000000"]]}}
{"type": "orderbook", "local_time": 1761342369644, "event_time": 1761342369714, "latency_ms": -70, "data": {"e": "depthUpdate", "E": 1761342369714, "s": "BTCUSDT", "U": 79012690080, "u": 79012690109, "b": [["111022.13000000", "0.08480000"], ["50000.00000000", "39.95322000"], ["39970.09000000", "0.00048000"]], "a": [["111028.03000000", "1.58021000"], ["111028.04000000", "0.30459000"], ["111028.95000000", "0.01365000"], ["111029.66000000", "0.00010000"], ["111029.67000000", "0.00010000"], ["111031.25000000", "0.24345000"], ["111031.79000000", "0.04953000"], ["111033.07000000", "0.29722000"], ["111034.56000000", "0.00000000"], ["111034.57000000", "0.28760000"], ["111034.69000000", "0.00540000"]]}}
{"type": "orderbook", "local_time": 1761342369742, "event_time": 1761342369814, "latency_ms": -72, "data": {"e": "depthUpdate", "E": 1761342369814, "s": "BTCUSDT", "U": 79012690110, "u": 79012690129, "b": [["111016.12000000", "0.00000000"], ["111015.31000000", "0.00460000"], ["110895.00000000", "0.00162000"], ["50000.00000000", "39.95352000"]], "a": [["111028.03000000", "1.58016000"], ["111028.04000000", "0.30454000"], ["111028.95000000", "0.01365000"], ["111029.66000000", "0.00000000"], ["111029.67000000", "0.00000000"], ["111031.25000000", "0.24350000"], ["111031.79000000", "0.00005000"], ["111033.06000000", "0.00005000"], ["111034.57000000", "0.28765000"], ["111096.29000000", "0.00044000"]]}}
{"type": "orderbook", "local_time": 1761342369843, "event_time": 1761342369914, "latency_ms": -71, "data": {"e": "depthUpdate", "E": 1761342369914, "s": "BTCUSDT", "U": 79012690130, "u": 79012690137, "b": [["50000.00000000", "39.95382000"]], "a": [["111028.03000000", "1.58011000"], ["111028.04000000", "0.30449000"], ["111031.26000000", "0.81635000"], ["111031.79000000", "0.00000000"], ["111034.69000000", "0.00545000"], ["111049.58000000", "0.06753000"]]}}
{"type": "orderbook", "local_time": 1761342370036, "event_time": 1761342370114, "latency_ms": -78, "data": {"e": "depthUpdate", "E": 1761342370114, "s": "BTCUSDT", "U": 79012690138, "u": 79012690138, "b": [], "a": [["116000.00000000", "88.49494000"]]}}
{"type": "orderbook", "local_time": 1761342370135, "event_time": 1761342370214, "latency_ms": -79, "data": {"e": "depthUpdate", "E": 1761342370214, "s": "BTCUSDT", "U": 79012690139, "u": 79012690147, "b": [["111028.02000000", "2.22566000"], ["111028.00000000", "2.47747000"], ["111027.98000000", "0.03000000"], ["111024.26000000", "0.18009000"], ["111024.25000000", "0.00005000"], ["111023.59000000", "0.00000000"], ["50000.00000000", "39.95412000"]], "a": [["111028.03000000", "1.58004000"], ["111041.99000000", "0.00450000"], ["111043.42000000", "0.00000000"]]}}
{"type": "orderbook", "local_time": 1761342370238, "event_time": 1761342370314, "latency_ms": -76, "data": {"e": "depthUpdate", "E": 1761342370314, "s": "BTCUSDT", "U": 79012690148, "u": 79012690176, "b": [["111028.02000000", "2.22578000"], ["111028.01000000", "0.85657000"], ["111028.00000000", "2.47747000"], ["111027.98000000", "0.00020000"], ["111027.94000000", "0.00000000"], ["111027.90000000", "0.03000000"], ["111027.75000000", "0.29733000"], ["111027.22000000", "0.03064000"], ["111025.24000000", "0.03449000"], ["111024.26000000", "0.18014000"], ["111024.25000000", "0.00000000"], ["111022.13000000", "0.08475000"]], "a": []}}
{"type": "orderbook", "local_time": 1761342370336, "event_time": 1761342370414, "latency_ms": -78, "data": {"e": "depthUpdate", "E": 1761342370414, "s": "BTCUSDT", "U": 79012690177, "u": 79012690211, "b": [["111028.02000000", "2.22604000"], ["111028.01000000", "0.85657000"], ["111028.00000000", "2.47747000"], ["111027.98000000", "0.00000000"], ["111027.90000000", "0.00020000"], ["111027.88000000", "0.00000000"], ["111027.22000000", "0.02968000"], ["111018.59000000", "0.02388000"], ["110918.09000000", "0.00000000"], ["99925.00000000", "0.00510000"]], "a": [["111028.03000000", "1.57909000"]]}}
{"type": "orderbook", "local_time": 1761342370436, "event_time": 1761342370514, "latency_ms": -78, "data": {"e": "depthUpdate", "E": 1761342370514, "s": "BTCUSDT", "U": 79012690212, "u": 79012690234, "b": [["111028.02000000", "2.22599000"], ["111028.01000000", "0.85652000"], ["111028.00000000", "2.47747000"], ["111027.90000000", "0.00000000"], ["111027.75000000", "0.29738000"], ["111027.22000000", "0.02978000"], ["111022.13000000", "0.06898000"], ["111021.36000000", "0.00540000"], ["110940.60000000", "0.01410000"]], "a": []}}
{"type": "orderbook", "local_time": 1761342370535, "event_time": 1761342370614, "latency_ms": -79, "data": {"e": "depthUpdate", "E": 1761342370614, "s": "BTCUSDT", "U": 79012690235, "u": 79012690237, "b": [["111022.47000000", "0.01626000"], ["111015.31000000", "0.00010000"], ["111014.16000000", "0.00450000"]], "a": [["113960.00000000", "0.01223000"]]}}
{"type": "orderbook", "local_time": 1761342370636, "event_time": 1761342370714, "latency_ms": -78, "data": {"e": "depthUpdate", "E": 1761342370714, "s": "BTCUSDT", "U": 79012690238, "u": 79012690249, "b": [["111028.02000000", "2.19350000"], ["111023.32000000", "0.04577000"], ["111022.47000000", "0.01631000"], ["111022.13000000", "0.06893000"], ["110940.60000000", "0.00000000"]], "a": [["111028.03000000", "1.58503000"], ["111042.74000000", "0.00044000"]]}}
{"type": "orderbook", "local_time": 1761342370736, "event_time": 1761342370814, "latency_ms": -78, "data": {"e": "depthUpdate", "E": 1761342370814, "s": "BTCUSDT", "U": 79012690250, "u": 79012690251, "b": [["42000.00000000", "1.36734000"]], "a": [["111028.03000000", "1.58510000"]]}}
{"type": "orderbook", "local_time": 1761342370938, "event_time": 1761342371014, "latency_ms": -76, "data": {"e": "depthUpdate", "E": 1761342371014, "s": "BTCUSDT", "U": 79012690252, "u": 79012690259, "b": [["111028.02000000", "2.15748000"], ["99925.00000000", "0.00510000"], ["88822.00000000", "0.00337000"]], "a": [["111028.03000000", "1.58431000"]]}}
{"type": "orderbook", "local_time": 1761342371034, "event_time": 1761342371114, "latency_ms": -80, "data": {"e": "depthUpdate", "E": 1761342371114, "s": "BTCUSDT", "U": 79012690260, "u": 79012690275, "b": [["111028.02000000", "2.14848000"], ["111027.89000000", "0.00000000"], ["105778.11000000", "0.00000000"], ["102145.79000000", "0.00010000"]], "a": [["111028.04000000", "0.29894000"], ["111035.87000000", "0.00000000"], ["111036.76000000", "0.00000000"], ["111042.74000000", "0.00000000"], ["111049.58000000", "0.00000000"], ["111053.27000000", "0.00000000"], ["111096.29000000", "0.00000000"]]}}
{"type": "orderbook", "local_time": 1761342371188, "event_time": 1761342371214, "latency_ms": -26, "data": {"e": "depthUpdate", "E": 1761342371214, "s": "BTCUSDT", "U": 79012690276, "u": 79012690282, "b": [["111022.13000000", "0.06901000"], ["60000.00000000", "56.85876000"]], "a": [["111028.03000000", "1.58431000"], ["111028.04000000", "0.29889000"], ["111033.75000000", "0.20745000"], ["111034.57000000", "0.20829000"]]}}
{"type": "orderbook", "local_time": 1761342371313, "event_time": 1761342371314, "latency_ms": -1, "data": {"e": "depthUpdate", "E": 1761342371314, "s": "BTCUSDT", "U": 79012690283, "u": 79012690296, "b": [["111028.02000000", "2.15403000"]], "a": [["111028.03000000", "1.58443000"], ["111028.04000000", "0.29894000"], ["111033.16000000", "0.04577000"], ["111033.75000000", "0.21470000"], ["111034.69000000", "0.00540000"], ["111124.22000000", "0.00100000"], ["111124.23000000", "0.00100000"], ["111125.70000000", "0.00000000"], ["111125.71000000", "0.00000000"]]}}
{"type": "orderbook", "local_time": 1761342371336, "event_time": 1761342371414, "latency_ms": -78, "data": {"e": "depthUpdate", "E": 1761342371414, "s": "BTCUSDT", "U": 79012690297, "u": 79012690304, "b": [["111027.50000000", "0.00250000"], ["111024.26000000", "0.00005000"], ["111023.59000000", "0.18009000"], ["111005.25000000", "0.00000000"]], "a": [["111035.62000000", "0.00000000"], ["111036.40000000", "0.00000000"], ["111043.82000000", "0.04773000"], ["111063.10000000", "0.00250000"], ["111800.00000000", "1.69930000"]]}}
{"type": "orderbook", "local_time": 1761342371434, "event_time": 1761342371514, "latency_ms": -80, "data": {"e": "depthUpdate", "E": 1761342371514, "s": "BTCUSDT", "U": 79012690305, "u": 79012690329, "b": [["111028.02000000", "2.16648000"], ["111027.75000000", "0.29738000"], ["111027.50000000", "0.00255000"], ["111027.22000000", "0.02973000"], ["111025.24000000", "0.03449000"], ["111024.26000000", "0.00000000"], ["111024.24000000", "0.04005000"], ["111023.59000000", "0.18014000"], ["99925.00000000", "0.00510000"]], "a": [["111028.03000000", "1.57538000"], ["111028.04000000", "0.29889000"], ["111034.57000000", "0.14635000"], ["111058.65000000", "0.00250000"], ["111063.10000000", "0.00000000"], ["111368.93000000", "0.48717000"]]}}
{"type": "orderbook", "local_time": 1761342371562, "event_time": 1761342371614, "latency_ms": -52, "data": {"e": "depthUpdate", "E": 1761342371614, "s": "BTCUSDT", "U": 79012690330, "u": 79012690335, "b": [["109599.87000000", "0.02499000"], ["102145.79000000", "0.00000000"], ["99925.00000000", "0.00510000"]], "a": [["120000.00000000", "236.63386000"]]}}
{"type": "orderbook", "local_time": 1761342371634, "event_time": 1761342371714, "latency_ms": -80, "data": {"e": "depthUpdate", "E": 1761342371714, "s": "BTCUSDT", "U": 79012690336, "u": 79012690340, "b": [["60000.00000000", "56.85866000"], ["33000.00000000", "3.79445000"]], "a": [["111039.90000000", "0.04773000"], ["111043.82000000", "0.00000000"]]}}
{"type": "orderbook", "local_time": 1761342371734, "event_time": 1761342371814, "latency_ms": -80, "data": {"e": "depthUpdate", "E": 1761342371814, "s": "BTCUSDT", "U": 79012690341, "u": 79012690341, "b": [], "a": [["111028.03000000", "1.62627000"]]}}
{"type": "orderbook", "local_time": 1761342371837, "event_time": 1761342371914, "latency_ms": -77, "data": {"e": "depthUpdate", "E": 1761342371914, "s": "BTCUSDT", "U": 79012690342, "u": 79012690344, "b": [], "a": [["111036.76000000", "0.00044000"], ["111049.58000000", "0.06552000"], ["111053.27000000", "0.00044000"]]}}
{"type": "orderbook", "local_time": 1761342371938, "event_time": 1761342372014, "latency_ms": -76, "data": {"e": "depthUpdate", "E": 1761342372014, "s": "BTCUSDT", "U": 79012690345, "u": 79012690346, "b": [["111000.58000000", "0.32428000"], ["110977.09000000", "0.00000000"]], "a": []}}
{"type": "orderbook", "local_time": 1761342372035, "event_time": 1761342372114, "latency_ms": -79, "data": {"e": "depthUpdate", "E": 1761342372114, "s": "BTCUSDT", "U": 79012690347, "u": 79012690356, "b": [["111028.02000000", "2.01518000"], ["99925.00000000", "0.00510000"]], "a": [["111028.03000000", "1.54962000"], ["111103.39000000", "0.00000000"], ["111105.51000000", "0.19452000"]]}}
{"type": "orderbook", "local_time": 1761342372239, "event_time": 1761342372314, "latency_ms": -75, "data": {"e": "depthUpdate", "E": 1761342372314, "s": "BTCUSDT", "U": 79012690357, "u": 79012690365, "b": [["111028.02000000", "2.01513000"], ["111027.50000000", "0.00005000"], ["111000.80000000", "0.00250000"]], "a": [["111036.40000000", "0.00250000"], ["111036.72000000", "0.04773000"], ["111039.90000000", "0.00000000"], ["111058.65000000", "0.00000000"], ["111096.98000000", "0.00000000"], ["111208.76000000", "0.00000000"]]}}
{"type": "orderbook", "local_time": 1761342372336, "event_time": 1761342372414, "latency_ms": -78, "data": {"e": "depthUpdate", "E": 1761342372414, "s": "BTCUSDT", "U": 79012690366, "u": 79012690379, "b": [["111028.02000000", "2.01509000"], ["111027.75000000", "0.29738000"], ["111027.50000000", "0.00000000"], ["111027.22000000", "0.02978000"], ["111016.12000000", "0.00450000"], ["111014.16000000", "0.00000000"]], "a": [["111028.03000000", "1.54967000"], ["111033.74000000", "0.22605000"], ["111034.57000000", "0.00005000"], ["111041.99000000", "0.00000000"], ["111043.14000000", "0.00450000"], ["111096.87000000", "0.00048000"], ["111208.79000000", "0.00019000"]]}}
{"type": "orderbook", "local_time": 1761342372529, "event_time": 1761342372514, "latency_ms": 15, "data": {"e": "depthUpdate", "E": 1761342372514, "s": "BTCUSDT", "U": 79012690380, "u": 79012690389, "b": [], "a": [["111028.03000000", "1.54967000"], ["111028.04000000", "0.29889000"], ["111033.16000000", "0.04577000"], ["111033.74000000", "0.22610000"], ["111033.75000000", "0.21470000"], ["111034.57000000", "0.00000000"]]}}
{"type": "orderbook", "local_time": 1761342372534, "event_time": 1761342372614, "latency_ms": -80, "data": {"e": "depthUpdate", "E": 1761342372614, "s": "BTCUSDT", "U": 79012690390, "u": 79012690392, "b": [["111028.02000000", "2.01459000"], ["99925.00000000", "0.00510000"]], "a": []}}
{"type": "orderbook", "local_time": 1761342372637, "event_time": 1761342372714, "latency_ms": -77, "data": {"e": "depthUpdate", "E": 1761342372714, "s": "BTCUSDT", "U": 79012690393, "u": 79012690397, "b": [["111028.02000000", "2.01500000"], ["99925.00000000", "0.00510000"]], "a": [["111028.03000000", "1.54697000"]]}}
{"type": "orderbook", "local_time": 1761342372738, "event_time": 1761342372815, "latency_ms": -77, "data": {"e": "depthUpdate", "E": 1761342372815, "s": "BTCUSDT", "U": 79012690398, "u": 79012690399, "b": [["105809.70000000", "0.00094000"]], "a": [["111028.03000000", "1.55000000"]]}}
{"type": "orderbook", "local_time": 1761342372836, "event_time": 1761342372914, "latency_ms": -78, "data": {"e": "depthUpdate", "E": 1761342372914, "s": "BTCUSDT", "U": 79012690400, "u": 79012690401, "b": [["110787.44000000", "0.00000000"]], "a": [["111270.21000000", "0.00000000"]]}}
{"type": "orderbook", "local_time": 1761342372938, "event_time": 1761342373014, "latency_ms": -76, "data": {"e": "depthUpdate", "E": 1761342373014, "s": "BTCUSDT", "U": 79012690402, "u": 79012690405, "b": [["111000.00000000", "0.02840000"]], "a": [["111028.03000000", "1.55246000"], ["111036.76000000", "0.00000000"], ["111053.27000000", "0.00000000"]]}}
{"type": "orderbook", "local_time": 1761342373036, "event_time": 1761342373114, "latency_ms": -78, "data": {"e": "depthUpdate", "E": 1761342373114, "s": "BTCUSDT", "U": 79012690406, "u": 79012690407, "b": [], "a": [["111368.93000000", "0.48717000"]]}}
{"type": "orderbook", "local_time": 1761342373136, "event_time": 1761342373214, "latency_ms": -78, "data": {"e": "depthUpdate", "E": 1761342373214, "s": "BTCUSDT", "U": 79012690408, "u": 79012690414, "b": [["110787.44000000", "0.84842000"], ["99925.00000000", "0.00510000"]], "a": [["111028.03000000", "1.55115000"], ["111270.19000000", "4.75096000"]]}}
{"type": "orderbook", "local_time": 1761342373236, "event_time": 1761342373314, "latency_ms": -78, "data": {"e": "depthUpdate", "E": 1761342373314, "s": "BTCUSDT", "U": 79012690415, "u": 79012690424, "b": [], "a": [["111120.52000000", "0.00000000"], ["111121.52000000", "0.03400000"], ["111122.47000000", "0.00000000"], ["111124.00000000", "0.00516000"], ["111124.22000000", "0.00000000"], ["111124.23000000", "0.00000000"], ["111125.70000000", "0.00100000"], ["111125.71000000", "0.00100000"], ["111125.95000000", "0.02500000"]]}}
{"type": "orderbook", "local_time": 1761342373338, "event_time": 1761342373414, "latency_ms": -76, "data": {"e": "depthUpdate", "E": 1761342373414, "s": "BTCUSDT", "U": 79012690425, "u": 79012690451, "b": [["111028.02000000", "2.01500000"], ["111027.90000000", "0.03000000"], ["111027.23000000", "0.18018000"], ["111023.59000000", "0.00005000"], ["111015.31000000", "0.00000000"]], "a": [["111028.03000000", "0.57687000"], ["111033.75000000", "0.00005000"], ["111034.80000000", "0.00000000"], ["111035.26000000", "0.00000000"], ["111036.72000000", "0.00000000"], ["111040.29000000", "0.00000000"], ["111040.49000000", "0.04773000"], ["111041.91000000", "0.04508000"], ["111043.14000000", "0.00000000"], ["111045.29000000", "0.00450000"], ["111045.91000000", "0.00000000"], ["111048.30000000", "0.27046000"], ["111048.97000000", "0.00000000"], ["111049.58000000", "0.00000000"], ["111061.07000000", "0.00000000"], ["111099.98000000", "0.20282000"], ["111125.00000000", "0.04076000"], ["111125.95000000", "0.00000000"], ["111151.08000000", "1.60159000"]]}}
{"type": "orderbook", "local_time": 1761342373435, "event_time": 1761342373515, "latency_ms": -80, "data": {"e": "depthUpdate", "E": 1761342373515, "s": "BTCUSDT", "U": 79012690452, "u": 79012690514, "b": [["111028.02000000", "2.01511000"], ["111028.00000000", "2.47747000"], ["111027.90000000", "0.03020000"], ["111027.75000000", "0.29733000"], ["111027.23000000", "0.18023000"], ["111027.22000000", "0.02968000"], ["111024.24000000", "0.04005000"], ["111023.59000000", "0.00000000"], ["111022.47000000", "0.01626000"]], "a": [["111028.03000000", "0.57682000"], ["111028.04000000", "0.29879000"], ["111031.25000000", "0.00020000"], ["111033.07000000", "0.00005000"], ["111033.74000000", "0.00005000"], ["111033.75000000", "0.00000000"], ["111034.69000000", "0.00545000"], ["111035.13000000", "0.00720000"], ["111035.19000000", "0.20745000"], ["111035.88000000", "0.29716000"], ["111036.76000000", "0.00044000"], ["111038.14000000", "0.00000000"], ["111040.28000000", "0.27949000"], ["111047.26000000", "0.01801000"], ["111121.52000000", "0.00000000"], ["111122.47000000", "0.03400000"], ["111125.00000000", "0.01576000"], ["111125.95000000", "0.02500000"]]}}
{"type": "orderbook", "local_time": 1761342373560, "event_time": 1761342373614, "latency_ms": -54, "data": {"e": "depthUpdate", "E": 1761342373614, "s": "BTCUSDT", "U": 79012690515, "u": 79012690558, "b": [], "a": [["111028.03000000", "0.49786000"], ["111028.04000000", "0.29879000"], ["111029.70000000", "0.04082000"], ["111031.24000000", "0.00000000"], ["111031.25000000", "0.25905000"], ["111031.26000000", "0.81640000"], ["111033.06000000", "0.00000000"], ["111033.07000000", "0.00000000"], ["111033.16000000", "0.04577000"], ["111033.74000000", "0.00000000"], ["111034.69000000", "0.00545000"], ["111035.13000000", "0.00725000"], ["111035.18000000", "0.16164000"], ["111035.19000000", "0.20750000"], ["111035.87000000", "0.00005000"], ["111035.88000000", "0.29721000"], ["111037.06000000", "0.04773000"], ["111040.49000000", "0.00000000"], ["111061.05000000", "0.93325000"]]}}
{"type": "orderbook", "local_time": 1761342377890, "event_time": 1761342373714, "latency_ms": 4176, "data": {"e": "depthUpdate", "E": 1761342373714, "s": "BTCUSDT", "U": 79012690559, "u": 79012690586, "b": [["110938.08000000", "0.01410000"], ["99925.00000000", "0.00510000"]], "a": [["111028.03000000", "0.49796000"], ["111028.04000000", "0.29889000"], ["111029.70000000", "0.04082000"], ["111031.24000000", "0.00010000"], ["111031.25000000", "0.25915000"], ["111031.26000000", "0.81635000"], ["111035.13000000", "0.00725000"], ["111035.17000000", "0.00005000"], ["111035.18000000", "0.16164000"], ["111035.19000000", "0.20745000"], ["111035.87000000", "0.00000000"], ["111035.88000000", "0.29716000"], ["111038.14000000", "0.20282000"], ["111040.27000000", "1.44342000"]]}}
{"type": "orderbook", "local_time": 1761342377890, "event_time": 1761342373814, "latency_ms": 4076, "data": {"e": "depthUpdate", "E": 1761342373814, "s": "BTCUSDT", "U": 79012690587, "u": 79012690592, "b": [["110998.27000000", "0.00000000"], ["110707.74000000", "0.00000000"], ["110706.75000000", "0.00572000"]], "a": [["111028.03000000", "0.49791000"], ["111040.26000000", "0.69610000"], ["111040.28000000", "0.00000000"], ["111061.05000000", "0.00000000"]]}}
{"type": "orderbook", "local_time": 1761342377891, "event_time": 1761342373914, "latency_ms": 3977, "data": {"e": "depthUpdate", "E": 1761342373914, "s": "BTCUSDT", "U": 79012690593, "u": 79012690595, "b": [["111000.34000000", "0.00000000"], ["88822.00000000", "0.00537000"]], "a": [["111049.58000000", "0.06073000"]]}}
{"type": "orderbook", "local_time": 1761342377892, "event_time": 1761342374014, "latency_ms": 3878, "data": {"e": "depthUpdate", "E": 1761342374014, "s": "BTCUSDT", "U": 79012690596, "u": 79012690601, "b": [["111000.09000000", "0.00576000"], ["110998.28000000", "0.84681000"], ["88822.00000000", "0.00337000"], ["39970.09000000", "0.00064000"]], "a": [["111028.03000000", "0.57446000"], ["111061.04000000", "0.95872000"]]}}
{"type": "orderbook", "local_time": 1761342377892, "event_time": 1761342374215, "latency_ms": 3677, "data": {"e": "depthUpdate", "E": 1761342374215, "s": "BTCUSDT", "U": 79012690602, "u": 79012690620, "b": [["111028.02000000", "2.00276000"], ["111028.01000000", "0.85657000"], ["111023.32000000", "0.00005000"], ["111015.31000000", "0.00000000"], ["111000.09000000", "0.00000000"], ["110983.35000000", "0.20282000"], ["110881.60000000", "0.00225000"], ["110881.59000000", "0.00000000"], ["110770.24000000", "0.00090000"], ["110770.23000000", "0.00000000"], ["99925.00000000", "0.00510000"]], "a": [["111028.03000000", "0.57265000"], ["111035.26000000", "0.04508000"], ["111041.91000000", "0.00000000"]]}}
{"type": "orderbook", "local_time": 1761342377892, "event_time": 1761342374314, "latency_ms": 3578, "data": {"e": "depthUpdate", "E": 1761342374314, "s": "BTCUSDT", "U": 79012690621, "u": 79012690629, "b": [["111024.71000000", "0.04571000"], ["111024.24000000", "0.04005000"], ["111023.32000000", "0.00000000"], ["111022.47000000", "0.01631000"], ["110999.77000000", "0.00576000"], ["110984.74000000", "0.34582000"]], "a": [["111028.03000000", "0.57270000"], ["111035.18000000", "0.22923000"]]}}
{"type": "orderbook", "local_time": 1761342377892, "event_time": 1761342374415, "latency_ms": 3477, "data": {"e": "depthUpdate", "E": 1761342374415, "s": "BTCUSDT", "U": 79012690630, "u": 79012690633, "b": [["111025.24000000", "0.03449000"], ["111024.71000000", "0.04576000"], ["111022.47000000", "0.01626000"]], "a": []}}
{"type": "orderbook", "local_time": 1761342378462, "event_time": 1761342374514, "latency_ms": 3948, "data": {"e": "depthUpdate", "E": 1761342374514, "s": "BTCUSDT", "U": 79012690634, "u": 79012690636, "b": [["111028.02000000", "2.00270000"]], "a": [["111028.03000000", "0.57265000"], ["111204.37000000", "0.00000000"]]}}
{"type": "orderbook", "local_time": 1761342378462, "event_time": 1761342374614, "latency_ms": 3848, "data": {"e": "depthUpdate", "E": 1761342374614, "s": "BTCUSDT", "U": 79012690637, "u": 79012690640, "b": [["111028.02000000", "2.34363000"], ["111027.23000000", "0.00014000"]], "a": []}}
{"type": "orderbook", "local_time": 1761342378463, "event_time": 1761342374714, "latency_ms": 3749, "data": {"e": "depthUpdate", "E": 1761342374714, "s": "BTCUSDT", "U": 79012690641, "u": 79012690651, "b": [["111028.02000000", "2.34363000"], ["111028.01000000", "0.85652000"], ["111027.75000000", "0.29733000"], ["111027.23000000", "0.00009000"], ["111022.47000000", "0.01631000"]], "a": []}}
{"type": "orderbook", "local_time": 1761342378463, "event_time": 1761342374814, "latency_ms": 3649, "data": {"e": "depthUpdate", "E": 1761342374814, "s": "BTCUSDT", "U": 79012690652, "u": 79012690654, "b": [["99925.00000000", "0.00510000"]], "a": [["111900.00000000", "3.36414000"]]}}
{"type": "orderbook", "local_time": 1761342378463, "event_time": 1761342375014, "latency_ms": 3449, "data": {"e": "depthUpdate", "E": 1761342375014, "s": "BTCUSDT", "U": 79012690655, "u": 79012690656, "b": [["111028.02000000", "2.34374000"]], "a": []}}
{"type": "orderbook", "local_time": 1761342378464, "event_time": 1761342375114, "latency_ms": 3350, "data": {"e": "depthUpdate", "E": 1761342375114, "s": "BTCUSDT", "U": 79012690657, "u": 79012690660, "b": [["111028.02000000", "2.16365000"], ["111025.26000000", "0.18009000"], ["110911.87000000", "0.10519000"], ["110906.75000000", "0.00000000"], ["110774.22000000", "0.00000000"]], "a": []}}
{"type": "orderbook", "local_time": 1761342378464, "event_time": 1761342375214, "latency_ms": 3250, "data": {"e": "depthUpdate", "E": 1761342375214, "s": "BTCUSDT", "U": 79012690661, "u": 79012690677, "b": [["111028.02000000", "2.15758000"], ["111027.22000000", "0.02968000"], ["111025.26000000", "0.18014000"], ["111022.47000000", "0.01626000"], ["110927.43000000", "0.04098000"], ["110920.01000000", "0.08096000"], ["110806.43000000", "0.01891000"], ["39970.09000000", "0.00080000"]], "a": [["111047.26000000", "0.00000000"], ["111047.30000000", "0.01801000"], ["111125.22000000", "0.00100000"], ["111125.23000000", "0.00100000"], ["111125.70000000", "0.00000000"], ["111125.71000000", "0.00000000"]]}}
{"type": "orderbook", "local_time": 1761342378465, "event_time": 1761342375314, "latency_ms": 3151, "data": {"e": "depthUpdate", "E": 1761342375314, "s": "BTCUSDT", "U": 79012690678, "u": 79012690679, "b": [["111028.02000000", "2.16380000"], ["99925.00000000", "0.00520000"]], "a": []}}
{"type": "orderbook", "local_time": 1761342379029, "event_time": 1761342375414, "latency_ms": 3615, "data": {"e": "depthUpdate", "E": 1761342375414, "s": "BTCUSDT", "U": 79012690680, "u": 79012690683, "b": [["110003.38000000", "0.00251000"], ["99925.00000000", "0.00510000"]], "a": [["111049.58000000", "0.00000000"], ["112051.27000000", "0.00247000"]]}}
{"type": "orderbook", "local_time": 1761342379030, "event_time": 1761342375514, "latency_ms": 3516, "data": {"e": "depthUpdate", "E": 1761342375514, "s": "BTCUSDT", "U": 79012690684, "u": 79012690686, "b": [["111023.05000000", "0.01910000"], ["111022.47000000", "0.00005000"], ["111022.13000000", "0.06893000"]], "a": []}}
{"type": "orderbook", "local_time": 1761342379030, "event_time": 1761342375614, "latency_ms": 3416, "data": {"e": "depthUpdate", "E": 1761342375614, "s": "BTCUSDT", "U": 79012690687, "u": 79012690692, "b": [["111024.24000000", "0.04005000"], ["33000.00000000", "3.79445000"]], "a": [["111125.22000000", "0.00000000"], ["111125.23000000", "0.00000000"]]}}
{"type": "orderbook", "local_time": 1761342379030, "event_time": 1761342375714, "latency_ms": 3316, "data": {"e": "depthUpdate", "E": 1761342375714, "s": "BTCUSDT", "U": 79012690693, "u": 79012690701, "b": [["111025.26000000", "0.00005000"], ["110787.44000000", "0.00000000"], ["110554.23000000", "0.03698000"], ["110552.62000000", "0.03698000"], ["110529.83000000", "0.00000000"], ["110527.27000000", "0.00000000"]], "a": [["111049.58000000", "0.05792000"], ["111125.71000000", "0.00100000"], ["111270.19000000", "0.00000000"]]}}
{"type": "orderbook", "local_time": 1761342379031, "event_time": 1761342375814, "latency_ms": 3217, "data": {"e": "depthUpdate", "E": 1761342375814, "s": "BTCUSDT", "U": 79012690702, "u": 79012690708, "b": [["111027.22000000", "0.02968000"], ["111025.26000000", "0.00000000"], ["111023.05000000", "0.01915000"], ["110745.97000000", "0.01711000"], ["110710.58000000", "0.00000000"]], "a": [["111125.70000000", "0.00100000"]]}}
{"type": "orderbook", "local_time": 1761342379031, "event_time": 1761342375914, "latency_ms": 3117, "data": {"e": "depthUpdate", "E": 1761342375914, "s": "BTCUSDT", "U": 79012690709, "u": 79012690712, "b": [["111028.02000000", "2.16385000"], ["110575.86000000", "0.00000000"], ["99925.00000000", "0.00510000"]], "a": []}}
{"type": "orderbook", "local_time": 1761342379031, "event_time": 1761342376014, "latency_ms": 3017, "data": {"e": "depthUpdate", "E": 1761342376014, "s": "BTCUSDT", "U": 79012690713, "u": 79012690722, "b": [["110911.87000000", "0.07996000"], ["110892.83000000", "0.00000000"], ["110881.74000000", "0.00000000"], ["110787.47000000", "0.84842000"], ["110689.01000000", "0.03698000"], ["110686.88000000", "0.02431000"], ["110669.75000000", "0.00000000"], ["110659.73000000", "0.00000000"], ["109599.87000000", "0.02498000"]], "a": [["111064.39000000", "0.00000000"], ["111076.89000000", "0.00000000"], ["111270.16000000", "4.80406000"]]}}
{"type": "orderbook", "local_time": 1761342379032, "event_time": 1761342376114, "latency_ms": 2918, "data": {"e": "depthUpdate", "E": 1761342376114, "s": "BTCUSDT", "U": 79012690723, "u": 79012690728, "b": [["111022.47000000", "0.00013000"], ["110920.01000000", "0.12194000"], ["110908.50000000", "0.00000000"], ["110904.93000000", "0.11994000"], ["110900.33000000", "0.02521000"]], "a": [["111036.76000000", "0.00000000"]]}}
{"type": "orderbook", "local_time": 1761342379032, "event_time": 1761342376214, "latency_ms": 2818, "data": {"e": "depthUpdate", "E": 1761342376214, "s": "BTCUSDT", "U": 79012690729, "u": 79012690735, "b": [["111028.02000000", "2.87695000"], ["110952.01000000", "0.01891000"], ["110892.83000000", "0.00114000"], ["110881.74000000", "0.00229000"], ["110709.00000000", "0.00000000"]], "a": [["111028.03000000", "0.57258000"], ["111064.99000000", "0.00124000"]]}}
{"type": "orderbook", "local_time": 1761342379032, "event_time": 1761342376314, "latency_ms": 2718, "data": {"e": "depthUpdate", "E": 1761342376314, "s": "BTCUSDT", "U": 79012690736, "u": 79012690738, "b": [["50000.00000000", "39.95352000"]], "a": [["111083.08000000", "0.00229000"]]}}
{"type": "orderbook", "local_time": 1761342379033, "event_time": 1761342376414, "latency_ms": 2619, "data": {"e": "depthUpdate", "E": 1761342376414, "s": "BTCUSDT", "U": 79012690739, "u": 79012690740, "b": [["50000.00000000", "39.95322000"]], "a": [["111049.58000000", "0.00000000"]]}}
{"type": "orderbook", "local_time": 1761342379034, "event_time": 1761342376514, "latency_ms": 2520, "data": {"e": "depthUpdate", "E": 1761342376514, "s": "BTCUSDT", "U": 79012690741, "u": 79012690744, "b": [["111028.02000000", "2.87692000"], ["50000.00000000", "39.95262000"]], "a": []}}
{"type": "orderbook", "local_time": 1761342379034, "event_time": 1761342376614, "latency_ms": 2420, "data": {"e": "depthUpdate", "E": 1761342376614, "s": "BTCUSDT", "U": 79012690745, "u": 79012690753, "b": [["111028.02000000", "2.87692000"], ["111019.70000000", "0.00000000"], ["111017.10000000", "0.30389000"], ["111013.90000000", "0.00000000"], ["102145.79000000", "0.00010000"]], "a": [["111035.13000000", "0.00005000"], ["111035.19000000", "0.00000000"]]}}
{"type": "orderbook", "local_time": 1761342379035, "event_time": 1761342376714, "latency_ms": 2321, "data": {"e": "depthUpdate", "E": 1761342376714, "s": "BTCUSDT", "U": 79012690754, "u": 79012690775, "b": [["111028.02000000", "2.90766000"], ["111027.90000000", "0.00020000"], ["111022.13000000", "0.15073000"], ["111019.70000000", "0.00450000"], ["111016.12000000", "0.00000000"], ["110003.38000000", "0.00000000"]], "a": [["111028.03000000", "0.57248000"], ["111028.04000000", "0.29879000"], ["111034.69000000", "0.00545000"], ["111035.13000000", "0.00000000"], ["111035.18000000", "0.43663000"], ["111035.26000000", "0.04513000"], ["111045.29000000", "0.00000000"], ["111047.29000000", "0.00450000"], ["111049.58000000", "0.05817000"], ["112051.27000000", "0.00000000"]]}}
{"type": "orderbook", "local_time": 1761342379036, "event_time": 1761342376814, "latency_ms": 2222, "data": {"e": "depthUpdate", "E": 1761342376814, "s": "BTCUSDT", "U": 79012690776, "u": 79012690796, "b": [["111028.02000000", "2.90766000"], ["111028.00000000", "2.47747000"], ["111027.90000000", "0.00000000"], ["111027.75000000", "0.29738000"], ["111027.22000000", "0.02978000"], ["111022.13000000", "0.15078000"]], "a": [["111035.16000000", "0.00720000"], ["111036.76000000", "0.00044000"]]}}
{"type": "orderbook", "local_time": 1761342379036, "event_time": 1761342376914, "latency_ms": 2122, "data": {"e": "depthUpdate", "E": 1761342376914, "s": "BTCUSDT", "U": 79012690797, "u": 79012690805, "b": [["99925.00000000", "0.00510000"]], "a": [["111028.03000000", "0.57246000"], ["111028.04000000", "0.29884000"], ["111034.69000000", "0.00545000"], ["111035.16000000", "0.00725000"], ["111035.26000000", "0.04508000"]]}}
{"type": "orderbook", "local_time": 1761342379037, "event_time": 1761342377014, "latency_ms": 2023, "data": {"e": "depthUpdate", "E": 1761342377014, "s": "BTCUSDT", "U": 79012690806, "u": 79012690808, "b": [["110652.21000000", "0.02698000"], ["88822.00000000", "0.00337000"]], "a": []}}
{"type": "orderbook", "local_time": 1761342379044, "event_time": 1761342377114, "latency_ms": 1930, "data": {"e": "depthUpdate", "E": 1761342377114, "s": "BTCUSDT", "U": 79012690809, "u": 79012690811, "b": [["110919.73000000", "0.08096000"], ["110904.93000000", "0.07996000"], ["110774.23000000", "0.00000000"]], "a": []}}
{"type": "orderbook", "local_time": 1761342379044, "event_time": 1761342377214, "latency_ms": 1830, "data": {"e": "depthUpdate", "E": 1761342377214, "s": "BTCUSDT", "U": 79012690812, "u": 79012690814, "b": [["110808.43000000", "0.01891000"], ["110713.55000000", "0.02598000"], ["102145.79000000", "0.00000000"]], "a": []}}
{"type": "orderbook", "local_time": 1761342379045, "event_time": 1761342377314, "latency_ms": 1731, "data": {"e": "depthUpdate", "E": 1761342377314, "s": "BTCUSDT", "U": 79012690815, "u": 79012690815, "b": [["110640.86000000", "0.00000000"]], "a": []}}
{"type": "orderbook", "local_time": 1761342379045, "event_time": 1761342377414, "latency_ms": 1631, "data": {"e": "depthUpdate", "E": 1761342377414, "s": "BTCUSDT", "U": 79012690816, "u": 79012690821, "b": [["111017.10000000", "0.00000000"], ["111013.90000000", "0.30390000"], ["110998.28000000", "0.00000000"], ["110628.92000000", "0.02431000"], ["99925.00000000", "0.00520000"]], "a": [["111028.03000000", "0.57253000"], ["111061.04000000", "0.00000000"]]}}
{"type": "orderbook", "local_time": 1761342379046, "event_time": 1761342377514, "latency_ms": 1532, "data": {"e": "depthUpdate", "E": 1761342377514, "s": "BTCUSDT", "U": 79012690822, "u": 79012690830, "b": [["111028.02000000", "2.52693000"], ["111022.13000000", "0.06898000"], ["111012.79000000", "0.00000000"], ["99925.00000000", "0.00510000"]], "a": [["111028.03000000", "0.49598000"], ["111041.66000000", "0.00000000"]]}}
{"type": "orderbook", "local_time": 1761342379046, "event_time": 1761342377614, "latency_ms": 1432, "data": {"e": "depthUpdate", "E": 1761342377614, "s": "BTCUSDT", "U": 79012690831, "u": 79012690833, "b": [["110998.33000000", "0.84681000"], ["110665.31000000", "0.00000000"]], "a": [["111061.40000000", "0.97119000"]]}}
{"type": "orderbook", "local_time": 1761342379047, "event_time": 1761342377714, "latency_ms": 1333, "data": {"e": "depthUpdate", "E": 1761342377714, "s": "BTCUSDT", "U": 79012690834, "u": 79012690836, "b": [["111028.02000000", "2.52733000"], ["110717.34000000", "0.01711000"]], "a": []}}
{"type": "orderbook", "local_time": 1761342379047, "event_time": 1761342377814, "latency_ms": 1233, "data": {"e": "depthUpdate", "E": 1761342377814, "s": "BTCUSDT", "U": 79012690837, "u": 79012690842, "b": [["110999.77000000", "0.00000000"], ["110712.89000000", "0.00000000"], ["110645.60000000", "0.00000000"]], "a": [["111125.37000000", "0.00100000"], ["111125.70000000", "0.00000000"], ["111125.71000000", "0.00000000"]]}}
{"type": "orderbook", "local_time": 1761342379356, "event_time": 1761342377914, "latency_ms": 1442, "data": {"e": "depthUpdate", "E": 1761342377914, "s": "BTCUSDT", "U": 79012690843, "u": 79012690847, "b": [["111018.59000000", "0.01604000"], ["111000.66000000", "0.00576000"], ["110745.78000000", "0.01711000"], ["110675.64000000", "0.01711000"]], "a": [["111125.38000000", "0.00100000"]]}}
{"type": "orderbook", "local_time": 1761342379357, "event_time": 1761342378014, "latency_ms": 1343, "data": {"e": "depthUpdate", "E": 1761342378014, "s": "BTCUSDT", "U": 79012690848, "u": 79012690853, "b": [["111028.02000000", "2.53517000"], ["99925.00000000", "0.00510000"]], "a": [["111036.76000000", "0.00000000"]]}}
{"type": "orderbook", "local_time": 1761342379357, "event_time": 1761342378114, "latency_ms": 1243, "data": {"e": "depthUpdate", "E": 1761342378114, "s": "BTCUSDT", "U": 79012690854, "u": 79012690857, "b": [["111019.70000000", "0.00000000"], ["111017.10000000", "0.00450000"], ["110905.62000000", "0.19452000"], ["110903.70000000", "0.00000000"]], "a": [["111028.03000000", "0.49605000"]]}}
{"type": "orderbook", "local_time": 1761342379358, "event_time": 1761342378314, "latency_ms": 1044, "data": {"e": "depthUpdate", "E": 1761342378314, "s": "BTCUSDT", "U": 79012690858, "u": 79012690858, "b": [["110707.74000000", "0.00572000"], ["110706.75000000", "0.00000000"]], "a": []}}
{"type": "orderbook", "local_time": 1761342379358, "event_time": 1761342378414, "latency_ms": 944, "data": {"e": "depthUpdate", "E": 1761342378414, "s": "BTCUSDT", "U": 79012690859, "u": 79012690864, "b": [["111028.02000000", "2.52962000"], ["110728.02000000", "0.00000000"], ["110669.62000000", "0.00000000"], ["110622.55000000", "0.00000000"], ["110620.88000000", "0.00000000"]], "a": []}}
{"type": "orderbook", "local_time": 1761342379359, "event_time": 1761342378514, "latency_ms": 845, "data": {"e": "depthUpdate", "E": 1761342378514, "s": "BTCUSDT", "U": 79012690865, "u": 79012690870, "b": [["111018.60000000", "0.00255000"], ["111016.09000000", "0.30390000"], ["111013.90000000", "0.00000000"], ["110743.67000000", "0.02198000"], ["110696.13000000", "0.02198000"], ["110695.73000000", "0.02198000"]], "a": [["111028.04000000", "0.30010000"]]}}
{"type": "orderbook", "local_time": 1761342379359, "event_time": 1761342378614, "latency_ms": 745, "data": {"e": "depthUpdate", "E": 1761342378614, "s": "BTCUSDT", "U": 79012690871, "u": 79012690873, "b": [["111028.02000000", "2.52922000"]], "a": [["111122.47000000", "0.00000000"]]}}
{"type": "orderbook", "local_time": 1761342379360, "event_time": 1761342378714, "latency_ms": 646, "data": {"e": "depthUpdate", "E": 1761342378714, "s": "BTCUSDT", "U": 79012690874, "u": 79012690874, "b": [], "a": [["111122.40000000", "0.03400000"]]}}
{"type": "orderbook", "local_time": 1761342379360, "event_time": 1761342378814, "latency_ms": 546, "data": {"e": "depthUpdate", "E": 1761342378814, "s": "BTCUSDT", "U": 79012690875, "u": 79012690875, "b": [["42000.00000000", "1.36834000"]], "a": []}}
{"type": "orderbook", "local_time": 1761342379360, "event_time": 1761342379014, "latency_ms": 346, "data": {"e": "depthUpdate", "E": 1761342379014, "s": "BTCUSDT", "U": 79012690876, "u": 79012690879, "b": [["99925.00000000", "0.00510000"]], "a": [["111036.76000000", "0.00044000"], ["111108.64000000", "0.00000000"]]}}
{"type": "orderbook", "local_time": 1761342379361, "event_time": 1761342379114, "latency_ms": 247, "data": {"e": "depthUpdate", "E": 1761342379114, "s": "BTCUSDT", "U": 79012690880, "u": 79012690889, "b": [["111028.02000000", "2.98708000"], ["111013.59000000", "0.06519000"], ["99925.00000000", "0.00510000"]], "a": [["111042.46000000", "0.04105000"]]}}
{"type": "orderbook", "local_time": 1761342379361, "event_time": 1761342379214, "latency_ms": 147, "data": {"e": "depthUpdate", "E": 1761342379214, "s": "BTCUSDT", "U": 79012690890, "u": 79012690892, "b": [["110728.02000000", "0.00000000"], ["107521.01000000", "0.00000000"]], "a": []}}
{"type": "orderbook", "local_time": 1761342379362, "event_time": 1761342379314, "latency_ms": 48, "data": {"e": "depthUpdate", "E": 1761342379314, "s": "BTCUSDT", "U": 79012690893, "u": 79012690895, "b": [["111000.66000000", "0.00000000"], ["110999.72000000", "0.00576000"]], "a": [["111042.46000000", "0.11187000"]]}}
{"type": "orderbook", "local_time": 1761342379362, "event_time": 1761342379414, "latency_ms": -52, "data": {"e": "depthUpdate", "E": 1761342379414, "s": "BTCUSDT", "U": 79012690896, "u": 79012690898, "b": [["111028.02000000", "2.98723000"], ["111018.59000000", "0.01588000"], ["110999.72000000", "0.00000000"]], "a": []}}
{"type": "orderbook", "local_time": 1761342379438, "event_time": 1761342379514, "latency_ms": -76, "data": {"e": "depthUpdate", "E": 1761342379514, "s": "BTCUSDT", "U": 79012690899, "u": 79012690901, "b": [["111028.02000000", "2.98780000"], ["111001.15000000", "0.00576000"]], "a": []}}
{"type": "orderbook", "local_time": 1761342379534, "event_time": 1761342379614, "latency_ms": -80, "data": {"e": "depthUpdate", "E": 1761342379614, "s": "BTCUSDT", "U": 79012690902, "u": 79012690904, "b": [["111001.15000000", "0.00000000"], ["99925.00000000", "0.00510000"]], "a": []}}
{"type": "orderbook", "local_time": 1761342379637, "event_time": 1761342379714, "latency_ms": -77, "data": {"e": "depthUpdate", "E": 1761342379714, "s": "BTCUSDT", "U": 79012690905, "u": 79012690905, "b": [["111000.04000000", "0.00576000"]], "a": []}}
{"type": "orderbook", "local_time": 1761342379735, "event_time": 1761342379814, "latency_ms": -79, "data": {"e": "depthUpdate", "E": 1761342379814, "s": "BTCUSDT", "U": 79012690906, "u": 79012690906, "b": [], "a": [["125199.00000000", "0.00000000"]]}}
{"type": "orderbook", "local_time": 1761342379950, "event_time": 1761342380014, "latency_ms": -64, "data": {"e": "depthUpdate", "E": 1761342380014, "s": "BTCUSDT", "U": 79012690907, "u": 79012690913, "b": [["88822.00000000", "0.00337000"]], "a": [["111047.30000000", "0.00000000"], ["111047.87000000", "0.01801000"], ["111108.64000000", "0.13292000"], ["111125.86000000", "0.02500000"], ["111125.95000000", "0.00000000"]]}}
{"type": "orderbook", "local_time": 1761342380038, "event_time": 1761342380115, "latency_ms": -77, "data": {"e": "depthUpdate", "E": 1761342380115, "s": "BTCUSDT", "U": 79012690914, "u": 79012690916, "b": [["99925.00000000", "0.00510000"]], "a": [["111036.76000000", "0.00000000"]]}}
{"type": "orderbook", "local_time": 1761342380136, "event_time": 1761342380214, "latency_ms": -78, "data": {"e": "depthUpdate", "E": 1761342380214, "s": "BTCUSDT", "U": 79012690917, "u": 79012690932, "b": [["111028.02000000", "2.23421000"], ["111000.04000000", "0.00000000"], ["99925.00000000", "0.00510000"]], "a": [["111028.03000000", "0.49591000"], ["111122.40000000", "0.00000000"], ["111123.35000000", "0.03400000"], ["111125.37000000", "0.00000000"], ["111125.38000000", "0.00000000"], ["111125.86000000", "0.00000000"], ["111125.90000000", "0.00100000"], ["111125.91000000", "0.00100000"], ["111126.81000000", "0.02500000"]]}}
{"type": "orderbook", "local_time": 1761342380235, "event_time": 1761342380314, "latency_ms": -79, "data": {"e": "depthUpdate", "E": 1761342380314, "s": "BTCUSDT", "U": 79012690933, "u": 79012690933, "b": [["110999.77000000", "0.00576000"]], "a": []}}
{"type": "orderbook", "local_time": 1761342380337, "event_time": 1761342380414, "latency_ms": -77, "data": {"e": "depthUpdate", "E": 1761342380414, "s": "BTCUSDT", "U": 79012690934, "u": 79012690935, "b": [["111028.02000000", "2.23522000"], ["106724.41000000", "0.00000000"]], "a": []}}
{"type": "orderbook", "local_time": 1761342380437, "event_time": 1761342380514, "latency_ms": -77, "data": {"e": "depthUpdate", "E": 1761342380514, "s": "BTCUSDT", "U": 79012690936, "u": 79012690936, "b": [], "a": [["111036.76000000", "0.00044000"]]}}
{"type": "orderbook", "local_time": 1761342380536, "event_time": 1761342380614, "latency_ms": -78, "data": {"e": "depthUpdate", "E": 1761342380614, "s": "BTCUSDT", "U": 79012690937, "u": 79012690938, "b": [["33000.00000000", "3.79445000"]], "a": []}}
{"type": "orderbook", "local_time": 1761342380637, "event_time": 1761342380714, "latency_ms": -77, "data": {"e": "depthUpdate", "E": 1761342380714, "s": "BTCUSDT", "U": 79012690939, "u": 79012690941, "b": [["99925.00000000", "0.00510000"]], "a": [["111028.03000000", "0.49559000"]]}}
{"type": "orderbook", "local_time": 1761342380736, "event_time": 1761342380814, "latency_ms": -78, "data": {"e": "depthUpdate", "E": 1761342380814, "s": "BTCUSDT", "U": 79012690942, "u": 79012690945, "b": [["42000.00000000", "1.36734000"], ["39970.09000000", "0.00096000"]], "a": [["111028.03000000", "0.49289000"], ["111028.04000000", "0.29884000"]]}}
{"type": "orderbook", "local_time": 1761342380835, "event_time": 1761342380914, "latency_ms": -79, "data": {"e": "depthUpdate", "E": 1761342380914, "s": "BTCUSDT", "U": 79012690946, "u": 79012690948, "b": [["111028.02000000", "2.23528000"], ["111028.01000000", "0.85778000"]], "a": []}}
{"type": "orderbook", "local_time": 1761342380937, "event_time": 1761342381014, "latency_ms": -77, "data": {"e": "depthUpdate", "E": 1761342381014, "s": "BTCUSDT", "U": 79012690949, "u": 79012690954, "b": [["111005.25000000", "0.00250000"], ["111000.80000000", "0.00000000"], ["110686.82000000", "0.03698000"], ["110653.49000000", "0.00000000"]], "a": [["111028.03000000", "0.49229000"]]}}
{"type": "orderbook", "local_time": 1761342381036, "event_time": 1761342381114, "latency_ms": -78, "data": {"e": "depthUpdate", "E": 1761342381114, "s": "BTCUSDT", "U": 79012690955, "u": 79012690968, "b": [["111019.69000000", "0.00000000"], ["111016.09000000", "0.00000000"], ["111015.31000000", "0.00010000"], ["111013.90000000", "0.30390000"], ["111013.34000000", "0.11267000"], ["110999.77000000", "0.00000000"], ["110911.87000000", "0.03998000"], ["110881.61000000", "0.00225000"], ["110881.60000000", "0.00000000"], ["110770.25000000", "0.00090000"], ["110770.24000000", "0.00000000"], ["99925.00000000", "0.00510000"]], "a": [["111028.03000000", "0.49220000"]]}}
{"type": "orderbook", "local_time": 1761342381141, "event_time": 1761342381214, "latency_ms": -73, "data": {"e": "depthUpdate", "E": 1761342381214, "s": "BTCUSDT", "U": 79012690969, "u": 79012690975, "b": [["111022.13000000", "0.03420000"], ["110917.43000000", "0.03998000"], ["99925.00000000", "0.00510000"], ["60000.00000000", "56.85876000"]], "a": [["111049.58000000", "0.00000000"]]}}
{"type": "orderbook", "local_time": 1761342381234, "event_time": 1761342381314, "latency_ms": -80, "data": {"e": "depthUpdate", "E": 1761342381314, "s": "BTCUSDT", "U": 79012690976, "u": 79012690986, "b": [["110999.81000000", "0.00576000"], ["110583.51000000", "0.02698000"], ["110583.14000000", "0.02698000"], ["110582.77000000", "0.02698000"], ["110581.39000000", "0.02714000"], ["110579.44000000", "0.02698000"], ["110530.58000000", "0.00000000"], ["110529.91000000", "0.00000000"], ["110523.39000000", "0.00000000"], ["110523.02000000", "0.00000000"], ["110522.66000000", "0.00000000"]], "a": []}}
{"type": "orderbook", "local_time": 1761342381335, "event_time": 1761342381414, "latency_ms": -79, "data": {"e": "depthUpdate", "E": 1761342381414, "s": "BTCUSDT", "U": 79012690987, "u": 79012690987, "b": [["110999.81000000", "0.00000000"]], "a": []}}
{"type": "orderbook", "local_time": 1761342381553, "event_time": 1761342381514, "latency_ms": 39, "data": {"e": "depthUpdate", "E": 1761342381514, "s": "BTCUSDT", "U": 79012690988, "u": 79012691008, "b": [["111028.02000000", "2.23427000"], ["111026.91000000", "0.00099000"], ["111025.25000000", "0.00198000"], ["111023.58000000", "0.00360000"], ["111021.36000000", "0.00540000"], ["111018.59000000", "0.01588000"], ["111016.92000000", "0.00721000"], ["111015.31000000", "0.00000000"], ["111001.02000000", "0.00576000"], ["110694.22000000", "0.02198000"], ["110627.88000000", "0.00000000"]], "a": [["111029.14000000", "0.00158000"], ["111030.80000000", "0.00198000"], ["111032.47000000", "0.00365000"], ["111034.69000000", "0.00545000"], ["111037.46000000", "0.00396000"], ["111039.13000000", "0.00720000"], ["112023.45000000", "0.00000000"]]}}
{"type": "orderbook", "local_time": 1761342381663, "event_time": 1761342381614, "latency_ms": 49, "data": {"e": "depthUpdate", "E": 1761342381614, "s": "BTCUSDT", "U": 79012691009, "u": 79012691011, "b": [["111028.02000000", "2.23417000"], ["99925.00000000", "0.00510000"]], "a": []}}
{"type": "orderbook", "local_time": 1761342381664, "event_time": 1761342381715, "latency_ms": -51, "data": {"e": "depthUpdate", "E": 1761342381715, "s": "BTCUSDT", "U": 79012691012, "u": 79012691020, "b": [["111001.02000000", "0.00000000"], ["110553.20000000", "0.03698000"], ["110551.84000000", "0.03698000"], ["110550.09000000", "0.03698000"], ["110532.95000000", "0.00000000"], ["110530.09000000", "0.00000000"], ["110527.22000000", "0.00000000"], ["99925.00000000", "0.00520000"], ["60000.00000000", "56.85866000"]], "a": []}}
{"type": "orderbook", "local_time": 1761342389935, "event_time": 1761342381814, "latency_ms": 8121, "data": {"e": "depthUpdate", "E": 1761342381814, "s": "BTCUSDT", "U": 79012691021, "u": 79012691023, "b": [["110999.75000000", "0.00576000"], ["99925.00000000", "0.00510000"]], "a": [["111053.27000000", "0.00044000"]]}}
{"type": "orderbook", "local_time": 1761342389936, "event_time": 1761342382014, "latency_ms": 7922, "data": {"e": "depthUpdate", "E": 1761342382014, "s": "BTCUSDT", "U": 79012691024, "u": 79012691025, "b": [["110787.47000000", "0.00000000"]], "a": [["111270.16000000", "0.00000000"]]}}
{"type": "orderbook", "local_time": 1761342389937, "event_time": 1761342382114, "latency_ms": 7823, "data": {"e": "depthUpdate", "E": 1761342382114, "s": "BTCUSDT", "U": 79012691026, "u": 79012691033, "b": [["111028.02000000", "2.22697000"], ["111027.14000000", "0.00720000"]], "a": [["111035.16000000", "0.00005000"], ["111035.18000000", "0.22918000"], ["111036.76000000", "0.00000000"], ["111053.27000000", "0.00000000"], ["111368.93000000", "0.48717000"]]}}
{"type": "orderbook", "local_time": 1761342389937, "event_time": 1761342382214, "latency_ms": 7723, "data": {"e": "depthUpdate", "E": 1761342382214, "s": "BTCUSDT", "U": 79012691034, "u": 79012691055, "b": [["111028.02000000", "2.22702000"], ["111028.01000000", "0.85783000"], ["111027.22000000", "0.02978000"], ["111027.14000000", "0.00725000"], ["111022.13000000", "0.03415000"], ["109599.87000000", "0.02499000"], ["102145.79000000", "0.00010000"], ["99925.00000000", "0.00510000"]], "a": [["111028.03000000", "0.49215000"], ["111028.04000000", "0.29879000"], ["111034.69000000", "0.00545000"], ["111035.16000000", "0.00000000"], ["111035.26000000", "0.04513000"], ["111035.53000000", "0.00720000"], ["111035.57000000", "0.20745000"]]}}
{"type": "orderbook", "local_time": 1761342389938, "event_time": 1761342382314, "latency_ms": 7624, "data": {"e": "depthUpdate", "E": 1761342382314, "s": "BTCUSDT", "U": 79012691056, "u": 79012691064, "b": [["110787.55000000", "0.84842000"]], "a": [["111028.03000000", "0.49225000"], ["111028.04000000", "0.29846000"], ["111035.26000000", "0.04513000"], ["111270.05000000", "4.70390000"]]}}
{"type": "orderbook", "local_time": 1761342390780, "event_time": 1761342382614, "latency_ms": 8166, "data": {"e": "depthUpdate", "E": 1761342382614, "s": "BTCUSDT", "U": 79012691065, "u": 79012691067, "b": [], "a": [["111122.40000000", "0.03400000"], ["111123.35000000", "0.00000000"], ["114126.85000000", "0.00000000"]]}}
{"type": "orderbook", "local_time": 1761342390781, "event_time": 1761342382714, "latency_ms": 8067, "data": {"e": "depthUpdate", "E": 1761342382714, "s": "BTCUSDT", "U": 79012691068, "u": 79012691072, "b": [["111028.02000000", "2.22586000"], ["102145.79000000", "0.00000000"], ["99925.00000000", "0.00510000"]], "a": [["111028.03000000", "0.49215000"]]}}
{"type": "orderbook", "local_time": 1761342390783, "event_time": 1761342382914, "latency_ms": 7869, "data": {"e": "depthUpdate", "E": 1761342382914, "s": "BTCUSDT", "U": 79012691073, "u": 79012691076, "b": [], "a": [["111028.03000000", "0.49208000"], ["111053.27000000", "0.00044000"], ["111071.99000000", "0.00000000"], ["111073.58000000", "0.34582000"]]}}
{"type": "orderbook", "local_time": 1761342390783, "event_time": 1761342383014, "latency_ms": 7769, "data": {"e": "depthUpdate", "E": 1761342383014, "s": "BTCUSDT", "U": 79012691077, "u": 79012691079, "b": [["88822.00000000", "0.00337000"]], "a": [["111036.76000000", "0.00044000"]]}}
{"type": "orderbook", "local_time": 1761342390784, "event_time": 1761342383114, "latency_ms": 7670, "data": {"e": "depthUpdate", "E": 1761342383114, "s": "BTCUSDT", "U": 79012691080, "u": 79012691084, "b": [["111028.02000000", "2.21686000"], ["111007.75000000", "0.40561000"], ["110999.75000000", "0.00000000"]], "a": [["111028.03000000", "0.49150000"], ["111049.25000000", "0.13409000"]]}}
{"type": "orderbook", "local_time": 1761342390784, "event_time": 1761342383214, "latency_ms": 7570, "data": {"e": "depthUpdate", "E": 1761342383214, "s": "BTCUSDT", "U": 79012691085, "u": 79012691096, "b": [["110999.72000000", "0.00576000"], ["110740.38000000", "0.02498000"], ["110740.37000000", "0.07494000"], ["110670.43000000", "0.00000000"], ["110668.79000000", "0.00000000"], ["110668.13000000", "0.00000000"], ["110667.86000000", "0.00000000"], ["99925.00000000", "0.00510000"]], "a": [["111028.03000000", "0.49135000"]]}}
{"type": "orderbook", "local_time": 1761342390785, "event_time": 1761342383314, "latency_ms": 7471, "data": {"e": "depthUpdate", "E": 1761342383314, "s": "BTCUSDT", "U": 79012691097, "u": 79012691098, "b": [["99925.00000000", "0.00510000"]], "a": []}}
{"type": "orderbook", "local_time": 1761342390785, "event_time": 1761342383514, "latency_ms": 7271, "data": {"e": "depthUpdate", "E": 1761342383514, "s": "BTCUSDT", "U": 79012691099, "u": 79012691100, "b": [["110999.72000000", "0.00000000"]], "a": [["111028.03000000", "0.49128000"]]}}
{"type": "orderbook", "local_time": 1761342390786, "event_time": 1761342383614, "latency_ms": 7172, "data": {"e": "depthUpdate", "E": 1761342383614, "s": "BTCUSDT", "U": 79012691101, "u": 79012691102, "b": [["110999.84000000", "0.00000000"]], "a": []}}
{"type": "orderbook", "local_time": 1761342390786, "event_time": 1761342383714, "latency_ms": 7072, "data": {"e": "depthUpdate", "E": 1761342383714, "s": "BTCUSDT", "U": 79012691103, "u": 79012691104, "b": [["111000.03000000", "0.00576000"]], "a": [["111028.03000000", "0.49204000"]]}}
{"type": "orderbook", "local_time": 1761342390786, "event_time": 1761342383814, "latency_ms": 6972, "data": {"e": "depthUpdate", "E": 1761342383814, "s": "BTCUSDT", "U": 79012691105, "u": 79012691112, "b": [["111028.02000000", "2.21685000"], ["110998.33000000", "0.00000000"], ["110952.59000000", "0.01410000"], ["110938.08000000", "0.00000000"], ["110913.43000000", "0.03998000"], ["99925.00000000", "0.00520000"]], "a": [["111061.40000000", "0.00000000"]]}}
{"type": "orderbook", "local_time": 1761342390787, "event_time": 1761342383914, "latency_ms": 6873, "data": {"e": "depthUpdate", "E": 1761342383914, "s": "BTCUSDT", "U": 79012691113, "u": 79012691121, "b": [["111018.60000000", "0.00255000"], ["111016.09000000", "0.30390000"], ["111013.90000000", "0.00000000"], ["110952.59000000", "0.00000000"], ["110938.08000000", "0.01410000"], ["110937.51000000", "0.03600000"], ["99925.00000000", "0.00510000"]], "a": [["111028.03000000", "0.49185000"]]}}
{"type": "orderbook", "local_time": 1761342390787, "event_time": 1761342384014, "latency_ms": 6773, "data": {"e": "depthUpdate", "E": 1761342384014, "s": "BTCUSDT", "U": 79012691122, "u": 79012691124, "b": [["111028.02000000", "2.21677000"]], "a": [["111028.03000000", "0.49101000"]]}}
{"type": "orderbook", "local_time": 1761342390787, "event_time": 1761342384115, "latency_ms": 6672, "data": {"e": "depthUpdate", "E": 1761342384115, "s": "BTCUSDT", "U": 79012691125, "u": 79012691133, "b": [["111028.02000000", "2.92927000"], ["110996.73000000", "0.84682000"], ["110938.08000000", "0.00000000"], ["103367.00000000", "0.00000000"]], "a": [["111036.76000000", "0.00000000"], ["111053.27000000", "0.00000000"], ["111061.27000000", "0.97323000"], ["111122.40000000", "0.00000000"], ["111122.41000000", "0.03400000"]]}}
{"type": "orderbook", "local_time": 1761342390788, "event_time": 1761342384314, "latency_ms": 6474, "data": {"e": "depthUpdate", "E": 1761342384314, "s": "BTCUSDT", "U": 79012691134, "u": 79012691137, "b": [["111016.09000000", "0.00000000"], ["111013.90000000", "0.30390000"], ["99925.00000000", "0.00510000"]], "a": [["115155.86000000", "0.00000000"]]}}
{"type": "orderbook", "local_time": 1761342390789, "event_time": 1761342384414, "latency_ms": 6375, "data": {"e": "depthUpdate", "E": 1761342384414, "s": "BTCUSDT", "U": 79012691138, "u": 79012691140, "b": [["111028.02000000", "2.92843000"], ["99925.00000000", "0.00510000"]], "a": []}}
{"type": "orderbook", "local_time": 1761342390790, "event_time": 1761342384514, "latency_ms": 6276, "data": {"e": "depthUpdate", "E": 1761342384514, "s": "BTCUSDT", "U": 79012691141, "u": 79012691147, "b": [["111028.02000000", "2.92827000"]], "a": [["111031.25000000", "0.25912000"]]}}
{"type": "orderbook", "local_time": 1761342390791, "event_time": 1761342384614, "latency_ms": 6177, "data": {"e": "depthUpdate", "E": 1761342384614, "s": "BTCUSDT", "U": 79012691148, "u": 79012691218, "b": [["111028.02000000", "2.21684000"], ["111028.01000000", "0.85783000"], ["111024.71000000", "0.00005000"], ["111017.10000000", "0.00000000"], ["111015.31000000", "0.00460000"], ["111012.63000000", "0.00000000"], ["111012.03000000", "0.00000000"], ["111000.03000000", "0.00000000"], ["110999.73000000", "0.13511000"], ["110984.74000000", "0.00000000"], ["110881.62000000", "0.00225000"], ["110881.61000000", "0.00000000"], ["110770.26000000", "0.00090000"], ["110770.25000000", "0.00000000"]], "a": [["111028.03000000", "1.50842000"], ["111028.04000000", "0.29841000"], ["111041.76000000", "0.00450000"], ["111047.29000000", "0.00000000"], ["111054.99000000", "0.00000000"], ["111055.45000000", "0.22535000"], ["111120.83000000", "0.00000000"], ["111120.94000000", "0.22535000"]]}}
{"type": "orderbook", "local_time": 1761342390791, "event_time": 1761342384714, "latency_ms": 6077, "data": {"e": "depthUpdate", "E": 1761342384714, "s": "BTCUSDT", "U": 79012691219, "u": 79012691231, "b": [["111028.02000000", "2.21704000"], ["111025.24000000", "0.03449000"], ["111024.71000000", "0.00000000"], ["111024.52000000", "0.04571000"], ["111022.13000000", "0.03420000"], ["110984.55000000", "0.34582000"]], "a": [["111028.03000000", "1.50849000"]]}}
{"type": "orderbook", "local_time": 1761342390792, "event_time": 1761342384814, "latency_ms": 5978, "data": {"e": "depthUpdate", "E": 1761342384814, "s": "BTCUSDT", "U": 79012691232, "u": 79012691255, "b": [["111028.02000000", "2.21709000"], ["111028.01000000", "0.85788000"], ["111025.24000000", "0.03449000"], ["111024.52000000", "0.04576000"], ["111022.13000000", "0.03415000"], ["111007.75000000", "0.00000000"], ["110999.79000000", "0.00576000"], ["110787.55000000", "0.00000000"]], "a": [["111028.03000000", "1.65240000"], ["111028.04000000", "0.29821000"], ["111096.29000000", "0.00044000"], ["111270.05000000", "0.00000000"]]}}
{"type": "orderbook", "local_time": 1761342391495, "event_time": 1761342384914, "latency_ms": 6581, "data": {"e": "depthUpdate", "E": 1761342384914, "s": "BTCUSDT", "U": 79012691256, "u": 79012691311, "b": [["111028.02000000", "1.86117000"], ["111028.01000000", "0.85803000"], ["111024.64000000", "0.20745000"], ["111024.34000000", "0.04670000"], ["111023.05000000", "0.01665000"], ["111016.08000000", "0.00000000"], ["111015.31000000", "0.00010000"], ["111013.90000000", "0.00000000"], ["111013.89000000", "0.00000000"], ["111013.35000000", "0.00450000"], ["111012.48000000", "0.01801000"], ["111012.03000000", "0.00005000"], ["111009.24000000", "0.30391000"], ["111000.80000000", "0.00250000"], ["110999.79000000", "0.00000000"], ["99925.00000000", "0.00510000"]], "a": [["111028.03000000", "2.28528000"], ["111028.04000000", "0.29811000"], ["111033.30000000", "0.04773000"], ["111033.40000000", "0.29716000"], ["111034.61000000", "0.20282000"], ["111035.88000000", "0.00000000"], ["111037.06000000", "0.00000000"], ["111037.62000000", "0.06748000"], ["111042.34000000", "0.00000000"], ["111044.11000000", "0.01801000"], ["111047.87000000", "0.00000000"], ["111054.90000000", "0.00022000"], ["111055.45000000", "0.00000000"], ["111068.01000000", "0.00000000"], ["111092.18000000", "0.00000000"], ["111092.89000000", "0.13524000"], ["111118.83000000", "0.00000000"], ["111118.95000000", "0.22535000"], ["111119.35000000", "0.22544000"], ["111120.94000000", "0.00000000"], ["111368.93000000", "0.48717000"]]}}
{"type": "orderbook", "local_time": 1761342391496, "event_time": 1761342385014, "latency_ms": 6482, "data": {"e": "depthUpdate", "E": 1761342385014, "s": "BTCUSDT", "U": 79012691312, "u": 79012691346, "b": [["111028.02000000", "1.86037000"], ["111028.01000000", "0.85813000"], ["111025.24000000", "0.03449000"], ["111024.64000000", "0.20750000"], ["111024.52000000", "0.04576000"], ["111024.34000000", "0.04675000"], ["111024.24000000", "0.04000000"], ["111023.05000000", "0.01660000"], ["110782.24000000", "0.84846000"]], "a": [["111028.03000000", "2.28860000"], ["111031.95000000", "0.00250000"], ["111033.16000000", "0.04577000"], ["111033.30000000", "0.04778000"], ["111033.39000000", "0.32059000"], ["111033.40000000", "0.29721000"], ["111034.61000000", "0.20287000"], ["111034.69000000", "0.00540000"], ["111035.18000000", "0.00000000"], ["111035.26000000", "0.04508000"], ["111041.77000000", "0.00000000"], ["111044.11000000", "0.00000000"], ["111044.12000000", "0.01806000"], ["111054.20000000", "0.00000000"], ["111118.95000000", "0.00000000"], ["111119.01000000", "0.22535000"], ["111269.98000000", "4.87963000"]]}}
{"type": "orderbook", "local_time": 1761342391496, "event_time": 1761342385114, "latency_ms": 6382, "data": {"e": "depthUpdate", "E": 1761342385114, "s": "BTCUSDT", "U": 79012691347, "u": 79012691364, "b": [["111028.02000000", "1.69299000"], ["111023.05000000", "0.00000000"], ["111022.13000000", "0.05142000"]], "a": [["111028.03000000", "2.28865000"], ["111033.30000000", "0.04778000"], ["111033.38000000", "0.00005000"], ["111033.39000000", "0.32064000"], ["111034.61000000", "0.20282000"], ["111035.17000000", "0.00000000"], ["111044.12000000", "0.00005000"], ["111044.14000000", "0.01801000"], ["111049.25000000", "0.00000000"], ["111096.29000000", "0.00000000"], ["111125.86000000", "0.02500000"], ["111126.81000000", "0.00000000"]]}}
{"type": "orderbook", "local_time": 1761342391497, "event_time": 1761342385214, "latency_ms": 6283, "data": {"e": "depthUpdate", "E": 1761342385214, "s": "BTCUSDT", "U": 79012691365, "u": 79012691374, "b": [["111028.02000000", "1.62039000"], ["111026.52000000", "0.05007000"], ["111012.03000000", "0.00000000"]], "a": [["111028.03000000", "2.23776000"], ["111044.14000000", "0.00000000"], ["111044.17000000", "0.04801000"]]}}
{"type": "orderbook", "local_time": 1761342391497, "event_time": 1761342385314, "latency_ms": 6183, "data": {"e": "depthUpdate", "E": 1761342385314, "s": "BTCUSDT", "U": 79012691375, "u": 79012691389, "b": [["111028.02000000", "1.62814000"], ["111028.01000000", "0.85818000"], ["111027.22000000", "0.02978000"], ["111027.14000000", "0.00725000"], ["111026.52000000", "0.05012000"], ["111024.34000000", "0.04670000"], ["99925.00000000", "0.00510000"]], "a": [["111044.17000000", "0.03000000"], ["111044.19000000", "0.01801000"], ["111045.43000000", "0.04055000"]]}}
{"type": "orderbook", "local_time": 1761342391498, "event_time": 1761342385414, "latency_ms": 6084, "data": {"e": "depthUpdate", "E": 1761342385414, "s": "BTCUSDT", "U": 79012691390, "u": 79012691390, "b": [["111000.73000000", "0.00576000"]], "a": []}}
{"type": "orderbook", "local_time": 1761342391498, "event_time": 1761342385514, "latency_ms": 5984, "data": {"e": "depthUpdate", "E": 1761342385514, "s": "BTCUSDT", "U": 79012691391, "u": 79012691397, "b": [["111028.02000000", "1.59814000"], ["111027.99000000", "0.00000000"], ["111027.96000000", "0.00000000"], ["111027.95000000", "0.00000000"]], "a": []}}
{"type": "orderbook", "local_time": 1761342391498, "event_time": 1761342385614, "latency_ms": 5884, "data": {"e": "depthUpdate", "E": 1761342385614, "s": "BTCUSDT", "U": 79012691398, "u": 79012691398, "b": [], "a": [["111045.43000000", "0.00000000"]]}}
{"type": "orderbook", "local_time": 1761342391499, "event_time": 1761342385714, "latency_ms": 5785, "data": {"e": "depthUpdate", "E": 1761342385714, "s": "BTCUSDT", "U": 79012691399, "u": 79012691402, "b": [["111028.01000000", "0.85692000"]], "a": [["111044.19000000", "0.00000000"], ["111044.26000000", "0.01801000"], ["111046.23000000", "0.03000000"]]}}
{"type": "orderbook", "local_time": 1761342391499, "event_time": 1761342385814, "latency_ms": 5685, "data": {"e": "depthUpdate", "E": 1761342385814, "s": "BTCUSDT", "U": 79012691403, "u": 79012691412, "b": [["111028.02000000", "1.59748000"]], "a": [["111028.03000000", "2.23902000"], ["111032.29000000", "0.21465000"], ["111035.53000000", "0.00000000"], ["111035.57000000", "0.00000000"], ["111045.43000000", "0.03933000"], ["111051.18000000", "0.00000000"]]}}
{"type": "orderbook", "local_time": 1761342391499, "event_time": 1761342385914, "latency_ms": 5585, "data": {"e": "depthUpdate", "E": 1761342385914, "s": "BTCUSDT", "U": 79012691413, "u": 79012691719, "b": [["111028.02000000", "0.00000000"], ["111028.01000000", "0.00000000"], ["111028.00000000", "2.47588000"], ["111027.99000000", "0.00065000"], ["111027.75000000", "0.00030000"], ["111027.23000000", "0.00019000"], ["111027.22000000", "0.02993000"], ["111027.14000000", "0.00015000"], ["111026.91000000", "0.00104000"], ["111026.53000000", "0.00010000"], ["111026.52000000", "0.00005000"], ["111025.25000000", "0.00208000"], ["111024.65000000", "0.00005000"], ["111024.52000000", "0.00005000"], ["111024.27000000", "0.00000000"], ["111023.31000000", "0.00720000"], ["111018.50000000", "0.00000000"], ["111015.31000000", "0.00005000"], ["111013.35000000", "0.00000000"], ["111013.34000000", "0.00000000"], ["111012.03000000", "0.00000000"], ["111012.02000000", "0.00000000"], ["111010.99000000", "0.00000000"], ["111010.98000000", "0.00000000"], ["111009.23000000", "0.00000000"], ["111006.98000000", "0.00450000"], ["111006.50000000", "0.00005000"], ["111005.91000000", "0.00000000"], ["111005.81000000", "0.11267000"], ["111004.71000000", "0.00000000"], ["111004.16000000", "0.00000000"], ["111002.82000000", "0.00000000"], ["111002.72000000", "0.04000000"], ["111001.86000000", "0.00000000"], ["111001.42000000", "0.16000000"], ["111000.73000000", "0.00000000"], ["111000.58000000", "0.00000000"], ["110999.71000000", "0.00000000"], ["110998.68000000", "0.00000000"], ["110996.02000000", "0.13524000"], ["110993.57000000", "0.08000000"], ["110992.57000000", "0.13519000"], ["110987.19000000", "0.00000000"], ["110984.55000000", "0.00000000"], ["110981.42000000", "0.32433000"], ["110955.09000000", "0.00000000"], ["110952.76000000", "0.00000000"], ["110942.72000000", "0.13524000"], ["110939.27000000", "0.13519000"], ["110881.62000000", "0.00000000"], ["110770.26000000", "0.00000000"], ["99925.00000000", "0.00520000"]], "a": [["111028.01000000", "3.52404000"], ["111028.02000000", "1.57326000"], ["111028.03000000", "1.27193000"], ["111028.04000000", "0.29761000"], ["111028.62000000", "0.00126000"], ["111028.95000000", "0.01360000"], ["111029.69000000", "0.00033000"], ["111029.70000000", "0.04077000"], ["111030.41000000", "0.06748000"], ["111030.57000000", "0.29717000"], ["111031.24000000", "0.20282000"], ["111031.25000000", "0.00005000"], ["111031.26000000", "0.81635000"], ["111032.28000000", "0.00000000"], ["111032.29000000", "0.21470000"], ["111033.30000000", "0.04773000"], ["111033.38000000", "0.00000000"], ["111033.39000000", "0.32054000"], ["111033.40000000", "0.00000000"], ["111033.59000000", "0.11267000"], ["111034.60000000", "0.00000000"], ["111034.67000000", "0.07661000"], ["111035.26000000", "0.00000000"], ["111037.45000000", "0.00450000"], ["111037.61000000", "0.27041000"], ["111041.76000000", "0.00000000"], ["111041.94000000", "0.14000000"], ["111043.62000000", "0.13511000"], ["111046.36000000", "0.00000000"], ["111047.44000000", "0.03000000"], ["111048.30000000", "0.00005000"], ["111048.31000000", "0.00000000"], ["111055.43000000", "0.00000000"], ["111055.96000000", "0.00000000"], ["111055.99000000", "0.00000000"], ["111060.02000000", "0.32410000"], ["111068.01000000", "0.00000000"], ["111068.07000000", "0.00000000"], ["111074.19000000", "0.04008000"], ["111080.33000000", "0.00000000"], ["111092.63000000", "0.00000000"], ["111092.89000000", "0.00000000"], ["111093.03000000", "0.00000000"], ["111096.29000000", "0.00044000"], ["111096.99000000", "0.00000000"], ["111111.29000000", "0.00000000"], ["111118.53000000", "0.00000000"], ["111118.80000000", "0.00000000"], ["111118.91000000", "0.00010000"], ["111119.01000000", "0.00000000"], ["111119.35000000", "0.00000000"]]}}
{"type": "orderbook", "local_time": 1761342391500, "event_time": 1761342386014, "latency_ms": 5486, "data": {"e": "depthUpdate", "E": 1761342386014, "s": "BTCUSDT", "U": 79012691720, "u": 79012693130, "b": [["111028.00000000", "0.00000000"], ["111027.99000000", "0.00000000"], ["111027.76000000", "0.00000000"], ["111027.75000000", "0.00000000"], ["111027.23000000", "0.00000000"], ["111027.22000000", "0.00000000"], ["111027.14000000", "0.00000000"], ["111026.91000000", "0.00000000"], ["111026.53000000", "0.00000000"], ["111026.52000000", "0.00000000"], ["111025.25000000", "0.00000000"], ["111025.24000000", "0.00000000"], ["111025.23000000", "0.00000000"], ["111024.80000000", "0.00000000"], ["111024.65000000", "0.00000000"], ["111024.64000000", "0.00000000"], ["111024.52000000", "0.00000000"], ["111024.35000000", "0.00000000"], ["111024.34000000", "0.00000000"], ["111024.25000000", "0.00000000"], ["111024.24000000", "0.00000000"], ["111024.19000000", "0.00000000"], ["111024.18000000", "0.00000000"], ["111024.17000000", "0.00000000"], ["111023.58000000", "0.00034000"], ["111023.57000000", "0.00090000"], ["111023.32000000", "0.00010000"], ["111023.31000000", "0.00005000"], ["111022.95000000", "0.00000000"], ["111022.70000000", "0.02703000"], ["111022.47000000", "0.00005000"], ["111022.29000000", "0.03295000"], ["111022.14000000", "0.00010000"], ["111022.13000000", "0.00010000"], ["111021.36000000", "0.00545000"], ["111019.05000000", "0.00000000"], ["111018.76000000", "0.00000000"], ["111018.60000000", "0.00015000"], ["111018.59000000", "0.01598000"], ["111018.29000000", "0.00014000"], ["111017.10000000", "0.00010000"], ["111017.09000000", "0.00010000"], ["111016.92000000", "0.00726000"], ["111015.54000000", "0.00000000"], ["111015.35000000", "0.00000000"], ["111015.31000000", "0.00005000"], ["111015.30000000", "0.00015000"], ["111014.83000000", "0.05092000"], ["111014.15000000", "0.00000000"], ["111013.64000000", "0.00000000"], ["111013.59000000", "0.06529000"], ["111013.29000000", "0.04196000"], ["111012.48000000", "0.00005000"], ["111012.00000000", "0.00005000"], ["111011.94000000", "0.00000000"], ["111011.83000000", "0.00000000"], ["111011.35000000", "0.00000000"], ["111010.97000000", "0.00000000"], ["111010.85000000", "0.00000000"], ["111010.76000000", "0.00000000"], ["111010.62000000", "0.01798000"], ["111009.73000000", "0.00000000"], ["111009.70000000", "0.00000000"], ["111009.24000000", "0.00000000"], ["111008.91000000", "0.04670000"], ["111008.50000000", "0.00000000"], ["111007.81000000", "0.00000000"], ["111006.98000000", "0.00000000"], ["111006.97000000", "0.00000000"], ["111006.69000000", "0.00000000"], ["111006.41000000", "0.00000000"], ["111006.22000000", "0.00000000"], ["111006.02000000", "0.00000000"], ["111005.81000000", "0.00000000"], ["111005.29000000", "0.00000000"], ["111004.31000000", "0.00000000"], ["111004.23000000", "0.00000000"], ["111003.67000000", "0.00000000"], ["111003.54000000", "0.00000000"], ["111002.73000000", "0.00000000"], ["111002.72000000", "0.00000000"], ["111002.69000000", "0.00000000"], ["111002.50000000", "0.00000000"], ["111001.94000000", "0.00000000"], ["111001.45000000", "0.00000000"], ["111001.42000000", "0.00000000"], ["111001.00000000", "0.00011000"], ["111000.81000000", "0.00000000"], ["111000.14000000", "0.00000000"], ["111000.13000000", "0.00000000"], ["110999.73000000", "0.00000000"], ["110999.42000000", "0.00000000"], ["110998.81000000", "0.00000000"], ["110998.79000000", "0.00260000"], ["110998.72000000", "0.00000000"], ["110998.49000000", "0.00000000"], ["110998.44000000", "0.00000000"], ["110997.76000000", "0.47085000"], ["110997.68000000", "0.00000000"], ["110997.62000000", "0.00000000"], ["110997.21000000", "0.00000000"], ["110997.12000000", "0.00000000"], ["110996.74000000", "0.00450000"], ["110996.73000000", "0.00000000"], ["110996.42000000", "0.00000000"], ["110996.35000000", "0.00250000"], ["110996.05000000", "0.00900000"], ["110996.02000000", "0.00000000"], ["110995.83000000", "0.00090000"], ["110995.22000000", "0.00000000"], ["110994.90000000", "0.50836000"], ["110994.89000000", "0.00000000"], ["110994.76000000", "0.00000000"], ["110994.00000000", "0.01801000"], ["110993.57000000", "0.00000000"], ["110993.23000000", "0.00000000"], ["110992.62000000", "0.00000000"], ["110992.61000000", "0.00000000"], ["110992.57000000", "0.00000000"], ["110992.28000000", "0.00000000"], ["110992.04000000", "0.79054000"], ["110991.90000000", "0.00250000"], ["110990.02000000", "0.00000000"], ["110989.52000000", "0.00000000"], ["110988.94000000", "0.00000000"], ["110988.91000000", "0.07661000"], ["110988.90000000", "0.00005000"], ["110988.68000000", "0.04000000"], ["110988.32000000", "0.30000000"], ["110987.45000000", "0.00250000"], ["110986.74000000", "0.24025000"], ["110986.39000000", "0.13601000"], ["110983.44000000", "0.00000000"], ["110983.34000000", "0.79570000"], ["110983.02000000", "0.00000000"], ["110980.12000000", "0.13524000"], ["110975.95000000", "0.32435000"], ["110972.00000000", "0.34703000"], ["110970.00000000", "0.00125000"], ["110964.88000000", "0.00000000"], ["110964.55000000", "0.00000000"], ["110964.43000000", "0.00000000"], ["110946.95000000", "0.38825000"], ["110944.34000000", "0.00000000"], ["110942.72000000", "0.00000000"], ["110939.82000000", "0.00000000"], ["110937.77000000", "0.00000000"], ["110935.20000000", "0.00000000"], ["110933.26000000", "0.00000000"], ["110931.17000000", "0.00000000"], ["110928.93000000", "0.00000000"], ["110927.41000000", "0.00000000"], ["110926.83000000", "0.13524000"], ["110924.01000000", "0.00000000"], ["110923.00000000", "0.00000000"], ["110921.85000000", "0.00225000"], ["110919.17000000", "0.03218000"], ["110914.82000000", "0.05100000"], ["110914.66000000", "0.00000000"], ["110914.64000000", "0.06534000"], ["110914.32000000", "0.00000000"], ["110905.00000000", "0.11380000"], ["110903.46000000", "0.00005000"], ["110900.32000000", "0.00000000"], ["110900.01000000", "0.00000000"], ["110898.02000000", "0.00191000"], ["110886.31000000", "0.11093000"], ["110882.97000000", "0.09817000"], ["110822.97000000", "0.00000000"], ["110812.14000000", "0.00000000"], ["110812.13000000", "0.00000000"], ["110810.01000000", "0.00090000"], ["110809.89000000", "0.00000000"], ["110790.01000000", "0.00000000"], ["110786.01000000", "0.00076000"], ["110766.40000000", "0.00000000"], ["110743.67000000", "0.00000000"], ["110733.91000000", "0.00000000"], ["110725.58000000", "0.00000000"], ["110696.13000000", "0.00000000"], ["110695.73000000", "0.00000000"], ["110686.24000000", "0.02198000"], ["110679.20000000", "0.02198000"], ["110678.12000000", "0.02198000"], ["110668.19000000", "0.03697000"], ["110653.53000000", "0.00000000"], ["110652.21000000", "0.00000000"], ["110622.73000000", "0.00000000"], ["110614.82000000", "0.02431000"], ["110590.32000000", "0.02698000"], ["110529.04000000", "0.03697000"], ["99925.00000000", "0.00510000"], ["88822.00000000", "0.00337000"], ["55485.56000000", "0.00000000"], ["55462.07000000", "0.00000000"], ["55459.51000000", "0.00040000"], ["55454.42000000", "0.00000000"]], "a": [["111023.59000000", "4.45713000"], ["111023.65000000", "0.00658000"], ["111024.18000000", "3.88241000"], ["111024.19000000", "0.72817000"], ["111024.24000000", "0.00000000"], ["111024.25000000", "0.36078000"], ["111024.35000000", "0.00000000"], ["111024.36000000", "0.04168000"], ["111024.42000000", "0.00000000"], ["111024.50000000", "0.00000000"], ["111024.53000000", "0.00000000"], ["111024.64000000", "0.26991000"], ["111024.65000000", "0.00010000"], ["111024.66000000", "0.00000000"], ["111024.80000000", "0.00005000"], ["111024.81000000", "0.00000000"], ["111025.24000000", "0.00000000"], ["111025.25000000", "0.29602000"], ["111025.26000000", "0.00000000"], ["111025.31000000", "0.00000000"], ["111025.32000000", "0.00000000"], ["111025.63000000", "0.01801000"], ["111026.00000000", "0.00000000"], ["111026.03000000", "0.00000000"], ["111026.05000000", "0.04571000"], ["111026.53000000", "0.00000000"], ["111026.54000000", "0.00000000"], ["111026.92000000", "0.00000000"], ["111027.15000000", "0.00000000"], ["111027.23000000", "0.00000000"], ["111027.24000000", "0.20282000"], ["111027.50000000", "0.00250000"], ["111027.76000000", "0.00000000"], ["111027.77000000", "0.00000000"], ["111027.99000000", "0.00000000"], ["111028.00000000", "3.53356000"], ["111028.01000000", "1.62018000"], ["111028.02000000", "0.00005000"], ["111028.03000000", "0.14391000"], ["111028.04000000", "0.29741000"], ["111028.95000000", "0.01350000"], ["111029.32000000", "0.00000000"], ["111029.35000000", "0.00000000"], ["111029.58000000", "0.00000000"], ["111029.70000000", "0.00072000"], ["111030.12000000", "0.00000000"], ["111030.41000000", "0.06748000"], ["111030.50000000", "0.00000000"], ["111030.57000000", "0.00000000"], ["111030.80000000", "0.00247000"], ["111031.25000000", "0.00000000"], ["111031.26000000", "0.81630000"], ["111031.94000000", "0.00000000"], ["111032.29000000", "0.00000000"], ["111033.16000000", "0.00000000"], ["111033.30000000", "0.00000000"], ["111034.26000000", "0.07656000"], ["111034.59000000", "1.44342000"], ["111034.76000000", "0.02703000"], ["111035.31000000", "0.00000000"], ["111035.86000000", "0.00000000"], ["111036.44000000", "0.01793000"], ["111037.45000000", "0.00000000"], ["111037.62000000", "0.00000000"], ["111037.70000000", "0.00900000"], ["111038.33000000", "0.00000000"], ["111039.44000000", "0.00000000"], ["111039.63000000", "0.00000000"], ["111039.86000000", "0.00000000"], ["111039.88000000", "0.00000000"], ["111039.94000000", "0.00000000"], ["111040.03000000", "0.00000000"], ["111040.96000000", "0.00000000"], ["111041.94000000", "0.00000000"], ["111043.62000000", "0.00000000"], ["111043.72000000", "0.00000000"], ["111044.26000000", "0.00000000"], ["111044.41000000", "0.00044000"], ["111044.49000000", "0.00000000"], ["111049.75000000", "0.00000000"], ["111049.95000000", "0.18319000"], ["111053.95000000", "0.04013000"], ["111054.14000000", "0.32412000"], ["111055.85000000", "0.00000000"], ["111057.78000000", "0.06680000"], ["111057.99000000", "0.00000000"], ["111062.44000000", "0.00090000"], ["111063.09000000", "0.00000000"], ["111064.16000000", "0.00000000"], ["111064.88000000", "0.44478000"], ["111065.18000000", "0.00016000"], ["111067.99000000", "0.00000000"], ["111068.91000000", "0.00000000"], ["111069.30000000", "0.00000000"], ["111069.97000000", "0.00000000"], ["111072.97000000", "0.00000000"], ["111074.19000000", "0.00000000"], ["111074.98000000", "0.00000000"], ["111075.57000000", "0.00000000"], ["111076.35000000", "0.00016000"], ["111077.19000000", "0.00000000"], ["111079.60000000", "0.00000000"], ["111080.32000000", "0.00000000"], ["111080.82000000", "0.00224000"], ["111083.56000000", "0.00000000"], ["111084.60000000", "0.03331000"], ["111089.12000000", "0.00000000"], ["111090.22000000", "0.09952000"], ["111093.40000000", "0.00410000"], ["111106.22000000", "0.00000000"], ["111107.98000000", "0.00224000"], ["111110.99000000", "0.00000000"], ["111111.11000000", "0.07325000"], ["111121.40000000", "0.03400000"], ["111122.41000000", "0.00000000"], ["111142.19000000", "0.00000000"], ["111155.50000000", "0.05665000"], ["111191.41000000", "0.00090000"], ["111195.37000000", "0.00000000"], ["111199.80000000", "0.02704000"], ["111218.88000000", "0.00090000"], ["111221.98000000", "0.00000000"], ["111222.00000000", "0.69501000"], ["111359.53000000", "0.00008000"], ["111368.93000000", "0.00000000"], ["111424.21000000", "0.00000000"]]}}
{"type": "orderbook", "local_time": 1761342391500, "event_time": 1761342386114, "latency_ms": 5386, "data": {"e": "depthUpdate", "E": 1761342386114, "s": "BTCUSDT", "U": 79012693131, "u": 79012694208, "b": [["111023.58000000", "0.00000000"], ["111023.57000000", "0.00000000"], ["111023.32000000", "0.00000000"], ["111023.31000000", "0.00000000"], ["111023.30000000", "0.00000000"], ["111022.71000000", "0.00000000"], ["111022.70000000", "0.00000000"], ["111022.69000000", "0.00000000"], ["111022.68000000", "0.00000000"], ["111022.47000000", "0.00000000"], ["111022.30000000", "0.00000000"], ["111022.29000000", "0.00000000"], ["111022.14000000", "0.00000000"], ["111022.13000000", "0.00000000"], ["111021.36000000", "0.00000000"], ["111020.82000000", "0.00000000"], ["111020.00000000", "0.00000000"], ["111019.32000000", "0.00000000"], ["111018.60000000", "0.00000000"], ["111018.59000000", "0.00129000"], ["111018.58000000", "0.00090000"], ["111018.29000000", "0.00000000"], ["111017.76000000", "0.00000000"], ["111017.10000000", "0.00000000"], ["111017.09000000", "0.00000000"], ["111016.93000000", "0.00010000"], ["111016.92000000", "0.00726000"], ["111016.81000000", "0.00000000"], ["111015.31000000", "0.00000000"], ["111015.30000000", "0.00005000"], ["111014.84000000", "0.00010000"], ["111014.83000000", "0.00010000"], ["111013.60000000", "0.00010000"], ["111013.59000000", "0.00010000"], ["111013.30000000", "0.00010000"], ["111013.29000000", "0.04201000"], ["111012.70000000", "0.00014000"], ["111012.48000000", "0.00000000"], ["111012.23000000", "0.00331000"], ["111012.22000000", "0.00000000"], ["111011.82000000", "0.00000000"], ["111011.37000000", "0.00000000"], ["111010.63000000", "0.00005000"], ["111010.62000000", "0.00010000"], ["111010.57000000", "0.00000000"], ["111009.12000000", "0.04954000"], ["111008.91000000", "0.00010000"], ["111007.54000000", "0.00005000"], ["111006.66000000", "0.00151000"], ["111006.50000000", "0.00000000"], ["111005.26000000", "0.00005000"], ["111005.25000000", "0.00000000"], ["111005.23000000", "0.00005000"], ["111005.03000000", "0.06499000"], ["111004.38000000", "0.04670000"], ["111004.16000000", "0.07668000"], ["111001.94000000", "0.00240000"], ["111001.83000000", "0.00000000"], ["111001.54000000", "0.00929000"], ["111000.75000000", "0.00007000"], ["110999.47000000", "0.05400000"], ["110998.61000000", "0.00000000"], ["110997.76000000", "0.17715000"], ["110997.57000000", "0.00000000"], ["110996.74000000", "0.00000000"], ["110994.90000000", "0.00000000"], ["110994.00000000", "0.00000000"], ["110992.47000000", "0.00000000"], ["110992.03000000", "0.00000000"], ["110991.80000000", "0.00000000"], ["110991.36000000", "0.00000000"], ["110990.43000000", "0.01801000"], ["110990.28000000", "0.04506000"], ["110989.65000000", "0.30847000"], ["110988.32000000", "0.00000000"], ["110986.92000000", "0.02000000"], ["110986.82000000", "0.00000000"], ["110986.75000000", "0.20443000"], ["110986.39000000", "0.13511000"], ["110986.09000000", "0.00000000"], ["110986.02000000", "0.00000000"], ["110985.32000000", "0.04000000"], ["110983.03000000", "0.00000000"], ["110983.01000000", "0.08000000"], ["110983.00000000", "0.00250000"], ["110981.42000000", "0.00000000"], ["110981.31000000", "0.23660000"], ["110972.27000000", "0.13519000"], ["110970.06000000", "0.00036000"], ["110969.23000000", "0.00034000"], ["110968.67000000", "0.36558000"], ["110964.52000000", "0.00005000"], ["110963.75000000", "0.00000000"], ["110963.71000000", "0.00000000"], ["110963.59000000", "0.00000000"], ["110962.98000000", "0.00000000"], ["110962.45000000", "0.00000000"], ["110962.33000000", "0.00000000"], ["110961.55000000", "0.00000000"], ["110960.60000000", "0.06870000"], ["110954.13000000", "0.00000000"], ["110949.55000000", "0.02663000"], ["110948.19000000", "0.00621000"], ["110947.65000000", "0.00628000"], ["110945.98000000", "0.00000000"], ["110936.44000000", "0.00626000"], ["110928.05000000", "0.00000000"], ["110925.97000000", "0.00000000"], ["110922.85000000", "0.13422000"], ["110922.51000000", "0.00000000"], ["110920.40000000", "0.00000000"], ["110916.11000000", "0.13826000"], ["110913.84000000", "0.00000000"], ["110912.38000000", "0.00000000"], ["110892.19000000", "0.36583000"], ["110880.26000000", "0.09817000"], ["110878.01000000", "0.03697000"], ["110876.01000000", "0.02744000"], ["110824.01000000", "0.00000000"], ["110823.88000000", "0.00000000"], ["110766.01000000", "0.00090000"], ["110760.72000000", "0.00000000"], ["110754.21000000", "0.00000000"], ["110740.38000000", "0.00000000"], ["110740.37000000", "0.00000000"], ["110715.14000000", "0.02498000"], ["110714.82000000", "0.02498000"], ["110714.54000000", "0.02498000"], ["110714.41000000", "0.02498000"], ["110694.22000000", "0.00000000"], ["110672.15000000", "0.02198000"], ["110664.80000000", "0.03697000"], ["110661.34000000", "0.03697000"], ["110657.10000000", "0.03697000"], ["110625.34000000", "0.00000000"], ["110623.17000000", "0.00005000"], ["110583.51000000", "0.00000000"], ["110583.14000000", "0.00000000"], ["110582.77000000", "0.00000000"], ["110581.39000000", "0.00016000"], ["110557.19000000", "0.02698000"], ["110556.47000000", "0.02698000"], ["110555.74000000", "0.02698000"], ["110554.85000000", "0.02698000"], ["110526.65000000", "0.03697000"], ["110526.61000000", "0.03697000"], ["55511.79000000", "0.00180000"]], "a": [["111018.60000000", "6.41693000"], ["111018.66000000", "0.00000000"], ["111018.86000000", "0.04571000"], ["111019.32000000", "0.00005000"], ["111019.38000000", "0.00042000"], ["111020.00000000", "0.00005000"], ["111020.40000000", "0.01801000"], ["111021.37000000", "0.00000000"], ["111022.30000000", "0.00010000"], ["111022.70000000", "0.00005000"], ["111022.71000000", "0.56545000"], ["111022.77000000", "0.00000000"], ["111023.05000000", "0.00250000"], ["111023.32000000", "0.00010000"], ["111023.33000000", "0.00000000"], ["111023.38000000", "0.00000000"], ["111023.43000000", "0.00000000"], ["111023.57000000", "4.07149000"], ["111023.58000000", "0.00005000"], ["111023.59000000", "0.38314000"], ["111023.65000000", "0.00005000"], ["111024.17000000", "0.00000000"], ["111024.18000000", "0.00005000"], ["111024.19000000", "0.27027000"], ["111024.25000000", "0.36068000"], ["111024.36000000", "0.00000000"], ["111024.64000000", "0.26991000"], ["111024.65000000", "0.00000000"], ["111024.69000000", "0.00005000"], ["111025.20000000", "0.00005000"], ["111025.25000000", "0.00000000"], ["111025.63000000", "0.00000000"], ["111026.05000000", "0.00000000"], ["111026.49000000", "0.00000000"], ["111027.99000000", "1.76174000"], ["111028.00000000", "0.00000000"], ["111028.01000000", "1.62013000"], ["111028.02000000", "0.00000000"], ["111028.03000000", "0.01383000"], ["111030.40000000", "0.27041000"], ["111030.41000000", "0.00000000"], ["111033.03000000", "0.12780000"], ["111033.39000000", "0.69445000"], ["111033.59000000", "0.00000000"], ["111034.67000000", "0.00000000"], ["111034.76000000", "0.00000000"], ["111035.00000000", "0.00044000"], ["111035.25000000", "0.00241000"], ["111037.61000000", "0.00000000"], ["111039.36000000", "0.00000000"], ["111039.99000000", "0.01916000"], ["111040.85000000", "0.00000000"], ["111042.46000000", "0.00000000"], ["111043.88000000", "0.00000000"], ["111044.41000000", "0.00000000"], ["111045.30000000", "0.00000000"], ["111045.43000000", "0.00000000"], ["111048.67000000", "0.32414000"], ["111051.48000000", "0.00000000"], ["111052.18000000", "0.00000000"], ["111056.89000000", "0.04507000"], ["111057.13000000", "0.00000000"], ["111059.88000000", "0.44478000"], ["111061.26000000", "1.15091000"], ["111061.29000000", "0.00000000"], ["111064.00000000", "0.00160000"], ["111064.53000000", "0.01410000"], ["111064.88000000", "0.00000000"], ["111074.12000000", "0.00000000"], ["111075.64000000", "0.00000000"], ["111075.84000000", "0.02572000"], ["111079.09000000", "0.00625000"], ["111080.05000000", "0.00000000"], ["111081.60000000", "0.00631000"], ["111084.74000000", "0.00665000"], ["111094.40000000", "0.00000000"], ["111096.88000000", "0.00000000"], ["111097.75000000", "0.00000000"], ["111099.85000000", "0.00000000"], ["111108.74000000", "0.00000000"], ["111121.94000000", "0.36508000"], ["111238.52000000", "0.03997000"], ["111240.48000000", "0.14650000"], ["111286.30000000", "0.02431000"], ["111404.14000000", "0.00000000"], ["111411.06000000", "0.03697000"]]}}
{"type": "orderbook", "local_time": 1761342391501, "event_time": 1761342386214, "latency_ms": 5287, "data": {"e": "depthUpdate", "E": 1761342386214, "s": "BTCUSDT", "U": 79012694209, "u": 79012694561, "b": [["111018.59000000", "0.00000000"], ["111018.58000000", "0.00095000"], ["111018.57000000", "0.00090000"], ["111016.92000000", "0.00746000"], ["111016.11000000", "0.00320000"], ["111014.84000000", "0.00000000"], ["111014.83000000", "0.00000000"], ["111013.60000000", "0.71160000"], ["111013.59000000", "0.00000000"], ["111013.29000000", "0.04211000"], ["111012.70000000", "0.00000000"], ["111012.23000000", "0.00000000"], ["111010.63000000", "0.00000000"], ["111010.62000000", "0.00000000"], ["111009.13000000", "0.00010000"], ["111009.12000000", "0.00010000"], ["111008.92000000", "0.00000000"], ["111008.91000000", "0.00000000"], ["111007.55000000", "0.00000000"], ["111007.54000000", "0.00000000"], ["111006.66000000", "0.29875000"], ["111005.27000000", "0.00000000"], ["111005.26000000", "0.00000000"], ["111005.23000000", "0.00000000"], ["111005.04000000", "0.00010000"], ["111005.03000000", "0.06504000"], ["111004.39000000", "0.00005000"], ["111004.38000000", "0.00010000"], ["111004.33000000", "0.00000000"], ["111004.16000000", "0.00010000"], ["111004.15000000", "0.07676000"], ["111004.11000000", "0.01799000"], ["111003.92000000", "0.04877000"], ["111001.94000000", "0.00960000"], ["111001.93000000", "0.20745000"], ["111001.54000000", "0.00934000"], ["111001.09000000", "0.01822000"], ["111000.80000000", "0.00000000"], ["111000.00000000", "0.02845000"], ["110999.56000000", "0.00326000"], ["110999.47000000", "0.05405000"], ["110997.76000000", "0.03742000"], ["110992.11000000", "0.00000000"], ["110990.43000000", "0.00000000"], ["110990.39000000", "0.01802000"], ["110989.21000000", "0.00000000"], ["110986.76000000", "0.20282000"], ["110979.65000000", "0.00009000"], ["110978.55000000", "0.00250000"], ["110977.50000000", "0.00009000"], ["110976.47000000", "0.00009000"], ["110971.37000000", "0.00009000"], ["110969.81000000", "0.32437000"], ["110968.09000000", "0.84519000"], ["110966.92000000", "0.22544000"], ["110966.59000000", "0.00000000"], ["110966.40000000", "0.22535000"], ["110965.01000000", "0.07661000"], ["110964.99000000", "0.00009000"], ["110936.34000000", "0.00000000"], ["110935.15000000", "0.00360000"], ["110930.27000000", "0.00000000"], ["110928.05000000", "0.00017000"], ["110923.79000000", "0.00090000"], ["110922.51000000", "0.00017000"], ["110921.84000000", "0.00000000"], ["110921.39000000", "0.00000000"], ["110904.93000000", "0.03998000"], ["110900.43000000", "0.00000000"], ["110900.13000000", "0.02420000"], ["110900.00000000", "0.03963000"], ["110899.83000000", "0.00112000"], ["110898.69000000", "0.04058000"], ["110882.98000000", "0.13127000"], ["110752.74000000", "0.90279000"], ["110714.27000000", "0.02503000"], ["110713.56000000", "0.02498000"], ["110675.21000000", "0.00000000"], ["110674.55000000", "0.00000000"], ["110663.60000000", "0.03997000"]], "a": [["111018.59000000", "4.62946000"], ["111018.60000000", "1.59910000"], ["111018.86000000", "0.04581000"], ["111020.40000000", "0.00010000"], ["111021.58000000", "0.01802000"], ["111022.30000000", "0.00000000"], ["111022.70000000", "0.00000000"], ["111022.71000000", "0.30010000"], ["111023.32000000", "0.00000000"], ["111023.57000000", "0.44469000"], ["111023.58000000", "0.00000000"], ["111023.59000000", "0.20287000"], ["111023.65000000", "0.00000000"], ["111024.18000000", "0.00000000"], ["111024.25000000", "0.13529000"], ["111024.64000000", "0.26996000"], ["111027.99000000", "0.76683000"], ["111028.01000000", "1.48494000"], ["111028.03000000", "0.06397000"], ["111028.50000000", "0.00005000"], ["111033.02000000", "0.12358000"], ["111033.03000000", "0.00000000"], ["111036.44000000", "0.00000000"], ["111059.48000000", "0.44478000"], ["111059.88000000", "0.00000000"], ["111064.53000000", "0.00000000"], ["111073.67000000", "0.00625000"], ["111087.37000000", "0.00000000"], ["111354.34000000", "0.48717000"]]}}
{"type": "orderbook", "local_time": 1761342391501, "event_time": 1761342386314, "latency_ms": 5187, "data": {"e": "depthUpdate", "E": 1761342386314, "s": "BTCUSDT", "U": 79012694562, "u": 79012694710, "b": [["111018.58000000", "0.00155000"], ["111018.57000000", "0.00120000"], ["111016.92000000", "0.00746000"], ["111016.11000000", "0.00310000"], ["111013.61000000", "0.00010000"], ["111013.60000000", "0.00015000"], ["111013.29000000", "0.04201000"], ["111009.96000000", "0.00360000"], ["111009.13000000", "0.00000000"], ["111009.12000000", "0.00000000"], ["111006.67000000", "0.08928000"], ["111006.66000000", "0.29885000"], ["111005.80000000", "0.00000000"], ["111005.03000000", "0.06504000"], ["111004.39000000", "0.00000000"], ["111004.38000000", "0.00000000"], ["111004.16000000", "0.12166000"], ["111004.15000000", "0.07706000"], ["111004.11000000", "0.01804000"], ["111003.92000000", "0.04882000"], ["111001.94000000", "0.00245000"], ["111001.93000000", "0.00005000"], ["111001.54000000", "0.00000000"], ["111000.21000000", "0.04670000"], ["111000.00000000", "0.02840000"], ["110999.47000000", "0.05400000"], ["110997.76000000", "0.03737000"], ["110996.05000000", "0.00000000"], ["110990.82000000", "0.11267000"], ["110986.39000000", "0.00000000"], ["110968.16000000", "0.20282000"], ["110960.60000000", "0.00009000"], ["110956.16000000", "0.18531000"], ["110922.85000000", "0.00000000"], ["110911.52000000", "0.05100000"], ["110909.23000000", "0.05400000"], ["110729.09000000", "0.02598000"], ["110719.10000000", "0.02598000"], ["110709.05000000", "0.02598000"], ["110699.06000000", "0.02598000"], ["110689.73000000", "0.02598000"], ["110684.62000000", "0.02598000"]], "a": [["111018.59000000", "5.01510000"], ["111018.60000000", "1.00367000"], ["111018.61000000", "0.07661000"], ["111018.86000000", "0.04576000"], ["111020.40000000", "0.00000000"], ["111020.77000000", "0.00360000"], ["111021.58000000", "0.00005000"], ["111023.24000000", "0.00000000"], ["111023.28000000", "0.01802000"], ["111023.57000000", "0.32358000"], ["111058.56000000", "0.36059000"], ["111111.96000000", "0.01410000"], ["111298.06000000", "0.03697000"], ["111354.34000000", "0.00000000"], ["111422.17000000", "0.00000000"], ["114500.00000000", "20.09740000"]]}}
{"type": "orderbook", "local_time": 1761342391502, "event_time": 1761342386414, "latency_ms": 5088, "data": {"e": "depthUpdate", "E": 1761342386414, "s": "BTCUSDT", "U": 79012694711, "u": 79012695088, "b": [["111018.58000000", "0.00000000"], ["111018.57000000", "0.00000000"], ["111016.93000000", "0.00000000"], ["111016.92000000", "0.00000000"], ["111016.11000000", "0.00000000"], ["111015.30000000", "0.00000000"], ["111013.84000000", "0.00000000"], ["111013.61000000", "0.00000000"], ["111013.60000000", "0.00000000"], ["111013.30000000", "0.00000000"], ["111013.29000000", "0.04468000"], ["111013.28000000", "0.00090000"], ["111013.05000000", "0.00000000"], ["111013.04000000", "0.00000000"], ["111009.96000000", "0.00380000"], ["111009.16000000", "0.00000000"], ["111006.68000000", "0.00010000"], ["111006.67000000", "0.08958000"], ["111006.66000000", "0.00161000"], ["111005.03000000", "0.06504000"], ["111004.17000000", "0.10808000"], ["111004.16000000", "0.00015000"], ["111004.15000000", "0.00005000"], ["111003.92000000", "0.00005000"], ["111003.78000000", "0.05082000"], ["111003.26000000", "0.29725000"], ["111002.25000000", "0.20745000"], ["111001.94000000", "0.00240000"], ["111001.93000000", "0.00000000"], ["111001.09000000", "0.00005000"], ["111000.21000000", "0.04675000"], ["110998.86000000", "0.07685000"], ["110996.64000000", "0.00150000"], ["110995.83000000", "0.00000000"], ["110990.39000000", "0.00000000"], ["110988.91000000", "0.00000000"], ["110988.09000000", "0.01802000"], ["110986.77000000", "0.27695000"], ["110986.74000000", "0.00000000"], ["110986.73000000", "0.00000000"], ["110975.95000000", "0.00000000"], ["110974.17000000", "0.07661000"], ["110969.45000000", "0.22239000"], ["110965.29000000", "0.36038000"], ["110959.61000000", "0.00000000"], ["110959.04000000", "0.00005000"], ["110921.85000000", "0.00000000"], ["110914.86000000", "0.05700000"], ["110910.97000000", "0.05100000"], ["110909.76000000", "0.00224000"], ["110898.02000000", "0.00000000"], ["110886.32000000", "0.00191000"], ["110876.01000000", "0.02521000"], ["110866.01000000", "0.00223000"], ["99925.00000000", "0.00500000"], ["99916.00000000", "0.00010000"]], "a": [["111013.30000000", "6.62699000"], ["111013.36000000", "0.00000000"], ["111013.61000000", "0.00000000"], ["111013.84000000", "0.00005000"], ["111013.97000000", "0.20282000"], ["111014.15000000", "0.00250000"], ["111015.31000000", "0.00000000"], ["111015.94000000", "0.00513000"], ["111016.11000000", "0.00000000"], ["111016.12000000", "0.00005000"], ["111016.93000000", "0.00000000"], ["111016.94000000", "0.00000000"], ["111018.58000000", "0.00000000"], ["111018.59000000", "1.42225000"], ["111018.60000000", "0.56717000"], ["111018.61000000", "0.07671000"], ["111018.86000000", "0.04576000"], ["111019.38000000", "0.00000000"], ["111019.71000000", "0.01802000"], ["111020.77000000", "0.00000000"], ["111020.78000000", "0.00000000"], ["111020.79000000", "0.00360000"], ["111021.58000000", "0.00000000"], ["111022.71000000", "0.30005000"], ["111023.28000000", "0.00005000"], ["111024.19000000", "0.27022000"], ["111024.25000000", "0.00000000"], ["111024.40000000", "0.00052000"], ["111024.64000000", "0.26991000"], ["111028.03000000", "0.00489000"], ["111028.62000000", "0.00000000"], ["111033.38000000", "0.03000000"], ["111035.25000000", "0.00090000"], ["111036.40000000", "0.00000000"], ["111037.26000000", "0.03000000"], ["111044.51000000", "0.36533000"], ["111052.15000000", "0.00090000"], ["111054.19000000", "0.44478000"], ["111058.56000000", "0.00005000"], ["111059.48000000", "0.00000000"], ["111061.27000000", "0.00000000"], ["111068.55000000", "0.00000000"], ["111111.96000000", "0.00000000"], ["111255.48000000", "0.01439000"]]}}
{"type": "orderbook", "local_time": 1761342391502, "event_time": 1761342386514, "latency_ms": 4988, "data": {"e": "depthUpdate", "E": 1761342386514, "s": "BTCUSDT", "U": 79012695089, "u": 79012695238, "b": [["111013.29000000", "0.04498000"], ["111013.28000000", "0.00115000"], ["111010.52000000", "0.00198000"], ["111009.96000000", "0.00020000"], ["111007.30000000", "0.00000000"], ["111007.29000000", "0.02703000"], ["111006.68000000", "0.33278000"], ["111006.67000000", "0.00020000"], ["111006.66000000", "0.00156000"], ["111006.63000000", "0.00541000"], ["111005.94000000", "0.29724000"], ["111005.03000000", "0.06504000"], ["111004.18000000", "0.00010000"], ["111004.17000000", "0.18084000"], ["111004.16000000", "0.00000000"], ["111004.15000000", "0.00000000"], ["111004.12000000", "0.00010000"], ["111004.11000000", "0.01809000"], ["111003.92000000", "0.00000000"], ["111003.86000000", "0.00396000"], ["111003.79000000", "0.00005000"], ["111003.78000000", "0.05087000"], ["111003.26000000", "0.00005000"], ["111002.25000000", "0.20750000"], ["111002.19000000", "0.00721000"], ["111001.21000000", "0.00720000"], ["111001.09000000", "0.00000000"], ["111000.00000000", "0.02845000"], ["110999.97000000", "0.01784000"], ["110999.48000000", "0.07471000"], ["110998.86000000", "0.07692000"], ["110997.76000000", "0.00000000"], ["110993.91000000", "0.00000000"], ["110979.99000000", "0.00009000"], ["110965.75000000", "0.00036000"], ["110964.19000000", "0.00035000"], ["110962.47000000", "0.32439000"], ["110960.60000000", "0.00000000"], ["110959.35000000", "0.06602000"], ["110946.68000000", "0.00009000"], ["110927.30000000", "0.00000000"], ["110914.78000000", "0.09000000"], ["110913.38000000", "0.00009000"], ["110910.44000000", "0.05100000"], ["110893.99000000", "0.00000000"], ["110880.07000000", "0.00009000"], ["110860.68000000", "0.00000000"], ["110846.77000000", "0.00009000"], ["110840.58000000", "0.00000000"], ["39964.79000000", "0.00016000"]], "a": [["111013.30000000", "6.80706000"], ["111013.97000000", "0.20287000"], ["111014.41000000", "0.00099000"], ["111015.94000000", "0.00518000"], ["111016.07000000", "0.00198000"], ["111016.12000000", "0.00000000"], ["111017.74000000", "0.00360000"], ["111018.59000000", "0.87897000"], ["111018.86000000", "0.04576000"], ["111019.71000000", "0.01807000"], ["111019.96000000", "0.00540000"], ["111022.71000000", "0.30000000"], ["111023.28000000", "0.00000000"], ["111023.59000000", "0.20282000"], ["111027.06000000", "0.00007000"], ["111030.80000000", "0.00049000"], ["111033.48000000", "0.06000000"], ["111034.69000000", "0.00000000"], ["111037.46000000", "0.00000000"], ["111037.81000000", "0.03000000"], ["111039.13000000", "0.00000000"], ["111046.60000000", "0.00009000"], ["111049.89000000", "0.00000000"], ["111053.78000000", "0.00000000"], ["111060.54000000", "0.00300000"], ["111061.26000000", "0.00000000"], ["111079.91000000", "0.00009000"], ["111093.85000000", "0.00000000"], ["111113.21000000", "0.00008000"], ["111127.15000000", "0.00000000"], ["111146.52000000", "0.00008000"], ["111160.46000000", "0.00000000"], ["111179.82000000", "0.00008000"], ["111193.77000000", "0.00000000"], ["111255.48000000", "0.00029000"]]}}
{"type": "orderbook", "local_time": 1761342391503, "event_time": 1761342386614, "latency_ms": 4889, "data": {"e": "depthUpdate", "E": 1761342386614, "s": "BTCUSDT", "U": 79012695239, "u": 79012695349, "b": [["111013.29000000", "0.04518000"], ["111013.28000000", "0.00115000"], ["111010.52000000", "0.00218000"], ["111009.96000000", "0.00000000"], ["111007.30000000", "0.30556000"], ["111007.29000000", "0.02718000"], ["111006.69000000", "0.19030000"], ["111006.68000000", "0.00010000"], ["111006.67000000", "0.00000000"], ["111006.66000000", "0.00151000"], ["111006.63000000", "0.00546000"], ["111005.95000000", "0.00010000"], ["111005.94000000", "0.29729000"], ["111004.17000000", "0.10803000"], ["111004.12000000", "0.00000000"], ["111004.11000000", "0.00005000"], ["111003.79000000", "0.00000000"], ["111003.78000000", "0.00005000"], ["111003.26000000", "0.00000000"], ["111002.25000000", "0.20750000"], ["111000.21000000", "0.04670000"], ["111000.00000000", "0.02840000"], ["110999.97000000", "0.00000000"], ["110998.86000000", "0.07696000"], ["110959.35000000", "0.00000000"], ["110956.31000000", "0.32441000"], ["110909.33000000", "0.03900000"], ["110824.51000000", "0.01410000"], ["99911.00000000", "0.00020000"]], "a": [["111019.71000000", "0.01807000"], ["111023.00000000", "0.00005000"], ["111023.57000000", "0.32353000"], ["111034.00000000", "0.00171000"], ["111042.72000000", "0.32415000"], ["111045.80000000", "0.97429000"], ["111049.97000000", "0.00000000"], ["111065.96000000", "0.00000000"], ["111123.29000000", "0.00000000"]]}}
{"type": "orderbook", "local_time": 1761342391503, "event_time": 1761342386714, "latency_ms": 4789, "data": {"e": "depthUpdate", "E": 1761342386714, "s": "BTCUSDT", "U": 79012695350, "u": 79012695678, "b": [["111013.29000000", "0.00000000"], ["111013.28000000", "0.00000000"], ["111012.00000000", "0.00000000"], ["111010.52000000", "0.00000000"], ["111008.70000000", "0.00000000"], ["111008.36000000", "0.00000000"], ["111007.31000000", "0.00000000"], ["111007.30000000", "0.31382000"], ["111007.29000000", "0.02823000"], ["111006.70000000", "0.00010000"], ["111006.69000000", "0.00030000"], ["111006.68000000", "0.00000000"], ["111006.66000000", "0.00010000"], ["111006.63000000", "0.00551000"], ["111005.94000000", "0.00010000"], ["111005.03000000", "0.06504000"], ["111004.18000000", "0.00005000"], ["111004.17000000", "0.10803000"], ["111004.11000000", "0.00000000"], ["111003.78000000", "0.00000000"], ["111003.28000000", "0.03070000"], ["111003.16000000", "0.29725000"], ["111002.19000000", "0.00726000"], ["111001.94000000", "0.00150000"], ["111001.21000000", "0.00725000"], ["110999.56000000", "0.00000000"], ["110998.86000000", "0.00000000"], ["110997.64000000", "0.00000000"], ["110993.50000000", "0.00000000"], ["110992.87000000", "0.07697000"], ["110989.65000000", "0.00450000"], ["110988.16000000", "0.03600000"], ["110986.73000000", "0.00990000"], ["110985.33000000", "0.30398000"], ["110960.06000000", "0.00038000"], ["110959.13000000", "0.00033000"], ["110957.95000000", "0.06879000"], ["110953.56000000", "0.00005000"], ["110915.91000000", "0.03900000"], ["110908.58000000", "0.00064000"], ["110886.85000000", "0.03600000"], ["110766.01000000", "0.00000000"], ["110750.01000000", "0.00090000"], ["99911.00000000", "0.00000000"], ["33000.00000000", "3.79445000"]], "a": [["111007.31000000", "6.20578000"], ["111007.32000000", "0.00000000"], ["111007.37000000", "0.00000000"], ["111007.74000000", "0.00000000"], ["111008.36000000", "0.00005000"], ["111008.89000000", "0.04773000"], ["111009.63000000", "0.29723000"], ["111009.70000000", "0.00250000"], ["111009.97000000", "0.00000000"], ["111010.53000000", "0.00000000"], ["111010.67000000", "0.06748000"], ["111012.01000000", "0.00000000"], ["111012.87000000", "0.11267000"], ["111013.29000000", "0.00010000"], ["111013.30000000", "1.49612000"], ["111013.97000000", "0.20292000"], ["111018.59000000", "0.20292000"], ["111018.60000000", "0.52077000"], ["111018.61000000", "0.07666000"], ["111018.85000000", "0.00000000"], ["111019.96000000", "0.00545000"], ["111021.74000000", "0.12657000"], ["111022.43000000", "1.44342000"], ["111023.70000000", "0.00044000"], ["111024.19000000", "0.13511000"], ["111030.80000000", "0.00000000"], ["111031.95000000", "0.00000000"], ["111033.02000000", "0.00000000"], ["111034.49000000", "0.03008000"], ["111035.00000000", "0.00000000"], ["111048.11000000", "0.44478000"], ["111048.22000000", "0.00016000"], ["111049.98000000", "0.00000000"], ["111054.19000000", "0.00000000"], ["111054.34000000", "0.00000000"], ["111059.82000000", "0.00016000"], ["111062.44000000", "0.00000000"], ["111063.16000000", "0.00000000"], ["111065.18000000", "0.00000000"], ["111068.64000000", "0.00000000"], ["111073.50000000", "0.00000000"], ["111075.99000000", "0.00048000"], ["111076.35000000", "0.00000000"], ["111096.87000000", "0.00000000"], ["111129.66000000", "0.00000000"], ["111133.55000000", "0.00000000"]]}}
{"type": "orderbook", "local_time": 1761342391504, "event_time": 1761342386814, "latency_ms": 4690, "data": {"e": "depthUpdate", "E": 1761342386814, "s": "BTCUSDT", "U": 79012695679, "u": 79012695786, "b": [["111007.30000000", "0.31392000"], ["111007.29000000", "0.00120000"], ["111006.87000000", "0.00000000"], ["111006.70000000", "0.00000000"], ["111006.69000000", "0.00020000"], ["111006.66000000", "0.00000000"], ["111006.63000000", "0.00556000"], ["111005.95000000", "0.00000000"], ["111005.94000000", "0.00000000"], ["111005.29000000", "0.70920000"], ["111005.03000000", "0.06509000"], ["111004.56000000", "0.02703000"], ["111004.18000000", "0.00010000"], ["111004.17000000", "0.17460000"], ["111003.29000000", "0.00010000"], ["111003.28000000", "0.03080000"], ["111003.17000000", "0.00005000"], ["111003.16000000", "0.29730000"], ["110999.48000000", "0.04882000"], ["110999.30000000", "0.04397000"], ["110992.04000000", "0.54367000"], ["110852.90000000", "0.00000000"], ["110840.60000000", "0.09093000"], ["110819.04000000", "0.00901000"]], "a": [["111007.31000000", "6.34122000"], ["111008.88000000", "0.00010000"], ["111008.89000000", "0.04783000"], ["111009.62000000", "0.00010000"], ["111009.63000000", "0.29733000"], ["111010.66000000", "0.00010000"], ["111010.67000000", "0.06753000"], ["111012.86000000", "0.00005000"], ["111013.30000000", "0.94254000"], ["111013.97000000", "0.20287000"], ["111016.62000000", "0.02703000"], ["111018.59000000", "0.20287000"], ["111018.60000000", "0.52072000"], ["111018.61000000", "0.07661000"], ["111018.86000000", "0.04571000"], ["111019.71000000", "0.01802000"], ["111019.96000000", "0.00540000"], ["111020.79000000", "0.00000000"], ["111025.27000000", "0.00000000"], ["111028.03000000", "0.00413000"], ["111046.23000000", "0.00000000"], ["111066.87000000", "0.20724000"], ["111081.22000000", "0.00000000"]]}}
{"type": "orderbook", "local_time": 1761342391504, "event_time": 1761342386914, "latency_ms": 4590, "data": {"e": "depthUpdate", "E": 1761342386914, "s": "BTCUSDT", "U": 79012695787, "u": 79012695871, "b": [["111007.30000000", "0.31516000"], ["111007.29000000", "0.00120000"], ["111006.69000000", "0.00000000"], ["111006.63000000", "0.00566000"], ["111005.30000000", "0.00010000"], ["111005.29000000", "0.00020000"], ["111005.03000000", "0.06504000"], ["111003.57000000", "0.04990000"], ["111003.29000000", "0.00000000"], ["111003.28000000", "0.03075000"], ["111003.17000000", "0.00010000"], ["111002.26000000", "0.00005000"], ["111001.21000000", "0.00720000"], ["110999.92000000", "0.01814000"], ["110988.68000000", "0.00000000"], ["110986.96000000", "0.03600000"], ["110977.68000000", "0.04000000"], ["110915.86000000", "0.03600000"], ["110914.64000000", "0.03998000"], ["110909.73000000", "0.03600000"], ["110909.28000000", "0.03900000"], ["110902.13000000", "0.02536000"], ["110707.74000000", "0.00000000"], ["110669.47000000", "0.00572000"]], "a": [["111007.31000000", "6.15970000"], ["111009.79000000", "0.00076000"], ["111010.67000000", "0.06758000"], ["111012.87000000", "0.11277000"], ["111013.30000000", "0.75718000"], ["111015.94000000", "0.00518000"], ["111016.62000000", "0.02708000"], ["111018.60000000", "0.52067000"], ["111022.01000000", "0.00044000"], ["111035.68000000", "0.03000000"], ["111071.47000000", "0.13519000"], ["111078.24000000", "0.11717000"], ["111108.74000000", "0.03000000"]]}}
{"type": "orderbook", "local_time": 1761342391504, "event_time": 1761342387014, "latency_ms": 4490, "data": {"e": "depthUpdate", "E": 1761342387014, "s": "BTCUSDT", "U": 79012695872, "u": 79012696237, "b": [["111007.30000000", "0.00000000"], ["111007.29000000", "0.00000000"], ["111006.63000000", "0.00692000"], ["111006.62000000", "0.00090000"], ["111005.58000000", "0.00000000"], ["111005.30000000", "0.00000000"], ["111005.29000000", "0.00000000"], ["111005.03000000", "0.06524000"], ["111004.57000000", "0.00010000"], ["111004.56000000", "0.02733000"], ["111004.17000000", "0.17470000"], ["111003.86000000", "0.00401000"], ["111003.58000000", "0.00010000"], ["111003.57000000", "0.00010000"], ["111003.29000000", "0.00005000"], ["111003.28000000", "0.03080000"], ["111003.17000000", "0.00005000"], ["111003.16000000", "0.00005000"], ["111002.26000000", "0.00000000"], ["111002.25000000", "0.00005000"], ["111001.21000000", "0.00005000"], ["111001.00000000", "0.00005000"], ["111000.33000000", "0.29725000"], ["111000.21000000", "0.00000000"], ["110999.92000000", "0.00000000"], ["110999.77000000", "0.00000000"], ["110999.47000000", "0.00300000"], ["110999.30000000", "0.00000000"], ["110998.34000000", "0.00720000"], ["110997.32000000", "0.00000000"], ["110996.58000000", "0.01771000"], ["110996.38000000", "0.00000000"], ["110996.35000000", "0.00000000"], ["110995.64000000", "0.20745000"], ["110994.92000000", "0.00333000"], ["110993.23000000", "0.00014000"], ["110990.82000000", "0.00000000"], ["110990.66000000", "0.00090000"], ["110990.46000000", "0.00000000"], ["110990.30000000", "0.00000000"], ["110989.65000000", "0.00000000"], ["110989.44000000", "0.00000000"], ["110988.09000000", "0.00000000"], ["110987.55000000", "0.00000000"], ["110986.92000000", "0.00000000"], ["110986.76000000", "0.00000000"], ["110986.75000000", "0.00000000"], ["110985.32000000", "0.00000000"], ["110985.09000000", "0.11267000"], ["110984.46000000", "0.00000000"], ["110983.54000000", "0.01802000"], ["110983.36000000", "0.00450000"], ["110983.35000000", "0.00000000"], ["110983.01000000", "0.00000000"], ["110981.41000000", "0.00000000"], ["110981.31000000", "0.07660000"], ["110980.13000000", "0.20444000"], ["110979.65000000", "0.00000000"], ["110979.41000000", "0.02000000"], ["110978.01000000", "0.12000000"], ["110977.50000000", "0.00000000"], ["110977.31000000", "0.16000000"], ["110976.47000000", "0.00000000"], ["110974.10000000", "0.00250000"], ["110972.00000000", "0.00120000"], ["110971.71000000", "0.00000000"], ["110971.37000000", "0.00000000"], ["110969.81000000", "0.00000000"], ["110968.09000000", "0.00000000"], ["110967.78000000", "0.00090000"], ["110964.99000000", "0.00000000"], ["110957.95000000", "0.00000000"], ["110957.35000000", "0.00000000"], ["110955.95000000", "0.00000000"], ["110953.78000000", "0.00000000"], ["110953.57000000", "0.06776000"], ["110952.01000000", "0.00000000"], ["110950.50000000", "0.32442000"], ["110949.55000000", "0.00000000"], ["110940.01000000", "0.00000000"], ["110936.49000000", "0.02663000"], ["110935.97000000", "0.00000000"], ["110931.08000000", "0.00000000"], ["110923.79000000", "0.00000000"], ["110919.17000000", "0.00000000"], ["110918.21000000", "0.00000000"], ["110906.48000000", "0.03218000"], ["110905.00000000", "0.00000000"], ["110896.55000000", "0.00005000"], ["110896.34000000", "0.22535000"], ["110891.44000000", "0.18027000"], ["110884.00000000", "0.11540000"], ["110866.01000000", "0.00000000"], ["110824.51000000", "0.00000000"], ["110808.43000000", "0.00000000"], ["110807.74000000", "0.01410000"], ["110803.14000000", "0.00000000"], ["110750.01000000", "0.00000000"], ["110745.97000000", "0.00000000"], ["110745.78000000", "0.00000000"], ["110717.34000000", "0.00000000"], ["110713.55000000", "0.00000000"], ["110712.83000000", "0.00000000"], ["110711.56000000", "0.00000000"], ["110707.73000000", "0.00000000"], ["110674.36000000", "0.00000000"], ["110626.81000000", "0.00000000"], ["110579.44000000", "0.00000000"], ["110575.44000000", "0.02698000"], ["110573.62000000", "0.02698000"], ["110551.33000000", "0.02698000"], ["110535.37000000", "0.00000000"], ["110533.86000000", "0.00000000"], ["110519.14000000", "0.03698000"], ["99916.00000000", "0.00000000"], ["99906.00000000", "0.00010000"]], "a": [["111006.64000000", "3.53486000"], ["111006.70000000", "0.00476000"], ["111007.30000000", "0.50005000"], ["111007.31000000", "2.10194000"], ["111008.88000000", "0.00000000"], ["111008.89000000", "0.00010000"], ["111008.93000000", "0.00000000"], ["111009.13000000", "0.01809000"], ["111009.62000000", "0.00000000"], ["111009.63000000", "0.00010000"], ["111010.66000000", "0.00000000"], ["111011.89000000", "0.04571000"], ["111012.86000000", "0.00000000"], ["111012.87000000", "0.11272000"], ["111013.29000000", "0.00000000"], ["111013.30000000", "0.00121000"], ["111016.08000000", "0.01802000"], ["111016.69000000", "1.44342000"], ["111018.41000000", "0.00087000"], ["111018.59000000", "0.20282000"], ["111018.60000000", "0.50235000"], ["111018.86000000", "0.00000000"], ["111019.71000000", "0.00000000"], ["111023.29000000", "0.00090000"], ["111028.01000000", "1.44342000"], ["111029.52000000", "0.00300000"], ["111037.70000000", "0.00000000"], ["111047.44000000", "0.25252000"], ["111048.03000000", "0.07661000"], ["111048.11000000", "0.00000000"], ["111051.91000000", "0.00000000"], ["111060.54000000", "0.00000000"], ["111071.47000000", "0.00000000"], ["111082.74000000", "0.00000000"], ["111088.55000000", "0.00000000"], ["111122.47000000", "0.09817000"], ["111132.26000000", "0.01350000"], ["111157.45000000", "0.00007000"], ["111162.23000000", "0.00000000"]]}}
{"type": "orderbook", "local_time": 1761342391505, "event_time": 1761342387114, "latency_ms": 4391, "data": {"e": "depthUpdate", "E": 1761342387114, "s": "BTCUSDT", "U": 79012696238, "u": 79012696441, "b": [["111006.63000000", "0.00894000"], ["111006.62000000", "0.00110000"], ["111005.04000000", "0.31244000"], ["111004.56000000", "0.00020000"], ["111004.17000000", "0.10813000"], ["111003.86000000", "0.00396000"], ["111003.58000000", "0.00000000"], ["111003.57000000", "0.00000000"], ["111003.29000000", "0.00010000"], ["111003.28000000", "0.03080000"], ["111003.17000000", "0.00000000"], ["111003.16000000", "0.00000000"], ["111002.25000000", "0.00000000"], ["111002.19000000", "0.00726000"], ["111001.71000000", "0.00000000"], ["111001.70000000", "0.00692000"], ["111001.21000000", "0.00000000"], ["111001.00000000", "0.00000000"], ["111000.34000000", "0.00005000"], ["111000.33000000", "0.29735000"], ["111000.00000000", "0.02845000"], ["110999.48000000", "0.09611000"], ["110998.34000000", "0.00005000"], ["110996.58000000", "0.00000000"], ["110995.48000000", "0.04435000"], ["110995.18000000", "0.04670000"], ["110994.42000000", "0.00720000"], ["110992.88000000", "0.04055000"], ["110992.04000000", "0.00000000"], ["110990.28000000", "0.00000000"], ["110989.98000000", "0.00151000"], ["110986.77000000", "0.15656000"], ["110985.09000000", "0.11567000"], ["110983.91000000", "0.20282000"], ["110983.56000000", "0.00000000"], ["110983.54000000", "0.00000000"], ["110983.51000000", "0.01802000"], ["110982.87000000", "0.05100000"], ["110980.78000000", "0.00000000"], ["110977.68000000", "0.00000000"], ["110975.18000000", "0.00000000"], ["110973.99000000", "0.00300000"], ["110973.24000000", "0.00009000"], ["110971.38000000", "0.04000000"], ["110971.10000000", "0.00009000"], ["110970.07000000", "0.00009000"], ["110965.29000000", "0.32438000"], ["110964.97000000", "0.00009000"], ["110958.58000000", "0.00009000"], ["110957.15000000", "0.34583000"], ["110956.68000000", "0.00090000"], ["110953.57000000", "0.00000000"], ["110926.01000000", "0.01891000"], ["110917.39000000", "0.00090000"], ["110916.42000000", "0.00000000"], ["110909.73000000", "0.00000000"], ["110895.41000000", "0.22544000"], ["110892.83000000", "0.00000000"], ["110887.04000000", "0.05100000"], ["110886.86000000", "0.03997000"], ["110886.85000000", "0.00000000"], ["110884.17000000", "0.00005000"], ["110881.74000000", "0.00000000"], ["110860.02000000", "0.00224000"], ["110794.13000000", "0.27137000"], ["110777.69000000", "0.01891000"], ["110748.39000000", "0.00090000"], ["110719.12000000", "0.01711000"], ["110717.31000000", "0.01711000"], ["110688.83000000", "0.01711000"], ["110680.32000000", "0.01711000"], ["110647.07000000", "0.01711000"], ["110625.93000000", "0.00000000"], ["110518.87000000", "0.03698000"]], "a": [["111006.64000000", "4.25019000"], ["111007.29000000", "0.53664000"], ["111007.30000000", "0.50025000"], ["111007.31000000", "1.16900000"], ["111008.89000000", "0.00000000"], ["111009.13000000", "0.01814000"], ["111009.63000000", "0.00000000"], ["111010.67000000", "0.06753000"], ["111011.89000000", "0.04576000"], ["111012.41000000", "0.00000000"], ["111012.87000000", "0.11272000"], ["111013.30000000", "0.00116000"], ["111013.85000000", "0.00000000"], ["111015.18000000", "0.01802000"], ["111015.94000000", "0.00518000"], ["111016.08000000", "0.00000000"], ["111016.62000000", "0.02703000"], ["111018.42000000", "0.00300000"], ["111047.44000000", "0.44504000"], ["111056.89000000", "0.00000000"], ["111064.99000000", "0.00010000"], ["111083.08000000", "0.00000000"], ["111096.29000000", "0.00000000"], ["111108.74000000", "0.00000000"], ["111291.69000000", "0.02432000"], ["111397.59000000", "0.00000000"]]}}
{"type": "orderbook", "local_time": 1761342391506, "event_time": 1761342387214, "latency_ms": 4292, "data": {"e": "depthUpdate", "E": 1761342387214, "s": "BTCUSDT", "U": 79012696442, "u": 79012696718, "b": [["111006.63000000", "0.00000000"], ["111006.62000000", "0.00000000"], ["111005.40000000", "0.00000000"], ["111005.28000000", "0.00000000"], ["111005.05000000", "0.00000000"], ["111005.04000000", "0.00735000"], ["111005.03000000", "0.06604000"], ["111004.57000000", "0.00000000"], ["111004.56000000", "0.00000000"], ["111004.17000000", "0.10828000"], ["111003.86000000", "0.00406000"], ["111003.28000000", "0.03085000"], ["111003.18000000", "0.29725000"], ["111002.89000000", "0.70680000"], ["111002.19000000", "0.00726000"], ["111001.70000000", "0.00005000"], ["111001.69000000", "0.00692000"], ["111001.39000000", "0.00000000"], ["111000.34000000", "0.00010000"], ["111000.33000000", "0.00010000"], ["111000.01000000", "0.00005000"], ["111000.00000000", "0.02850000"], ["110999.48000000", "0.09611000"], ["110998.34000000", "0.00000000"], ["110998.17000000", "0.00000000"], ["110997.55000000", "0.04958000"], ["110996.40000000", "0.04551000"], ["110995.64000000", "0.20745000"], ["110994.92000000", "0.00000000"], ["110993.23000000", "0.00000000"], ["110992.88000000", "0.02755000"], ["110990.97000000", "0.00014000"], ["110970.37000000", "0.13511000"], ["110956.24000000", "0.84230000"], ["110952.92000000", "0.00000000"], ["110952.36000000", "0.06824000"], ["110949.30000000", "0.00005000"], ["110918.09000000", "0.01410000"], ["110909.76000000", "0.00000000"], ["110900.34000000", "0.00223000"], ["110886.32000000", "0.00000000"], ["110878.02000000", "0.00191000"], ["110869.45000000", "0.00114000"], ["110858.36000000", "0.00229000"], ["110810.01000000", "0.00000000"], ["110790.01000000", "0.00090000"], ["110786.01000000", "0.00000000"], ["110766.01000000", "0.00076000"], ["109599.87000000", "0.02501000"]], "a": [["111005.05000000", "6.12457000"], ["111005.06000000", "0.00000000"], ["111005.11000000", "0.00000000"], ["111005.25000000", "0.00250000"], ["111005.83000000", "0.00033000"], ["111006.63000000", "1.48332000"], ["111006.64000000", "0.92439000"], ["111006.70000000", "0.00000000"], ["111007.28000000", "0.00010000"], ["111007.29000000", "0.00010000"], ["111007.31000000", "0.35669000"], ["111012.86000000", "0.11119000"], ["111013.97000000", "0.20287000"], ["111015.94000000", "0.00513000"], ["111016.68000000", "0.70601000"], ["111022.42000000", "0.76452000"], ["111023.57000000", "0.00000000"], ["111025.62000000", "0.01035000"], ["111027.50000000", "0.00000000"], ["111045.85000000", "0.22252000"], ["111047.44000000", "0.22252000"], ["111048.08000000", "0.00000000"], ["111060.34000000", "0.00224000"], ["111064.99000000", "0.00124000"], ["111069.01000000", "0.00000000"], ["111069.07000000", "0.13519000"], ["111069.36000000", "0.00000000"], ["111071.50000000", "0.13511000"], ["111080.82000000", "0.00000000"], ["111087.99000000", "0.00224000"], ["111107.98000000", "0.00000000"], ["111171.36000000", "0.00090000"], ["111191.41000000", "0.00000000"], ["111199.79000000", "0.00090000"], ["111218.88000000", "0.00000000"]]}}
{"type": "orderbook", "local_time": 1761342391506, "event_time": 1761342387314, "latency_ms": 4192, "data": {"e": "depthUpdate", "E": 1761342387314, "s": "BTCUSDT", "U": 79012696719, "u": 79012696806, "b": [["111005.04000000", "0.00740000"], ["111005.03000000", "0.06599000"], ["111003.28000000", "0.03085000"], ["111003.19000000", "0.00010000"], ["111003.18000000", "0.29735000"], ["111002.90000000", "0.00005000"], ["111002.89000000", "0.00010000"], ["111002.19000000", "0.00726000"], ["111001.70000000", "0.00000000"], ["111001.69000000", "0.00005000"], ["111000.55000000", "0.02703000"], ["111000.34000000", "0.00000000"], ["111000.33000000", "0.00000000"], ["111000.01000000", "0.00000000"], ["111000.00000000", "0.02845000"], ["110999.48000000", "0.09611000"], ["110998.34000000", "0.00720000"], ["110996.40000000", "0.04546000"], ["110994.42000000", "0.00000000"], ["110971.74000000", "0.04506000"], ["110952.36000000", "0.00000000"], ["110951.71000000", "0.06879000"], ["110913.97000000", "0.13377000"], ["110887.04000000", "0.00000000"]], "a": [["111005.05000000", "6.12467000"], ["111006.62000000", "0.68963000"], ["111006.63000000", "0.00020000"], ["111006.64000000", "0.75615000"], ["111007.28000000", "0.00000000"], ["111007.29000000", "0.00010000"], ["111011.89000000", "0.04576000"], ["111013.97000000", "0.20282000"], ["111015.18000000", "0.00000000"], ["111016.71000000", "0.01802000"], ["111026.19000000", "0.00700000"], ["111038.35000000", "0.04507000"], ["111069.07000000", "0.00000000"], ["111070.43000000", "0.13519000"], ["111083.08000000", "0.00229000"], ["111096.40000000", "0.13511000"], ["111101.38000000", "0.03400000"], ["111108.64000000", "0.00000000"], ["111121.40000000", "0.00000000"]]}}
{"type": "orderbook", "local_time": 1761342391507, "event_time": 1761342387414, "latency_ms": 4093, "data": {"e": "depthUpdate", "E": 1761342387414, "s": "BTCUSDT", "U": 79012696807, "u": 79012696855, "b": [["111005.04000000", "0.00409000"], ["111005.03000000", "0.06599000"], ["111003.18000000", "0.29735000"], ["111002.90000000", "0.00000000"], ["111002.89000000", "0.00000000"], ["111002.19000000", "0.00726000"], ["111001.69000000", "0.00000000"], ["111000.56000000", "0.00005000"], ["111000.55000000", "0.02708000"], ["110999.83000000", "0.20745000"], ["110999.48000000", "0.09611000"], ["110995.64000000", "0.00000000"], ["110992.80000000", "0.00326000"], ["110986.55000000", "0.01802000"], ["110983.51000000", "0.00000000"], ["110956.24000000", "0.00000000"], ["110914.63000000", "0.00000000"]], "a": [["111005.05000000", "6.15790000"], ["111006.61000000", "0.40252000"], ["111006.62000000", "0.00010000"], ["111006.63000000", "0.00010000"], ["111012.86000000", "0.11124000"], ["111016.71000000", "0.00000000"], ["111018.17000000", "0.01802000"], ["111018.60000000", "0.50240000"], ["111045.80000000", "0.00000000"]]}}
{"type": "orderbook", "local_time": 1761342391507, "event_time": 1761342387514, "latency_ms": 3993, "data": {"e": "depthUpdate", "E": 1761342387514, "s": "BTCUSDT", "U": 79012696856, "u": 79012696873, "b": [["111005.04000000", "0.00409000"], ["111000.55000000", "0.00005000"], ["111000.00000000", "0.02840000"], ["110996.58000000", "0.01838000"]], "a": [["111005.05000000", "6.15800000"], ["111006.60000000", "0.00010000"], ["111006.61000000", "0.40247000"], ["111006.62000000", "0.00000000"], ["111006.64000000", "0.57588000"], ["111101.38000000", "0.00000000"], ["111101.39000000", "0.03400000"], ["111123.29000000", "0.03000000"]]}}
{"type": "orderbook", "local_time": 1761342391507, "event_time": 1761342387614, "latency_ms": 3893, "data": {"e": "depthUpdate", "E": 1761342387614, "s": "BTCUSDT", "U": 79012696874, "u": 79012696896, "b": [["111005.04000000", "0.00409000"], ["111005.03000000", "0.06599000"], ["111003.18000000", "0.29730000"], ["111002.19000000", "0.00726000"], ["111000.56000000", "0.00000000"], ["111000.55000000", "0.00000000"], ["111000.01000000", "0.00005000"], ["111000.00000000", "0.02845000"]], "a": [["111005.05000000", "5.84262000"], ["111006.61000000", "0.40252000"], ["111006.64000000", "0.08010000"], ["111017.50000000", "0.00005000"], ["111018.60000000", "0.27696000"], ["111080.59000000", "0.13172000"], ["111095.98000000", "0.18027000"]]}}
{"type": "orderbook", "local_time": 1761342391508, "event_time": 1761342387714, "latency_ms": 3794, "data": {"e": "depthUpdate", "E": 1761342387714, "s": "BTCUSDT", "U": 79012696897, "u": 79012696909, "b": [["110956.24000000", "0.84230000"], ["110926.15000000", "0.03600000"], ["110824.22000000", "0.00000000"]], "a": [["111010.66000000", "0.00005000"], ["111021.75000000", "0.13519000"], ["111032.36000000", "0.18027000"], ["111040.12000000", "0.93944000"], ["111045.57000000", "0.13511000"], ["111071.57000000", "0.13524000"], ["111076.20000000", "0.00000000"], ["111097.17000000", "0.22535000"], ["111097.88000000", "0.22544000"], ["111250.36000000", "0.00000000"]]}}
{"type": "orderbook", "local_time": 1761342391508, "event_time": 1761342387815, "latency_ms": 3693, "data": {"e": "depthUpdate", "E": 1761342387815, "s": "BTCUSDT", "U": 79012696910, "u": 79012696917, "b": [["111000.53000000", "0.02703000"], ["110957.52000000", "1.03932000"], ["102145.79000000", "0.00010000"]], "a": [["111045.56000000", "0.81482000"], ["111045.93000000", "0.00000000"], ["111070.48000000", "0.00402000"], ["111244.62000000", "0.00089000"], ["111357.99000000", "0.48717000"]]}}
{"type": "orderbook", "local_time": 1761342391509, "event_time": 1761342387914, "latency_ms": 3595, "data": {"e": "depthUpdate", "E": 1761342387914, "s": "BTCUSDT", "U": 79012696918, "u": 79012696941, "b": [["111005.04000000", "0.00414000"], ["111005.03000000", "0.06604000"], ["111002.19000000", "0.00726000"], ["110999.83000000", "0.00000000"], ["110998.34000000", "0.00000000"], ["110909.73000000", "0.03600000"]], "a": [["111005.05000000", "6.15800000"], ["111006.96000000", "0.00720000"], ["111007.31000000", "0.34949000"], ["111045.02000000", "0.58590000"], ["111045.57000000", "0.00000000"], ["111095.79000000", "0.00000000"], ["111095.98000000", "0.00000000"], ["111096.40000000", "0.00000000"], ["111097.17000000", "0.00000000"], ["111097.88000000", "0.00000000"], ["111108.74000000", "0.03000000"]]}}
{"type": "orderbook", "local_time": 1761342391509, "event_time": 1761342388014, "latency_ms": 3495, "data": {"e": "depthUpdate", "E": 1761342388014, "s": "BTCUSDT", "U": 79012696942, "u": 79012696966, "b": [["111005.04000000", "0.00538000"], ["111005.03000000", "0.06609000"], ["111000.53000000", "0.00005000"], ["111000.52000000", "0.02703000"], ["111000.00000000", "0.02845000"], ["110999.48000000", "0.09606000"], ["110999.24000000", "0.21465000"], ["110985.09000000", "0.11267000"], ["110981.67000000", "0.00900000"], ["110971.73000000", "0.00300000"]], "a": [["111006.64000000", "0.08010000"], ["111006.96000000", "0.00725000"], ["111012.87000000", "0.11267000"], ["111022.01000000", "0.00000000"], ["111045.02000000", "0.45079000"], ["111095.63000000", "0.13511000"], ["111357.99000000", "0.00000000"]]}}
{"type": "orderbook", "local_time": 1761342391509, "event_time": 1761342388114, "latency_ms": 3395, "data": {"e": "depthUpdate", "E": 1761342388114, "s": "BTCUSDT", "U": 79012696967, "u": 79012697004, "b": [["111005.04000000", "0.00563000"], ["111005.03000000", "0.06609000"], ["111002.19000000", "0.00726000"], ["111000.53000000", "0.00000000"], ["111000.52000000", "0.00000000"], ["111000.33000000", "0.02703000"], ["110999.24000000", "0.00000000"], ["110997.55000000", "0.04972000"], ["110990.97000000", "0.00000000"], ["110986.55000000", "0.00000000"], ["110986.54000000", "0.01802000"], ["110977.00000000", "0.00000000"], ["110888.78000000", "0.00005000"], ["110807.74000000", "0.00000000"], ["99906.00000000", "0.00000000"], ["99904.00000000", "0.00010000"]], "a": [["111005.05000000", "6.29246000"], ["111021.75000000", "0.00000000"], ["111028.03000000", "0.00287000"], ["111045.02000000", "0.58590000"], ["111069.65000000", "0.13519000"], ["111070.43000000", "0.00000000"], ["111095.63000000", "0.00000000"], ["111103.35000000", "0.00100000"], ["111103.36000000", "0.00100000"], ["111125.90000000", "0.00000000"], ["111125.91000000", "0.00000000"], ["111227.83000000", "0.00000000"]]}}
{"type": "orderbook", "local_time": 1761342391510, "event_time": 1761342388214, "latency_ms": 3296, "data": {"e": "depthUpdate", "E": 1761342388214, "s": "BTCUSDT", "U": 79012697005, "u": 79012697028, "b": [["111005.04000000", "0.00563000"], ["111005.03000000", "0.06604000"], ["111002.19000000", "0.00726000"], ["111000.34000000", "0.00005000"], ["111000.33000000", "0.00000000"], ["111000.32000000", "0.02703000"], ["110998.84000000", "0.21465000"], ["110904.31000000", "0.00005000"], ["110792.37000000", "0.01410000"], ["99904.00000000", "0.00040000"]], "a": [["111009.13000000", "0.00005000"], ["111010.66000000", "0.00000000"], ["111010.74000000", "0.01819000"], ["111045.02000000", "0.45079000"], ["111098.39000000", "0.03400000"], ["111101.39000000", "0.00000000"], ["111204.64000000", "0.01410000"]]}}
{"type": "orderbook", "local_time": 1761342392215, "event_time": 1761342388314, "latency_ms": 3901, "data": {"e": "depthUpdate", "E": 1761342388314, "s": "BTCUSDT", "U": 79012697029, "u": 79012697061, "b": [["111005.04000000", "0.00563000"], ["111005.03000000", "0.06614000"], ["111002.19000000", "0.00726000"], ["111000.34000000", "0.00000000"], ["111000.33000000", "0.00005000"], ["111000.32000000", "0.00000000"], ["111000.23000000", "0.00000000"], ["111000.22000000", "0.02703000"], ["111000.01000000", "0.00000000"], ["110956.24000000", "0.00000000"], ["102145.79000000", "0.00000000"], ["99904.00000000", "0.00020000"], ["39961.82000000", "0.00016000"]], "a": [["111005.05000000", "6.29251000"], ["111007.31000000", "0.34949000"], ["111009.13000000", "0.00000000"], ["111010.66000000", "0.00000000"], ["111010.67000000", "0.06753000"], ["111010.74000000", "0.01824000"], ["111021.21000000", "0.03000000"], ["111023.52000000", "0.03000000"], ["111045.02000000", "0.58590000"]]}}
{"type": "orderbook", "local_time": 1761342392216, "event_time": 1761342388414, "latency_ms": 3802, "data": {"e": "depthUpdate", "E": 1761342388414, "s": "BTCUSDT", "U": 79012697062, "u": 79012697093, "b": [["111005.04000000", "0.00563000"], ["111005.03000000", "0.06614000"], ["111002.19000000", "0.00726000"], ["111000.33000000", "0.00000000"], ["111000.23000000", "0.00005000"], ["111000.22000000", "0.00000000"], ["111000.21000000", "0.02703000"], ["110982.89000000", "0.04000000"], ["110971.74000000", "0.00000000"], ["110971.38000000", "0.00000000"], ["99904.00000000", "0.00010000"]], "a": [["111005.05000000", "6.15732000"], ["111005.80000000", "0.04571000"], ["111005.99000000", "0.04000000"], ["111006.64000000", "0.00010000"], ["111010.66000000", "0.00005000"], ["111011.89000000", "0.00005000"], ["111017.90000000", "0.03000000"], ["111018.17000000", "0.00000000"], ["111019.01000000", "0.13519000"], ["111019.10000000", "0.01802000"], ["111021.78000000", "0.03000000"], ["111032.36000000", "0.00000000"], ["111038.35000000", "0.00000000"], ["111045.02000000", "0.45079000"], ["111045.74000000", "0.00000000"], ["111096.22000000", "0.00000000"], ["111096.86000000", "0.18027000"]]}}
{"type": "orderbook", "local_time": 1761342392216, "event_time": 1761342388514, "latency_ms": 3702, "data": {"e": "depthUpdate", "E": 1761342388514, "s": "BTCUSDT", "U": 79012697094, "u": 79012697136, "b": [["111005.04000000", "0.00563000"], ["111005.03000000", "0.06614000"], ["111002.19000000", "0.00721000"], ["111000.23000000", "0.00000000"], ["111000.22000000", "0.00005000"], ["111000.21000000", "0.00000000"], ["111000.20000000", "0.02703000"], ["110997.51000000", "0.04541000"], ["110995.18000000", "0.00000000"], ["110973.47000000", "0.84217000"]], "a": [["111005.05000000", "6.10974000"], ["111005.79000000", "0.00010000"], ["111005.80000000", "0.04581000"], ["111005.98000000", "0.00005000"], ["111005.99000000", "0.04005000"], ["111006.61000000", "0.28256000"], ["111006.63000000", "0.00000000"], ["111006.64000000", "0.00000000"], ["111007.31000000", "0.34944000"], ["111010.66000000", "0.00000000"], ["111010.74000000", "0.01824000"], ["111011.89000000", "0.00000000"], ["111018.01000000", "0.06000000"], ["111022.34000000", "0.03000000"], ["111033.38000000", "0.00000000"], ["111037.26000000", "0.00000000"], ["111096.71000000", "0.13511000"], ["113000.00000000", "40.24554000"]]}}
{"type": "orderbook", "local_time": 1761342392217, "event_time": 1761342388614, "latency_ms": 3603, "data": {"e": "depthUpdate", "E": 1761342388614, "s": "BTCUSDT", "U": 79012697137, "u": 79012697314, "b": [["111005.04000000", "0.00000000"], ["111005.03000000", "0.06546000"], ["111005.02000000", "0.00080000"], ["111003.86000000", "0.00416000"], ["111003.28000000", "0.03090000"], ["111003.18000000", "0.29740000"], ["111002.19000000", "0.00726000"], ["111000.22000000", "0.00000000"], ["111000.21000000", "0.00010000"], ["111000.20000000", "0.02713000"], ["111000.01000000", "0.00005000"], ["110999.48000000", "0.09611000"], ["110998.84000000", "0.21470000"], ["110997.55000000", "0.04977000"], ["110982.89000000", "0.00000000"], ["110980.39000000", "0.04000000"], ["99904.00000000", "0.00010000"]], "a": [["111005.04000000", "5.75306000"], ["111005.05000000", "2.11236000"], ["111005.79000000", "0.00000000"], ["111005.98000000", "0.00000000"], ["111005.99000000", "0.04010000"], ["111006.60000000", "0.00000000"], ["111006.61000000", "0.00010000"], ["111007.16000000", "0.04548000"], ["111007.29000000", "0.00000000"], ["111007.30000000", "0.50010000"], ["111012.86000000", "0.11119000"], ["111017.91000000", "0.03000000"], ["111023.45000000", "0.03000000"], ["111033.48000000", "0.03000000"], ["111045.02000000", "0.00000000"], ["111045.85000000", "0.00000000"], ["111071.57000000", "0.00000000"], ["111096.86000000", "0.00000000"], ["111097.44000000", "0.03405000"], ["111098.39000000", "0.00000000"], ["111120.70000000", "0.00000000"], ["111123.29000000", "0.00000000"]]}}
{"type": "orderbook", "local_time": 1761342392217, "event_time": 1761342388714, "latency_ms": 3503, "data": {"e": "depthUpdate", "E": 1761342388714, "s": "BTCUSDT", "U": 79012697315, "u": 79012697366, "b": [["111005.03000000", "0.15962000"], ["111005.02000000", "0.00100000"], ["111003.86000000", "0.00406000"], ["111003.29000000", "0.70510000"], ["111003.28000000", "0.03085000"], ["111003.18000000", "0.29735000"], ["111000.19000000", "0.00014000"], ["110997.55000000", "0.04963000"]], "a": [["111005.04000000", "5.79239000"], ["111005.05000000", "1.30970000"], ["111005.99000000", "0.04010000"], ["111006.61000000", "0.00000000"], ["111006.96000000", "0.00725000"], ["111007.16000000", "0.04553000"], ["111007.29000000", "0.00010000"], ["111007.30000000", "0.50020000"], ["111016.81000000", "0.03000000"], ["111019.03000000", "0.03000000"], ["111033.48000000", "0.00000000"], ["111037.81000000", "0.00000000"], ["111045.84000000", "0.22257000"], ["111069.47000000", "0.13524000"], ["111073.29000000", "0.00044000"], ["111095.93000000", "0.00000000"], ["111096.02000000", "0.22544000"], ["111096.10000000", "0.00000000"], ["111096.72000000", "0.18027000"]]}}
{"type": "orderbook", "local_time": 1761342392218, "event_time": 1761342388814, "latency_ms": 3404, "data": {"e": "depthUpdate", "E": 1761342388814, "s": "BTCUSDT", "U": 79012697367, "u": 79012697431, "b": [["111005.03000000", "0.15972000"], ["111005.02000000", "0.00105000"], ["111004.17000000", "0.00030000"], ["111003.86000000", "0.00406000"], ["111003.30000000", "0.32791000"], ["111003.29000000", "0.00015000"], ["111003.28000000", "0.03080000"], ["111003.04000000", "0.04876000"], ["111000.21000000", "0.00000000"], ["111000.20000000", "0.02708000"], ["111000.01000000", "0.00000000"], ["110999.62000000", "0.04536000"], ["110999.49000000", "0.00010000"], ["110998.85000000", "0.00005000"], ["110997.55000000", "0.00000000"], ["110997.51000000", "0.00005000"], ["110976.80000000", "0.00576000"], ["110971.15000000", "0.91560000"], ["110946.95000000", "0.00000000"], ["110840.60000000", "0.00000000"], ["110794.13000000", "0.00000000"], ["42000.00000000", "1.36834000"]], "a": [["111005.04000000", "5.56695000"], ["111005.05000000", "0.63373000"], ["111005.25000000", "0.00000000"], ["111005.99000000", "0.00010000"], ["111006.96000000", "0.00005000"], ["111007.16000000", "0.00005000"], ["111007.31000000", "0.14199000"], ["111009.89000000", "0.04000000"], ["111012.00000000", "0.00005000"], ["111012.87000000", "0.00000000"], ["111013.96000000", "0.00010000"], ["111016.16000000", "0.11267000"], ["111019.85000000", "0.13524000"], ["111027.50000000", "0.00250000"], ["111032.84000000", "0.18027000"], ["111034.49000000", "0.00008000"], ["111047.14000000", "0.13511000"], ["111063.58000000", "0.52192000"], ["111097.65000000", "0.22535000"], ["111118.89000000", "0.00000000"], ["111148.39000000", "0.06000000"], ["111204.64000000", "0.00000000"]]}}
{"type": "orderbook", "local_time": 1761342392218, "event_time": 1761342388914, "latency_ms": 3304, "data": {"e": "depthUpdate", "E": 1761342388914, "s": "BTCUSDT", "U": 79012697432, "u": 79012697516, "b": [["111005.03000000", "0.15982000"], ["111005.02000000", "0.00095000"], ["111004.18000000", "0.00000000"], ["111004.17000000", "0.00020000"], ["111003.86000000", "0.00406000"], ["111003.31000000", "0.93455000"], ["111003.30000000", "0.00015000"], ["111003.29000000", "0.00010000"], ["111003.18000000", "0.29730000"], ["111003.05000000", "0.00010000"], ["111003.04000000", "0.04881000"], ["111000.00000000", "0.02840000"], ["110999.63000000", "0.00005000"], ["110999.49000000", "0.00005000"], ["110998.85000000", "0.00000000"], ["110998.84000000", "0.21465000"], ["110981.67000000", "0.00000000"], ["110976.80000000", "0.00000000"]], "a": [["111005.04000000", "5.56695000"], ["111005.05000000", "0.51410000"], ["111005.79000000", "0.00010000"], ["111005.80000000", "0.04581000"], ["111005.99000000", "0.00000000"], ["111006.60000000", "0.20745000"], ["111006.96000000", "0.00000000"], ["111007.16000000", "0.00000000"], ["111007.30000000", "0.50025000"], ["111007.31000000", "0.14204000"], ["111009.28000000", "0.04548000"], ["111009.89000000", "0.00005000"], ["111012.80000000", "0.04000000"], ["111012.86000000", "0.11124000"], ["111013.96000000", "0.00000000"], ["111013.97000000", "0.20287000"], ["111016.93000000", "0.03000000"], ["111020.26000000", "0.03000000"], ["111023.48000000", "0.03000000"], ["111023.58000000", "0.00043000"], ["111030.80000000", "0.22544000"], ["111097.65000000", "0.00000000"]]}}
{"type": "orderbook", "local_time": 1761342392219, "event_time": 1761342389014, "latency_ms": 3205, "data": {"e": "depthUpdate", "E": 1761342389014, "s": "BTCUSDT", "U": 79012697517, "u": 79012697585, "b": [["111005.03000000", "0.16117000"], ["111005.02000000", "0.00090000"], ["111004.17000000", "0.00000000"], ["111003.86000000", "0.00416000"], ["111003.32000000", "0.41097000"], ["111003.31000000", "0.00010000"], ["111003.30000000", "0.00000000"], ["111003.29000000", "0.00000000"], ["111003.28000000", "0.03085000"], ["111003.05000000", "0.00000000"], ["110999.63000000", "0.00000000"], ["110999.49000000", "0.00010000"], ["110998.85000000", "0.00010000"], ["110996.35000000", "0.00250000"], ["110979.45000000", "0.00900000"], ["110974.10000000", "0.00000000"], ["88804.00000000", "0.00000000"]], "a": [["111005.04000000", "5.56695000"], ["111005.80000000", "0.04581000"], ["111006.59000000", "0.00730000"], ["111006.60000000", "0.20755000"], ["111007.31000000", "0.14199000"], ["111009.28000000", "0.04553000"], ["111009.89000000", "0.00000000"], ["111010.74000000", "0.01824000"], ["111012.80000000", "0.04005000"], ["111012.86000000", "0.11119000"], ["111013.97000000", "0.20282000"], ["111045.01000000", "0.22535000"], ["111095.95000000", "0.00000000"]]}}
{"type": "orderbook", "local_time": 1761342392220, "event_time": 1761342389114, "latency_ms": 3106, "data": {"e": "depthUpdate", "E": 1761342389114, "s": "BTCUSDT", "U": 79012697586, "u": 79012697625, "b": [["111005.03000000", "0.16122000"], ["111005.02000000", "0.00100000"], ["111003.86000000", "0.00416000"], ["111003.33000000", "0.25462000"], ["111003.32000000", "0.00010000"], ["111003.31000000", "0.00000000"], ["111003.29000000", "0.00010000"], ["111003.05000000", "0.00005000"], ["110999.49000000", "0.00005000"], ["110998.85000000", "0.00000000"], ["110995.48000000", "0.00000000"]], "a": [["111005.04000000", "5.79239000"], ["111005.80000000", "0.04581000"], ["111006.59000000", "0.00735000"], ["111012.80000000", "0.04000000"], ["111016.92000000", "0.00005000"], ["111035.68000000", "0.00000000"], ["111063.63000000", "0.04420000"], ["111096.02000000", "0.00000000"], ["111096.47000000", "0.00000000"], ["111096.69000000", "0.00000000"], ["111108.74000000", "0.00000000"], ["111112.91000000", "0.00000000"], ["111124.44000000", "0.00000000"]]}}
{"type": "orderbook", "local_time": 1761342392221, "event_time": 1761342389214, "latency_ms": 3007, "data": {"e": "depthUpdate", "E": 1761342389214, "s": "BTCUSDT", "U": 79012697626, "u": 79012697651, "b": [["111005.03000000", "0.16117000"], ["111005.02000000", "0.00095000"], ["111003.86000000", "0.00416000"], ["111003.34000000", "0.20800000"], ["111003.33000000", "0.00010000"], ["111003.32000000", "0.00000000"], ["111003.05000000", "0.00010000"], ["110999.49000000", "0.00000000"], ["110988.08000000", "0.04571000"], ["110694.90000000", "0.02603000"], ["110685.90000000", "0.02598000"], ["110681.73000000", "0.02598000"]], "a": []}}
{"type": "orderbook", "local_time": 1761342392222, "event_time": 1761342389314, "latency_ms": 2908, "data": {"e": "depthUpdate", "E": 1761342389314, "s": "BTCUSDT", "U": 79012697652, "u": 79012697674, "b": [["111005.03000000", "0.16117000"], ["111005.02000000", "0.00095000"], ["111003.86000000", "0.00416000"], ["111003.35000000", "0.00010000"], ["111003.34000000", "0.13201000"], ["111003.33000000", "0.00000000"], ["110714.73000000", "0.02598000"], ["110704.97000000", "0.02598000"], ["99904.00000000", "0.00010000"]], "a": [["111020.81000000", "0.00005000"]]}}
{"type": "orderbook", "local_time": 1761342392223, "event_time": 1761342389414, "latency_ms": 2809, "data": {"e": "depthUpdate", "E": 1761342389414, "s": "BTCUSDT", "U": 79012697675, "u": 79012697677, "b": [], "a": [["111045.76000000", "0.03000000"], ["111049.64000000", "0.03040000"], ["111343.41000000", "0.48717000"]]}}
{"type": "orderbook", "local_time": 1761342392223, "event_time": 1761342389514, "latency_ms": 2709, "data": {"e": "depthUpdate", "E": 1761342389514, "s": "BTCUSDT", "U": 79012697678, "u": 79012697709, "b": [["111005.03000000", "0.06706000"], ["111003.04000000", "0.00005000"], ["111000.20000000", "0.00005000"], ["111000.19000000", "0.02717000"], ["110999.62000000", "0.00000000"], ["110988.08000000", "0.00000000"], ["110980.39000000", "0.00000000"], ["110975.29000000", "0.04000000"], ["110957.15000000", "0.00000000"]], "a": [["111005.04000000", "6.24301000"], ["111006.51000000", "0.04548000"], ["111009.28000000", "0.00005000"], ["111028.03000000", "0.00280000"], ["111030.80000000", "0.00000000"], ["111045.01000000", "0.22535000"], ["111045.87000000", "0.06000000"], ["111050.20000000", "0.03000000"], ["111069.47000000", "0.00000000"], ["111072.79000000", "0.00065000"], ["111096.71000000", "0.00000000"], ["111096.72000000", "0.00000000"], ["111097.15000000", "0.00000000"], ["111123.29000000", "0.03000000"], ["111245.47000000", "0.01410000"]]}}
{"type": "orderbook", "local_time": 1761342392223, "event_time": 1761342389614, "latency_ms": 2609, "data": {"e": "depthUpdate", "E": 1761342389614, "s": "BTCUSDT", "U": 79012697710, "u": 79012697764, "b": [["111005.03000000", "0.06269000"], ["111005.02000000", "0.00100000"], ["111003.34000000", "0.13206000"], ["111003.18000000", "0.29730000"], ["111003.05000000", "0.00000000"], ["111003.04000000", "0.00000000"], ["111002.19000000", "0.00726000"], ["111000.20000000", "0.00010000"], ["111000.01000000", "0.00005000"], ["110996.86000000", "0.04536000"], ["110987.62000000", "0.04571000"], ["110957.52000000", "0.00000000"], ["110951.36000000", "0.34584000"], ["110906.48000000", "0.00000000"], ["110894.25000000", "0.03218000"], ["99904.00000000", "0.00010000"]], "a": [["111005.04000000", "6.24301000"], ["111005.80000000", "0.04581000"], ["111006.50000000", "0.00005000"], ["111006.51000000", "0.04558000"], ["111007.30000000", "0.50010000"], ["111007.31000000", "0.14199000"], ["111009.28000000", "0.00000000"], ["111047.14000000", "0.00000000"], ["111095.66000000", "0.13511000"], ["111095.67000000", "0.00000000"], ["111106.52000000", "0.00000000"], ["111123.29000000", "0.00000000"], ["111343.41000000", "0.00000000"]]}}
{"type": "orderbook", "local_time": 1761342392224, "event_time": 1761342389714, "latency_ms": 2510, "data": {"e": "depthUpdate", "E": 1761342389714, "s": "BTCUSDT", "U": 79012697765, "u": 79012697773, "b": [["111005.03000000", "0.06274000"], ["111005.02000000", "0.00105000"], ["110936.60000000", "0.48600000"], ["110902.13000000", "0.00000000"]], "a": [["111045.01000000", "0.22535000"], ["111046.89000000", "0.03000000"], ["111095.66000000", "0.13511000"]]}}
{"type": "orderbook", "local_time": 1761342392224, "event_time": 1761342389814, "latency_ms": 2410, "data": {"e": "depthUpdate", "E": 1761342389814, "s": "BTCUSDT", "U": 79012697774, "u": 79012697868, "b": [["111002.16000000", "0.00000000"], ["111000.19000000", "0.00014000"], ["110999.70000000", "0.00000000"], ["110999.53000000", "0.05001000"], ["110999.41000000", "0.02703000"], ["110998.84000000", "0.00000000"], ["110996.86000000", "0.00000000"], ["110996.35000000", "0.00000000"], ["110995.17000000", "0.21465000"], ["110994.28000000", "0.04536000"], ["110986.54000000", "0.00000000"], ["110986.03000000", "0.00000000"], ["110985.10000000", "0.01802000"], ["110983.91000000", "0.00000000"], ["110983.08000000", "0.00000000"], ["110979.41000000", "0.00000000"], ["110978.12000000", "0.02000000"], ["110977.18000000", "0.91102000"], ["110975.29000000", "0.00000000"], ["110973.24000000", "0.00000000"], ["110972.99000000", "0.04000000"], ["110971.10000000", "0.00000000"], ["110970.07000000", "0.00000000"], ["110969.65000000", "0.00250000"], ["110964.97000000", "0.00000000"], ["110958.58000000", "0.00000000"], ["110951.71000000", "0.00000000"], ["110951.22000000", "0.00000000"], ["110950.75000000", "0.06613000"], ["110948.19000000", "0.00000000"], ["110947.65000000", "0.00000000"], ["110932.43000000", "0.00628000"], ["110932.35000000", "0.00624000"], ["110927.43000000", "0.00000000"], ["110927.42000000", "0.00000000"], ["110927.18000000", "0.20282000"], ["110920.01000000", "0.03998000"], ["110919.73000000", "0.03998000"], ["110919.23000000", "0.04257000"], ["110917.39000000", "0.00000000"], ["110916.11000000", "0.00000000"], ["110914.65000000", "0.03997000"], ["110913.97000000", "0.00000000"], ["110909.76000000", "0.03997000"], ["110902.65000000", "0.03997000"], ["110890.01000000", "0.07994000"], ["110882.98000000", "0.00000000"], ["110827.40000000", "0.00060000"], ["110763.69000000", "0.00000000"], ["110706.74000000", "0.00005000"], ["110686.24000000", "0.00000000"], ["110662.44000000", "0.02198000"], ["110655.91000000", "0.03698000"], ["110558.59000000", "0.00000000"], ["110557.32000000", "0.00000000"], ["110521.68000000", "0.03698000"], ["110520.87000000", "0.07395000"]], "a": [["111005.04000000", "6.28849000"], ["111005.25000000", "0.00250000"], ["111006.51000000", "0.00010000"], ["111007.29000000", "0.00000000"], ["111011.28000000", "0.06000000"], ["111014.70000000", "0.00000000"], ["111016.72000000", "0.01802000"], ["111019.10000000", "0.00000000"], ["111022.71000000", "0.24000000"], ["111027.50000000", "0.00000000"], ["111032.84000000", "0.00000000"], ["111045.01000000", "0.63106000"], ["111071.10000000", "0.00665000"], ["111084.74000000", "0.00000000"], ["111095.66000000", "0.00000000"], ["111122.74000000", "0.00000000"]]}}
{"type": "orderbook", "local_time": 1761342392225, "event_time": 1761342389914, "latency_ms": 2311, "data": {"e": "depthUpdate", "E": 1761342389914, "s": "BTCUSDT", "U": 79012697869, "u": 79012697947, "b": [["111005.03000000", "0.06274000"], ["111005.02000000", "0.00110000"], ["111003.34000000", "0.00015000"], ["111002.19000000", "0.00726000"], ["111000.20000000", "0.00000000"], ["111000.01000000", "0.00010000"], ["111000.00000000", "0.02845000"], ["110999.54000000", "0.00005000"], ["110999.48000000", "0.09606000"], ["110994.29000000", "0.04209000"], ["110994.28000000", "0.00000000"], ["110993.04000000", "0.04536000"], ["110992.88000000", "0.00000000"], ["110991.90000000", "0.00000000"], ["110982.80000000", "0.20282000"], ["110979.45000000", "0.00000000"], ["110974.10000000", "0.00250000"], ["110971.64000000", "0.00009000"], ["110969.50000000", "0.00009000"], ["110968.46000000", "0.00009000"], ["110963.36000000", "0.00009000"], ["110956.98000000", "0.00009000"], ["110956.63000000", "0.00000000"], ["110939.55000000", "0.00000000"], ["110923.73000000", "0.00660000"], ["110915.79000000", "0.00090000"], ["110895.56000000", "0.02536000"]], "a": [["111005.04000000", "6.28857000"], ["111005.80000000", "0.04581000"], ["111006.50000000", "0.00000000"], ["111006.51000000", "0.00000000"], ["111007.29000000", "0.00010000"], ["111007.30000000", "0.50020000"], ["111010.74000000", "0.01824000"], ["111011.28000000", "0.06005000"], ["111016.12000000", "0.04503000"], ["111019.85000000", "0.00000000"], ["111023.00000000", "0.00011000"], ["111045.01000000", "0.63106000"], ["111048.12000000", "0.03000000"], ["111069.65000000", "0.00000000"], ["111070.16000000", "0.13524000"], ["111077.75000000", "0.00000000"], ["111095.08000000", "0.00000000"], ["111096.43000000", "0.00000000"], ["111097.38000000", "0.03400000"], ["111097.44000000", "0.00005000"], ["111106.18000000", "0.00000000"], ["111106.58000000", "0.00000000"], ["111108.74000000", "0.03000000"], ["111116.28000000", "0.00053000"], ["111130.53000000", "0.00179000"], ["111133.94000000", "0.00000000"], ["111141.63000000", "0.00359000"], ["111169.40000000", "0.00899000"]]}}
{"type": "orderbook", "local_time": 1761342392225, "event_time": 1761342390014, "latency_ms": 2211, "data": {"e": "depthUpdate", "E": 1761342390014, "s": "BTCUSDT", "U": 79012697948, "u": 79012698153, "b": [["111005.03000000", "0.00000000"], ["111005.02000000", "0.00220000"], ["111005.01000000", "0.00090000"], ["111003.86000000", "0.00416000"], ["111003.35000000", "0.00000000"], ["111003.34000000", "0.00000000"], ["111003.28000000", "0.03100000"], ["111003.18000000", "0.00020000"], ["111002.19000000", "0.00731000"], ["111000.00000000", "0.02850000"], ["110999.58000000", "0.29725000"], ["110999.54000000", "0.00010000"], ["110999.53000000", "0.00010000"], ["110999.49000000", "0.00005000"], ["110999.48000000", "0.09616000"], ["110999.41000000", "0.00005000"], ["110999.36000000", "0.02703000"], ["110999.23000000", "0.04972000"], ["110996.58000000", "0.01843000"], ["110996.40000000", "0.04551000"], ["110995.74000000", "0.00720000"], ["110995.17000000", "0.20745000"], ["110993.04000000", "0.00000000"], ["110987.62000000", "0.00000000"], ["110985.10000000", "0.00000000"], ["110985.09000000", "0.00000000"], ["110982.80000000", "0.00000000"], ["110981.31000000", "0.00000000"], ["110980.12000000", "0.00000000"], ["110978.01000000", "0.04000000"], ["110977.31000000", "0.00000000"], ["110976.74000000", "0.00900000"], ["110976.42000000", "0.08000000"], ["110975.72000000", "0.16000000"], ["110960.27000000", "0.00000000"], ["110954.43000000", "0.00000000"], ["110951.36000000", "0.00000000"], ["110950.75000000", "0.00000000"], ["110950.65000000", "0.00000000"], ["110947.67000000", "0.00000000"], ["110938.52000000", "0.31079000"], ["110931.71000000", "0.28437000"], ["110926.83000000", "0.00000000"], ["110920.01000000", "0.00000000"], ["110919.73000000", "0.00000000"], ["110917.43000000", "0.00000000"], ["110916.21000000", "0.13511000"], ["110912.91000000", "0.00000000"], ["110888.95000000", "0.03997000"], ["99904.00000000", "0.00010000"]], "a": [["111005.03000000", "4.31013000"], ["111005.04000000", "1.80083000"], ["111005.05000000", "0.27001000"], ["111005.79000000", "0.00000000"], ["111006.59000000", "0.00005000"], ["111006.60000000", "0.00010000"], ["111007.29000000", "0.00000000"], ["111007.30000000", "0.20287000"], ["111009.79000000", "0.00000000"], ["111011.28000000", "0.06000000"], ["111012.00000000", "0.00010000"], ["111016.12000000", "0.00000000"], ["111016.16000000", "0.00000000"], ["111019.01000000", "0.00000000"], ["111045.01000000", "0.00000000"], ["111045.84000000", "0.00000000"], ["111047.44000000", "0.00000000"], ["111070.16000000", "0.00000000"], ["111071.50000000", "0.00000000"], ["111080.92000000", "0.00000000"]]}}
{"type": "orderbook", "local_time": 1761342392226, "event_time": 1761342390114, "latency_ms": 2112, "data": {"e": "depthUpdate", "E": 1761342390114, "s": "BTCUSDT", "U": 79012698154, "u": 79012698490, "b": [["111005.02000000", "0.00000000"], ["111005.01000000", "0.00115000"], ["111003.28000000", "0.03095000"], ["111003.19000000", "0.00000000"], ["111003.18000000", "0.00000000"], ["111002.20000000", "0.00010000"], ["111002.19000000", "0.00736000"], ["111001.94000000", "0.00155000"], ["111000.00000000", "0.02850000"], ["110999.59000000", "0.00010000"], ["110999.58000000", "0.00010000"], ["110999.54000000", "0.00000000"], ["110999.53000000", "0.00000000"], ["110999.49000000", "0.00005000"], ["110999.48000000", "0.00010000"], ["110999.41000000", "0.00000000"], ["110999.36000000", "0.00010000"], ["110999.23000000", "0.00005000"], ["110999.10000000", "0.00000000"], ["110999.01000000", "0.00416000"], ["110996.58000000", "0.00005000"], ["110996.40000000", "0.04551000"], ["110996.29000000", "0.00000000"], ["110996.21000000", "0.00000000"], ["110995.87000000", "0.04964000"], ["110995.77000000", "0.29727000"], ["110995.74000000", "0.00005000"], ["110995.17000000", "0.00000000"], ["110994.29000000", "0.02781000"], ["110993.06000000", "0.00000000"], ["110990.97000000", "0.00000000"], ["110990.20000000", "0.00000000"], ["110989.16000000", "0.04536000"], ["110988.16000000", "0.00000000"], ["110986.96000000", "0.00000000"], ["110986.47000000", "0.21465000"], ["110985.33000000", "0.00000000"], ["110984.19000000", "0.00000000"], ["110981.32000000", "0.30399000"], ["110981.14000000", "0.00000000"], ["110980.74000000", "0.00000000"], ["110979.50000000", "0.00000000"], ["110978.12000000", "0.00000000"], ["110978.01000000", "0.00000000"], ["110977.62000000", "0.00000000"], ["110977.27000000", "0.11267000"], ["110976.66000000", "0.00000000"], ["110976.42000000", "0.14000000"], ["110975.72000000", "0.00000000"], ["110972.99000000", "0.00000000"], ["110972.17000000", "0.00000000"], ["110971.92000000", "0.16000000"], ["110971.64000000", "0.00000000"], ["110969.99000000", "0.04000000"], ["110969.50000000", "0.00000000"], ["110969.03000000", "0.13524000"], ["110968.46000000", "0.00000000"], ["110965.29000000", "0.00000000"], ["110963.36000000", "0.00000000"], ["110956.98000000", "0.00000000"], ["110955.39000000", "0.07656000"], ["110950.75000000", "0.02432000"], ["110950.35000000", "0.00000000"], ["110949.75000000", "0.00000000"], ["110949.71000000", "0.00000000"], ["110947.49000000", "0.34584000"], ["110946.54000000", "0.32443000"], ["110936.44000000", "0.00000000"], ["110935.15000000", "0.00000000"], ["110925.54000000", "0.00000000"], ["110918.60000000", "0.07661000"], ["110915.79000000", "0.00000000"], ["110915.74000000", "0.13524000"], ["110902.01000000", "0.03997000"], ["110900.33000000", "0.00000000"], ["110895.56000000", "0.00000000"], ["110888.76000000", "0.04052000"], ["110866.01000000", "0.02612000"], ["110860.02000000", "0.00000000"], ["110858.37000000", "0.00224000"], ["110806.43000000", "0.00000000"], ["110805.96000000", "0.00000000"], ["110782.59000000", "0.01891000"], ["110777.82000000", "0.01891000"], ["110748.39000000", "0.00000000"], ["110746.01000000", "0.00090000"], ["110686.88000000", "0.00000000"], ["110684.76000000", "0.00000000"], ["110675.64000000", "0.00000000"], ["110656.70000000", "0.02432000"], ["110655.99000000", "0.02432000"], ["110647.20000000", "0.01711000"], ["110628.92000000", "0.00000000"], ["110626.69000000", "0.00000000"], ["110625.51000000", "0.00000000"], ["110621.48000000", "0.00000000"], ["110607.97000000", "0.02432000"], ["110604.85000000", "0.02432000"], ["110603.83000000", "0.00000000"], ["110603.73000000", "0.02432000"], ["110602.05000000", "0.02432000"], ["110600.61000000", "0.04864000"], ["110597.61000000", "0.02432000"], ["110593.50000000", "0.00000000"], ["110589.48000000", "0.00000000"], ["110554.65000000", "0.00000000"], ["110554.23000000", "0.00000000"], ["110551.84000000", "0.00000000"], ["110544.52000000", "0.00000000"], ["110540.11000000", "0.00000000"], ["110536.21000000", "0.03698000"], ["110534.22000000", "0.03698000"], ["110533.07000000", "0.00000000"], ["110532.76000000", "0.03698000"], ["110531.45000000", "0.03698000"], ["110530.76000000", "0.00000000"], ["110530.50000000", "0.00000000"], ["110529.89000000", "0.03698000"], ["110528.34000000", "0.03698000"], ["110527.07000000", "0.00000000"], ["110527.03000000", "0.03698000"], ["110526.65000000", "0.00000000"], ["110526.37000000", "0.00000000"], ["110525.78000000", "0.03703000"], ["110523.52000000", "0.03698000"], ["110522.41000000", "0.03698000"], ["110521.68000000", "0.00000000"], ["110521.60000000", "0.03698000"], ["110521.55000000", "0.03698000"], ["110520.65000000", "0.03698000"], ["110520.64000000", "0.03698000"], ["110520.34000000", "0.03698000"], ["110520.10000000", "0.00000000"], ["110519.14000000", "0.00000000"], ["110518.58000000", "0.00000000"]], "a": [["111005.02000000", "3.79865000"], ["111005.03000000", "3.52325000"], ["111005.04000000", "0.33724000"], ["111005.80000000", "0.04581000"], ["111006.59000000", "0.00000000"], ["111006.60000000", "0.00000000"], ["111007.30000000", "0.20287000"], ["111008.29000000", "0.01802000"], ["111011.28000000", "0.06005000"], ["111012.77000000", "0.00000000"], ["111012.80000000", "0.00005000"], ["111012.86000000", "0.07214000"], ["111013.04000000", "0.00005000"], ["111015.30000000", "0.00005000"], ["111016.72000000", "0.00000000"], ["111024.19000000", "0.00000000"], ["111036.15000000", "0.04008000"], ["111045.83000000", "0.00000000"], ["111051.78000000", "0.07661000"], ["111053.95000000", "0.00005000"], ["111065.22000000", "0.00633000"], ["111066.93000000", "0.03326000"], ["111073.29000000", "0.00000000"], ["111079.09000000", "0.00000000"], ["111081.30000000", "0.00072000"], ["111081.60000000", "0.00000000"], ["111084.60000000", "0.00000000"], ["111108.05000000", "0.00000000"], ["111108.74000000", "0.00000000"], ["111119.93000000", "0.00000000"], ["111290.95000000", "0.02432000"], ["111396.43000000", "0.00000000"]]}}
{"type": "orderbook", "local_time": 1761342392226, "event_time": 1761342390214, "latency_ms": 2012, "data": {"e": "depthUpdate", "E": 1761342390214, "s": "BTCUSDT", "U": 79012698491, "u": 79012698842, "b": [["111005.01000000", "0.00000000"], ["111005.00000000", "0.00000000"], ["111003.86000000", "0.00364000"], ["111003.85000000", "0.00090000"], ["111003.28000000", "0.00030000"], ["111002.19000000", "0.00746000"], ["111001.94000000", "0.00010000"], ["111000.19000000", "0.00000000"], ["111000.00000000", "0.02855000"], ["110999.59000000", "0.00000000"], ["110999.58000000", "0.00000000"], ["110999.49000000", "0.00000000"], ["110999.48000000", "0.00000000"], ["110999.36000000", "0.00000000"], ["110999.23000000", "0.00000000"], ["110999.01000000", "0.00000000"], ["110999.00000000", "0.00000000"], ["110998.94000000", "0.00416000"], ["110998.47000000", "0.29726000"], ["110997.40000000", "0.03211000"], ["110996.65000000", "0.00000000"], ["110996.59000000", "0.00012000"], ["110996.58000000", "0.00000000"], ["110996.41000000", "0.00010000"], ["110996.40000000", "0.04551000"], ["110995.88000000", "0.11984000"], ["110995.87000000", "0.04969000"], ["110995.77000000", "0.00005000"], ["110995.74000000", "0.00000000"], ["110994.87000000", "0.05428000"], ["110994.29000000", "0.02786000"], ["110992.87000000", "0.07702000"], ["110992.29000000", "0.01785000"], ["110989.64000000", "0.00995000"], ["110987.21000000", "0.00150000"], ["110986.77000000", "0.09088000"], ["110983.25000000", "0.04571000"], ["110973.93000000", "0.00000000"], ["110973.37000000", "0.00000000"], ["110969.94000000", "0.00009000"], ["110967.80000000", "0.00009000"], ["110966.76000000", "0.00009000"], ["110961.66000000", "0.00009000"], ["110956.18000000", "0.00268000"], ["110955.40000000", "0.00012000"], ["110955.28000000", "0.00009000"], ["110954.42000000", "0.00445000"], ["110949.52000000", "0.00000000"], ["110920.38000000", "0.00622000"], ["110914.24000000", "0.00000000"], ["110914.09000000", "0.00090000"], ["110911.68000000", "0.13588000"], ["110880.00000000", "0.02073000"], ["110876.16000000", "0.04632000"]], "a": [["111003.87000000", "5.28009000"], ["111003.93000000", "0.00000000"], ["111004.44000000", "0.00513000"], ["111004.65000000", "0.00032000"], ["111005.01000000", "3.00021000"], ["111005.02000000", "1.20489000"], ["111005.03000000", "0.29551000"], ["111005.04000000", "0.11277000"], ["111005.80000000", "0.04576000"], ["111005.83000000", "0.00000000"], ["111007.31000000", "0.14199000"], ["111008.29000000", "0.00005000"], ["111010.74000000", "0.01819000"], ["111011.28000000", "0.06000000"], ["111012.80000000", "0.00000000"], ["111015.94000000", "0.00000000"], ["111045.82000000", "0.00000000"], ["111049.95000000", "0.25775000"], ["111067.45000000", "0.00626000"], ["111068.28000000", "0.13511000"], ["111087.30000000", "0.04053000"], ["111088.51000000", "0.00112000"], ["111088.75000000", "0.02459000"], ["111107.06000000", "0.00000000"], ["111108.55000000", "0.00000000"]]}}
{"type": "orderbook", "local_time": 1761342392226, "event_time": 1761342390314, "latency_ms": 1912, "data": {"e": "depthUpdate", "E": 1761342390314, "s": "BTCUSDT", "U": 79012698843, "u": 79012699201, "b": [["111003.86000000", "0.00000000"], ["111003.85000000", "0.00000000"], ["111003.29000000", "0.00000000"], ["111003.28000000", "0.00000000"], ["111002.88000000", "0.00000000"], ["111002.20000000", "0.00000000"], ["111002.19000000", "0.00000000"], ["111002.10000000", "0.00000000"], ["111001.94000000", "0.00000000"], ["111000.75000000", "0.00000000"], ["111000.01000000", "0.00000000"], ["111000.00000000", "0.00000000"], ["110999.47000000", "0.00000000"], ["110998.94000000", "0.00000000"], ["110998.80000000", "0.00000000"], ["110998.79000000", "0.00000000"], ["110998.48000000", "0.00000000"], ["110998.47000000", "0.39834000"], ["110998.46000000", "0.00090000"], ["110997.41000000", "0.00010000"], ["110997.40000000", "0.03236000"], ["110996.64000000", "0.00000000"], ["110996.59000000", "0.00000000"], ["110996.41000000", "0.08054000"], ["110996.40000000", "0.04551000"], ["110995.89000000", "0.00010000"], ["110995.88000000", "0.00015000"], ["110995.87000000", "0.04969000"], ["110995.77000000", "0.00000000"], ["110994.88000000", "0.00005000"], ["110994.29000000", "0.04320000"], ["110993.60000000", "0.00000000"], ["110992.87000000", "0.00005000"], ["110992.80000000", "0.00000000"], ["110992.29000000", "0.01790000"], ["110991.20000000", "0.00012000"], ["110990.66000000", "0.00000000"], ["110990.28000000", "0.21105000"], ["110989.64000000", "0.00005000"], ["110986.47000000", "0.00000000"], ["110984.04000000", "0.08374000"], ["110983.36000000", "0.00000000"], ["110981.82000000", "0.00150000"], ["110980.13000000", "0.00000000"], ["110980.00000000", "0.01944000"], ["110978.56000000", "0.00450000"], ["110977.83000000", "0.00000000"], ["110977.80000000", "0.00990000"], ["110974.18000000", "0.20445000"], ["110973.51000000", "0.00005000"], ["110955.34000000", "0.00037000"], ["110954.79000000", "0.00034000"], ["110950.15000000", "0.00034000"], ["110949.00000000", "0.00035000"], ["110948.53000000", "0.00090000"], ["110948.52000000", "0.06869000"], ["110948.08000000", "0.00005000"], ["110942.70000000", "0.00005000"], ["110933.32000000", "0.00500000"], ["110911.68000000", "0.00000000"], ["110903.18000000", "0.00000000"], ["110900.21000000", "0.00060000"], ["110884.90000000", "0.00005000"], ["110878.02000000", "0.00000000"], ["110871.88000000", "0.07853000"], ["110870.88000000", "0.00191000"], ["110840.48000000", "0.00157000"], ["110771.86000000", "0.00000000"], ["110743.18000000", "1.01127000"], ["110447.76000000", "0.00005000"]], "a": [["110998.48000000", "5.74603000"], ["110998.49000000", "0.00000000"], ["110998.54000000", "0.00000000"], ["110998.80000000", "0.00000000"], ["110998.95000000", "0.00000000"], ["110999.02000000", "0.00000000"], ["110999.13000000", "0.00720000"], ["110999.14000000", "0.20745000"], ["110999.48000000", "0.00000000"], ["110999.78000000", "0.04548000"], ["110999.86000000", "0.04571000"], ["111000.00000000", "0.00005000"], ["111000.01000000", "0.00000000"], ["111000.80000000", "0.00250000"], ["111001.95000000", "0.00000000"], ["111002.20000000", "0.00000000"], ["111002.21000000", "0.00000000"], ["111002.88000000", "0.00005000"], ["111003.29000000", "0.00000000"], ["111003.86000000", "2.91440000"], ["111003.87000000", "1.27260000"], ["111004.44000000", "0.00518000"], ["111004.65000000", "0.00000000"], ["111005.00000000", "0.00010000"], ["111005.01000000", "0.00005000"], ["111005.02000000", "0.13516000"], ["111005.03000000", "0.08086000"], ["111005.04000000", "0.11272000"], ["111005.05000000", "0.26996000"], ["111005.80000000", "0.00005000"], ["111007.29000000", "0.12930000"], ["111007.31000000", "0.00390000"], ["111008.29000000", "0.00000000"], ["111009.58000000", "0.00034000"], ["111010.67000000", "0.00000000"], ["111012.91000000", "0.11041000"], ["111013.30000000", "0.00000000"], ["111014.87000000", "0.00044000"], ["111015.12000000", "0.00090000"], ["111016.00000000", "0.00007000"], ["111019.15000000", "0.01036000"], ["111021.74000000", "0.00000000"], ["111023.05000000", "0.00000000"], ["111023.70000000", "0.00000000"], ["111024.40000000", "0.00000000"], ["111027.75000000", "0.00012000"], ["111028.03000000", "0.00027000"], ["111038.96000000", "0.44600000"], ["111039.98000000", "0.00016000"], ["111043.18000000", "0.00000000"], ["111044.67000000", "0.00000000"], ["111045.68000000", "0.00000000"], ["111048.22000000", "0.00000000"], ["111050.88000000", "0.00016000"], ["111052.15000000", "0.00000000"], ["111055.68000000", "0.20726000"], ["111057.68000000", "0.00000000"], ["111059.82000000", "0.00000000"], ["111062.96000000", "0.13524000"], ["111065.95000000", "0.13526000"], ["111066.87000000", "0.00000000"], ["111089.87000000", "0.18027000"], ["111090.25000000", "0.13511000"], ["111106.65000000", "0.50650000"], ["111132.00000000", "0.08773000"], ["111162.74000000", "0.00000000"]]}}
{"type": "orderbook", "local_time": 1761342392227, "event_time": 1761342390414, "latency_ms": 1813, "data": {"e": "depthUpdate", "E": 1761342390414, "s": "BTCUSDT", "U": 79012699202, "u": 79012699319, "b": [["110998.47000000", "0.39955000"], ["110998.46000000", "0.00110000"], ["110997.40000000", "0.03236000"], ["110996.42000000", "0.00010000"], ["110996.41000000", "0.04499000"], ["110996.40000000", "0.04556000"], ["110995.89000000", "0.00000000"], ["110995.88000000", "0.70150000"], ["110995.87000000", "0.00005000"], ["110994.29000000", "0.07710000"], ["110992.87000000", "0.00000000"], ["110992.29000000", "0.00005000"], ["110990.28000000", "0.21110000"], ["110989.64000000", "0.00000000"], ["110989.46000000", "0.01814000"], ["110989.16000000", "0.04541000"], ["110986.77000000", "0.05046000"], ["110887.69000000", "0.02536000"], ["99898.00000000", "0.03577000"]], "a": [["110998.48000000", "5.82035000"], ["110999.12000000", "0.00010000"], ["110999.13000000", "0.00735000"], ["110999.14000000", "0.20750000"], ["110999.16000000", "0.01830000"], ["110999.77000000", "0.00010000"], ["110999.78000000", "0.04553000"], ["110999.85000000", "0.00010000"], ["110999.86000000", "0.04576000"], ["111001.15000000", "0.29725000"], ["111003.85000000", "1.37309000"], ["111003.86000000", "0.00010000"], ["111003.87000000", "1.23947000"], ["111004.44000000", "0.00513000"], ["111005.00000000", "0.00000000"], ["111005.01000000", "0.00000000"], ["111005.03000000", "0.00081000"], ["111005.04000000", "0.11267000"], ["111005.05000000", "0.26991000"], ["111005.80000000", "0.00000000"], ["111007.29000000", "0.06801000"], ["111007.30000000", "0.20282000"], ["111010.74000000", "0.00000000"], ["111036.53000000", "0.32417000"], ["111060.02000000", "0.00000000"], ["111062.96000000", "0.00000000"], ["111089.50000000", "0.18027000"], ["111089.86000000", "0.21214000"], ["111089.87000000", "0.00000000"], ["111090.22000000", "0.00000000"]]}}
{"type": "orderbook", "local_time": 1761342392227, "event_time": 1761342390515, "latency_ms": 1712, "data": {"e": "depthUpdate", "E": 1761342390515, "s": "BTCUSDT", "U": 79012699320, "u": 79012699400, "b": [["110998.47000000", "0.39960000"], ["110998.46000000", "0.00110000"], ["110996.41000000", "0.23379000"], ["110996.40000000", "0.04556000"], ["110995.89000000", "0.00010000"], ["110995.88000000", "0.00005000"], ["110995.87000000", "0.00000000"], ["110994.29000000", "0.07710000"], ["110992.29000000", "0.00000000"], ["110990.28000000", "0.21110000"], ["110979.99000000", "0.00000000"], ["110965.17000000", "0.00009000"], ["110946.68000000", "0.00000000"], ["110931.87000000", "0.00009000"], ["110913.38000000", "0.00000000"], ["110898.57000000", "0.00009000"], ["110880.07000000", "0.00000000"], ["110865.27000000", "0.00009000"], ["110846.77000000", "0.00000000"], ["110831.97000000", "0.00009000"], ["99904.00000000", "0.00000000"], ["99898.00000000", "0.03587000"], ["33000.00000000", "3.79505000"]], "a": [["110998.48000000", "5.78025000"], ["110999.14000000", "0.20750000"], ["110999.15000000", "0.00005000"], ["110999.16000000", "0.00005000"], ["110999.86000000", "0.04576000"], ["111000.89000000", "0.04000000"], ["111001.15000000", "0.29730000"], ["111003.85000000", "0.30358000"], ["111003.86000000", "0.00000000"], ["111003.87000000", "0.78868000"], ["111004.44000000", "0.00518000"], ["111005.02000000", "0.13511000"], ["111005.03000000", "0.00076000"], ["111011.36000000", "0.00324000"], ["111023.45000000", "0.03005000"], ["111031.78000000", "0.00009000"], ["111038.44000000", "0.00000000"], ["111043.58000000", "0.00000000"], ["111046.60000000", "0.00000000"], ["111065.08000000", "0.00009000"], ["111065.24000000", "0.13524000"], ["111079.91000000", "0.00000000"], ["111089.37000000", "0.45079000"], ["111089.86000000", "0.00000000"], ["111098.38000000", "0.00009000"], ["111113.21000000", "0.00000000"], ["111131.68000000", "0.00008000"], ["111146.52000000", "0.00000000"], ["111164.98000000", "0.00008000"], ["111179.82000000", "0.00000000"]]}}
{"type": "orderbook", "local_time": 1761342392228, "event_time": 1761342390614, "latency_ms": 1614, "data": {"e": "depthUpdate", "E": 1761342390614, "s": "BTCUSDT", "U": 79012699401, "u": 79012699451, "b": [["110998.47000000", "0.39974000"], ["110998.46000000", "0.00598000"], ["110996.41000000", "0.03013000"], ["110996.40000000", "0.04556000"], ["110995.89000000", "0.00000000"], ["110995.88000000", "0.00000000"], ["110995.00000000", "0.02704000"], ["110994.88000000", "0.00010000"], ["110994.30000000", "0.00005000"], ["110993.83000000", "0.05063000"], ["110989.46000000", "0.01819000"], ["99898.00000000", "0.03597000"], ["33000.00000000", "3.79445000"]], "a": [["110998.48000000", "5.29521000"], ["110998.76000000", "0.00000000"], ["110999.14000000", "0.20750000"], ["110999.15000000", "0.00000000"], ["110999.16000000", "0.00000000"], ["110999.77000000", "0.48326000"], ["110999.86000000", "0.04576000"], ["111000.88000000", "0.00005000"], ["111000.89000000", "0.04005000"], ["111002.69000000", "0.00000000"], ["111003.85000000", "0.00005000"], ["111003.87000000", "0.65349000"], ["111005.02000000", "0.00000000"], ["111005.04000000", "0.00000000"], ["111009.58000000", "0.11301000"], ["111017.73000000", "0.13519000"], ["111020.24000000", "0.13511000"], ["111026.55000000", "0.22535000"], ["111038.44000000", "0.00000000"], ["111068.28000000", "0.00000000"], ["111073.52000000", "0.13511000"], ["111089.37000000", "0.22544000"], ["111089.70000000", "0.22535000"]]}}
