{"type": "orderbook", "local_time": 1761342328186, "event_time": 1761342328214, "latency_ms": -28, "data": {"e": "depthUpdate", "E": 1761342328214, "s": "BTCUSDT", "U": 79012683689, "u": 79012683697, "b": [["111026.06000000", "0.00025000"], ["111025.25000000", "0.18019000"], ["99924.00000000", "0.00010000"]], "a": [["111038.96000000", "0.00000000"], ["111038.99000000", "0.01801000"], ["111118.45000000", "0.00000000"], ["111118.46000000", "0.03400000"], ["123364.63000000", "0.00000000"], ["124131.07000000", "0.00000000"]]}}
{"type": "orderbook", "local_time": 1761342328243, "event_time": 1761342328314, "latency_ms": -71, "data": {"e": "depthUpdate", "E": 1761342328314, "s": "BTCUSDT", "U": 79012683698, "u": 79012683718, "b": [["111026.11000000", "0.00119000"], ["111026.07000000", "0.00000000"], ["111026.06000000", "0.00010000"], ["111026.05000000", "0.13208000"], ["111026.04000000", "0.29728000"], ["111025.26000000", "0.00010000"], ["111025.25000000", "0.18024000"]], "a": [["111027.23000000", "0.81710000"], ["111038.99000000", "0.00000000"], ["111039.02000000", "0.01801000"], ["111078.24000000", "0.19280000"], ["125626.32000000", "0.00000000"]]}}
{"type": "orderbook", "local_time": 1761342328340, "event_time": 1761342328414, "latency_ms": -74, "data": {"e": "depthUpdate", "E": 1761342328414, "s": "BTCUSDT", "U": 79012683719, "u": 79012683723, "b": [["106837.16000000", "0.00000000"]], "a": [["111039.02000000", "0.00000000"], ["111039.04000000", "0.04801000"], ["111207.74000000", "0.00500000"], ["112683.23000000", "0.00000000"]]}}
{"type": "orderbook", "local_time": 1761342328435, "event_time": 1761342328514, "latency_ms": -79, "data": {"e": "depthUpdate", "E": 1761342328514, "s": "BTCUSDT", "U": 79012683724, "u": 79012683728, "b": [["109982.47000000", "0.00000000"], ["108937.19000000", "0.00000000"]], "a": [["111027.23000000", "0.81720000"], ["111122.12000000", "0.00100000"], ["111122.13000000", "0.00100000"]]}}
{"type": "orderbook", "local_time": 1761342328538, "event_time": 1761342328615, "latency_ms": -77, "data": {"e": "depthUpdate", "E": 1761342328615, "s": "BTCUSDT", "U": 79012683729, "u": 79012683735, "b": [["110938.00000000", "0.00160000"], ["110936.00000000", "0.00160000"], ["110934.00000000", "0.00160000"], ["110932.00000000", "0.00160000"]], "a": [["111074.98000000", "0.06652000"], ["111396.55000000", "0.00000000"], ["111683.37000000", "0.00000000"]]}}
{"type": "orderbook", "local_time": 1761342328635, "event_time": 1761342328714, "latency_ms": -79, "data": {"e": "depthUpdate", "E": 1761342328714, "s": "BTCUSDT", "U": 79012683736, "u": 79012683736, "b": [], "a": [["111140.00000000", "0.01956000"]]}}
{"type": "orderbook", "local_time": 1761342328736, "event_time": 1761342328814, "latency_ms": -78, "data": {"e": "depthUpdate", "E": 1761342328814, "s": "BTCUSDT", "U": 79012683737, "u": 79012683746, "b": [["110957.10000000", "0.03218000"], ["110926.14000000", "0.00000000"], ["42000.00000000", "1.36834000"]], "a": [["111039.04000000", "0.03000000"], ["111039.08000000", "0.00000000"], ["111039.09000000", "0.01801000"], ["111041.83000000", "0.00044000"], ["111368.93000000", "0.48717000"]]}}
{"type": "orderbook", "local_time": 1761342328838, "event_time": 1761342328914, "latency_ms": -76, "data": {"e": "depthUpdate", "E": 1761342328914, "s": "BTCUSDT", "U": 79012683747, "u": 79012683750, "b": [["110997.88000000", "0.00000000"]], "a": [["111035.90000000", "0.00044000"], ["111051.35000000", "0.00044000"], ["111061.30000000", "0.00000000"]]}}
{"type": "orderbook", "local_time": 1761342328951, "event_time": 1761342329014, "latency_ms": -63, "data": {"e": "depthUpdate", "E": 1761342329014, "s": "BTCUSDT", "U": 79012683751, "u": 79012683761, "b": [["111027.22000000", "5.03534000"], ["111020.22000000", "0.05054000"], ["99924.00000000", "0.00010000"], ["88822.00000000", "0.00337000"]], "a": [["111028.64000000", "0.05099000"], ["111032.86000000", "0.01827000"], ["111039.09000000", "0.00000000"], ["111039.10000000", "0.01801000"], ["111056.54000000", "0.00000000"]]}}
{"type": "orderbook", "local_time": 1761342329036, "event_time": 1761342329114, "latency_ms": -78, "data": {"e": "depthUpdate", "E": 1761342329114, "s": "BTCUSDT", "U": 79012683762, "u": 79012683786, "b": [["111020.56000000", "0.00545000"], ["110997.84000000", "0.84681000"], ["110939.40000000", "0.00005000"], ["99924.00000000", "0.00010000"]], "a": [["111027.23000000", "0.81730000"], ["111027.24000000", "0.00100000"], ["111028.63000000", "0.00005000"], ["111028.64000000", "0.05109000"], ["111031.25000000", "0.20287000"], ["111032.79000000", "0.11272000"], ["111032.86000000", "0.01832000"], ["111033.16000000", "0.04572000"], ["111033.39000000", "0.13524000"], ["111058.54000000", "0.93355000"], ["111081.30000000", "0.00077000"]]}}
{"type": "orderbook", "local_time": 1761342329137, "event_time": 1761342329214, "latency_ms": -77, "data": {"e": "depthUpdate", "E": 1761342329214, "s": "BTCUSDT", "U": 79012683787, "u": 79012683789, "b": [], "a": [["111039.10000000", "0.00000000"], ["111039.11000000", "0.01801000"], ["111122.12000000", "0.00000000"]]}}
{"type": "orderbook", "local_time": 1761342329235, "event_time": 1761342329314, "latency_ms": -79, "data": {"e": "depthUpdate", "E": 1761342329314, "s": "BTCUSDT", "U": 79012683790, "u": 79012683792, "b": [], "a": [["111039.11000000", "0.00000000"], ["111039.28000000", "0.01871000"], ["124131.55000000", "0.00060000"]]}}
{"type": "orderbook", "local_time": 1761342329336, "event_time": 1761342329414, "latency_ms": -78, "data": {"e": "depthUpdate", "E": 1761342329414, "s": "BTCUSDT", "U": 79012683793, "u": 79012683793, "b": [], "a": [["123363.85000000", "0.00060000"]]}}
{"type": "orderbook", "local_time": 1761342329438, "event_time": 1761342329514, "latency_ms": -76, "data": {"e": "depthUpdate", "E": 1761342329514, "s": "BTCUSDT", "U": 79012683794, "u": 79012683805, "b": [["111027.22000000", "5.03436000"], ["111010.98000000", "0.20282000"], ["110923.57000000", "0.00000000"], ["99924.00000000", "0.00010000"]], "a": [["111028.64000000", "0.00010000"], ["111030.46000000", "0.00010000"], ["111032.86000000", "0.00005000"], ["111041.03000000", "0.13519000"], ["111044.13000000", "0.04912000"], ["125626.78000000", "0.00059000"]]}}
{"type": "orderbook", "local_time": 1761342329537, "event_time": 1761342329614, "latency_ms": -77, "data": {"e": "depthUpdate", "E": 1761342329614, "s": "BTCUSDT", "U": 79012683806, "u": 79012683853, "b": [["111027.22000000", "5.03357000"], ["111027.09000000", "0.00618000"], ["110788.47000000", "0.00000000"]], "a": [["111027.23000000", "0.81720000"], ["111027.24000000", "0.00090000"], ["111028.63000000", "0.00000000"], ["111028.64000000", "0.00000000"], ["111029.78000000", "0.44486000"], ["111029.79000000", "0.29727000"], ["111030.45000000", "0.00000000"], ["111030.46000000", "0.00000000"], ["111031.25000000", "0.20302000"], ["111031.26000000", "0.81640000"], ["111032.78000000", "0.00000000"], ["111032.79000000", "0.00005000"], ["111032.86000000", "0.00000000"], ["111033.16000000", "0.04577000"], ["111033.38000000", "0.00005000"], ["111033.39000000", "0.13529000"], ["111033.89000000", "0.00545000"], ["111038.34000000", "0.11267000"], ["111100.15000000", "0.18647000"], ["111122.00000000", "0.00913000"], ["111122.01000000", "0.02500000"], ["111270.13000000", "0.00000000"], ["112694.36000000", "0.00066000"]]}}
{"type": "orderbook", "local_time": 1761342329637, "event_time": 1761342329714, "latency_ms": -77, "data": {"e": "depthUpdate", "E": 1761342329714, "s": "BTCUSDT", "U": 79012683854, "u": 79012683884, "b": [["111027.22000000", "5.03437000"], ["111027.10000000", "0.00005000"], ["111022.08000000", "0.00000000"], ["106832.25000000", "0.00070000"]], "a": [["111027.23000000", "0.81720000"], ["111027.24000000", "0.00090000"], ["111029.70000000", "0.04730000"], ["111029.77000000", "0.00010000"], ["111029.78000000", "0.44496000"], ["111031.26000000", "0.81635000"], ["111032.79000000", "0.00000000"], ["111033.38000000", "0.00000000"], ["111041.09000000", "0.04912000"], ["111044.13000000", "0.00000000"], ["111061.29000000", "1.01535000"], ["111122.04000000", "0.00000000"], ["111124.76000000", "0.00000000"]]}}
{"type": "orderbook", "local_time": 1761342329739, "event_time": 1761342329814, "latency_ms": -75, "data": {"e": "depthUpdate", "E": 1761342329814, "s": "BTCUSDT", "U": 79012683885, "u": 79012683892, "b": [["111027.22000000", "5.00571000"], ["108934.06000000", "0.00068000"]], "a": [["111039.28000000", "0.00070000"], ["111039.30000000", "0.01801000"], ["111061.23000000", "0.00000000"], ["111072.33000000", "0.00000000"], ["111077.75000000", "0.00054000"], ["111083.43000000", "0.00000000"], ["111095.08000000", "0.00180000"], ["111106.18000000", "0.00360000"], ["111111.19000000", "0.00000000"], ["111133.94000000", "0.00899000"]]}}
{"type": "orderbook", "local_time": 1761342329837, "event_time": 1761342329914, "latency_ms": -77, "data": {"e": "depthUpdate", "E": 1761342329914, "s": "BTCUSDT", "U": 79012683893, "u": 79012683896, "b": [["110788.41000000", "0.84841000"]], "a": [["111027.23000000", "0.81725000"], ["111270.15000000", "4.83141000"]]}}
{"type": "orderbook", "local_time": 1761342329940, "event_time": 1761342330014, "latency_ms": -74, "data": {"e": "depthUpdate", "E": 1761342330014, "s": "BTCUSDT", "U": 79012683897, "u": 79012683901, "b": [["110858.86000000", "0.00000000"], ["109983.21000000", "0.00068000"]], "a": [["111039.30000000", "0.00000000"], ["111039.31000000", "0.01801000"], ["111107.73000000", "0.13718000"]]}}
{"type": "orderbook", "local_time": 1761342330042, "event_time": 1761342330114, "latency_ms": -72, "data": {"e": "depthUpdate", "E": 1761342330114, "s": "BTCUSDT", "U": 79012683902, "u": 79012683914, "b": [["111027.22000000", "5.00541000"], ["111027.09000000", "0.00231000"], ["99924.00000000", "0.00010000"]], "a": [["111035.90000000", "0.00000000"], ["111039.31000000", "0.00000000"], ["111039.67000000", "0.01801000"], ["111041.83000000", "0.00000000"], ["111043.14000000", "0.00450000"], ["111045.09000000", "0.00000000"], ["111051.35000000", "0.00000000"], ["111689.44000000", "0.00131000"]]}}
{"type": "orderbook", "local_time": 1761342330152, "event_time": 1761342330214, "latency_ms": -62, "data": {"e": "depthUpdate", "E": 1761342330214, "s": "BTCUSDT", "U": 79012683915, "u": 79012683925, "b": [["111027.10000000", "0.00387000"], ["111026.24000000", "0.01834000"], ["111022.08000000", "0.00005000"], ["111020.22000000", "0.00000000"], ["111010.27000000", "0.00000000"]], "a": [["111028.64000000", "0.05012000"], ["111032.86000000", "0.01815000"], ["111039.67000000", "0.00000000"], ["111039.68000000", "0.01801000"], ["111406.56000000", "0.00067000"]]}}
{"type": "orderbook", "local_time": 1761342330236, "event_time": 1761342330314, "latency_ms": -78, "data": {"e": "depthUpdate", "E": 1761342330314, "s": "BTCUSDT", "U": 79012683926, "u": 79012683971, "b": [["111027.22000000", "5.00537000"], ["111027.10000000", "0.00407000"], ["111027.09000000", "0.00231000"], ["111026.25000000", "0.00005000"], ["111026.24000000", "0.00010000"], ["111026.11000000", "0.00104000"], ["111026.05000000", "0.13198000"], ["111026.04000000", "0.29723000"], ["111024.95000000", "0.04937000"], ["111022.08000000", "0.00000000"], ["111020.56000000", "0.00540000"], ["111018.59000000", "0.36954000"], ["99924.00000000", "0.00030000"]], "a": [["111027.23000000", "0.81735000"], ["111028.63000000", "0.00010000"], ["111028.64000000", "0.05022000"], ["111031.25000000", "0.20287000"], ["111031.26000000", "0.81635000"], ["111032.86000000", "0.01820000"], ["111033.39000000", "0.13524000"], ["111033.89000000", "0.00540000"]]}}
{"type": "orderbook", "local_time": 1761342330335, "event_time": 1761342330414, "latency_ms": -79, "data": {"e": "depthUpdate", "E": 1761342330414, "s": "BTCUSDT", "U": 79012683972, "u": 79012683994, "b": [["111027.09000000", "0.00231000"], ["111026.25000000", "0.00000000"], ["111026.24000000", "0.00000000"], ["111026.11000000", "0.00109000"], ["111026.05000000", "0.13203000"], ["111025.24000000", "0.03449000"], ["111024.96000000", "0.00005000"], ["111015.30000000", "0.19186000"], ["110952.60000000", "0.00000000"], ["110898.11000000", "0.00000000"], ["99924.00000000", "0.00030000"]], "a": [["111039.68000000", "0.00000000"], ["111039.69000000", "0.01801000"]]}}
{"type": "orderbook", "local_time": 1761342330440, "event_time": 1761342330514, "latency_ms": -74, "data": {"e": "depthUpdate", "E": 1761342330514, "s": "BTCUSDT", "U": 79012683995, "u": 79012684002, "b": [["111027.22000000", "5.00529000"], ["111020.00000000", "0.01312000"], ["111014.16000000", "0.30389000"], ["111014.15000000", "0.00610000"], ["110941.18000000", "0.13764000"], ["110928.57000000", "0.01410000"], ["99924.00000000", "0.00010000"]], "a": []}}
{"type": "orderbook", "local_time": 1761342330536, "event_time": 1761342330615, "latency_ms": -79, "data": {"e": "depthUpdate", "E": 1761342330615, "s": "BTCUSDT", "U": 79012684003, "u": 79012684009, "b": [["111027.22000000", "5.00059000"], ["110957.10000000", "0.00000000"], ["110945.17000000", "0.03218000"], ["110928.57000000", "0.00000000"], ["110898.11000000", "0.01410000"], ["99924.00000000", "0.00010000"]], "a": []}}
{"type": "orderbook", "local_time": 1761342330643, "event_time": 1761342330714, "latency_ms": -71, "data": {"e": "depthUpdate", "E": 1761342330714, "s": "BTCUSDT", "U": 79012684010, "u": 79012684018, "b": [["111027.22000000", "5.00100000"], ["111021.01000000", "0.20745000"], ["111018.59000000", "0.16196000"], ["110898.11000000", "0.00000000"]], "a": [["111027.23000000", "0.60962000"], ["111028.39000000", "0.20745000"], ["111043.14000000", "0.00000000"], ["111044.16000000", "0.00450000"], ["111122.14000000", "0.00100000"]]}}
{"type": "orderbook", "local_time": 1761342330747, "event_time": 1761342330814, "latency_ms": -67, "data": {"e": "depthUpdate", "E": 1761342330814, "s": "BTCUSDT", "U": 79012684019, "u": 79012684095, "b": [["111027.22000000", "4.04765000"], ["111025.25000000", "0.00015000"], ["111025.01000000", "0.01784000"], ["111024.95000000", "0.00005000"], ["111023.06000000", "0.18009000"], ["111023.05000000", "0.00000000"], ["111022.07000000", "0.04572000"], ["111021.63000000", "0.00000000"], ["111021.01000000", "0.00000000"], ["111019.71000000", "0.16708000"], ["111018.60000000", "0.00155000"], ["111018.59000000", "0.04099000"], ["111017.07000000", "0.20745000"], ["111016.12000000", "0.00000000"], ["111014.17000000", "0.00450000"], ["111014.16000000", "0.00000000"], ["111011.72000000", "0.00000000"], ["111008.51000000", "0.00000000"], ["111007.32000000", "0.00000000"], ["111005.30000000", "0.30392000"], ["111004.15000000", "0.01801000"], ["111000.80000000", "0.00250000"], ["110998.31000000", "0.28187000"], ["110996.35000000", "0.00250000"], ["110941.18000000", "0.00000000"], ["110699.00000000", "2.02305000"], ["110572.00000000", "0.00011000"], ["99924.50000000", "0.00020000"], ["42000.00000000", "1.36734000"]], "a": [["111027.23000000", "2.21893000"], ["111027.24000000", "0.00095000"], ["111028.38000000", "0.00010000"], ["111028.39000000", "0.20755000"], ["111029.79000000", "0.29722000"], ["111031.24000000", "0.00000000"], ["111031.95000000", "0.00250000"], ["111033.14000000", "0.04912000"], ["111033.16000000", "0.04572000"], ["111033.39000000", "0.00000000"], ["111035.78000000", "0.01801000"], ["111036.27000000", "0.00000000"], ["111036.40000000", "0.00250000"], ["111039.28000000", "0.00000000"], ["111039.69000000", "0.00000000"], ["111040.29000000", "0.00450000"], ["111041.09000000", "0.00000000"], ["111044.16000000", "0.00000000"], ["111054.20000000", "0.00000000"], ["111058.65000000", "0.00000000"], ["111082.93000000", "0.00000000"], ["111091.56000000", "0.13524000"], ["111109.36000000", "0.00000000"], ["111112.47000000", "0.00128000"], ["111151.08000000", "0.15817000"]]}}
{"type": "orderbook", "local_time": 1761342330843, "event_time": 1761342330915, "latency_ms": -72, "data": {"e": "depthUpdate", "E": 1761342330915, "s": "BTCUSDT", "U": 79012684096, "u": 79012684163, "b": [["111027.22000000", "3.95299000"], ["111026.05000000", "0.13208000"], ["111026.04000000", "0.29728000"], ["111025.26000000", "0.00000000"], ["111025.25000000", "0.00010000"], ["111025.24000000", "0.03454000"], ["111025.01000000", "0.00010000"], ["111024.96000000", "0.00000000"], ["111024.95000000", "0.00000000"], ["111023.58000000", "0.04920000"], ["111023.07000000", "0.00010000"], ["111023.06000000", "0.18014000"], ["111022.08000000", "0.00005000"], ["111022.07000000", "0.04577000"], ["111020.56000000", "0.00545000"], ["111020.00000000", "0.01317000"], ["111019.71000000", "0.16713000"], ["111013.36000000", "0.04790000"]], "a": [["111027.23000000", "2.30595000"], ["111027.24000000", "0.00100000"], ["111030.56000000", "0.00000000"], ["111030.57000000", "0.00000000"], ["111030.68000000", "0.00000000"], ["111032.93000000", "0.00620000"], ["111035.90000000", "0.00044000"], ["111041.83000000", "0.00044000"], ["111046.57000000", "0.00000000"], ["111051.35000000", "0.00044000"], ["111067.20000000", "0.00000000"], ["111094.71000000", "0.00044000"], ["111111.11000000", "0.07325000"], ["111118.33000000", "0.22544000"]]}}
{"type": "orderbook", "local_time": 1761342330941, "event_time": 1761342331014, "latency_ms": -73, "data": {"e": "depthUpdate", "E": 1761342331014, "s": "BTCUSDT", "U": 79012684164, "u": 79012684185, "b": [["111027.22000000", "4.04710000"], ["111025.24000000", "0.03454000"], ["111025.01000000", "0.00000000"], ["111023.59000000", "0.00005000"], ["111023.58000000", "0.04930000"], ["111022.08000000", "0.00000000"], ["102600.00000000", "2.31150000"]], "a": [["111027.23000000", "2.21231000"], ["111035.78000000", "0.00000000"], ["111035.79000000", "0.00000000"], ["111035.80000000", "0.01801000"], ["111043.58000000", "0.00049000"], ["111045.61000000", "0.00000000"]]}}
{"type": "orderbook", "local_time": 1761342331045, "event_time": 1761342331114, "latency_ms": -69, "data": {"e": "depthUpdate", "E": 1761342331114, "s": "BTCUSDT", "U": 79012684186, "u": 79012684197, "b": [["111019.71000000", "0.16721000"], ["111005.91000000", "0.01801000"], ["111004.15000000", "0.00000000"], ["110880.00000000", "0.01984000"]], "a": [["111027.23000000", "2.21184000"], ["111035.80000000", "0.00000000"], ["111037.54000000", "0.00000000"], ["111037.55000000", "0.01801000"], ["111067.20000000", "0.22535000"], ["111117.95000000", "0.00000000"]]}}
{"type": "orderbook", "local_time": 1761342331139, "event_time": 1761342331215, "latency_ms": -76, "data": {"e": "depthUpdate", "E": 1761342331215, "s": "BTCUSDT", "U": 79012684198, "u": 79012684201, "b": [["111012.01000000", "0.30390000"], ["111005.30000000", "0.00000000"], ["60000.00000000", "56.85876000"]], "a": [["111037.55000000", "0.00000000"], ["111037.58000000", "0.01801000"]]}}
{"type": "orderbook", "local_time": 1761342331291, "event_time": 1761342331314, "latency_ms": -23, "data": {"e": "depthUpdate", "E": 1761342331314, "s": "BTCUSDT", "U": 79012684202, "u": 79012684223, "b": [["111027.22000000", "4.03590000"], ["111027.21000000", "0.00010000"], ["111021.58000000", "0.01760000"], ["111019.34000000", "0.04790000"], ["111018.60000000", "0.00405000"], ["111013.36000000", "0.00000000"], ["110996.35000000", "0.00000000"], ["110909.00000000", "0.00000000"], ["110880.00000000", "0.13557000"], ["110711.75000000", "0.00572000"], ["110703.89000000", "0.00000000"], ["99924.00000000", "0.00010000"]], "a": [["111037.58000000", "0.00000000"], ["111037.61000000", "0.01801000"], ["111067.20000000", "0.00000000"], ["111117.96000000", "0.22535000"]]}}
{"type": "orderbook", "local_time": 1761342331345, "event_time": 1761342331414, "latency_ms": -69, "data": {"e": "depthUpdate", "E": 1761342331414, "s": "BTCUSDT", "U": 79012684224, "u": 79012684232, "b": [["111027.22000000", "4.03608000"], ["111022.07000000", "0.04577000"], ["111021.58000000", "0.01765000"], ["111019.71000000", "0.16716000"]], "a": [["111037.61000000", "0.00000000"], ["111037.64000000", "0.01801000"]]}}
{"type": "orderbook", "local_time": 1761342331457, "event_time": 1761342331514, "latency_ms": -57, "data": {"e": "depthUpdate", "E": 1761342331514, "s": "BTCUSDT", "U": 79012684233, "u": 79012684239, "b": [["111023.58000000", "0.00010000"], ["111021.58000000", "0.00005000"], ["109599.87000000", "0.02501000"]], "a": [["111028.64000000", "0.00010000"], ["111032.86000000", "0.00005000"], ["111107.73000000", "0.00000000"]]}}
{"type": "orderbook", "local_time": 1761342331542, "event_time": 1761342331614, "latency_ms": -72, "data": {"e": "depthUpdate", "E": 1761342331614, "s": "BTCUSDT", "U": 79012684240, "u": 79012684285, "b": [["111027.22000000", "4.03608000"], ["111025.24000000", "0.03454000"], ["111023.59000000", "0.00000000"], ["111023.58000000", "0.00000000"], ["111023.06000000", "0.18019000"], ["111022.12000000", "0.04790000"], ["111022.08000000", "0.00005000"], ["111022.07000000", "0.04577000"], ["111021.58000000", "0.00000000"], ["111019.71000000", "0.16721000"], ["111019.70000000", "0.33157000"], ["111019.34000000", "0.00000000"], ["111018.59000000", "0.04087000"]], "a": [["111027.23000000", "2.21179000"], ["111028.39000000", "0.20755000"], ["111028.63000000", "0.00000000"], ["111028.64000000", "0.00000000"], ["111029.79000000", "0.29727000"], ["111031.24000000", "0.00005000"], ["111031.26000000", "0.81635000"], ["111032.86000000", "0.00000000"], ["111033.14000000", "0.00005000"], ["111033.16000000", "0.04577000"], ["111036.00000000", "0.05072000"], ["111067.20000000", "0.22535000"], ["111117.51000000", "0.03400000"], ["111117.96000000", "0.00000000"], ["111118.46000000", "0.00000000"], ["111121.05000000", "0.02500000"], ["111122.01000000", "0.00000000"], ["112350.00000000", "0.22459000"], ["112400.00000000", "0.99357000"]]}}
{"type": "orderbook", "local_time": 1761342331636, "event_time": 1761342331714, "latency_ms": -78, "data": {"e": "depthUpdate", "E": 1761342331714, "s": "BTCUSDT", "U": 79012684286, "u": 79012684309, "b": [["111027.22000000", "4.03608000"], ["111023.06000000", "0.18019000"], ["111022.13000000", "0.00005000"], ["111022.12000000", "0.04795000"], ["111019.70000000", "0.33152000"], ["110952.60000000", "0.00005000"], ["60000.00000000", "56.85866000"], ["33000.00000000", "3.79445000"]], "a": [["111027.23000000", "2.21179000"], ["111027.24000000", "0.00095000"], ["111032.93000000", "0.00620000"], ["111033.14000000", "0.00000000"], ["111033.89000000", "0.00545000"], ["111067.20000000", "0.00000000"], ["111117.94000000", "0.22535000"], ["111365.28000000", "0.48717000"], ["111368.93000000", "0.00000000"]]}}
{"type": "orderbook", "local_time": 1761342331741, "event_time": 1761342331814, "latency_ms": -73, "data": {"e": "depthUpdate", "E": 1761342331814, "s": "BTCUSDT", "U": 79012684310, "u": 79012684315, "b": [["110997.84000000", "0.00000000"]], "a": [["111037.64000000", "0.00000000"], ["111037.71000000", "0.01801000"], ["111058.54000000", "0.00000000"], ["111067.20000000", "0.22535000"], ["111117.94000000", "0.00000000"]]}}
{"type": "orderbook", "local_time": 1761342331837, "event_time": 1761342331914, "latency_ms": -77, "data": {"e": "depthUpdate", "E": 1761342331914, "s": "BTCUSDT", "U": 79012684316, "u": 79012684325, "b": [["102137.10000000", "0.00205000"], ["99924.00000000", "0.00010000"]], "a": [["111037.71000000", "0.00000000"], ["111037.74000000", "0.01801000"], ["111067.20000000", "0.00000000"], ["111117.89000000", "0.00000000"]]}}
{"type": "orderbook", "local_time": 1761342331938, "event_time": 1761342332014, "latency_ms": -76, "data": {"e": "depthUpdate", "E": 1761342332014, "s": "BTCUSDT", "U": 79012684326, "u": 79012684340, "b": [["111027.22000000", "3.62620000"], ["110995.78000000", "0.84683000"], ["99924.50000000", "0.00000000"], ["88822.00000000", "0.00337000"]], "a": [["111037.74000000", "0.00000000"], ["111037.76000000", "0.01801000"], ["111058.58000000", "0.97871000"], ["111067.20000000", "0.00000000"], ["111117.92000000", "0.00000000"]]}}
{"type": "orderbook", "local_time": 1761342332039, "event_time": 1761342332114, "latency_ms": -75, "data": {"e": "depthUpdate", "E": 1761342332114, "s": "BTCUSDT", "U": 79012684341, "u": 79012684351, "b": [["110900.33000000", "0.19453000"], ["110893.57000000", "0.00000000"]], "a": [["111035.90000000", "0.00000000"], ["111037.76000000", "0.00000000"], ["111037.79000000", "0.00000000"], ["111037.81000000", "0.01801000"], ["111041.83000000", "0.00000000"], ["111051.35000000", "0.00000000"], ["111094.71000000", "0.00000000"], ["111118.14000000", "0.22535000"]]}}
{"type": "orderbook", "local_time": 1761342332140, "event_time": 1761342332214, "latency_ms": -74, "data": {"e": "depthUpdate", "E": 1761342332214, "s": "BTCUSDT", "U": 79012684352, "u": 79012684358, "b": [["111017.09000000", "0.01799000"]], "a": [["111036.44000000", "0.01766000"], ["111037.81000000", "0.00000000"], ["111037.84000000", "0.01801000"], ["111067.20000000", "0.22535000"], ["111118.14000000", "0.00000000"], ["111118.33000000", "0.00000000"]]}}
{"type": "orderbook", "local_time": 1761342332237, "event_time": 1761342332314, "latency_ms": -77, "data": {"e": "depthUpdate", "E": 1761342332314, "s": "BTCUSDT", "U": 79012684359, "u": 79012684372, "b": [["111027.22000000", "3.62399000"], ["111019.04000000", "0.00360000"], ["111017.09000000", "0.00000000"], ["99924.00000000", "0.00010000"]], "a": [["111027.23000000", "2.21534000"], ["111037.84000000", "0.00000000"], ["111037.86000000", "0.01801000"], ["111067.20000000", "0.45079000"], ["111117.88000000", "0.00000000"]]}}
{"type": "orderbook", "local_time": 1761342332335, "event_time": 1761342332414, "latency_ms": -79, "data": {"e": "depthUpdate", "E": 1761342332414, "s": "BTCUSDT", "U": 79012684373, "u": 79012684385, "b": [["111027.22000000", "3.62409000"], ["111027.21000000", "0.00020000"], ["111019.11000000", "0.05099000"], ["111014.17000000", "0.00000000"], ["111012.80000000", "0.00450000"], ["102137.10000000", "0.00195000"], ["99924.00000000", "0.00010000"]], "a": [["111032.35000000", "0.04972000"], ["111067.19000000", "0.33010000"], ["111067.20000000", "0.22535000"], ["111067.62000000", "0.00000000"]]}}
{"type": "orderbook", "local_time": 1761342332438, "event_time": 1761342332514, "latency_ms": -76, "data": {"e": "depthUpdate", "E": 1761342332514, "s": "BTCUSDT", "U": 79012684386, "u": 79012684398, "b": [["99924.00000000", "0.00010000"]], "a": [["111027.23000000", "2.08015000"], ["111027.24000000", "0.00100000"], ["111031.26000000", "0.81635000"], ["111032.35000000", "0.04977000"], ["111033.89000000", "0.00540000"], ["111040.64000000", "0.13566000"], ["111067.20000000", "0.00000000"], ["111117.94000000", "0.22535000"], ["111118.12000000", "0.22544000"]]}}
{"type": "orderbook", "local_time": 1761342332536, "event_time": 1761342332614, "latency_ms": -78, "data": {"e": "depthUpdate", "E": 1761342332614, "s": "BTCUSDT", "U": 79012684399, "u": 79012684405, "b": [["111027.22000000", "3.62419000"], ["111027.21000000", "0.00030000"]], "a": [["111037.86000000", "0.00000000"], ["111038.51000000", "0.01801000"], ["111067.19000000", "0.00000000"]]}}
{"type": "orderbook", "local_time": 1761342332636, "event_time": 1761342332714, "latency_ms": -78, "data": {"e": "depthUpdate", "E": 1761342332714, "s": "BTCUSDT", "U": 79012684406, "u": 79012684419, "b": [["111027.22000000", "3.62429000"], ["111027.21000000", "0.00050000"], ["111027.09000000", "0.00221000"], ["111026.11000000", "0.00104000"], ["111026.05000000", "0.13203000"]], "a": [["111084.52000000", "0.00402000"], ["111090.61000000", "0.00000000"], ["111258.67000000", "0.00089000"], ["111264.76000000", "0.00000000"]]}}
{"type": "orderbook", "local_time": 1761342332871, "event_time": 1761342332814, "latency_ms": 57, "data": {"e": "depthUpdate", "E": 1761342332814, "s": "BTCUSDT", "U": 79012684420, "u": 79012684425, "b": [["99924.00000000", "0.00010000"]], "a": [["111035.90000000", "0.00044000"], ["111038.51000000", "0.00000000"], ["111038.60000000", "0.01801000"], ["111051.35000000", "0.00044000"]]}}
{"type": "orderbook", "local_time": 1761342332872, "event_time": 1761342332914, "latency_ms": -42, "data": {"e": "depthUpdate", "E": 1761342332914, "s": "BTCUSDT", "U": 79012684426, "u": 79012684429, "b": [["99924.00000000", "0.00010000"]], "a": [["111038.60000000", "0.00000000"], ["111038.62000000", "0.01801000"]]}}
{"type": "orderbook", "local_time": 1761342332943, "event_time": 1761342333015, "latency_ms": -72, "data": {"e": "depthUpdate", "E": 1761342333015, "s": "BTCUSDT", "U": 79012684430, "u": 79012684431, "b": [], "a": [["111038.62000000", "0.00000000"], ["111038.64000000", "0.01801000"]]}}
{"type": "orderbook", "local_time": 1761342333037, "event_time": 1761342333115, "latency_ms": -78, "data": {"e": "depthUpdate", "E": 1761342333115, "s": "BTCUSDT", "U": 79012684432, "u": 79012684453, "b": [["111027.22000000", "3.73922000"], ["111020.02000000", "0.00360000"], ["111019.04000000", "0.00000000"], ["111018.59000000", "0.03998000"], ["110709.26000000", "0.00000000"], ["99924.00000000", "0.00010000"]], "a": [["111027.23000000", "1.58083000"], ["111027.35000000", "0.21105000"], ["111028.39000000", "0.00010000"], ["111034.67000000", "1.44342000"], ["111038.64000000", "0.00000000"], ["111038.67000000", "0.00000000"], ["111038.69000000", "0.01801000"], ["111040.29000000", "0.00000000"], ["111041.99000000", "0.00450000"], ["111053.87000000", "0.22544000"], ["111150.00000000", "0.07593000"]]}}
{"type": "orderbook", "local_time": 1761342333140, "event_time": 1761342333214, "latency_ms": -74, "data": {"e": "depthUpdate", "E": 1761342333214, "s": "BTCUSDT", "U": 79012684454, "u": 79012684481, "b": [["111020.02000000", "0.01691000"], ["111020.00000000", "0.00010000"], ["111019.71000000", "0.16713000"], ["111017.09000000", "0.01768000"], ["110949.51000000", "0.00389000"]], "a": [["111027.23000000", "1.58098000"], ["111027.24000000", "0.00105000"], ["111027.34000000", "0.00010000"], ["111027.35000000", "0.21120000"], ["111028.00000000", "0.00165000"], ["111028.03000000", "0.00396000"], ["111028.38000000", "0.00000000"], ["111028.39000000", "0.00000000"], ["111034.66000000", "0.59474000"], ["111034.68000000", "0.00000000"]]}}
{"type": "orderbook", "local_time": 1761342333236, "event_time": 1761342333314, "latency_ms": -78, "data": {"e": "depthUpdate", "E": 1761342333314, "s": "BTCUSDT", "U": 79012684482, "u": 79012684496, "b": [["111020.56000000", "0.00545000"], ["111020.00000000", "0.00005000"], ["110727.22000000", "0.00010000"], ["110517.82000000", "0.00000000"]], "a": [["111027.23000000", "1.58098000"], ["111027.24000000", "0.00105000"], ["111027.35000000", "0.21125000"], ["111038.69000000", "0.00000000"], ["111038.76000000", "0.00000000"], ["111038.80000000", "0.01801000"], ["111575.66000000", "0.00000000"]]}}
{"type": "orderbook", "local_time": 1761342333335, "event_time": 1761342333414, "latency_ms": -79, "data": {"e": "depthUpdate", "E": 1761342333414, "s": "BTCUSDT", "U": 79012684497, "u": 79012684501, "b": [["111027.22000000", "3.73934000"], ["111018.59000000", "0.03098000"], ["110727.22000000", "0.00000000"]], "a": [["111068.91000000", "0.18530000"]]}}
{"type": "orderbook", "local_time": 1761342333438, "event_time": 1761342333514, "latency_ms": -76, "data": {"e": "depthUpdate", "E": 1761342333514, "s": "BTCUSDT", "U": 79012684502, "u": 79012684509, "b": [["111020.18000000", "0.20745000"], ["111017.07000000", "0.00000000"], ["110939.82000000", "0.13301000"], ["99924.00000000", "0.00010000"]], "a": [["111038.80000000", "0.00000000"], ["111038.82000000", "0.01801000"], ["111107.73000000", "0.13559000"]]}}
{"type": "orderbook", "local_time": 1761342333539, "event_time": 1761342333614, "latency_ms": -75, "data": {"e": "depthUpdate", "E": 1761342333614, "s": "BTCUSDT", "U": 79012684510, "u": 79012684530, "b": [["111020.56000000", "0.00545000"], ["111020.18000000", "0.22085000"], ["111020.02000000", "0.00360000"], ["111019.71000000", "0.16708000"], ["110971.71000000", "0.04363000"], ["110962.52000000", "0.00000000"], ["99924.00000000", "0.00010000"]], "a": [["111027.23000000", "1.55588000"], ["111075.96000000", "0.00000000"], ["111082.74000000", "0.04473000"], ["111117.51000000", "0.00000000"], ["111118.46000000", "0.03400000"], ["111121.05000000", "0.00000000"], ["111122.00000000", "0.03413000"], ["111181.07000000", "0.02000000"], ["111249.29000000", "0.02000000"]]}}
{"type": "orderbook", "local_time": 1761342333640, "event_time": 1761342333714, "latency_ms": -74, "data": {"e": "depthUpdate", "E": 1761342333714, "s": "BTCUSDT", "U": 79012684531, "u": 79012684541, "b": [["111020.18000000", "0.22085000"], ["110898.11000000", "0.01410000"]], "a": [["111027.23000000", "1.58467000"], ["111121.71000000", "0.00100000"], ["111121.72000000", "0.00100000"], ["111122.13000000", "0.00000000"], ["111122.14000000", "0.00000000"]]}}
{"type": "orderbook", "local_time": 1761342333743, "event_time": 1761342333814, "latency_ms": -71, "data": {"e": "depthUpdate", "E": 1761342333814, "s": "BTCUSDT", "U": 79012684542, "u": 79012684546, "b": [], "a": [["111038.82000000", "0.00000000"], ["111038.88000000", "0.01801000"], ["111181.07000000", "0.00000000"], ["111241.75000000", "0.00006000"]]}}
{"type": "orderbook", "local_time": 1761342333839, "event_time": 1761342333914, "latency_ms": -75, "data": {"e": "depthUpdate", "E": 1761342333914, "s": "BTCUSDT", "U": 79012684547, "u": 79012684557, "b": [["111025.78000000", "0.04790000"], ["111023.05000000", "0.00250000"], ["111022.12000000", "0.00005000"], ["111000.80000000", "0.00000000"]], "a": [["111031.95000000", "0.00000000"], ["111036.00000000", "0.00160000"], ["111038.88000000", "0.00000000"], ["111038.90000000", "0.01801000"], ["111058.65000000", "0.00250000"], ["111249.29000000", "0.04000000"]]}}
{"type": "orderbook", "local_time": 1761342333936, "event_time": 1761342334014, "latency_ms": -78, "data": {"e": "depthUpdate", "E": 1761342334014, "s": "BTCUSDT", "U": 79012684558, "u": 79012684580, "b": [["111027.22000000", "3.73934000"], ["111026.04000000", "0.29728000"], ["111025.79000000", "0.00010000"], ["111025.78000000", "0.04800000"], ["111023.06000000", "0.18014000"], ["111022.13000000", "0.00000000"], ["111022.12000000", "0.00000000"], ["111022.08000000", "0.00000000"]], "a": [["111027.23000000", "1.58462000"], ["111027.24000000", "0.00100000"], ["111038.90000000", "0.00000000"], ["111038.92000000", "0.01801000"], ["111039.66000000", "0.04912000"], ["111054.20000000", "0.00250000"], ["111058.65000000", "0.00000000"]]}}
{"type": "orderbook", "local_time": 1761342334066, "event_time": 1761342334114, "latency_ms": -48, "data": {"e": "depthUpdate", "E": 1761342334114, "s": "BTCUSDT", "U": 79012684581, "u": 79012684586, "b": [["111027.22000000", "3.62484000"], ["110706.74000000", "0.02503000"]], "a": [["111035.90000000", "0.00000000"], ["111038.92000000", "0.00000000"], ["111038.94000000", "0.01801000"], ["111051.35000000", "0.00000000"]]}}
{"type": "orderbook", "local_time": 1761342334139, "event_time": 1761342334214, "latency_ms": -75, "data": {"e": "depthUpdate", "E": 1761342334214, "s": "BTCUSDT", "U": 79012684587, "u": 79012684590, "b": [["110727.22000000", "0.00000000"]], "a": [["111038.94000000", "0.00000000"], ["111038.96000000", "0.01801000"]]}}
{"type": "orderbook", "local_time": 1761342334235, "event_time": 1761342334314, "latency_ms": -79, "data": {"e": "depthUpdate", "E": 1761342334314, "s": "BTCUSDT", "U": 79012684591, "u": 79012684594, "b": [], "a": [["111038.96000000", "0.00000000"], ["111039.00000000", "0.00000000"], ["111039.06000000", "0.01835000"]]}}
{"type": "orderbook", "local_time": 1761342334334, "event_time": 1761342334414, "latency_ms": -80, "data": {"e": "depthUpdate", "E": 1761342334414, "s": "BTCUSDT", "U": 79012684595, "u": 79012684602, "b": [["111027.22000000", "3.62489000"], ["111027.21000000", "0.00055000"], ["111025.78000000", "0.00010000"], ["111023.05000000", "0.00000000"], ["111000.80000000", "0.00250000"], ["107000.00000000", "26.28186000"]], "a": [["111036.94000000", "0.04912000"], ["111039.66000000", "0.00000000"]]}}
{"type": "orderbook", "local_time": 1761342334445, "event_time": 1761342334514, "latency_ms": -69, "data": {"e": "depthUpdate", "E": 1761342334514, "s": "BTCUSDT", "U": 79012684603, "u": 79012684626, "b": [["111027.22000000", "3.63384000"], ["111027.21000000", "0.00050000"], ["111026.04000000", "0.29728000"], ["111025.79000000", "0.00000000"], ["111025.78000000", "0.00000000"], ["111023.06000000", "0.18019000"], ["111022.33000000", "0.04790000"], ["111022.08000000", "0.00005000"], ["111019.71000000", "0.16713000"], ["109900.00000000", "3.98764000"], ["99924.00000000", "0.00030000"]], "a": [["111027.23000000", "1.58282000"], ["111109.50000000", "0.00000000"], ["118000.00000000", "53.07480000"]]}}
{"type": "orderbook", "local_time": 1761342334539, "event_time": 1761342334615, "latency_ms": -76, "data": {"e": "depthUpdate", "E": 1761342334615, "s": "BTCUSDT", "U": 79012684627, "u": 79012684637, "b": [["111027.22000000", "3.63384000"], ["111023.06000000", "0.18019000"], ["111022.34000000", "0.00005000"], ["111020.02000000", "0.00367000"], ["99924.00000000", "0.00020000"]], "a": [["111116.05000000", "0.00500000"]]}}
{"type": "orderbook", "local_time": 1761342334635, "event_time": 1761342334714, "latency_ms": -79, "data": {"e": "depthUpdate", "E": 1761342334714, "s": "BTCUSDT", "U": 79012684638, "u": 79012684638, "b": [["99924.00000000", "0.00010000"]], "a": []}}
{"type": "orderbook", "local_time": 1761342334736, "event_time": 1761342334814, "latency_ms": -78, "data": {"e": "depthUpdate", "E": 1761342334814, "s": "BTCUSDT", "U": 79012684639, "u": 79012684644, "b": [["111018.58000000", "0.00000000"]], "a": [["111027.23000000", "1.60466000"], ["111039.06000000", "0.00034000"], ["111039.13000000", "0.01801000"]]}}
{"type": "orderbook", "local_time": 1761342334834, "event_time": 1761342334914, "latency_ms": -80, "data": {"e": "depthUpdate", "E": 1761342334914, "s": "BTCUSDT", "U": 79012684645, "u": 79012684652, "b": [["111027.09000000", "0.00010000"], ["111004.71000000", "0.06000000"], ["110993.57000000", "0.08000000"], ["95375.00000000", "0.00032000"]], "a": [["111039.13000000", "0.00000000"], ["111039.15000000", "0.01801000"]]}}
{"type": "orderbook", "local_time": 1761342334945, "event_time": 1761342335015, "latency_ms": -70, "data": {"e": "depthUpdate", "E": 1761342335015, "s": "BTCUSDT", "U": 79012684653, "u": 79012684672, "b": [["111027.22000000", "3.63371000"], ["111027.21000000", "0.00045000"], ["111027.10000000", "0.00407000"], ["111027.09000000", "0.00000000"], ["111026.11000000", "0.00109000"], ["111026.05000000", "0.13208000"], ["111022.33000000", "0.04795000"], ["99924.00000000", "0.00010000"], ["88822.00000000", "0.00337000"]], "a": [["111027.23000000", "1.60545000"], ["111094.71000000", "0.00044000"]]}}
{"type": "orderbook", "local_time": 1761342335034, "event_time": 1761342335114, "latency_ms": -80, "data": {"e": "depthUpdate", "E": 1761342335114, "s": "BTCUSDT", "U": 79012684673, "u": 79012684687, "b": [["111027.22000000", "3.64685000"], ["111005.02000000", "0.01991000"], ["110888.69000000", "0.00000000"]], "a": [["111027.23000000", "1.48738000"], ["111027.24000000", "0.04603000"]]}}
{"type": "orderbook", "local_time": 1761342335134, "event_time": 1761342335214, "latency_ms": -80, "data": {"e": "depthUpdate", "E": 1761342335214, "s": "BTCUSDT", "U": 79012684688, "u": 79012684704, "b": [["111027.22000000", "3.64787000"], ["110962.45000000", "0.02663000"], ["110903.18000000", "0.07853000"], ["110900.00000000", "0.04052000"]], "a": [["111027.23000000", "1.48758000"], ["111027.24000000", "0.04613000"], ["111029.79000000", "0.29722000"], ["111031.24000000", "0.00000000"], ["111033.16000000", "0.04572000"], ["111039.15000000", "0.00000000"], ["111039.16000000", "0.01801000"], ["111096.88000000", "0.02572000"], ["111153.00000000", "0.07853000"]]}}
{"type": "orderbook", "local_time": 1761342335239, "event_time": 1761342335314, "latency_ms": -75, "data": {"e": "depthUpdate", "E": 1761342335314, "s": "BTCUSDT", "U": 79012684705, "u": 79012684731, "b": [["111027.22000000", "3.64787000"], ["111027.21000000", "0.00045000"], ["111020.52000000", "0.00360000"], ["111007.75000000", "0.01801000"], ["111005.91000000", "0.00000000"], ["110995.78000000", "0.00000000"], ["110950.50000000", "0.00000000"], ["99924.00000000", "0.00020000"]], "a": [["111028.28000000", "0.00360000"], ["111039.16000000", "0.00000000"], ["111039.38000000", "0.00000000"], ["111039.39000000", "0.01801000"], ["111040.26000000", "0.00000000"], ["111058.58000000", "0.00000000"], ["111365.28000000", "0.00000000"], ["111372.57000000", "0.48717000"]]}}
{"type": "orderbook", "local_time": 1761342335334, "event_time": 1761342335414, "latency_ms": -80, "data": {"e": "depthUpdate", "E": 1761342335414, "s": "BTCUSDT", "U": 79012684732, "u": 79012684744, "b": [["99924.00000000", "0.00020000"]], "a": [["111027.23000000", "1.26223000"], ["111027.24000000", "0.04618000"], ["111054.67000000", "0.22535000"], ["111096.87000000", "0.00048000"], ["111096.97000000", "0.00000000"], ["111207.73000000", "0.00019000"], ["111208.79000000", "0.00000000"]]}}
{"type": "orderbook", "local_time": 1761342335435, "event_time": 1761342335514, "latency_ms": -79, "data": {"e": "depthUpdate", "E": 1761342335514, "s": "BTCUSDT", "U": 79012684745, "u": 79012684759, "b": [["111027.22000000", "3.64777000"], ["111020.56000000", "0.01891000"], ["111020.18000000", "0.20750000"], ["111020.02000000", "0.00360000"], ["110997.18000000", "0.84682000"], ["110526.43000000", "0.00000000"], ["99924.00000000", "0.00010000"]], "a": [["111027.23000000", "1.26213000"], ["111027.24000000", "0.04623000"], ["111049.95000000", "0.47724000"], ["111058.65000000", "0.98015000"]]}}
{"type": "orderbook", "local_time": 1761342335542, "event_time": 1761342335614, "latency_ms": -72, "data": {"e": "depthUpdate", "E": 1761342335614, "s": "BTCUSDT", "U": 79012684760, "u": 79012684773, "b": [["111025.08000000", "0.04790000"], ["111022.33000000", "0.00005000"], ["111020.53000000", "0.00720000"], ["111020.52000000", "0.00000000"], ["111020.02000000", "0.00000000"], ["110544.52000000", "0.03798000"]], "a": [["111027.35000000", "0.00020000"], ["111028.28000000", "0.00000000"], ["111029.78000000", "0.00020000"], ["111036.94000000", "0.00000000"], ["111040.28000000", "0.02703000"], ["111041.99000000", "0.00000000"], ["111043.87000000", "0.00450000"]]}}
{"type": "orderbook", "local_time": 1761342335646, "event_time": 1761342335714, "latency_ms": -68, "data": {"e": "depthUpdate", "E": 1761342335714, "s": "BTCUSDT", "U": 79012684774, "u": 79012684841, "b": [["111027.22000000", "3.64782000"], ["111025.24000000", "0.03454000"], ["111025.09000000", "0.00010000"], ["111025.08000000", "0.04800000"], ["111023.06000000", "0.18014000"], ["111022.34000000", "0.00000000"], ["111022.33000000", "0.00000000"], ["111022.08000000", "0.00000000"], ["111020.56000000", "0.01891000"], ["111020.53000000", "0.00725000"], ["111019.71000000", "0.16708000"], ["99924.00000000", "0.00010000"]], "a": [["111027.23000000", "1.26138000"], ["111027.24000000", "0.04608000"], ["111027.34000000", "0.00000000"], ["111027.35000000", "0.00000000"], ["111028.00000000", "0.00170000"], ["111028.03000000", "0.00401000"], ["111028.29000000", "0.20745000"], ["111029.70000000", "0.04730000"], ["111029.77000000", "0.00000000"], ["111029.78000000", "0.42531000"], ["111029.79000000", "0.29727000"], ["111031.24000000", "0.00010000"], ["111031.25000000", "0.20297000"], ["111033.16000000", "0.04577000"], ["111033.89000000", "0.00545000"], ["111039.11000000", "0.00069000"], ["111040.59000000", "0.04912000"]]}}
{"type": "orderbook", "local_time": 1761342335740, "event_time": 1761342335817, "latency_ms": -77, "data": {"e": "depthUpdate", "E": 1761342335817, "s": "BTCUSDT", "U": 79012684842, "u": 79012684884, "b": [["111027.22000000", "3.38909000"]], "a": [["111027.23000000", "1.11705000"], ["111027.24000000", "0.04613000"], ["111028.28000000", "0.00010000"], ["111028.29000000", "0.20755000"], ["111028.30000000", "0.00720000"], ["111029.70000000", "0.04730000"], ["111029.77000000", "0.00005000"], ["111029.78000000", "0.42541000"], ["111029.79000000", "0.29722000"], ["111031.24000000", "0.00000000"], ["111031.25000000", "0.20287000"], ["111033.16000000", "0.04572000"], ["111033.89000000", "0.00540000"], ["111039.11000000", "0.00000000"], ["111039.39000000", "0.00000000"], ["111039.40000000", "0.01801000"]]}}
{"type": "orderbook", "local_time": 1761342335840, "event_time": 1761342335914, "latency_ms": -74, "data": {"e": "depthUpdate", "E": 1761342335914, "s": "BTCUSDT", "U": 79012684885, "u": 79012684900, "b": [["110838.25000000", "0.00000000"], ["110788.41000000", "0.00000000"], ["110711.75000000", "0.00000000"], ["110706.75000000", "0.00572000"], ["110684.72000000", "0.04198000"]], "a": [["111027.23000000", "1.11705000"], ["111027.24000000", "0.04618000"], ["111028.29000000", "0.20755000"], ["111028.30000000", "0.00725000"], ["111032.93000000", "0.00615000"], ["111039.40000000", "0.00000000"], ["111039.41000000", "0.01801000"], ["111121.05000000", "0.02500000"], ["111122.00000000", "0.00913000"], ["111270.15000000", "0.00000000"]]}}
{"type": "orderbook", "local_time": 1761342335935, "event_time": 1761342336015, "latency_ms": -80, "data": {"e": "depthUpdate", "E": 1761342336015, "s": "BTCUSDT", "U": 79012684901, "u": 79012684906, "b": [["111027.22000000", "3.43752000"], ["111025.08000000", "0.00010000"]], "a": [["111027.23000000", "1.11636000"], ["111039.10000000", "0.00070000"], ["111277.58000000", "0.00000000"]]}}
{"type": "orderbook", "local_time": 1761342336055, "event_time": 1761342336114, "latency_ms": -59, "data": {"e": "depthUpdate", "E": 1761342336114, "s": "BTCUSDT", "U": 79012684907, "u": 79012684939, "b": [["111027.22000000", "3.43757000"], ["111025.24000000", "0.03454000"], ["111025.09000000", "0.00000000"], ["111025.08000000", "0.00000000"], ["111023.06000000", "0.18019000"], ["111022.08000000", "0.00005000"], ["111020.53000000", "0.00733000"], ["111019.71000000", "0.16713000"]], "a": [["111027.23000000", "0.43461000"], ["111028.29000000", "0.00010000"], ["111028.30000000", "0.00005000"], ["111029.77000000", "0.00010000"], ["111029.78000000", "0.42540000"], ["111034.67000000", "0.00000000"], ["111039.41000000", "0.00000000"], ["111040.59000000", "0.00000000"], ["111040.61000000", "0.00000000"], ["111043.10000000", "0.04912000"], ["111058.65000000", "0.00000000"], ["111217.26000000", "0.00000000"]]}}
{"type": "orderbook", "local_time": 1761342336135, "event_time": 1761342336214, "latency_ms": -79, "data": {"e": "depthUpdate", "E": 1761342336214, "s": "BTCUSDT", "U": 79012684940, "u": 79012685006, "b": [["111027.22000000", "3.60836000"], ["111023.05000000", "0.00250000"], ["111019.11000000", "0.00000000"], ["111000.80000000", "0.00000000"], ["110990.18000000", "0.00000000"], ["110936.32000000", "0.00000000"], ["110896.67000000", "0.02199000"], ["110787.03000000", "0.84842000"]], "a": [["111027.23000000", "0.43379000"], ["111027.24000000", "0.04603000"], ["111028.28000000", "0.00000000"], ["111028.29000000", "0.00000000"], ["111028.30000000", "0.00000000"], ["111029.42000000", "0.00000000"], ["111029.78000000", "0.00020000"], ["111029.79000000", "0.00010000"], ["111031.24000000", "0.00005000"], ["111032.76000000", "0.29717000"], ["111032.93000000", "0.00620000"], ["111033.16000000", "0.04577000"], ["111034.66000000", "0.14371000"], ["111035.26000000", "0.00000000"], ["111038.34000000", "0.00000000"], ["111039.09000000", "0.00000000"], ["111039.21000000", "0.04912000"], ["111039.22000000", "0.00000000"], ["111040.61000000", "0.01801000"], ["111043.10000000", "0.00000000"], ["111046.36000000", "0.11267000"], ["111060.36000000", "0.00000000"], ["111080.13000000", "0.32404000"], ["111094.71000000", "0.00000000"], ["111121.05000000", "0.00000000"], ["111121.71000000", "0.00000000"], ["111121.72000000", "0.00000000"], ["111122.00000000", "0.03413000"], ["111122.13000000", "0.00100000"], ["111122.14000000", "0.00100000"], ["111229.93000000", "0.01410000"], ["111269.92000000", "4.86772000"]]}}
{"type": "orderbook", "local_time": 1761342336235, "event_time": 1761342336314, "latency_ms": -79, "data": {"e": "depthUpdate", "E": 1761342336314, "s": "BTCUSDT", "U": 79012685007, "u": 79012685069, "b": [["111027.22000000", "3.79975000"], ["111023.06000000", "0.00010000"], ["111018.61000000", "0.00450000"], ["111012.80000000", "0.00000000"], ["111010.32000000", "0.01801000"], ["111009.06000000", "0.13524000"], ["111007.75000000", "0.00000000"], ["111004.31000000", "0.07661000"]], "a": [["111027.23000000", "0.43309000"], ["111027.24000000", "0.04603000"], ["111029.70000000", "0.04730000"], ["111029.77000000", "0.00000000"], ["111029.78000000", "0.00000000"], ["111029.79000000", "0.00000000"], ["111030.78000000", "0.21465000"], ["111031.24000000", "0.00010000"], ["111031.25000000", "0.56628000"], ["111031.26000000", "0.81640000"], ["111032.35000000", "0.04977000"], ["111032.75000000", "0.00005000"], ["111032.76000000", "0.29722000"], ["111033.89000000", "0.00545000"], ["111034.66000000", "0.09662000"], ["111039.20000000", "0.00068000"], ["111039.35000000", "0.00074000"], ["111040.28000000", "0.00000000"], ["111040.29000000", "0.02703000"], ["111040.61000000", "0.00000000"], ["111041.11000000", "0.04508000"], ["111041.95000000", "0.01801000"], ["111043.87000000", "0.00000000"], ["111046.35000000", "0.00450000"], ["111063.27000000", "0.94495000"], ["111080.12000000", "0.00016000"], ["111080.82000000", "0.00000000"]]}}
{"type": "orderbook", "local_time": 1761342336335, "event_time": 1761342336414, "latency_ms": -79, "data": {"e": "depthUpdate", "E": 1761342336414, "s": "BTCUSDT", "U": 79012685070, "u": 79012685100, "b": [["111027.22000000", "3.78850000"], ["111025.24000000", "0.03454000"], ["111023.07000000", "0.00000000"], ["111023.06000000", "0.00000000"], ["111022.08000000", "0.00010000"], ["111020.19000000", "0.00005000"], ["111019.70000000", "0.33157000"], ["111012.02000000", "1.44342000"]], "a": [["111027.23000000", "0.43245000"], ["111027.24000000", "0.04608000"], ["111029.70000000", "0.04730000"], ["111030.77000000", "0.00010000"], ["111030.78000000", "0.21475000"], ["111031.26000000", "0.81635000"], ["111032.75000000", "0.00000000"], ["111033.89000000", "0.00540000"], ["111039.18000000", "0.00070000"]]}}
{"type": "orderbook", "local_time": 1761342336437, "event_time": 1761342336514, "latency_ms": -77, "data": {"e": "depthUpdate", "E": 1761342336514, "s": "BTCUSDT", "U": 79012685101, "u": 79012685108, "b": [["111015.30000000", "0.63993000"], ["110993.21000000", "0.00000000"]], "a": [["111040.29000000", "0.00000000"], ["111040.45000000", "0.02703000"], ["111041.95000000", "0.00000000"], ["111042.07000000", "0.01801000"]]}}
{"type": "orderbook", "local_time": 1761342336535, "event_time": 1761342336614, "latency_ms": -79, "data": {"e": "depthUpdate", "E": 1761342336614, "s": "BTCUSDT", "U": 79012685109, "u": 79012685152, "b": [["111027.22000000", "3.43837000"], ["111025.25000000", "0.18019000"], ["111023.23000000", "0.04790000"], ["111023.05000000", "0.00000000"], ["111022.07000000", "0.04582000"], ["111018.61000000", "0.00000000"], ["111016.12000000", "0.00450000"], ["111000.80000000", "0.00250000"], ["110949.37000000", "0.13524000"], ["99924.00000000", "0.00010000"]], "a": [["111027.23000000", "1.01906000"], ["111027.24000000", "0.04608000"], ["111029.94000000", "0.29717000"], ["111031.95000000", "0.00250000"], ["111032.76000000", "0.00005000"], ["111032.81000000", "0.04912000"], ["111034.99000000", "0.00000000"], ["111035.26000000", "0.04508000"], ["111039.18000000", "0.00000000"], ["111039.21000000", "0.00000000"], ["111041.11000000", "0.00000000"], ["111054.20000000", "0.00000000"], ["111091.56000000", "0.00000000"], ["111109.74000000", "0.00000000"], ["111117.94000000", "0.00000000"], ["111118.12000000", "0.00000000"], ["111118.80000000", "0.00000000"], ["111229.93000000", "0.00000000"]]}}
{"type": "orderbook", "local_time": 1761342336633, "event_time": 1761342336714, "latency_ms": -81, "data": {"e": "depthUpdate", "E": 1761342336714, "s": "BTCUSDT", "U": 79012685153, "u": 79012685222, "b": [["111027.22000000", "3.43737000"], ["111026.04000000", "0.29728000"], ["111025.34000000", "0.00000000"], ["111025.26000000", "0.00010000"], ["111025.25000000", "0.00020000"], ["111025.24000000", "0.03454000"], ["111023.23000000", "0.00005000"], ["111022.79000000", "0.18010000"], ["111022.08000000", "0.00005000"], ["111022.07000000", "0.04577000"], ["111020.19000000", "0.00000000"], ["111019.71000000", "0.16708000"], ["111019.70000000", "0.33152000"], ["33000.00000000", "3.79445000"]], "a": [["111027.23000000", "1.02049000"], ["111027.24000000", "0.04608000"], ["111029.70000000", "0.04730000"], ["111029.93000000", "0.00010000"], ["111029.94000000", "0.29727000"], ["111031.25000000", "0.56613000"], ["111031.95000000", "0.00000000"], ["111032.35000000", "0.04977000"], ["111032.76000000", "0.00000000"], ["111032.81000000", "0.00005000"], ["111033.16000000", "0.04572000"], ["111037.87000000", "0.04912000"], ["111039.20000000", "0.00000000"], ["111039.35000000", "0.00000000"], ["111040.64000000", "0.00042000"], ["111054.20000000", "0.00250000"], ["111118.09000000", "0.13511000"], ["111118.17000000", "0.18027000"]]}}
{"type": "orderbook", "local_time": 1761342336734, "event_time": 1761342336814, "latency_ms": -80, "data": {"e": "depthUpdate", "E": 1761342336814, "s": "BTCUSDT", "U": 79012685223, "u": 79012685258, "b": [["111027.22000000", "3.43747000"], ["111027.00000000", "0.04889000"], ["111026.04000000", "0.29728000"], ["111025.26000000", "0.00000000"], ["111025.25000000", "0.00010000"], ["111025.24000000", "0.03454000"], ["111023.23000000", "0.00000000"], ["111022.80000000", "0.00010000"], ["111022.79000000", "0.18020000"], ["111019.71000000", "0.16713000"], ["111010.32000000", "0.00000000"], ["111009.10000000", "0.01801000"], ["99924.00000000", "0.00010000"]], "a": [["111027.23000000", "1.02044000"], ["111027.24000000", "0.04603000"], ["111032.35000000", "0.04977000"], ["111032.81000000", "0.00000000"], ["111033.16000000", "0.04577000"], ["111091.27000000", "0.13524000"]]}}
{"type": "orderbook", "local_time": 1761342336854, "event_time": 1761342336914, "latency_ms": -60, "data": {"e": "depthUpdate", "E": 1761342336914, "s": "BTCUSDT", "U": 79012685259, "u": 79012685313, "b": [["111027.22000000", "3.43752000"], ["111027.21000000", "0.00040000"], ["111027.10000000", "0.00407000"], ["111027.01000000", "0.00005000"], ["111027.00000000", "0.00010000"], ["111026.11000000", "0.00104000"], ["111026.05000000", "0.13203000"], ["111023.05000000", "0.00250000"], ["111022.79000000", "0.18015000"], ["111022.08000000", "0.00000000"], ["111020.53000000", "0.00013000"], ["111020.05000000", "0.00720000"], ["111019.71000000", "0.16708000"], ["111009.10000000", "0.00000000"], ["111007.43000000", "0.01801000"], ["111000.80000000", "0.00000000"], ["99924.00000000", "0.00010000"]], "a": [["111027.23000000", "0.65833000"], ["111030.78000000", "0.00010000"], ["111037.87000000", "0.00000000"], ["111039.22000000", "0.00073000"], ["111040.73000000", "0.13524000"], ["111042.07000000", "0.00000000"], ["111053.87000000", "0.00000000"], ["111054.37000000", "0.22544000"], ["111054.67000000", "0.00000000"], ["111094.21000000", "0.00000000"], ["111096.68000000", "0.00048000"], ["111096.87000000", "0.00000000"], ["111100.69000000", "0.19453000"], ["111119.96000000", "0.22535000"], ["111120.99000000", "0.22544000"], ["111207.72000000", "0.00019000"], ["111207.73000000", "0.00000000"], ["111365.28000000", "0.48717000"], ["111372.57000000", "0.00000000"]]}}
{"type": "orderbook", "local_time": 1761342336937, "event_time": 1761342337014, "latency_ms": -77, "data": {"e": "depthUpdate", "E": 1761342337014, "s": "BTCUSDT", "U": 79012685314, "u": 79012685357, "b": [["111027.22000000", "3.43747000"], ["111027.21000000", "0.00035000"], ["111027.10000000", "0.00407000"], ["111027.01000000", "0.00000000"], ["111027.00000000", "0.00000000"], ["111026.11000000", "0.00109000"], ["111026.05000000", "0.13208000"], ["111022.08000000", "0.00005000"], ["111020.56000000", "0.01891000"], ["111020.53000000", "0.00008000"], ["111020.18000000", "0.20750000"], ["111020.05000000", "0.00725000"], ["109599.87000000", "0.02501000"]], "a": [["111027.23000000", "0.65903000"], ["111027.24000000", "0.04598000"], ["111029.70000000", "0.26195000"], ["111029.94000000", "0.29727000"], ["111030.77000000", "0.00000000"], ["111030.78000000", "0.00000000"], ["111031.25000000", "0.56623000"], ["111033.89000000", "0.00545000"], ["111039.10000000", "0.00070000"], ["111040.64000000", "0.01843000"], ["111040.74000000", "0.04912000"]]}}
{"type": "orderbook", "local_time": 1761342337048, "event_time": 1761342337114, "latency_ms": -66, "data": {"e": "depthUpdate", "E": 1761342337114, "s": "BTCUSDT", "U": 79012685358, "u": 79012685364, "b": [["111027.22000000", "3.43693000"], ["111020.53000000", "0.00000000"], ["111020.18000000", "0.20766000"], ["110714.23000000", "0.00000000"], ["110709.31000000", "0.00000000"]], "a": [["111039.18000000", "0.00074000"], ["111039.22000000", "0.00000000"]]}}
{"type": "orderbook", "local_time": 1761342337141, "event_time": 1761342337214, "latency_ms": -73, "data": {"e": "depthUpdate", "E": 1761342337214, "s": "BTCUSDT", "U": 79012685365, "u": 79012685371, "b": [["110802.00000000", "0.00872000"], ["110786.72000000", "0.00000000"]], "a": [["111027.23000000", "0.65833000"], ["111032.93000000", "0.00005000"], ["111048.23000000", "0.00615000"], ["111078.51000000", "0.00402000"], ["111084.52000000", "0.00000000"], ["111252.66000000", "0.00089000"], ["111258.67000000", "0.00000000"]]}}
{"type": "orderbook", "local_time": 1761342337239, "event_time": 1761342337314, "latency_ms": -75, "data": {"e": "depthUpdate", "E": 1761342337314, "s": "BTCUSDT", "U": 79012685372, "u": 79012685381, "b": [["111027.22000000", "3.43743000"]], "a": [["111027.23000000", "0.65838000"], ["111027.24000000", "0.04593000"], ["111032.35000000", "0.04977000"], ["111032.93000000", "0.00000000"], ["111034.66000000", "0.09667000"], ["111038.36000000", "0.04912000"], ["111039.09000000", "0.00070000"], ["111040.74000000", "0.00000000"]]}}
{"type": "orderbook", "local_time": 1761342337337, "event_time": 1761342337414, "latency_ms": -77, "data": {"e": "depthUpdate", "E": 1761342337414, "s": "BTCUSDT", "U": 79012685382, "u": 79012685384, "b": [], "a": [["111043.58000000", "0.00005000"], ["111060.36000000", "0.32410000"], ["111080.13000000", "0.00000000"]]}}
{"type": "orderbook", "local_time": 1761342337435, "event_time": 1761342337514, "latency_ms": -79, "data": {"e": "depthUpdate", "E": 1761342337514, "s": "BTCUSDT", "U": 79012685385, "u": 79012685389, "b": [["111027.22000000", "3.43831000"], ["102145.04000000", "0.00010000"]], "a": [["111027.23000000", "0.65749000"], ["111039.09000000", "0.00000000"], ["111072.57000000", "0.00000000"]]}}
{"type": "orderbook", "local_time": 1761342337554, "event_time": 1761342337615, "latency_ms": -61, "data": {"e": "depthUpdate", "E": 1761342337615, "s": "BTCUSDT", "U": 79012685390, "u": 79012685396, "b": [["111025.82000000", "0.05031000"], ["111024.24000000", "0.04000000"]], "a": [["111027.23000000", "0.66224000"], ["111080.12000000", "0.00000000"], ["111080.82000000", "0.00016000"], ["111118.13000000", "0.22535000"], ["111119.96000000", "0.00000000"]]}}
{"type": "orderbook", "local_time": 1761342337634, "event_time": 1761342337714, "latency_ms": -80, "data": {"e": "depthUpdate", "E": 1761342337714, "s": "BTCUSDT", "U": 79012685397, "u": 79012685412, "b": [["111027.22000000", "3.43841000"], ["111026.04000000", "0.29723000"], ["111025.83000000", "0.00010000"], ["111025.82000000", "0.05036000"], ["111025.24000000", "0.03449000"], ["111024.25000000", "0.00005000"], ["111022.80000000", "0.00005000"], ["111022.08000000", "0.00000000"], ["111020.05000000", "0.00720000"], ["39969.80000000", "0.00032000"]], "a": []}}
{"type": "orderbook", "local_time": 1761342337736, "event_time": 1761342337814, "latency_ms": -78, "data": {"e": "depthUpdate", "E": 1761342337814, "s": "BTCUSDT", "U": 79012685413, "u": 79012685424, "b": [["111027.22000000", "3.35338000"], ["111025.82000000", "0.00005000"], ["110891.03000000", "0.00000000"], ["99924.00000000", "0.00010000"]], "a": [["111027.23000000", "0.66155000"], ["111039.18000000", "0.00000000"], ["111040.45000000", "0.00000000"], ["111040.55000000", "0.02703000"]]}}
{"type": "orderbook", "local_time": 1761342337834, "event_time": 1761342337914, "latency_ms": -80, "data": {"e": "depthUpdate", "E": 1761342337914, "s": "BTCUSDT", "U": 79012685425, "u": 79012685441, "b": [["111026.04000000", "0.29723000"], ["111025.83000000", "0.00000000"], ["111025.82000000", "0.00000000"], ["111024.25000000", "0.00010000"], ["111024.24000000", "0.04005000"], ["110900.01000000", "0.03698000"], ["99924.00000000", "0.00010000"]], "a": [["111027.23000000", "0.66227000"], ["111039.23000000", "0.00069000"], ["111041.83000000", "0.00044000"], ["111075.64000000", "0.01410000"], ["111121.97000000", "0.00000000"]]}}
{"type": "orderbook", "local_time": 1761342338008, "event_time": 1761342338014, "latency_ms": -6, "data": {"e": "depthUpdate", "E": 1761342338014, "s": "BTCUSDT", "U": 79012685442, "u": 79012685448, "b": [["111027.22000000", "3.35333000"], ["111027.21000000", "0.00030000"], ["102145.04000000", "0.00000000"], ["88822.00000000", "0.00337000"]], "a": [["111027.23000000", "0.66155000"], ["111039.36000000", "0.00074000"]]}}
{"type": "orderbook", "local_time": 1761342338035, "event_time": 1761342338114, "latency_ms": -79, "data": {"e": "depthUpdate", "E": 1761342338114, "s": "BTCUSDT", "U": 79012685449, "u": 79012685449, "b": [["111027.22000000", "3.34631000"]], "a": []}}
{"type": "orderbook", "local_time": 1761342338138, "event_time": 1761342338214, "latency_ms": -76, "data": {"e": "depthUpdate", "E": 1761342338214, "s": "BTCUSDT", "U": 79012685450, "u": 79012685452, "b": [], "a": [["111039.23000000", "0.00000000"], ["111039.36000000", "0.00000000"], ["111319.90000000", "0.02498000"]]}}
{"type": "orderbook", "local_time": 1761342338237, "event_time": 1761342338314, "latency_ms": -77, "data": {"e": "depthUpdate", "E": 1761342338314, "s": "BTCUSDT", "U": 79012685453, "u": 79012685454, "b": [], "a": [["111027.23000000", "0.66298000"]]}}
{"type": "orderbook", "local_time": 1761342338341, "event_time": 1761342338414, "latency_ms": -73, "data": {"e": "depthUpdate", "E": 1761342338414, "s": "BTCUSDT", "U": 79012685455, "u": 79012685458, "b": [["111027.22000000", "3.29841000"], ["111024.47000000", "0.04790000"]], "a": [["111036.06000000", "0.04912000"], ["111038.36000000", "0.00000000"]]}}
{"type": "orderbook", "local_time": 1761342338435, "event_time": 1761342338514, "latency_ms": -79, "data": {"e": "depthUpdate", "E": 1761342338514, "s": "BTCUSDT", "U": 79012685459, "u": 79012685468, "b": [["111027.22000000", "3.31011000"], ["111026.96000000", "0.04790000"], ["111025.24000000", "0.03449000"], ["111024.48000000", "0.00010000"], ["111024.47000000", "0.00000000"], ["111022.80000000", "0.00000000"]], "a": [["111027.23000000", "0.66303000"], ["111027.24000000", "0.04598000"]]}}
{"type": "orderbook", "local_time": 1761342338546, "event_time": 1761342338614, "latency_ms": -68, "data": {"e": "depthUpdate", "E": 1761342338614, "s": "BTCUSDT", "U": 79012685469, "u": 79012685486, "b": [["111027.22000000", "3.31016000"], ["111027.10000000", "0.00407000"], ["111026.97000000", "0.00010000"], ["111026.96000000", "0.04800000"], ["111026.11000000", "0.00104000"], ["111026.05000000", "0.13203000"], ["111025.24000000", "0.03444000"], ["111024.48000000", "0.00000000"]], "a": [["111027.23000000", "0.66372000"], ["111039.10000000", "0.00000000"], ["111067.20000000", "0.22535000"], ["111118.13000000", "0.00000000"]]}}
{"type": "orderbook", "local_time": 1761342338641, "event_time": 1761342338714, "latency_ms": -73, "data": {"e": "depthUpdate", "E": 1761342338714, "s": "BTCUSDT", "U": 79012685487, "u": 79012685494, "b": [["111027.22000000", "3.30934000"]], "a": [["111036.06000000", "0.00000000"], ["111067.20000000", "0.22535000"], ["111117.91000000", "0.00000000"]]}}
{"type": "orderbook", "local_time": 1761342338736, "event_time": 1761342338814, "latency_ms": -78, "data": {"e": "depthUpdate", "E": 1761342338814, "s": "BTCUSDT", "U": 79012685495, "u": 79012685501, "b": [["111027.22000000", "3.31006000"], ["42000.00000000", "1.36834000"]], "a": [["111027.23000000", "0.66367000"], ["111027.24000000", "0.04593000"], ["111038.13000000", "0.04912000"], ["111067.20000000", "0.00000000"], ["111118.36000000", "0.22535000"]]}}
{"type": "orderbook", "local_time": 1761342338835, "event_time": 1761342338914, "latency_ms": -79, "data": {"e": "depthUpdate", "E": 1761342338914, "s": "BTCUSDT", "U": 79012685502, "u": 79012685504, "b": [["99924.00000000", "0.00030000"], ["50000.00000000", "39.95292000"]], "a": [["111118.46000000", "0.00000000"]]}}
{"type": "orderbook", "local_time": 1761342338953, "event_time": 1761342339014, "latency_ms": -61, "data": {"e": "depthUpdate", "E": 1761342339014, "s": "BTCUSDT", "U": 79012685505, "u": 79012685529, "b": [["111027.22000000", "3.54190000"], ["111027.21000000", "0.00020000"], ["111025.82000000", "0.05042000"], ["111006.41000000", "0.09100000"], ["110995.26000000", "0.00000000"], ["99924.00000000", "0.00010000"], ["50000.00000000", "39.95352000"]], "a": [["111027.23000000", "0.43856000"], ["111031.25000000", "0.20297000"], ["111039.11000000", "0.00069000"], ["111054.10000000", "0.22535000"], ["111096.68000000", "0.00000000"], ["111118.45000000", "0.03400000"], ["111207.72000000", "0.00000000"]]}}
{"type": "orderbook", "local_time": 1761342339035, "event_time": 1761342339114, "latency_ms": -79, "data": {"e": "depthUpdate", "E": 1761342339114, "s": "BTCUSDT", "U": 79012685530, "u": 79012685607, "b": [["111027.22000000", "3.58985000"], ["111027.21000000", "0.00000000"], ["111027.10000000", "0.00020000"], ["111026.96000000", "0.00025000"], ["111026.11000000", "0.00109000"], ["111026.05000000", "0.13208000"], ["111026.04000000", "0.29723000"], ["111025.83000000", "0.00010000"], ["111024.25000000", "0.00000000"], ["111021.31000000", "0.06748000"], ["111020.18000000", "0.20761000"], ["111009.68000000", "0.01801000"], ["111007.43000000", "0.00000000"], ["111000.45000000", "0.00000000"], ["110999.90000000", "0.00576000"], ["110998.31000000", "0.28178000"], ["110997.27000000", "0.00000000"], ["110992.17000000", "0.00000000"], ["110988.90000000", "0.36556000"], ["110985.79000000", "0.00000000"], ["110975.04000000", "0.00000000"], ["110944.58000000", "0.00000000"], ["110809.89000000", "0.02498000"], ["110725.58000000", "0.02498000"], ["50000.00000000", "39.95382000"]], "a": [["111027.23000000", "0.43644000"], ["111029.93000000", "0.36297000"], ["111032.35000000", "0.00005000"], ["111036.40000000", "0.00000000"], ["111038.13000000", "0.00000000"], ["111039.30000000", "0.00070000"], ["111039.41000000", "0.00073000"], ["111039.47000000", "0.00070000"], ["111040.55000000", "0.00000000"], ["111040.64000000", "0.00042000"], ["111040.65000000", "0.00000000"], ["111041.23000000", "0.00000000"], ["111041.25000000", "0.00000000"], ["111041.31000000", "0.01801000"], ["111041.83000000", "0.00000000"], ["111041.94000000", "0.14000000"], ["111042.69000000", "0.04912000"], ["111056.92000000", "0.00000000"], ["111058.41000000", "0.00000000"], ["111058.65000000", "0.00250000"], ["111068.54000000", "0.03798000"], ["111069.98000000", "0.03714000"], ["111096.65000000", "0.00048000"], ["111128.32000000", "0.00000000"], ["111142.19000000", "0.36501000"], ["111207.73000000", "0.00019000"], ["111248.39000000", "0.00006000"], ["111365.28000000", "0.00000000"], ["111372.57000000", "0.48717000"], ["111421.01000000", "0.03698000"]]}}
{"type": "orderbook", "local_time": 1761342339154, "event_time": 1761342339214, "latency_ms": -60, "data": {"e": "depthUpdate", "E": 1761342339214, "s": "BTCUSDT", "U": 79012685608, "u": 79012685676, "b": [["111027.22000000", "3.59372000"], ["111027.10000000", "0.00000000"], ["111026.97000000", "0.00000000"], ["111026.96000000", "0.00000000"], ["111026.11000000", "0.00119000"], ["111026.05000000", "0.13223000"], ["111026.04000000", "0.29733000"], ["111025.82000000", "0.05052000"], ["111025.24000000", "0.03449000"], ["111024.25000000", "0.00005000"], ["111023.46000000", "0.21465000"], ["111022.07000000", "0.04572000"], ["111020.18000000", "0.00016000"], ["111020.05000000", "0.00000000"], ["111001.86000000", "0.00009000"], ["110999.71000000", "0.00009000"], ["110998.68000000", "0.00009000"], ["110993.57000000", "0.08009000"], ["110987.19000000", "0.00009000"], ["110945.98000000", "0.00090000"], ["110625.51000000", "0.02431000"], ["110614.72000000", "0.00000000"], ["50000.00000000", "39.95412000"]], "a": [["111027.23000000", "0.43644000"], ["111027.24000000", "0.04598000"], ["111028.20000000", "0.00000000"], ["111029.70000000", "0.26195000"], ["111029.92000000", "0.00010000"], ["111029.93000000", "0.36307000"], ["111031.25000000", "0.20287000"], ["111031.26000000", "0.81635000"], ["111032.35000000", "0.00000000"], ["111041.26000000", "0.02703000"], ["111041.31000000", "0.00000000"], ["111042.63000000", "0.00000000"], ["111042.64000000", "0.01801000"], ["111094.50000000", "0.00005000"]]}}
{"type": "orderbook", "local_time": 1761342339234, "event_time": 1761342339314, "latency_ms": -80, "data": {"e": "depthUpdate", "E": 1761342339314, "s": "BTCUSDT", "U": 79012685677, "u": 79012685693, "b": [["111026.05000000", "0.22998000"], ["111024.24000000", "0.04005000"], ["111023.47000000", "0.00720000"], ["111023.46000000", "0.20750000"], ["111020.56000000", "0.01886000"], ["111020.18000000", "0.00000000"], ["111020.00000000", "0.00037000"]], "a": [["111027.23000000", "0.43313000"], ["111029.70000000", "0.04730000"], ["111031.88000000", "0.21465000"], ["111042.64000000", "0.00000000"], ["111042.72000000", "0.01801000"]]}}
{"type": "orderbook", "local_time": 1761342339340, "event_time": 1761342339414, "latency_ms": -74, "data": {"e": "depthUpdate", "E": 1761342339414, "s": "BTCUSDT", "U": 79012685694, "u": 79012685722, "b": [["111027.22000000", "3.77381000"], ["111024.24000000", "0.04005000"], ["111022.79000000", "0.00005000"]], "a": [["111027.23000000", "0.43651000"], ["111027.24000000", "0.04603000"], ["111029.92000000", "0.00010000"], ["111029.93000000", "0.00020000"], ["111031.25000000", "0.00005000"], ["111031.26000000", "0.81635000"], ["111031.88000000", "0.21470000"], ["111034.66000000", "0.09662000"], ["111039.24000000", "0.00000000"], ["111042.72000000", "0.00000000"], ["111042.73000000", "0.01801000"], ["111118.45000000", "0.00000000"], ["111119.46000000", "0.03400000"], ["111122.00000000", "0.00913000"], ["111122.13000000", "0.00000000"], ["111122.14000000", "0.00000000"], ["111123.00000000", "0.02550000"], ["111123.13000000", "0.00100000"], ["111123.14000000", "0.00100000"]]}}
{"type": "orderbook", "local_time": 1761342339443, "event_time": 1761342339514, "latency_ms": -71, "data": {"e": "depthUpdate", "E": 1761342339514, "s": "BTCUSDT", "U": 79012685723, "u": 79012685793, "b": [["111027.22000000", "3.76186000"], ["111027.21000000", "0.00005000"], ["111026.04000000", "0.29738000"], ["111025.82000000", "0.05057000"], ["111025.24000000", "0.03454000"], ["111023.47000000", "0.00725000"], ["111023.46000000", "0.20750000"], ["111022.79000000", "0.00000000"], ["111022.07000000", "0.04577000"], ["111021.31000000", "0.06753000"], ["110997.18000000", "0.00000000"], ["110787.03000000", "0.00000000"], ["109750.00000000", "0.21589000"], ["99924.00000000", "0.00010000"]], "a": [["111027.23000000", "0.43079000"], ["111027.24000000", "0.05214000"], ["111029.70000000", "0.04730000"], ["111029.92000000", "0.00000000"], ["111029.93000000", "0.41221000"], ["111029.94000000", "0.29727000"], ["111031.24000000", "0.00000000"], ["111031.25000000", "0.00010000"], ["111031.26000000", "0.81640000"], ["111031.87000000", "0.00005000"], ["111031.88000000", "0.00005000"], ["111034.66000000", "0.09667000"], ["111034.82000000", "0.20287000"], ["111063.27000000", "0.00000000"], ["111269.92000000", "0.00000000"], ["112500.00000000", "21.28365000"], ["113900.00000000", "4.58449000"]]}}
{"type": "orderbook", "local_time": 1761342339536, "event_time": 1761342339614, "latency_ms": -78, "data": {"e": "depthUpdate", "E": 1761342339614, "s": "BTCUSDT", "U": 79012685794, "u": 79012685824, "b": [["111027.22000000", "3.76191000"]], "a": [["111027.23000000", "0.43084000"], ["111027.24000000", "0.05209000"], ["111029.70000000", "0.04730000"], ["111029.92000000", "0.00010000"], ["111029.93000000", "0.41231000"], ["111031.26000000", "0.81635000"], ["111031.87000000", "0.00000000"], ["111031.88000000", "0.00000000"], ["111031.95000000", "0.21465000"], ["111035.26000000", "0.00000000"], ["111035.96000000", "0.00044000"], ["111040.56000000", "0.04912000"], ["111041.11000000", "0.04508000"], ["111042.69000000", "0.00000000"], ["111042.73000000", "0.00000000"], ["111042.80000000", "0.01801000"], ["111052.47000000", "0.00044000"], ["111109.99000000", "0.00225000"], ["111110.99000000", "0.00000000"], ["111227.83000000", "0.01410000"]]}}
{"type": "orderbook", "local_time": 1761342339637, "event_time": 1761342339714, "latency_ms": -77, "data": {"e": "depthUpdate", "E": 1761342339714, "s": "BTCUSDT", "U": 79012685825, "u": 79012685837, "b": [["111027.22000000", "3.76625000"], ["110997.75000000", "0.84681000"], ["110786.75000000", "0.84842000"], ["103358.00000000", "0.00000000"]], "a": [["111027.23000000", "0.43084000"], ["111031.26000000", "0.81635000"], ["111031.95000000", "0.21470000"], ["111034.82000000", "0.20282000"], ["111060.96000000", "0.96630000"], ["111269.74000000", "4.66498000"]]}}
{"type": "orderbook", "local_time": 1761342339734, "event_time": 1761342339814, "latency_ms": -80, "data": {"e": "depthUpdate", "E": 1761342339814, "s": "BTCUSDT", "U": 79012685838, "u": 79012685840, "b": [["111027.22000000", "3.76537000"]], "a": [["111042.80000000", "0.00000000"], ["111042.83000000", "0.01801000"]]}}
{"type": "orderbook", "local_time": 1761342339835, "event_time": 1761342339914, "latency_ms": -79, "data": {"e": "depthUpdate", "E": 1761342339914, "s": "BTCUSDT", "U": 79012685841, "u": 79012685844, "b": [["111027.22000000", "3.76447000"], ["99924.00000000", "0.00010000"]], "a": [["111027.23000000", "0.43079000"]]}}
{"type": "orderbook", "local_time": 1761342339937, "event_time": 1761342340014, "latency_ms": -77, "data": {"e": "depthUpdate", "E": 1761342340014, "s": "BTCUSDT", "U": 79012685845, "u": 79012685848, "b": [], "a": [["111042.83000000", "0.00000000"], ["111042.84000000", "0.00000000"], ["111042.85000000", "0.01801000"]]}}
{"type": "orderbook", "local_time": 1761342340034, "event_time": 1761342340114, "latency_ms": -80, "data": {"e": "depthUpdate", "E": 1761342340114, "s": "BTCUSDT", "U": 79012685849, "u": 79012685873, "b": [["111027.22000000", "3.76432000"], ["111027.21000000", "0.00000000"], ["110950.33000000", "0.13519000"], ["110930.79000000", "0.00000000"], ["99924.00000000", "0.00010000"]], "a": [["111027.23000000", "0.43723000"], ["111027.24000000", "0.04593000"], ["111029.93000000", "0.00020000"], ["111031.95000000", "0.00005000"], ["111048.93000000", "0.00000000"], ["111060.36000000", "0.00000000"], ["111079.60000000", "0.32409000"], ["111088.55000000", "0.07661000"], ["111096.65000000", "0.00000000"], ["111207.73000000", "0.00000000"]]}}
{"type": "orderbook", "local_time": 1761342340134, "event_time": 1761342340214, "latency_ms": -80, "data": {"e": "depthUpdate", "E": 1761342340214, "s": "BTCUSDT", "U": 79012685874, "u": 79012685914, "b": [], "a": [["111027.23000000", "0.43390000"], ["111027.24000000", "0.04603000"], ["111029.70000000", "0.04730000"], ["111029.92000000", "0.00000000"], ["111029.93000000", "0.00010000"], ["111031.26000000", "0.81640000"], ["111031.95000000", "0.00000000"], ["111031.97000000", "0.21465000"], ["111034.65000000", "0.00039000"], ["111034.82000000", "0.20287000"], ["111035.88000000", "0.07666000"], ["111039.34000000", "0.00324000"], ["111041.26000000", "0.00000000"], ["111041.27000000", "0.00000000"], ["111042.85000000", "0.00000000"], ["111042.86000000", "0.01801000"], ["111045.00000000", "0.00016000"], ["111096.65000000", "0.00048000"], ["111207.73000000", "0.00019000"]]}}
{"type": "orderbook", "local_time": 1761342340236, "event_time": 1761342340314, "latency_ms": -78, "data": {"e": "depthUpdate", "E": 1761342340314, "s": "BTCUSDT", "U": 79012685915, "u": 79012685930, "b": [["110916.00000000", "0.11668000"], ["110880.00000000", "0.01984000"], ["99924.00000000", "0.00020000"]], "a": [["111027.23000000", "0.43395000"], ["111027.24000000", "0.04608000"], ["111031.26000000", "0.81640000"], ["111031.96000000", "0.00005000"], ["111031.97000000", "0.21470000"], ["111035.88000000", "0.07661000"], ["111041.29000000", "0.02703000"], ["111042.86000000", "0.00000000"], ["111042.87000000", "0.01801000"]]}}
{"type": "orderbook", "local_time": 1761342340345, "event_time": 1761342340414, "latency_ms": -69, "data": {"e": "depthUpdate", "E": 1761342340414, "s": "BTCUSDT", "U": 79012685931, "u": 79012685942, "b": [["111027.22000000", "3.76528000"], ["110994.87000000", "0.05331000"], ["110720.62000000", "0.00470000"], ["110689.47000000", "0.00000000"], ["99924.00000000", "0.00030000"]], "a": [["111029.93000000", "0.41223000"], ["111040.56000000", "0.00000000"]]}}
{"type": "orderbook", "local_time": 1761342340458, "event_time": 1761342340514, "latency_ms": -56, "data": {"e": "depthUpdate", "E": 1761342340514, "s": "BTCUSDT", "U": 79012685943, "u": 79012685975, "b": [["111018.61000000", "0.30389000"], ["111012.01000000", "0.00000000"], ["110711.75000000", "0.00572000"], ["110706.75000000", "0.00000000"], ["110531.27000000", "0.02699000"], ["110529.19000000", "0.00000000"], ["99924.00000000", "0.00010000"]], "a": [["111027.23000000", "0.43400000"], ["111029.70000000", "0.04730000"], ["111029.92000000", "0.00010000"], ["111029.93000000", "0.00020000"], ["111031.26000000", "0.81635000"], ["111031.96000000", "0.00000000"], ["111034.65000000", "0.00034000"], ["111034.82000000", "0.20282000"], ["111042.72000000", "0.00000000"], ["111046.77000000", "0.04912000"], ["111119.46000000", "0.00000000"], ["111120.41000000", "0.03400000"], ["111123.00000000", "0.00050000"], ["111123.13000000", "0.00000000"], ["111123.14000000", "0.00000000"], ["111123.61000000", "0.00100000"], ["111123.62000000", "0.00100000"], ["111123.95000000", "0.02500000"]]}}
{"type": "orderbook", "local_time": 1761342340534, "event_time": 1761342340614, "latency_ms": -80, "data": {"e": "depthUpdate", "E": 1761342340614, "s": "BTCUSDT", "U": 79012685976, "u": 79012685998, "b": [["111027.22000000", "4.47028000"], ["111011.24000000", "0.00044000"], ["110964.88000000", "0.06667000"], ["110558.59000000", "0.03798000"], ["110557.32000000", "0.03798000"]], "a": [["111027.23000000", "0.43395000"], ["111029.70000000", "0.04730000"], ["111029.92000000", "0.00000000"], ["111029.93000000", "0.41220000"], ["111031.26000000", "0.81640000"], ["111031.96000000", "0.00005000"], ["111034.82000000", "0.20287000"], ["111044.68000000", "0.04912000"], ["111046.77000000", "0.00000000"]]}}
{"type": "orderbook", "local_time": 1761342340691, "event_time": 1761342340714, "latency_ms": -23, "data": {"e": "depthUpdate", "E": 1761342340714, "s": "BTCUSDT", "U": 79012685999, "u": 79012686025, "b": [["111027.22000000", "3.80125000"], ["106593.62000000", "0.00000000"], ["99924.00000000", "0.00010000"]], "a": [["111027.23000000", "0.43566000"], ["111029.70000000", "0.04730000"], ["111029.92000000", "0.00010000"], ["111029.93000000", "0.41230000"], ["111031.26000000", "0.81635000"], ["111031.96000000", "0.00000000"], ["111034.82000000", "0.20282000"], ["111039.34000000", "0.00000000"], ["111042.56000000", "0.04912000"], ["111044.68000000", "0.00000000"]]}}
{"type": "orderbook", "local_time": 1761342340736, "event_time": 1761342340814, "latency_ms": -78, "data": {"e": "depthUpdate", "E": 1761342340814, "s": "BTCUSDT", "U": 79012686026, "u": 79012686038, "b": [["111027.22000000", "3.80119000"], ["110999.90000000", "0.00000000"], ["110892.67000000", "0.00119000"], ["110881.57000000", "0.00229000"], ["110684.76000000", "0.02431000"], ["110658.58000000", "0.00000000"], ["108774.98000000", "0.00000000"], ["42000.00000000", "1.36734000"], ["23000.00000000", "11.13548000"]], "a": [["111027.23000000", "0.42922000"], ["111027.24000000", "0.05150000"], ["111064.39000000", "0.00114000"], ["118224.69000000", "0.00000000"]]}}
{"type": "orderbook", "local_time": 1761342340835, "event_time": 1761342340914, "latency_ms": -79, "data": {"e": "depthUpdate", "E": 1761342340914, "s": "BTCUSDT", "U": 79012686039, "u": 79012686044, "b": [["110686.95000000", "0.03698000"], ["110663.86000000", "0.00000000"], ["108806.67000000", "0.00459000"]], "a": [["111075.49000000", "0.00229000"], ["111368.93000000", "0.48717000"], ["111372.57000000", "0.00000000"]]}}
{"type": "orderbook", "local_time": 1761342340940, "event_time": 1761342341014, "latency_ms": -74, "data": {"e": "depthUpdate", "E": 1761342341014, "s": "BTCUSDT", "U": 79012686045, "u": 79012686046, "b": [["88822.00000000", "0.00337000"]], "a": []}}
{"type": "orderbook", "local_time": 1761342341035, "event_time": 1761342341114, "latency_ms": -79, "data": {"e": "depthUpdate", "E": 1761342341114, "s": "BTCUSDT", "U": 79012686047, "u": 79012686048, "b": [["99924.00000000", "0.00010000"]], "a": []}}
{"type": "orderbook", "local_time": 1761342341135, "event_time": 1761342341214, "latency_ms": -79, "data": {"e": "depthUpdate", "E": 1761342341214, "s": "BTCUSDT", "U": 79012686049, "u": 79012686053, "b": [["99924.00000000", "0.00010000"], ["60000.00000000", "56.85876000"], ["33000.00000000", "3.79445000"]], "a": []}}
{"type": "orderbook", "local_time": 1761342341235, "event_time": 1761342341314, "latency_ms": -79, "data": {"e": "depthUpdate", "E": 1761342341314, "s": "BTCUSDT", "U": 79012686054, "u": 79012686056, "b": [["111027.22000000", "3.80109000"], ["99924.00000000", "0.00010000"]], "a": []}}
{"type": "orderbook", "local_time": 1761342341335, "event_time": 1761342341414, "latency_ms": -79, "data": {"e": "depthUpdate", "E": 1761342341414, "s": "BTCUSDT", "U": 79012686057, "u": 79012686058, "b": [], "a": [["111040.50000000", "0.04912000"], ["111042.56000000", "0.00000000"]]}}
{"type": "orderbook", "local_time": 1761342341438, "event_time": 1761342341514, "latency_ms": -76, "data": {"e": "depthUpdate", "E": 1761342341514, "s": "BTCUSDT", "U": 79012686059, "u": 79012686063, "b": [["111027.22000000", "3.80109000"]], "a": [["111027.23000000", "0.43573000"], ["111027.24000000", "0.04608000"]]}}
{"type": "orderbook", "local_time": 1761342341543, "event_time": 1761342341614, "latency_ms": -71, "data": {"e": "depthUpdate", "E": 1761342341614, "s": "BTCUSDT", "U": 79012686064, "u": 79012686065, "b": [["110549.44000000", "0.03798000"], ["110529.93000000", "0.00000000"]], "a": []}}
{"type": "orderbook", "local_time": 1761342341640, "event_time": 1761342341714, "latency_ms": -74, "data": {"e": "depthUpdate", "E": 1761342341714, "s": "BTCUSDT", "U": 79012686066, "u": 79012686073, "b": [["111027.22000000", "3.80101000"], ["110825.28000000", "0.02161000"], ["110816.74000000", "0.00000000"], ["110674.36000000", "0.01711000"], ["110642.27000000", "0.00000000"], ["60000.00000000", "56.85866000"]], "a": [["111027.23000000", "0.42898000"], ["111027.24000000", "0.05103000"]]}}
{"type": "orderbook", "local_time": 1761342341735, "event_time": 1761342341814, "latency_ms": -79, "data": {"e": "depthUpdate", "E": 1761342341814, "s": "BTCUSDT", "U": 79012686074, "u": 79012686076, "b": [], "a": [["111027.23000000", "0.43571000"], ["111027.24000000", "0.04608000"]]}}
{"type": "orderbook", "local_time": 1761342341835, "event_time": 1761342341914, "latency_ms": -79, "data": {"e": "depthUpdate", "E": 1761342341914, "s": "BTCUSDT", "U": 79012686077, "u": 79012686082, "b": [["111027.22000000", "3.80100000"], ["99924.00000000", "0.00010000"]], "a": []}}
{"type": "orderbook", "local_time": 1761342341935, "event_time": 1761342342014, "latency_ms": -79, "data": {"e": "depthUpdate", "E": 1761342342014, "s": "BTCUSDT", "U": 79012686083, "u": 79012686085, "b": [["111027.22000000", "3.80655000"]], "a": [["111035.96000000", "0.00000000"], ["111052.47000000", "0.00000000"]]}}
{"type": "orderbook", "local_time": 1761342342035, "event_time": 1761342342114, "latency_ms": -79, "data": {"e": "depthUpdate", "E": 1761342342114, "s": "BTCUSDT", "U": 79012686086, "u": 79012686089, "b": [["111027.22000000", "3.77053000"], ["110720.98000000", "0.00000000"], ["110711.56000000", "0.02498000"]], "a": [["111027.23000000", "0.43243000"]]}}
{"type": "orderbook", "local_time": 1761342342138, "event_time": 1761342342214, "latency_ms": -76, "data": {"e": "depthUpdate", "E": 1761342342214, "s": "BTCUSDT", "U": 79012686090, "u": 79012686092, "b": [["110626.69000000", "0.02431000"], ["110621.93000000", "0.00000000"]], "a": [["111027.23000000", "0.43571000"]]}}
{"type": "orderbook", "local_time": 1761342342236, "event_time": 1761342342315, "latency_ms": -79, "data": {"e": "depthUpdate", "E": 1761342342315, "s": "BTCUSDT", "U": 79012686093, "u": 79012686096, "b": [["111027.22000000", "3.76603000"], ["110881.51000000", "0.00360000"], ["110853.54000000", "0.00000000"], ["99924.00000000", "0.00010000"]], "a": []}}
{"type": "orderbook", "local_time": 1761342342335, "event_time": 1761342342414, "latency_ms": -79, "data": {"e": "depthUpdate", "E": 1761342342414, "s": "BTCUSDT", "U": 79012686097, "u": 79012686100, "b": [["111027.22000000", "3.80205000"], ["99924.00000000", "0.00010000"]], "a": [["111027.23000000", "0.43346000"]]}}
{"type": "orderbook", "local_time": 1761342342436, "event_time": 1761342342514, "latency_ms": -78, "data": {"e": "depthUpdate", "E": 1761342342514, "s": "BTCUSDT", "U": 79012686101, "u": 79012686103, "b": [["110707.73000000", "0.01711000"], ["110701.92000000", "0.00000000"]], "a": [["111027.23000000", "0.43342000"]]}}
{"type": "orderbook", "local_time": 1761342342545, "event_time": 1761342342614, "latency_ms": -69, "data": {"e": "depthUpdate", "E": 1761342342614, "s": "BTCUSDT", "U": 79012686104, "u": 79012686105, "b": [], "a": [["111368.93000000", "0.48717000"]]}}
{"type": "orderbook", "local_time": 1761342342634, "event_time": 1761342342714, "latency_ms": -80, "data": {"e": "depthUpdate", "E": 1761342342714, "s": "BTCUSDT", "U": 79012686106, "u": 79012686108, "b": [["111027.22000000", "3.79663000"]], "a": [["111027.23000000", "0.42664000"], ["111027.24000000", "0.05222000"]]}}
{"type": "orderbook", "local_time": 1761342342735, "event_time": 1761342342814, "latency_ms": -79, "data": {"e": "depthUpdate", "E": 1761342342814, "s": "BTCUSDT", "U": 79012686109, "u": 79012686110, "b": [["99924.00000000", "0.00010000"]], "a": []}}
{"type": "orderbook", "local_time": 1761342342842, "event_time": 1761342342914, "latency_ms": -72, "data": {"e": "depthUpdate", "E": 1761342342914, "s": "BTCUSDT", "U": 79012686111, "u": 79012686117, "b": [["111027.22000000", "3.83088000"], ["99924.00000000", "0.00010000"]], "a": [["111028.20000000", "0.05059000"]]}}
{"type": "orderbook", "local_time": 1761342342938, "event_time": 1761342343015, "latency_ms": -77, "data": {"e": "depthUpdate", "E": 1761342343015, "s": "BTCUSDT", "U": 79012686118, "u": 79012686138, "b": [["110964.88000000", "0.06623000"]], "a": [["111027.23000000", "0.43162000"], ["111027.24000000", "0.04608000"], ["111028.19000000", "0.00010000"], ["111028.20000000", "0.05069000"], ["111029.94000000", "0.29722000"], ["111031.25000000", "0.00000000"], ["111034.66000000", "0.09662000"]]}}
{"type": "orderbook", "local_time": 1761342343038, "event_time": 1761342343114, "latency_ms": -76, "data": {"e": "depthUpdate", "E": 1761342343114, "s": "BTCUSDT", "U": 79012686139, "u": 79012686141, "b": [["111027.22000000", "3.79486000"], ["111011.24000000", "0.00000000"], ["102145.04000000", "0.00010000"]], "a": []}}
{"type": "orderbook", "local_time": 1761342343136, "event_time": 1761342343214, "latency_ms": -78, "data": {"e": "depthUpdate", "E": 1761342343214, "s": "BTCUSDT", "U": 79012686142, "u": 79012686143, "b": [["99924.00000000", "0.00010000"]], "a": []}}
{"type": "orderbook", "local_time": 1761342343236, "event_time": 1761342343314, "latency_ms": -78, "data": {"e": "depthUpdate", "E": 1761342343314, "s": "BTCUSDT", "U": 79012686144, "u": 79012686148, "b": [], "a": [["111029.93000000", "0.00020000"], ["111036.40000000", "0.00250000"], ["111041.11000000", "0.00000000"], ["111058.65000000", "0.00000000"]]}}
{"type": "orderbook", "local_time": 1761342343335, "event_time": 1761342343414, "latency_ms": -79, "data": {"e": "depthUpdate", "E": 1761342343414, "s": "BTCUSDT", "U": 79012686149, "u": 79012686171, "b": [["111027.22000000", "3.74448000"]], "a": [["111027.23000000", "0.43162000"], ["111029.70000000", "0.04730000"], ["111029.92000000", "0.00000000"], ["111029.93000000", "0.41215000"], ["111029.94000000", "0.29727000"], ["111031.25000000", "0.00005000"], ["111034.66000000", "0.09667000"], ["111035.26000000", "0.04508000"], ["111037.85000000", "0.04912000"], ["111040.50000000", "0.00000000"]]}}
{"type": "orderbook", "local_time": 1761342343446, "event_time": 1761342343514, "latency_ms": -68, "data": {"e": "depthUpdate", "E": 1761342343514, "s": "BTCUSDT", "U": 79012686172, "u": 79012686218, "b": [["111027.22000000", "3.55502000"], ["111025.82000000", "0.00015000"], ["111024.46000000", "0.18009000"], ["111021.31000000", "0.00005000"], ["111018.61000000", "0.00000000"], ["111016.13000000", "0.30389000"], ["110880.01000000", "0.00000000"], ["110769.59000000", "0.00000000"], ["99924.00000000", "0.00010000"], ["99840.64000000", "0.00000000"]], "a": [["111027.23000000", "1.70829000"], ["111027.24000000", "0.04598000"], ["111029.70000000", "0.04730000"], ["111029.92000000", "0.00010000"], ["111029.93000000", "0.41225000"], ["111029.94000000", "0.29722000"], ["111031.25000000", "0.00000000"], ["111034.66000000", "0.09662000"], ["111039.28000000", "0.00000000"], ["111040.73000000", "0.00000000"], ["111054.10000000", "0.00000000"], ["111054.37000000", "0.00000000"], ["111091.27000000", "0.00000000"], ["111091.81000000", "0.13524000"], ["111118.16000000", "0.22557000"], ["111118.36000000", "0.00000000"], ["111118.52000000", "0.22544000"], ["111120.99000000", "0.00000000"]]}}
{"type": "orderbook", "local_time": 1761342343537, "event_time": 1761342343614, "latency_ms": -77, "data": {"e": "depthUpdate", "E": 1761342343614, "s": "BTCUSDT", "U": 79012686219, "u": 79012686252, "b": [["111027.22000000", "3.55435000"], ["111026.04000000", "0.29738000"], ["111025.83000000", "0.00000000"], ["111025.82000000", "0.00000000"], ["111025.24000000", "0.03459000"], ["111024.47000000", "0.00010000"], ["111024.46000000", "0.18019000"], ["111022.07000000", "0.04577000"], ["111021.31000000", "0.00000000"], ["111020.56000000", "0.01891000"], ["110880.01000000", "0.00224000"], ["110769.59000000", "0.00090000"], ["102145.04000000", "0.00000000"], ["99924.50000000", "0.00012000"]], "a": [["111067.20000000", "0.22535000"], ["111118.16000000", "0.00022000"], ["111118.23000000", "0.22544000"], ["111118.52000000", "0.00000000"]]}}
{"type": "orderbook", "local_time": 1761342343637, "event_time": 1761342343714, "latency_ms": -77, "data": {"e": "depthUpdate", "E": 1761342343714, "s": "BTCUSDT", "U": 79012686253, "u": 79012686261, "b": [["111027.22000000", "3.56416000"], ["109599.87000000", "0.02501000"]], "a": [["111027.23000000", "1.72555000"], ["111067.19000000", "0.28518000"], ["111067.20000000", "0.00000000"], ["111068.91000000", "0.00000000"], ["111118.07000000", "0.22535000"]]}}
{"type": "orderbook", "local_time": 1761342343785, "event_time": 1761342343814, "latency_ms": -29, "data": {"e": "depthUpdate", "E": 1761342343814, "s": "BTCUSDT", "U": 79012686262, "u": 79012686271, "b": [["111027.22000000", "3.56398000"], ["110928.57000000", "0.01410000"], ["110898.11000000", "0.00000000"], ["99924.00000000", "0.00010000"]], "a": [["111027.23000000", "1.72542000"], ["111049.01000000", "0.04988000"]]}}
{"type": "orderbook", "local_time": 1761342343845, "event_time": 1761342343914, "latency_ms": -69, "data": {"e": "depthUpdate", "E": 1761342343914, "s": "BTCUSDT", "U": 79012686272, "u": 79012686273, "b": [["110928.57000000", "0.00000000"], ["110898.11000000", "0.01410000"]], "a": []}}
{"type": "orderbook", "local_time": 1761342343937, "event_time": 1761342344014, "latency_ms": -77, "data": {"e": "depthUpdate", "E": 1761342344014, "s": "BTCUSDT", "U": 79012686274, "u": 79012686276, "b": [["111027.22000000", "3.56595000"], ["88822.00000000", "0.00337000"]], "a": []}}
{"type": "orderbook", "local_time": 1761342344037, "event_time": 1761342344115, "latency_ms": -78, "data": {"e": "depthUpdate", "E": 1761342344115, "s": "BTCUSDT", "U": 79012686277, "u": 79012686278, "b": [["110898.11000000", "0.00000000"]], "a": [["111049.01000000", "0.00000000"]]}}
{"type": "orderbook", "local_time": 1761342344138, "event_time": 1761342344214, "latency_ms": -76, "data": {"e": "depthUpdate", "E": 1761342344214, "s": "BTCUSDT", "U": 79012686279, "u": 79012686285, "b": [["99924.00000000", "0.00010000"]], "a": [["111027.23000000", "1.71999000"], ["111123.61000000", "0.00000000"], ["111123.62000000", "0.00000000"], ["111123.65000000", "0.00100000"], ["111123.66000000", "0.00100000"]]}}
{"type": "orderbook", "local_time": 1761342344239, "event_time": 1761342344314, "latency_ms": -75, "data": {"e": "depthUpdate", "E": 1761342344314, "s": "BTCUSDT", "U": 79012686286, "u": 79012686288, "b": [], "a": [["111028.20000000", "0.00010000"], ["111031.25000000", "0.20282000"], ["111049.01000000", "0.04616000"]]}}
{"type": "orderbook", "local_time": 1761342344342, "event_time": 1761342344414, "latency_ms": -72, "data": {"e": "depthUpdate", "E": 1761342344414, "s": "BTCUSDT", "U": 79012686289, "u": 79012686347, "b": [["111027.22000000", "3.74604000"], ["111026.04000000", "0.34635000"], ["111024.46000000", "0.00010000"], ["111023.47000000", "0.00005000"], ["111023.25000000", "0.00720000"], ["111011.51000000", "0.00000000"], ["111011.18000000", "0.01801000"], ["111009.68000000", "0.00000000"]], "a": [["111027.23000000", "0.42117000"], ["111027.24000000", "0.06687000"], ["111028.19000000", "0.00000000"], ["111028.20000000", "0.00000000"], ["111029.94000000", "0.29727000"], ["111031.24000000", "0.00005000"], ["111031.25000000", "0.00005000"], ["111031.71000000", "0.04980000"], ["111031.97000000", "0.00005000"], ["111036.40000000", "0.00250000"], ["111037.85000000", "0.00000000"], ["111038.91000000", "0.04912000"], ["111041.21000000", "0.00000000"], ["111042.87000000", "0.00000000"], ["111043.14000000", "0.01801000"], ["111045.39000000", "0.00000000"], ["111045.75000000", "0.13524000"], ["111058.00000000", "0.22695000"], ["111058.65000000", "0.00000000"], ["111058.70000000", "0.22544000"], ["111063.10000000", "0.00000000"], ["111107.73000000", "0.00000000"], ["111368.93000000", "0.48717000"]]}}
{"type": "orderbook", "local_time": 1761342344437, "event_time": 1761342344514, "latency_ms": -77, "data": {"e": "depthUpdate", "E": 1761342344514, "s": "BTCUSDT", "U": 79012686348, "u": 79012686394, "b": [["111027.22000000", "3.69814000"], ["111026.04000000", "0.29738000"], ["111025.24000000", "0.03459000"], ["111024.47000000", "0.00000000"], ["111024.46000000", "0.00000000"], ["111024.25000000", "0.00010000"], ["111024.24000000", "0.04010000"], ["111023.47000000", "0.00005000"], ["111023.46000000", "0.20750000"], ["111023.25000000", "0.00725000"], ["111019.71000000", "0.16713000"]], "a": [["111027.23000000", "0.42117000"], ["111027.24000000", "0.06687000"], ["111029.94000000", "0.29727000"], ["111031.24000000", "0.00000000"], ["111031.25000000", "0.00005000"], ["111031.26000000", "0.81635000"], ["111031.71000000", "0.04985000"], ["111031.97000000", "0.00000000"], ["111034.66000000", "0.09667000"], ["111036.09000000", "0.04912000"], ["111038.91000000", "0.00000000"], ["111049.01000000", "0.00000000"], ["111119.46000000", "0.03400000"], ["111120.41000000", "0.00000000"]]}}
{"type": "orderbook", "local_time": 1761342344539, "event_time": 1761342344614, "latency_ms": -75, "data": {"e": "depthUpdate", "E": 1761342344614, "s": "BTCUSDT", "U": 79012686395, "u": 79012686400, "b": [["111025.06000000", "0.04790000"], ["99924.00000000", "0.00010000"]], "a": [["111027.23000000", "0.42122000"], ["111027.24000000", "0.06692000"], ["111029.22000000", "0.20745000"]]}}
{"type": "orderbook", "local_time": 1761342344726, "event_time": 1761342344714, "latency_ms": 12, "data": {"e": "depthUpdate", "E": 1761342344714, "s": "BTCUSDT", "U": 79012686401, "u": 79012686807, "b": [["111028.02000000", "2.22962000"], ["111028.01000000", "1.74721000"], ["111028.00000000", "2.47737000"], ["111027.99000000", "0.00000000"], ["111027.96000000", "0.00000000"], ["111027.23000000", "0.00010000"], ["111027.22000000", "0.37192000"], ["111026.11000000", "0.00109000"], ["111026.06000000", "0.00000000"], ["111026.05000000", "0.00015000"], ["111026.04000000", "0.00010000"], ["111025.25000000", "0.00000000"], ["111025.24000000", "0.03454000"], ["111025.07000000", "0.00000000"], ["111025.06000000", "0.00005000"], ["111024.25000000", "0.00000000"], ["111024.24000000", "0.04005000"], ["111023.60000000", "0.06748000"], ["111023.47000000", "0.00000000"], ["111020.56000000", "0.01886000"], ["111019.71000000", "0.16708000"], ["111019.70000000", "0.00000000"], ["111011.37000000", "0.00150000"], ["111007.49000000", "0.00000000"], ["111005.02000000", "0.00000000"], ["110998.31000000", "0.00000000"], ["110986.73000000", "0.20230000"], ["110985.93000000", "0.00000000"], ["110978.06000000", "0.00090000"], ["110971.73000000", "0.00000000"], ["110964.77000000", "0.00000000"], ["110847.72000000", "0.00000000"], ["110790.01000000", "0.00076000"], ["110789.11000000", "0.00000000"], ["99924.00000000", "0.00010000"]], "a": [["111027.23000000", "0.00000000"], ["111027.24000000", "0.00000000"], ["111028.00000000", "0.00000000"], ["111028.03000000", "0.04617000"], ["111028.04000000", "0.00140000"], ["111028.50000000", "0.00000000"], ["111028.95000000", "0.00000000"], ["111029.21000000", "0.31214000"], ["111029.22000000", "0.00020000"], ["111029.69000000", "0.00053000"], ["111029.70000000", "0.04735000"], ["111029.94000000", "0.29727000"], ["111031.25000000", "0.00005000"], ["111031.26000000", "0.81635000"], ["111034.66000000", "0.09667000"], ["111034.82000000", "0.20282000"], ["111036.09000000", "0.00000000"], ["111038.42000000", "0.00000000"], ["111039.47000000", "0.00000000"], ["111039.98000000", "0.00069000"], ["111041.05000000", "0.20912000"], ["111044.68000000", "0.00090000"], ["111082.50000000", "0.00000000"], ["111083.56000000", "0.00224000"], ["111109.99000000", "0.00000000"], ["111110.99000000", "0.00224000"]]}}
{"type": "orderbook", "local_time": 1761342344771, "event_time": 1761342344814, "latency_ms": -43, "data": {"e": "depthUpdate", "E": 1761342344814, "s": "BTCUSDT", "U": 79012686808, "u": 79012686909, "b": [["111028.02000000", "2.31456000"], ["111028.01000000", "0.80960000"], ["111028.00000000", "2.47747000"], ["111027.23000000", "0.00000000"], ["111027.22000000", "0.36298000"], ["111026.11000000", "0.00104000"], ["111026.05000000", "0.00000000"], ["111026.04000000", "0.04889000"], ["111025.24000000", "0.03454000"], ["111025.06000000", "0.00000000"], ["111024.24000000", "0.04005000"], ["111022.08000000", "0.05369000"], ["111019.71000000", "0.00000000"], ["110997.76000000", "0.10409000"], ["110997.75000000", "0.00000000"], ["110840.58000000", "0.01410000"], ["110836.12000000", "0.00000000"]], "a": [["111028.03000000", "0.37577000"], ["111028.04000000", "0.00140000"], ["111028.95000000", "0.01350000"], ["111029.20000000", "0.00010000"], ["111029.21000000", "0.00020000"], ["111029.22000000", "0.00000000"], ["111029.69000000", "0.00048000"], ["111029.70000000", "0.04730000"], ["111029.80000000", "0.21465000"], ["111041.29000000", "0.00000000"], ["111041.49000000", "0.00000000"], ["111041.55000000", "0.02703000"], ["111060.96000000", "0.00000000"]]}}
{"type": "orderbook", "local_time": 1761342344841, "event_time": 1761342344915, "latency_ms": -74, "data": {"e": "depthUpdate", "E": 1761342344915, "s": "BTCUSDT", "U": 79012686910, "u": 79012686970, "b": [["111028.02000000", "2.39005000"], ["111027.23000000", "0.00010000"], ["111027.22000000", "0.32298000"], ["111026.11000000", "0.00104000"], ["111026.04000000", "0.04894000"], ["111025.24000000", "0.03449000"], ["111023.25000000", "0.00720000"], ["111022.07000000", "0.04572000"], ["111005.03000000", "0.06494000"]], "a": [["111028.03000000", "0.41767000"], ["111028.04000000", "0.00145000"], ["111028.94000000", "0.00010000"], ["111028.95000000", "0.01370000"], ["111029.20000000", "0.00000000"], ["111029.21000000", "0.00000000"], ["111029.70000000", "0.04730000"], ["111029.79000000", "0.00010000"], ["111029.80000000", "0.21475000"], ["111029.94000000", "0.29722000"], ["111031.25000000", "0.00000000"], ["111034.66000000", "0.09662000"], ["111040.05000000", "0.00000000"]]}}
{"type": "orderbook", "local_time": 1761342344936, "event_time": 1761342345014, "latency_ms": -78, "data": {"e": "depthUpdate", "E": 1761342345014, "s": "BTCUSDT", "U": 79012686971, "u": 79012687012, "b": [["111028.02000000", "2.20903000"], ["111028.01000000", "0.80975000"], ["111026.04000000", "0.04899000"], ["111024.25000000", "0.18009000"], ["111023.60000000", "0.00005000"], ["111023.25000000", "0.00725000"], ["111016.13000000", "0.00000000"], ["111015.31000000", "0.00010000"], ["111013.35000000", "0.30390000"], ["110997.80000000", "0.84681000"], ["110880.01000000", "0.00000000"], ["110769.59000000", "0.00000000"]], "a": [["111028.03000000", "1.50647000"], ["111038.63000000", "0.04912000"], ["111041.05000000", "0.16000000"], ["111058.70000000", "0.00000000"], ["111060.82000000", "0.00000000"], ["111062.82000000", "0.95294000"], ["111091.81000000", "0.00000000"], ["111118.07000000", "0.00000000"], ["111118.09000000", "0.00000000"], ["111118.17000000", "0.00000000"], ["111118.23000000", "0.00000000"], ["111120.03000000", "0.18027000"]]}}
{"type": "orderbook", "local_time": 1761342345040, "event_time": 1761342345114, "latency_ms": -74, "data": {"e": "depthUpdate", "E": 1761342345114, "s": "BTCUSDT", "U": 79012687013, "u": 79012687036, "b": [["111027.22000000", "0.04709000"], ["111025.24000000", "0.03449000"], ["111024.25000000", "0.18014000"], ["111024.24000000", "0.04005000"], ["111023.60000000", "0.00000000"], ["111015.31000000", "0.00000000"], ["110945.17000000", "0.00000000"], ["110932.72000000", "0.03218000"], ["110881.58000000", "0.00225000"], ["110770.22000000", "0.00090000"]], "a": [["111028.03000000", "1.50716000"], ["111031.71000000", "0.05038000"], ["111039.98000000", "0.00000000"], ["111090.22000000", "0.09952000"], ["111118.71000000", "0.13511000"], ["111118.94000000", "0.00000000"], ["111118.95000000", "0.22544000"]]}}
{"type": "orderbook", "local_time": 1761342345134, "event_time": 1761342345214, "latency_ms": -80, "data": {"e": "depthUpdate", "E": 1761342345214, "s": "BTCUSDT", "U": 79012687037, "u": 79012687053, "b": [["111028.02000000", "2.20908000"], ["111028.01000000", "0.80980000"], ["111027.23000000", "0.00000000"], ["111015.31000000", "0.00010000"], ["110956.92000000", "0.00000000"]], "a": [["111028.03000000", "1.65303000"], ["111039.30000000", "0.00000000"], ["111039.41000000", "0.00000000"], ["111045.75000000", "0.00000000"], ["111108.64000000", "0.13613000"], ["111118.95000000", "0.00000000"], ["111119.22000000", "0.22615000"]]}}
{"type": "orderbook", "local_time": 1761342345240, "event_time": 1761342345314, "latency_ms": -74, "data": {"e": "depthUpdate", "E": 1761342345314, "s": "BTCUSDT", "U": 79012687054, "u": 79012687063, "b": [["111028.02000000", "2.20952000"], ["111027.22000000", "0.04665000"], ["99925.00000000", "0.00510000"], ["50000.00000000", "39.95352000"]], "a": [["111058.00000000", "0.00160000"], ["111092.18000000", "0.13524000"], ["111118.98000000", "0.22535000"]]}}
{"type": "orderbook", "local_time": 1761342345335, "event_time": 1761342345414, "latency_ms": -79, "data": {"e": "depthUpdate", "E": 1761342345414, "s": "BTCUSDT", "U": 79012687064, "u": 79012687076, "b": [["111028.02000000", "2.10115000"], ["110008.28000000", "0.00251000"], ["99925.00000000", "0.00520000"], ["99924.00000000", "0.00000000"], ["50000.00000000", "39.95322000"]], "a": [["111123.00000000", "0.02550000"], ["111123.95000000", "0.00000000"], ["112051.27000000", "0.00247000"]]}}
{"type": "orderbook", "local_time": 1761342345438, "event_time": 1761342345514, "latency_ms": -76, "data": {"e": "depthUpdate", "E": 1761342345514, "s": "BTCUSDT", "U": 79012687077, "u": 79012687119, "b": [["111028.02000000", "2.32015000"], ["111026.04000000", "0.00010000"], ["111024.25000000", "0.00005000"], ["111023.05000000", "0.00000000"], ["111022.49000000", "0.00000000"], ["111020.82000000", "0.01430000"], ["111020.57000000", "0.18009000"], ["111020.56000000", "0.00540000"], ["111020.00000000", "0.00005000"], ["111016.12000000", "0.00000000"], ["111013.36000000", "0.00450000"], ["111013.35000000", "0.00000000"], ["111012.03000000", "0.00000000"], ["111011.71000000", "0.00000000"], ["111011.18000000", "0.00000000"], ["111009.74000000", "0.30391000"], ["111007.58000000", "0.01801000"], ["110996.35000000", "0.00250000"], ["99925.00000000", "0.00510000"], ["50000.00000000", "39.95262000"]], "a": [["111031.25000000", "0.20282000"], ["111031.95000000", "0.00250000"], ["111032.96000000", "0.04912000"], ["111035.56000000", "0.00000000"], ["111038.01000000", "0.06748000"], ["111038.63000000", "0.00000000"], ["111039.21000000", "0.01801000"], ["111043.14000000", "0.00000000"], ["111054.20000000", "0.00000000"], ["111068.01000000", "0.36046000"], ["111118.71000000", "0.00000000"], ["111118.77000000", "0.00000000"], ["111118.98000000", "0.00000000"], ["111119.22000000", "0.00071000"]]}}
{"type": "orderbook", "local_time": 1761342345537, "event_time": 1761342345614, "latency_ms": -77, "data": {"e": "depthUpdate", "E": 1761342345614, "s": "BTCUSDT", "U": 79012687120, "u": 79012687170, "b": [["111028.02000000", "2.32924000"], ["111028.01000000", "0.80975000"], ["111027.22000000", "0.04665000"], ["111026.11000000", "0.00104000"], ["111026.04000000", "0.00000000"], ["111025.96000000", "0.05078000"], ["111025.24000000", "0.03454000"], ["111024.25000000", "0.00000000"], ["111022.08000000", "0.10075000"], ["111022.07000000", "0.04577000"], ["111018.89000000", "0.04790000"], ["111010.97000000", "0.70429000"], ["110996.52000000", "0.00000000"]], "a": [["111028.03000000", "1.65377000"], ["111028.04000000", "0.00150000"], ["111029.94000000", "0.29722000"], ["111031.25000000", "0.20287000"], ["111031.71000000", "0.05038000"], ["111032.96000000", "0.04917000"], ["111033.16000000", "0.04572000"], ["111033.89000000", "0.00540000"], ["111039.11000000", "0.00000000"], ["111046.65000000", "0.05834000"], ["111068.01000000", "0.22535000"], ["111118.83000000", "0.13511000"], ["111119.21000000", "0.22544000"]]}}
{"type": "orderbook", "local_time": 1761342345637, "event_time": 1761342345714, "latency_ms": -77, "data": {"e": "depthUpdate", "E": 1761342345714, "s": "BTCUSDT", "U": 79012687171, "u": 79012687192, "b": [["111028.02000000", "2.32929000"], ["111027.22000000", "0.04665000"], ["111026.11000000", "0.00104000"], ["111025.96000000", "0.00010000"], ["111025.24000000", "0.03449000"], ["111022.07000000", "0.04572000"], ["111000.80000000", "0.00250000"], ["110996.35000000", "0.00000000"], ["99925.00000000", "0.00510000"]], "a": [["111039.21000000", "0.00000000"], ["111039.31000000", "0.01801000"], ["111068.01000000", "0.00000000"], ["111078.51000000", "0.00000000"], ["111118.88000000", "0.22535000"], ["111252.66000000", "0.00000000"]]}}
{"type": "orderbook", "local_time": 1761342345740, "event_time": 1761342345815, "latency_ms": -75, "data": {"e": "depthUpdate", "E": 1761342345815, "s": "BTCUSDT", "U": 79012687193, "u": 79012687212, "b": [["111027.22000000", "0.04665000"], ["111026.11000000", "0.00104000"], ["111025.96000000", "0.00000000"], ["111025.24000000", "0.03454000"], ["111022.07000000", "0.04577000"]], "a": [["111028.03000000", "1.65165000"], ["111039.31000000", "0.00000000"], ["111039.42000000", "0.01801000"], ["111039.96000000", "0.00320000"], ["111040.06000000", "0.00074000"], ["111040.17000000", "0.00069000"], ["111084.48000000", "0.00402000"], ["111258.64000000", "0.00089000"]]}}
{"type": "orderbook", "local_time": 1761342345846, "event_time": 1761342345915, "latency_ms": -69, "data": {"e": "depthUpdate", "E": 1761342345915, "s": "BTCUSDT", "U": 79012687213, "u": 79012687215, "b": [["110528.02000000", "0.00000000"]], "a": [["111036.76000000", "0.00044000"], ["111053.27000000", "0.00044000"]]}}
{"type": "orderbook", "local_time": 1761342345936, "event_time": 1761342346014, "latency_ms": -78, "data": {"e": "depthUpdate", "E": 1761342346014, "s": "BTCUSDT", "U": 79012687216, "u": 79012687228, "b": [["111028.02000000", "2.33827000"], ["111022.50000000", "0.04790000"], ["111018.89000000", "0.00000000"], ["110994.87000000", "0.05423000"]], "a": [["111028.03000000", "1.65192000"], ["111031.95000000", "0.00000000"], ["111039.42000000", "0.00000000"], ["111039.47000000", "0.00000000"], ["111039.52000000", "0.01801000"], ["111054.20000000", "0.00250000"]]}}
{"type": "orderbook", "local_time": 1761342346034, "event_time": 1761342346114, "latency_ms": -80, "data": {"e": "depthUpdate", "E": 1761342346114, "s": "BTCUSDT", "U": 79012687229, "u": 79012687249, "b": [["111028.02000000", "2.33817000"], ["111023.25000000", "0.00725000"], ["111022.50000000", "0.04795000"], ["111022.07000000", "0.04572000"], ["111020.57000000", "0.18017000"], ["111008.51000000", "0.01801000"], ["111007.58000000", "0.00000000"], ["99925.00000000", "0.00510000"], ["33000.00000000", "3.79445000"]], "a": [["111028.03000000", "1.80111000"], ["111028.04000000", "0.00145000"], ["111039.52000000", "0.00000000"], ["111040.14000000", "0.01801000"], ["111068.01000000", "0.00000000"], ["111118.88000000", "0.00000000"]]}}
{"type": "orderbook", "local_time": 1761342346137, "event_time": 1761342346214, "latency_ms": -77, "data": {"e": "depthUpdate", "E": 1761342346214, "s": "BTCUSDT", "U": 79012687250, "u": 79012687253, "b": [], "a": [["111032.96000000", "0.00005000"], ["111040.14000000", "0.00000000"], ["111040.19000000", "0.01801000"], ["111118.82000000", "0.22557000"]]}}
{"type": "orderbook", "local_time": 1761342346235, "event_time": 1761342346314, "latency_ms": -79, "data": {"e": "depthUpdate", "E": 1761342346314, "s": "BTCUSDT", "U": 79012687254, "u": 79012687264, "b": [["111028.02000000", "2.63535000"]], "a": [["111028.03000000", "1.80106000"], ["111028.04000000", "0.00140000"], ["111031.71000000", "0.05038000"], ["111032.96000000", "0.00000000"], ["111033.16000000", "0.04577000"], ["111035.42000000", "0.04912000"], ["111040.19000000", "0.00000000"], ["111040.23000000", "0.01801000"], ["111046.65000000", "0.00000000"]]}}
{"type": "orderbook", "local_time": 1761342346336, "event_time": 1761342346414, "latency_ms": -78, "data": {"e": "depthUpdate", "E": 1761342346414, "s": "BTCUSDT", "U": 79012687265, "u": 79012687271, "b": [["111028.02000000", "2.63422000"]], "a": [["111028.03000000", "1.80111000"], ["111028.04000000", "0.00145000"], ["111040.23000000", "0.00000000"], ["111040.26000000", "0.01801000"], ["111365.28000000", "0.48717000"], ["111368.93000000", "0.00000000"]]}}
{"type": "orderbook", "local_time": 1761342346433, "event_time": 1761342346514, "latency_ms": -81, "data": {"e": "depthUpdate", "E": 1761342346514, "s": "BTCUSDT", "U": 79012687272, "u": 79012687274, "b": [["111015.31000000", "0.30400000"], ["111009.74000000", "0.00000000"]], "a": [["111173.94000000", "0.00000000"], ["111183.04000000", "0.02161000"]]}}
{"type": "orderbook", "local_time": 1761342346542, "event_time": 1761342346614, "latency_ms": -72, "data": {"e": "depthUpdate", "E": 1761342346614, "s": "BTCUSDT", "U": 79012687275, "u": 79012687356, "b": [["111028.02000000", "2.23454000"], ["111028.01000000", "0.85702000"], ["111027.22000000", "0.03736000"], ["111025.09000000", "0.29719000"], ["111024.84000000", "0.04790000"], ["111024.32000000", "0.05097000"], ["111023.25000000", "0.00005000"], ["111022.50000000", "0.00005000"], ["111021.61000000", "0.00720000"], ["111015.31000000", "0.00010000"], ["111013.34000000", "0.00000000"], ["111012.80000000", "0.30390000"], ["111012.03000000", "0.00010000"], ["111009.06000000", "0.00000000"], ["111005.81000000", "0.11267000"], ["110995.66000000", "0.13524000"], ["110994.64000000", "0.00000000"], ["110974.62000000", "0.32435000"], ["110960.00000000", "0.01947000"], ["110949.37000000", "0.00000000"], ["110942.36000000", "0.13524000"], ["110881.59000000", "0.00225000"], ["110881.58000000", "0.00000000"], ["110770.23000000", "0.00090000"], ["110770.22000000", "0.00000000"]], "a": [["111028.03000000", "2.20761000"], ["111029.80000000", "0.00010000"], ["111033.59000000", "0.11267000"], ["111035.26000000", "0.00000000"], ["111039.24000000", "0.00450000"], ["111039.96000000", "0.00250000"], ["111040.00000000", "0.07966000"], ["111040.06000000", "0.00000000"], ["111040.17000000", "0.00000000"], ["111041.03000000", "0.00000000"], ["111046.35000000", "0.00000000"], ["111046.36000000", "0.00000000"], ["111046.65000000", "0.05177000"], ["111060.06000000", "0.32410000"], ["111068.01000000", "0.58590000"], ["111079.60000000", "0.00005000"], ["111093.03000000", "0.13519000"], ["111097.87000000", "0.00000000"], ["111118.82000000", "0.00022000"], ["111118.83000000", "0.00000000"], ["111119.21000000", "0.00000000"], ["111120.03000000", "0.00000000"]]}}
{"type": "orderbook", "local_time": 1761342346636, "event_time": 1761342346714, "latency_ms": -78, "data": {"e": "depthUpdate", "E": 1761342346714, "s": "BTCUSDT", "U": 79012687357, "u": 79012687419, "b": [["111028.02000000", "2.25216000"], ["111028.01000000", "0.85707000"], ["111025.24000000", "0.03449000"], ["111025.10000000", "0.00010000"], ["111025.09000000", "0.29724000"], ["111024.84000000", "0.04795000"], ["111024.32000000", "0.05102000"], ["111023.46000000", "0.20750000"], ["111023.25000000", "0.00000000"], ["111022.50000000", "0.00000000"], ["111022.08000000", "0.10070000"], ["111012.03000000", "0.00000000"], ["110994.76000000", "0.32429000"], ["110974.62000000", "0.00000000"], ["110008.28000000", "0.00000000"]], "a": [["111028.03000000", "2.20894000"], ["111028.04000000", "0.00140000"], ["111028.93000000", "0.20745000"], ["111029.70000000", "0.04730000"], ["111029.79000000", "0.00000000"], ["111029.80000000", "0.00000000"], ["111029.94000000", "0.29727000"], ["111031.24000000", "0.00005000"], ["111033.16000000", "0.04577000"], ["111033.58000000", "0.16715000"], ["111033.59000000", "0.11272000"], ["111034.66000000", "0.00000000"], ["111044.43000000", "0.00044000"], ["111075.88000000", "0.00412000"], ["111084.48000000", "0.00000000"], ["111090.22000000", "0.17106000"], ["111119.46000000", "0.00000000"], ["111123.00000000", "0.00050000"], ["111258.64000000", "0.00000000"], ["112051.27000000", "0.00000000"]]}}
{"type": "orderbook", "local_time": 1761342346737, "event_time": 1761342346814, "latency_ms": -77, "data": {"e": "depthUpdate", "E": 1761342346814, "s": "BTCUSDT", "U": 79012687420, "u": 79012687473, "b": [["111028.02000000", "2.09574000"], ["110980.00000000", "0.00137000"], ["99925.00000000", "0.00510000"]], "a": [["111028.03000000", "2.07375000"], ["111028.04000000", "0.00140000"], ["111028.92000000", "0.00010000"], ["111028.93000000", "0.20765000"], ["111028.95000000", "0.01365000"], ["111029.04000000", "0.00720000"], ["111029.69000000", "0.00043000"], ["111029.94000000", "0.29722000"], ["111031.24000000", "0.00000000"], ["111033.16000000", "0.04577000"], ["111033.46000000", "0.04912000"], ["111033.59000000", "0.11267000"], ["111035.42000000", "0.00000000"], ["111040.26000000", "0.00000000"], ["111040.32000000", "0.00000000"], ["111040.34000000", "0.01801000"], ["111040.94000000", "0.13519000"], ["111041.55000000", "0.00000000"], ["111044.49000000", "0.02703000"], ["111046.65000000", "0.00000000"], ["111052.19000000", "0.00000000"], ["111068.01000000", "0.76617000"], ["111120.41000000", "0.03400000"], ["111123.95000000", "0.02500000"], ["111250.04000000", "0.00089000"]]}}
{"type": "orderbook", "local_time": 1761342346884, "event_time": 1761342346914, "latency_ms": -30, "data": {"e": "depthUpdate", "E": 1761342346914, "s": "BTCUSDT", "U": 79012687474, "u": 79012687492, "b": [["111028.02000000", "2.18985000"], ["99925.00000000", "0.00510000"]], "a": [["111028.03000000", "2.07385000"], ["111028.04000000", "0.00145000"], ["111028.95000000", "0.01365000"], ["111029.04000000", "0.00725000"], ["111033.16000000", "0.04572000"], ["111049.95000000", "0.30554000"], ["111068.01000000", "0.58590000"], ["111118.82000000", "0.18049000"]]}}
{"type": "orderbook", "local_time": 1761342346945, "event_time": 1761342347014, "latency_ms": -69, "data": {"e": "depthUpdate", "E": 1761342347014, "s": "BTCUSDT", "U": 79012687493, "u": 79012687504, "b": [["111022.07000000", "0.00000000"], ["111006.41000000", "0.05100000"], ["111001.45000000", "0.04000000"], ["110982.09000000", "0.00000000"], ["88822.00000000", "0.00337000"]], "a": [["111040.34000000", "0.00000000"], ["111040.36000000", "0.00000000"], ["111040.38000000", "0.01801000"], ["111068.01000000", "0.76617000"], ["111118.82000000", "0.00022000"]]}}
{"type": "orderbook", "local_time": 1761342347036, "event_time": 1761342347114, "latency_ms": -78, "data": {"e": "depthUpdate", "E": 1761342347114, "s": "BTCUSDT", "U": 79012687505, "u": 79012687513, "b": [["111028.02000000", "2.18980000"], ["111028.01000000", "0.85702000"], ["110898.11000000", "0.01410000"], ["109633.27000000", "0.00000000"]], "a": [["111036.76000000", "0.00000000"], ["111040.38000000", "0.00000000"], ["111040.40000000", "0.01801000"], ["111044.87000000", "0.03915000"], ["111053.27000000", "0.00000000"]]}}
{"type": "orderbook", "local_time": 1761342347136, "event_time": 1761342347214, "latency_ms": -78, "data": {"e": "depthUpdate", "E": 1761342347214, "s": "BTCUSDT", "U": 79012687514, "u": 79012687525, "b": [["111023.32000000", "0.04572000"], ["110983.35000000", "0.54865000"]], "a": [["111028.03000000", "2.02877000"], ["111035.26000000", "0.04508000"], ["111040.40000000", "0.00000000"], ["111040.42000000", "0.01801000"], ["111068.01000000", "0.45079000"], ["111118.53000000", "0.13511000"], ["111119.09000000", "0.18027000"], ["111120.40000000", "0.03400000"], ["111120.41000000", "0.00000000"]]}}
{"type": "orderbook", "local_time": 1761342347238, "event_time": 1761342347315, "latency_ms": -77, "data": {"e": "depthUpdate", "E": 1761342347315, "s": "BTCUSDT", "U": 79012687526, "u": 79012687538, "b": [["111028.02000000", "2.18985000"], ["111028.01000000", "0.85707000"], ["111023.46000000", "0.20750000"]], "a": [["111028.03000000", "2.02872000"], ["111028.04000000", "0.00140000"], ["111040.42000000", "0.00000000"], ["111040.43000000", "0.01801000"], ["111044.87000000", "0.00000000"], ["111068.01000000", "0.58590000"], ["111118.53000000", "0.00000000"]]}}
{"type": "orderbook", "local_time": 1761342347336, "event_time": 1761342347414, "latency_ms": -78, "data": {"e": "depthUpdate", "E": 1761342347414, "s": "BTCUSDT", "U": 79012687539, "u": 79012687542, "b": [["99925.00000000", "0.00510000"]], "a": [["111040.43000000", "0.00000000"], ["111040.44000000", "0.01801000"]]}}
{"type": "orderbook", "local_time": 1761342347436, "event_time": 1761342347514, "latency_ms": -78, "data": {"e": "depthUpdate", "E": 1761342347514, "s": "BTCUSDT", "U": 79012687543, "u": 79012687546, "b": [], "a": [["111068.01000000", "0.22535000"], ["111118.89000000", "0.25544000"], ["111118.99000000", "0.13511000"]]}}
{"type": "orderbook", "local_time": 1761342347539, "event_time": 1761342347615, "latency_ms": -76, "data": {"e": "depthUpdate", "E": 1761342347615, "s": "BTCUSDT", "U": 79012687547, "u": 79012687567, "b": [["111028.02000000", "2.18990000"], ["111028.01000000", "0.85712000"], ["111024.84000000", "0.00005000"], ["111024.32000000", "0.00005000"], ["111023.32000000", "0.00000000"], ["111018.35000000", "0.04790000"], ["111012.03000000", "0.00005000"], ["110983.35000000", "0.20282000"]], "a": [["111031.15000000", "0.04912000"], ["111031.95000000", "0.00250000"], ["111033.46000000", "0.00000000"], ["111040.44000000", "0.00000000"], ["111040.80000000", "0.01801000"], ["111046.67000000", "0.05945000"], ["111054.20000000", "0.00000000"], ["111068.01000000", "0.76617000"], ["111118.89000000", "0.03000000"], ["111118.99000000", "0.00000000"], ["111119.09000000", "0.00000000"]]}}
{"type": "orderbook", "local_time": 1761342347633, "event_time": 1761342347714, "latency_ms": -81, "data": {"e": "depthUpdate", "E": 1761342347714, "s": "BTCUSDT", "U": 79012687568, "u": 79012687599, "b": [["111028.02000000", "2.11924000"], ["111028.01000000", "0.85697000"], ["111025.09000000", "0.29724000"], ["111024.84000000", "0.00000000"], ["111024.32000000", "0.00000000"], ["111024.18000000", "0.04969000"], ["111023.46000000", "0.20750000"], ["111023.32000000", "0.04572000"], ["111022.08000000", "0.10075000"], ["111021.61000000", "0.00725000"], ["110983.35000000", "0.54865000"]], "a": [["111028.03000000", "2.11874000"], ["111028.04000000", "0.00130000"], ["111029.94000000", "0.29722000"], ["111031.15000000", "0.04917000"], ["111031.71000000", "0.05033000"]]}}
{"type": "orderbook", "local_time": 1761342347734, "event_time": 1761342347814, "latency_ms": -80, "data": {"e": "depthUpdate", "E": 1761342347814, "s": "BTCUSDT", "U": 79012687600, "u": 79012687623, "b": [["111028.02000000", "2.12180000"], ["111028.01000000", "0.85702000"], ["111024.24000000", "0.04005000"], ["111024.18000000", "0.04974000"], ["111023.46000000", "0.20750000"], ["111023.32000000", "0.04577000"], ["111022.08000000", "0.10070000"], ["111021.64000000", "0.04790000"], ["111021.61000000", "0.00720000"], ["111018.35000000", "0.00000000"], ["111013.36000000", "0.00000000"], ["111012.03000000", "0.00455000"], ["99925.00000000", "0.00510000"]], "a": [["111039.24000000", "0.00000000"], ["111039.80000000", "0.00450000"], ["111040.80000000", "0.00000000"], ["111040.81000000", "0.01801000"], ["111042.27000000", "0.27041000"], ["111048.92000000", "0.00000000"], ["111067.19000000", "0.41016000"], ["111068.01000000", "0.58590000"], ["111118.91000000", "0.18037000"]]}}
{"type": "orderbook", "local_time": 1761342347835, "event_time": 1761342347914, "latency_ms": -79, "data": {"e": "depthUpdate", "E": 1761342347914, "s": "BTCUSDT", "U": 79012687624, "u": 79012687635, "b": [["111028.02000000", "2.12185000"], ["111028.01000000", "0.85707000"], ["111024.58000000", "0.04790000"], ["111021.64000000", "0.00000000"], ["110940.00000000", "0.01962000"], ["99925.00000000", "0.00510000"]], "a": [["111031.15000000", "0.00005000"], ["111034.67000000", "0.04912000"], ["111046.67000000", "0.00000000"], ["111068.01000000", "0.45079000"], ["111118.58000000", "0.13511000"]]}}
{"type": "orderbook", "local_time": 1761342347936, "event_time": 1761342348014, "latency_ms": -78, "data": {"e": "depthUpdate", "E": 1761342348014, "s": "BTCUSDT", "U": 79012687636, "u": 79012687662, "b": [["111028.02000000", "2.12185000"], ["111028.01000000", "0.85707000"], ["111025.09000000", "0.29724000"], ["111024.58000000", "0.04795000"], ["111023.32000000", "0.04572000"], ["99925.00000000", "0.00510000"]], "a": [["111028.03000000", "2.11874000"], ["111028.04000000", "0.00125000"], ["111029.94000000", "0.29722000"], ["111031.15000000", "0.00000000"], ["111031.71000000", "0.05038000"], ["111040.81000000", "0.00000000"], ["111040.82000000", "0.01801000"], ["111120.40000000", "0.00000000"], ["111121.41000000", "0.03400000"], ["111123.65000000", "0.00000000"], ["111123.66000000", "0.00000000"], ["111123.95000000", "0.00000000"], ["111124.65000000", "0.00100000"], ["111124.66000000", "0.00100000"], ["111124.95000000", "0.02500000"]]}}
{"type": "orderbook", "local_time": 1761342348039, "event_time": 1761342348115, "latency_ms": -76, "data": {"e": "depthUpdate", "E": 1761342348115, "s": "BTCUSDT", "U": 79012687663, "u": 79012687674, "b": [["111020.58000000", "0.18009000"], ["111020.57000000", "0.00008000"], ["111018.61000000", "0.00000000"], ["111012.03000000", "0.00450000"], ["99925.22000000", "0.00020000"]], "a": [["111028.03000000", "2.02867000"], ["111047.88000000", "0.04785000"], ["111068.01000000", "0.58590000"], ["111118.53000000", "0.00000000"], ["111118.58000000", "0.00000000"]]}}
{"type": "orderbook", "local_time": 1761342348136, "event_time": 1761342348214, "latency_ms": -78, "data": {"e": "depthUpdate", "E": 1761342348214, "s": "BTCUSDT", "U": 79012687675, "u": 79012687680, "b": [["111028.02000000", "2.12140000"], ["111020.57000000", "0.00000000"], ["99925.00000000", "0.00510000"]], "a": [["111068.01000000", "0.58590000"]]}}
{"type": "orderbook", "local_time": 1761342348240, "event_time": 1761342348314, "latency_ms": -74, "data": {"e": "depthUpdate", "E": 1761342348314, "s": "BTCUSDT", "U": 79012687681, "u": 79012687685, "b": [["111020.58000000", "0.18032000"], ["110728.02000000", "0.00010000"]], "a": [["111040.82000000", "0.00000000"], ["111040.83000000", "0.01801000"], ["111047.88000000", "0.00000000"]]}}
{"type": "orderbook", "local_time": 1761342348340, "event_time": 1761342348415, "latency_ms": -75, "data": {"e": "depthUpdate", "E": 1761342348415, "s": "BTCUSDT", "U": 79012687686, "u": 79012687688, "b": [["110728.02000000", "0.00000000"]], "a": [["111068.01000000", "0.58590000"]]}}
{"type": "orderbook", "local_time": 1761342348434, "event_time": 1761342348514, "latency_ms": -80, "data": {"e": "depthUpdate", "E": 1761342348514, "s": "BTCUSDT", "U": 79012687689, "u": 79012687692, "b": [], "a": [["111068.01000000", "0.45079000"], ["111118.55000000", "0.13511000"], ["111120.41000000", "0.03400000"], ["111121.41000000", "0.00000000"]]}}
{"type": "orderbook", "local_time": 1761342348537, "event_time": 1761342348614, "latency_ms": -77, "data": {"e": "depthUpdate", "E": 1761342348614, "s": "BTCUSDT", "U": 79012687693, "u": 79012687697, "b": [["111028.02000000", "2.12098000"], ["102145.04000000", "0.00010000"]], "a": [["111044.88000000", "0.05736000"], ["111120.41000000", "0.00000000"], ["111121.41000000", "0.03400000"]]}}
{"type": "orderbook", "local_time": 1761342348640, "event_time": 1761342348714, "latency_ms": -74, "data": {"e": "depthUpdate", "E": 1761342348714, "s": "BTCUSDT", "U": 79012687698, "u": 79012687701, "b": [["111028.02000000", "2.12147000"], ["110699.57000000", "0.00000000"]], "a": [["111040.83000000", "0.00000000"], ["111040.87000000", "0.01801000"]]}}
{"type": "orderbook", "local_time": 1761342348736, "event_time": 1761342348814, "latency_ms": -78, "data": {"e": "depthUpdate", "E": 1761342348814, "s": "BTCUSDT", "U": 79012687702, "u": 79012687709, "b": [["111021.62000000", "0.18010000"], ["111020.58000000", "0.00023000"], ["111012.81000000", "0.00450000"], ["111012.03000000", "0.00000000"], ["42000.00000000", "1.36834000"]], "a": [["111040.87000000", "0.00000000"], ["111040.88000000", "0.01801000"], ["111042.27000000", "0.00000000"], ["111044.41000000", "0.27041000"], ["111044.88000000", "0.00000000"], ["111118.55000000", "0.00000000"]]}}
{"type": "orderbook", "local_time": 1761342348837, "event_time": 1761342348914, "latency_ms": -77, "data": {"e": "depthUpdate", "E": 1761342348914, "s": "BTCUSDT", "U": 79012687710, "u": 79012687717, "b": [["111028.02000000", "2.12152000"], ["111028.01000000", "0.85712000"], ["111020.58000000", "0.00000000"], ["109646.60000000", "0.00089000"]], "a": [["111068.01000000", "0.45079000"], ["111096.29000000", "0.00044000"], ["111118.53000000", "0.13511000"]]}}
{"type": "orderbook", "local_time": 1761342348937, "event_time": 1761342349014, "latency_ms": -77, "data": {"e": "depthUpdate", "E": 1761342349014, "s": "BTCUSDT", "U": 79012687718, "u": 79012687720, "b": [["111020.56000000", "0.00567000"]], "a": [["111040.88000000", "0.00000000"], ["111040.89000000", "0.01801000"]]}}
{"type": "orderbook", "local_time": 1761342349035, "event_time": 1761342349115, "latency_ms": -80, "data": {"e": "depthUpdate", "E": 1761342349115, "s": "BTCUSDT", "U": 79012687721, "u": 79012687731, "b": [["111028.02000000", "2.11974000"], ["111012.81000000", "0.00000000"], ["111012.03000000", "0.00450000"], ["110711.75000000", "0.00000000"], ["110706.75000000", "0.00572000"], ["99925.22000000", "0.00000000"], ["99925.00000000", "0.00510000"]], "a": [["111032.79000000", "0.04912000"], ["111034.67000000", "0.00000000"], ["111044.89000000", "0.02681000"]]}}
{"type": "orderbook", "local_time": 1761342349137, "event_time": 1761342349214, "latency_ms": -77, "data": {"e": "depthUpdate", "E": 1761342349214, "s": "BTCUSDT", "U": 79012687732, "u": 79012687739, "b": [["110728.02000000", "0.00000000"], ["102145.04000000", "0.00000000"]], "a": [["111028.03000000", "2.02867000"], ["111028.04000000", "0.00130000"], ["111031.71000000", "0.05038000"]]}}
{"type": "orderbook", "local_time": 1761342349238, "event_time": 1761342349314, "latency_ms": -76, "data": {"e": "depthUpdate", "E": 1761342349314, "s": "BTCUSDT", "U": 79012687740, "u": 79012687745, "b": [["111028.02000000", "2.11973000"]], "a": [["111040.89000000", "0.00000000"], ["111040.99000000", "0.01801000"], ["111365.28000000", "0.00000000"], ["111372.57000000", "0.48717000"]]}}
{"type": "orderbook", "local_time": 1761342349342, "event_time": 1761342349414, "latency_ms": -72, "data": {"e": "depthUpdate", "E": 1761342349414, "s": "BTCUSDT", "U": 79012687746, "u": 79012687771, "b": [["111028.02000000", "2.16763000"], ["111024.58000000", "0.00005000"], ["111023.05000000", "0.00250000"], ["111022.11000000", "0.00720000"], ["111021.61000000", "0.00000000"], ["111000.80000000", "0.00000000"], ["111000.07000000", "0.00576000"], ["110952.89000000", "0.03218000"], ["110932.72000000", "0.00000000"]], "a": [["111028.03000000", "1.62296000"], ["111028.93000000", "0.00020000"], ["111029.04000000", "0.00005000"], ["111031.95000000", "0.00000000"], ["111032.79000000", "0.00000000"], ["111036.40000000", "0.00000000"], ["111041.35000000", "0.04912000"], ["111044.89000000", "0.00000000"], ["111054.20000000", "0.00250000"], ["111054.90000000", "0.22566000"], ["111055.99000000", "0.18027000"], ["111058.65000000", "0.00250000"], ["111068.01000000", "0.00000000"], ["111118.83000000", "0.22544000"], ["111120.83000000", "0.22535000"]]}}
{"type": "orderbook", "local_time": 1761342349435, "event_time": 1761342349514, "latency_ms": -79, "data": {"e": "depthUpdate", "E": 1761342349514, "s": "BTCUSDT", "U": 79012687772, "u": 79012687826, "b": [["111028.02000000", "2.23467000"], ["111028.01000000", "0.86342000"], ["111025.09000000", "0.29724000"], ["111024.58000000", "0.00000000"], ["111023.32000000", "0.04577000"], ["111023.06000000", "0.18009000"], ["111021.62000000", "0.00000000"], ["110997.80000000", "0.00000000"], ["110952.89000000", "0.00000000"], ["110932.26000000", "0.03218000"], ["99925.00000000", "0.00520000"]], "a": [["111028.03000000", "1.48765000"], ["111028.04000000", "0.00115000"], ["111028.92000000", "0.00000000"], ["111028.93000000", "0.00000000"], ["111028.95000000", "0.01370000"], ["111029.04000000", "0.00000000"], ["111029.69000000", "0.00048000"], ["111029.94000000", "0.29727000"], ["111031.24000000", "0.00005000"], ["111031.71000000", "0.05038000"], ["111033.16000000", "0.04577000"], ["111033.58000000", "0.16720000"], ["111039.80000000", "0.00000000"], ["111040.93000000", "0.00450000"], ["111062.82000000", "0.00000000"], ["111067.19000000", "0.28518000"], ["111068.07000000", "0.13511000"]]}}
{"type": "orderbook", "local_time": 1761342349539, "event_time": 1761342349614, "latency_ms": -75, "data": {"e": "depthUpdate", "E": 1761342349614, "s": "BTCUSDT", "U": 79012687827, "u": 79012687838, "b": [["111028.02000000", "2.23467000"], ["111028.01000000", "0.86342000"], ["111023.32000000", "0.04577000"], ["111022.08000000", "0.05369000"], ["99925.00000000", "0.00510000"]], "a": [["111029.70000000", "0.04802000"], ["111029.90000000", "0.20745000"], ["111030.28000000", "0.00099000"], ["111044.89000000", "0.02681000"]]}}
{"type": "orderbook", "local_time": 1761342349639, "event_time": 1761342349714, "latency_ms": -75, "data": {"e": "depthUpdate", "E": 1761342349714, "s": "BTCUSDT", "U": 79012687839, "u": 79012687855, "b": [], "a": [["111028.03000000", "1.48770000"], ["111028.04000000", "0.00120000"], ["111029.70000000", "0.04802000"], ["111029.89000000", "0.00010000"], ["111029.90000000", "0.20755000"], ["111029.94000000", "0.29722000"], ["111031.24000000", "0.00000000"], ["111033.58000000", "0.16715000"], ["111033.59000000", "0.00000000"], ["111039.14000000", "0.11397000"]]}}
{"type": "orderbook", "local_time": 1761342349735, "event_time": 1761342349814, "latency_ms": -79, "data": {"e": "depthUpdate", "E": 1761342349814, "s": "BTCUSDT", "U": 79012687856, "u": 79012687863, "b": [["110996.01000000", "0.84682000"]], "a": [["111028.03000000", "1.48765000"], ["111028.04000000", "0.00115000"], ["111029.98000000", "0.00720000"], ["111040.99000000", "0.00000000"], ["111041.04000000", "0.01801000"], ["111061.13000000", "0.96499000"]]}}
{"type": "orderbook", "local_time": 1761342349835, "event_time": 1761342349914, "latency_ms": -79, "data": {"e": "depthUpdate", "E": 1761342349914, "s": "BTCUSDT", "U": 79012687864, "u": 79012687876, "b": [], "a": [["111028.03000000", "1.48770000"], ["111028.04000000", "0.00120000"], ["111029.94000000", "0.29722000"], ["111029.98000000", "0.00725000"], ["111033.16000000", "0.04572000"], ["111036.40000000", "0.00250000"], ["111038.38000000", "0.04912000"], ["111041.04000000", "0.00000000"], ["111041.06000000", "0.01801000"], ["111041.35000000", "0.00000000"], ["111044.89000000", "0.00000000"], ["111058.65000000", "0.00000000"]]}}
{"type": "orderbook", "local_time": 1761342349987, "event_time": 1761342350014, "latency_ms": -27, "data": {"e": "depthUpdate", "E": 1761342350014, "s": "BTCUSDT", "U": 79012687877, "u": 79012687884, "b": [["111028.02000000", "2.23477000"], ["88822.00000000", "0.00337000"]], "a": [["111035.99000000", "0.04912000"], ["111038.38000000", "0.00000000"], ["111041.06000000", "0.00000000"], ["111041.07000000", "0.01801000"]]}}
{"type": "orderbook", "local_time": 1761342350045, "event_time": 1761342350114, "latency_ms": -69, "data": {"e": "depthUpdate", "E": 1761342350114, "s": "BTCUSDT", "U": 79012687885, "u": 79012687902, "b": [["111028.02000000", "2.22956000"], ["111023.06000000", "0.00000000"], ["111022.12000000", "0.18010000"], ["111011.59000000", "0.01801000"], ["111008.51000000", "0.00000000"], ["111000.07000000", "0.00000000"], ["99925.00000000", "0.00510000"]], "a": [["111041.07000000", "0.00000000"], ["111041.09000000", "0.00000000"], ["111043.22000000", "0.00000000"], ["111043.24000000", "0.01801000"], ["111044.87000000", "0.03684000"], ["111096.29000000", "0.00000000"]]}}
{"type": "orderbook", "local_time": 1761342350134, "event_time": 1761342350214, "latency_ms": -80, "data": {"e": "depthUpdate", "E": 1761342350214, "s": "BTCUSDT", "U": 79012687903, "u": 79012687914, "b": [["111028.02000000", "2.22956000"], ["111028.01000000", "0.86342000"], ["111023.32000000", "0.04577000"], ["111022.13000000", "0.09615000"], ["111022.08000000", "0.00000000"], ["110999.72000000", "0.00576000"], ["109600.00000000", "2.44731000"]], "a": [["111043.24000000", "0.00000000"], ["111043.26000000", "0.01801000"]]}}
{"type": "orderbook", "local_time": 1761342350246, "event_time": 1761342350314, "latency_ms": -68, "data": {"e": "depthUpdate", "E": 1761342350314, "s": "BTCUSDT", "U": 79012687915, "u": 79012687924, "b": [["111028.02000000", "2.18166000"], ["111028.01000000", "0.86342000"], ["111026.03000000", "0.04790000"], ["111023.32000000", "0.04577000"], ["99925.00000000", "0.00520000"]], "a": [["111044.87000000", "0.00000000"]]}}
{"type": "orderbook", "local_time": 1761342350343, "event_time": 1761342350414, "latency_ms": -71, "data": {"e": "depthUpdate", "E": 1761342350414, "s": "BTCUSDT", "U": 79012687925, "u": 79012687940, "b": [["111028.02000000", "2.18176000"], ["111028.01000000", "0.86347000"], ["111027.22000000", "0.03731000"], ["111026.11000000", "0.00104000"], ["111026.03000000", "0.04795000"], ["111023.32000000", "0.04572000"], ["99925.00000000", "0.00520000"]], "a": [["111043.26000000", "0.00000000"], ["111043.27000000", "0.01801000"]]}}
{"type": "orderbook", "local_time": 1761342350444, "event_time": 1761342350514, "latency_ms": -70, "data": {"e": "depthUpdate", "E": 1761342350514, "s": "BTCUSDT", "U": 79012687941, "u": 79012687942, "b": [["99925.00000000", "0.00510000"]], "a": []}}
{"type": "orderbook", "local_time": 1761342350544, "event_time": 1761342350614, "latency_ms": -70, "data": {"e": "depthUpdate", "E": 1761342350614, "s": "BTCUSDT", "U": 79012687943, "u": 79012687951, "b": [["111018.60000000", "0.00255000"], ["111014.16000000", "0.00450000"], ["111012.03000000", "0.00000000"]], "a": [["111028.03000000", "1.12716000"], ["111040.93000000", "0.00000000"], ["111041.93000000", "0.00450000"], ["111046.67000000", "0.05866000"], ["111096.65000000", "0.00000000"], ["111207.73000000", "0.00000000"]]}}
{"type": "orderbook", "local_time": 1761342350634, "event_time": 1761342350714, "latency_ms": -80, "data": {"e": "depthUpdate", "E": 1761342350714, "s": "BTCUSDT", "U": 79012687952, "u": 79012687977, "b": [["111028.02000000", "2.18152000"], ["111027.22000000", "0.03736000"], ["111026.03000000", "0.04800000"], ["111015.31000000", "0.00010000"], ["99925.00000000", "0.00510000"]], "a": [["111028.03000000", "1.12640000"], ["111042.34000000", "0.13524000"], ["111042.74000000", "0.00044000"], ["111054.99000000", "0.22535000"], ["111097.74000000", "0.00048000"], ["111208.79000000", "0.00019000"]]}}
{"type": "orderbook", "local_time": 1761342350796, "event_time": 1761342350814, "latency_ms": -18, "data": {"e": "depthUpdate", "E": 1761342350814, "s": "BTCUSDT", "U": 79012687978, "u": 79012688001, "b": [["111028.02000000", "2.17716000"], ["111026.91000000", "0.00099000"], ["111026.11000000", "0.00005000"], ["111025.25000000", "0.00198000"], ["111024.45000000", "0.00000000"], ["111023.58000000", "0.00360000"], ["111022.78000000", "0.00000000"], ["111021.36000000", "0.00540000"], ["111020.56000000", "0.00027000"], ["111018.59000000", "0.03494000"], ["111017.48000000", "0.00000000"], ["111016.92000000", "0.00721000"], ["111014.15000000", "0.00250000"], ["111005.81000000", "0.00000000"], ["110999.72000000", "0.00000000"], ["110949.51000000", "0.00000000"], ["42000.00000000", "1.36734000"]], "a": [["111029.14000000", "0.00099000"], ["111029.70000000", "0.04082000"], ["111030.00000000", "0.00160000"], ["111030.80000000", "0.00198000"], ["111032.47000000", "0.00365000"], ["111033.89000000", "0.00000000"], ["111034.69000000", "0.00540000"], ["111036.66000000", "0.00000000"], ["111036.76000000", "0.00044000"], ["111037.46000000", "0.00396000"], ["111038.33000000", "0.00151000"], ["111039.13000000", "0.00720000"], ["111043.27000000", "0.00000000"], ["111043.35000000", "0.01801000"], ["111049.95000000", "0.42343000"], ["111053.27000000", "0.00044000"]]}}
{"type": "orderbook", "local_time": 1761342350834, "event_time": 1761342350914, "latency_ms": -80, "data": {"e": "depthUpdate", "E": 1761342350914, "s": "BTCUSDT", "U": 79012688002, "u": 79012688038, "b": [["111028.02000000", "2.17716000"], ["111028.01000000", "0.86347000"], ["111027.22000000", "0.03736000"], ["111026.91000000", "0.00104000"], ["111026.11000000", "0.00000000"], ["111021.36000000", "0.02008000"], ["111020.82000000", "0.00005000"], ["111020.56000000", "0.00000000"], ["111019.69000000", "0.11267000"], ["109599.87000000", "0.02501000"]], "a": [["111028.03000000", "1.12645000"], ["111028.04000000", "0.00115000"], ["111028.95000000", "0.01370000"], ["111029.14000000", "0.00104000"], ["111029.69000000", "0.00043000"], ["111043.35000000", "0.00000000"], ["111043.38000000", "0.01801000"], ["111046.67000000", "0.00000000"]]}}
{"type": "orderbook", "local_time": 1761342350934, "event_time": 1761342351015, "latency_ms": -81, "data": {"e": "depthUpdate", "E": 1761342351015, "s": "BTCUSDT", "U": 79012688039, "u": 79012688044, "b": [["111028.02000000", "2.17711000"], ["110999.97000000", "0.00576000"]], "a": [["111028.03000000", "1.12634000"], ["111043.38000000", "0.00000000"], ["111043.41000000", "0.01801000"], ["112900.00000000", "0.54244000"]]}}
{"type": "orderbook", "local_time": 1761342351038, "event_time": 1761342351114, "latency_ms": -76, "data": {"e": "depthUpdate", "E": 1761342351114, "s": "BTCUSDT", "U": 79012688045, "u": 79012688048, "b": [], "a": [["111043.41000000", "0.00000000"], ["111043.43000000", "0.03000000"], ["111043.46000000", "0.01801000"]]}}
{"type": "orderbook", "local_time": 1761342351136, "event_time": 1761342351214, "latency_ms": -78, "data": {"e": "depthUpdate", "E": 1761342351214, "s": "BTCUSDT", "U": 79012688049, "u": 79012688054, "b": [["110950.31000000", "0.00389000"], ["60000.00000000", "56.85876000"]], "a": [["111028.03000000", "1.12565000"], ["111039.84000000", "0.00069000"], ["111043.46000000", "0.00000000"], ["111043.49000000", "0.01801000"]]}}
{"type": "orderbook", "local_time": 1761342351243, "event_time": 1761342351314, "latency_ms": -71, "data": {"e": "depthUpdate", "E": 1761342351314, "s": "BTCUSDT", "U": 79012688055, "u": 79012688061, "b": [["111028.02000000", "2.17551000"], ["99925.00000000", "0.00510000"]], "a": [["111043.49000000", "0.00000000"], ["111043.51000000", "0.01801000"]]}}
{"type": "orderbook", "local_time": 1761342351335, "event_time": 1761342351414, "latency_ms": -79, "data": {"e": "depthUpdate", "E": 1761342351414, "s": "BTCUSDT", "U": 79012688062, "u": 79012688065, "b": [["111028.02000000", "2.17584000"]], "a": [["111028.03000000", "1.12634000"], ["111039.84000000", "0.00000000"]]}}
{"type": "orderbook", "local_time": 1761342351548, "event_time": 1761342351614, "latency_ms": -66, "data": {"e": "depthUpdate", "E": 1761342351614, "s": "BTCUSDT", "U": 79012688066, "u": 79012688071, "b": [["111020.82000000", "0.00013000"], ["110786.75000000", "0.00000000"]], "a": [["111046.67000000", "0.03903000"], ["111269.74000000", "0.00000000"], ["111368.93000000", "0.48717000"], ["111372.57000000", "0.00000000"]]}}
{"type": "orderbook", "local_time": 1761342351644, "event_time": 1761342351715, "latency_ms": -71, "data": {"e": "depthUpdate", "E": 1761342351715, "s": "BTCUSDT", "U": 79012688072, "u": 79012688076, "b": [["99925.00000000", "0.00510000"], ["60000.00000000", "56.85866000"], ["33000.00000000", "3.79445000"]], "a": []}}
{"type": "orderbook", "local_time": 1761342351742, "event_time": 1761342351814, "latency_ms": -72, "data": {"e": "depthUpdate", "E": 1761342351814, "s": "BTCUSDT", "U": 79012688077, "u": 79012688112, "b": [["111028.02000000", "2.17529000"], ["111028.01000000", "0.86312000"], ["111025.55000000", "0.00720000"], ["111022.11000000", "0.00000000"]], "a": [["111029.90000000", "0.00010000"], ["111029.98000000", "0.00005000"], ["111033.52000000", "0.21465000"], ["111035.26000000", "0.00000000"], ["111038.01000000", "0.00000000"], ["111041.91000000", "0.04508000"], ["111043.51000000", "0.00000000"], ["111043.61000000", "0.00000000"], ["111044.52000000", "0.01801000"], ["118000.00000000", "53.07580000"]]}}
{"type": "orderbook", "local_time": 1761342351834, "event_time": 1761342351914, "latency_ms": -80, "data": {"e": "depthUpdate", "E": 1761342351914, "s": "BTCUSDT", "U": 79012688113, "u": 79012688154, "b": [["111027.23000000", "0.00009000"], ["111026.03000000", "0.04800000"], ["111025.55000000", "0.00725000"], ["111023.46000000", "0.20745000"], ["110786.86000000", "0.84842000"], ["99925.00000000", "0.00510000"]], "a": [["111028.03000000", "1.12629000"], ["111028.04000000", "0.00115000"], ["111029.70000000", "0.04082000"], ["111029.89000000", "0.00000000"], ["111029.90000000", "0.00000000"], ["111029.94000000", "0.29727000"], ["111029.98000000", "0.00000000"], ["111031.24000000", "0.00005000"], ["111033.16000000", "0.04577000"], ["111033.51000000", "0.17530000"], ["111033.52000000", "0.21470000"], ["111033.58000000", "0.00000000"], ["111044.52000000", "0.00000000"], ["111044.54000000", "0.01801000"], ["111096.29000000", "0.00044000"], ["111270.25000000", "4.85664000"]]}}
{"type": "orderbook", "local_time": 1761342352080, "event_time": 1761342352014, "latency_ms": 66, "data": {"e": "depthUpdate", "E": 1761342352014, "s": "BTCUSDT", "U": 79012688155, "u": 79012688168, "b": [["111028.02000000", "1.90834000"], ["111028.01000000", "0.86307000"], ["110990.50000000", "0.00013000"]], "a": [["111028.03000000", "1.12629000"], ["111028.04000000", "0.00115000"], ["111033.16000000", "0.04577000"], ["111033.51000000", "0.17535000"], ["111033.52000000", "0.21465000"], ["111044.54000000", "0.00000000"], ["111044.57000000", "0.01801000"]]}}
{"type": "orderbook", "local_time": 1761342352080, "event_time": 1761342352114, "latency_ms": -34, "data": {"e": "depthUpdate", "E": 1761342352114, "s": "BTCUSDT", "U": 79012688169, "u": 79012688173, "b": [], "a": [["111036.76000000", "0.00000000"], ["111042.74000000", "0.00000000"], ["111044.57000000", "0.00000000"], ["111044.59000000", "0.01801000"], ["111053.27000000", "0.00000000"]]}}
{"type": "orderbook", "local_time": 1761342352134, "event_time": 1761342352214, "latency_ms": -80, "data": {"e": "depthUpdate", "E": 1761342352214, "s": "BTCUSDT", "U": 79012688174, "u": 79012688175, "b": [], "a": [["111044.59000000", "0.00000000"], ["111044.61000000", "0.01801000"]]}}
{"type": "orderbook", "local_time": 1761342352237, "event_time": 1761342352314, "latency_ms": -77, "data": {"e": "depthUpdate", "E": 1761342352314, "s": "BTCUSDT", "U": 79012688176, "u": 79012688177, "b": [], "a": [["111044.61000000", "0.00000000"], ["111044.66000000", "0.01801000"]]}}
{"type": "orderbook", "local_time": 1761342352340, "event_time": 1761342352415, "latency_ms": -75, "data": {"e": "depthUpdate", "E": 1761342352415, "s": "BTCUSDT", "U": 79012688178, "u": 79012688180, "b": [["110817.06000000", "0.01261000"], ["110789.10000000", "0.00000000"], ["99925.00000000", "0.00510000"]], "a": []}}
{"type": "orderbook", "local_time": 1761342352436, "event_time": 1761342352514, "latency_ms": -78, "data": {"e": "depthUpdate", "E": 1761342352514, "s": "BTCUSDT", "U": 79012688181, "u": 79012688186, "b": [], "a": [["111121.41000000", "0.00000000"], ["111121.46000000", "0.03400000"], ["111124.65000000", "0.00000000"], ["111124.66000000", "0.00000000"], ["111124.70000000", "0.00100000"], ["111124.71000000", "0.00100000"]]}}
{"type": "orderbook", "local_time": 1761342352539, "event_time": 1761342352614, "latency_ms": -75, "data": {"e": "depthUpdate", "E": 1761342352614, "s": "BTCUSDT", "U": 79012688187, "u": 79012688195, "b": [["111028.02000000", "1.90829000"], ["111028.01000000", "0.86302000"], ["111013.39000000", "0.01801000"], ["111011.59000000", "0.00000000"], ["109500.00000000", "13.94363000"]], "a": [["111044.66000000", "0.00000000"], ["111045.03000000", "0.01801000"], ["111124.95000000", "0.00000000"], ["111124.96000000", "0.02500000"]]}}
{"type": "orderbook", "local_time": 1761342352639, "event_time": 1761342352714, "latency_ms": -75, "data": {"e": "depthUpdate", "E": 1761342352714, "s": "BTCUSDT", "U": 79012688196, "u": 79012688201, "b": [["111015.31000000", "0.00000000"], ["111013.89000000", "0.06748000"]], "a": [["111046.67000000", "0.00000000"], ["111121.46000000", "0.00000000"], ["111121.48000000", "0.03400000"]]}}
{"type": "orderbook", "local_time": 1761342352736, "event_time": 1761342352814, "latency_ms": -78, "data": {"e": "depthUpdate", "E": 1761342352814, "s": "BTCUSDT", "U": 79012688202, "u": 79012688262, "b": [["111028.02000000", "2.11260000"], ["111027.88000000", "0.00000000"], ["111027.75000000", "0.29718000"], ["111026.13000000", "0.00720000"], ["111026.03000000", "0.00010000"], ["111025.55000000", "0.00005000"], ["111025.26000000", "0.18009000"], ["111025.09000000", "0.00005000"], ["111022.12000000", "0.00000000"], ["110950.46000000", "0.03218000"], ["110932.26000000", "0.00000000"], ["99925.00000000", "0.00510000"]], "a": [["111028.03000000", "0.93594000"], ["111029.93000000", "0.00020000"], ["111031.25000000", "0.00005000"], ["111033.51000000", "0.00005000"], ["111033.52000000", "0.00000000"], ["111035.99000000", "0.00000000"], ["111038.92000000", "0.04912000"], ["111039.14000000", "0.00130000"], ["111039.88000000", "0.00070000"], ["111041.93000000", "0.00000000"], ["111043.42000000", "0.00450000"], ["111045.03000000", "0.00000000"], ["111045.11000000", "0.07664000"], ["111061.13000000", "0.00000000"], ["111121.48000000", "0.00000000"], ["111122.43000000", "0.00010000"], ["111123.38000000", "0.03400000"], ["111124.70000000", "0.00000000"], ["111124.71000000", "0.00000000"], ["111124.96000000", "0.00000000"], ["111125.23000000", "0.00000000"], ["111125.24000000", "0.00000000"], ["111125.91000000", "0.00000000"], ["111126.86000000", "0.02500000"], ["111403.79000000", "0.00000000"], ["111421.56000000", "0.03698000"]]}}
{"type": "orderbook", "local_time": 1761342352834, "event_time": 1761342352914, "latency_ms": -80, "data": {"e": "depthUpdate", "E": 1761342352914, "s": "BTCUSDT", "U": 79012688263, "u": 79012688377, "b": [["111028.02000000", "2.32017000"], ["111028.00000000", "2.47747000"], ["111027.76000000", "0.00010000"], ["111027.75000000", "0.29738000"], ["111027.22000000", "0.03731000"], ["111026.91000000", "0.00099000"], ["111026.13000000", "0.00725000"], ["111026.03000000", "0.00000000"], ["111025.55000000", "0.00000000"], ["111025.26000000", "0.18014000"], ["111025.24000000", "0.03449000"], ["111025.10000000", "0.00000000"], ["111025.09000000", "0.00000000"], ["111023.46000000", "0.00000000"], ["111013.39000000", "0.00000000"], ["99925.00000000", "0.00510000"]], "a": [["111028.03000000", "0.85734000"], ["111028.04000000", "0.00100000"], ["111029.70000000", "0.04082000"], ["111029.92000000", "0.00000000"], ["111029.93000000", "0.36450000"], ["111029.94000000", "0.29727000"], ["111031.24000000", "0.00000000"], ["111031.25000000", "0.00010000"], ["111031.26000000", "0.81640000"], ["111033.16000000", "0.04577000"], ["111033.50000000", "0.00000000"], ["111033.51000000", "0.00000000"], ["111034.69000000", "0.00545000"], ["111034.81000000", "0.09426000"], ["111034.82000000", "0.00005000"], ["111035.23000000", "0.21465000"], ["111035.88000000", "0.07666000"], ["111036.06000000", "0.04912000"], ["111038.92000000", "0.00000000"], ["111039.86000000", "0.00069000"], ["111039.94000000", "0.00074000"], ["111040.31000000", "0.00000000"], ["111044.41000000", "0.00000000"], ["111046.36000000", "0.11267000"], ["111049.94000000", "0.27041000"], ["111060.06000000", "0.00000000"], ["111066.60000000", "0.00000000"], ["111071.99000000", "0.34583000"], ["111080.33000000", "0.32404000"], ["111123.38000000", "0.00000000"], ["111124.38000000", "0.03400000"], ["111126.86000000", "0.00000000"], ["111127.86000000", "0.02500000"], ["111403.73000000", "0.00000000"], ["111421.58000000", "0.03698000"]]}}
{"type": "orderbook", "local_time": 1761342352937, "event_time": 1761342353014, "latency_ms": -77, "data": {"e": "depthUpdate", "E": 1761342353014, "s": "BTCUSDT", "U": 79012688378, "u": 79012688423, "b": [["111024.18000000", "0.04974000"], ["88822.00000000", "0.00337000"]], "a": [["111028.03000000", "0.60369000"], ["111028.04000000", "0.00105000"], ["111029.70000000", "0.04082000"], ["111029.92000000", "0.00010000"], ["111029.93000000", "0.36460000"], ["111031.26000000", "0.81635000"], ["111034.69000000", "0.00545000"], ["111034.80000000", "0.20282000"], ["111034.81000000", "0.11248000"], ["111034.82000000", "0.00000000"], ["111035.23000000", "0.00000000"], ["111035.88000000", "0.07661000"], ["111038.14000000", "0.20282000"], ["111040.29000000", "1.44342000"], ["111040.30000000", "0.34556000"], ["111046.75000000", "0.05092000"], ["111061.29000000", "0.75017000"]]}}
{"type": "orderbook", "local_time": 1761342353041, "event_time": 1761342353114, "latency_ms": -73, "data": {"e": "depthUpdate", "E": 1761342353114, "s": "BTCUSDT", "U": 79012688424, "u": 79012688451, "b": [["111028.02000000", "2.33321000"]], "a": [["111028.03000000", "0.60845000"], ["111028.04000000", "0.00100000"], ["111029.93000000", "0.36450000"], ["111029.94000000", "0.00010000"], ["111032.56000000", "0.29717000"], ["111034.69000000", "0.00545000"], ["111034.79000000", "0.20304000"], ["111034.80000000", "0.20287000"], ["111034.81000000", "0.00000000"], ["111040.28000000", "0.77642000"], ["111040.30000000", "0.00000000"], ["111043.42000000", "0.00000000"], ["111045.10000000", "0.00726000"], ["111061.53000000", "0.98294000"], ["111096.29000000", "0.00000000"]]}}
{"type": "orderbook", "local_time": 1761342353155, "event_time": 1761342353214, "latency_ms": -59, "data": {"e": "depthUpdate", "E": 1761342353214, "s": "BTCUSDT", "U": 79012688452, "u": 79012688483, "b": [["111023.14000000", "0.06748000"], ["111018.61000000", "0.00450000"], ["111014.16000000", "0.00000000"]], "a": [["111028.03000000", "0.60849000"], ["111028.04000000", "0.00100000"], ["111029.93000000", "0.36450000"], ["111029.94000000", "0.00000000"], ["111031.26000000", "0.81640000"], ["111031.71000000", "0.05038000"], ["111032.55000000", "0.00005000"], ["111032.56000000", "0.29722000"], ["111034.69000000", "0.00545000"], ["111034.79000000", "0.20309000"], ["111034.80000000", "0.20282000"], ["111035.25000000", "0.21616000"], ["111046.75000000", "0.00000000"], ["111368.93000000", "0.48717000"]]}}
{"type": "orderbook", "local_time": 1761342353237, "event_time": 1761342353314, "latency_ms": -77, "data": {"e": "depthUpdate", "E": 1761342353314, "s": "BTCUSDT", "U": 79012688484, "u": 79012688489, "b": [["111028.02000000", "2.33581000"], ["111018.60000000", "0.30644000"], ["111012.80000000", "0.00000000"]], "a": [["111028.03000000", "0.60785000"], ["111028.04000000", "0.00105000"], ["111036.06000000", "0.00000000"]]}}
{"type": "orderbook", "local_time": 1761342353347, "event_time": 1761342353414, "latency_ms": -67, "data": {"e": "depthUpdate", "E": 1761342353414, "s": "BTCUSDT", "U": 79012688490, "u": 79012688495, "b": [["111022.13000000", "0.15630000"]], "a": [["111028.03000000", "0.67776000"], ["111028.04000000", "0.00100000"], ["111038.72000000", "0.04912000"]]}}
{"type": "orderbook", "local_time": 1761342353437, "event_time": 1761342353514, "latency_ms": -77, "data": {"e": "depthUpdate", "E": 1761342353514, "s": "BTCUSDT", "U": 79012688496, "u": 79012688497, "b": [["99925.00000000", "0.00530000"]], "a": [["111150.04000000", "0.00005000"], ["111202.70000000", "0.01258000"]]}}
{"type": "orderbook", "local_time": 1761342353545, "event_time": 1761342353614, "latency_ms": -69, "data": {"e": "depthUpdate", "E": 1761342353614, "s": "BTCUSDT", "U": 79012688498, "u": 79012688498, "b": [["99925.00000000", "0.00510000"]], "a": []}}
{"type": "orderbook", "local_time": 1761342353635, "event_time": 1761342353714, "latency_ms": -79, "data": {"e": "depthUpdate", "E": 1761342353714, "s": "BTCUSDT", "U": 79012688499, "u": 79012688500, "b": [["111028.02000000", "2.33576000"], ["111028.01000000", "0.86297000"]], "a": []}}
{"type": "orderbook", "local_time": 1761342353747, "event_time": 1761342353814, "latency_ms": -67, "data": {"e": "depthUpdate", "E": 1761342353814, "s": "BTCUSDT", "U": 79012688501, "u": 79012688504, "b": [["111028.02000000", "2.33527000"], ["111024.18000000", "0.00005000"], ["111018.59000000", "0.02460000"], ["99925.00000000", "0.00520000"]], "a": []}}
{"type": "orderbook", "local_time": 1761342353835, "event_time": 1761342353914, "latency_ms": -79, "data": {"e": "depthUpdate", "E": 1761342353914, "s": "BTCUSDT", "U": 79012688505, "u": 79012688510, "b": [["111024.24000000", "0.04005000"], ["111024.18000000", "0.00000000"], ["111023.32000000", "0.04577000"], ["110998.79000000", "0.07373000"], ["99925.00000000", "0.00510000"]], "a": []}}
{"type": "orderbook", "local_time": 1761342353951, "event_time": 1761342354014, "latency_ms": -63, "data": {"e": "depthUpdate", "E": 1761342354014, "s": "BTCUSDT", "U": 79012688511, "u": 79012688513, "b": [["111028.02000000", "2.34114000"], ["111018.60000000", "0.00255000"], ["111015.31000000", "0.30389000"], ["110707.74000000", "0.00572000"], ["110706.75000000", "0.00000000"]], "a": []}}
{"type": "orderbook", "local_time": 1761342354042, "event_time": 1761342354114, "latency_ms": -72, "data": {"e": "depthUpdate", "E": 1761342354114, "s": "BTCUSDT", "U": 79012688514, "u": 79012688515, "b": [["111022.13000000", "0.09615000"], ["111018.61000000", "0.00000000"], ["111017.10000000", "0.00450000"]], "a": []}}
{"type": "orderbook", "local_time": 1761342354137, "event_time": 1761342354214, "latency_ms": -77, "data": {"e": "depthUpdate", "E": 1761342354214, "s": "BTCUSDT", "U": 79012688516, "u": 79012688526, "b": [["111028.02000000", "2.34165000"], ["111016.56000000", "0.01801000"], ["111014.46000000", "0.00000000"], ["102145.04000000", "0.00010000"]], "a": [["111036.40000000", "0.00000000"], ["111038.72000000", "0.00000000"], ["111047.76000000", "0.00000000"], ["111048.20000000", "0.01801000"], ["111058.65000000", "0.00250000"]]}}
{"type": "orderbook", "local_time": 1761342354242, "event_time": 1761342354316, "latency_ms": -74, "data": {"e": "depthUpdate", "E": 1761342354316, "s": "BTCUSDT", "U": 79012688527, "u": 79012688535, "b": [["111028.02000000", "2.39261000"]], "a": [["111028.03000000", "0.67701000"], ["111039.96000000", "0.00319000"], ["111041.74000000", "0.04912000"], ["111048.20000000", "0.00000000"], ["111048.23000000", "0.00615000"], ["111048.24000000", "0.01801000"]]}}
{"type": "orderbook", "local_time": 1761342354337, "event_time": 1761342354414, "latency_ms": -77, "data": {"e": "depthUpdate", "E": 1761342354414, "s": "BTCUSDT", "U": 79012688536, "u": 79012688539, "b": [["110996.01000000", "0.00000000"]], "a": [["111048.24000000", "0.00000000"], ["111048.25000000", "0.01801000"], ["111061.53000000", "0.00000000"]]}}
{"type": "orderbook", "local_time": 1761342354438, "event_time": 1761342354514, "latency_ms": -76, "data": {"e": "depthUpdate", "E": 1761342354514, "s": "BTCUSDT", "U": 79012688540, "u": 79012688547, "b": [["111028.02000000", "2.39216000"], ["110950.46000000", "0.00000000"], ["110938.64000000", "0.03218000"], ["99925.00000000", "0.00510000"]], "a": [["111028.03000000", "0.67696000"], ["111125.23000000", "0.00100000"], ["111125.24000000", "0.00100000"]]}}
{"type": "orderbook", "local_time": 1761342354542, "event_time": 1761342354614, "latency_ms": -72, "data": {"e": "depthUpdate", "E": 1761342354614, "s": "BTCUSDT", "U": 79012688548, "u": 79012688558, "b": [["110998.18000000", "0.84681000"], ["99925.00000000", "0.00510000"]], "a": [["111028.03000000", "0.60770000"], ["111039.10000000", "0.04912000"], ["111039.89000000", "0.00070000"], ["111039.96000000", "0.00250000"], ["111041.74000000", "0.00000000"], ["111061.55000000", "0.96231000"]]}}
{"type": "orderbook", "local_time": 1761342354638, "event_time": 1761342354714, "latency_ms": -76, "data": {"e": "depthUpdate", "E": 1761342354714, "s": "BTCUSDT", "U": 79012688559, "u": 79012688560, "b": [], "a": [["111028.03000000", "0.68685000"], ["111039.89000000", "0.00000000"]]}}
{"type": "orderbook", "local_time": 1761342354737, "event_time": 1761342354814, "latency_ms": -77, "data": {"e": "depthUpdate", "E": 1761342354814, "s": "BTCUSDT", "U": 79012688561, "u": 79012688569, "b": [["110999.97000000", "0.00000000"], ["102145.04000000", "0.00000000"]], "a": [["111039.89000000", "0.00070000"], ["111048.25000000", "0.00000000"], ["111048.28000000", "0.00000000"], ["111048.29000000", "0.00000000"], ["111048.55000000", "0.01801000"]]}}
{"type": "orderbook", "local_time": 1761342354836, "event_time": 1761342354914, "latency_ms": -78, "data": {"e": "depthUpdate", "E": 1761342354914, "s": "BTCUSDT", "U": 79012688570, "u": 79012688577, "b": [["111028.02000000", "2.39206000"], ["99925.00000000", "0.00510000"]], "a": [["111028.03000000", "0.68755000"], ["111039.89000000", "0.00000000"], ["111047.38000000", "0.03187000"], ["111368.93000000", "0.48717000"]]}}
{"type": "orderbook", "local_time": 1761342354961, "event_time": 1761342355015, "latency_ms": -54, "data": {"e": "depthUpdate", "E": 1761342355015, "s": "BTCUSDT", "U": 79012688578, "u": 79012688584, "b": [["111000.34000000", "0.00576000"]], "a": [["111028.03000000", "0.68685000"], ["111039.91000000", "0.00070000"], ["111048.55000000", "0.00000000"], ["111048.56000000", "0.00000000"], ["111048.57000000", "0.01801000"]]}}
{"type": "orderbook", "local_time": 1761342355165, "event_time": 1761342355216, "latency_ms": -51, "data": {"e": "depthUpdate", "E": 1761342355216, "s": "BTCUSDT", "U": 79012688585, "u": 79012688588, "b": [["111028.02000000", "2.39204000"]], "a": [["111044.43000000", "0.00000000"]]}}
{"type": "orderbook", "local_time": 1761342355260, "event_time": 1761342355314, "latency_ms": -54, "data": {"e": "depthUpdate", "E": 1761342355314, "s": "BTCUSDT", "U": 79012688589, "u": 79012688594, "b": [["111028.02000000", "2.39194000"], ["111028.01000000", "0.86287000"], ["99925.00000000", "0.00520000"]], "a": [["111031.71000000", "0.00005000"]]}}
{"type": "orderbook", "local_time": 1761342355366, "event_time": 1761342355415, "latency_ms": -49, "data": {"e": "depthUpdate", "E": 1761342355415, "s": "BTCUSDT", "U": 79012688595, "u": 79012688611, "b": [["111028.02000000", "3.28093000"], ["111025.26000000", "0.00005000"], ["110916.00000000", "0.00160000"], ["110869.00000000", "0.11455000"], ["99925.00000000", "0.00530000"]], "a": [["111028.03000000", "0.68690000"], ["111028.04000000", "0.00100000"], ["111031.26000000", "0.81640000"], ["111031.71000000", "0.00000000"], ["111034.80000000", "0.20287000"]]}}
{"type": "orderbook", "local_time": 1761342355458, "event_time": 1761342355514, "latency_ms": -56, "data": {"e": "depthUpdate", "E": 1761342355514, "s": "BTCUSDT", "U": 79012688612, "u": 79012688632, "b": [["111028.02000000", "2.56816000"], ["111027.22000000", "0.03731000"], ["111026.13000000", "0.00725000"], ["111025.26000000", "0.00000000"], ["111023.14000000", "0.06753000"], ["109599.87000000", "0.02498000"], ["99925.00000000", "0.00510000"]], "a": [["111028.03000000", "0.68539000"], ["111047.38000000", "0.00000000"], ["111116.05000000", "0.00000000"]]}}
{"type": "orderbook", "local_time": 1761342355551, "event_time": 1761342355614, "latency_ms": -63, "data": {"e": "depthUpdate", "E": 1761342355614, "s": "BTCUSDT", "U": 79012688633, "u": 79012688639, "b": [["111028.02000000", "2.57214000"], ["111021.36000000", "0.00540000"], ["111020.00000000", "0.01500000"], ["110552.02000000", "0.03698000"], ["110527.81000000", "0.00000000"]], "a": [["111117.00000000", "0.00380000"]]}}
{"type": "orderbook", "local_time": 1761342355639, "event_time": 1761342355714, "latency_ms": -75, "data": {"e": "depthUpdate", "E": 1761342355714, "s": "BTCUSDT", "U": 79012688640, "u": 79012688642, "b": [["110892.67000000", "0.00005000"], ["110881.57000000", "0.00000000"], ["99925.00000000", "0.00510000"]], "a": [["111064.39000000", "0.00000000"], ["111075.49000000", "0.00000000"]]}}
{"type": "orderbook", "local_time": 1761342355740, "event_time": 1761342355814, "latency_ms": -74, "data": {"e": "depthUpdate", "E": 1761342355814, "s": "BTCUSDT", "U": 79012688643, "u": 79012688646, "b": [["110892.67000000", "0.00119000"]], "a": [["111039.81000000", "0.00000000"], ["111064.39000000", "0.00114000"], ["111080.05000000", "0.01916000"]]}}
{"type": "orderbook", "local_time": 1761342355836, "event_time": 1761342355914, "latency_ms": -78, "data": {"e": "depthUpdate", "E": 1761342355914, "s": "BTCUSDT", "U": 79012688647, "u": 79012688654, "b": [["111028.02000000", "2.57128000"], ["111027.22000000", "0.03629000"], ["110881.57000000", "0.00229000"], ["110786.86000000", "0.00000000"]], "a": [["111075.49000000", "0.00229000"], ["111270.25000000", "0.00000000"]]}}
{"type": "orderbook", "local_time": 1761342355940, "event_time": 1761342356014, "latency_ms": -74, "data": {"e": "depthUpdate", "E": 1761342356014, "s": "BTCUSDT", "U": 79012688655, "u": 79012688662, "b": [["111028.02000000", "2.57181000"], ["110910.23000000", "0.00000000"], ["110907.87000000", "0.03998000"], ["110904.93000000", "0.19990000"], ["99925.00000000", "0.00510000"], ["88822.00000000", "0.00337000"]], "a": []}}
{"type": "orderbook", "local_time": 1761342356036, "event_time": 1761342356114, "latency_ms": -78, "data": {"e": "depthUpdate", "E": 1761342356114, "s": "BTCUSDT", "U": 79012688663, "u": 79012688667, "b": [["111028.02000000", "2.60783000"], ["110940.01000000", "0.03998000"], ["110927.18000000", "0.24280000"], ["110919.73000000", "0.03998000"], ["107000.00000000", "26.29288000"]], "a": []}}
{"type": "orderbook", "local_time": 1761342356133, "event_time": 1761342356214, "latency_ms": -81, "data": {"e": "depthUpdate", "E": 1761342356214, "s": "BTCUSDT", "U": 79012688668, "u": 79012688674, "b": [["111028.02000000", "2.60828000"], ["110787.39000000", "0.84842000"], ["110712.83000000", "0.02598000"], ["110708.93000000", "0.00000000"], ["33000.00000000", "3.79445000"]], "a": [["111270.73000000", "4.86389000"]]}}
{"type": "orderbook", "local_time": 1761342356276, "event_time": 1761342356314, "latency_ms": -38, "data": {"e": "depthUpdate", "E": 1761342356314, "s": "BTCUSDT", "U": 79012688675, "u": 79012688678, "b": [["111028.02000000", "3.31718000"], ["99925.00000000", "0.00510000"]], "a": [["111028.03000000", "0.68436000"]]}}
{"type": "orderbook", "local_time": 1761342356440, "event_time": 1761342356514, "latency_ms": -74, "data": {"e": "depthUpdate", "E": 1761342356514, "s": "BTCUSDT", "U": 79012688679, "u": 79012688679, "b": [["111028.02000000", "3.30404000"]], "a": []}}
{"type": "orderbook", "local_time": 1761342356533, "event_time": 1761342356614, "latency_ms": -81, "data": {"e": "depthUpdate", "E": 1761342356614, "s": "BTCUSDT", "U": 79012688680, "u": 79012688705, "b": [["111028.02000000", "2.15970000"], ["111026.14000000", "0.00000000"], ["111026.13000000", "0.00005000"], ["111026.06000000", "0.04790000"], ["111024.25000000", "0.18009000"], ["111023.14000000", "0.00005000"], ["111017.10000000", "0.00000000"], ["111016.56000000", "0.00000000"], ["111015.32000000", "0.00450000"], ["111015.31000000", "0.30399000"], ["110980.00000000", "0.01939000"]], "a": [["111028.03000000", "1.49625000"], ["111034.78000000", "0.00720000"], ["111035.25000000", "0.20896000"], ["111036.82000000", "0.04912000"], ["111039.10000000", "0.00000000"], ["111039.91000000", "0.00000000"], ["111368.93000000", "0.48717000"], ["116000.00000000", "88.49394000"]]}}
{"type": "orderbook", "local_time": 1761342356643, "event_time": 1761342356714, "latency_ms": -71, "data": {"e": "depthUpdate", "E": 1761342356714, "s": "BTCUSDT", "U": 79012688706, "u": 79012688738, "b": [["111028.02000000", "2.20760000"], ["111027.22000000", "0.03629000"], ["111026.13000000", "0.00000000"], ["111026.06000000", "0.00005000"], ["111025.24000000", "0.03449000"], ["111024.25000000", "0.18014000"], ["111023.32000000", "0.04577000"], ["111023.14000000", "0.00000000"], ["111015.31000000", "0.30389000"]], "a": [["111028.03000000", "1.49639000"], ["111028.04000000", "0.00110000"], ["111034.45000000", "0.00000000"], ["111034.69000000", "0.00545000"], ["111034.78000000", "0.00725000"], ["111034.80000000", "0.20282000"], ["111036.82000000", "0.00000000"]]}}
{"type": "orderbook", "local_time": 1761342356736, "event_time": 1761342356814, "latency_ms": -78, "data": {"e": "depthUpdate", "E": 1761342356814, "s": "BTCUSDT", "U": 79012688739, "u": 79012688807, "b": [["111028.02000000", "2.06844000"], ["111027.50000000", "0.00250000"], ["111027.22000000", "0.03629000"], ["111026.06000000", "0.00000000"], ["111022.13000000", "0.09620000"], ["111020.01000000", "0.00000000"], ["111017.47000000", "0.00000000"], ["111017.10000000", "0.30389000"], ["111015.31000000", "0.00000000"], ["111009.70000000", "0.00250000"], ["111008.88000000", "0.00000000"], ["111005.25000000", "0.00000000"], ["111000.34000000", "0.00000000"], ["110963.75000000", "0.00631000"], ["110963.59000000", "0.00632000"], ["110956.33000000", "0.03218000"], ["110954.13000000", "0.00631000"], ["110947.76000000", "0.00000000"], ["110947.63000000", "0.00000000"], ["110938.64000000", "0.00000000"], ["110938.30000000", "0.00000000"], ["110921.84000000", "0.02436000"], ["110921.39000000", "0.00112000"], ["110920.40000000", "0.04033000"], ["110899.85000000", "0.00000000"], ["110899.38000000", "0.00000000"], ["110898.39000000", "0.00000000"], ["99925.00000000", "0.00510000"]], "a": [["111028.03000000", "1.49237000"], ["111028.04000000", "0.00105000"], ["111029.93000000", "0.00010000"], ["111031.25000000", "0.34777000"], ["111031.74000000", "0.05007000"], ["111034.78000000", "0.00005000"], ["111035.25000000", "0.00151000"], ["111035.26000000", "0.04508000"], ["111037.04000000", "0.00000000"], ["111040.03000000", "0.00069000"], ["111041.77000000", "0.00328000"], ["111041.91000000", "0.00000000"], ["111043.04000000", "0.04912000"], ["111086.12000000", "0.00000000"], ["111131.48000000", "0.00000000"]]}}
{"type": "orderbook", "local_time": 1761342356842, "event_time": 1761342356914, "latency_ms": -72, "data": {"e": "depthUpdate", "E": 1761342356914, "s": "BTCUSDT", "U": 79012688808, "u": 79012688855, "b": [["111028.02000000", "2.27589000"], ["111027.75000000", "0.29738000"], ["111027.50000000", "0.00255000"], ["111027.22000000", "0.03624000"], ["111022.13000000", "0.15200000"], ["111017.49000000", "0.01801000"], ["110999.90000000", "0.00576000"], ["99925.00000000", "0.00510000"]], "a": [["111028.03000000", "1.49237000"], ["111028.04000000", "0.00100000"], ["111029.70000000", "0.04082000"], ["111029.92000000", "0.00000000"], ["111029.93000000", "0.00000000"], ["111031.24000000", "0.00010000"], ["111031.25000000", "0.34787000"], ["111031.26000000", "0.81640000"], ["111031.74000000", "0.05012000"], ["111034.69000000", "0.00545000"], ["111034.78000000", "0.00000000"], ["111034.81000000", "0.20745000"], ["111099.85000000", "0.00647000"], ["111162.74000000", "0.08943000"]]}}
{"type": "orderbook", "local_time": 1761342356961, "event_time": 1761342357014, "latency_ms": -53, "data": {"e": "depthUpdate", "E": 1761342357014, "s": "BTCUSDT", "U": 79012688856, "u": 79012688861, "b": [["111028.02000000", "2.28309000"]], "a": [["111028.03000000", "1.49242000"], ["111034.82000000", "0.00720000"], ["111036.76000000", "0.00044000"]]}}
{"type": "orderbook", "local_time": 1761342357078, "event_time": 1761342357114, "latency_ms": -36, "data": {"e": "depthUpdate", "E": 1761342357114, "s": "BTCUSDT", "U": 79012688862, "u": 79012688868, "b": [["110928.57000000", "0.01410000"], ["110898.11000000", "0.00000000"], ["110188.35000000", "0.00200000"], ["110177.34000000", "0.00000000"]], "a": [["111028.03000000", "1.49242000"], ["111028.04000000", "0.00095000"], ["111259.58000000", "0.00000000"], ["111270.70000000", "0.00200000"]]}}
{"type": "orderbook", "local_time": 1761342357147, "event_time": 1761342357214, "latency_ms": -67, "data": {"e": "depthUpdate", "E": 1761342357214, "s": "BTCUSDT", "U": 79012688869, "u": 79012688883, "b": [["111028.02000000", "2.25648000"], ["111027.50000000", "0.00005000"], ["111015.31000000", "0.00010000"], ["111000.80000000", "0.00250000"], ["110999.90000000", "0.00000000"], ["99925.00000000", "0.00510000"]], "a": [["111028.03000000", "1.47775000"], ["111036.40000000", "0.00250000"], ["111036.93000000", "0.04912000"], ["111043.04000000", "0.00000000"], ["111049.72000000", "0.08027000"], ["111058.65000000", "0.00000000"]]}}
{"type": "orderbook", "local_time": 1761342357255, "event_time": 1761342357323, "latency_ms": -68, "data": {"e": "depthUpdate", "E": 1761342357323, "s": "BTCUSDT", "U": 79012688884, "u": 79012688889, "b": [["111027.75000000", "0.29738000"], ["111027.50000000", "0.00000000"], ["111027.22000000", "0.03629000"]], "a": [["111028.03000000", "1.47770000"], ["111028.04000000", "0.00090000"]]}}
{"type": "orderbook", "local_time": 1761342357336, "event_time": 1761342357414, "latency_ms": -78, "data": {"e": "depthUpdate", "E": 1761342357414, "s": "BTCUSDT", "U": 79012688890, "u": 79012688892, "b": [["110999.77000000", "0.00576000"], ["110928.57000000", "0.00000000"]], "a": [["111028.03000000", "1.47777000"]]}}
{"type": "orderbook", "local_time": 1761342357445, "event_time": 1761342357514, "latency_ms": -69, "data": {"e": "depthUpdate", "E": 1761342357514, "s": "BTCUSDT", "U": 79012688893, "u": 79012688903, "b": [["111028.02000000", "2.12170000"], ["111024.93000000", "0.04633000"], ["111010.98000000", "0.00000000"]], "a": [["111028.03000000", "1.46463000"], ["111031.24000000", "0.20292000"], ["111033.67000000", "0.04808000"], ["111036.93000000", "0.00000000"]]}}
{"type": "orderbook", "local_time": 1761342357539, "event_time": 1761342357614, "latency_ms": -75, "data": {"e": "depthUpdate", "E": 1761342357614, "s": "BTCUSDT", "U": 79012688904, "u": 79012688938, "b": [["111028.02000000", "2.18121000"], ["111027.49000000", "0.04633000"], ["111025.24000000", "0.03449000"], ["111024.93000000", "0.00005000"], ["111022.13000000", "0.15195000"]], "a": [["111028.03000000", "1.65428000"], ["111028.04000000", "0.00100000"], ["111029.70000000", "0.04082000"], ["111031.23000000", "0.00010000"], ["111031.24000000", "0.20302000"], ["111031.26000000", "0.81635000"], ["111032.55000000", "0.00000000"], ["111033.16000000", "0.04577000"], ["111033.67000000", "0.00005000"], ["111034.69000000", "0.00540000"], ["111034.79000000", "0.20299000"], ["111036.46000000", "0.04808000"]]}}
{"type": "orderbook", "local_time": 1761342357640, "event_time": 1761342357714, "latency_ms": -74, "data": {"e": "depthUpdate", "E": 1761342357714, "s": "BTCUSDT", "U": 79012688939, "u": 79012688965, "b": [["111028.02000000", "2.18121000"], ["111027.75000000", "0.29738000"], ["111027.49000000", "0.04648000"], ["111027.22000000", "0.03619000"], ["111025.24000000", "0.03449000"], ["111024.93000000", "0.00000000"], ["110903.70000000", "0.19453000"], ["110900.33000000", "0.00000000"]], "a": [["111028.03000000", "1.65423000"], ["111028.04000000", "0.00095000"], ["111033.16000000", "0.04577000"], ["111033.67000000", "0.00000000"], ["111034.69000000", "0.00545000"], ["111053.27000000", "0.00044000"], ["111125.23000000", "0.00000000"], ["111125.24000000", "0.00000000"]]}}
{"type": "orderbook", "local_time": 1761342357734, "event_time": 1761342357814, "latency_ms": -80, "data": {"e": "depthUpdate", "E": 1761342357814, "s": "BTCUSDT", "U": 79012688966, "u": 79012688971, "b": [["111028.02000000", "2.18126000"], ["111028.01000000", "0.86292000"], ["111017.10000000", "0.00000000"], ["111015.33000000", "0.30390000"], ["99925.00000000", "0.00510000"]], "a": [["111044.43000000", "0.00044000"]]}}
{"type": "orderbook", "local_time": 1761342357838, "event_time": 1761342357916, "latency_ms": -78, "data": {"e": "depthUpdate", "E": 1761342357916, "s": "BTCUSDT", "U": 79012688972, "u": 79012688976, "b": [["111022.13000000", "0.09615000"], ["111010.98000000", "0.20282000"], ["99925.00000000", "0.00530000"]], "a": []}}
{"type": "orderbook", "local_time": 1761342357938, "event_time": 1761342358014, "latency_ms": -76, "data": {"e": "depthUpdate", "E": 1761342358014, "s": "BTCUSDT", "U": 79012688977, "u": 79012688983, "b": [["111028.02000000", "2.18131000"], ["111028.01000000", "0.86297000"], ["99925.00000000", "0.00510000"]], "a": [["111028.03000000", "1.65419000"]]}}
{"type": "orderbook", "local_time": 1761342358044, "event_time": 1761342358115, "latency_ms": -71, "data": {"e": "depthUpdate", "E": 1761342358115, "s": "BTCUSDT", "U": 79012688984, "u": 79012688991, "b": [["111028.02000000", "2.22764000"], ["111027.49000000", "0.00015000"], ["111017.49000000", "0.00000000"], ["111016.72000000", "0.01801000"], ["99925.00000000", "0.00510000"]], "a": [["111036.76000000", "0.00000000"], ["111053.27000000", "0.00000000"]]}}
{"type": "orderbook", "local_time": 1761342358135, "event_time": 1761342358215, "latency_ms": -80, "data": {"e": "depthUpdate", "E": 1761342358215, "s": "BTCUSDT", "U": 79012688992, "u": 79012689007, "b": [["111028.02000000", "2.22759000"], ["111028.01000000", "0.86292000"], ["111027.75000000", "0.29738000"], ["111027.49000000", "0.00000000"], ["111027.22000000", "0.03629000"], ["111022.13000000", "0.09620000"]], "a": []}}
{"type": "orderbook", "local_time": 1761342358235, "event_time": 1761342358315, "latency_ms": -80, "data": {"e": "depthUpdate", "E": 1761342358315, "s": "BTCUSDT", "U": 79012689008, "u": 79012689010, "b": [["110200.00000000", "0.13735000"], ["110000.00000000", "7.19646000"]], "a": [["111125.22000000", "0.00100000"], ["111125.23000000", "0.00100000"]]}}
{"type": "orderbook", "local_time": 1761342358438, "event_time": 1761342358516, "latency_ms": -78, "data": {"e": "depthUpdate", "E": 1761342358516, "s": "BTCUSDT", "U": 79012689011, "u": 79012689011, "b": [["111028.02000000", "2.23004000"]], "a": []}}
{"type": "orderbook", "local_time": 1761342358534, "event_time": 1761342358614, "latency_ms": -80, "data": {"e": "depthUpdate", "E": 1761342358614, "s": "BTCUSDT", "U": 79012689012, "u": 79012689016, "b": [["99925.00000000", "0.00510000"]], "a": [["111028.03000000", "1.61045000"], ["111368.93000000", "0.48717000"]]}}
{"type": "orderbook", "local_time": 1761342358635, "event_time": 1761342358714, "latency_ms": -79, "data": {"e": "depthUpdate", "E": 1761342358714, "s": "BTCUSDT", "U": 79012689017, "u": 79012689019, "b": [["111028.02000000", "2.22956000"]], "a": [["111031.24000000", "0.00020000"]]}}
{"type": "orderbook", "local_time": 1761342358735, "event_time": 1761342358814, "latency_ms": -79, "data": {"e": "depthUpdate", "E": 1761342358814, "s": "BTCUSDT", "U": 79012689020, "u": 79012689039, "b": [["111028.02000000", "2.22973000"], ["42000.00000000", "1.36834000"]], "a": [["111028.03000000", "1.61040000"], ["111028.04000000", "0.00090000"], ["111029.70000000", "0.04082000"], ["111031.23000000", "0.00000000"], ["111031.24000000", "0.00010000"], ["111031.26000000", "0.81640000"], ["111032.55000000", "0.00005000"], ["111034.79000000", "0.20304000"], ["111036.46000000", "0.00000000"], ["111121.53000000", "0.03400000"], ["111124.38000000", "0.00000000"]]}}
{"type": "orderbook", "local_time": 1761342358847, "event_time": 1761342358914, "latency_ms": -67, "data": {"e": "depthUpdate", "E": 1761342358914, "s": "BTCUSDT", "U": 79012689040, "u": 79012689043, "b": [["111015.31000000", "0.00000000"]], "a": [["111028.03000000", "1.56537000"], ["111037.29000000", "0.04773000"]]}}
{"type": "orderbook", "local_time": 1761342358946, "event_time": 1761342359014, "latency_ms": -68, "data": {"e": "depthUpdate", "E": 1761342359014, "s": "BTCUSDT", "U": 79012689044, "u": 79012689050, "b": [["111028.02000000", "2.22960000"], ["111015.31000000", "0.00010000"], ["111005.25000000", "0.00250000"], ["111000.80000000", "0.00000000"], ["88822.00000000", "0.00337000"]], "a": []}}
{"type": "orderbook", "local_time": 1761342359043, "event_time": 1761342359114, "latency_ms": -71, "data": {"e": "depthUpdate", "E": 1761342359114, "s": "BTCUSDT", "U": 79012689051, "u": 79012689054, "b": [["110998.18000000", "0.00000000"], ["99925.00000000", "0.00510000"]], "a": [["111061.55000000", "0.00000000"]]}}
{"type": "orderbook", "local_time": 1761342359134, "event_time": 1761342359214, "latency_ms": -80, "data": {"e": "depthUpdate", "E": 1761342359214, "s": "BTCUSDT", "U": 79012689055, "u": 79012689055, "b": [], "a": [["111028.03000000", "1.50089000"]]}}
{"type": "orderbook", "local_time": 1761342359234, "event_time": 1761342359314, "latency_ms": -80, "data": {"e": "depthUpdate", "E": 1761342359314, "s": "BTCUSDT", "U": 79012689056, "u": 79012689057, "b": [["111022.47000000", "0.00005000"]], "a": [["111049.72000000", "0.03000000"]]}}
{"type": "orderbook", "local_time": 1761342359383, "event_time": 1761342359414, "latency_ms": -31, "data": {"e": "depthUpdate", "E": 1761342359414, "s": "BTCUSDT", "U": 79012689058, "u": 79012689061, "b": [["110998.27000000", "0.84681000"]], "a": [["111028.03000000", "1.56950000"], ["111037.29000000", "0.00000000"], ["111061.70000000", "0.97140000"]]}}
{"type": "orderbook", "local_time": 1761342359443, "event_time": 1761342359514, "latency_ms": -71, "data": {"e": "depthUpdate", "E": 1761342359514, "s": "BTCUSDT", "U": 79012689062, "u": 79012689065, "b": [["110787.39000000", "0.00000000"]], "a": [["111039.56000000", "0.04773000"], ["111049.70000000", "0.06818000"], ["111270.73000000", "0.00000000"]]}}
{"type": "orderbook", "local_time": 1761342359538, "event_time": 1761342359614, "latency_ms": -76, "data": {"e": "depthUpdate", "E": 1761342359614, "s": "BTCUSDT", "U": 79012689066, "u": 79012689076, "b": [["111028.02000000", "2.22916000"]], "a": [["111034.81000000", "0.00000000"], ["111034.82000000", "0.00000000"], ["111048.57000000", "0.00000000"], ["111121.53000000", "0.00000000"], ["111122.48000000", "0.03400000"], ["111125.22000000", "0.00000000"], ["111125.23000000", "0.00000000"]]}}
{"type": "orderbook", "local_time": 1761342359639, "event_time": 1761342359715, "latency_ms": -76, "data": {"e": "depthUpdate", "E": 1761342359715, "s": "BTCUSDT", "U": 79012689077, "u": 79012689085, "b": [["111028.02000000", "2.22948000"]], "a": [["111028.03000000", "1.56950000"], ["111034.58000000", "0.20745000"], ["111037.11000000", "0.04773000"], ["111039.56000000", "0.00000000"], ["111047.74000000", "0.01801000"]]}}
{"type": "orderbook", "local_time": 1761342359736, "event_time": 1761342359814, "latency_ms": -78, "data": {"e": "depthUpdate", "E": 1761342359814, "s": "BTCUSDT", "U": 79012689086, "u": 79012689099, "b": [["110956.33000000", "0.00000000"], ["110943.72000000", "0.03218000"], ["110787.37000000", "0.84842000"]], "a": [["111028.03000000", "1.56955000"], ["111028.04000000", "0.00095000"], ["111033.16000000", "0.04577000"], ["111034.58000000", "0.21470000"], ["111034.79000000", "0.20299000"], ["111047.74000000", "0.00000000"], ["111047.76000000", "0.01801000"], ["111270.46000000", "4.73859000"]]}}
{"type": "orderbook", "local_time": 1761342359834, "event_time": 1761342359914, "latency_ms": -80, "data": {"e": "depthUpdate", "E": 1761342359914, "s": "BTCUSDT", "U": 79012689100, "u": 79012689100, "b": [["102145.04000000", "0.00010000"]], "a": []}}
{"type": "orderbook", "local_time": 1761342359934, "event_time": 1761342360014, "latency_ms": -80, "data": {"e": "depthUpdate", "E": 1761342360014, "s": "BTCUSDT", "U": 79012689101, "u": 79012689106, "b": [["111016.72000000", "0.00000000"], ["111016.50000000", "0.01801000"], ["110924.01000000", "0.00224000"], ["110923.89000000", "0.00000000"], ["110900.32000000", "0.00191000"], ["110900.31000000", "0.04297000"]], "a": [["111069.97000000", "0.00016000"], ["111069.98000000", "0.03698000"], ["111221.98000000", "0.00090000"], ["111221.99000000", "0.24292000"]]}}
{"type": "orderbook", "local_time": 1761342360036, "event_time": 1761342360114, "latency_ms": -78, "data": {"e": "depthUpdate", "E": 1761342360114, "s": "BTCUSDT", "U": 79012689107, "u": 79012689107, "b": [], "a": [["111031.74000000", "0.00005000"]]}}
{"type": "orderbook", "local_time": 1761342360136, "event_time": 1761342360214, "latency_ms": -78, "data": {"e": "depthUpdate", "E": 1761342360214, "s": "BTCUSDT", "U": 79012689108, "u": 79012689125, "b": [["111028.02000000", "2.18315000"], ["111024.03000000", "0.04670000"], ["99925.00000000", "0.00520000"]], "a": [["111028.03000000", "1.57165000"], ["111028.04000000", "0.00090000"], ["111031.26000000", "0.81640000"], ["111031.74000000", "0.00000000"], ["111034.12000000", "0.04773000"], ["111034.79000000", "0.20304000"], ["111037.11000000", "0.00000000"], ["111049.70000000", "0.00000000"]]}}
{"type": "orderbook", "local_time": 1761342360236, "event_time": 1761342360314, "latency_ms": -78, "data": {"e": "depthUpdate", "E": 1761342360314, "s": "BTCUSDT", "U": 79012689126, "u": 79012689145, "b": [["111028.02000000", "2.23303000"], ["111024.24000000", "0.04005000"], ["111024.03000000", "0.00005000"], ["111022.13000000", "0.09615000"], ["99925.00000000", "0.00520000"]], "a": [["111028.03000000", "1.57041000"], ["111028.04000000", "0.00095000"], ["111033.16000000", "0.04577000"], ["111034.12000000", "0.00005000"], ["111034.79000000", "0.20299000"], ["111037.00000000", "0.04773000"]]}}
{"type": "orderbook", "local_time": 1761342360336, "event_time": 1761342360414, "latency_ms": -78, "data": {"e": "depthUpdate", "E": 1761342360414, "s": "BTCUSDT", "U": 79012689146, "u": 79012689171, "b": [["111028.02000000", "2.26896000"], ["111024.24000000", "0.04005000"], ["111024.03000000", "0.00000000"], ["111022.13000000", "0.09620000"], ["110999.77000000", "0.00000000"], ["110923.00000000", "0.11444000"], ["110918.09000000", "0.01410000"], ["110869.00000000", "0.00011000"], ["102145.04000000", "0.00000000"], ["99925.00000000", "0.00520000"]], "a": [["111028.03000000", "1.57026000"], ["111028.04000000", "0.00090000"], ["111033.16000000", "0.04577000"], ["111034.12000000", "0.00000000"], ["111034.79000000", "0.20304000"]]}}
{"type": "orderbook", "local_time": 1761342360438, "event_time": 1761342360514, "latency_ms": -76, "data": {"e": "depthUpdate", "E": 1761342360514, "s": "BTCUSDT", "U": 79012689172, "u": 79012689182, "b": [["111021.36000000", "0.02083000"], ["111020.82000000", "0.00005000"], ["111020.00000000", "0.00005000"], ["110999.78000000", "0.00576000"], ["109536.65000000", "0.00008000"], ["109502.51000000", "0.00000000"], ["99925.00000000", "0.00510000"]], "a": [["111036.76000000", "0.00044000"], ["111049.71000000", "0.06842000"], ["111053.27000000", "0.00044000"]]}}
{"type": "orderbook", "local_time": 1761342360546, "event_time": 1761342360614, "latency_ms": -68, "data": {"e": "depthUpdate", "E": 1761342360614, "s": "BTCUSDT", "U": 79012689183, "u": 79012689185, "b": [["110999.78000000", "0.00000000"]], "a": [["111028.03000000", "1.62080000"], ["111044.43000000", "0.00000000"]]}}
{"type": "orderbook", "local_time": 1761342360644, "event_time": 1761342360714, "latency_ms": -70, "data": {"e": "depthUpdate", "E": 1761342360714, "s": "BTCUSDT", "U": 79012689186, "u": 79012689189, "b": [["111015.31000000", "0.00000000"]], "a": [["111028.03000000", "1.47628000"]]}}
{"type": "orderbook", "local_time": 1761342360749, "event_time": 1761342360814, "latency_ms": -65, "data": {"e": "depthUpdate", "E": 1761342360814, "s": "BTCUSDT", "U": 79012689190, "u": 79012689196, "b": [["111015.31000000", "0.00010000"], ["110999.81000000", "0.00576000"], ["109599.87000000", "0.02498000"], ["42000.00000000", "1.36734000"]], "a": [["111042.74000000", "0.00044000"]]}}
{"type": "orderbook", "local_time": 1761342360941, "event_time": 1761342361014, "latency_ms": -73, "data": {"e": "depthUpdate", "E": 1761342361014, "s": "BTCUSDT", "U": 79012689197, "u": 79012689199, "b": [["110943.72000000", "0.00000000"], ["110930.25000000", "0.03218000"], ["109250.00000000", "0.22592000"]], "a": []}}
{"type": "orderbook", "local_time": 1761342361034, "event_time": 1761342361114, "latency_ms": -80, "data": {"e": "depthUpdate", "E": 1761342361114, "s": "BTCUSDT", "U": 79012689200, "u": 79012689201, "b": [["111020.82000000", "0.00012000"], ["108220.00000000", "0.00025000"]], "a": []}}
{"type": "orderbook", "local_time": 1761342361137, "event_time": 1761342361214, "latency_ms": -77, "data": {"e": "depthUpdate", "E": 1761342361214, "s": "BTCUSDT", "U": 79012689202, "u": 79012689202, "b": [["60000.00000000", "56.85876000"]], "a": []}}
{"type": "orderbook", "local_time": 1761342361236, "event_time": 1761342361314, "latency_ms": -78, "data": {"e": "depthUpdate", "E": 1761342361314, "s": "BTCUSDT", "U": 79012689203, "u": 79012689208, "b": [["111028.02000000", "2.23269000"], ["99925.00000000", "0.00510000"]], "a": [["111049.71000000", "0.00000000"]]}}
{"type": "orderbook", "local_time": 1761342361337, "event_time": 1761342361414, "latency_ms": -77, "data": {"e": "depthUpdate", "E": 1761342361414, "s": "BTCUSDT", "U": 79012689209, "u": 79012689209, "b": [], "a": [["111031.24000000", "0.20292000"]]}}
{"type": "orderbook", "local_time": 1761342361435, "event_time": 1761342361514, "latency_ms": -79, "data": {"e": "depthUpdate", "E": 1761342361514, "s": "BTCUSDT", "U": 79012689210, "u": 79012689226, "b": [["111015.31000000", "0.00000000"], ["110707.74000000", "0.00000000"], ["110706.75000000", "0.00572000"]], "a": [["111028.03000000", "1.47633000"], ["111029.70000000", "0.04082000"], ["111031.23000000", "0.00010000"], ["111031.24000000", "0.20302000"], ["111031.26000000", "0.81635000"], ["111032.55000000", "0.00000000"], ["111034.79000000", "0.20299000"]]}}
{"type": "orderbook", "local_time": 1761342361536, "event_time": 1761342361614, "latency_ms": -78, "data": {"e": "depthUpdate", "E": 1761342361614, "s": "BTCUSDT", "U": 79012689227, "u": 79012689246, "b": [["111028.02000000", "2.23245000"], ["111028.01000000", "0.86287000"], ["111009.23000000", "0.13524000"], ["111005.91000000", "0.13519000"], ["110995.66000000", "0.00000000"], ["110950.33000000", "0.00000000"], ["110942.36000000", "0.00000000"], ["99925.00000000", "0.00510000"]], "a": [["111035.26000000", "0.00000000"], ["111041.05000000", "0.00000000"], ["111041.91000000", "0.04508000"], ["111042.52000000", "0.16000000"], ["111097.73000000", "0.00055000"], ["111097.74000000", "0.00000000"], ["111208.78000000", "0.00019000"], ["111208.79000000", "0.00000000"]]}}
{"type": "orderbook", "local_time": 1761342361634, "event_time": 1761342361714, "latency_ms": -80, "data": {"e": "depthUpdate", "E": 1761342361714, "s": "BTCUSDT", "U": 79012689247, "u": 79012689326, "b": [["111028.02000000", "2.23240000"], ["111027.50000000", "0.00250000"], ["111023.75000000", "0.06748000"], ["111022.14000000", "0.00000000"], ["111019.70000000", "0.30388000"], ["111015.33000000", "0.00000000"], ["111012.63000000", "0.13511000"], ["111005.25000000", "0.00000000"], ["110998.30000000", "0.00000000"], ["110994.72000000", "0.04506000"], ["110991.98000000", "0.00000000"], ["110956.63000000", "0.13511000"], ["110955.09000000", "0.13524000"], ["110952.76000000", "0.13519000"], ["110940.12000000", "0.00000000"], ["110936.34000000", "0.22544000"], ["110935.97000000", "0.22535000"], ["110931.08000000", "0.18027000"], ["110925.50000000", "0.00000000"], ["110925.42000000", "0.00000000"], ["110904.60000000", "0.00000000"], ["110733.91000000", "0.02431000"], ["110574.27000000", "0.00000000"], ["60000.00000000", "56.85866000"], ["33000.00000000", "3.79445000"]], "a": [["111028.03000000", "0.66381000"], ["111031.25000000", "0.00020000"], ["111034.58000000", "0.00005000"], ["111034.79000000", "0.00000000"], ["111035.88000000", "0.00000000"], ["111036.40000000", "0.00000000"], ["111037.00000000", "0.00000000"], ["111039.96000000", "0.00000000"], ["111040.85000000", "0.00250000"], ["111040.94000000", "0.00000000"], ["111041.41000000", "0.04773000"], ["111042.11000000", "0.00000000"], ["111042.28000000", "0.00000000"], ["111042.52000000", "0.00000000"], ["111043.72000000", "0.16000000"], ["111043.81000000", "0.00000000"], ["111047.76000000", "0.00000000"], ["111048.31000000", "0.07661000"], ["111048.73000000", "0.00000000"], ["111049.12000000", "0.00000000"], ["111055.96000000", "0.13519000"], ["111057.99000000", "0.13511000"], ["111058.65000000", "0.00250000"], ["111061.61000000", "0.04514000"], ["111063.10000000", "0.00000000"], ["111095.57000000", "0.00000000"], ["111097.72000000", "0.00048000"], ["111097.73000000", "0.00007000"], ["111111.29000000", "0.13511000"], ["111208.77000000", "0.00019000"], ["111208.78000000", "0.00000000"], ["111402.10000000", "0.00000000"], ["111402.15000000", "0.00000000"], ["111402.74000000", "0.00000000"], ["111403.69000000", "0.00000000"], ["111420.48000000", "0.03698000"], ["111421.26000000", "0.03698000"], ["111422.17000000", "0.03698000"], ["111424.21000000", "0.03698000"], ["111559.19000000", "0.00000000"], ["111579.83000000", "0.03698000"], ["111580.43000000", "0.03698000"]]}}
{"type": "orderbook", "local_time": 1761342361735, "event_time": 1761342361814, "latency_ms": -79, "data": {"e": "depthUpdate", "E": 1761342361814, "s": "BTCUSDT", "U": 79012689327, "u": 79012689381, "b": [["111027.75000000", "0.29738000"], ["111027.50000000", "0.00255000"], ["111027.22000000", "0.03624000"], ["111024.24000000", "0.04005000"], ["111023.75000000", "0.06753000"], ["111022.13000000", "0.15209000"]], "a": [["111028.03000000", "0.66056000"], ["111028.04000000", "0.00090000"], ["111031.24000000", "0.20292000"], ["111031.25000000", "0.34775000"], ["111031.26000000", "0.81640000"], ["111032.55000000", "0.00005000"], ["111033.16000000", "0.04577000"], ["111034.58000000", "0.00000000"], ["111034.69000000", "0.00545000"], ["111034.79000000", "0.13127000"], ["111034.80000000", "0.20287000"], ["111035.83000000", "0.20745000"], ["111036.44000000", "0.01771000"], ["111049.14000000", "0.01801000"], ["111111.11000000", "0.10443000"], ["111125.22000000", "0.00100000"], ["111125.23000000", "0.00100000"]]}}
{"type": "orderbook", "local_time": 1761342361835, "event_time": 1761342361914, "latency_ms": -79, "data": {"e": "depthUpdate", "E": 1761342361914, "s": "BTCUSDT", "U": 79012689382, "u": 79012689423, "b": [["111028.02000000", "2.23265000"], ["111028.01000000", "0.86292000"], ["111019.70000000", "0.00000000"], ["111017.10000000", "0.30389000"], ["111015.31000000", "0.00010000"], ["110904.68000000", "0.00054000"], ["110896.69000000", "0.00000000"], ["110893.59000000", "0.00180000"], ["110885.60000000", "0.00000000"], ["99925.00000000", "0.00510000"]], "a": [["111028.03000000", "0.66071000"], ["111028.04000000", "0.00133000"], ["111031.24000000", "0.20302000"], ["111031.25000000", "0.34785000"], ["111031.26000000", "0.81635000"], ["111032.55000000", "0.00000000"], ["111034.69000000", "0.00545000"], ["111034.79000000", "0.13132000"], ["111034.80000000", "0.20282000"], ["111036.44000000", "0.01766000"], ["111039.16000000", "0.04773000"], ["111041.41000000", "0.00000000"], ["111368.93000000", "0.00000000"], ["111376.22000000", "0.48717000"]]}}
{"type": "orderbook", "local_time": 1761342361934, "event_time": 1761342362014, "latency_ms": -80, "data": {"e": "depthUpdate", "E": 1761342362014, "s": "BTCUSDT", "U": 79012689424, "u": 79012689431, "b": [["111028.02000000", "2.23254000"], ["88822.00000000", "0.00337000"]], "a": [["111028.03000000", "0.66066000"], ["111035.82000000", "0.00720000"], ["111053.27000000", "0.00000000"]]}}
{"type": "orderbook", "local_time": 1761342362036, "event_time": 1761342362114, "latency_ms": -78, "data": {"e": "depthUpdate", "E": 1761342362114, "s": "BTCUSDT", "U": 79012689432, "u": 79012689442, "b": [["111028.02000000", "2.22937000"], ["111000.00000000", "0.01039000"]], "a": [["111028.03000000", "0.73721000"], ["111028.04000000", "0.00133000"], ["111028.62000000", "0.00126000"], ["111036.76000000", "0.00000000"]]}}
{"type": "orderbook", "local_time": 1761342362139, "event_time": 1761342362214, "latency_ms": -75, "data": {"e": "depthUpdate", "E": 1761342362214, "s": "BTCUSDT", "U": 79012689443, "u": 79012689448, "b": [], "a": [["111028.04000000", "0.00133000"], ["111028.62000000", "0.00136000"], ["111028.95000000", "0.01365000"], ["111029.14000000", "0.00099000"]]}}
{"type": "orderbook", "local_time": 1761342362234, "event_time": 1761342362314, "latency_ms": -80, "data": {"e": "depthUpdate", "E": 1761342362314, "s": "BTCUSDT", "U": 79012689449, "u": 79012689451, "b": [["111028.02000000", "2.94067000"], ["111027.84000000", "0.03000000"], ["110796.55000000", "0.00000000"]], "a": []}}
{"type": "orderbook", "local_time": 1761342362333, "event_time": 1761342362414, "latency_ms": -81, "data": {"e": "depthUpdate", "E": 1761342362414, "s": "BTCUSDT", "U": 79012689452, "u": 79012689479, "b": [["111028.02000000", "2.94077000"], ["111028.01000000", "0.86297000"], ["111028.00000000", "2.47747000"], ["111027.84000000", "0.03020000"], ["111027.75000000", "0.29733000"], ["111027.50000000", "0.00000000"], ["111027.22000000", "0.03619000"], ["111023.32000000", "0.04572000"], ["111017.10000000", "0.00000000"], ["111013.90000000", "0.30390000"], ["111005.25000000", "0.00250000"], ["99925.00000000", "0.00510000"]], "a": [["111036.40000000", "0.00250000"], ["111036.58000000", "0.04773000"], ["111039.16000000", "0.00000000"], ["111058.65000000", "0.00000000"]]}}
{"type": "orderbook", "local_time": 1761342362438, "event_time": 1761342362514, "latency_ms": -76, "data": {"e": "depthUpdate", "E": 1761342362514, "s": "BTCUSDT", "U": 79012689480, "u": 79012689493, "b": [["111028.02000000", "2.94072000"], ["111028.01000000", "0.86292000"], ["111027.75000000", "0.29733000"], ["111022.13000000", "0.09615000"], ["110574.96000000", "0.00000000"], ["99925.00000000", "0.00510000"]], "a": [["111028.03000000", "0.73716000"], ["111034.79000000", "0.19347000"], ["111100.69000000", "0.00000000"], ["111103.39000000", "0.19452000"]]}}
{"type": "orderbook", "local_time": 1761342362534, "event_time": 1761342362614, "latency_ms": -80, "data": {"e": "depthUpdate", "E": 1761342362614, "s": "BTCUSDT", "U": 79012689494, "u": 79012689497, "b": [["111028.02000000", "2.97674000"], ["110532.60000000", "0.00000000"], ["110530.15000000", "0.00000000"], ["110527.56000000", "0.00000000"]], "a": []}}
{"type": "orderbook", "local_time": 1761342362638, "event_time": 1761342362714, "latency_ms": -76, "data": {"e": "depthUpdate", "E": 1761342362714, "s": "BTCUSDT", "U": 79012689498, "u": 79012689502, "b": [["110994.72000000", "0.00000000"], ["110556.30000000", "0.03698000"], ["110554.65000000", "0.03698000"], ["110553.34000000", "0.03698000"]], "a": [["111061.61000000", "0.00007000"]]}}
{"type": "orderbook", "local_time": 1761342362735, "event_time": 1761342362814, "latency_ms": -79, "data": {"e": "depthUpdate", "E": 1761342362814, "s": "BTCUSDT", "U": 79012689503, "u": 79012689507, "b": [["111028.02000000", "2.97694000"], ["110875.15000000", "0.06000000"], ["108252.32000000", "0.00092000"], ["99925.00000000", "0.00510000"]], "a": []}}
{"type": "orderbook", "local_time": 1761342362849, "event_time": 1761342362914, "latency_ms": -65, "data": {"e": "depthUpdate", "E": 1761342362914, "s": "BTCUSDT", "U": 79012689508, "u": 79012689519, "b": [["111028.02000000", "2.22994000"], ["110861.56000000", "0.00000000"], ["99925.00000000", "0.00510000"]], "a": [["111028.03000000", "0.73709000"], ["111035.26000000", "0.04508000"], ["111041.91000000", "0.00000000"]]}}
{"type": "orderbook", "local_time": 1761342362935, "event_time": 1761342363014, "latency_ms": -79, "data": {"e": "depthUpdate", "E": 1761342363014, "s": "BTCUSDT", "U": 79012689520, "u": 79012689536, "b": [["111028.02000000", "1.96864000"], ["111025.57000000", "0.04670000"], ["111023.75000000", "0.00005000"], ["110927.42000000", "0.03998000"], ["110920.01000000", "0.03998000"], ["110907.87000000", "0.00000000"], ["110904.93000000", "0.15992000"], ["103367.00000000", "0.00006000"]], "a": [["111028.03000000", "0.73709000"], ["111034.13000000", "0.04773000"], ["111034.67000000", "0.00720000"], ["111035.82000000", "0.00000000"], ["111036.58000000", "0.00000000"]]}}
{"type": "orderbook", "local_time": 1761342363039, "event_time": 1761342363114, "latency_ms": -75, "data": {"e": "depthUpdate", "E": 1761342363114, "s": "BTCUSDT", "U": 79012689537, "u": 79012689565, "b": [["111028.02000000", "1.96869000"], ["111028.01000000", "0.86297000"], ["111027.22000000", "0.03619000"], ["111025.57000000", "0.04675000"], ["111024.24000000", "0.04005000"], ["111023.75000000", "0.00000000"], ["111016.50000000", "0.00000000"], ["110805.96000000", "0.01891000"], ["110774.01000000", "0.00000000"]], "a": [["111028.03000000", "0.73714000"], ["111028.04000000", "0.00133000"], ["111033.16000000", "0.04577000"], ["111034.13000000", "0.04778000"], ["111034.67000000", "0.00725000"], ["111034.69000000", "0.00540000"], ["111034.79000000", "0.19342000"], ["111042.74000000", "0.00000000"]]}}
