{"type": "orderbook", "local_time": 1761342301534, "event_time": 1761342301614, "latency_ms": -80, "data": {"e": "depthUpdate", "E": 1761342301614, "s": "BTCUSDT", "U": 79012676633, "u": 79012676665, "b": [["111018.59000000", "4.78074000"], ["111018.58000000", "0.33182000"], ["111018.45000000", "0.00000000"], ["111018.44000000", "0.00000000"], ["111018.40000000", "0.00010000"], ["111018.39000000", "0.00020000"], ["111018.38000000", "0.00000000"], ["111018.36000000", "0.00000000"], ["111018.34000000", "0.03000000"], ["110919.60000000", "0.00005000"]], "a": [["111018.60000000", "0.65193000"], ["111049.95000000", "0.50911000"], ["111124.20000000", "0.00005000"]]}}
{"type": "orderbook", "local_time": 1761342301636, "event_time": 1761342301714, "latency_ms": -78, "data": {"e": "depthUpdate", "E": 1761342301714, "s": "BTCUSDT", "U": 79012676666, "u": 79012676707, "b": [["111018.59000000", "4.78021000"], ["111018.58000000", "0.33182000"], ["111018.40000000", "0.00000000"], ["111018.39000000", "0.00000000"], ["111018.35000000", "0.00010000"], ["111018.34000000", "0.00030000"], ["111018.33000000", "0.00000000"], ["111018.31000000", "0.00000000"], ["111018.30000000", "0.00000000"], ["111018.27000000", "0.03000000"], ["110903.46000000", "0.00005000"], ["99916.00000000", "0.00010000"], ["60000.00000000", "56.85866000"]], "a": [["111018.60000000", "0.65173000"], ["111024.31000000", "0.00010000"]]}}
{"type": "orderbook", "local_time": 1761342301735, "event_time": 1761342301814, "latency_ms": -79, "data": {"e": "depthUpdate", "E": 1761342301814, "s": "BTCUSDT", "U": 79012676708, "u": 79012676762, "b": [["111018.59000000", "4.78018000"], ["111018.58000000", "0.33182000"], ["111018.35000000", "0.00000000"], ["111018.34000000", "0.00020000"], ["111018.28000000", "0.00000000"], ["111018.27000000", "0.00020000"], ["111018.25000000", "0.00000000"], ["111018.23000000", "0.00000000"], ["111018.22000000", "0.00000000"], ["111018.21000000", "0.00000000"], ["111018.20000000", "0.00000000"], ["111017.80000000", "0.04953000"], ["111017.48000000", "0.00099000"], ["111015.30000000", "0.21054000"], ["110896.69000000", "0.00054000"], ["110885.60000000", "0.00180000"], ["110865.41000000", "0.00000000"], ["110854.33000000", "0.00000000"], ["110119.96000000", "0.00000000"], ["109231.90000000", "0.00000000"]], "a": [["111018.60000000", "0.65173000"], ["111018.61000000", "0.00095000"], ["111023.52000000", "0.29729000"], ["111024.30000000", "0.00000000"], ["111024.31000000", "0.00000000"], ["111024.92000000", "0.00010000"], ["111024.93000000", "0.21488000"], ["111025.96000000", "0.00005000"], ["111029.24000000", "0.78137000"]]}}
{"type": "orderbook", "local_time": 1761342301844, "event_time": 1761342301914, "latency_ms": -70, "data": {"e": "depthUpdate", "E": 1761342301914, "s": "BTCUSDT", "U": 79012676763, "u": 79012676821, "b": [["111018.59000000", "4.78023000"], ["111018.58000000", "0.33182000"], ["111018.34000000", "0.00000000"], ["111018.27000000", "0.00000000"], ["111018.15000000", "0.00000000"], ["111018.11000000", "0.00000000"], ["111018.09000000", "0.03000000"], ["111017.80000000", "0.04968000"], ["111017.48000000", "0.00109000"], ["111016.67000000", "0.06763000"], ["111015.30000000", "0.21059000"], ["111011.93000000", "0.00546000"], ["110967.16000000", "0.06646000"], ["108343.83000000", "0.00000000"], ["107455.77000000", "0.00000000"], ["106567.70000000", "0.00000000"], ["105679.64000000", "0.00000000"], ["104791.58000000", "0.00000000"], ["103903.51000000", "0.00000000"], ["103015.45000000", "0.00000000"], ["102127.38000000", "0.00000000"], ["99916.00000000", "0.00020000"], ["99463.19000000", "0.00000000"], ["98575.13000000", "0.00000000"], ["97687.06000000", "0.00000000"], ["96799.00000000", "0.00000000"], ["95910.93000000", "0.00000000"], ["94134.80000000", "0.00000000"], ["93246.74000000", "0.00000000"], ["92358.68000000", "0.00000000"], ["91470.61000000", "0.00000000"], ["90582.55000000", "0.00000000"], ["89694.48000000", "0.00000000"], ["88806.42000000", "0.00000000"]], "a": [["111030.44000000", "0.00000000"], ["111030.46000000", "0.02703000"], ["111044.33000000", "0.00900000"], ["111361.64000000", "0.48717000"], ["111365.28000000", "0.00000000"]]}}
{"type": "orderbook", "local_time": 1761342301936, "event_time": 1761342302014, "latency_ms": -78, "data": {"e": "depthUpdate", "E": 1761342302014, "s": "BTCUSDT", "U": 79012676822, "u": 79012676872, "b": [["111018.59000000", "4.12979000"], ["111018.58000000", "0.33182000"], ["111018.10000000", "0.00000000"], ["111018.09000000", "0.00025000"], ["111018.06000000", "0.00000000"], ["111018.04000000", "0.00000000"], ["111018.01000000", "0.03000000"], ["111017.80000000", "0.04958000"], ["111017.48000000", "0.00104000"], ["111016.67000000", "0.06758000"], ["111015.30000000", "0.21054000"], ["111011.93000000", "0.00541000"], ["111002.67000000", "0.00000000"], ["111001.98000000", "0.00044000"], ["110957.15000000", "0.00000000"], ["99916.00000000", "0.00010000"], ["88815.00000000", "0.00000000"]], "a": [["111018.60000000", "0.65173000"], ["111018.61000000", "0.00100000"], ["111027.27000000", "0.00000000"], ["111042.72000000", "0.00000000"], ["111081.49000000", "0.00000000"], ["111096.44000000", "0.00402000"], ["111256.64000000", "0.00000000"], ["111270.59000000", "0.00089000"]]}}
{"type": "orderbook", "local_time": 1761342302036, "event_time": 1761342302114, "latency_ms": -78, "data": {"e": "depthUpdate", "E": 1761342302114, "s": "BTCUSDT", "U": 79012676873, "u": 79012676914, "b": [["111018.59000000", "4.12895000"], ["111018.58000000", "0.33177000"], ["111018.09000000", "0.00000000"], ["111018.02000000", "0.00000000"], ["111018.01000000", "0.00025000"], ["111017.97000000", "0.00000000"], ["111017.94000000", "0.00000000"], ["111017.92000000", "0.00000000"], ["111017.90000000", "0.00000000"], ["111015.30000000", "0.21054000"], ["111001.98000000", "0.00000000"], ["110948.53000000", "0.00000000"], ["110635.24000000", "0.00000000"], ["101239.32000000", "0.00000000"], ["100351.25000000", "0.00000000"], ["95022.87000000", "0.00000000"]], "a": [["111058.57000000", "0.45079000"], ["111109.08000000", "0.18027000"]]}}
{"type": "orderbook", "local_time": 1761342302135, "event_time": 1761342302214, "latency_ms": -79, "data": {"e": "depthUpdate", "E": 1761342302214, "s": "BTCUSDT", "U": 79012676915, "u": 79012676950, "b": [["111018.58000000", "0.33177000"], ["111018.01000000", "0.00000000"], ["111017.88000000", "0.00000000"], ["111017.87000000", "0.00000000"], ["111017.85000000", "0.00000000"], ["111017.84000000", "0.00000000"], ["111017.83000000", "0.00000000"], ["111017.80000000", "0.04968000"], ["111017.48000000", "0.00109000"], ["111016.67000000", "0.00015000"], ["111011.93000000", "0.00546000"], ["110967.16000000", "0.00000000"], ["110965.76000000", "0.00000000"], ["110964.88000000", "0.06623000"]], "a": [["111058.57000000", "0.63106000"], ["111097.76000000", "0.13626000"], ["111109.08000000", "0.00000000"]]}}
{"type": "orderbook", "local_time": 1761342302234, "event_time": 1761342302315, "latency_ms": -81, "data": {"e": "depthUpdate", "E": 1761342302315, "s": "BTCUSDT", "U": 79012676951, "u": 79012676970, "b": [["111018.59000000", "4.12900000"], ["111018.58000000", "0.33182000"], ["111017.80000000", "0.04963000"], ["111017.79000000", "0.00000000"], ["111017.77000000", "0.00000000"], ["111017.48000000", "0.00109000"], ["111016.68000000", "0.00000000"], ["111016.67000000", "0.00000000"], ["111015.82000000", "0.00203000"], ["111015.30000000", "0.21059000"], ["111013.99000000", "0.00005000"], ["111011.78000000", "0.01763000"]], "a": []}}
{"type": "orderbook", "local_time": 1761342302334, "event_time": 1761342302414, "latency_ms": -80, "data": {"e": "depthUpdate", "E": 1761342302414, "s": "BTCUSDT", "U": 79012676971, "u": 79012676979, "b": [["111018.59000000", "4.12892000"], ["99916.00000000", "0.00010000"]], "a": [["111018.60000000", "0.68868000"]]}}
{"type": "orderbook", "local_time": 1761342302434, "event_time": 1761342302514, "latency_ms": -80, "data": {"e": "depthUpdate", "E": 1761342302514, "s": "BTCUSDT", "U": 79012676980, "u": 79012676984, "b": [["110789.60000000", "0.00000000"], ["99916.00000000", "0.00010000"]], "a": [["111035.07000000", "0.00000000"], ["111058.57000000", "0.45079000"]]}}
{"type": "orderbook", "local_time": 1761342302534, "event_time": 1761342302614, "latency_ms": -80, "data": {"e": "depthUpdate", "E": 1761342302614, "s": "BTCUSDT", "U": 79012676985, "u": 79012677081, "b": [["111018.59000000", "4.12137000"], ["111018.58000000", "0.33192000"], ["111018.15000000", "0.00000000"], ["111017.89000000", "0.06748000"], ["111017.81000000", "0.00000000"], ["111017.72000000", "0.20758000"], ["111015.74000000", "0.00720000"], ["111015.31000000", "0.00000000"], ["111015.30000000", "0.21049000"], ["111013.99000000", "0.00000000"], ["111013.98000000", "0.00005000"], ["111013.30000000", "0.30390000"], ["111005.33000000", "0.01801000"], ["111004.71000000", "0.00000000"], ["111003.44000000", "0.00000000"], ["110993.57000000", "0.14000000"], ["110988.85000000", "0.00000000"], ["110986.70000000", "0.00000000"], ["110985.67000000", "0.00000000"], ["110982.34000000", "0.00000000"], ["110981.31000000", "0.11358000"], ["110980.57000000", "0.00000000"], ["110974.19000000", "0.00000000"], ["110970.68000000", "0.00000000"], ["110932.99000000", "0.00000000"], ["110884.00000000", "0.00160000"], ["110760.72000000", "0.03698000"], ["110674.35000000", "0.00000000"], ["110651.07000000", "0.00000000"], ["110625.34000000", "0.03798000"], ["110515.94000000", "0.00000000"]], "a": [["111018.60000000", "0.50841000"], ["111023.51000000", "0.00020000"], ["111023.52000000", "0.00010000"], ["111024.93000000", "0.00010000"], ["111025.97000000", "0.00005000"], ["111026.06000000", "0.00000000"], ["111026.23000000", "0.29718000"], ["111027.25000000", "0.04513000"], ["111028.80000000", "0.00005000"], ["111029.25000000", "0.00000000"], ["111029.27000000", "0.00000000"], ["111029.71000000", "0.00000000"], ["111030.33000000", "0.00000000"], ["111030.47000000", "0.00000000"], ["111031.17000000", "0.14000000"], ["111032.37000000", "0.16000000"], ["111035.26000000", "0.00000000"], ["111035.35000000", "0.00000000"], ["111036.96000000", "0.01801000"], ["111038.35000000", "0.11267000"], ["111046.14000000", "0.00000000"], ["111047.99000000", "0.00000000"], ["111048.37000000", "0.18027000"], ["111056.92000000", "0.03798000"], ["111058.41000000", "0.03698000"], ["111058.57000000", "0.45079000"], ["111059.07000000", "0.00000000"], ["111080.37000000", "0.32404000"], ["111089.78000000", "0.00007000"], ["111097.76000000", "0.00000000"], ["111106.02000000", "0.00000000"], ["111108.95000000", "0.18027000"], ["111109.08000000", "0.00000000"], ["111199.79000000", "0.00000000"], ["111199.80000000", "0.00000000"], ["111530.78000000", "0.00000000"], ["111572.61000000", "0.03798000"]]}}
{"type": "orderbook", "local_time": 1761342302635, "event_time": 1761342302714, "latency_ms": -79, "data": {"e": "depthUpdate", "E": 1761342302714, "s": "BTCUSDT", "U": 79012677082, "u": 79012677238, "b": [["111018.59000000", "4.12132000"], ["111018.58000000", "0.33177000"], ["111017.89000000", "0.06773000"], ["111017.80000000", "0.04953000"], ["111017.72000000", "0.20768000"], ["111017.48000000", "0.00099000"], ["111017.39000000", "0.00435000"], ["111015.82000000", "0.00198000"], ["111015.74000000", "0.00725000"], ["111015.48000000", "0.00000000"], ["111015.30000000", "0.29674000"], ["111014.15000000", "0.00615000"], ["111013.98000000", "0.00000000"], ["111013.30000000", "0.30395000"], ["111013.29000000", "0.04191000"], ["111011.93000000", "0.00541000"], ["111011.78000000", "0.01758000"], ["111007.00000000", "0.01801000"], ["111005.33000000", "0.00000000"], ["111005.28000000", "0.00005000"], ["110990.75000000", "0.00009000"], ["110988.61000000", "0.00009000"], ["110987.57000000", "0.00009000"], ["110985.29000000", "0.04506000"], ["110982.47000000", "0.00009000"], ["110976.09000000", "0.00009000"], ["110934.88000000", "0.00090000"], ["110682.32000000", "0.00000000"]], "a": [["111018.60000000", "0.50841000"], ["111018.61000000", "0.00080000"], ["111020.00000000", "0.02026000"], ["111023.50000000", "0.00000000"], ["111023.51000000", "0.00000000"], ["111023.52000000", "0.00000000"], ["111024.92000000", "0.00000000"], ["111024.93000000", "0.00000000"], ["111025.26000000", "0.00545000"], ["111025.96000000", "0.00000000"], ["111025.97000000", "0.00000000"], ["111026.06000000", "0.00000000"], ["111026.22000000", "0.10273000"], ["111026.23000000", "0.00010000"], ["111027.24000000", "0.00161000"], ["111027.25000000", "0.04518000"], ["111027.27000000", "0.00044000"], ["111027.91000000", "0.00720000"], ["111028.80000000", "0.00000000"], ["111029.23000000", "0.00010000"], ["111029.24000000", "0.45113000"], ["111029.70000000", "0.04725000"], ["111030.33000000", "0.01805000"], ["111030.37000000", "0.00005000"], ["111030.38000000", "0.20287000"], ["111030.46000000", "0.00005000"], ["111030.65000000", "0.02703000"], ["111031.17000000", "0.14005000"], ["111034.62000000", "0.00000000"], ["111036.96000000", "0.00000000"], ["111038.06000000", "0.04736000"], ["111038.63000000", "0.01801000"], ["111044.33000000", "0.00000000"], ["111051.90000000", "0.04512000"], ["111059.76000000", "0.32410000"], ["111078.24000000", "0.23291000"], ["111080.37000000", "0.00000000"], ["111089.78000000", "0.00055000"], ["111111.46000000", "0.00000000"], ["111115.01000000", "0.00000000"], ["111115.06000000", "0.02500000"], ["111122.51000000", "0.00399000"], ["111199.99000000", "0.00019000"], ["111222.00000000", "0.03720000"]]}}
{"type": "orderbook", "local_time": 1761342302736, "event_time": 1761342302814, "latency_ms": -78, "data": {"e": "depthUpdate", "E": 1761342302814, "s": "BTCUSDT", "U": 79012677239, "u": 79012677288, "b": [["111006.50000000", "0.00005000"], ["111005.33000000", "0.00000000"], ["110870.15000000", "0.06000000"], ["110568.02000000", "0.00000000"], ["99916.00000000", "0.00010000"]], "a": [["111018.60000000", "0.50851000"], ["111018.61000000", "0.00090000"], ["111020.00000000", "0.02026000"], ["111025.26000000", "0.00545000"], ["111026.21000000", "0.04489000"], ["111026.22000000", "0.00010000"], ["111026.23000000", "0.00000000"], ["111027.25000000", "0.04518000"], ["111027.89000000", "0.20758000"], ["111027.91000000", "0.00725000"], ["111029.69000000", "0.00038000"], ["111029.70000000", "0.04725000"], ["111030.33000000", "0.01810000"], ["111030.38000000", "0.20287000"], ["111030.46000000", "0.00000000"], ["111031.17000000", "0.14000000"], ["111078.24000000", "0.11717000"]]}}
{"type": "orderbook", "local_time": 1761342302837, "event_time": 1761342302914, "latency_ms": -77, "data": {"e": "depthUpdate", "E": 1761342302914, "s": "BTCUSDT", "U": 79012677289, "u": 79012677339, "b": [["111018.59000000", "4.12120000"], ["111007.00000000", "0.02892000"], ["111002.13000000", "0.03600000"], ["110993.17000000", "0.00000000"], ["110948.33000000", "0.00000000"], ["110948.10000000", "0.03146000"], ["110842.89000000", "0.00000000"], ["99916.00000000", "0.00010000"]], "a": [["111018.60000000", "0.50851000"], ["111018.61000000", "0.00095000"], ["111020.00000000", "0.02026000"], ["111025.26000000", "0.00545000"], ["111026.20000000", "0.02763000"], ["111026.21000000", "0.00010000"], ["111026.22000000", "0.00000000"], ["111027.25000000", "0.04518000"], ["111027.88000000", "0.00010000"], ["111027.89000000", "0.20768000"], ["111029.24000000", "0.45108000"], ["111029.69000000", "0.00033000"], ["111030.37000000", "0.00000000"], ["111030.38000000", "0.20282000"], ["111031.17000000", "0.06000000"], ["111032.37000000", "0.00000000"], ["111033.67000000", "0.16000000"], ["111046.24000000", "0.00900000"]]}}
{"type": "orderbook", "local_time": 1761342302935, "event_time": 1761342303014, "latency_ms": -79, "data": {"e": "depthUpdate", "E": 1761342303014, "s": "BTCUSDT", "U": 79012677340, "u": 79012677384, "b": [["111018.59000000", "4.12090000"], ["111018.58000000", "0.33182000"], ["111017.89000000", "0.06778000"], ["111017.80000000", "0.04958000"], ["111017.72000000", "0.20773000"], ["111005.40000000", "0.00005000"], ["110922.90000000", "0.00000000"], ["110823.88000000", "0.02498000"], ["110703.48000000", "0.02498000"], ["110346.88000000", "0.00000000"], ["99916.00000000", "0.00010000"]], "a": [["111018.60000000", "0.50802000"], ["111018.61000000", "0.00090000"], ["111020.00000000", "0.02026000"], ["111025.26000000", "0.00545000"], ["111026.06000000", "0.04903000"], ["111026.19000000", "0.02248000"], ["111026.20000000", "0.00010000"], ["111026.21000000", "0.00000000"], ["111032.87000000", "0.08000000"], ["111061.50000000", "0.00010000"]]}}
{"type": "orderbook", "local_time": 1761342303034, "event_time": 1761342303114, "latency_ms": -80, "data": {"e": "depthUpdate", "E": 1761342303114, "s": "BTCUSDT", "U": 79012677385, "u": 79012677419, "b": [["111018.59000000", "4.66146000"]], "a": [["111018.60000000", "0.50817000"], ["111018.61000000", "0.00095000"], ["111020.00000000", "0.02026000"], ["111025.26000000", "0.00545000"], ["111026.05000000", "0.03581000"], ["111026.06000000", "0.04913000"], ["111026.18000000", "0.00010000"], ["111026.19000000", "0.00010000"], ["111026.20000000", "0.00000000"], ["111027.89000000", "0.20763000"], ["111029.23000000", "0.00000000"], ["111030.33000000", "0.01805000"], ["111030.65000000", "0.00000000"], ["111030.70000000", "0.02703000"], ["111111.51000000", "0.03400000"]]}}
{"type": "orderbook", "local_time": 1761342303134, "event_time": 1761342303214, "latency_ms": -80, "data": {"e": "depthUpdate", "E": 1761342303214, "s": "BTCUSDT", "U": 79012677420, "u": 79012677444, "b": [], "a": [["111018.60000000", "0.50725000"], ["111018.61000000", "0.00095000"], ["111020.00000000", "0.02026000"], ["111025.26000000", "0.00545000"], ["111026.04000000", "0.00010000"], ["111026.05000000", "0.03591000"], ["111026.06000000", "0.04908000"], ["111026.18000000", "0.00000000"], ["111026.19000000", "0.00000000"]]}}
{"type": "orderbook", "local_time": 1761342303244, "event_time": 1761342303314, "latency_ms": -70, "data": {"e": "depthUpdate", "E": 1761342303314, "s": "BTCUSDT", "U": 79012677445, "u": 79012677462, "b": [["111018.59000000", "4.69730000"], ["111017.90000000", "0.00010000"], ["111017.81000000", "0.00010000"], ["111017.73000000", "0.00010000"], ["111015.31000000", "0.00005000"], ["110893.57000000", "0.19456000"], ["110863.07000000", "0.00000000"], ["110126.19000000", "0.00000000"]], "a": [["111018.60000000", "0.50733000"], ["111026.06000000", "0.04913000"]]}}
{"type": "orderbook", "local_time": 1761342303337, "event_time": 1761342303414, "latency_ms": -77, "data": {"e": "depthUpdate", "E": 1761342303414, "s": "BTCUSDT", "U": 79012677463, "u": 79012677469, "b": [["111018.59000000", "4.69720000"], ["110780.18000000", "0.00000000"], ["110718.59000000", "0.00000000"], ["99916.00000000", "0.00010000"]], "a": [["111280.01000000", "0.00000000"]]}}
{"type": "orderbook", "local_time": 1761342303434, "event_time": 1761342303514, "latency_ms": -80, "data": {"e": "depthUpdate", "E": 1761342303514, "s": "BTCUSDT", "U": 79012677470, "u": 79012677480, "b": [["111018.59000000", "4.66118000"], ["110959.43000000", "0.03146000"], ["110948.10000000", "0.00000000"], ["110935.21000000", "0.00000000"], ["109905.94000000", "0.00000000"]], "a": [["111026.06000000", "0.00010000"], ["111030.33000000", "0.00000000"], ["111048.09000000", "0.00000000"], ["111060.79000000", "0.00000000"], ["111140.00000000", "0.00245000"]]}}
{"type": "orderbook", "local_time": 1761342303535, "event_time": 1761342303614, "latency_ms": -79, "data": {"e": "depthUpdate", "E": 1761342303614, "s": "BTCUSDT", "U": 79012677481, "u": 79012677514, "b": [["111018.59000000", "4.77111000"], ["111006.50000000", "0.00013000"], ["111003.35000000", "0.03600000"], ["110959.43000000", "0.00000000"], ["110928.69000000", "0.03146000"], ["110779.72000000", "0.82357000"], ["99916.00000000", "0.00010000"]], "a": [["111018.60000000", "0.50723000"], ["111018.61000000", "0.00085000"], ["111026.05000000", "0.01446000"], ["111026.06000000", "0.00000000"], ["111027.89000000", "0.20768000"], ["111029.23000000", "0.00005000"], ["111029.70000000", "0.04725000"], ["111030.38000000", "0.20287000"], ["111042.72000000", "0.00044000"], ["111265.45000000", "4.62104000"], ["111361.64000000", "0.48717000"]]}}
{"type": "orderbook", "local_time": 1761342303635, "event_time": 1761342303715, "latency_ms": -80, "data": {"e": "depthUpdate", "E": 1761342303715, "s": "BTCUSDT", "U": 79012677515, "u": 79012677516, "b": [["111018.59000000", "4.76111000"], ["110888.11000000", "0.00000000"]], "a": []}}
{"type": "orderbook", "local_time": 1761342303733, "event_time": 1761342303814, "latency_ms": -81, "data": {"e": "depthUpdate", "E": 1761342303814, "s": "BTCUSDT", "U": 79012677517, "u": 79012677521, "b": [["110994.24000000", "0.00000000"], ["110985.29000000", "0.00000000"], ["110920.61000000", "0.00000000"]], "a": [["111051.90000000", "0.00005000"]]}}
{"type": "orderbook", "local_time": 1761342303843, "event_time": 1761342303914, "latency_ms": -71, "data": {"e": "depthUpdate", "E": 1761342303914, "s": "BTCUSDT", "U": 79012677522, "u": 79012677524, "b": [["111018.59000000", "4.79713000"], ["110994.87000000", "0.05477000"], ["110898.11000000", "0.01410000"]], "a": []}}
{"type": "orderbook", "local_time": 1761342303961, "event_time": 1761342304014, "latency_ms": -53, "data": {"e": "depthUpdate", "E": 1761342304014, "s": "BTCUSDT", "U": 79012677525, "u": 79012677557, "b": [["111018.59000000", "5.49596000"], ["111007.00000000", "0.01091000"], ["110898.11000000", "0.00000000"], ["110130.44000000", "0.00181000"], ["109242.29000000", "0.00183000"], ["108354.14000000", "0.00184000"], ["107465.99000000", "0.00186000"], ["106577.84000000", "0.00187000"], ["105689.69000000", "0.00189000"], ["104801.54000000", "0.00190000"], ["103913.40000000", "0.00192000"], ["103025.25000000", "0.00194000"], ["102137.10000000", "0.00205000"], ["101248.95000000", "0.00197000"], ["100360.80000000", "0.00199000"], ["99916.00000000", "0.00010000"], ["99472.65000000", "0.00201000"], ["98584.50000000", "0.00202000"], ["97696.35000000", "0.00204000"], ["96808.21000000", "0.00206000"], ["95920.06000000", "0.00208000"], ["95031.91000000", "0.00210000"], ["94143.76000000", "0.00212000"], ["93255.61000000", "0.00214000"], ["92367.46000000", "0.00216000"], ["91479.31000000", "0.00218000"], ["90591.16000000", "0.00220000"], ["89703.02000000", "0.00222000"], ["88814.87000000", "0.00225000"]], "a": [["111060.84000000", "0.06843000"]]}}
{"type": "orderbook", "local_time": 1761342304035, "event_time": 1761342304114, "latency_ms": -79, "data": {"e": "depthUpdate", "E": 1761342304114, "s": "BTCUSDT", "U": 79012677558, "u": 79012677587, "b": [["111018.59000000", "4.40583000"], ["111017.89000000", "0.00030000"], ["111013.30000000", "0.00005000"], ["111010.61000000", "0.30391000"], ["111007.00000000", "0.00000000"], ["111005.40000000", "0.01100000"], ["111003.17000000", "0.00000000"], ["110971.09000000", "0.00000000"], ["110953.01000000", "0.03146000"], ["110928.69000000", "0.00000000"], ["109873.00000000", "0.00000000"]], "a": [["111018.60000000", "1.18327000"], ["111027.27000000", "0.00000000"], ["111030.33000000", "0.01835000"], ["111042.72000000", "0.00000000"], ["111058.57000000", "0.58597000"], ["111060.71000000", "0.00000000"], ["111082.76000000", "0.00000000"], ["111108.91000000", "0.00000000"], ["111108.95000000", "0.00000000"], ["111120.15000000", "0.00000000"]]}}
{"type": "orderbook", "local_time": 1761342304146, "event_time": 1761342304214, "latency_ms": -68, "data": {"e": "depthUpdate", "E": 1761342304214, "s": "BTCUSDT", "U": 79012677588, "u": 79012677670, "b": [["111018.59000000", "4.34727000"], ["111018.58000000", "0.33182000"], ["111017.90000000", "0.00000000"], ["111017.89000000", "0.00020000"], ["111017.72000000", "0.00015000"], ["111015.31000000", "0.00010000"], ["111015.30000000", "0.29684000"], ["111014.15000000", "0.00365000"], ["111014.12000000", "0.04691000"], ["111013.30000000", "0.00000000"], ["111013.29000000", "0.04196000"], ["111012.60000000", "0.20758000"], ["111012.00000000", "0.00005000"], ["111011.93000000", "0.00546000"], ["111010.62000000", "0.11323000"], ["111010.61000000", "0.00000000"], ["111010.60000000", "0.00000000"], ["111008.75000000", "0.00000000"], ["111007.33000000", "0.00000000"], ["111005.76000000", "0.00000000"], ["111005.41000000", "0.00000000"], ["111003.36000000", "0.00450000"], ["111002.51000000", "0.00000000"], ["111002.41000000", "0.00000000"], ["111001.47000000", "0.01801000"], ["110999.83000000", "0.30394000"], ["110999.72000000", "0.00000000"], ["110998.79000000", "0.08926000"], ["110991.90000000", "0.00250000"], ["110984.95000000", "0.13518000"], ["110984.38000000", "0.00000000"], ["110963.30000000", "0.32438000"], ["110953.01000000", "0.00000000"], ["110935.30000000", "0.03146000"], ["110718.59000000", "0.00000000"]], "a": [["111018.60000000", "1.41277000"], ["111022.94000000", "0.21478000"], ["111023.38000000", "0.29719000"], ["111027.50000000", "0.00250000"], ["111027.55000000", "0.04736000"], ["111027.89000000", "0.00010000"], ["111027.91000000", "0.00005000"], ["111029.23000000", "1.44347000"], ["111029.70000000", "0.04725000"], ["111030.33000000", "0.01840000"], ["111030.38000000", "0.20282000"], ["111030.85000000", "0.00000000"], ["111031.82000000", "0.00000000"], ["111034.04000000", "0.01801000"], ["111034.41000000", "0.00000000"], ["111034.67000000", "0.00000000"], ["111038.06000000", "0.00000000"], ["111038.63000000", "0.00000000"], ["111047.63000000", "0.06748000"], ["111049.75000000", "0.00000000"], ["111058.57000000", "0.58597000"], ["111083.30000000", "0.00000000"], ["111096.99000000", "0.04008000"], ["111097.76000000", "0.13507000"], ["111120.83000000", "0.00000000"]]}}
{"type": "orderbook", "local_time": 1761342304235, "event_time": 1761342304314, "latency_ms": -79, "data": {"e": "depthUpdate", "E": 1761342304314, "s": "BTCUSDT", "U": 79012677671, "u": 79012677796, "b": [["111018.59000000", "4.10003000"], ["111018.58000000", "0.33182000"], ["111017.89000000", "0.00000000"], ["111017.80000000", "0.04968000"], ["111017.73000000", "0.00000000"], ["111017.72000000", "0.00000000"], ["111017.48000000", "0.00109000"], ["111017.39000000", "0.00440000"], ["111015.74000000", "0.00005000"], ["111015.30000000", "0.29689000"], ["111015.29000000", "0.33162000"], ["111014.15000000", "0.00360000"], ["111014.13000000", "0.00005000"], ["111014.12000000", "0.04696000"], ["111013.92000000", "0.29722000"], ["111013.29000000", "0.04196000"], ["111012.60000000", "0.20763000"], ["111012.56000000", "0.00720000"], ["111010.62000000", "0.00000000"], ["111002.10000000", "0.00005000"], ["111001.47000000", "0.00000000"], ["111001.43000000", "0.01801000"], ["110988.86000000", "0.09352000"], ["110977.18000000", "0.41551000"], ["110929.50000000", "0.00005000"], ["110926.20000000", "0.00000000"]], "a": [["111018.60000000", "1.45931000"], ["111018.61000000", "0.00095000"], ["111020.00000000", "0.02026000"], ["111020.55000000", "0.29720000"], ["111022.93000000", "0.18509000"], ["111022.94000000", "0.21488000"], ["111023.05000000", "0.00250000"], ["111023.37000000", "0.00010000"], ["111023.38000000", "0.00010000"], ["111026.04000000", "0.00000000"], ["111026.05000000", "0.00010000"], ["111026.98000000", "0.20282000"], ["111027.25000000", "0.00005000"], ["111027.54000000", "0.00005000"], ["111027.55000000", "0.04741000"], ["111027.88000000", "0.00000000"], ["111027.89000000", "0.00000000"], ["111027.91000000", "0.00000000"], ["111029.22000000", "0.83947000"], ["111029.23000000", "1.44347000"], ["111029.24000000", "0.00005000"], ["111029.70000000", "0.04720000"], ["111030.33000000", "0.01835000"], ["111031.92000000", "0.00000000"], ["111032.13000000", "0.00000000"], ["111032.24000000", "0.00000000"], ["111045.30000000", "0.00000000"], ["111068.10000000", "0.00005000"]]}}
{"type": "orderbook", "local_time": 1761342304335, "event_time": 1761342304414, "latency_ms": -79, "data": {"e": "depthUpdate", "E": 1761342304414, "s": "BTCUSDT", "U": 79012677797, "u": 79012677871, "b": [["111017.80000000", "0.04968000"], ["111015.74000000", "0.00000000"], ["111014.12000000", "0.04696000"], ["111013.92000000", "0.29727000"], ["111012.60000000", "0.20763000"], ["111012.56000000", "0.00725000"], ["111011.93000000", "0.00541000"]], "a": [["111018.60000000", "1.46005000"], ["111018.61000000", "0.00100000"], ["111020.00000000", "0.02026000"], ["111020.54000000", "0.09135000"], ["111020.55000000", "0.29730000"], ["111022.92000000", "0.00010000"], ["111022.93000000", "0.13637000"], ["111022.94000000", "0.21488000"], ["111023.37000000", "0.00000000"], ["111023.38000000", "0.00000000"], ["111025.26000000", "0.00545000"], ["111026.05000000", "0.00000000"], ["111026.97000000", "0.00005000"], ["111026.98000000", "0.20287000"], ["111027.24000000", "0.00151000"], ["111027.25000000", "0.00000000"], ["111027.55000000", "0.04741000"], ["111029.22000000", "0.83952000"], ["111029.23000000", "1.44347000"], ["111029.24000000", "0.00000000"]]}}
{"type": "orderbook", "local_time": 1761342304434, "event_time": 1761342304514, "latency_ms": -80, "data": {"e": "depthUpdate", "E": 1761342304514, "s": "BTCUSDT", "U": 79012677872, "u": 79012677892, "b": [["110914.65000000", "0.00224000"], ["110907.26000000", "0.00000000"], ["110804.01000000", "0.00090000"], ["110780.01000000", "0.00000000"], ["102137.10000000", "0.00195000"]], "a": [["111018.60000000", "1.46005000"], ["111018.61000000", "0.00105000"], ["111020.00000000", "0.02026000"], ["111020.53000000", "0.00010000"], ["111020.54000000", "0.09145000"], ["111022.94000000", "0.21483000"], ["111026.97000000", "0.00000000"], ["111027.54000000", "0.00000000"], ["111029.23000000", "1.44342000"], ["111030.97000000", "0.00450000"], ["111038.61000000", "0.00000000"]]}}
{"type": "orderbook", "local_time": 1761342304546, "event_time": 1761342304614, "latency_ms": -68, "data": {"e": "depthUpdate", "E": 1761342304614, "s": "BTCUSDT", "U": 79012677893, "u": 79012677930, "b": [["111018.59000000", "4.14469000"], ["111017.07000000", "0.00000000"], ["111016.94000000", "0.29721000"], ["111014.15000000", "0.00610000"], ["111014.12000000", "0.00005000"], ["111013.92000000", "0.00005000"], ["111012.56000000", "0.00005000"], ["111012.55000000", "0.00720000"], ["110998.79000000", "0.08111000"], ["110991.90000000", "0.00000000"], ["110891.04000000", "0.00191000"], ["110868.01000000", "0.00000000"], ["110780.02000000", "0.00076000"], ["110761.06000000", "0.00090000"], ["110756.01000000", "0.00000000"], ["110737.51000000", "0.00000000"], ["99916.00000000", "0.00020000"]], "a": [["111018.60000000", "1.41492000"], ["111018.61000000", "0.00100000"], ["111022.94000000", "0.00005000"], ["111023.05000000", "0.00000000"], ["111027.25000000", "0.04508000"], ["111027.55000000", "0.00005000"], ["111030.97000000", "0.00000000"], ["111031.94000000", "0.00450000"], ["111033.06000000", "0.04736000"], ["111034.69000000", "0.27041000"], ["111044.41000000", "0.00000000"], ["111045.30000000", "0.00250000"], ["111058.57000000", "0.58597000"], ["111108.94000000", "0.00000000"]]}}
{"type": "orderbook", "local_time": 1761342304647, "event_time": 1761342304714, "latency_ms": -67, "data": {"e": "depthUpdate", "E": 1761342304714, "s": "BTCUSDT", "U": 79012677931, "u": 79012677992, "b": [["111018.59000000", "4.15289000"], ["111017.80000000", "0.04968000"], ["111017.39000000", "0.00440000"], ["111016.95000000", "0.00010000"], ["111016.94000000", "0.29726000"], ["111015.29000000", "0.33157000"], ["111014.15000000", "0.00615000"], ["111014.13000000", "0.00000000"], ["111014.12000000", "0.00000000"], ["111013.92000000", "0.00000000"], ["111012.60000000", "0.20763000"], ["111012.56000000", "0.00000000"], ["111012.55000000", "0.00725000"], ["99916.00000000", "0.00010000"]], "a": [["111018.60000000", "1.41345000"], ["111018.61000000", "0.00085000"], ["111021.96000000", "0.20758000"], ["111022.93000000", "0.07463000"], ["111022.94000000", "0.00000000"], ["111026.97000000", "0.00005000"], ["111026.98000000", "0.20287000"], ["111027.25000000", "0.04513000"], ["111027.55000000", "0.00000000"], ["111029.23000000", "1.44347000"], ["111030.71000000", "0.00073000"], ["111058.57000000", "0.22535000"], ["111109.40000000", "0.22544000"], ["111109.47000000", "0.13518000"], ["111113.60000000", "0.00100000"], ["111113.61000000", "0.00100000"]]}}
{"type": "orderbook", "local_time": 1761342304736, "event_time": 1761342304814, "latency_ms": -78, "data": {"e": "depthUpdate", "E": 1761342304814, "s": "BTCUSDT", "U": 79012677993, "u": 79012678027, "b": [["110983.44000000", "0.32433000"], ["110963.30000000", "0.00000000"], ["99916.00000000", "0.00010000"]], "a": [["111018.60000000", "1.41492000"], ["111018.61000000", "0.00090000"], ["111020.54000000", "0.14178000"], ["111020.55000000", "0.29730000"], ["111021.94000000", "0.00720000"], ["111021.95000000", "0.00010000"], ["111021.96000000", "0.20768000"], ["111022.93000000", "0.07298000"], ["111026.97000000", "0.00000000"], ["111029.23000000", "1.44342000"], ["111030.56000000", "0.00000000"], ["111030.71000000", "0.00000000"], ["111040.34000000", "0.00000000"], ["111058.57000000", "0.00000000"], ["111082.36000000", "0.13531000"], ["111109.01000000", "0.22535000"]]}}
{"type": "orderbook", "local_time": 1761342304835, "event_time": 1761342304914, "latency_ms": -79, "data": {"e": "depthUpdate", "E": 1761342304914, "s": "BTCUSDT", "U": 79012678028, "u": 79012678040, "b": [["111018.59000000", "4.15199000"]], "a": [["111018.60000000", "1.41497000"], ["111018.61000000", "0.00095000"], ["111020.55000000", "0.29730000"], ["111021.94000000", "0.00725000"], ["111029.22000000", "0.83947000"], ["111058.57000000", "0.58597000"], ["111109.01000000", "0.00000000"], ["111109.40000000", "0.00000000"], ["111109.47000000", "0.00000000"]]}}
{"type": "orderbook", "local_time": 1761342304934, "event_time": 1761342305014, "latency_ms": -80, "data": {"e": "depthUpdate", "E": 1761342305014, "s": "BTCUSDT", "U": 79012678041, "u": 79012678048, "b": [["88815.00000000", "0.00000000"]], "a": [["111058.57000000", "0.00000000"], ["111109.41000000", "0.22535000"], ["111109.74000000", "0.13518000"], ["111110.11000000", "0.22544000"]]}}
{"type": "orderbook", "local_time": 1761342305042, "event_time": 1761342305114, "latency_ms": -72, "data": {"e": "depthUpdate", "E": 1761342305114, "s": "BTCUSDT", "U": 79012678049, "u": 79012678055, "b": [["111018.59000000", "4.50710000"]], "a": [["111018.60000000", "1.41355000"], ["111019.62000000", "0.04911000"], ["111030.51000000", "0.00109000"], ["111030.66000000", "0.00073000"]]}}
{"type": "orderbook", "local_time": 1761342305135, "event_time": 1761342305214, "latency_ms": -79, "data": {"e": "depthUpdate", "E": 1761342305214, "s": "BTCUSDT", "U": 79012678056, "u": 79012678078, "b": [], "a": [["111018.60000000", "1.41425000"], ["111018.61000000", "0.00100000"], ["111019.61000000", "0.00010000"], ["111019.62000000", "0.04931000"], ["111020.00000000", "0.02021000"], ["111020.47000000", "0.00059000"], ["111021.96000000", "0.20763000"], ["111022.92000000", "0.00000000"], ["111027.25000000", "0.04508000"], ["111030.51000000", "0.00039000"]]}}
{"type": "orderbook", "local_time": 1761342305252, "event_time": 1761342305314, "latency_ms": -62, "data": {"e": "depthUpdate", "E": 1761342305314, "s": "BTCUSDT", "U": 79012678079, "u": 79012678081, "b": [["99916.00000000", "0.00020000"]], "a": [["111018.60000000", "1.41498000"], ["111030.66000000", "0.00000000"]]}}
{"type": "orderbook", "local_time": 1761342305338, "event_time": 1761342305414, "latency_ms": -76, "data": {"e": "depthUpdate", "E": 1761342305414, "s": "BTCUSDT", "U": 79012678082, "u": 79012678087, "b": [["99916.00000000", "0.00020000"]], "a": [["111361.64000000", "0.48717000"]]}}
{"type": "orderbook", "local_time": 1761342305442, "event_time": 1761342305514, "latency_ms": -72, "data": {"e": "depthUpdate", "E": 1761342305514, "s": "BTCUSDT", "U": 79012678088, "u": 79012678097, "b": [["111018.59000000", "4.51135000"], ["111015.82000000", "0.01313000"], ["111006.50000000", "0.00005000"], ["111005.40000000", "0.00005000"], ["110917.18000000", "0.00000000"], ["99916.00000000", "0.00010000"]], "a": []}}
{"type": "orderbook", "local_time": 1761342305535, "event_time": 1761342305614, "latency_ms": -79, "data": {"e": "depthUpdate", "E": 1761342305614, "s": "BTCUSDT", "U": 79012678098, "u": 79012678106, "b": [["111018.59000000", "4.50689000"], ["111016.94000000", "0.29726000"], ["111015.82000000", "0.01318000"], ["111015.30000000", "0.29684000"], ["111012.55000000", "0.00720000"], ["111004.45000000", "0.00450000"], ["111003.36000000", "0.00000000"], ["110926.20000000", "0.00005000"]], "a": []}}
{"type": "orderbook", "local_time": 1761342305645, "event_time": 1761342305714, "latency_ms": -69, "data": {"e": "depthUpdate", "E": 1761342305714, "s": "BTCUSDT", "U": 79012678107, "u": 79012678116, "b": [["110988.86000000", "0.18620000"], ["110944.34000000", "0.00510000"], ["110841.34000000", "0.00000000"], ["110673.91000000", "0.03698000"], ["110656.63000000", "0.00000000"], ["109599.87000000", "0.02503000"]], "a": [["111018.60000000", "1.41425000"], ["111019.62000000", "0.00020000"], ["111096.32000000", "0.00390000"]]}}
{"type": "orderbook", "local_time": 1761342305735, "event_time": 1761342305814, "latency_ms": -79, "data": {"e": "depthUpdate", "E": 1761342305814, "s": "BTCUSDT", "U": 79012678117, "u": 79012678139, "b": [["99916.00000000", "0.00030000"]], "a": [["111018.60000000", "1.41350000"], ["111018.61000000", "0.00095000"], ["111019.61000000", "0.00000000"], ["111019.62000000", "0.00000000"], ["111020.00000000", "0.02026000"], ["111020.47000000", "0.00064000"], ["111021.96000000", "0.20768000"], ["111022.92000000", "0.00005000"], ["111027.25000000", "0.04513000"], ["111030.52000000", "0.00069000"], ["111030.65000000", "0.00072000"]]}}
{"type": "orderbook", "local_time": 1761342305837, "event_time": 1761342305914, "latency_ms": -77, "data": {"e": "depthUpdate", "E": 1761342305914, "s": "BTCUSDT", "U": 79012678140, "u": 79012678143, "b": [["110940.89000000", "0.00389000"], ["99916.00000000", "0.00010000"]], "a": [["111018.60000000", "1.41419000"], ["111030.52000000", "0.00000000"]]}}
{"type": "orderbook", "local_time": 1761342305935, "event_time": 1761342306014, "latency_ms": -79, "data": {"e": "depthUpdate", "E": 1761342306014, "s": "BTCUSDT", "U": 79012678144, "u": 79012678145, "b": [], "a": [["111018.60000000", "1.41350000"], ["111030.51000000", "0.00109000"]]}}
{"type": "orderbook", "local_time": 1761342306037, "event_time": 1761342306114, "latency_ms": -77, "data": {"e": "depthUpdate", "E": 1761342306114, "s": "BTCUSDT", "U": 79012678146, "u": 79012678149, "b": [["111004.45000000", "0.00000000"], ["111003.36000000", "0.00450000"]], "a": [["111018.60000000", "1.41420000"], ["111030.51000000", "0.00039000"], ["111030.65000000", "0.00000000"]]}}
{"type": "orderbook", "local_time": 1761342306133, "event_time": 1761342306214, "latency_ms": -81, "data": {"e": "depthUpdate", "E": 1761342306214, "s": "BTCUSDT", "U": 79012678150, "u": 79012678152, "b": [["110977.90000000", "0.00000000"]], "a": [["111018.60000000", "1.41493000"], ["111052.88000000", "0.00005000"]]}}
{"type": "orderbook", "local_time": 1761342306239, "event_time": 1761342306314, "latency_ms": -75, "data": {"e": "depthUpdate", "E": 1761342306314, "s": "BTCUSDT", "U": 79012678153, "u": 79012678153, "b": [], "a": [["111049.95000000", "0.30554000"]]}}
{"type": "orderbook", "local_time": 1761342306355, "event_time": 1761342306414, "latency_ms": -59, "data": {"e": "depthUpdate", "E": 1761342306414, "s": "BTCUSDT", "U": 79012678154, "u": 79012678161, "b": [["110702.00000000", "0.00160000"], ["110695.03000000", "0.01711000"]], "a": [["111024.16000000", "0.11267000"], ["111038.35000000", "0.00000000"], ["111058.57000000", "0.45079000"], ["111109.41000000", "0.00000000"], ["111110.11000000", "0.00000000"]]}}
{"type": "orderbook", "local_time": 1761342306434, "event_time": 1761342306514, "latency_ms": -80, "data": {"e": "depthUpdate", "E": 1761342306514, "s": "BTCUSDT", "U": 79012678162, "u": 79012678181, "b": [["111018.59000000", "4.50685000"], ["111015.31000000", "0.00017000"], ["110988.30000000", "0.82202000"], ["110796.55000000", "0.00010000"], ["99916.00000000", "0.00010000"], ["39966.69000000", "0.00048000"]], "a": [["111018.60000000", "1.41498000"], ["111018.61000000", "0.00100000"], ["111022.93000000", "0.10284000"], ["111024.16000000", "0.11272000"], ["111027.25000000", "0.04508000"], ["111049.55000000", "0.95567000"], ["111058.57000000", "0.00000000"], ["111109.17000000", "0.22535000"], ["111109.61000000", "0.22544000"]]}}
{"type": "orderbook", "local_time": 1761342306551, "event_time": 1761342306614, "latency_ms": -63, "data": {"e": "depthUpdate", "E": 1761342306614, "s": "BTCUSDT", "U": 79012678182, "u": 79012678187, "b": [["111018.59000000", "4.50667000"]], "a": [["111045.93000000", "0.76718000"], ["111058.57000000", "0.22535000"], ["111109.17000000", "0.00000000"]]}}
{"type": "orderbook", "local_time": 1761342306647, "event_time": 1761342306714, "latency_ms": -67, "data": {"e": "depthUpdate", "E": 1761342306714, "s": "BTCUSDT", "U": 79012678188, "u": 79012678195, "b": [["110574.96000000", "0.00010000"], ["33000.00000000", "3.79445000"]], "a": [["111058.57000000", "0.00000000"], ["111109.01000000", "0.00000000"]]}}
{"type": "orderbook", "local_time": 1761342306742, "event_time": 1761342306814, "latency_ms": -72, "data": {"e": "depthUpdate", "E": 1761342306814, "s": "BTCUSDT", "U": 79012678196, "u": 79012678201, "b": [["110988.86000000", "0.41972000"], ["99916.00000000", "0.00020000"]], "a": [["111018.60000000", "1.41425000"], ["111109.01000000", "0.22535000"]]}}
{"type": "orderbook", "local_time": 1761342306836, "event_time": 1761342306914, "latency_ms": -78, "data": {"e": "depthUpdate", "E": 1761342306914, "s": "BTCUSDT", "U": 79012678202, "u": 79012678218, "b": [["110779.72000000", "0.00000000"], ["102000.00000000", "134.14149000"], ["99916.00000000", "0.00010000"], ["39966.69000000", "0.00064000"]], "a": [["111018.60000000", "1.14313000"], ["111019.62000000", "0.05078000"], ["111030.64000000", "0.00072000"], ["111048.37000000", "0.00000000"], ["111265.45000000", "0.00000000"]]}}
{"type": "orderbook", "local_time": 1761342306938, "event_time": 1761342307015, "latency_ms": -77, "data": {"e": "depthUpdate", "E": 1761342307015, "s": "BTCUSDT", "U": 79012678219, "u": 79012678247, "b": [["111001.43000000", "0.00000000"], ["111001.41000000", "0.01801000"], ["110995.50000000", "0.00010000"], ["110936.10000000", "0.00000000"], ["110932.80000000", "0.00000000"]], "a": [["111018.60000000", "1.14313000"], ["111018.61000000", "0.00095000"], ["111019.61000000", "0.00010000"], ["111019.62000000", "0.05098000"], ["111020.00000000", "0.02021000"], ["111020.47000000", "0.00059000"], ["111021.96000000", "0.20763000"], ["111022.92000000", "0.00000000"], ["111026.98000000", "0.20282000"], ["111030.55000000", "0.00069000"], ["111031.99000000", "0.13524000"], ["111059.40000000", "0.13518000"], ["111109.62000000", "0.18027000"]]}}
{"type": "orderbook", "local_time": 1761342307037, "event_time": 1761342307114, "latency_ms": -77, "data": {"e": "depthUpdate", "E": 1761342307114, "s": "BTCUSDT", "U": 79012678248, "u": 79012678252, "b": [["111001.41000000", "0.00000000"], ["111001.35000000", "0.00000000"], ["111001.29000000", "0.01801000"]], "a": [["111106.65000000", "0.74834000"]]}}
{"type": "orderbook", "local_time": 1761342307151, "event_time": 1761342307214, "latency_ms": -63, "data": {"e": "depthUpdate", "E": 1761342307214, "s": "BTCUSDT", "U": 79012678253, "u": 79012678261, "b": [["111001.29000000", "0.00000000"], ["110998.43000000", "0.01801000"], ["110924.93000000", "0.01410000"], ["110779.25000000", "0.82357000"]], "a": [["111030.06000000", "0.01801000"], ["111034.04000000", "0.00000000"], ["111262.15000000", "4.79379000"], ["111357.99000000", "0.48717000"], ["111361.64000000", "0.00000000"]]}}
{"type": "orderbook", "local_time": 1761342307236, "event_time": 1761342307314, "latency_ms": -78, "data": {"e": "depthUpdate", "E": 1761342307314, "s": "BTCUSDT", "U": 79012678262, "u": 79012678265, "b": [["110516.29000000", "0.00000000"]], "a": [["111018.60000000", "1.14308000"], ["111018.61000000", "0.00090000"], ["111572.61000000", "0.00000000"]]}}
{"type": "orderbook", "local_time": 1761342307336, "event_time": 1761342307414, "latency_ms": -78, "data": {"e": "depthUpdate", "E": 1761342307414, "s": "BTCUSDT", "U": 79012678266, "u": 79012678273, "b": [["110353.81000000", "0.00010000"]], "a": [["111018.60000000", "0.91855000"], ["111024.16000000", "0.00005000"], ["111029.71000000", "0.11267000"], ["111031.94000000", "0.00000000"], ["111032.86000000", "0.00450000"], ["111034.69000000", "0.00000000"], ["111041.01000000", "0.27041000"], ["111045.34000000", "0.22544000"]]}}
{"type": "orderbook", "local_time": 1761342307457, "event_time": 1761342307514, "latency_ms": -57, "data": {"e": "depthUpdate", "E": 1761342307514, "s": "BTCUSDT", "U": 79012678274, "u": 79012678287, "b": [["111018.59000000", "4.50743000"]], "a": [["111018.60000000", "0.91897000"], ["111018.61000000", "0.00085000"], ["111019.62000000", "0.00020000"], ["111022.93000000", "0.10284000"], ["111024.16000000", "0.00000000"], ["111026.98000000", "0.20287000"], ["111030.06000000", "0.00000000"], ["111041.00000000", "0.25278000"], ["111041.02000000", "0.00000000"]]}}
{"type": "orderbook", "local_time": 1761342307535, "event_time": 1761342307614, "latency_ms": -79, "data": {"e": "depthUpdate", "E": 1761342307614, "s": "BTCUSDT", "U": 79012678288, "u": 79012678310, "b": [["110133.10000000", "0.00010000"]], "a": [["111018.60000000", "0.91892000"], ["111018.61000000", "0.00085000"], ["111019.61000000", "0.00000000"], ["111019.62000000", "0.00000000"], ["111020.00000000", "0.02026000"], ["111020.47000000", "0.00064000"], ["111021.96000000", "0.20768000"], ["111022.92000000", "0.00005000"], ["111027.25000000", "0.04513000"], ["111030.20000000", "0.01801000"], ["112500.00000000", "21.28274000"]]}}
{"type": "orderbook", "local_time": 1761342307643, "event_time": 1761342307714, "latency_ms": -71, "data": {"e": "depthUpdate", "E": 1761342307714, "s": "BTCUSDT", "U": 79012678311, "u": 79012678315, "b": [["110997.65000000", "0.04502000"], ["39966.69000000", "0.00080000"]], "a": [["111018.60000000", "0.91897000"], ["111018.61000000", "0.00090000"], ["111042.27000000", "0.04502000"]]}}
{"type": "orderbook", "local_time": 1761342307736, "event_time": 1761342307814, "latency_ms": -78, "data": {"e": "depthUpdate", "E": 1761342307814, "s": "BTCUSDT", "U": 79012678316, "u": 79012678330, "b": [["111018.59000000", "4.50723000"], ["111016.94000000", "0.29731000"], ["111015.82000000", "0.01323000"], ["99916.00000000", "0.00010000"]], "a": [["111018.60000000", "0.91738000"], ["111058.57000000", "0.18027000"], ["111109.62000000", "0.00000000"]]}}
{"type": "orderbook", "local_time": 1761342307838, "event_time": 1761342307914, "latency_ms": -76, "data": {"e": "depthUpdate", "E": 1761342307914, "s": "BTCUSDT", "U": 79012678331, "u": 79012678337, "b": [["99916.00000000", "0.00010000"]], "a": [["111058.57000000", "0.00000000"]]}}
{"type": "orderbook", "local_time": 1761342307948, "event_time": 1761342308014, "latency_ms": -66, "data": {"e": "depthUpdate", "E": 1761342308014, "s": "BTCUSDT", "U": 79012678338, "u": 79012678344, "b": [["88815.00000000", "0.00000000"]], "a": [["111030.20000000", "0.00000000"], ["111031.67000000", "0.01801000"], ["111058.57000000", "0.18027000"], ["111109.03000000", "0.00000000"]]}}
{"type": "orderbook", "local_time": 1761342308044, "event_time": 1761342308114, "latency_ms": -70, "data": {"e": "depthUpdate", "E": 1761342308114, "s": "BTCUSDT", "U": 79012678345, "u": 79012678350, "b": [["110971.37000000", "0.34587000"], ["110946.05000000", "0.00000000"], ["99916.00000000", "0.00010000"]], "a": [["111018.60000000", "0.91733000"], ["111018.61000000", "0.00085000"]]}}
{"type": "orderbook", "local_time": 1761342308155, "event_time": 1761342308214, "latency_ms": -59, "data": {"e": "depthUpdate", "E": 1761342308214, "s": "BTCUSDT", "U": 79012678351, "u": 79012678388, "b": [["111018.59000000", "4.49823000"], ["111018.51000000", "0.06748000"], ["111013.30000000", "0.30390000"], ["111012.60000000", "0.27511000"], ["111007.50000000", "0.00000000"], ["111004.71000000", "0.00450000"], ["111003.36000000", "0.00000000"], ["111002.69000000", "0.20282000"], ["111002.59000000", "0.01801000"], ["110999.83000000", "0.00000000"], ["110998.43000000", "0.00000000"], ["50000.00000000", "39.95292000"]], "a": [["111018.60000000", "0.46865000"], ["111018.61000000", "0.04436000"], ["111020.54000000", "0.00020000"], ["111020.55000000", "0.00010000"], ["111023.00000000", "0.00000000"], ["111024.03000000", "0.29719000"], ["111027.50000000", "0.00000000"], ["111029.71000000", "0.00000000"], ["111031.67000000", "0.00000000"], ["111031.95000000", "0.00000000"], ["111032.86000000", "0.00000000"], ["111033.06000000", "0.00000000"], ["111034.22000000", "0.01801000"], ["111034.59000000", "0.00450000"], ["111035.26000000", "0.11267000"], ["111039.04000000", "0.07736000"], ["111047.61000000", "0.18027000"], ["111049.75000000", "0.00250000"], ["111049.95000000", "0.53089000"], ["111054.20000000", "0.00250000"], ["111058.57000000", "0.00000000"], ["111060.84000000", "0.00000000"], ["111061.20000000", "0.06752000"], ["111097.76000000", "0.00000000"], ["111114.22000000", "0.18027000"]]}}
{"type": "orderbook", "local_time": 1761342308244, "event_time": 1761342308315, "latency_ms": -71, "data": {"e": "depthUpdate", "E": 1761342308315, "s": "BTCUSDT", "U": 79012678389, "u": 79012678551, "b": [["111018.59000000", "4.49813000"], ["111018.58000000", "0.33182000"], ["111018.52000000", "0.00000000"], ["111018.51000000", "0.06778000"], ["111017.81000000", "0.00000000"], ["111017.80000000", "0.04958000"], ["111017.48000000", "0.00104000"], ["111017.39000000", "0.00435000"], ["111016.95000000", "0.50063000"], ["111015.82000000", "0.01318000"], ["111015.31000000", "0.00007000"], ["111015.30000000", "0.00005000"], ["111014.15000000", "0.00615000"], ["111013.30000000", "0.00000000"], ["111013.29000000", "0.04191000"], ["111013.06000000", "0.00000000"], ["111012.61000000", "0.30390000"], ["111012.60000000", "0.06748000"], ["111012.55000000", "0.00000000"], ["111004.72000000", "0.00000000"], ["111002.59000000", "0.00000000"], ["111002.21000000", "0.00000000"], ["111002.16000000", "0.01801000"], ["110998.30000000", "0.13518000"], ["110989.39000000", "0.32431000"], ["110984.95000000", "0.00000000"], ["110969.88000000", "0.00000000"], ["110958.76000000", "0.00000000"], ["110946.29000000", "0.00000000"], ["110940.12000000", "0.13518000"], ["110932.80000000", "0.00005000"], ["109912.84000000", "0.00010000"]], "a": [["111018.60000000", "0.13669000"], ["111018.61000000", "0.04436000"], ["111020.00000000", "0.02026000"], ["111020.53000000", "0.00000000"], ["111020.54000000", "0.00000000"], ["111020.55000000", "0.00000000"], ["111021.94000000", "0.00005000"], ["111021.95000000", "0.00010000"], ["111021.96000000", "0.00010000"], ["111022.92000000", "0.00010000"], ["111022.93000000", "0.00010000"], ["111024.02000000", "0.00005000"], ["111024.03000000", "0.00005000"], ["111026.32000000", "0.00000000"], ["111026.98000000", "0.00005000"], ["111027.20000000", "0.29718000"], ["111027.25000000", "0.00005000"], ["111027.35000000", "0.05089000"], ["111029.23000000", "0.00000000"], ["111030.33000000", "0.00000000"], ["111030.38000000", "0.00000000"], ["111030.69000000", "0.00000000"], ["111030.91000000", "0.00068000"], ["111031.17000000", "0.00000000"], ["111031.25000000", "0.20282000"], ["111032.76000000", "0.00000000"], ["111032.87000000", "0.00000000"], ["111033.67000000", "0.00000000"], ["111034.22000000", "0.00000000"], ["111034.59000000", "0.01801000"], ["111034.84000000", "0.00000000"], ["111035.16000000", "0.06000000"], ["111035.26000000", "0.04508000"], ["111035.56000000", "0.08000000"], ["111035.74000000", "0.00000000"], ["111035.86000000", "0.16000000"], ["111036.96000000", "0.00450000"], ["111036.97000000", "0.00000000"], ["111038.35000000", "0.11267000"], ["111040.31000000", "1.44342000"], ["111042.27000000", "0.00000000"], ["111045.10000000", "0.04778000"], ["111050.32000000", "0.00000000"], ["111059.76000000", "0.00000000"], ["111059.99000000", "0.32410000"], ["111061.20000000", "0.00007000"], ["111062.04000000", "0.00000000"], ["111062.99000000", "0.02698000"], ["111079.82000000", "0.00000000"], ["111089.78000000", "0.00007000"], ["111095.11000000", "0.20282000"], ["111096.32000000", "0.00000000"], ["111199.99000000", "0.00000000"], ["111532.66000000", "0.00000000"], ["111534.66000000", "0.00000000"], ["111574.51000000", "0.03798000"], ["111575.66000000", "0.03798000"]]}}
{"type": "orderbook", "local_time": 1761342308335, "event_time": 1761342308414, "latency_ms": -79, "data": {"e": "depthUpdate", "E": 1761342308414, "s": "BTCUSDT", "U": 79012678552, "u": 79012678695, "b": [["111018.59000000", "4.49808000"], ["111017.80000000", "0.04953000"], ["111017.39000000", "0.00000000"], ["111016.95000000", "0.50068000"], ["111016.94000000", "0.29726000"], ["111016.53000000", "0.21478000"], ["111015.82000000", "0.01318000"], ["111015.31000000", "0.00000000"], ["111015.30000000", "0.00000000"], ["111014.15000000", "0.00615000"], ["111013.29000000", "0.04196000"], ["111012.61000000", "0.00000000"], ["111004.72000000", "0.30390000"], ["111004.20000000", "0.00000000"], ["111004.06000000", "0.01801000"], ["111002.16000000", "0.00000000"], ["110990.75000000", "0.00000000"], ["110989.39000000", "0.00000000"], ["110988.61000000", "0.00000000"], ["110987.57000000", "0.00000000"], ["110982.47000000", "0.00000000"], ["110976.09000000", "0.00000000"], ["110968.74000000", "0.32437000"], ["110952.98000000", "0.03146000"], ["110935.30000000", "0.00000000"], ["110934.88000000", "0.00000000"], ["110682.42000000", "0.00000000"], ["110622.73000000", "0.03798000"], ["110517.05000000", "0.00000000"], ["99916.00000000", "0.00010000"], ["50000.00000000", "39.95322000"]], "a": [["111018.60000000", "0.13230000"], ["111018.61000000", "0.04426000"], ["111020.00000000", "0.02026000"], ["111021.94000000", "0.00000000"], ["111021.95000000", "0.00000000"], ["111021.96000000", "0.00000000"], ["111022.92000000", "0.00000000"], ["111022.93000000", "0.00000000"], ["111024.02000000", "0.00000000"], ["111024.03000000", "0.00000000"], ["111024.31000000", "0.29719000"], ["111025.16000000", "0.20758000"], ["111025.17000000", "0.00720000"], ["111025.26000000", "0.00545000"], ["111026.97000000", "0.00000000"], ["111026.98000000", "0.00000000"], ["111027.19000000", "0.10446000"], ["111027.20000000", "0.00010000"], ["111027.24000000", "0.00151000"], ["111027.25000000", "0.00000000"], ["111027.34000000", "0.00010000"], ["111027.35000000", "0.05099000"], ["111029.21000000", "0.00005000"], ["111029.22000000", "0.40094000"], ["111029.70000000", "0.04725000"], ["111030.69000000", "0.01800000"], ["111030.70000000", "0.00000000"], ["111031.22000000", "0.03029000"], ["111031.27000000", "0.00069000"], ["111034.59000000", "0.00000000"], ["111034.69000000", "1.44342000"], ["111034.83000000", "0.20515000"], ["111035.83000000", "0.01801000"], ["111035.86000000", "0.00000000"], ["111037.26000000", "0.16000000"], ["111040.30000000", "0.68388000"], ["111041.00000000", "0.00000000"], ["111046.24000000", "0.00000000"], ["111047.63000000", "0.07648000"], ["111089.78000000", "0.00055000"], ["111103.88000000", "0.00400000"], ["111199.99000000", "0.00019000"], ["111210.18000000", "0.01410000"], ["111300.65000000", "0.00000000"], ["111357.99000000", "0.00000000"]]}}
{"type": "orderbook", "local_time": 1761342308542, "event_time": 1761342308514, "latency_ms": 28, "data": {"e": "depthUpdate", "E": 1761342308514, "s": "BTCUSDT", "U": 79012678696, "u": 79012678766, "b": [["111018.59000000", "4.51221000"], ["111017.48000000", "0.00104000"], ["111016.94000000", "0.29726000"], ["111015.30000000", "0.00000000"], ["111013.29000000", "0.04191000"], ["110992.15000000", "0.00009000"], ["110990.01000000", "0.00009000"], ["110988.97000000", "0.00009000"], ["110983.87000000", "0.00009000"], ["110977.49000000", "0.00009000"], ["110936.28000000", "0.00090000"], ["50000.00000000", "39.95352000"]], "a": [["111018.60000000", "0.13587000"], ["111018.61000000", "0.04446000"], ["111020.00000000", "0.02021000"], ["111024.30000000", "0.00010000"], ["111024.31000000", "0.29724000"], ["111025.15000000", "0.00010000"], ["111025.16000000", "0.20763000"], ["111025.17000000", "0.00725000"], ["111025.26000000", "0.00545000"], ["111027.18000000", "0.00005000"], ["111027.19000000", "0.00005000"], ["111027.20000000", "0.00000000"], ["111027.34000000", "0.00005000"], ["111027.35000000", "0.05094000"], ["111029.21000000", "0.00000000"], ["111029.22000000", "0.38298000"], ["111029.70000000", "0.04720000"], ["111031.22000000", "0.02703000"], ["111034.68000000", "0.73412000"], ["111034.83000000", "0.00000000"], ["111039.04000000", "0.03000000"], ["111043.39000000", "0.04736000"], ["111210.18000000", "0.00000000"], ["111228.13000000", "0.01410000"]]}}
{"type": "orderbook", "local_time": 1761342308543, "event_time": 1761342308614, "latency_ms": -71, "data": {"e": "depthUpdate", "E": 1761342308614, "s": "BTCUSDT", "U": 79012678767, "u": 79012678800, "b": [["111018.59000000", "4.51231000"], ["111018.52000000", "0.00010000"], ["111017.81000000", "0.00010000"], ["111016.96000000", "0.00010000"], ["111016.95000000", "0.50073000"], ["111015.29000000", "0.33180000"], ["110872.19000000", "0.00000000"], ["110761.06000000", "0.00000000"], ["50000.00000000", "39.95382000"]], "a": [["111018.60000000", "0.45133000"], ["111018.61000000", "0.04441000"], ["111024.30000000", "0.17120000"], ["111025.26000000", "0.00545000"], ["111027.18000000", "0.00000000"], ["111027.19000000", "0.00000000"], ["111027.25000000", "0.04508000"], ["111029.70000000", "0.04725000"], ["111031.99000000", "0.00000000"], ["111035.26000000", "0.00000000"], ["111046.58000000", "0.03000000"], ["111082.36000000", "0.00007000"], ["111082.89000000", "0.13524000"], ["111109.01000000", "0.00000000"], ["111109.16000000", "0.22535000"], ["111114.22000000", "0.00000000"], ["111119.93000000", "0.03000000"]]}}
{"type": "orderbook", "local_time": 1761342308635, "event_time": 1761342308714, "latency_ms": -79, "data": {"e": "depthUpdate", "E": 1761342308714, "s": "BTCUSDT", "U": 79012678801, "u": 79012678827, "b": [["111018.59000000", "4.51233000"], ["110872.19000000", "0.00225000"], ["110761.06000000", "0.00090000"], ["50000.00000000", "39.95412000"]], "a": [["111018.60000000", "0.67743000"], ["111018.61000000", "0.04441000"], ["111020.00000000", "0.02021000"], ["111024.29000000", "0.00010000"], ["111024.30000000", "0.17125000"], ["111025.26000000", "0.00545000"], ["111027.25000000", "0.04513000"], ["111027.34000000", "0.00000000"], ["111029.22000000", "0.38293000"], ["111029.70000000", "0.04720000"], ["111031.27000000", "0.00000000"], ["111049.95000000", "0.30554000"], ["111109.06000000", "0.22535000"], ["111109.16000000", "0.00000000"]]}}
{"type": "orderbook", "local_time": 1761342308735, "event_time": 1761342308814, "latency_ms": -79, "data": {"e": "depthUpdate", "E": 1761342308814, "s": "BTCUSDT", "U": 79012678828, "u": 79012678832, "b": [["111004.06000000", "0.00000000"], ["111003.86000000", "0.01801000"], ["42000.00000000", "1.36834000"]], "a": [["111062.14000000", "0.06699000"], ["111064.39000000", "0.00000000"]]}}
{"type": "orderbook", "local_time": 1761342308837, "event_time": 1761342308915, "latency_ms": -78, "data": {"e": "depthUpdate", "E": 1761342308915, "s": "BTCUSDT", "U": 79012678833, "u": 79012678865, "b": [["111018.59000000", "4.51147000"], ["111017.80000000", "0.04958000"], ["111016.95000000", "0.50078000"], ["111016.53000000", "0.21483000"], ["111003.86000000", "0.00000000"], ["111003.82000000", "0.01801000"], ["99916.00000000", "0.00010000"]], "a": [["111018.60000000", "0.71935000"], ["111018.61000000", "0.00090000"], ["111020.00000000", "0.02026000"], ["111024.30000000", "0.17130000"], ["111024.31000000", "0.29729000"], ["111040.62000000", "0.04736000"], ["111043.39000000", "0.00000000"], ["111047.77000000", "0.03000000"], ["111136.52000000", "0.03000000"], ["111228.13000000", "0.00000000"], ["111290.45000000", "0.01410000"]]}}
{"type": "orderbook", "local_time": 1761342308937, "event_time": 1761342309014, "latency_ms": -77, "data": {"e": "depthUpdate", "E": 1761342309014, "s": "BTCUSDT", "U": 79012678866, "u": 79012678883, "b": [["111003.82000000", "0.00000000"], ["111003.78000000", "0.01801000"], ["99916.00000000", "0.00010000"]], "a": [["111018.60000000", "0.71920000"], ["111018.61000000", "0.00080000"], ["111025.16000000", "0.20768000"], ["111027.24000000", "0.00156000"], ["111029.22000000", "0.38298000"], ["111136.52000000", "0.00000000"], ["111290.45000000", "0.00000000"]]}}
{"type": "orderbook", "local_time": 1761342309039, "event_time": 1761342309116, "latency_ms": -77, "data": {"e": "depthUpdate", "E": 1761342309116, "s": "BTCUSDT", "U": 79012678884, "u": 79012678888, "b": [["111003.78000000", "0.00000000"], ["111003.74000000", "0.01801000"]], "a": [["111047.61000000", "0.00000000"], ["111109.36000000", "0.00000000"]]}}
{"type": "orderbook", "local_time": 1761342309139, "event_time": 1761342309214, "latency_ms": -75, "data": {"e": "depthUpdate", "E": 1761342309214, "s": "BTCUSDT", "U": 79012678889, "u": 79012678892, "b": [["111003.74000000", "0.00000000"], ["111003.71000000", "0.01801000"], ["99916.00000000", "0.00030000"]], "a": [["111109.36000000", "0.18027000"]]}}
{"type": "orderbook", "local_time": 1761342309235, "event_time": 1761342309314, "latency_ms": -79, "data": {"e": "depthUpdate", "E": 1761342309314, "s": "BTCUSDT", "U": 79012678893, "u": 79012678895, "b": [["111003.71000000", "0.00000000"], ["111003.68000000", "0.01801000"], ["99916.00000000", "0.00010000"]], "a": []}}
{"type": "orderbook", "local_time": 1761342309339, "event_time": 1761342309414, "latency_ms": -75, "data": {"e": "depthUpdate", "E": 1761342309414, "s": "BTCUSDT", "U": 79012678896, "u": 79012678899, "b": [["111018.51000000", "0.00030000"]], "a": [["111024.29000000", "0.20292000"], ["111058.57000000", "0.18027000"], ["111109.36000000", "0.00000000"]]}}
{"type": "orderbook", "local_time": 1761342309476, "event_time": 1761342309514, "latency_ms": -38, "data": {"e": "depthUpdate", "E": 1761342309514, "s": "BTCUSDT", "U": 79012678900, "u": 79012678931, "b": [["111018.59000000", "4.51152000"], ["111018.58000000", "0.33182000"], ["111018.52000000", "0.00000000"], ["111018.51000000", "0.00020000"], ["111016.95000000", "0.50083000"], ["111016.94000000", "0.29731000"], ["111016.54000000", "0.00005000"], ["111013.29000000", "0.04196000"], ["108250.78000000", "0.00000000"]], "a": [["111018.60000000", "0.71925000"], ["111018.61000000", "0.00085000"], ["111020.00000000", "0.02026000"], ["111024.28000000", "0.00010000"], ["111024.29000000", "0.20302000"], ["111025.16000000", "0.20763000"], ["111027.24000000", "0.00151000"], ["111029.22000000", "0.38293000"], ["111061.18000000", "0.00024000"], ["111071.99000000", "0.00016000"], ["111361.64000000", "0.48717000"]]}}
{"type": "orderbook", "local_time": 1761342309537, "event_time": 1761342309614, "latency_ms": -77, "data": {"e": "depthUpdate", "E": 1761342309614, "s": "BTCUSDT", "U": 79012678932, "u": 79012678950, "b": [["111018.59000000", "4.50639000"], ["111018.58000000", "0.33182000"], ["111018.51000000", "0.00000000"], ["111017.80000000", "0.04968000"], ["111017.48000000", "0.00109000"], ["111016.95000000", "0.50088000"], ["110988.90000000", "0.00005000"], ["102137.10000000", "0.00205000"]], "a": [["111018.60000000", "0.71849000"], ["111058.57000000", "0.00000000"], ["111109.33000000", "0.00000000"]]}}
{"type": "orderbook", "local_time": 1761342309639, "event_time": 1761342309714, "latency_ms": -75, "data": {"e": "depthUpdate", "E": 1761342309714, "s": "BTCUSDT", "U": 79012678951, "u": 79012678960, "b": [["111018.59000000", "4.51121000"], ["110656.73000000", "0.00000000"], ["108265.20000000", "0.00092000"]], "a": [["111018.60000000", "0.71923000"], ["111031.22000000", "0.00000000"], ["111031.53000000", "0.02703000"], ["111109.24000000", "0.00000000"], ["111109.30000000", "0.00000000"]]}}
{"type": "orderbook", "local_time": 1761342309737, "event_time": 1761342309814, "latency_ms": -77, "data": {"e": "depthUpdate", "E": 1761342309814, "s": "BTCUSDT", "U": 79012678961, "u": 79012678971, "b": [["111018.59000000", "4.51161000"], ["111003.68000000", "0.00000000"], ["111003.55000000", "0.01801000"], ["110675.79000000", "0.03698000"]], "a": [["111018.60000000", "0.71923000"], ["111018.61000000", "0.00085000"], ["111037.31000000", "0.04736000"], ["111040.62000000", "0.00000000"], ["111058.57000000", "0.18027000"]]}}
{"type": "orderbook", "local_time": 1761342309835, "event_time": 1761342309914, "latency_ms": -79, "data": {"e": "depthUpdate", "E": 1761342309914, "s": "BTCUSDT", "U": 79012678972, "u": 79012678972, "b": [["111018.59000000", "5.21181000"]], "a": []}}
{"type": "orderbook", "local_time": 1761342309937, "event_time": 1761342310014, "latency_ms": -77, "data": {"e": "depthUpdate", "E": 1761342310014, "s": "BTCUSDT", "U": 79012678973, "u": 79012678981, "b": [["111003.55000000", "0.00000000"], ["111003.52000000", "0.00000000"], ["111003.49000000", "0.01801000"], ["110830.80000000", "0.01410000"], ["110821.93000000", "0.00000000"]], "a": [["111058.57000000", "0.00000000"], ["111109.02000000", "0.00000000"]]}}
{"type": "orderbook", "local_time": 1761342310036, "event_time": 1761342310115, "latency_ms": -79, "data": {"e": "depthUpdate", "E": 1761342310115, "s": "BTCUSDT", "U": 79012678982, "u": 79012679014, "b": [["111018.59000000", "4.51107000"], ["111016.53000000", "0.00005000"], ["111012.65000000", "0.21478000"], ["111003.49000000", "0.00000000"], ["111000.55000000", "0.01801000"], ["110994.89000000", "0.20282000"], ["102137.10000000", "0.00195000"], ["99916.00000000", "0.00010000"]], "a": [["111018.60000000", "0.67645000"], ["111018.61000000", "0.04323000"], ["111021.74000000", "0.21478000"], ["111025.16000000", "0.00005000"], ["111025.17000000", "0.00005000"], ["111032.18000000", "0.01801000"], ["111035.83000000", "0.00000000"], ["111058.57000000", "0.18027000"]]}}
{"type": "orderbook", "local_time": 1761342310135, "event_time": 1761342310214, "latency_ms": -79, "data": {"e": "depthUpdate", "E": 1761342310214, "s": "BTCUSDT", "U": 79012679015, "u": 79012679075, "b": [["111018.59000000", "4.51029000"], ["111016.94000000", "0.29731000"], ["111016.54000000", "0.00000000"], ["111016.53000000", "0.00000000"], ["111015.30000000", "0.00005000"], ["111013.29000000", "0.04196000"], ["111012.65000000", "0.21483000"], ["111012.00000000", "0.00011000"], ["110971.13000000", "0.00000000"]], "a": [["111018.60000000", "0.71938000"], ["111018.61000000", "0.00090000"], ["111020.00000000", "0.02026000"], ["111021.73000000", "0.06560000"], ["111021.74000000", "0.21488000"], ["111024.28000000", "0.18119000"], ["111024.30000000", "0.00005000"], ["111024.31000000", "0.29724000"], ["111025.15000000", "0.00000000"], ["111025.16000000", "0.00000000"], ["111025.17000000", "0.00000000"], ["111058.57000000", "0.18027000"], ["111109.22000000", "0.00000000"]]}}
{"type": "orderbook", "local_time": 1761342310241, "event_time": 1761342310314, "latency_ms": -73, "data": {"e": "depthUpdate", "E": 1761342310314, "s": "BTCUSDT", "U": 79012679076, "u": 79012679132, "b": [["111012.60000000", "0.00000000"], ["111004.72000000", "0.00000000"], ["111001.55000000", "0.30393000"], ["111000.55000000", "0.00000000"], ["110999.49000000", "0.01801000"], ["99916.00000000", "0.00030000"]], "a": [["111018.60000000", "0.71928000"], ["111018.61000000", "0.00085000"], ["111020.00000000", "0.02026000"], ["111021.72000000", "0.00010000"], ["111021.73000000", "0.06570000"], ["111021.74000000", "0.21488000"], ["111024.27000000", "0.00010000"], ["111024.28000000", "0.18129000"], ["111024.29000000", "0.20287000"], ["111024.30000000", "0.00000000"], ["111027.50000000", "0.00250000"], ["111031.17000000", "0.04736000"], ["111031.95000000", "0.00250000"], ["111033.02000000", "0.00450000"], ["111034.07000000", "0.00000000"], ["111036.96000000", "0.00000000"], ["111037.31000000", "0.00000000"], ["111049.75000000", "0.00000000"], ["111054.20000000", "0.00000000"], ["111058.57000000", "0.18027000"], ["111109.06000000", "0.00000000"], ["111109.90000000", "0.22535000"]]}}
{"type": "orderbook", "local_time": 1761342310355, "event_time": 1761342310414, "latency_ms": -59, "data": {"e": "depthUpdate", "E": 1761342310414, "s": "BTCUSDT", "U": 79012679133, "u": 79012679172, "b": [["111018.59000000", "4.46333000"], ["111018.58000000", "0.33739000"], ["111015.61000000", "0.04691000"], ["111015.30000000", "0.00040000"], ["111015.29000000", "0.33157000"], ["111012.65000000", "0.21483000"], ["110999.49000000", "0.00000000"], ["110999.45000000", "0.01801000"], ["110996.39000000", "0.00042000"], ["110994.87000000", "0.05428000"], ["110988.30000000", "0.00000000"], ["110877.99000000", "0.00000000"], ["110711.75000000", "0.00000000"], ["110703.49000000", "0.00572000"], ["99916.00000000", "0.00030000"]], "a": [["111018.60000000", "0.49607000"], ["111018.61000000", "0.08935000"], ["111032.19000000", "0.13524000"], ["111049.55000000", "0.00000000"], ["111058.57000000", "0.00000000"], ["111109.73000000", "0.18027000"]]}}
{"type": "orderbook", "local_time": 1761342310436, "event_time": 1761342310514, "latency_ms": -78, "data": {"e": "depthUpdate", "E": 1761342310514, "s": "BTCUSDT", "U": 79012679173, "u": 79012679197, "b": [["111015.82000000", "0.00203000"], ["111015.30000000", "0.00005000"], ["111014.15000000", "0.01765000"], ["111012.65000000", "0.21478000"], ["110988.86000000", "0.15778000"], ["99916.00000000", "0.00010000"]], "a": [["111018.60000000", "0.49627000"], ["111018.61000000", "0.08940000"], ["111024.28000000", "0.18114000"], ["111027.35000000", "0.05089000"], ["111045.93000000", "0.50668000"]]}}
{"type": "orderbook", "local_time": 1761342310535, "event_time": 1761342310614, "latency_ms": -79, "data": {"e": "depthUpdate", "E": 1761342310614, "s": "BTCUSDT", "U": 79012679198, "u": 79012679207, "b": [["111018.59000000", "4.46333000"], ["111016.94000000", "0.29731000"], ["111015.82000000", "0.00198000"], ["111015.61000000", "0.04696000"], ["110988.78000000", "0.82202000"]], "a": [["111052.55000000", "0.94869000"]]}}
{"type": "orderbook", "local_time": 1761342310634, "event_time": 1761342310714, "latency_ms": -80, "data": {"e": "depthUpdate", "E": 1761342310714, "s": "BTCUSDT", "U": 79012679208, "u": 79012679212, "b": [], "a": [["111018.60000000", "0.49639000"], ["111031.53000000", "0.00000000"], ["111031.54000000", "0.03738000"], ["111049.95000000", "0.50389000"]]}}
{"type": "orderbook", "local_time": 1761342310735, "event_time": 1761342310814, "latency_ms": -79, "data": {"e": "depthUpdate", "E": 1761342310814, "s": "BTCUSDT", "U": 79012679213, "u": 79012679230, "b": [["110999.45000000", "0.00000000"], ["110999.37000000", "0.00000000"], ["110999.35000000", "0.01801000"], ["110911.06000000", "0.01352000"], ["110905.51000000", "0.01352000"], ["110898.07000000", "0.00000000"], ["110892.52000000", "0.00000000"], ["42000.00000000", "1.36734000"]], "a": [["111018.60000000", "0.27104000"], ["111027.27000000", "0.00044000"], ["111042.72000000", "0.00044000"], ["111045.95000000", "0.22535000"], ["111058.57000000", "0.00000000"], ["111099.53000000", "0.13330000"], ["111109.73000000", "0.00000000"], ["111111.36000000", "0.18027000"]]}}
{"type": "orderbook", "local_time": 1761342310842, "event_time": 1761342310914, "latency_ms": -72, "data": {"e": "depthUpdate", "E": 1761342310914, "s": "BTCUSDT", "U": 79012679231, "u": 79012679238, "b": [["111018.59000000", "4.46365000"], ["109599.87000000", "0.02503000"]], "a": [["111021.73000000", "0.00020000"], ["111024.28000000", "0.00005000"], ["111033.02000000", "0.00000000"], ["111034.59000000", "0.00450000"], ["111111.11000000", "0.14199000"]]}}
{"type": "orderbook", "local_time": 1761342310941, "event_time": 1761342311014, "latency_ms": -73, "data": {"e": "depthUpdate", "E": 1761342311014, "s": "BTCUSDT", "U": 79012679239, "u": 79012679283, "b": [["111018.59000000", "4.46214000"], ["111013.76000000", "0.06748000"], ["111012.65000000", "0.21483000"], ["110999.35000000", "0.00000000"], ["110999.33000000", "0.00000000"], ["110999.31000000", "0.01801000"], ["99916.00000000", "0.00010000"], ["88815.00000000", "0.00000000"]], "a": [["111018.60000000", "0.09959000"], ["111018.61000000", "0.04583000"], ["111020.00000000", "0.02026000"], ["111021.72000000", "0.00000000"], ["111021.73000000", "0.06563000"], ["111021.74000000", "0.21488000"], ["111024.27000000", "0.00000000"], ["111024.28000000", "0.00010000"], ["111024.29000000", "0.20292000"], ["111024.30000000", "0.00005000"], ["111027.35000000", "0.05094000"], ["111029.22000000", "0.38298000"], ["111046.52000000", "0.18027000"]]}}
{"type": "orderbook", "local_time": 1761342311039, "event_time": 1761342311114, "latency_ms": -75, "data": {"e": "depthUpdate", "E": 1761342311114, "s": "BTCUSDT", "U": 79012679284, "u": 79012679307, "b": [["111014.15000000", "0.01765000"], ["111013.84000000", "0.00013000"], ["111013.76000000", "0.06753000"], ["111012.65000000", "0.21478000"]], "a": [["111018.60000000", "0.09964000"], ["111020.00000000", "0.02026000"], ["111021.72000000", "0.00010000"], ["111021.73000000", "0.06573000"], ["111024.28000000", "0.18192000"], ["111024.29000000", "0.20287000"], ["111024.30000000", "0.00000000"], ["111029.22000000", "0.38293000"], ["111066.53000000", "0.00000000"], ["111245.47000000", "0.00000000"]]}}
{"type": "orderbook", "local_time": 1761342311135, "event_time": 1761342311214, "latency_ms": -79, "data": {"e": "depthUpdate", "E": 1761342311214, "s": "BTCUSDT", "U": 79012679308, "u": 79012679328, "b": [["111018.59000000", "4.46186000"], ["111015.83000000", "0.18010000"], ["110997.65000000", "0.00000000"], ["110886.44000000", "0.00114000"], ["99916.00000000", "0.00020000"], ["60000.00000000", "56.85876000"], ["33000.00000000", "3.79445000"]], "a": [["111018.60000000", "0.09969000"], ["111021.74000000", "0.21488000"], ["111024.27000000", "0.00005000"], ["111024.28000000", "0.18192000"], ["111027.35000000", "0.05089000"], ["111045.10000000", "0.00276000"], ["111061.92000000", "0.00114000"], ["111111.96000000", "0.01410000"]]}}
{"type": "orderbook", "local_time": 1761342311236, "event_time": 1761342311315, "latency_ms": -79, "data": {"e": "depthUpdate", "E": 1761342311315, "s": "BTCUSDT", "U": 79012679329, "u": 79012679339, "b": [["111018.59000000", "4.49794000"], ["111016.94000000", "0.29731000"], ["111015.84000000", "0.00005000"], ["111015.83000000", "0.18015000"], ["111013.29000000", "0.04191000"], ["110875.34000000", "0.00229000"], ["99916.00000000", "0.00010000"]], "a": []}}
{"type": "orderbook", "local_time": 1761342311349, "event_time": 1761342311414, "latency_ms": -65, "data": {"e": "depthUpdate", "E": 1761342311414, "s": "BTCUSDT", "U": 79012679340, "u": 79012679362, "b": [["111018.59000000", "4.46191000"], ["111014.15000000", "0.01515000"], ["110999.31000000", "0.00000000"], ["110998.89000000", "0.01801000"], ["110991.90000000", "0.00250000"]], "a": [["111018.60000000", "0.54553000"], ["111021.56000000", "0.29720000"], ["111024.31000000", "0.00005000"], ["111027.35000000", "0.04928000"], ["111028.32000000", "0.04736000"], ["111031.17000000", "0.00000000"], ["111045.95000000", "0.00000000"], ["111053.71000000", "0.32412000"], ["111075.49000000", "0.00229000"], ["111076.39000000", "0.00000000"], ["111109.23000000", "0.22535000"], ["111109.90000000", "0.00000000"], ["111111.36000000", "0.00000000"], ["111111.96000000", "0.00000000"]]}}
{"type": "orderbook", "local_time": 1761342311437, "event_time": 1761342311514, "latency_ms": -77, "data": {"e": "depthUpdate", "E": 1761342311514, "s": "BTCUSDT", "U": 79012679363, "u": 79012679393, "b": [["99916.00000000", "0.00010000"]], "a": [["111018.60000000", "0.54553000"], ["111018.61000000", "0.04593000"], ["111020.00000000", "0.02026000"], ["111021.55000000", "0.15488000"], ["111021.56000000", "0.29730000"], ["111021.73000000", "0.00020000"], ["111021.74000000", "0.21483000"], ["111024.27000000", "0.00000000"], ["111024.28000000", "0.09264000"], ["111024.29000000", "0.20287000"], ["111024.31000000", "0.00000000"], ["111111.11000000", "0.07325000"]]}}
{"type": "orderbook", "local_time": 1761342311534, "event_time": 1761342311614, "latency_ms": -80, "data": {"e": "depthUpdate", "E": 1761342311614, "s": "BTCUSDT", "U": 79012679394, "u": 79012679417, "b": [], "a": [["111018.60000000", "0.54553000"], ["111018.61000000", "0.04598000"], ["111020.00000000", "0.02026000"], ["111021.54000000", "0.00010000"], ["111021.55000000", "0.15498000"], ["111021.56000000", "0.29730000"], ["111021.72000000", "0.00000000"], ["111021.73000000", "0.00010000"], ["111041.10000000", "0.03000000"], ["111357.99000000", "0.48717000"], ["111361.64000000", "0.00000000"]]}}
{"type": "orderbook", "local_time": 1761342311656, "event_time": 1761342311714, "latency_ms": -58, "data": {"e": "depthUpdate", "E": 1761342311714, "s": "BTCUSDT", "U": 79012679418, "u": 79012679427, "b": [["111015.83000000", "0.00005000"], ["111014.16000000", "0.18010000"], ["110999.79000000", "0.01801000"], ["110998.89000000", "0.00000000"], ["110997.22000000", "0.00000000"], ["60000.00000000", "56.85866000"]], "a": [["111028.85000000", "0.00000000"], ["111031.42000000", "0.01801000"], ["111032.18000000", "0.00000000"]]}}
{"type": "orderbook", "local_time": 1761342311735, "event_time": 1761342311814, "latency_ms": -79, "data": {"e": "depthUpdate", "E": 1761342311814, "s": "BTCUSDT", "U": 79012679428, "u": 79012679440, "b": [["111016.94000000", "0.29731000"], ["111015.84000000", "0.00000000"], ["111015.83000000", "0.00000000"], ["111015.29000000", "0.33157000"], ["111014.16000000", "0.19177000"], ["111014.15000000", "0.00365000"], ["111013.84000000", "0.00005000"]], "a": [["111046.58000000", "0.00000000"]]}}
{"type": "orderbook", "local_time": 1761342311835, "event_time": 1761342311914, "latency_ms": -79, "data": {"e": "depthUpdate", "E": 1761342311914, "s": "BTCUSDT", "U": 79012679441, "u": 79012679454, "b": [["111014.16000000", "0.19177000"], ["111014.15000000", "0.00360000"], ["111013.29000000", "0.04196000"], ["99916.00000000", "0.00010000"]], "a": [["111018.60000000", "0.54566000"], ["111042.34000000", "0.03000000"], ["111046.52000000", "0.00000000"], ["111047.77000000", "0.00000000"], ["111109.16000000", "0.18027000"]]}}
{"type": "orderbook", "local_time": 1761342311938, "event_time": 1761342312014, "latency_ms": -76, "data": {"e": "depthUpdate", "E": 1761342312014, "s": "BTCUSDT", "U": 79012679455, "u": 79012679460, "b": [["110988.86000000", "0.38298000"], ["39966.69000000", "0.00096000"]], "a": [["111027.27000000", "0.00000000"], ["111028.32000000", "0.00000000"], ["111042.72000000", "0.00000000"], ["111257.77000000", "0.01410000"]]}}
{"type": "orderbook", "local_time": 1761342312037, "event_time": 1761342312114, "latency_ms": -77, "data": {"e": "depthUpdate", "E": 1761342312114, "s": "BTCUSDT", "U": 79012679461, "u": 79012679465, "b": [], "a": [["111018.60000000", "0.54561000"], ["111018.61000000", "0.04593000"], ["111031.92000000", "0.04736000"], ["111058.57000000", "0.18027000"], ["111109.16000000", "0.00000000"]]}}
{"type": "orderbook", "local_time": 1761342312238, "event_time": 1761342312314, "latency_ms": -76, "data": {"e": "depthUpdate", "E": 1761342312314, "s": "BTCUSDT", "U": 79012679466, "u": 79012679477, "b": [["111018.59000000", "4.10191000"], ["111012.65000000", "0.00000000"], ["99916.00000000", "0.00010000"]], "a": [["111018.60000000", "1.23621000"], ["111019.53000000", "0.00720000"], ["111021.74000000", "0.20763000"], ["111034.67000000", "0.27041000"], ["111041.01000000", "0.00000000"]]}}
{"type": "orderbook", "local_time": 1761342312335, "event_time": 1761342312414, "latency_ms": -79, "data": {"e": "depthUpdate", "E": 1761342312414, "s": "BTCUSDT", "U": 79012679478, "u": 79012679531, "b": [["111018.59000000", "4.02468000"], ["111015.61000000", "0.00005000"], ["111014.16000000", "0.01167000"], ["111013.76000000", "0.00005000"], ["111013.29000000", "0.04196000"], ["111011.94000000", "0.18010000"], ["111010.90000000", "0.20758000"], ["111010.09000000", "0.04691000"], ["111009.01000000", "0.00720000"], ["111001.55000000", "0.00000000"], ["110999.79000000", "0.00000000"], ["110998.83000000", "0.30393000"], ["110998.28000000", "0.01801000"]], "a": [["111018.60000000", "2.10940000"], ["111018.61000000", "0.04598000"], ["111019.52000000", "0.00010000"], ["111019.53000000", "0.00735000"], ["111020.00000000", "0.02021000"], ["111020.47000000", "0.00059000"], ["111021.73000000", "0.00000000"], ["111023.05000000", "0.00250000"], ["111025.14000000", "0.04736000"], ["111027.25000000", "0.00000000"], ["111028.90000000", "0.00000000"], ["111030.55000000", "0.00000000"], ["111030.91000000", "0.00000000"], ["111031.92000000", "0.00000000"], ["111032.60000000", "0.06748000"], ["111045.30000000", "0.00000000"], ["111058.57000000", "0.40562000"], ["111082.89000000", "0.00000000"], ["111092.94000000", "0.03398000"], ["111109.23000000", "0.00000000"], ["111109.61000000", "0.00000000"], ["111109.74000000", "0.00000000"], ["111110.57000000", "0.00007000"]]}}
{"type": "orderbook", "local_time": 1761342312438, "event_time": 1761342312514, "latency_ms": -76, "data": {"e": "depthUpdate", "E": 1761342312514, "s": "BTCUSDT", "U": 79012679532, "u": 79012679564, "b": [["111018.59000000", "4.02473000"], ["111016.94000000", "0.29731000"], ["111015.61000000", "0.00000000"], ["111014.16000000", "0.01167000"], ["111014.15000000", "0.00368000"], ["111013.76000000", "0.00000000"], ["111013.29000000", "0.04196000"], ["111011.94000000", "0.18015000"], ["111011.93000000", "0.00546000"], ["111010.91000000", "0.07912000"], ["111004.71000000", "0.00000000"], ["111002.70000000", "0.00450000"]], "a": [["111018.60000000", "2.25493000"], ["111018.61000000", "0.04603000"], ["111024.29000000", "0.20287000"], ["111025.14000000", "0.04741000"], ["111025.26000000", "0.00540000"], ["111029.99000000", "0.00450000"], ["111030.64000000", "0.00000000"], ["111034.59000000", "0.00000000"], ["111034.95000000", "0.00044000"], ["111115.06000000", "0.00000000"]]}}
{"type": "orderbook", "local_time": 1761342312585, "event_time": 1761342312614, "latency_ms": -29, "data": {"e": "depthUpdate", "E": 1761342312614, "s": "BTCUSDT", "U": 79012679565, "u": 79012679572, "b": [["99916.00000000", "0.00010000"]], "a": [["111018.60000000", "2.25482000"], ["111018.61000000", "0.04598000"], ["111024.16000000", "0.11267000"], ["111038.35000000", "0.00000000"]]}}
{"type": "orderbook", "local_time": 1761342312643, "event_time": 1761342312714, "latency_ms": -71, "data": {"e": "depthUpdate", "E": 1761342312714, "s": "BTCUSDT", "U": 79012679573, "u": 79012679580, "b": [], "a": [["111018.60000000", "2.25482000"], ["111018.61000000", "0.04593000"], ["111021.74000000", "0.20763000"], ["111024.16000000", "0.11272000"], ["111025.14000000", "0.04736000"], ["111113.95000000", "0.02500000"]]}}
{"type": "orderbook", "local_time": 1761342312737, "event_time": 1761342312814, "latency_ms": -77, "data": {"e": "depthUpdate", "E": 1761342312814, "s": "BTCUSDT", "U": 79012679581, "u": 79012679585, "b": [["111018.59000000", "4.03329000"], ["99916.00000000", "0.00010000"]], "a": [["111059.40000000", "0.00000000"], ["111109.20000000", "0.13518000"]]}}
{"type": "orderbook", "local_time": 1761342312838, "event_time": 1761342312915, "latency_ms": -77, "data": {"e": "depthUpdate", "E": 1761342312915, "s": "BTCUSDT", "U": 79012679586, "u": 79012679594, "b": [["111012.83000000", "0.04691000"], ["111010.09000000", "0.00000000"], ["99916.00000000", "0.00010000"]], "a": [["111025.14000000", "0.00000000"], ["111072.44000000", "0.00000000"], ["111094.21000000", "0.19454000"], ["111113.60000000", "0.00000000"], ["111113.61000000", "0.00000000"]]}}
{"type": "orderbook", "local_time": 1761342312939, "event_time": 1761342313014, "latency_ms": -75, "data": {"e": "depthUpdate", "E": 1761342313014, "s": "BTCUSDT", "U": 79012679595, "u": 79012679609, "b": [["111013.29000000", "0.04196000"], ["111012.83000000", "0.04696000"], ["111011.93000000", "0.00541000"], ["110971.15000000", "0.36781000"]], "a": [["111018.60000000", "2.25477000"], ["111018.61000000", "0.04588000"], ["111024.29000000", "0.20287000"], ["111028.12000000", "0.04736000"], ["111086.07000000", "0.00044000"], ["111090.22000000", "0.15852000"], ["111113.95000000", "0.00000000"], ["111114.15000000", "0.00100000"], ["111114.90000000", "0.02500000"]]}}
{"type": "orderbook", "local_time": 1761342313039, "event_time": 1761342313114, "latency_ms": -75, "data": {"e": "depthUpdate", "E": 1761342313114, "s": "BTCUSDT", "U": 79012679610, "u": 79012679622, "b": [["111018.59000000", "4.03319000"], ["111004.71000000", "0.30392000"], ["110998.83000000", "0.00000000"], ["110727.15000000", "0.00000000"], ["110721.06000000", "0.00000000"], ["99916.00000000", "0.00010000"]], "a": [["111018.60000000", "2.25442000"], ["111018.61000000", "0.04593000"], ["111023.05000000", "0.00000000"], ["111045.30000000", "0.00250000"], ["111114.14000000", "0.00100000"]]}}
{"type": "orderbook", "local_time": 1761342313137, "event_time": 1761342313214, "latency_ms": -77, "data": {"e": "depthUpdate", "E": 1761342313214, "s": "BTCUSDT", "U": 79012679623, "u": 79012679625, "b": [["111014.15000000", "0.00618000"], ["110991.90000000", "0.00000000"]], "a": [["111018.60000000", "2.25437000"]]}}
{"type": "orderbook", "local_time": 1761342313235, "event_time": 1761342313314, "latency_ms": -79, "data": {"e": "depthUpdate", "E": 1761342313314, "s": "BTCUSDT", "U": 79012679626, "u": 79012679640, "b": [["111014.16000000", "0.01167000"], ["111014.15000000", "0.00623000"], ["111011.94000000", "0.18010000"]], "a": [["111018.60000000", "2.20929000"], ["111032.19000000", "0.00000000"], ["111045.34000000", "0.00000000"], ["111058.57000000", "0.40562000"], ["111082.66000000", "0.13524000"], ["111109.20000000", "0.00000000"], ["111109.41000000", "0.22544000"], ["111110.10000000", "0.13518000"], ["111357.99000000", "0.00000000"], ["111365.28000000", "0.48717000"]]}}
{"type": "orderbook", "local_time": 1761342313338, "event_time": 1761342313414, "latency_ms": -76, "data": {"e": "depthUpdate", "E": 1761342313414, "s": "BTCUSDT", "U": 79012679641, "u": 79012679650, "b": [["110530.23000000", "0.00000000"], ["110527.39000000", "0.00000000"], ["99916.00000000", "0.00010000"]], "a": [["111018.60000000", "2.20798000"], ["111027.25000000", "0.04508000"], ["111027.35000000", "0.00000000"], ["111058.57000000", "0.18027000"], ["111109.85000000", "0.22535000"]]}}
{"type": "orderbook", "local_time": 1761342313436, "event_time": 1761342313514, "latency_ms": -78, "data": {"e": "depthUpdate", "E": 1761342313514, "s": "BTCUSDT", "U": 79012679651, "u": 79012679657, "b": [["111015.64000000", "0.04691000"], ["111012.83000000", "0.00005000"], ["110540.11000000", "0.03798000"], ["110538.93000000", "0.03798000"]], "a": [["111018.60000000", "2.20798000"], ["111018.61000000", "0.04588000"]]}}
{"type": "orderbook", "local_time": 1761342313647, "event_time": 1761342313615, "latency_ms": 32, "data": {"e": "depthUpdate", "E": 1761342313615, "s": "BTCUSDT", "U": 79012679658, "u": 79012679677, "b": [["111018.59000000", "3.80898000"], ["111016.94000000", "0.29731000"], ["111015.64000000", "0.04696000"], ["111013.29000000", "0.04196000"], ["111012.83000000", "0.00000000"]], "a": [["111018.60000000", "1.71212000"], ["111028.12000000", "0.00000000"], ["111032.65000000", "0.13524000"], ["111045.72000000", "0.22544000"], ["111058.57000000", "0.00000000"], ["111058.88000000", "0.13518000"], ["111109.29000000", "0.18027000"]]}}
{"type": "orderbook", "local_time": 1761342313648, "event_time": 1761342313714, "latency_ms": -66, "data": {"e": "depthUpdate", "E": 1761342313714, "s": "BTCUSDT", "U": 79012679678, "u": 79012679688, "b": [["110794.31000000", "0.00000000"], ["99916.00000000", "0.00010000"]], "a": [["111018.60000000", "1.48677000"], ["111018.61000000", "0.04588000"], ["111022.28000000", "0.05060000"], ["111031.24000000", "0.04736000"], ["111045.61000000", "0.22535000"]]}}
{"type": "orderbook", "local_time": 1761342313737, "event_time": 1761342313814, "latency_ms": -77, "data": {"e": "depthUpdate", "E": 1761342313814, "s": "BTCUSDT", "U": 79012679689, "u": 79012679695, "b": [["110675.85000000", "0.03598000"]], "a": [["111018.60000000", "1.48682000"], ["111018.61000000", "0.04593000"], ["111021.74000000", "0.20763000"], ["111022.28000000", "0.05065000"], ["111024.29000000", "0.20282000"]]}}
{"type": "orderbook", "local_time": 1761342313838, "event_time": 1761342313914, "latency_ms": -76, "data": {"e": "depthUpdate", "E": 1761342313914, "s": "BTCUSDT", "U": 79012679696, "u": 79012679699, "b": [], "a": [["111018.60000000", "1.48609000"], ["111022.28000000", "0.00005000"], ["111030.60000000", "0.00072000"], ["111033.19000000", "0.00044000"]]}}
{"type": "orderbook", "local_time": 1761342313936, "event_time": 1761342314014, "latency_ms": -78, "data": {"e": "depthUpdate", "E": 1761342314014, "s": "BTCUSDT", "U": 79012679700, "u": 79012679707, "b": [["88815.00000000", "0.00000000"]], "a": [["111018.60000000", "1.48604000"], ["111018.61000000", "0.04588000"], ["111021.74000000", "0.20763000"], ["111022.28000000", "0.00000000"], ["111024.29000000", "0.20287000"]]}}
{"type": "orderbook", "local_time": 1761342314036, "event_time": 1761342314114, "latency_ms": -78, "data": {"e": "depthUpdate", "E": 1761342314114, "s": "BTCUSDT", "U": 79012679708, "u": 79012679714, "b": [["110711.34000000", "0.02598000"], ["110709.12000000", "0.00000000"], ["110703.88000000", "0.02598000"], ["110699.57000000", "0.02598000"]], "a": [["111018.60000000", "1.48676000"], ["111030.60000000", "0.00000000"], ["111086.07000000", "0.00000000"]]}}
{"type": "orderbook", "local_time": 1761342314135, "event_time": 1761342314214, "latency_ms": -79, "data": {"e": "depthUpdate", "E": 1761342314214, "s": "BTCUSDT", "U": 79012679715, "u": 79012679718, "b": [["110618.99000000", "0.00000000"]], "a": [["111227.77000000", "0.00000000"], ["111359.10000000", "0.04298000"], ["111359.24000000", "0.00000000"]]}}
{"type": "orderbook", "local_time": 1761342314334, "event_time": 1761342314414, "latency_ms": -80, "data": {"e": "depthUpdate", "E": 1761342314414, "s": "BTCUSDT", "U": 79012679719, "u": 79012679736, "b": [["111018.59000000", "3.72395000"], ["111014.15000000", "0.00373000"], ["110991.90000000", "0.00250000"], ["99916.00000000", "0.00010000"]], "a": [["111018.60000000", "1.75718000"], ["111022.28000000", "0.05093000"], ["111027.58000000", "0.04736000"], ["111031.24000000", "0.00000000"], ["111058.57000000", "0.18027000"], ["111082.66000000", "0.00000000"], ["111109.29000000", "0.00000000"], ["111109.41000000", "0.00000000"], ["111109.85000000", "0.00000000"], ["111110.10000000", "0.00000000"], ["111135.60000000", "0.01410000"]]}}
{"type": "orderbook", "local_time": 1761342314435, "event_time": 1761342314514, "latency_ms": -79, "data": {"e": "depthUpdate", "E": 1761342314514, "s": "BTCUSDT", "U": 79012679737, "u": 79012679790, "b": [["111018.59000000", "3.67404000"], ["111017.80000000", "0.00030000"], ["111016.94000000", "0.00010000"], ["111015.64000000", "0.00005000"], ["111014.16000000", "0.01167000"], ["111014.15000000", "0.00368000"], ["111014.06000000", "0.29722000"], ["111013.76000000", "0.00000000"], ["111011.94000000", "0.18015000"], ["111011.78000000", "0.00000000"], ["111010.90000000", "0.00000000"], ["111010.70000000", "0.04691000"], ["111007.39000000", "0.20758000"], ["111004.71000000", "0.00000000"], ["111000.14000000", "0.30393000"], ["110998.28000000", "0.00000000"], ["110996.12000000", "0.00000000"], ["110995.87000000", "0.00000000"], ["110995.03000000", "0.01801000"], ["110989.72000000", "0.04000000"]], "a": [["111018.60000000", "2.41565000"], ["111018.61000000", "0.04593000"], ["111018.79000000", "0.29720000"], ["111021.56000000", "0.00010000"], ["111021.74000000", "0.00005000"], ["111022.28000000", "0.04977000"], ["111023.05000000", "0.00250000"], ["111024.29000000", "0.20282000"], ["111026.00000000", "0.04733000"], ["111027.75000000", "0.01801000"], ["111030.69000000", "0.00000000"], ["111031.42000000", "0.00000000"], ["111035.51000000", "0.00034000"], ["111045.30000000", "0.00000000"], ["111058.57000000", "0.31545000"], ["111058.88000000", "0.00000000"], ["111109.11000000", "0.00000000"]]}}
{"type": "orderbook", "local_time": 1761342314535, "event_time": 1761342314614, "latency_ms": -79, "data": {"e": "depthUpdate", "E": 1761342314614, "s": "BTCUSDT", "U": 79012679791, "u": 79012679910, "b": [["111018.59000000", "3.67414000"], ["111018.58000000", "0.33739000"], ["111017.81000000", "0.00000000"], ["111017.80000000", "0.00020000"], ["111017.05000000", "0.29721000"], ["111016.95000000", "0.37366000"], ["111016.94000000", "0.00000000"], ["111015.64000000", "0.00000000"], ["111015.30000000", "0.00010000"], ["111015.29000000", "0.33162000"], ["111014.16000000", "0.01172000"], ["111014.07000000", "0.00010000"], ["111014.06000000", "0.00005000"], ["111011.95000000", "0.00005000"], ["111011.93000000", "0.00546000"], ["111011.45000000", "0.04578000"], ["111010.27000000", "0.01771000"], ["111009.01000000", "0.00000000"], ["111006.12000000", "0.00720000"]], "a": [["111018.60000000", "2.23832000"], ["111018.61000000", "0.04583000"], ["111018.78000000", "0.10000000"], ["111018.79000000", "0.29740000"], ["111019.52000000", "0.00000000"], ["111019.53000000", "0.00010000"], ["111020.00000000", "0.02016000"], ["111021.55000000", "0.00010000"], ["111021.56000000", "0.00000000"], ["111021.74000000", "0.00000000"], ["111021.77000000", "0.01807000"], ["111022.27000000", "0.00005000"], ["111024.15000000", "0.14451000"], ["111024.28000000", "0.00005000"], ["111024.29000000", "0.20287000"], ["111032.65000000", "0.00000000"], ["111045.72000000", "0.00000000"], ["111058.57000000", "0.00000000"], ["111082.93000000", "0.13524000"], ["111109.36000000", "0.22544000"], ["111109.74000000", "0.13518000"]]}}
{"type": "orderbook", "local_time": 1761342314646, "event_time": 1761342314714, "latency_ms": -68, "data": {"e": "depthUpdate", "E": 1761342314714, "s": "BTCUSDT", "U": 79012679911, "u": 79012680016, "b": [["111018.59000000", "3.67324000"], ["111018.58000000", "0.33739000"], ["111017.80000000", "0.00000000"], ["111017.48000000", "0.00119000"], ["111017.06000000", "0.00010000"], ["111017.05000000", "0.29741000"], ["111014.16000000", "0.01167000"], ["111014.07000000", "0.00000000"], ["111014.06000000", "0.00000000"], ["111013.76000000", "0.04889000"], ["110967.31000000", "0.00000000"], ["110954.81000000", "0.02663000"], ["110779.25000000", "0.00000000"]], "a": [["111018.60000000", "0.73431000"], ["111018.61000000", "0.08333000"], ["111018.77000000", "0.00010000"], ["111018.78000000", "0.10020000"], ["111018.79000000", "0.29735000"], ["111019.53000000", "0.00000000"], ["111020.00000000", "0.02016000"], ["111021.54000000", "0.00000000"], ["111021.55000000", "0.00000000"], ["111021.77000000", "0.00005000"], ["111022.28000000", "0.04977000"], ["111024.15000000", "0.14456000"], ["111024.16000000", "0.00005000"], ["111024.28000000", "0.00000000"], ["111029.71000000", "0.11267000"], ["111029.99000000", "0.00000000"], ["111032.59000000", "0.00450000"], ["111032.60000000", "0.00000000"], ["111033.39000000", "0.13524000"], ["111046.57000000", "0.22544000"], ["111060.82000000", "0.13518000"], ["111089.78000000", "0.00007000"], ["111111.35000000", "0.03400000"], ["111111.51000000", "0.00000000"], ["111112.47000000", "0.22663000"], ["111199.99000000", "0.00000000"], ["111262.15000000", "0.00000000"]]}}
{"type": "orderbook", "local_time": 1761342314735, "event_time": 1761342314814, "latency_ms": -79, "data": {"e": "depthUpdate", "E": 1761342314814, "s": "BTCUSDT", "U": 79012680017, "u": 79012680054, "b": [["111014.16000000", "0.01167000"], ["111013.76000000", "0.04894000"], ["111011.45000000", "0.04573000"], ["111010.19000000", "0.00720000"], ["111006.13000000", "0.30391000"], ["111006.12000000", "0.00000000"], ["111000.14000000", "0.00000000"], ["110997.43000000", "0.01801000"], ["110995.03000000", "0.00000000"], ["99916.00000000", "0.00010000"], ["50000.00000000", "39.95352000"]], "a": [["111018.60000000", "0.73352000"], ["111018.61000000", "0.08328000"], ["111020.00000000", "0.02016000"], ["111021.77000000", "0.00000000"], ["111022.23000000", "0.01780000"], ["111024.15000000", "0.14456000"], ["111024.16000000", "0.00000000"], ["111025.26000000", "0.00545000"], ["111026.00000000", "0.04738000"], ["111027.75000000", "0.00000000"], ["111029.05000000", "0.01801000"], ["111030.57000000", "0.00070000"], ["111089.78000000", "0.00055000"], ["111111.11000000", "0.15545000"], ["111199.99000000", "0.00019000"], ["111209.38000000", "0.00000000"], ["111225.06000000", "0.04298000"]]}}
{"type": "orderbook", "local_time": 1761342314852, "event_time": 1761342314914, "latency_ms": -62, "data": {"e": "depthUpdate", "E": 1761342314914, "s": "BTCUSDT", "U": 79012680055, "u": 79012680094, "b": [["111017.27000000", "0.04691000"], ["111014.15000000", "0.00618000"], ["111013.76000000", "0.00005000"], ["111013.18000000", "0.06748000"], ["111010.91000000", "0.16501000"], ["111010.70000000", "0.00000000"], ["111001.04000000", "0.04000000"], ["110991.90000000", "0.00000000"], ["110989.72000000", "0.00000000"], ["50000.00000000", "39.95322000"]], "a": [["111018.60000000", "0.51812000"], ["111018.61000000", "0.08333000"], ["111018.78000000", "0.00030000"], ["111018.79000000", "0.00015000"], ["111020.00000000", "0.02011000"], ["111021.45000000", "0.29720000"], ["111022.23000000", "0.00005000"], ["111022.28000000", "0.00005000"], ["111023.05000000", "0.00000000"], ["111024.15000000", "0.10270000"], ["111026.00000000", "0.04733000"], ["111027.58000000", "0.00000000"], ["111030.60000000", "0.00000000"], ["111049.75000000", "0.00250000"]]}}
{"type": "orderbook", "local_time": 1761342314935, "event_time": 1761342315014, "latency_ms": -79, "data": {"e": "depthUpdate", "E": 1761342315014, "s": "BTCUSDT", "U": 79012680095, "u": 79012680218, "b": [["111018.59000000", "3.67263000"], ["111018.58000000", "0.33739000"], ["111017.48000000", "0.00119000"], ["111017.28000000", "0.00010000"], ["111017.27000000", "0.04711000"], ["111017.05000000", "0.29736000"], ["111016.96000000", "0.18020000"], ["111016.95000000", "0.37361000"], ["111015.29000000", "0.33157000"], ["111014.16000000", "0.01167000"], ["111014.15000000", "0.00623000"], ["111014.05000000", "0.00720000"], ["111013.76000000", "0.00000000"], ["111013.29000000", "0.04196000"], ["111013.18000000", "0.06753000"], ["111012.42000000", "0.20758000"], ["111011.95000000", "0.00000000"], ["111011.94000000", "0.00000000"], ["111011.93000000", "0.00541000"], ["111010.19000000", "0.00000000"], ["111007.39000000", "0.00000000"], ["111001.26000000", "0.01801000"], ["110997.43000000", "0.00000000"], ["110770.95000000", "0.82363000"], ["99916.00000000", "0.00010000"], ["50000.00000000", "39.95262000"]], "a": [["111018.60000000", "0.55556000"], ["111018.61000000", "0.04573000"], ["111018.77000000", "0.00000000"], ["111018.78000000", "0.00010000"], ["111018.79000000", "0.00000000"], ["111020.00000000", "0.02021000"], ["111021.44000000", "0.09065000"], ["111021.45000000", "0.29730000"], ["111021.77000000", "0.20758000"], ["111022.23000000", "0.00000000"], ["111022.27000000", "0.00000000"], ["111022.28000000", "0.00000000"], ["111024.14000000", "0.00010000"], ["111024.15000000", "0.10275000"], ["111024.28000000", "0.00005000"], ["111026.00000000", "0.04738000"], ["111027.25000000", "0.04513000"], ["111029.05000000", "0.00005000"], ["111029.71000000", "0.00000000"], ["111030.68000000", "0.00069000"], ["111030.71000000", "0.00072000"], ["111030.78000000", "0.00070000"], ["111031.86000000", "0.04736000"], ["111032.59000000", "0.00000000"], ["111032.89000000", "0.01801000"], ["111034.67000000", "0.00000000"], ["111034.81000000", "0.00450000"], ["111035.26000000", "0.11267000"], ["111040.29000000", "0.27041000"], ["111045.30000000", "0.00250000"], ["111049.75000000", "0.00000000"], ["111103.88000000", "0.00000000"], ["111261.24000000", "4.63088000"], ["111361.64000000", "0.48717000"], ["111365.28000000", "0.00000000"]]}}
{"type": "orderbook", "local_time": 1761342315044, "event_time": 1761342315114, "latency_ms": -70, "data": {"e": "depthUpdate", "E": 1761342315114, "s": "BTCUSDT", "U": 79012680219, "u": 79012680288, "b": [["111018.59000000", "3.67248000"], ["111017.05000000", "0.29736000"], ["111016.97000000", "0.00010000"], ["111016.96000000", "0.18030000"], ["111016.95000000", "0.37356000"], ["111015.30000000", "0.00000000"], ["111014.15000000", "0.00623000"], ["111014.05000000", "0.00725000"], ["111013.29000000", "0.04191000"], ["111013.18000000", "0.06748000"], ["111010.91000000", "0.07912000"], ["102137.10000000", "0.00205000"]], "a": [["111018.60000000", "0.41145000"], ["111018.61000000", "0.04573000"], ["111018.78000000", "0.00000000"], ["111020.00000000", "0.02026000"], ["111020.25000000", "0.00720000"], ["111020.47000000", "0.00064000"], ["111021.43000000", "0.00010000"], ["111021.44000000", "0.14117000"], ["111021.45000000", "0.29730000"], ["111021.76000000", "0.00005000"], ["111021.77000000", "0.20763000"], ["111024.14000000", "0.00005000"], ["111024.15000000", "0.08028000"], ["111024.28000000", "0.00000000"], ["111027.25000000", "0.04508000"], ["111029.05000000", "0.00000000"], ["111033.19000000", "0.00000000"], ["111034.95000000", "0.00000000"], ["111052.19000000", "0.18027000"], ["111106.71000000", "0.00410000"], ["111118.80000000", "0.18027000"]]}}
{"type": "orderbook", "local_time": 1761342315135, "event_time": 1761342315214, "latency_ms": -79, "data": {"e": "depthUpdate", "E": 1761342315214, "s": "BTCUSDT", "U": 79012680289, "u": 79012680302, "b": [["111001.26000000", "0.00000000"], ["111000.63000000", "0.01801000"], ["109599.87000000", "0.02503000"]], "a": [["111018.60000000", "0.41150000"], ["111018.61000000", "0.04578000"], ["111020.00000000", "0.02026000"], ["111020.25000000", "0.00730000"], ["111020.47000000", "0.00059000"], ["111026.00000000", "0.04733000"]]}}
{"type": "orderbook", "local_time": 1761342315248, "event_time": 1761342315314, "latency_ms": -66, "data": {"e": "depthUpdate", "E": 1761342315314, "s": "BTCUSDT", "U": 79012680303, "u": 79012680307, "b": [["111018.59000000", "3.67243000"], ["111000.63000000", "0.00000000"], ["111000.62000000", "0.01801000"]], "a": [["111018.60000000", "0.41128000"], ["111027.20000000", "0.01783000"]]}}
{"type": "orderbook", "local_time": 1761342315345, "event_time": 1761342315414, "latency_ms": -69, "data": {"e": "depthUpdate", "E": 1761342315414, "s": "BTCUSDT", "U": 79012680308, "u": 79012680315, "b": [["111018.59000000", "3.66795000"], ["99916.00000000", "0.00030000"]], "a": [["111018.60000000", "0.37232000"], ["111018.61000000", "0.08617000"]]}}
{"type": "orderbook", "local_time": 1761342315447, "event_time": 1761342315515, "latency_ms": -68, "data": {"e": "depthUpdate", "E": 1761342315515, "s": "BTCUSDT", "U": 79012680316, "u": 79012680323, "b": [["111018.59000000", "3.71734000"], ["111018.58000000", "0.33182000"], ["99916.00000000", "0.00010000"]], "a": [["111018.61000000", "0.09064000"], ["111022.28000000", "0.05074000"]]}}
{"type": "orderbook", "local_time": 1761342315535, "event_time": 1761342315614, "latency_ms": -79, "data": {"e": "depthUpdate", "E": 1761342315614, "s": "BTCUSDT", "U": 79012680324, "u": 79012680347, "b": [["111018.59000000", "3.76288000"], ["111017.27000000", "0.00020000"], ["111014.05000000", "0.00005000"], ["111011.45000000", "0.05293000"], ["111006.13000000", "0.00000000"], ["111003.36000000", "0.30392000"], ["110988.99000000", "0.32431000"], ["110968.74000000", "0.00000000"], ["99916.00000000", "0.00010000"]], "a": [["111018.60000000", "0.41655000"], ["111018.61000000", "0.05025000"], ["111020.25000000", "0.00010000"], ["111021.77000000", "0.00005000"], ["111022.28000000", "0.00005000"], ["111022.68000000", "0.05105000"], ["111024.14000000", "0.00000000"], ["111025.26000000", "0.00540000"]]}}
{"type": "orderbook", "local_time": 1761342315688, "event_time": 1761342315714, "latency_ms": -26, "data": {"e": "depthUpdate", "E": 1761342315714, "s": "BTCUSDT", "U": 79012680348, "u": 79012680403, "b": [["111018.59000000", "3.76293000"], ["111018.58000000", "0.33182000"], ["111017.48000000", "0.00119000"], ["111017.28000000", "0.00000000"], ["111017.27000000", "0.00000000"], ["111017.05000000", "0.29741000"], ["111016.96000000", "0.18035000"], ["111016.95000000", "0.37361000"], ["111015.30000000", "0.00005000"], ["111014.15000000", "0.00623000"], ["111014.05000000", "0.00000000"], ["111013.29000000", "0.04196000"], ["111013.18000000", "0.06753000"], ["111010.91000000", "0.00000000"], ["110988.78000000", "0.00000000"], ["102137.10000000", "0.00195000"]], "a": [["111018.60000000", "0.41645000"], ["111018.61000000", "0.05025000"], ["111020.00000000", "0.02026000"], ["111020.25000000", "0.00000000"], ["111020.47000000", "0.00064000"], ["111021.44000000", "0.10940000"], ["111021.45000000", "0.29730000"], ["111021.76000000", "0.00000000"], ["111021.77000000", "0.00000000"], ["111022.28000000", "0.00000000"], ["111022.67000000", "0.00005000"], ["111022.68000000", "0.00005000"], ["111025.26000000", "0.00545000"], ["111026.00000000", "0.04738000"], ["111052.55000000", "0.00000000"]]}}
{"type": "orderbook", "local_time": 1761342315744, "event_time": 1761342315815, "latency_ms": -71, "data": {"e": "depthUpdate", "E": 1761342315815, "s": "BTCUSDT", "U": 79012680404, "u": 79012680424, "b": [["111018.59000000", "4.46643000"], ["111000.62000000", "0.00000000"], ["111000.57000000", "0.01801000"], ["110988.86000000", "0.15778000"], ["110703.89000000", "0.00572000"], ["110703.49000000", "0.00000000"]], "a": [["111018.60000000", "0.41645000"], ["111018.61000000", "0.05020000"], ["111019.70000000", "0.21478000"], ["111021.45000000", "0.29730000"], ["111022.67000000", "0.00000000"], ["111022.68000000", "0.00000000"], ["111024.14000000", "0.00005000"], ["111027.20000000", "0.01788000"]]}}
{"type": "orderbook", "local_time": 1761342315847, "event_time": 1761342315914, "latency_ms": -67, "data": {"e": "depthUpdate", "E": 1761342315914, "s": "BTCUSDT", "U": 79012680425, "u": 79012680458, "b": [["111018.59000000", "3.76271000"], ["111000.57000000", "0.00000000"], ["111000.55000000", "0.01801000"], ["109986.34000000", "0.00251000"], ["99916.00000000", "0.00030000"]], "a": [["111018.60000000", "0.37124000"], ["111018.61000000", "0.08573000"], ["111019.69000000", "0.00010000"], ["111019.70000000", "0.21498000"], ["111020.00000000", "0.02021000"], ["111020.47000000", "0.00059000"], ["111021.45000000", "0.29725000"], ["111022.98000000", "0.05021000"], ["111024.14000000", "0.00000000"], ["111027.20000000", "0.01783000"], ["112043.99000000", "0.00247000"]]}}
{"type": "orderbook", "local_time": 1761342315940, "event_time": 1761342316014, "latency_ms": -74, "data": {"e": "depthUpdate", "E": 1761342316014, "s": "BTCUSDT", "U": 79012680459, "u": 79012680477, "b": [["111000.55000000", "0.00000000"], ["111000.54000000", "0.01801000"], ["110989.76000000", "0.82201000"], ["110988.99000000", "0.00000000"], ["110969.59000000", "0.32437000"], ["99916.00000000", "0.00010000"]], "a": [["111018.60000000", "0.37112000"], ["111018.61000000", "0.08578000"], ["111019.85000000", "0.00000000"], ["111021.45000000", "0.29725000"], ["111022.98000000", "0.00005000"], ["111026.00000000", "0.04733000"], ["111052.79000000", "0.93660000"]]}}
{"type": "orderbook", "local_time": 1761342316034, "event_time": 1761342316114, "latency_ms": -80, "data": {"e": "depthUpdate", "E": 1761342316114, "s": "BTCUSDT", "U": 79012680478, "u": 79012680494, "b": [["111018.59000000", "3.76141000"], ["111000.54000000", "0.00000000"], ["111000.53000000", "0.01801000"], ["110990.47000000", "0.75774000"], ["110852.90000000", "0.00901000"], ["110825.85000000", "0.00000000"]], "a": [["111018.60000000", "0.40945000"], ["111018.61000000", "0.05025000"], ["111021.45000000", "0.29725000"], ["111022.66000000", "0.04876000"], ["111022.98000000", "0.00000000"], ["111026.00000000", "0.04738000"], ["111111.35000000", "0.00000000"], ["111111.36000000", "0.03400000"]]}}
{"type": "orderbook", "local_time": 1761342316138, "event_time": 1761342316214, "latency_ms": -76, "data": {"e": "depthUpdate", "E": 1761342316214, "s": "BTCUSDT", "U": 79012680495, "u": 79012680506, "b": [["111000.53000000", "0.00000000"], ["111000.52000000", "0.01801000"], ["33000.00000000", "3.79445000"]], "a": [["111018.60000000", "0.40998000"], ["111018.61000000", "0.05030000"], ["111021.45000000", "0.29725000"], ["111022.66000000", "0.00005000"], ["111026.00000000", "0.04733000"]]}}
{"type": "orderbook", "local_time": 1761342316235, "event_time": 1761342316314, "latency_ms": -79, "data": {"e": "depthUpdate", "E": 1761342316314, "s": "BTCUSDT", "U": 79012680507, "u": 79012680514, "b": [["111000.52000000", "0.00000000"], ["111000.50000000", "0.01801000"]], "a": [["111018.60000000", "0.40993000"], ["111018.61000000", "0.05025000"], ["111021.45000000", "0.29725000"], ["111022.66000000", "0.00000000"], ["111026.00000000", "0.04738000"]]}}
{"type": "orderbook", "local_time": 1761342316745, "event_time": 1761342316814, "latency_ms": -69, "data": {"e": "depthUpdate", "E": 1761342316814, "s": "BTCUSDT", "U": 79012680515, "u": 79012680522, "b": [["111018.59000000", "4.46281000"], ["111000.50000000", "0.00000000"], ["111000.45000000", "0.01801000"], ["99916.00000000", "0.00010000"]], "a": [["111361.64000000", "0.48717000"]]}}
{"type": "orderbook", "local_time": 1761342316843, "event_time": 1761342316914, "latency_ms": -71, "data": {"e": "depthUpdate", "E": 1761342316914, "s": "BTCUSDT", "U": 79012680523, "u": 79012680532, "b": [["111018.59000000", "4.46280000"], ["111000.45000000", "0.00000000"], ["111000.44000000", "0.01801000"], ["99916.00000000", "0.00010000"]], "a": [["111111.35000000", "0.03400000"], ["111111.36000000", "0.00000000"]]}}
{"type": "orderbook", "local_time": 1761342316941, "event_time": 1761342317014, "latency_ms": -73, "data": {"e": "depthUpdate", "E": 1761342317014, "s": "BTCUSDT", "U": 79012680533, "u": 79012680539, "b": [["111018.59000000", "3.75960000"], ["111000.44000000", "0.00000000"], ["111000.43000000", "0.01801000"], ["99916.00000000", "0.00030000"], ["88815.00000000", "0.00000000"]], "a": [["111018.60000000", "0.40875000"]]}}
{"type": "orderbook", "local_time": 1761342317034, "event_time": 1761342317114, "latency_ms": -80, "data": {"e": "depthUpdate", "E": 1761342317114, "s": "BTCUSDT", "U": 79012680540, "u": 79012680548, "b": [["111000.43000000", "0.00000000"], ["111000.42000000", "0.01801000"], ["99916.00000000", "0.00010000"]], "a": [["111018.60000000", "0.37066000"], ["111018.61000000", "0.08577000"], ["111030.78000000", "0.00000000"], ["111111.35000000", "0.00000000"], ["111111.36000000", "0.03400000"]]}}
{"type": "orderbook", "local_time": 1761342317136, "event_time": 1761342317214, "latency_ms": -78, "data": {"e": "depthUpdate", "E": 1761342317214, "s": "BTCUSDT", "U": 79012680549, "u": 79012680556, "b": [["111000.42000000", "0.00000000"], ["111000.41000000", "0.01801000"], ["110924.93000000", "0.00000000"], ["110898.11000000", "0.01410000"], ["109986.34000000", "0.00000000"]], "a": [["111018.60000000", "0.51477000"], ["112043.99000000", "0.00000000"]]}}
{"type": "orderbook", "local_time": 1761342317237, "event_time": 1761342317314, "latency_ms": -77, "data": {"e": "depthUpdate", "E": 1761342317314, "s": "BTCUSDT", "U": 79012680557, "u": 79012680561, "b": [["111000.41000000", "0.00000000"], ["111000.40000000", "0.01801000"], ["99916.00000000", "0.00010000"]], "a": [["111018.60000000", "0.51471000"]]}}
{"type": "orderbook", "local_time": 1761342317337, "event_time": 1761342317414, "latency_ms": -77, "data": {"e": "depthUpdate", "E": 1761342317414, "s": "BTCUSDT", "U": 79012680562, "u": 79012680564, "b": [["111000.40000000", "0.00000000"], ["111000.39000000", "0.01801000"], ["110898.11000000", "0.00000000"]], "a": []}}
{"type": "orderbook", "local_time": 1761342317536, "event_time": 1761342317614, "latency_ms": -78, "data": {"e": "depthUpdate", "E": 1761342317614, "s": "BTCUSDT", "U": 79012680565, "u": 79012680569, "b": [["99916.00000000", "0.00020000"]], "a": [["111090.61000000", "0.00402000"], ["111096.44000000", "0.00000000"], ["111264.76000000", "0.00089000"], ["111270.59000000", "0.00000000"]]}}
{"type": "orderbook", "local_time": 1761342317634, "event_time": 1761342317714, "latency_ms": -80, "data": {"e": "depthUpdate", "E": 1761342317714, "s": "BTCUSDT", "U": 79012680570, "u": 79012680574, "b": [["111018.59000000", "3.75961000"], ["110816.74000000", "0.02161000"], ["110796.59000000", "0.00000000"], ["99916.00000000", "0.00010000"]], "a": []}}
{"type": "orderbook", "local_time": 1761342317741, "event_time": 1761342317814, "latency_ms": -73, "data": {"e": "depthUpdate", "E": 1761342317814, "s": "BTCUSDT", "U": 79012680575, "u": 79012680576, "b": [["99916.00000000", "0.00010000"]], "a": []}}
{"type": "orderbook", "local_time": 1761342317841, "event_time": 1761342317914, "latency_ms": -73, "data": {"e": "depthUpdate", "E": 1761342317914, "s": "BTCUSDT", "U": 79012680577, "u": 79012680579, "b": [["99916.00000000", "0.00010000"]], "a": [["111018.61000000", "0.08130000"]]}}
{"type": "orderbook", "local_time": 1761342317951, "event_time": 1761342318014, "latency_ms": -63, "data": {"e": "depthUpdate", "E": 1761342318014, "s": "BTCUSDT", "U": 79012680580, "u": 79012680584, "b": [["111018.59000000", "3.77191000"], ["99916.00000000", "0.00010000"]], "a": [["111018.60000000", "0.51021000"]]}}
{"type": "orderbook", "local_time": 1761342318041, "event_time": 1761342318114, "latency_ms": -73, "data": {"e": "depthUpdate", "E": 1761342318114, "s": "BTCUSDT", "U": 79012680585, "u": 79012680587, "b": [["99916.00000000", "0.00030000"]], "a": [["111086.07000000", "0.00044000"], ["111700.00000000", "0.57517000"]]}}
{"type": "orderbook", "local_time": 1761342318138, "event_time": 1761342318214, "latency_ms": -76, "data": {"e": "depthUpdate", "E": 1761342318214, "s": "BTCUSDT", "U": 79012680588, "u": 79012680588, "b": [["99916.00000000", "0.00010000"]], "a": []}}
{"type": "orderbook", "local_time": 1761342318345, "event_time": 1761342318414, "latency_ms": -69, "data": {"e": "depthUpdate", "E": 1761342318414, "s": "BTCUSDT", "U": 79012680589, "u": 79012680592, "b": [["110718.59000000", "0.00000000"]], "a": [["111018.60000000", "0.51018000"]]}}
{"type": "orderbook", "local_time": 1761342318442, "event_time": 1761342318517, "latency_ms": -75, "data": {"e": "depthUpdate", "E": 1761342318517, "s": "BTCUSDT", "U": 79012680593, "u": 79012680595, "b": [["111013.04000000", "0.00005000"]], "a": [["111018.60000000", "0.48316000"]]}}
{"type": "orderbook", "local_time": 1761342318535, "event_time": 1761342318614, "latency_ms": -79, "data": {"e": "depthUpdate", "E": 1761342318614, "s": "BTCUSDT", "U": 79012680596, "u": 79012680598, "b": [["103358.00000000", "0.00006000"]], "a": [["111018.60000000", "0.48346000"]]}}
{"type": "orderbook", "local_time": 1761342318637, "event_time": 1761342318714, "latency_ms": -77, "data": {"e": "depthUpdate", "E": 1761342318714, "s": "BTCUSDT", "U": 79012680599, "u": 79012680601, "b": [], "a": [["111111.35000000", "0.03400000"], ["111111.36000000", "0.00000000"], ["113000.00000000", "40.24509000"]]}}
{"type": "orderbook", "local_time": 1761342318785, "event_time": 1761342318814, "latency_ms": -29, "data": {"e": "depthUpdate", "E": 1761342318814, "s": "BTCUSDT", "U": 79012680602, "u": 79012680604, "b": [["42000.00000000", "1.36834000"]], "a": [["111357.99000000", "0.48717000"], ["111361.64000000", "0.00000000"]]}}
{"type": "orderbook", "local_time": 1761342318939, "event_time": 1761342319014, "latency_ms": -75, "data": {"e": "depthUpdate", "E": 1761342319014, "s": "BTCUSDT", "U": 79012680605, "u": 79012680612, "b": [["111000.39000000", "0.00000000"], ["110997.85000000", "0.01801000"], ["110900.00000000", "0.03963000"], ["110770.95000000", "0.00000000"]], "a": [["111029.48000000", "0.01801000"], ["111032.89000000", "0.00000000"], ["111086.07000000", "0.00000000"], ["111261.24000000", "0.00000000"]]}}
{"type": "orderbook", "local_time": 1761342319035, "event_time": 1761342319114, "latency_ms": -79, "data": {"e": "depthUpdate", "E": 1761342319114, "s": "BTCUSDT", "U": 79012680613, "u": 79012680614, "b": [], "a": [["111018.60000000", "0.48351000"], ["111018.61000000", "0.08135000"]]}}
{"type": "orderbook", "local_time": 1761342319139, "event_time": 1761342319214, "latency_ms": -75, "data": {"e": "depthUpdate", "E": 1761342319214, "s": "BTCUSDT", "U": 79012680615, "u": 79012680619, "b": [["110718.59000000", "0.00000000"]], "a": [["111022.66000000", "0.05028000"], ["111111.35000000", "0.00000000"], ["111111.36000000", "0.03400000"]]}}
{"type": "orderbook", "local_time": 1761342319237, "event_time": 1761342319314, "latency_ms": -77, "data": {"e": "depthUpdate", "E": 1761342319314, "s": "BTCUSDT", "U": 79012680620, "u": 79012680629, "b": [["110778.87000000", "0.82358000"], ["99916.00000000", "0.00010000"]], "a": [["111018.60000000", "0.48351000"], ["111021.45000000", "0.29725000"], ["111022.66000000", "0.05033000"], ["111026.00000000", "0.04733000"], ["111261.69000000", "4.78817000"]]}}
{"type": "orderbook", "local_time": 1761342319339, "event_time": 1761342319414, "latency_ms": -75, "data": {"e": "depthUpdate", "E": 1761342319414, "s": "BTCUSDT", "U": 79012680630, "u": 79012680630, "b": [], "a": [["111022.66000000", "0.00005000"]]}}
{"type": "orderbook", "local_time": 1761342319437, "event_time": 1761342319514, "latency_ms": -77, "data": {"e": "depthUpdate", "E": 1761342319514, "s": "BTCUSDT", "U": 79012680631, "u": 79012680635, "b": [], "a": [["111018.60000000", "0.48346000"], ["111021.45000000", "0.29725000"], ["111022.66000000", "0.00000000"], ["111026.00000000", "0.04738000"]]}}
{"type": "orderbook", "local_time": 1761342319539, "event_time": 1761342319614, "latency_ms": -75, "data": {"e": "depthUpdate", "E": 1761342319614, "s": "BTCUSDT", "U": 79012680636, "u": 79012680638, "b": [["110988.94000000", "0.32431000"], ["110969.59000000", "0.00000000"]], "a": [["111027.20000000", "0.00000000"]]}}
{"type": "orderbook", "local_time": 1761342319635, "event_time": 1761342319714, "latency_ms": -79, "data": {"e": "depthUpdate", "E": 1761342319714, "s": "BTCUSDT", "U": 79012680639, "u": 79012680646, "b": [["99916.00000000", "0.00010000"]], "a": [["111018.60000000", "0.47872000"], ["111026.00000000", "0.04738000"], ["111030.57000000", "0.00140000"]]}}
{"type": "orderbook", "local_time": 1761342319738, "event_time": 1761342319814, "latency_ms": -76, "data": {"e": "depthUpdate", "E": 1761342319814, "s": "BTCUSDT", "U": 79012680647, "u": 79012680655, "b": [["111018.59000000", "3.77491000"], ["99916.00000000", "0.00010000"]], "a": [["111018.60000000", "0.47938000"], ["111027.21000000", "0.01773000"], ["111030.57000000", "0.00070000"]]}}
{"type": "orderbook", "local_time": 1761342319838, "event_time": 1761342319914, "latency_ms": -76, "data": {"e": "depthUpdate", "E": 1761342319914, "s": "BTCUSDT", "U": 79012680656, "u": 79012680660, "b": [], "a": [["111018.60000000", "0.47943000"], ["111018.61000000", "0.08140000"], ["111026.00000000", "0.04738000"], ["111111.36000000", "0.00000000"]]}}
{"type": "orderbook", "local_time": 1761342319951, "event_time": 1761342320014, "latency_ms": -63, "data": {"e": "depthUpdate", "E": 1761342320014, "s": "BTCUSDT", "U": 79012680661, "u": 79012680665, "b": [["111018.59000000", "3.77029000"], ["110836.12000000", "0.01410000"], ["110830.80000000", "0.00000000"], ["88815.00000000", "0.00200000"]], "a": [["111111.35000000", "0.03400000"]]}}
{"type": "orderbook", "local_time": 1761342320040, "event_time": 1761342320114, "latency_ms": -74, "data": {"e": "depthUpdate", "E": 1761342320114, "s": "BTCUSDT", "U": 79012680666, "u": 79012680669, "b": [["111018.59000000", "3.77171000"], ["99916.00000000", "0.00000000"], ["88815.00000000", "0.00000000"]], "a": []}}
{"type": "orderbook", "local_time": 1761342320137, "event_time": 1761342320214, "latency_ms": -77, "data": {"e": "depthUpdate", "E": 1761342320214, "s": "BTCUSDT", "U": 79012680670, "u": 79012680677, "b": [["99916.00000000", "0.00010000"]], "a": [["111018.60000000", "0.52325000"], ["111018.61000000", "0.04588000"], ["111021.45000000", "0.00005000"], ["111024.09000000", "0.29719000"], ["111027.21000000", "0.00000000"], ["111030.57000000", "0.00140000"]]}}
{"type": "orderbook", "local_time": 1761342320244, "event_time": 1761342320314, "latency_ms": -70, "data": {"e": "depthUpdate", "E": 1761342320314, "s": "BTCUSDT", "U": 79012680678, "u": 79012680746, "b": [["111018.59000000", "3.80706000"], ["111013.37000000", "0.00720000"], ["111011.46000000", "0.00000000"], ["111011.45000000", "0.04573000"], ["111009.98000000", "0.00000000"], ["111004.71000000", "0.30391000"], ["111003.36000000", "0.00000000"], ["111002.52000000", "0.00000000"], ["110998.50000000", "0.01801000"], ["110997.85000000", "0.00000000"], ["110692.23000000", "0.00000000"], ["99916.00000000", "0.00020000"]], "a": [["111018.60000000", "0.06088000"], ["111018.61000000", "0.04583000"], ["111019.69000000", "0.00010000"], ["111019.70000000", "0.00020000"], ["111021.44000000", "0.00010000"], ["111021.45000000", "0.00000000"], ["111024.08000000", "0.18016000"], ["111024.09000000", "0.29724000"], ["111024.15000000", "0.00005000"], ["111024.29000000", "0.00005000"], ["111024.32000000", "0.04940000"], ["111026.00000000", "0.04738000"], ["111027.25000000", "0.00000000"], ["111027.50000000", "0.00000000"], ["111028.28000000", "0.01768000"], ["111029.48000000", "0.00000000"], ["111031.86000000", "0.00000000"], ["111031.95000000", "0.00000000"], ["111034.15000000", "0.00000000"], ["111034.81000000", "0.00000000"], ["111035.26000000", "0.15775000"], ["111036.92000000", "0.00000000"], ["111037.25000000", "0.00450000"], ["111049.75000000", "0.00250000"], ["111053.71000000", "0.00000000"], ["111054.20000000", "0.00250000"], ["111062.14000000", "0.00000000"], ["111073.01000000", "0.32406000"], ["111099.53000000", "0.00000000"]]}}
{"type": "orderbook", "local_time": 1761342320338, "event_time": 1761342320414, "latency_ms": -76, "data": {"e": "depthUpdate", "E": 1761342320414, "s": "BTCUSDT", "U": 79012680747, "u": 79012680832, "b": [["111018.59000000", "3.98795000"], ["111016.96000000", "0.00025000"], ["111014.15000000", "0.00623000"], ["111013.37000000", "0.00725000"], ["111013.18000000", "0.06748000"], ["110898.11000000", "0.01410000"], ["99916.00000000", "0.00030000"]], "a": [["111018.60000000", "0.06098000"], ["111018.61000000", "0.04573000"], ["111019.27000000", "0.21478000"], ["111019.69000000", "0.00000000"], ["111019.70000000", "0.00000000"], ["111020.00000000", "0.02026000"], ["111020.47000000", "0.00064000"], ["111021.43000000", "0.00000000"], ["111021.44000000", "0.00000000"], ["111024.07000000", "0.00010000"], ["111024.08000000", "0.13104000"], ["111024.09000000", "0.29729000"], ["111024.14000000", "0.00000000"], ["111024.15000000", "0.00000000"], ["111024.29000000", "0.00000000"], ["111024.31000000", "0.00005000"], ["111024.32000000", "0.04945000"], ["111026.00000000", "0.04738000"], ["111028.28000000", "0.01773000"], ["111029.22000000", "0.38298000"], ["111030.12000000", "0.00000000"], ["111030.13000000", "0.01801000"], ["111043.53000000", "0.04736000"]]}}
{"type": "orderbook", "local_time": 1761342320451, "event_time": 1761342320514, "latency_ms": -63, "data": {"e": "depthUpdate", "E": 1761342320514, "s": "BTCUSDT", "U": 79012680833, "u": 79012680882, "b": [["111018.59000000", "3.97600000"], ["111017.05000000", "0.29741000"], ["111016.97000000", "0.00000000"], ["111016.96000000", "0.00010000"], ["111016.95000000", "0.37366000"], ["111015.29000000", "0.33162000"], ["111013.18000000", "0.06753000"], ["110989.76000000", "0.00000000"], ["99916.00000000", "0.00010000"]], "a": [["111018.60000000", "0.05770000"], ["111018.61000000", "0.04583000"], ["111019.26000000", "0.00010000"], ["111019.27000000", "0.21498000"], ["111020.00000000", "0.02021000"], ["111020.47000000", "0.00059000"], ["111024.09000000", "0.29724000"], ["111024.31000000", "0.00000000"], ["111027.27000000", "0.00044000"], ["111029.22000000", "0.38293000"], ["111030.78000000", "0.00333000"], ["111042.72000000", "0.00044000"], ["111052.79000000", "0.00000000"], ["111054.42000000", "0.32412000"], ["111073.01000000", "0.00000000"]]}}
{"type": "orderbook", "local_time": 1761342320555, "event_time": 1761342320614, "latency_ms": -59, "data": {"e": "depthUpdate", "E": 1761342320614, "s": "BTCUSDT", "U": 79012680883, "u": 79012680923, "b": [["111018.59000000", "3.06339000"], ["111017.48000000", "0.00119000"], ["111015.83000000", "0.18010000"], ["111015.82000000", "0.00198000"], ["111015.30000000", "0.00010000"], ["111014.15000000", "0.00623000"], ["111013.37000000", "0.00005000"], ["111012.43000000", "0.00005000"], ["111012.42000000", "0.00000000"], ["111011.93000000", "0.00541000"], ["111009.16000000", "0.00401000"], ["111007.49000000", "0.00777000"], ["110997.68000000", "0.00000000"], ["110996.52000000", "0.48811000"], ["110994.35000000", "0.00000000"], ["99916.00000000", "0.00010000"]], "a": [["111018.60000000", "0.75159000"], ["111018.61000000", "0.04588000"], ["111019.27000000", "0.00020000"], ["111019.71000000", "0.00099000"], ["111021.37000000", "0.00198000"], ["111021.40000000", "0.29720000"], ["111023.04000000", "0.00360000"], ["111024.08000000", "0.00020000"], ["111024.09000000", "0.00005000"], ["111024.32000000", "0.00005000"], ["111025.26000000", "0.00545000"], ["111027.25000000", "0.04508000"], ["111028.03000000", "0.00396000"], ["111029.70000000", "0.04720000"], ["111030.78000000", "0.00000000"], ["111035.26000000", "0.11267000"]]}}
{"type": "orderbook", "local_time": 1761342320637, "event_time": 1761342320714, "latency_ms": -77, "data": {"e": "depthUpdate", "E": 1761342320714, "s": "BTCUSDT", "U": 79012680924, "u": 79012681023, "b": [["111018.59000000", "3.07234000"], ["111016.95000000", "0.37366000"], ["111015.84000000", "0.00010000"], ["111015.83000000", "0.18020000"], ["111015.29000000", "0.33157000"], ["111014.15000000", "0.00623000"], ["111013.37000000", "0.00000000"], ["111013.18000000", "0.06753000"], ["111012.43000000", "0.00000000"], ["111010.28000000", "0.00959000"], ["102137.10000000", "0.00205000"]], "a": [["111018.60000000", "0.70355000"], ["111018.61000000", "0.08945000"], ["111018.91000000", "0.00338000"], ["111019.26000000", "0.00000000"], ["111019.27000000", "0.00000000"], ["111019.71000000", "0.00109000"], ["111020.00000000", "0.02021000"], ["111020.74000000", "0.00000000"], ["111021.39000000", "0.00010000"], ["111021.40000000", "0.29730000"], ["111024.07000000", "0.00000000"], ["111024.08000000", "0.00000000"], ["111024.09000000", "0.00000000"], ["111024.32000000", "0.00000000"], ["111025.99000000", "0.02852000"], ["111026.00000000", "0.04743000"], ["111027.24000000", "0.00156000"], ["111027.25000000", "0.04513000"], ["111029.22000000", "0.38298000"], ["111029.70000000", "0.04725000"], ["111033.19000000", "0.00044000"], ["111041.03000000", "0.18255000"], ["111043.53000000", "0.00000000"], ["111086.07000000", "0.00044000"]]}}
{"type": "orderbook", "local_time": 1761342320736, "event_time": 1761342320814, "latency_ms": -78, "data": {"e": "depthUpdate", "E": 1761342320814, "s": "BTCUSDT", "U": 79012681024, "u": 79012681058, "b": [["111010.96000000", "0.21478000"], ["110991.12000000", "0.82200000"], ["109599.87000000", "0.02503000"], ["42000.00000000", "1.36734000"]], "a": [["111018.60000000", "0.70370000"], ["111018.61000000", "0.08950000"], ["111018.91000000", "0.00348000"], ["111019.21000000", "0.21478000"], ["111019.71000000", "0.00104000"], ["111020.00000000", "0.02016000"], ["111021.40000000", "0.29730000"], ["111025.26000000", "0.00545000"], ["111025.98000000", "0.00010000"], ["111025.99000000", "0.02862000"], ["111026.00000000", "0.04738000"], ["111027.24000000", "0.00151000"], ["111029.70000000", "0.04720000"], ["111038.33000000", "0.04736000"], ["111041.03000000", "0.13519000"], ["111055.82000000", "0.97361000"], ["111062.27000000", "0.06757000"]]}}
{"type": "orderbook", "local_time": 1761342320857, "event_time": 1761342320914, "latency_ms": -57, "data": {"e": "depthUpdate", "E": 1761342320914, "s": "BTCUSDT", "U": 79012681059, "u": 79012681086, "b": [["111018.59000000", "3.25260000"], ["111015.83000000", "0.00010000"], ["111010.97000000", "0.07374000"], ["111010.28000000", "0.00000000"]], "a": [["111018.60000000", "0.00986000"], ["111018.61000000", "0.08955000"], ["111018.91000000", "0.00348000"], ["111019.20000000", "0.00010000"], ["111019.21000000", "0.21493000"], ["111019.71000000", "0.00099000"], ["111025.99000000", "0.02847000"], ["111029.22000000", "0.38293000"], ["111030.66000000", "0.00326000"]]}}
{"type": "orderbook", "local_time": 1761342320950, "event_time": 1761342321014, "latency_ms": -64, "data": {"e": "depthUpdate", "E": 1761342321014, "s": "BTCUSDT", "U": 79012681087, "u": 79012681107, "b": [["111018.59000000", "3.25260000"], ["111016.95000000", "0.25213000"], ["111015.84000000", "0.00000000"], ["111015.83000000", "0.00000000"], ["111011.93000000", "0.00546000"]], "a": [["111018.60000000", "0.00986000"], ["111018.61000000", "0.08960000"], ["111025.99000000", "0.02852000"], ["111030.13000000", "0.00000000"], ["111031.22000000", "0.01801000"]]}}
{"type": "orderbook", "local_time": 1761342321049, "event_time": 1761342321115, "latency_ms": -66, "data": {"e": "depthUpdate", "E": 1761342321115, "s": "BTCUSDT", "U": 79012681108, "u": 79012681127, "b": [["111015.30000000", "0.00000000"], ["111013.19000000", "0.00000000"], ["110927.78000000", "0.22544000"], ["110919.99000000", "0.00000000"], ["110700.67000000", "0.02598000"], ["33000.00000000", "3.79445000"]], "a": [["111018.60000000", "0.00986000"], ["111018.61000000", "0.08955000"], ["111019.21000000", "0.00015000"], ["111021.40000000", "0.00010000"], ["111023.89000000", "0.29719000"], ["111027.25000000", "0.00005000"], ["111035.26000000", "0.15775000"], ["111062.27000000", "0.00000000"]]}}
{"type": "orderbook", "local_time": 1761342321135, "event_time": 1761342321214, "latency_ms": -79, "data": {"e": "depthUpdate", "E": 1761342321214, "s": "BTCUSDT", "U": 79012681128, "u": 79012681192, "b": [["111018.59000000", "3.51803000"], ["111001.10000000", "0.01801000"], ["110998.50000000", "0.00000000"], ["110991.12000000", "0.00000000"], ["110972.45000000", "0.00000000"], ["110927.78000000", "0.00000000"], ["110927.46000000", "0.22544000"], ["110694.57000000", "0.00000000"], ["109259.91000000", "0.00000000"], ["102137.10000000", "0.00195000"], ["60000.00000000", "56.85876000"]], "a": [["111018.60000000", "0.00981000"], ["111018.61000000", "0.08950000"], ["111018.91000000", "0.00348000"], ["111019.20000000", "0.00000000"], ["111019.21000000", "0.00000000"], ["111019.71000000", "0.00104000"], ["111020.00000000", "0.02016000"], ["111020.48000000", "0.21118000"], ["111021.39000000", "0.00000000"], ["111021.40000000", "0.00000000"], ["111023.88000000", "0.00010000"], ["111023.89000000", "0.29729000"], ["111025.99000000", "0.00015000"], ["111026.00000000", "0.04738000"], ["111027.25000000", "0.00000000"], ["111029.22000000", "0.38298000"], ["111031.22000000", "0.00000000"], ["111032.73000000", "0.01801000"], ["111038.33000000", "0.00000000"], ["111048.49000000", "0.04736000"], ["111054.42000000", "0.00000000"], ["111055.82000000", "0.00000000"], ["111063.01000000", "0.06716000"], ["111073.71000000", "0.32406000"], ["111100.75000000", "0.13498000"]]}}
{"type": "orderbook", "local_time": 1761342321270, "event_time": 1761342321314, "latency_ms": -44, "data": {"e": "depthUpdate", "E": 1761342321314, "s": "BTCUSDT", "U": 79012681193, "u": 79012681231, "b": [["111018.59000000", "3.56645000"]], "a": [["111018.60000000", "0.00986000"], ["111018.61000000", "0.08955000"], ["111020.00000000", "0.02016000"], ["111020.47000000", "0.00069000"], ["111020.48000000", "0.21128000"], ["111023.88000000", "0.10621000"], ["111023.89000000", "0.00005000"], ["111025.26000000", "0.00545000"], ["111025.98000000", "0.00000000"], ["111025.99000000", "0.00005000"], ["111026.48000000", "0.29718000"], ["111029.70000000", "0.04725000"], ["111033.45000000", "0.00000000"], ["111034.60000000", "0.00000000"], ["111034.70000000", "0.00000000"], ["111037.90000000", "0.00000000"], ["111038.48000000", "0.00000000"], ["111039.04000000", "0.00000000"], ["111040.12000000", "0.00000000"], ["111040.22000000", "0.00000000"], ["111041.10000000", "0.00000000"], ["111042.34000000", "0.00000000"], ["111049.95000000", "0.30554000"]]}}
{"type": "orderbook", "local_time": 1761342321336, "event_time": 1761342321414, "latency_ms": -78, "data": {"e": "depthUpdate", "E": 1761342321414, "s": "BTCUSDT", "U": 79012681232, "u": 79012681315, "b": [["111018.59000000", "3.02859000"], ["111017.73000000", "0.04876000"], ["111015.83000000", "0.18010000"], ["111015.30000000", "0.00010000"], ["111013.19000000", "0.00005000"], ["111013.18000000", "0.00005000"], ["111011.45000000", "0.00000000"], ["111004.71000000", "0.00000000"], ["111001.11000000", "0.00000000"], ["111001.10000000", "0.00000000"], ["111001.04000000", "0.00000000"], ["110997.65000000", "0.30394000"], ["110997.44000000", "0.01801000"], ["110995.26000000", "0.04000000"], ["110991.13000000", "0.82200000"], ["110990.25000000", "0.22544000"], ["110952.98000000", "0.00000000"], ["110937.98000000", "0.03218000"], ["110927.46000000", "0.00000000"], ["110923.64000000", "0.22544000"]], "a": [["111018.60000000", "1.08482000"], ["111018.61000000", "0.04588000"], ["111019.69000000", "0.04902000"], ["111020.47000000", "0.06630000"], ["111020.48000000", "0.21123000"], ["111022.11000000", "0.00000000"], ["111023.65000000", "0.00000000"], ["111023.87000000", "0.00010000"], ["111023.88000000", "0.10616000"], ["111023.89000000", "0.00000000"], ["111026.00000000", "0.00165000"], ["111026.48000000", "0.00005000"], ["111027.25000000", "0.04508000"], ["111027.50000000", "0.00250000"], ["111027.75000000", "0.04736000"], ["111029.06000000", "0.01801000"], ["111029.70000000", "0.04720000"], ["111030.20000000", "0.00000000"], ["111031.95000000", "0.00250000"], ["111032.73000000", "0.00000000"], ["111033.16000000", "0.04572000"], ["111033.35000000", "0.00000000"], ["111035.26000000", "0.11267000"], ["111039.18000000", "0.00000000"], ["111042.11000000", "0.00000000"], ["111048.49000000", "0.00000000"], ["111049.75000000", "0.00000000"], ["111049.89000000", "0.03000000"], ["111053.78000000", "0.03000000"], ["111054.15000000", "0.32449000"], ["111054.20000000", "0.00000000"], ["111054.34000000", "0.03000000"], ["111061.42000000", "0.98459000"], ["111073.71000000", "0.00000000"], ["111122.74000000", "0.03000000"], ["111123.29000000", "0.03000000"], ["111134.30000000", "0.03000000"]]}}
{"type": "orderbook", "local_time": 1761342321434, "event_time": 1761342321514, "latency_ms": -80, "data": {"e": "depthUpdate", "E": 1761342321514, "s": "BTCUSDT", "U": 79012681316, "u": 79012681425, "b": [["111018.59000000", "3.01609000"], ["111018.58000000", "0.33177000"], ["111017.74000000", "0.00010000"], ["111017.73000000", "0.00025000"], ["111017.48000000", "0.00109000"], ["111017.05000000", "0.29736000"], ["111016.95000000", "0.25203000"], ["111016.82000000", "0.04000000"], ["111015.84000000", "0.00005000"], ["111015.83000000", "0.00005000"], ["111015.30000000", "0.00005000"], ["111014.91000000", "0.04572000"], ["111014.72000000", "0.04691000"], ["111014.15000000", "0.00373000"], ["111013.30000000", "0.18010000"], ["111013.29000000", "0.04196000"], ["111013.19000000", "0.00000000"], ["111013.18000000", "0.00000000"], ["111011.93000000", "0.00541000"], ["110998.82000000", "0.50038000"], ["110998.79000000", "0.07961000"], ["110991.90000000", "0.00250000"], ["109386.62000000", "0.00010000"], ["99916.00000000", "0.00030000"]], "a": [["111018.60000000", "1.08894000"], ["111018.61000000", "0.04593000"], ["111018.91000000", "0.00348000"], ["111019.68000000", "0.00010000"], ["111019.69000000", "0.00015000"], ["111019.71000000", "0.00099000"], ["111020.00000000", "0.02016000"], ["111020.46000000", "0.00010000"], ["111020.47000000", "0.06640000"], ["111023.87000000", "0.00000000"], ["111023.88000000", "0.03209000"], ["111025.26000000", "0.00545000"], ["111025.99000000", "0.00000000"], ["111026.00000000", "0.00160000"], ["111026.48000000", "0.00000000"], ["111027.25000000", "0.04513000"], ["111027.75000000", "0.04741000"], ["111028.28000000", "0.01768000"], ["111029.22000000", "0.38293000"], ["111030.57000000", "0.00070000"], ["111030.65000000", "0.00000000"], ["111030.66000000", "0.00000000"], ["111049.97000000", "0.03000000"], ["111049.98000000", "0.03000000"], ["111061.41000000", "1.19620000"], ["111061.47000000", "0.00000000"], ["111067.75000000", "0.00000000"], ["111134.30000000", "0.00000000"], ["111134.36000000", "0.06000000"]]}}
{"type": "orderbook", "local_time": 1761342321537, "event_time": 1761342321614, "latency_ms": -77, "data": {"e": "depthUpdate", "E": 1761342321614, "s": "BTCUSDT", "U": 79012681426, "u": 79012681502, "b": [["111018.59000000", "3.01448000"], ["111018.58000000", "0.33182000"], ["111017.74000000", "0.00000000"], ["111017.73000000", "0.00000000"], ["111017.48000000", "0.00119000"], ["111017.06000000", "0.39964000"], ["111017.05000000", "0.29741000"], ["111016.95000000", "0.00015000"], ["111016.83000000", "0.00010000"], ["111016.82000000", "0.04010000"], ["111015.84000000", "0.00000000"], ["111015.83000000", "0.00000000"], ["111015.29000000", "0.33157000"], ["111014.91000000", "0.04577000"], ["111014.72000000", "0.05936000"], ["111014.16000000", "0.00005000"], ["111014.15000000", "0.00360000"], ["111013.30000000", "0.18015000"], ["111013.29000000", "0.04191000"], ["111002.51000000", "0.30393000"], ["110997.65000000", "0.00000000"], ["99916.00000000", "0.00010000"]], "a": [["111018.60000000", "1.08854000"], ["111018.61000000", "0.04588000"], ["111018.91000000", "0.00348000"], ["111019.68000000", "0.00000000"], ["111019.69000000", "0.00000000"], ["111019.71000000", "0.00104000"], ["111020.48000000", "0.21128000"], ["111023.87000000", "0.00005000"], ["111028.28000000", "0.01773000"], ["111041.26000000", "0.03000000"], ["111045.72000000", "0.03000000"], ["111067.19000000", "0.00000000"], ["111124.25000000", "0.03091000"], ["111147.71000000", "0.03000000"]]}}
{"type": "orderbook", "local_time": 1761342321647, "event_time": 1761342321714, "latency_ms": -67, "data": {"e": "depthUpdate", "E": 1761342321714, "s": "BTCUSDT", "U": 79012681503, "u": 79012681552, "b": [["111018.59000000", "3.01448000"], ["111018.58000000", "0.33182000"], ["111017.73000000", "0.05024000"], ["111017.48000000", "0.00119000"], ["111017.07000000", "0.00010000"], ["111017.06000000", "0.39984000"], ["111017.05000000", "0.29736000"], ["111016.96000000", "0.00000000"], ["111016.95000000", "0.00000000"], ["111016.83000000", "0.00000000"], ["111015.30000000", "0.00010000"], ["111014.72000000", "0.05936000"], ["111014.16000000", "0.00000000"], ["111013.31000000", "0.00005000"], ["111013.29000000", "0.04196000"], ["60000.00000000", "56.85866000"]], "a": [["111018.60000000", "1.08848000"], ["111021.03000000", "0.05104000"], ["111023.05000000", "0.00250000"], ["111025.56000000", "0.04736000"], ["111027.75000000", "0.00005000"], ["111039.04000000", "0.03000000"], ["111045.30000000", "0.00000000"], ["111124.47000000", "0.03000000"], ["111357.99000000", "0.00000000"], ["111365.28000000", "0.48717000"]]}}
{"type": "orderbook", "local_time": 1761342321738, "event_time": 1761342321814, "latency_ms": -76, "data": {"e": "depthUpdate", "E": 1761342321814, "s": "BTCUSDT", "U": 79012681553, "u": 79012681600, "b": [["111018.59000000", "3.01448000"], ["111018.58000000", "0.33182000"], ["111017.74000000", "0.00010000"], ["111017.73000000", "0.05054000"], ["111017.48000000", "0.00109000"], ["111017.06000000", "0.39979000"], ["111017.05000000", "0.29731000"], ["111016.82000000", "0.04005000"], ["111013.31000000", "0.00000000"], ["111013.29000000", "0.04191000"]], "a": [["111018.60000000", "1.08863000"], ["111018.61000000", "0.04598000"], ["111020.48000000", "0.21128000"], ["111021.02000000", "0.00005000"], ["111021.03000000", "0.05109000"], ["111025.26000000", "0.00545000"], ["111025.56000000", "0.04741000"], ["111027.25000000", "0.04513000"], ["111027.75000000", "0.00000000"], ["111027.78000000", "0.20282000"], ["111028.28000000", "0.01768000"], ["111134.36000000", "0.00000000"]]}}
{"type": "orderbook", "local_time": 1761342321832, "event_time": 1761342321914, "latency_ms": -82, "data": {"e": "depthUpdate", "E": 1761342321914, "s": "BTCUSDT", "U": 79012681601, "u": 79012681617, "b": [["110937.98000000", "0.00000000"], ["110925.37000000", "0.03218000"], ["99916.00000000", "0.00010000"]], "a": [["111018.60000000", "1.09075000"], ["111018.61000000", "0.04603000"], ["111027.25000000", "0.04513000"], ["111042.44000000", "0.03000000"], ["111136.52000000", "0.03000000"]]}}
{"type": "orderbook", "local_time": 1761342321956, "event_time": 1761342322014, "latency_ms": -58, "data": {"e": "depthUpdate", "E": 1761342322014, "s": "BTCUSDT", "U": 79012681618, "u": 79012681623, "b": [], "a": [["111021.03000000", "0.00005000"], ["111124.25000000", "0.00091000"], ["111124.47000000", "0.00000000"], ["111136.52000000", "0.00000000"], ["111147.71000000", "0.00000000"], ["111257.77000000", "0.00000000"]]}}
{"type": "orderbook", "local_time": 1761342322033, "event_time": 1761342322114, "latency_ms": -81, "data": {"e": "depthUpdate", "E": 1761342322114, "s": "BTCUSDT", "U": 79012681624, "u": 79012681637, "b": [["111018.59000000", "2.76073000"], ["110803.14000000", "0.02598000"]], "a": [["111018.60000000", "1.09070000"], ["111018.61000000", "0.04598000"], ["111020.48000000", "0.21128000"], ["111021.02000000", "0.00000000"], ["111021.03000000", "0.00000000"], ["111027.78000000", "0.20287000"], ["111028.07000000", "0.01801000"], ["111029.06000000", "0.00000000"], ["111217.26000000", "0.01410000"]]}}
{"type": "orderbook", "local_time": 1761342322136, "event_time": 1761342322214, "latency_ms": -78, "data": {"e": "depthUpdate", "E": 1761342322214, "s": "BTCUSDT", "U": 79012681638, "u": 79012681647, "b": [], "a": [["111018.60000000", "1.09070000"], ["111018.61000000", "0.04598000"], ["111027.78000000", "0.20287000"], ["111028.07000000", "0.00000000"], ["111028.10000000", "0.01801000"], ["111043.43000000", "0.03000000"], ["111120.70000000", "0.03000000"]]}}
{"type": "orderbook", "local_time": 1761342322241, "event_time": 1761342322314, "latency_ms": -73, "data": {"e": "depthUpdate", "E": 1761342322314, "s": "BTCUSDT", "U": 79012681648, "u": 79012681658, "b": [["111017.73000000", "0.00030000"]], "a": [["111018.60000000", "1.09070000"], ["111018.61000000", "0.04598000"], ["111020.40000000", "0.29720000"], ["111027.78000000", "0.20287000"], ["111045.74000000", "0.03000000"], ["111065.15000000", "0.00000000"], ["111133.06000000", "0.03015000"]]}}
{"type": "orderbook", "local_time": 1761342322336, "event_time": 1761342322414, "latency_ms": -78, "data": {"e": "depthUpdate", "E": 1761342322414, "s": "BTCUSDT", "U": 79012681659, "u": 79012681705, "b": [["111018.59000000", "2.76073000"], ["111018.58000000", "0.33182000"], ["111017.74000000", "0.00000000"], ["111017.73000000", "0.00020000"], ["111016.82000000", "0.04010000"], ["111013.31000000", "0.00005000"], ["111013.29000000", "0.04196000"], ["110872.20000000", "0.00225000"], ["110872.19000000", "0.00000000"], ["110761.07000000", "0.00090000"], ["110761.06000000", "0.00000000"]], "a": [["111018.60000000", "1.09150000"], ["111018.61000000", "0.04603000"], ["111020.00000000", "0.02016000"], ["111020.39000000", "0.15469000"], ["111020.40000000", "0.29730000"], ["111020.47000000", "0.00079000"], ["111020.48000000", "0.21123000"], ["111023.87000000", "0.00000000"], ["111023.88000000", "0.03209000"], ["111025.56000000", "0.00005000"], ["111027.78000000", "0.20282000"], ["111027.97000000", "0.04736000"], ["111028.10000000", "0.00000000"], ["111028.13000000", "0.00000000"], ["111028.15000000", "0.01801000"], ["111030.47000000", "0.00000000"], ["111030.68000000", "0.00000000"], ["111061.41000000", "1.17153000"]]}}
{"type": "orderbook", "local_time": 1761342322435, "event_time": 1761342322514, "latency_ms": -79, "data": {"e": "depthUpdate", "E": 1761342322514, "s": "BTCUSDT", "U": 79012681706, "u": 79012681767, "b": [["111018.58000000", "0.33182000"], ["111017.73000000", "0.00000000"], ["111017.48000000", "0.00119000"], ["111017.06000000", "0.39984000"], ["111017.05000000", "0.29736000"], ["111015.50000000", "0.00000000"], ["111014.15000000", "0.00368000"], ["110911.04000000", "0.00000000"]], "a": [["111018.60000000", "1.09155000"], ["111018.61000000", "0.04603000"], ["111020.00000000", "0.02016000"], ["111020.38000000", "0.00010000"], ["111020.39000000", "0.15479000"], ["111020.40000000", "0.29725000"], ["111020.46000000", "0.00000000"], ["111020.47000000", "0.00069000"], ["111023.88000000", "0.01795000"], ["111024.11000000", "0.00000000"], ["111025.26000000", "0.00545000"], ["111025.56000000", "0.00000000"], ["111027.78000000", "0.20287000"], ["111028.28000000", "0.00000000"], ["111030.56000000", "0.00074000"], ["111030.71000000", "0.00000000"], ["111063.01000000", "0.00100000"], ["111100.75000000", "0.00000000"], ["111162.22000000", "0.00000000"], ["111173.94000000", "0.02161000"], ["111294.89000000", "0.00000000"], ["111406.81000000", "0.00036000"]]}}
{"type": "orderbook", "local_time": 1761342322626, "event_time": 1761342322614, "latency_ms": 12, "data": {"e": "depthUpdate", "E": 1761342322614, "s": "BTCUSDT", "U": 79012681768, "u": 79012681777, "b": [["111018.59000000", "2.75627000"], ["99916.00000000", "0.00010000"]], "a": [["111018.60000000", "1.09080000"], ["111018.61000000", "0.04598000"], ["111028.15000000", "0.00000000"], ["111028.47000000", "0.01801000"], ["111030.68000000", "0.00070000"], ["111039.71000000", "0.02180000"]]}}
{"type": "orderbook", "local_time": 1761342322636, "event_time": 1761342322714, "latency_ms": -78, "data": {"e": "depthUpdate", "E": 1761342322714, "s": "BTCUSDT", "U": 79012681778, "u": 79012681787, "b": [], "a": [["111018.60000000", "1.09079000"], ["111018.61000000", "0.04609000"], ["111133.06000000", "0.00015000"], ["111217.26000000", "0.00000000"], ["111267.56000000", "0.01410000"]]}}
{"type": "orderbook", "local_time": 1761342322737, "event_time": 1761342322814, "latency_ms": -77, "data": {"e": "depthUpdate", "E": 1761342322814, "s": "BTCUSDT", "U": 79012681788, "u": 79012681794, "b": [["111017.14000000", "0.04691000"], ["111014.72000000", "0.01245000"], ["99916.00000000", "0.00010000"]], "a": [["111028.47000000", "0.00000000"], ["111028.55000000", "0.01801000"], ["111039.71000000", "0.00000000"]]}}
{"type": "orderbook", "local_time": 1761342322837, "event_time": 1761342322914, "latency_ms": -77, "data": {"e": "depthUpdate", "E": 1761342322914, "s": "BTCUSDT", "U": 79012681795, "u": 79012681824, "b": [["111018.59000000", "2.75627000"], ["111018.58000000", "0.33182000"], ["111017.48000000", "0.00119000"], ["111017.15000000", "0.00010000"], ["111017.14000000", "0.04706000"], ["111017.06000000", "0.39979000"], ["111017.05000000", "0.29731000"], ["111016.82000000", "0.04005000"], ["111013.31000000", "0.00000000"], ["111013.29000000", "0.04191000"], ["99916.00000000", "0.00010000"], ["39966.69000000", "0.00112000"]], "a": [["111018.60000000", "1.09079000"], ["111018.61000000", "0.04609000"], ["111020.40000000", "0.29730000"], ["111028.55000000", "0.00000000"], ["111028.57000000", "0.01801000"]]}}
{"type": "orderbook", "local_time": 1761342322938, "event_time": 1761342323014, "latency_ms": -76, "data": {"e": "depthUpdate", "E": 1761342323014, "s": "BTCUSDT", "U": 79012681825, "u": 79012681839, "b": [["111018.59000000", "3.01002000"], ["110858.86000000", "0.13809000"], ["88815.00000000", "0.00000000"]], "a": [["111018.60000000", "1.09079000"], ["111018.61000000", "0.04609000"], ["111028.57000000", "0.00000000"], ["111028.60000000", "0.00000000"], ["111028.62000000", "0.01801000"], ["111065.92000000", "0.06890000"], ["111171.95000000", "0.13448000"], ["111267.56000000", "0.00000000"]]}}
{"type": "orderbook", "local_time": 1761342323034, "event_time": 1761342323114, "latency_ms": -80, "data": {"e": "depthUpdate", "E": 1761342323114, "s": "BTCUSDT", "U": 79012681840, "u": 79012681861, "b": [["111018.59000000", "3.00822000"], ["111017.14000000", "0.04711000"], ["99916.00000000", "0.00010000"]], "a": [["111018.60000000", "1.08994000"], ["111018.61000000", "0.04609000"], ["111027.27000000", "0.00000000"], ["111028.62000000", "0.00000000"], ["111029.43000000", "0.01840000"], ["111029.80000000", "0.00000000"], ["111029.82000000", "0.01801000"], ["111033.19000000", "0.00000000"], ["111039.71000000", "0.04622000"], ["111042.72000000", "0.00000000"], ["111086.07000000", "0.00000000"]]}}
{"type": "orderbook", "local_time": 1761342323135, "event_time": 1761342323214, "latency_ms": -79, "data": {"e": "depthUpdate", "E": 1761342323214, "s": "BTCUSDT", "U": 79012681862, "u": 79012681869, "b": [["111018.59000000", "2.96822000"]], "a": [["111018.60000000", "1.08989000"], ["111018.61000000", "0.04604000"], ["111029.82000000", "0.00000000"], ["111029.85000000", "0.01801000"], ["111030.55000000", "0.00070000"]]}}
{"type": "orderbook", "local_time": 1761342323235, "event_time": 1761342323314, "latency_ms": -79, "data": {"e": "depthUpdate", "E": 1761342323314, "s": "BTCUSDT", "U": 79012681870, "u": 79012681879, "b": [["110778.87000000", "0.00000000"]], "a": [["111018.60000000", "1.09059000"], ["111023.05000000", "0.00000000"], ["111029.85000000", "0.00000000"], ["111029.87000000", "0.01801000"], ["111030.55000000", "0.00000000"], ["111045.30000000", "0.00250000"], ["111261.69000000", "0.00000000"], ["111361.64000000", "0.48717000"], ["111365.28000000", "0.00000000"]]}}
{"type": "orderbook", "local_time": 1761342323334, "event_time": 1761342323414, "latency_ms": -80, "data": {"e": "depthUpdate", "E": 1761342323414, "s": "BTCUSDT", "U": 79012681880, "u": 79012681885, "b": [], "a": [["111018.60000000", "1.09059000"], ["111018.61000000", "0.04609000"], ["111029.87000000", "0.00000000"], ["111029.89000000", "0.01801000"], ["111039.71000000", "0.00000000"]]}}
{"type": "orderbook", "local_time": 1761342323434, "event_time": 1761342323514, "latency_ms": -80, "data": {"e": "depthUpdate", "E": 1761342323514, "s": "BTCUSDT", "U": 79012681886, "u": 79012681886, "b": [], "a": [["111018.60000000", "1.08989000"]]}}
{"type": "orderbook", "local_time": 1761342323535, "event_time": 1761342323614, "latency_ms": -79, "data": {"e": "depthUpdate", "E": 1761342323614, "s": "BTCUSDT", "U": 79012681887, "u": 79012682035, "b": [["111018.59000000", "3.44077000"], ["111017.15000000", "0.00000000"], ["111017.14000000", "0.00020000"], ["111017.07000000", "0.00000000"], ["111017.06000000", "0.39969000"], ["111015.50000000", "0.05030000"], ["111015.30000000", "0.00000000"], ["111014.15000000", "0.00618000"], ["111013.30000000", "0.00005000"], ["111011.71000000", "0.06748000"], ["111011.37000000", "0.00450000"], ["111010.96000000", "0.20758000"], ["111010.61000000", "0.00360000"], ["111009.17000000", "0.30391000"], ["111006.50000000", "0.20287000"], ["111004.70000000", "0.00000000"], ["111004.16000000", "0.16000000"], ["111002.70000000", "0.00000000"], ["111002.51000000", "0.00000000"], ["110992.15000000", "0.00000000"], ["110991.90000000", "0.00000000"], ["110990.01000000", "0.00000000"], ["110988.97000000", "0.00000000"], ["110983.87000000", "0.00000000"], ["110979.24000000", "0.00000000"], ["110977.49000000", "0.00000000"], ["110945.66000000", "0.01900000"], ["110936.28000000", "0.00000000"], ["110919.59000000", "0.00000000"], ["110909.00000000", "0.11573000"], ["110898.34000000", "0.00000000"], ["110870.31000000", "0.00000000"], ["110868.00000000", "0.00160000"], ["110779.35000000", "0.82357000"], ["110698.36000000", "0.00000000"]], "a": [["111018.60000000", "0.05228000"], ["111020.39000000", "0.00020000"], ["111020.40000000", "0.00010000"], ["111020.48000000", "0.00005000"], ["111023.88000000", "0.00005000"], ["111027.25000000", "0.00005000"], ["111027.50000000", "0.00000000"], ["111027.51000000", "0.29718000"], ["111027.78000000", "0.00005000"], ["111027.97000000", "0.00000000"], ["111028.42000000", "0.04920000"], ["111028.50000000", "0.00005000"], ["111029.22000000", "0.00000000"], ["111029.43000000", "0.00000000"], ["111029.89000000", "0.00000000"], ["111029.93000000", "0.01801000"], ["111030.57000000", "0.00139000"], ["111031.54000000", "0.01035000"], ["111031.95000000", "0.00000000"], ["111032.68000000", "0.02703000"], ["111034.69000000", "0.00000000"], ["111035.16000000", "0.00000000"], ["111035.26000000", "0.04508000"], ["111035.52000000", "0.00000000"], ["111035.56000000", "0.00000000"], ["111037.26000000", "0.00000000"], ["111039.71000000", "0.00000000"], ["111040.29000000", "0.00000000"], ["111040.33000000", "0.04736000"], ["111040.65000000", "0.14000000"], ["111040.81000000", "0.11267000"], ["111041.05000000", "0.16000000"], ["111044.41000000", "0.27041000"], ["111045.00000000", "0.00016000"], ["111048.17000000", "0.00000000"], ["111049.75000000", "0.00250000"], ["111054.15000000", "0.00037000"], ["111054.20000000", "0.00250000"], ["111055.26000000", "0.00000000"], ["111055.99000000", "0.00000000"], ["111057.19000000", "0.00000000"], ["111058.65000000", "0.00250000"], ["111061.42000000", "0.00000000"], ["111065.92000000", "0.00000000"], ["111066.35000000", "0.02498000"], ["111066.59000000", "0.02198000"], ["111071.46000000", "0.06796000"], ["111075.57000000", "0.32406000"], ["111089.78000000", "0.00007000"], ["111111.89000000", "0.00000000"], ["111115.19000000", "0.00000000"], ["111124.62000000", "0.01900000"], ["111132.44000000", "0.00399000"], ["111133.58000000", "0.00900000"], ["111146.15000000", "0.00000000"], ["111149.64000000", "0.00670000"], ["111157.45000000", "0.01357000"], ["111171.95000000", "0.00000000"], ["111178.38000000", "0.00000000"], ["111190.86000000", "0.00000000"], ["111199.99000000", "0.00000000"], ["111215.08000000", "0.02074000"], ["111227.40000000", "0.00522000"], ["111234.58000000", "0.00000000"], ["111261.26000000", "4.66381000"], ["111295.34000000", "0.03598000"], ["111323.12000000", "0.00000000"], ["111324.38000000", "0.00000000"], ["111342.75000000", "0.00022000"], ["111358.85000000", "0.02198000"], ["111359.30000000", "0.04298000"], ["111359.53000000", "0.04306000"], ["111453.55000000", "0.00000000"], ["111454.63000000", "0.00000000"], ["111455.58000000", "0.00000000"], ["111456.43000000", "0.00000000"], ["111468.96000000", "0.02698000"], ["111469.32000000", "0.02698000"], ["111469.69000000", "0.02698000"], ["111470.06000000", "0.02698000"], ["111536.14000000", "0.00000000"], ["111536.83000000", "0.00000000"], ["111537.95000000", "0.00000000"], ["111542.91000000", "0.00000000"], ["111570.80000000", "0.03798000"], ["111571.62000000", "0.03798000"], ["111572.24000000", "0.03798000"], ["111573.52000000", "0.03798000"]]}}
{"type": "orderbook", "local_time": 1761342323634, "event_time": 1761342323714, "latency_ms": -80, "data": {"e": "depthUpdate", "E": 1761342323714, "s": "BTCUSDT", "U": 79012682036, "u": 79012682198, "b": [["111018.59000000", "3.47920000"], ["111018.58000000", "0.33182000"], ["111017.48000000", "0.00119000"], ["111017.14000000", "0.00000000"], ["111017.06000000", "0.39974000"], ["111017.05000000", "0.29736000"], ["111016.82000000", "0.04010000"], ["111015.50000000", "0.05035000"], ["111014.94000000", "0.21118000"], ["111014.92000000", "0.30389000"], ["111014.72000000", "0.01245000"], ["111014.15000000", "0.00623000"], ["111013.30000000", "0.00000000"], ["111010.97000000", "0.21449000"], ["111010.96000000", "0.00000000"], ["111010.61000000", "0.00000000"], ["111009.17000000", "0.00000000"], ["111005.44000000", "0.01801000"], ["111002.77000000", "0.00000000"], ["111000.88000000", "0.00000000"], ["110997.44000000", "0.00000000"], ["110990.40000000", "0.00576000"], ["110983.34000000", "0.55995000"], ["110952.73000000", "0.00000000"], ["110938.71000000", "0.03218000"], ["110925.37000000", "0.00000000"], ["110923.64000000", "0.00000000"], ["110919.79000000", "0.00000000"], ["110914.24000000", "0.04645000"], ["110870.87000000", "0.02522000"], ["110766.40000000", "0.03598000"], ["110651.30000000", "0.00000000"], ["99916.00000000", "0.00030000"]], "a": [["111018.60000000", "0.05140000"], ["111018.61000000", "0.04589000"], ["111018.91000000", "0.00010000"], ["111020.00000000", "0.02016000"], ["111020.38000000", "0.00000000"], ["111020.39000000", "0.00000000"], ["111020.40000000", "0.00000000"], ["111020.47000000", "0.00059000"], ["111020.48000000", "0.00000000"], ["111023.87000000", "0.00000000"], ["111023.88000000", "0.00000000"], ["111023.89000000", "0.21118000"], ["111025.26000000", "0.00545000"], ["111027.24000000", "0.00151000"], ["111027.25000000", "0.00000000"], ["111027.27000000", "0.00044000"], ["111027.50000000", "0.00010000"], ["111027.51000000", "0.29728000"], ["111027.77000000", "0.00000000"], ["111027.78000000", "0.00000000"], ["111028.41000000", "0.00010000"], ["111028.42000000", "0.04930000"], ["111029.69000000", "0.00038000"], ["111029.70000000", "0.04725000"], ["111029.93000000", "0.00000000"], ["111031.24000000", "0.35856000"], ["111031.75000000", "0.00329000"], ["111032.51000000", "0.00000000"], ["111032.64000000", "0.01788000"], ["111032.68000000", "0.00000000"], ["111032.69000000", "0.00000000"], ["111034.40000000", "0.00000000"], ["111034.42000000", "0.00000000"], ["111034.68000000", "0.12449000"], ["111035.55000000", "0.00000000"], ["111036.56000000", "0.02703000"], ["111037.07000000", "0.01801000"], ["111037.25000000", "0.00000000"], ["111039.80000000", "0.00450000"], ["111040.33000000", "0.00000000"], ["111047.63000000", "0.00900000"], ["111052.48000000", "0.93871000"], ["111063.09000000", "0.07656000"], ["111071.46000000", "0.00000000"], ["111072.80000000", "0.06612000"], ["111088.28000000", "0.00048000"], ["111092.94000000", "0.00000000"], ["111106.22000000", "0.03326000"], ["111106.71000000", "0.00000000"], ["111199.99000000", "0.00019000"]]}}
{"type": "orderbook", "local_time": 1761342323749, "event_time": 1761342323814, "latency_ms": -65, "data": {"e": "depthUpdate", "E": 1761342323814, "s": "BTCUSDT", "U": 79012682199, "u": 79012682275, "b": [["111018.59000000", "4.06510000"], ["111015.29000000", "0.33157000"], ["111014.94000000", "0.21123000"], ["111014.92000000", "0.30394000"], ["111014.72000000", "0.01240000"], ["111014.15000000", "0.00618000"], ["111011.35000000", "0.00900000"], ["111010.97000000", "0.07374000"], ["111006.22000000", "1.44342000"], ["111000.45000000", "0.00009000"], ["110999.82000000", "0.00000000"], ["110998.31000000", "0.00009000"], ["110997.27000000", "0.00009000"], ["110992.17000000", "0.00009000"], ["110985.79000000", "0.00009000"], ["110969.73000000", "0.00000000"], ["110944.58000000", "0.00090000"], ["110928.22000000", "0.00000000"], ["110927.86000000", "0.13511000"], ["110914.66000000", "0.36576000"], ["110913.03000000", "0.00000000"], ["110890.87000000", "0.00000000"], ["99916.00000000", "0.00010000"]], "a": [["111018.60000000", "0.05145000"], ["111018.61000000", "0.04589000"], ["111018.91000000", "0.00000000"], ["111019.71000000", "0.00109000"], ["111020.00000000", "0.02021000"], ["111023.88000000", "0.00010000"], ["111023.89000000", "0.21128000"], ["111027.51000000", "0.00010000"], ["111028.42000000", "0.04925000"], ["111029.69000000", "0.00033000"], ["111029.70000000", "0.04725000"], ["111030.47000000", "0.29717000"], ["111031.24000000", "0.35861000"], ["111031.25000000", "0.20287000"], ["111040.81000000", "0.00000000"], ["111044.13000000", "0.04736000"], ["111047.63000000", "0.00000000"], ["111049.95000000", "0.58473000"], ["111055.85000000", "0.00900000"], ["111111.35000000", "0.03400000"], ["111114.14000000", "0.00000000"], ["111114.15000000", "0.00000000"], ["111114.90000000", "0.00000000"], ["111115.14000000", "0.00100000"], ["111115.15000000", "0.00100000"], ["111115.90000000", "0.02500000"]]}}
{"type": "orderbook", "local_time": 1761342323840, "event_time": 1761342323914, "latency_ms": -74, "data": {"e": "depthUpdate", "E": 1761342323914, "s": "BTCUSDT", "U": 79012682276, "u": 79012682321, "b": [["111018.59000000", "4.27268000"], ["111014.94000000", "0.00005000"], ["111010.97000000", "0.49160000"], ["110971.15000000", "0.00000000"]], "a": [["111018.60000000", "0.05145000"], ["111018.61000000", "0.04584000"], ["111023.89000000", "0.00010000"], ["111025.26000000", "0.00545000"], ["111027.50000000", "0.00000000"], ["111027.51000000", "0.00000000"], ["111027.97000000", "0.20758000"], ["111028.42000000", "0.04930000"], ["111029.69000000", "0.00038000"], ["111029.70000000", "0.04725000"], ["111030.46000000", "0.55373000"], ["111030.47000000", "0.29722000"], ["111031.24000000", "0.00005000"], ["111037.07000000", "0.00000000"], ["111037.28000000", "0.00000000"], ["111038.40000000", "0.01806000"], ["111041.24000000", "0.00005000"], ["111080.21000000", "0.00000000"], ["111107.60000000", "0.00000000"], ["111111.35000000", "0.00000000"], ["111112.35000000", "0.00000000"], ["111112.45000000", "0.03400000"], ["111115.14000000", "0.00000000"], ["111115.15000000", "0.00000000"], ["111115.90000000", "0.00000000"], ["111116.00000000", "0.02500000"]]}}
{"type": "orderbook", "local_time": 1761342323942, "event_time": 1761342324014, "latency_ms": -72, "data": {"e": "depthUpdate", "E": 1761342324014, "s": "BTCUSDT", "U": 79012682322, "u": 79012682381, "b": [["111015.29000000", "0.33157000"], ["111014.94000000", "0.00000000"], ["111014.72000000", "0.00005000"], ["111013.84000000", "0.01253000"], ["111007.99000000", "0.01801000"], ["111005.44000000", "0.00000000"], ["110990.40000000", "0.00000000"], ["110938.71000000", "0.00000000"], ["110927.95000000", "0.00000000"], ["110927.86000000", "0.00000000"], ["110926.14000000", "0.03218000"], ["110652.93000000", "0.00000000"], ["110251.46000000", "0.40089000"], ["110096.41000000", "0.00000000"], ["99916.00000000", "0.00010000"]], "a": [["111018.60000000", "0.04900000"], ["111018.61000000", "0.04579000"], ["111020.00000000", "0.02021000"], ["111023.88000000", "0.00000000"], ["111023.89000000", "0.00000000"], ["111025.26000000", "0.00545000"], ["111027.96000000", "0.00010000"], ["111027.97000000", "0.20768000"], ["111029.69000000", "0.00043000"], ["111029.70000000", "0.04725000"], ["111030.46000000", "0.55378000"], ["111030.47000000", "0.29722000"], ["111031.24000000", "0.00000000"], ["111036.56000000", "0.00000000"], ["111036.57000000", "0.02703000"], ["111038.40000000", "0.00005000"], ["111039.62000000", "0.01801000"], ["111046.36000000", "0.11267000"], ["111076.36000000", "0.02162000"], ["111094.40000000", "0.00633000"], ["111116.12000000", "0.00100000"], ["111116.13000000", "0.00100000"], ["111409.70000000", "0.00000000"]]}}
{"type": "orderbook", "local_time": 1761342324040, "event_time": 1761342324114, "latency_ms": -74, "data": {"e": "depthUpdate", "E": 1761342324114, "s": "BTCUSDT", "U": 79012682382, "u": 79012682400, "b": [["111014.91000000", "0.04577000"], ["111014.72000000", "0.00000000"], ["111014.15000000", "0.00623000"], ["110978.62000000", "0.00000000"], ["110927.93000000", "0.13511000"], ["110812.13000000", "0.02499000"], ["110520.30000000", "0.00036000"], ["110409.12000000", "0.00000000"]], "a": [["111039.62000000", "0.00000000"], ["111041.17000000", "0.01801000"], ["111069.24000000", "0.00000000"], ["111109.50000000", "0.00510000"], ["111112.45000000", "0.00000000"], ["111113.46000000", "0.03400000"], ["111116.00000000", "0.00000000"], ["111116.12000000", "0.00000000"], ["111116.13000000", "0.00000000"], ["111117.00000000", "0.02500000"]]}}
{"type": "orderbook", "local_time": 1761342324137, "event_time": 1761342324214, "latency_ms": -77, "data": {"e": "depthUpdate", "E": 1761342324214, "s": "BTCUSDT", "U": 79012682401, "u": 79012682410, "b": [["111014.15000000", "0.01875000"], ["111013.84000000", "0.00005000"], ["111007.54000000", "0.05100000"], ["110990.25000000", "0.00000000"], ["110972.10000000", "0.00000000"], ["110927.92000000", "0.22544000"], ["110927.56000000", "0.22535000"]], "a": [["111113.45000000", "0.03400000"], ["111113.46000000", "0.00000000"]]}}
{"type": "orderbook", "local_time": 1761342324236, "event_time": 1761342324314, "latency_ms": -78, "data": {"e": "depthUpdate", "E": 1761342324314, "s": "BTCUSDT", "U": 79012682411, "u": 79012682416, "b": [["111014.15000000", "0.01875000"], ["111005.23000000", "0.05400000"], ["110992.08000000", "0.00000000"], ["110990.35000000", "0.00576000"]], "a": [["111113.45000000", "0.00000000"]]}}
{"type": "orderbook", "local_time": 1761342324335, "event_time": 1761342324414, "latency_ms": -79, "data": {"e": "depthUpdate", "E": 1761342324414, "s": "BTCUSDT", "U": 79012682417, "u": 79012682425, "b": [["111010.85000000", "0.05700000"], ["111006.97000000", "0.05100000"], ["111006.41000000", "0.05100000"], ["110989.77000000", "0.00000000"]], "a": [["111075.64000000", "0.01410000"], ["111086.61000000", "0.00000000"], ["111099.82000000", "0.02572000"], ["111113.46000000", "0.03400000"], ["111135.60000000", "0.00000000"]]}}
{"type": "orderbook", "local_time": 1761342324441, "event_time": 1761342324514, "latency_ms": -73, "data": {"e": "depthUpdate", "E": 1761342324514, "s": "BTCUSDT", "U": 79012682426, "u": 79012682439, "b": [["111018.59000000", "4.13757000"], ["111010.85000000", "0.10800000"], ["111010.76000000", "0.09000000"], ["110995.47000000", "0.00000000"], ["110990.87000000", "0.00000000"], ["110976.98000000", "0.13511000"], ["110927.93000000", "0.00000000"], ["110923.69000000", "0.13511000"], ["110908.56000000", "0.00000000"]], "a": [["111027.47000000", "0.29718000"], ["111030.47000000", "0.00005000"], ["111075.64000000", "0.00000000"], ["111091.12000000", "0.01410000"]]}}
{"type": "orderbook", "local_time": 1761342324542, "event_time": 1761342324614, "latency_ms": -72, "data": {"e": "depthUpdate", "E": 1761342324614, "s": "BTCUSDT", "U": 79012682440, "u": 79012682493, "b": [["111018.59000000", "4.13757000"], ["111009.73000000", "0.03600000"], ["111005.29000000", "0.03900000"], ["110995.31000000", "0.00000000"], ["110995.24000000", "0.00000000"], ["110994.64000000", "0.32429000"], ["110991.91000000", "0.22535000"], ["110991.43000000", "0.00000000"], ["110978.62000000", "0.22544000"], ["110970.99000000", "0.00000000"], ["110927.92000000", "0.00000000"], ["110927.56000000", "0.00000000"], ["110925.30000000", "0.00000000"], ["110923.69000000", "0.00000000"]], "a": [["111018.60000000", "0.04900000"], ["111018.61000000", "0.04584000"], ["111020.00000000", "0.02021000"], ["111025.26000000", "0.00545000"], ["111027.46000000", "0.00010000"], ["111027.47000000", "0.00010000"], ["111028.42000000", "0.04925000"], ["111029.69000000", "0.00033000"], ["111030.33000000", "0.29717000"], ["111030.46000000", "0.43146000"], ["111030.47000000", "0.00000000"], ["111042.72000000", "0.00044000"], ["111072.80000000", "0.00000000"], ["111073.33000000", "0.06731000"], ["111091.12000000", "0.00000000"], ["111111.96000000", "0.01410000"], ["111113.46000000", "0.00000000"], ["111114.46000000", "0.03400000"], ["111117.00000000", "0.00000000"], ["111117.12000000", "0.00000000"], ["111117.13000000", "0.00007000"], ["111118.00000000", "0.07500000"]]}}
{"type": "orderbook", "local_time": 1761342324648, "event_time": 1761342324714, "latency_ms": -66, "data": {"e": "depthUpdate", "E": 1761342324714, "s": "BTCUSDT", "U": 79012682494, "u": 79012682551, "b": [["111018.59000000", "4.83937000"], ["111017.07000000", "0.00010000"], ["111017.06000000", "0.39984000"], ["111015.51000000", "0.00000000"], ["111015.30000000", "0.00000000"], ["111011.94000000", "0.03900000"], ["110991.91000000", "0.00000000"], ["110990.35000000", "0.00000000"], ["110979.05000000", "0.13511000"], ["110978.62000000", "0.00000000"], ["110976.98000000", "0.00000000"], ["110927.78000000", "0.22544000"], ["110927.48000000", "0.22535000"], ["110927.44000000", "0.00000000"], ["110925.72000000", "0.13511000"]], "a": [["111018.60000000", "0.04900000"], ["111018.61000000", "0.04579000"], ["111020.00000000", "0.02021000"], ["111023.03000000", "0.00000000"], ["111025.26000000", "0.00545000"], ["111027.23000000", "0.00000000"], ["111027.46000000", "0.00000000"], ["111027.47000000", "0.00000000"], ["111027.96000000", "0.00010000"], ["111028.42000000", "0.04930000"], ["111029.69000000", "0.00038000"], ["111029.70000000", "0.04725000"], ["111030.33000000", "0.29722000"], ["111036.57000000", "0.00000000"], ["111036.92000000", "0.02703000"], ["111041.26000000", "0.00000000"], ["111042.44000000", "0.00000000"], ["111052.48000000", "0.00000000"], ["111073.33000000", "0.00000000"]]}}
{"type": "orderbook", "local_time": 1761342324734, "event_time": 1761342324814, "latency_ms": -80, "data": {"e": "depthUpdate", "E": 1761342324814, "s": "BTCUSDT", "U": 79012682552, "u": 79012682576, "b": [["111018.59000000", "4.38858000"], ["111014.92000000", "0.00005000"], ["111011.95000000", "0.30390000"], ["111007.99000000", "0.00000000"], ["111005.50000000", "0.01801000"], ["111003.35000000", "0.00000000"], ["110996.46000000", "0.00000000"], ["110992.11000000", "0.22544000"], ["110992.03000000", "0.22535000"], ["110989.78000000", "0.00000000"], ["110927.78000000", "0.00000000"], ["110927.48000000", "0.00000000"], ["110925.50000000", "0.22544000"], ["110925.42000000", "0.22535000"], ["110875.05000000", "0.06000000"], ["110872.21000000", "0.00225000"], ["110872.20000000", "0.00000000"], ["110761.08000000", "0.00090000"], ["110761.07000000", "0.00000000"], ["39966.69000000", "0.00128000"]], "a": [["111027.96000000", "0.32706000"], ["111037.13000000", "0.01801000"], ["111041.17000000", "0.00000000"], ["111049.95000000", "0.30554000"], ["111111.96000000", "0.00000000"]]}}
{"type": "orderbook", "local_time": 1761342324840, "event_time": 1761342324914, "latency_ms": -74, "data": {"e": "depthUpdate", "E": 1761342324914, "s": "BTCUSDT", "U": 79012682577, "u": 79012682608, "b": [["111018.59000000", "4.39118000"], ["111015.29000000", "0.33157000"], ["111014.92000000", "0.00000000"], ["111013.29000000", "0.04196000"], ["111011.83000000", "0.03600000"], ["111008.50000000", "0.03600000"], ["111005.26000000", "0.03900000"], ["110989.91000000", "0.00000000"], ["110850.08000000", "0.00000000"], ["99916.00000000", "0.00010000"]], "a": [["111018.60000000", "0.04905000"], ["111018.61000000", "0.04584000"], ["111020.00000000", "0.02021000"], ["111025.26000000", "0.00545000"], ["111027.95000000", "0.00010000"], ["111027.96000000", "0.00020000"], ["111028.42000000", "0.04925000"], ["111029.69000000", "0.00033000"], ["111031.25000000", "0.20282000"], ["111037.13000000", "0.00000000"], ["111037.15000000", "0.01801000"], ["111052.18000000", "0.03000000"], ["111136.52000000", "0.03000000"]]}}
{"type": "orderbook", "local_time": 1761342324965, "event_time": 1761342325014, "latency_ms": -49, "data": {"e": "depthUpdate", "E": 1761342325014, "s": "BTCUSDT", "U": 79012682609, "u": 79012682643, "b": [["111018.59000000", "3.68943000"], ["111002.13000000", "0.00000000"], ["110996.49000000", "0.00000000"], ["110983.03000000", "0.05100000"], ["99916.00000000", "0.00010000"]], "a": [["111018.60000000", "0.00514000"], ["111018.61000000", "0.05118000"], ["111020.00000000", "0.02021000"], ["111025.26000000", "0.00545000"], ["111027.23000000", "0.34245000"], ["111027.27000000", "0.00000000"], ["111027.95000000", "0.00000000"], ["111027.96000000", "0.32706000"], ["111028.42000000", "0.04930000"], ["111029.69000000", "0.00038000"], ["111029.70000000", "0.04730000"], ["111031.25000000", "0.20287000"], ["111037.15000000", "0.00000000"], ["111037.16000000", "0.01801000"], ["111042.72000000", "0.00000000"], ["111073.05000000", "0.96760000"], ["111136.52000000", "0.00000000"]]}}
{"type": "orderbook", "local_time": 1761342325086, "event_time": 1761342325115, "latency_ms": -29, "data": {"e": "depthUpdate", "E": 1761342325115, "s": "BTCUSDT", "U": 79012682644, "u": 79012683028, "b": [["111027.22000000", "4.57772000"], ["111027.21000000", "0.00000000"], ["111026.66000000", "0.03000000"], ["111026.19000000", "0.00000000"], ["111026.04000000", "0.29718000"], ["111025.47000000", "0.06748000"], ["111025.25000000", "0.00000000"], ["111025.24000000", "0.03444000"], ["111024.80000000", "0.00005000"], ["111024.22000000", "0.04000000"], ["111024.15000000", "0.00000000"], ["111023.05000000", "0.00250000"], ["111023.03000000", "0.00000000"], ["111022.07000000", "0.04572000"], ["111021.77000000", "0.00000000"], ["111021.36000000", "0.00000000"], ["111020.82000000", "0.00005000"], ["111020.00000000", "0.00005000"], ["111019.99000000", "0.00000000"], ["111019.98000000", "0.00000000"], ["111019.70000000", "0.33152000"], ["111019.64000000", "0.00000000"], ["111019.32000000", "0.00005000"], ["111019.31000000", "0.00000000"], ["111018.60000000", "2.00590000"], ["111018.59000000", "1.22386000"], ["111018.58000000", "0.00041000"], ["111018.50000000", "0.06100000"], ["111017.48000000", "0.00109000"], ["111017.07000000", "0.30389000"], ["111017.06000000", "0.00015000"], ["111017.05000000", "0.00010000"], ["111016.93000000", "0.00005000"], ["111016.82000000", "0.00005000"], ["111015.50000000", "0.00005000"], ["111015.30000000", "0.36868000"], ["111015.29000000", "0.00005000"], ["111014.91000000", "0.00005000"], ["111013.84000000", "0.00013000"], ["111013.29000000", "0.04191000"], ["111012.79000000", "0.10595000"], ["111012.00000000", "0.06011000"], ["111011.95000000", "0.00000000"], ["111011.82000000", "0.00007000"], ["111011.36000000", "0.00000000"], ["111010.57000000", "0.00090000"], ["111005.25000000", "0.00250000"], ["111004.44000000", "0.00000000"], ["111001.94000000", "0.00090000"], ["111001.52000000", "0.00000000"], ["111000.00000000", "0.00005000"], ["110998.82000000", "0.00000000"], ["110996.39000000", "0.00000000"], ["110996.35000000", "0.00000000"], ["110993.92000000", "0.04506000"], ["110990.47000000", "0.00000000"], ["110988.86000000", "0.00000000"], ["110985.93000000", "0.19741000"], ["110984.88000000", "0.00000000"], ["110983.34000000", "0.00000000"], ["110977.18000000", "0.00000000"], ["110976.28000000", "0.00000000"], ["110970.00000000", "0.00120000"], ["110964.52000000", "0.00000000"], ["110942.70000000", "0.00000000"], ["110939.40000000", "0.00000000"], ["110923.89000000", "0.00225000"], ["110914.65000000", "0.00000000"], ["110904.31000000", "0.00000000"], ["110903.46000000", "0.00000000"], ["110900.31000000", "0.04488000"], ["110891.04000000", "0.00000000"], ["110873.40000000", "0.00000000"], ["110812.14000000", "0.00090000"], ["110804.01000000", "0.00000000"], ["110802.00000000", "0.00257000"], ["110790.42000000", "0.00000000"], ["110789.11000000", "0.00076000"], ["110780.02000000", "0.00000000"], ["110771.86000000", "1.01100000"], ["110739.59000000", "0.00000000"]], "a": [["111018.60000000", "0.00000000"], ["111018.61000000", "0.00000000"], ["111019.32000000", "0.00000000"], ["111019.65000000", "0.00000000"], ["111019.71000000", "0.00000000"], ["111019.99000000", "0.00000000"], ["111020.00000000", "0.00000000"], ["111020.47000000", "0.00000000"], ["111020.57000000", "0.00000000"], ["111021.37000000", "0.00000000"], ["111021.69000000", "0.00000000"], ["111021.78000000", "0.00000000"], ["111021.90000000", "0.00000000"], ["111022.00000000", "0.00000000"], ["111023.04000000", "0.00000000"], ["111023.23000000", "0.00000000"], ["111023.97000000", "0.00000000"], ["111024.00000000", "0.00000000"], ["111024.69000000", "0.00000000"], ["111024.80000000", "0.00000000"], ["111025.20000000", "0.00000000"], ["111025.26000000", "0.00000000"], ["111025.48000000", "0.00000000"], ["111026.00000000", "0.00000000"], ["111026.13000000", "0.00000000"], ["111027.22000000", "0.00000000"], ["111027.23000000", "0.43839000"], ["111027.24000000", "0.00090000"], ["111027.95000000", "0.00010000"], ["111027.96000000", "0.00020000"], ["111028.41000000", "0.00010000"], ["111028.42000000", "0.04930000"], ["111028.58000000", "0.00000000"], ["111029.69000000", "0.00043000"], ["111029.70000000", "0.04730000"], ["111030.32000000", "0.00005000"], ["111030.33000000", "0.00005000"], ["111030.46000000", "0.43146000"], ["111030.57000000", "0.00070000"], ["111031.25000000", "0.20287000"], ["111031.26000000", "0.81635000"], ["111031.54000000", "0.00000000"], ["111031.75000000", "0.00000000"], ["111032.86000000", "0.29717000"], ["111033.03000000", "0.00000000"], ["111037.16000000", "0.00000000"], ["111037.19000000", "0.00000000"], ["111038.33000000", "0.00151000"], ["111038.52000000", "0.00000000"], ["111038.55000000", "0.01801000"], ["111039.80000000", "0.00000000"], ["111041.66000000", "0.08579000"], ["111043.88000000", "0.00150000"], ["111044.36000000", "0.00037000"], ["111044.41000000", "0.00000000"], ["111044.47000000", "0.00450000"], ["111044.70000000", "0.00039000"], ["111048.08000000", "0.01036000"], ["111048.92000000", "0.27041000"], ["111049.64000000", "0.00040000"], ["111050.11000000", "0.00035000"], ["111059.84000000", "0.00000000"], ["111059.99000000", "0.00000000"], ["111060.53000000", "0.04507000"], ["111061.18000000", "0.00008000"], ["111069.98000000", "0.00016000"], ["111071.85000000", "0.00060000"], ["111071.99000000", "0.00000000"], ["111073.98000000", "0.00000000"], ["111074.12000000", "0.00005000"], ["111074.70000000", "0.00005000"], ["111074.87000000", "0.06652000"], ["111077.19000000", "0.00090000"], ["111079.60000000", "0.00005000"], ["111080.82000000", "0.00016000"], ["111080.85000000", "0.32404000"], ["111082.50000000", "0.00224000"], ["111088.28000000", "0.00000000"], ["111096.98000000", "0.00048000"], ["111101.99000000", "0.00000000"], ["111110.99000000", "0.00224000"], ["111114.46000000", "0.00000000"], ["111117.46000000", "0.00000000"], ["111118.00000000", "0.05000000"], ["111121.01000000", "0.00011000"], ["111160.00000000", "0.00433000"], ["111180.90000000", "0.13574000"], ["111184.93000000", "0.00000000"], ["111191.25000000", "0.00000000"], ["111195.37000000", "0.00090000"], ["111214.66000000", "0.00000000"], ["111221.99000000", "0.24382000"], ["111225.64000000", "0.00405000"], ["111361.64000000", "0.00000000"], ["111368.93000000", "0.48717000"]]}}
{"type": "orderbook", "local_time": 1761342325136, "event_time": 1761342325214, "latency_ms": -78, "data": {"e": "depthUpdate", "E": 1761342325214, "s": "BTCUSDT", "U": 79012683029, "u": 79012683181, "b": [["111027.22000000", "4.64515000"], ["111027.09000000", "0.00445000"], ["111026.67000000", "0.00010000"], ["111026.66000000", "0.03030000"], ["111026.19000000", "0.00000000"], ["111026.05000000", "0.13193000"], ["111026.04000000", "0.29743000"], ["111025.48000000", "0.00010000"], ["111025.47000000", "0.06763000"], ["111025.25000000", "0.00010000"], ["111025.24000000", "0.03454000"], ["111024.23000000", "0.00005000"], ["111024.22000000", "0.04005000"], ["111022.07000000", "0.04577000"], ["111019.70000000", "0.33157000"], ["111018.61000000", "1.07351000"], ["111018.60000000", "0.70430000"], ["111018.59000000", "1.15643000"], ["111018.58000000", "0.00011000"], ["111017.48000000", "0.00099000"], ["111017.06000000", "0.00000000"], ["111017.05000000", "0.00000000"], ["111016.82000000", "0.00000000"], ["111015.50000000", "0.00000000"], ["111015.30000000", "0.11597000"], ["111015.29000000", "0.00000000"], ["111014.91000000", "0.00000000"], ["111014.15000000", "0.01870000"], ["111010.58000000", "0.00000000"], ["110996.40000000", "0.04546000"], ["110979.46000000", "0.05100000"], ["110911.06000000", "0.00000000"], ["110908.59000000", "0.00000000"], ["110905.51000000", "0.00000000"], ["110841.33000000", "0.16332000"], ["110802.81000000", "0.00000000"]], "a": [["111027.23000000", "0.43446000"], ["111027.24000000", "0.00100000"], ["111027.95000000", "0.00000000"], ["111027.96000000", "0.00010000"], ["111027.97000000", "0.20778000"], ["111028.00000000", "0.00165000"], ["111028.95000000", "0.00008000"], ["111029.70000000", "0.04730000"], ["111029.79000000", "0.29717000"], ["111030.32000000", "0.00000000"], ["111030.33000000", "0.00000000"], ["111030.45000000", "0.00010000"], ["111030.46000000", "0.43151000"], ["111031.24000000", "0.00005000"], ["111031.26000000", "0.81635000"], ["111032.64000000", "0.01793000"], ["111032.86000000", "0.00005000"], ["111032.93000000", "0.00620000"], ["111034.49000000", "0.00008000"], ["111036.92000000", "0.00000000"], ["111039.92000000", "0.00333000"], ["111040.26000000", "0.02703000"], ["111040.43000000", "0.00070000"], ["111066.36000000", "0.00000000"], ["111078.24000000", "0.23180000"], ["111083.69000000", "0.00000000"], ["111097.75000000", "0.00631000"], ["111117.51000000", "0.03400000"], ["111121.06000000", "0.02500000"], ["111140.00000000", "0.02045000"]]}}
{"type": "orderbook", "local_time": 1761342325234, "event_time": 1761342325314, "latency_ms": -80, "data": {"e": "depthUpdate", "E": 1761342325314, "s": "BTCUSDT", "U": 79012683182, "u": 79012683242, "b": [["111027.22000000", "4.64508000"], ["111027.09000000", "0.00465000"], ["111026.66000000", "0.03025000"], ["111026.06000000", "0.00005000"], ["111026.05000000", "0.13208000"], ["111026.04000000", "0.29728000"], ["111025.47000000", "0.06753000"], ["111025.24000000", "0.03449000"], ["111024.23000000", "0.00000000"], ["111019.70000000", "0.33157000"], ["111018.61000000", "0.66469000"], ["111018.60000000", "0.70425000"], ["111017.07000000", "0.00000000"], ["111014.16000000", "0.30389000"], ["110977.15000000", "0.05400000"], ["110928.05000000", "0.01352000"], ["110922.51000000", "0.01352000"], ["99924.00000000", "0.00010000"]], "a": [["111027.23000000", "0.43451000"], ["111027.24000000", "0.00105000"], ["111029.70000000", "0.04730000"], ["111029.78000000", "0.00010000"], ["111029.79000000", "0.29727000"], ["111030.46000000", "0.43146000"], ["111031.24000000", "0.00000000"], ["111032.64000000", "0.01793000"], ["111032.86000000", "0.00000000"], ["111038.55000000", "0.00000000"], ["111038.60000000", "0.01801000"], ["111061.41000000", "0.00000000"]]}}
{"type": "orderbook", "local_time": 1761342325336, "event_time": 1761342325414, "latency_ms": -78, "data": {"e": "depthUpdate", "E": 1761342325414, "s": "BTCUSDT", "U": 79012683243, "u": 79012683264, "b": [["111015.30000000", "0.19181000"], ["111014.16000000", "0.31657000"], ["111014.15000000", "0.00610000"], ["111013.84000000", "0.00005000"], ["110991.13000000", "0.00000000"], ["110982.79000000", "0.05700000"], ["110978.91000000", "0.05100000"], ["110978.35000000", "0.05100000"], ["110914.85000000", "0.05700000"], ["109599.87000000", "0.02502000"], ["99924.00000000", "0.00010000"]], "a": [["111027.23000000", "0.43782000"], ["111039.92000000", "0.00000000"], ["111073.05000000", "0.00000000"], ["111096.97000000", "0.00048000"], ["111096.98000000", "0.00000000"], ["111199.99000000", "0.00000000"], ["111208.79000000", "0.00019000"]]}}
{"type": "orderbook", "local_time": 1761342325435, "event_time": 1761342325514, "latency_ms": -79, "data": {"e": "depthUpdate", "E": 1761342325514, "s": "BTCUSDT", "U": 79012683265, "u": 79012683276, "b": [["111020.78000000", "0.04977000"], ["111018.60000000", "0.00255000"], ["111010.27000000", "0.00000000"], ["110982.70000000", "0.09000000"], ["110914.85000000", "0.00000000"], ["110910.44000000", "0.00000000"], ["110892.73000000", "0.00000000"], ["110840.00000000", "0.00160000"], ["99924.00000000", "0.00000000"]], "a": [["111027.23000000", "0.43879000"]]}}
{"type": "orderbook", "local_time": 1761342325539, "event_time": 1761342325615, "latency_ms": -76, "data": {"e": "depthUpdate", "E": 1761342325615, "s": "BTCUSDT", "U": 79012683277, "u": 79012683313, "b": [["111027.22000000", "4.64586000"], ["111026.66000000", "0.00025000"], ["111026.58000000", "0.00000000"], ["111026.11000000", "0.00099000"], ["111024.45000000", "0.00198000"], ["111022.78000000", "0.00360000"], ["111022.07000000", "0.04577000"], ["111020.56000000", "0.00540000"], ["111018.61000000", "0.36451000"], ["111018.59000000", "0.73762000"], ["111015.82000000", "0.00000000"], ["111011.93000000", "0.00000000"], ["111009.16000000", "0.00005000"], ["111007.49000000", "0.00056000"], ["110998.31000000", "0.08447000"], ["110997.88000000", "0.84681000"], ["110977.24000000", "0.03900000"], ["33000.00000000", "3.79445000"]], "a": [["111027.23000000", "0.46524000"], ["111030.00000000", "0.00358000"], ["111033.89000000", "0.00540000"], ["111035.90000000", "0.00044000"], ["111036.66000000", "0.00396000"], ["111038.33000000", "0.00871000"], ["111051.18000000", "0.03000000"], ["111051.35000000", "0.00044000"], ["111061.30000000", "0.95342000"], ["111147.72000000", "0.03000000"]]}}
{"type": "orderbook", "local_time": 1761342325640, "event_time": 1761342325714, "latency_ms": -74, "data": {"e": "depthUpdate", "E": 1761342325714, "s": "BTCUSDT", "U": 79012683314, "u": 79012683358, "b": [["111027.22000000", "4.62769000"], ["111027.09000000", "0.00465000"], ["111026.67000000", "0.00000000"], ["111026.66000000", "0.00000000"], ["111026.11000000", "0.00119000"], ["111026.06000000", "0.00010000"], ["111025.47000000", "0.00005000"], ["111024.23000000", "0.00005000"], ["111020.78000000", "0.00000000"], ["111018.61000000", "0.23949000"], ["111018.59000000", "0.62495000"], ["111013.34000000", "0.11267000"], ["111010.27000000", "0.01768000"], ["110983.90000000", "0.03900000"], ["110892.83000000", "0.00114000"], ["110890.55000000", "0.00000000"], ["110886.44000000", "0.00000000"], ["110875.34000000", "0.00000000"], ["110872.21000000", "0.00000000"], ["110761.08000000", "0.00000000"], ["99924.00000000", "0.00010000"], ["99916.00000000", "0.00000000"]], "a": [["111027.23000000", "1.15589000"], ["111027.24000000", "0.00110000"], ["111061.92000000", "0.00000000"], ["111075.49000000", "0.00000000"]]}}
{"type": "orderbook", "local_time": 1761342325747, "event_time": 1761342325814, "latency_ms": -67, "data": {"e": "depthUpdate", "E": 1761342325814, "s": "BTCUSDT", "U": 79012683359, "u": 79012683382, "b": [["111026.04000000", "0.29728000"], ["111025.48000000", "0.00000000"], ["111025.47000000", "0.00000000"], ["111024.23000000", "0.00010000"], ["111022.08000000", "0.00005000"], ["111022.07000000", "0.04577000"], ["111020.78000000", "0.04982000"], ["111020.56000000", "0.00545000"], ["110964.77000000", "0.12502000"], ["110896.03000000", "0.00000000"], ["110892.22000000", "0.00000000"], ["110881.74000000", "0.00229000"], ["110880.01000000", "0.00224000"], ["110769.59000000", "0.00090000"]], "a": [["111027.23000000", "1.30004000"], ["111064.39000000", "0.00114000"], ["111081.22000000", "0.19338000"]]}}
{"type": "orderbook", "local_time": 1761342325853, "event_time": 1761342325914, "latency_ms": -61, "data": {"e": "depthUpdate", "E": 1761342325914, "s": "BTCUSDT", "U": 79012683383, "u": 79012683426, "b": [["111022.07000000", "0.04577000"], ["111020.78000000", "0.00000000"], ["111016.11000000", "0.00300000"], ["110993.91000000", "0.00009000"], ["110983.81000000", "0.03600000"], ["110978.00000000", "0.00120000"], ["110977.37000000", "0.00000000"], ["110977.28000000", "0.00000000"], ["110977.24000000", "0.07800000"], ["110976.00000000", "0.00120000"], ["110974.00000000", "0.00120000"], ["110972.00000000", "0.00120000"], ["110960.60000000", "0.00009000"], ["110943.97000000", "0.00000000"], ["110927.30000000", "0.00009000"], ["110910.67000000", "0.00000000"], ["110893.99000000", "0.00009000"], ["110877.37000000", "0.00000000"], ["110860.68000000", "0.00009000"], ["110844.06000000", "0.00000000"], ["99924.00000000", "0.00010000"]], "a": [["111027.23000000", "1.30073000"], ["111040.43000000", "0.00000000"], ["111043.89000000", "0.00000000"], ["111060.54000000", "0.00309000"], ["111075.49000000", "0.00229000"], ["111077.20000000", "0.00000000"], ["111093.85000000", "0.00009000"], ["111094.71000000", "0.00044000"], ["111110.50000000", "0.00000000"], ["111121.70000000", "0.00100000"], ["111121.71000000", "0.00100000"], ["111127.15000000", "0.00008000"], ["111143.80000000", "0.00000000"], ["111160.46000000", "0.00008000"], ["111163.00000000", "0.00000000"], ["111177.11000000", "0.00000000"], ["111193.77000000", "0.00008000"], ["111222.00000000", "0.72205000"], ["111299.00000000", "0.00100000"], ["111417.00000000", "2.79228000"]]}}
{"type": "orderbook", "local_time": 1761342325944, "event_time": 1761342326014, "latency_ms": -70, "data": {"e": "depthUpdate", "E": 1761342326014, "s": "BTCUSDT", "U": 79012683427, "u": 79012683441, "b": [["111027.22000000", "4.55404000"], ["111022.07000000", "0.04577000"], ["111014.15000000", "0.00618000"], ["110912.92000000", "0.00000000"], ["110909.28000000", "0.00000000"], ["110906.52000000", "0.00000000"], ["110906.24000000", "0.00000000"], ["110892.83000000", "0.00000000"], ["110881.74000000", "0.00000000"], ["88815.00000000", "0.00000000"]], "a": [["111041.83000000", "0.00044000"], ["111064.39000000", "0.00000000"], ["111075.49000000", "0.00000000"], ["111147.72000000", "0.00000000"], ["111277.58000000", "0.01410000"]]}}
{"type": "orderbook", "local_time": 1761342326038, "event_time": 1761342326114, "latency_ms": -76, "data": {"e": "depthUpdate", "E": 1761342326114, "s": "BTCUSDT", "U": 79012683442, "u": 79012683448, "b": [["111024.22000000", "0.00005000"], ["110993.92000000", "0.00000000"], ["99924.00000000", "0.00010000"]], "a": [["111060.53000000", "0.00000000"], ["111121.70000000", "0.00000000"], ["111133.55000000", "0.00005000"]]}}
{"type": "orderbook", "local_time": 1761342326142, "event_time": 1761342326214, "latency_ms": -72, "data": {"e": "depthUpdate", "E": 1761342326214, "s": "BTCUSDT", "U": 79012683449, "u": 79012683459, "b": [["111027.22000000", "4.64423000"], ["111026.06000000", "0.18019000"], ["111025.24000000", "0.03449000"], ["111024.23000000", "0.00000000"], ["111024.22000000", "0.00000000"], ["111022.08000000", "0.00010000"], ["111019.71000000", "0.00005000"], ["111018.61000000", "0.23954000"], ["111017.49000000", "0.00450000"], ["111011.37000000", "0.00000000"]], "a": []}}
{"type": "orderbook", "local_time": 1761342326234, "event_time": 1761342326314, "latency_ms": -80, "data": {"e": "depthUpdate", "E": 1761342326314, "s": "BTCUSDT", "U": 79012683460, "u": 79012683480, "b": [["111027.22000000", "4.64413000"], ["111027.09000000", "0.00020000"], ["111026.11000000", "0.00119000"], ["111026.07000000", "0.00005000"], ["111026.06000000", "0.18029000"], ["111026.05000000", "0.13203000"], ["111026.04000000", "0.29723000"], ["111019.71000000", "0.00000000"], ["111018.60000000", "0.00405000"], ["111017.49000000", "0.00000000"], ["111016.12000000", "0.00450000"], ["102137.10000000", "0.00205000"], ["99924.00000000", "0.00010000"]], "a": [["111027.23000000", "1.30004000"], ["111039.26000000", "0.00069000"], ["111061.29000000", "1.13767000"]]}}
{"type": "orderbook", "local_time": 1761342326464, "event_time": 1761342326414, "latency_ms": 50, "data": {"e": "depthUpdate", "E": 1761342326414, "s": "BTCUSDT", "U": 79012683481, "u": 79012683496, "b": [["111027.22000000", "4.64428000"], ["111027.09000000", "0.00387000"], ["111026.06000000", "0.18039000"], ["111026.05000000", "0.13208000"], ["111026.04000000", "0.29728000"], ["111017.49000000", "0.00450000"], ["111016.12000000", "0.00000000"], ["111012.00000000", "0.06016000"], ["110880.00000000", "0.02068000"]], "a": [["111130.80000000", "0.00005000"]]}}
{"type": "orderbook", "local_time": 1761342326465, "event_time": 1761342326514, "latency_ms": -49, "data": {"e": "depthUpdate", "E": 1761342326514, "s": "BTCUSDT", "U": 79012683497, "u": 79012683505, "b": [["111027.09000000", "0.00407000"], ["111026.06000000", "0.18029000"], ["111026.05000000", "0.13203000"], ["111026.04000000", "0.29723000"]], "a": [["111078.24000000", "0.11717000"]]}}
{"type": "orderbook", "local_time": 1761342326535, "event_time": 1761342326614, "latency_ms": -79, "data": {"e": "depthUpdate", "E": 1761342326614, "s": "BTCUSDT", "U": 79012683506, "u": 79012683507, "b": [["111027.22000000", "4.78388000"]], "a": [["111044.47000000", "0.00000000"], ["111045.09000000", "0.00450000"]]}}
{"type": "orderbook", "local_time": 1761342326637, "event_time": 1761342326714, "latency_ms": -77, "data": {"e": "depthUpdate", "E": 1761342326714, "s": "BTCUSDT", "U": 79012683508, "u": 79012683509, "b": [["111020.24000000", "0.05051000"], ["111017.49000000", "0.00000000"], ["111016.12000000", "0.00450000"]], "a": []}}
{"type": "orderbook", "local_time": 1761342326740, "event_time": 1761342326814, "latency_ms": -74, "data": {"e": "depthUpdate", "E": 1761342326814, "s": "BTCUSDT", "U": 79012683510, "u": 79012683518, "b": [["111027.22000000", "4.78393000"], ["111020.56000000", "0.00540000"], ["111020.24000000", "0.00000000"], ["110958.00000000", "0.00140000"], ["110956.00000000", "0.00140000"], ["110779.35000000", "0.00000000"], ["102137.10000000", "0.00195000"]], "a": [["111121.72000000", "0.00100000"], ["111261.26000000", "0.00000000"]]}}
{"type": "orderbook", "local_time": 1761342326837, "event_time": 1761342326914, "latency_ms": -77, "data": {"e": "depthUpdate", "E": 1761342326914, "s": "BTCUSDT", "U": 79012683519, "u": 79012683528, "b": [["110954.00000000", "0.00140000"], ["110952.00000000", "0.00140000"], ["99924.00000000", "0.00010000"]], "a": [["111032.79000000", "0.11267000"], ["111046.36000000", "0.00000000"], ["111368.93000000", "0.48717000"]]}}
{"type": "orderbook", "local_time": 1761342326934, "event_time": 1761342327014, "latency_ms": -80, "data": {"e": "depthUpdate", "E": 1761342327014, "s": "BTCUSDT", "U": 79012683529, "u": 79012683541, "b": [["111027.22000000", "4.78383000"], ["99924.00000000", "0.00010000"]], "a": [["111027.23000000", "1.30004000"], ["111027.24000000", "0.00110000"], ["111032.64000000", "0.01793000"], ["111032.79000000", "0.11272000"], ["111032.93000000", "0.00615000"]]}}
{"type": "orderbook", "local_time": 1761342327043, "event_time": 1761342327114, "latency_ms": -71, "data": {"e": "depthUpdate", "E": 1761342327114, "s": "BTCUSDT", "U": 79012683542, "u": 79012683547, "b": [["111027.22000000", "4.78384000"], ["111018.59000000", "0.37120000"], ["110788.47000000", "0.84841000"]], "a": [["111094.71000000", "0.00000000"], ["111270.13000000", "4.74145000"]]}}
{"type": "orderbook", "local_time": 1761342327134, "event_time": 1761342327214, "latency_ms": -80, "data": {"e": "depthUpdate", "E": 1761342327214, "s": "BTCUSDT", "U": 79012683548, "u": 79012683551, "b": [["111019.71000000", "0.22957000"], ["111018.61000000", "0.00005000"], ["110930.80000000", "0.00992000"]], "a": [["113844.72000000", "0.00009000"], ["113887.00000000", "0.00000000"]]}}
{"type": "orderbook", "local_time": 1761342327235, "event_time": 1761342327315, "latency_ms": -80, "data": {"e": "depthUpdate", "E": 1761342327315, "s": "BTCUSDT", "U": 79012683552, "u": 79012683561, "b": [["111026.06000000", "0.18034000"], ["111020.56000000", "0.00545000"], ["111019.70000000", "0.33152000"], ["111018.61000000", "0.00000000"], ["110998.31000000", "0.21941000"], ["110982.09000000", "0.34585000"], ["110971.37000000", "0.00000000"]], "a": [["111078.24000000", "0.28953000"], ["111117.50000000", "0.03400000"], ["111117.51000000", "0.00000000"]]}}
{"type": "orderbook", "local_time": 1761342327335, "event_time": 1761342327414, "latency_ms": -79, "data": {"e": "depthUpdate", "E": 1761342327414, "s": "BTCUSDT", "U": 79012683562, "u": 79012683562, "b": [], "a": [["111051.13000000", "0.06748000"]]}}
{"type": "orderbook", "local_time": 1761342327436, "event_time": 1761342327514, "latency_ms": -78, "data": {"e": "depthUpdate", "E": 1761342327514, "s": "BTCUSDT", "U": 79012683563, "u": 79012683566, "b": [["111027.22000000", "5.03759000"], ["39969.80000000", "0.00016000"]], "a": [["111027.23000000", "1.30073000"], ["111039.26000000", "0.00000000"]]}}
{"type": "orderbook", "local_time": 1761342327536, "event_time": 1761342327614, "latency_ms": -78, "data": {"e": "depthUpdate", "E": 1761342327614, "s": "BTCUSDT", "U": 79012683567, "u": 79012683568, "b": [["111018.59000000", "0.35920000"]], "a": [["111027.23000000", "1.30087000"]]}}
{"type": "orderbook", "local_time": 1761342327638, "event_time": 1761342327714, "latency_ms": -76, "data": {"e": "depthUpdate", "E": 1761342327714, "s": "BTCUSDT", "U": 79012683569, "u": 79012683578, "b": [["111026.06000000", "0.00025000"], ["111025.25000000", "0.00010000"], ["111024.46000000", "0.18009000"], ["110954.81000000", "0.00000000"], ["110902.84000000", "0.00000000"], ["110880.00000000", "0.02073000"]], "a": [["111041.03000000", "0.18255000"], ["111044.13000000", "0.00000000"], ["111099.82000000", "0.00000000"], ["111133.89000000", "0.00000000"], ["111137.40000000", "0.00005000"]]}}
{"type": "orderbook", "local_time": 1761342327743, "event_time": 1761342327814, "latency_ms": -71, "data": {"e": "depthUpdate", "E": 1761342327814, "s": "BTCUSDT", "U": 79012683579, "u": 79012683595, "b": [["111026.11000000", "0.00119000"], ["111026.07000000", "0.00000000"], ["111026.06000000", "0.00010000"], ["111026.05000000", "0.13208000"], ["111026.04000000", "0.29728000"], ["111025.24000000", "0.03449000"], ["111024.47000000", "0.00005000"], ["111024.46000000", "0.18014000"], ["99924.00000000", "0.00010000"]], "a": [["111121.97000000", "0.01410000"]]}}
{"type": "orderbook", "local_time": 1761342327838, "event_time": 1761342327914, "latency_ms": -76, "data": {"e": "depthUpdate", "E": 1761342327914, "s": "BTCUSDT", "U": 79012683596, "u": 79012683602, "b": [["99924.00000000", "0.00010000"]], "a": [["111027.97000000", "0.00020000"], ["111028.42000000", "0.00010000"], ["111032.64000000", "0.00005000"], ["111060.36000000", "0.32410000"], ["111080.85000000", "0.00000000"]]}}
{"type": "orderbook", "local_time": 1761342327936, "event_time": 1761342328014, "latency_ms": -78, "data": {"e": "depthUpdate", "E": 1761342328014, "s": "BTCUSDT", "U": 79012683603, "u": 79012683658, "b": [["111026.06000000", "0.18019000"], ["111024.47000000", "0.00010000"], ["111024.46000000", "0.00005000"]], "a": [["111027.23000000", "0.61035000"], ["111027.24000000", "0.00095000"], ["111027.96000000", "0.00000000"], ["111027.97000000", "0.00000000"], ["111028.00000000", "0.00170000"], ["111028.03000000", "0.00401000"], ["111028.41000000", "0.00000000"], ["111028.42000000", "0.00000000"], ["111030.46000000", "0.43151000"], ["111031.24000000", "0.00010000"], ["111031.25000000", "0.20297000"], ["111031.26000000", "0.81635000"], ["111032.64000000", "0.00000000"], ["111032.93000000", "0.00620000"], ["111033.16000000", "0.04577000"], ["111033.39000000", "0.13529000"], ["111038.60000000", "0.00000000"], ["111041.83000000", "0.00000000"], ["111051.35000000", "0.00000000"], ["111056.54000000", "0.00223000"], ["111078.24000000", "0.11717000"], ["111117.50000000", "0.00000000"], ["111118.45000000", "0.03400000"], ["111121.06000000", "0.00000000"], ["111121.71000000", "0.00000000"], ["111121.72000000", "0.00000000"], ["111122.00000000", "0.03413000"]]}}
{"type": "orderbook", "local_time": 1761342328037, "event_time": 1761342328114, "latency_ms": -77, "data": {"e": "depthUpdate", "E": 1761342328114, "s": "BTCUSDT", "U": 79012683659, "u": 79012683688, "b": [["111026.11000000", "0.00119000"], ["111026.07000000", "0.00010000"], ["111026.06000000", "0.18034000"], ["111026.05000000", "0.13203000"], ["111026.04000000", "0.29723000"], ["111025.24000000", "0.03449000"], ["111024.47000000", "0.00000000"], ["111024.46000000", "0.00000000"], ["111007.32000000", "0.01801000"], ["111005.50000000", "0.00000000"], ["110940.89000000", "0.00000000"], ["99924.00000000", "0.00010000"]], "a": [["111027.23000000", "0.81724000"], ["111035.90000000", "0.00000000"], ["111037.97000000", "0.00000000"], ["111038.96000000", "0.01801000"], ["111039.28000000", "0.00070000"], ["111074.87000000", "0.00000000"], ["111180.90000000", "0.00000000"]]}}
